Workbook
Name AER: Convencionales!#REF!
Name ASC: Convencionales!#REF!
Name BIN: Convencionales!#REF!
Name EST: Convencionales!#REF!
Name FIN: Convencionales!#REF!
Name ICA: Convencionales!#REF!
Name IMS: Convencionales!#REF!
Name MIS: Convencionales!#REF!
Name OBE: Convencionales!$I$3:$I$17
Name OGA: Convencionales!#REF!
Name PAC: Convencionales!#REF!
Name PRF: Convencionales!#REF!
Name RAI: Convencionales!#REF!
Name THM: Convencionales!#REF!
Name VNI: Convencionales!#REF!

Sheet Convencionales
G1: fup*
B2: Elija | D2: DD | E2: MM | F2: AAAA | G2: Elija | I2: OBE | K2: LOCALIDAD | M2: Descripcion ccosto | O2: Nombres
A3: Elija | B3: SI | C3: Elija | D3: 1 | E3: Ene | F3: 2019 | G3: ANALISTA DE SISTEMAS | I3: Elija | K3: Elija | M3: Elija | O3: Elija
A4: Pregrado | B4: NO | C4: 4 Meses Semestre 1 | D4: 2 | E4: Feb | F4: 2020 | G4: APRENDIZ SENA | I4: 1. Misión y Proyecto Educativo Institucional | K4: POPAYÁN | M4: ADMINISTRACION DE EMPRESAS | O4: DIAZ CARMONA DANILO MANZILLER
A5: Especialización Profesional | B5: TRASLADO | C5: 4 Meses Semestre 2 | D5: 3 | E5: Mar | F5: 2021 | G5: ASESOR | I5: 2. Estudiantes | K5: SANTANDER DE QUILICHAO | M5: ADMINISTRACION DE EMPRESAS / MOD. VIRTUAL | O5: SOLIS ESCOBAR FERNANDO
A6: Maestría | C6: 8 Meses | D6: 4 | E6: Abr | F6: 2022 | G6: ASISTENTE ADMINISTRATIVO | I6: 3. Talento Humano | M6: ADMINISTRACION DE EMPRESAS AGROPECUARIAS | O6: IBARRA SOTELO MARYEM ROCIO
A7: Doctorado | C7: 10 meses | D7: 5 | E7: May | F7: 2023 | G7: ASISTENTE ACADEMICO | I7: 4. Profesores | M7: ADMINISTRACION DE EMPRESAS AGROPECUARIAS / MOD. VIRTUAL | O7: GARCIA BUITRON JULIO CESAR
C8: 11 meses | D8: 6 | E8: Jun | G8: AUXILIAR ACADEMICO | I8: 5. Procesos académicos | M8: ARQUITECTURA | O8: COBO POTOSI YISEL
C9: 1 año | D9: 7 | E9: Jul | G9: AUXILIAR ADMINISTRATIVO | I9: 6. Visibilidad Nacional e Internacional | M9: ASEGURAMIENTO DE LA CALIDAD | O9: DULCEY MUJICA INGRITH TATIANA
A10: Elija | C10: Indefinido | D10: 8 | E10: Ago | G10: AUXILIAR CONTABLE | I10: 7. Investigación y Creación Artística | M10: AUTOEVALUACION | O10: VALVERDE ROJAS ERICA ANDREA
A11: Especialización Profesional | D11: 9 | E11: Sep | G11: AUXILIAR DE CAMPO | I11: 8. Impacto social | M11: BIBLIOTECA | O11: URBANO GALLEGO ANDREA CECILIA
A12: Maestría | C12: Elija | D12: 10 | E12: Oct | G12: AUXILIAR DE ENFERMERIA | I12: 9. Autoevaluación y Autorregulación | M12: BIENESTAR INSTITUCIONAL | O12: LOZANO NIÑO SERGIO
A13: Doctorado | C13: Semestre 1 | D13: 11 | E13: Nov | G13: AUXILIAR DE INVESTIGACION | I13: 10. Bienestar Institucional | M13: CALIDAD INSTITUCIONAL | O13: CASTRO DOMINGUEZ GLORIA PATRICIA
C14: Semestre 2 | D14: 12 | E14: Dic | G14: AUXILIAR DE LABORATORIO | I14: 11. Organización, gestión y administración | M14: CENTRO DE INFORMATICA | O14: FERIZ GARCIA DANIEL ANDRES
A15: Elija | C15: Ambos | D15: 13 | G15: AUXILIAR DE MANTENIMIENTO | I15: 12. Recursos de apoyo académico e infraestructura física | M15: CICMA | O15: DURAN LOPEZ JULIAN ANDRES
A16: TRANSVERSAL | D16: 14 | G16: AUXILIAR DE MANTENIMIENTO TI | I16: 13. Recursos financieros | M16: COORDINACION DE PROYECTOS | O16: QUINTERO ROJAS ANGELA MARIA
A17: CONVENCIONAL | D17: 15 | G17: AUXILIAR DE SOPORTE | I17: 14. Aseguramiento de la Calidad | M17: COMUNICACIÓN SOCIAL | O17: URREA PANTOJA WILMER JAIR
D18: 16 | G18: AUXILIAR SERVICIOS GENERALES | M18: COMUNICACIÓN SOCIAL / MOD. VIRTUAL | O18: MOSQUERA SANCHEZ LUIS EMIRO
A19: Tipo | D19: 17 | G19: BIBLIOTECOLOGA | M19: COMUNICACIONES | O19: GAVIRIA ARMERO SONIA DEL CONSUELO
A20: PMI | D20: 18 | G20: CAMAROGRAFO AUDIOVISUALES | M20: CONTABILIDAD | O20: ROJAS GIRALDO JUAN CARLOS
A21: PMC | D21: 19 | G21: CAPELLAN | M21: CONTADURIA | O21: PASAJE BURBANO FABIAN FERNANDO
A22: PMP | D22: 20 | G22: COMMUNITY MANAGER | M22: DECANATURA | O22: ZUÑIGA MUÑOZ YADY VANESSA
A23: PGR | D23: 21 | G23: CONDUCTOR | M23: DERECHO | O23: CLEVES SUAZA LUIS GUILLERMO
A24: EST | D24: 22 | G24: CONTADOR | M24: ECOLOGIA | O24: MEDINA LLANTEN JESUS ANTONIO
A25: DM | D25: 23 | G25: COORDINADOR | M25: ECONOMIA | O25: ARIAS HOYOS ARNOL
D26: 24 | G26: COORDINADOR - LOGISTICA, COMPRAS Y ALMACEN | M26: EGRESADOS | O26: DURAN ENRIQUEZ CARLOS ANDRES
D27: 25 | G27: COORDINADOR ACADEMICO | M27: ESCUELA DE DESARROLLO PROFESORAL | O27: MONTOYA BONILLA BIBIANA PATRICIA
D28: 26 | G28: COORDINADOR ACADEMICO GENERAL | M28: ESCUELA DE IDIOMAS | O28: BETANCOURT LOPEZ JOSE GREGORIO
D29: 27 | G29: COORDINADOR ADMISIONES | M29: ESCUELA DE LECTO-ESCRITURA | O29: VALENCIA PALOMINO DAISY XIMENA
D30: 28 | G30: COORDINADOR CULTURA Y DEPORTES | M30: ESCUELA DE MATEMATICAS | O30: MINA ZAPE CARLOS FERNANDO
D31: 29 | G31: COORDINADOR DE EMPRENDIMIENTO | M31: ESCUELA DE MUSICA | O31: MOSQUERA CERON JUAN PABLO
D32: 30 | G32: COORDINADOR DE MEDIOS EDUCATIVOS | M32: EXTENSIÓN Y PROYECCIÓN SOCIAL | O32: JOAQUI ESCOBAR PAOLA ANDREA
D33: 31 | G33: COORDINADOR DE PROYECTOS | M33: FINCA | O33: BOLAÑOS SARRIA DIEGO FABIAN
G34: COORDINADOR GESTION CURRICULAR | M34: INGENIERIA DE SISTEMAS | O34: SATIZABAL SERNA CLARA EUGENIA
G35: COORDINADOR GESTION DOCUMENTAL | M35: INGENIERIA INDUSTRIAL | O35: ACOSTA CAICEDO OMAR ANDRES
G36: COORDINADOR PERMANENCIA | M36: INTERNACIONALIZACION | O36: PRADO QUINTERO JUAN MANUEL
G37: COORDINADOR REGISTRO ACADEMICO | M37: LABORATORIOS | O37: RONCANCIO ANDREA CAICEDO
G38: COORDINADOR SERVICIOS DE SALUD | M38: LEAC | O38: AGUILAR BURBANO ANDRES FELIPE
G39: COORDINADOR SG - SST | M39: MERCADEO - ADMISIONES | O39: ERAZO MEDINA MONICA ADRIANA
G40: DESARROLLADOR | M40: PASTORAL | O40: CARDONA CHAVEZ CARLOS MANUEL
...

Sheet BaseSalarial
B2: Incremento | D2: 1.09
B3: Carga prestacional | D3: 1.52
B4: Salario Mínimo | D4: 1200000
B5: Supsidio de transporte | D5: 140606
B6: Horas Laborales Tiempo Completo | D6: 40
B7: Horas Laborales Medio Tiempo | D7: =D6/2 -> 20
B8: Horas Laborales TP | D8: =D7/2 -> 10
B9: Vr. Hora por docente | D9: =(D2*D4)/30 -> 43600
B12: CUALIFICACIÓN DOCENTE | C12: SALARIO 2021 TC | D12: SALARIO CON INCREMENTO TC | E12: CON CARGA PRESTACIONAL TC | F12: Vr. Hora por docente TC | G12: SALARIO 2021 MT | H12: SALARIO CON INCREMENTO MT | I12: CON CARGA PRESTACIONAL MT | J12: Vr. Hora por docente MT | K12: Vr. Hora por docente TP
B13: Pregrado | C13: 2531429 | D13: =C13*$D$2 -> 2759257.6 | E13: =+D13*$D$3 -> 4194071.6 | F13: =E13/$D$6 -> 104851.79 | G13: =C13/2 -> 1265714.5 | H13: =G13*$D$2 -> 1379628.8 | I13: =(H13*$D$3)+$D$5 -> 2237641.8 | J13: =I13/$D$7 -> 111882.09 | K13: =I13/$D$8 -> 223764.18
B14: Especialización Profesional | C14: 2703909 | D14: =C14*$D$2 -> 2947260.8 | E14: =+D14*$D$3 -> 4479836.4 | F14: =E14/$D$6 -> 111995.91 | G14: =C14/2 -> 1351954.5 | H14: =G14*$D$2 -> 1473630.4 | I14: =(H14*$D$3)+$D$5 -> 2380524.2 | J14: =I14/$D$7 -> 119026.21 | K14: =I14/$D$8 -> 238052.42
B15: Maestría | C15: 2876389 | D15: =C15*$D$2 -> 3135264 | E15: =+D15*$D$3 -> 4765601.3 | F15: =E15/$D$6 -> 119140.03 | G15: =C15/2 -> 1438194.5 | H15: =G15*$D$2 -> 1567632 | I15: =(H15*$D$3)+$D$5 -> 2523406.6 | J15: =I15/$D$7 -> 126170.33 | K15: =I15/$D$8 -> 252340.66
B16: Doctorado | C16: 3048868 | D16: =C16*$D$2 -> 3323266.1 | E16: =+D16*$D$3 -> 5051364.5 | F16: =E16/$D$6 -> 126284.11 | G16: =C16/2 -> 1524434 | H16: =G16*$D$2 -> 1661633.1 | I16: =(H16*$D$3)+$D$5 -> 2666288.3 | J16: =I16/$D$7 -> 133314.41 | K16: =I16/$D$8 -> 266628.83
B19: CÓDIGO SALARIO | C19: SALARIO 2022 | D19: SALARIO CON INCREMENTO | E19: CON CARGA PRESTACIONAL | G19: CUALIFICACIÓN DOCENTE | H19: COSTO HORA
B20: CS01 | C20: 4476389 | D20: =C20*$D$2 -> 4879264 | E20: =+D20*$D$3 -> 7416481.3 | G20: Especialización Profesional | H20: 100000
B21: CS02 | C21: 4303910 | D21: =C21*$D$2 -> 4691261.9 | E21: =+D21*$D$3 -> 7130718.1 | G21: Maestría | H21: 120000
B22: CS03 | C22: 4273788 | D22: =C22*$D$2 -> 4658428.9 | E22: =+D22*$D$3 -> 7080812 | G22: Doctorado | H22: 150000
B23: CS04 | C23: 4131429 | D23: =C23*$D$2 -> 4503257.6 | E23: =+D23*$D$3 -> 6844951.6
B24: CS05 | C24: 3900489 | D24: =C24*$D$2 -> 4251533 | E24: =+D24*$D$3 -> 6462330.2
B25: CS06 | C25: 3720033 | D25: =C25*$D$2 -> 4054836 | E25: =+D25*$D$3 -> 6163350.7
B26: CS07 | C26: 3676389 | D26: =C26*$D$2 -> 4007264 | E26: =+D26*$D$3 -> 6091041.3
B27: CS08 | C27: 3578221 | D27: =C27*$D$2 -> 3900260.9 | E27: =+D27*$D$3 -> 5928396.6
B28: CS09 | C28: 3503910 | D28: =C28*$D$2 -> 3819261.9 | E28: =+D28*$D$3 -> 5805278.1
B29: CS10 | C29: 3473868 | D29: =C29*$D$2 -> 3786516.1 | E29: =+D29*$D$3 -> 5755504.5
B30: CS11 | C30: 3458389 | D30: =C30*$D$2 -> 3769644 | E30: =+D30*$D$3 -> 5729858.9
B31: CS12 | C31: 3331429 | D31: =C31*$D$2 -> 3631257.6 | E31: =+D31*$D$3 -> 5519511.6
B32: CS13 | C32: 3285910 | D32: =C32*$D$2 -> 3581641.9 | E32: =+D32*$D$3 -> 5444095.7
B33: CS14 | C33: 3126389 | D33: =C33*$D$2 -> 3407764 | E33: =+D33*$D$3 -> 5179801.3
B34: CS15 | C34: 3113429 | D34: =C34*$D$2 -> 3393637.6 | E34: =+D34*$D$3 -> 5158329.2
... B58: CS39 | C58: 500000 | D58: =C58*$D$2 -> 545000 | E58: =+D58*$D$3 -> 828400

Sheet ADM
B2: Nombre del colaborador | C2: Seleccione el Cargo | D2: Código Salario | E2: Cantidad Personal | F2: Periodo de contratación | G2: Meses de contratación | H2: Totales | I2: Costo por Semestre I | J2: Costo por Semestre II | K2: Aprobado SI-NO | L2: Costo Semestre 1 | M2: Costo Semestre 2 | N2: Observaciones | O2: Ejecución | P2: Observaciones de la Ejecución
C3: Elija | F3: Elija | G3: =IF(F3="4 MESES Semestre 1",4,IF(F3="4 MESES Semestre 2",4,IF(F3="8 Meses",4,IF(F3="10 Meses",5,IF(F3="11 Meses",5.5,IF(F3="1 año",6,IF(F3="Indefinido",6,0))))))) -> 0 | H3: =(E3*G3*(IFERROR(VLOOKUP(D3,BaseSalarial!$B$20:$E$58,4,0)/G3,"0"))) -> 0 | I3: =IF(F3="4 MESES Semestre 1",H3*G3,IF(F3="4 MESES Semestre 2",0,IF(F3="8 Meses",H3*G3,IF(F3="10 Meses",H3*G3,IF(F3="11 Meses",H3*G3,IF(F3="1 Año",H3*G3,IF(F3="Indefinido",H3*G3,0))))))) -> 0 | J3: =IF(F3="4 MESES Semestre 1",0,IF(F3="4 MESES Semestre 2",H3*G3,IF(F3="8 Meses",H3*G3,IF(F3="10 Meses",H3*G3,IF(F3="11 Meses",H3*G3,IF(F3="1 Año",H3*G3,IF(F3="Indefinido",H3*G3,0))))))) -> 0 | K3: NO | L3: =IF(K3="SI",I3,IF(K3="NO",0,"Sin comprobar")) -> 0 | M3: =IF(K3="SI",J3,IF(K3="NO",0,"Sin comprobar")) -> 0
C4: Elija | F4: Elija | G4: =IF(F4="4 MESES Semestre 1",4,IF(F4="4 MESES Semestre 2",4,IF(F4="8 Meses",4,IF(F4="10 Meses",5,IF(F4="11 Meses",5.5,IF(F4="1 año",6,IF(F4="Indefinido",6,0))))))) -> 0 | H4: =(E4*G4*(IFERROR(VLOOKUP(D4,BaseSalarial!$B$20:$E$58,4,0)/G4,"0"))) -> 0 | I4: =IF(F4="4 MESES Semestre 1",H4*G4,IF(F4="4 MESES Semestre 2",0,IF(F4="8 Meses",H4*G4,IF(F4="10 Meses",H4*G4,IF(F4="11 Meses",H4*G4,IF(F4="1 Año",H4*G4,IF(F4="Indefinido",H4*G4,0))))))) -> 0 | J4: =IF(F4="4 MESES Semestre 1",0,IF(F4="4 MESES Semestre 2",H4*G4,IF(F4="8 Meses",H4*G4,IF(F4="10 Meses",H4*G4,IF(F4="11 Meses",H4*G4,IF(F4="1 Año",H4*G4,IF(F4="Indefinido",H4*G4,0))))))) -> 0 | K4: NO | L4: =IF(K4="SI",I4,IF(K4="NO",0,"Sin comprobar")) -> 0 | M4: =IF(K4="SI",J4,IF(K4="NO",0,"Sin comprobar")) -> 0
C5: Elija | F5: Elija | G5: =IF(F5="4 MESES Semestre 1",4,IF(F5="4 MESES Semestre 2",4,IF(F5="8 Meses",4,IF(F5="10 Meses",5,IF(F5="11 Meses",5.5,IF(F5="1 año",6,IF(F5="Indefinido",6,0))))))) -> 0 | H5: =(E5*G5*(IFERROR(VLOOKUP(D5,BaseSalarial!$B$20:$E$58,4,0)/G5,"0"))) -> 0 | I5: =IF(F5="4 MESES Semestre 1",H5*G5,IF(F5="4 MESES Semestre 2",0,IF(F5="8 Meses",H5*G5,IF(F5="10 Meses",H5*G5,IF(F5="11 Meses",H5*G5,IF(F5="1 Año",H5*G5,IF(F5="Indefinido",H5*G5,0))))))) -> 0 | J5: =IF(F5="4 MESES Semestre 1",0,IF(F5="4 MESES Semestre 2",H5*G5,IF(F5="8 Meses",H5*G5,IF(F5="10 Meses",H5*G5,IF(F5="11 Meses",H5*G5,IF(F5="1 Año",H5*G5,IF(F5="Indefinido",H5*G5,0))))))) -> 0 | K5: NO | L5: =IF(K5="SI",I5,IF(K5="NO",0,"Sin comprobar")) -> 0 | M5: =IF(K5="SI",J5,IF(K5="NO",0,"Sin comprobar")) -> 0
C6: Elija | F6: Elija | G6: =IF(F6="4 MESES Semestre 1",4,IF(F6="4 MESES Semestre 2",4,IF(F6="8 Meses",4,IF(F6="10 Meses",5,IF(F6="11 Meses",5.5,IF(F6="1 año",6,IF(F6="Indefinido",6,0))))))) -> 0 | H6: =(E6*G6*(IFERROR(VLOOKUP(D6,BaseSalarial!$B$20:$E$58,4,0)/G6,"0"))) -> 0 | I6: =IF(F6="4 MESES Semestre 1",H6*G6,IF(F6="4 MESES Semestre 2",0,IF(F6="8 Meses",H6*G6,IF(F6="10 Meses",H6*G6,IF(F6="11 Meses",H6*G6,IF(F6="1 Año",H6*G6,IF(F6="Indefinido",H6*G6,0))))))) -> 0 | J6: =IF(F6="4 MESES Semestre 1",0,IF(F6="4 MESES Semestre 2",H6*G6,IF(F6="8 Meses",H6*G6,IF(F6="10 Meses",H6*G6,IF(F6="11 Meses",H6*G6,IF(F6="1 Año",H6*G6,IF(F6="Indefinido",H6*G6,0))))))) -> 0 | K6: NO | L6: =IF(K6="SI",I6,IF(K6="NO",0,"Sin comprobar")) -> 0 | M6: =IF(K6="SI",J6,IF(K6="NO",0,"Sin comprobar")) -> 0
C7: Elija | F7: Elija | G7: =IF(F7="4 MESES Semestre 1",4,IF(F7="4 MESES Semestre 2",4,IF(F7="8 Meses",4,IF(F7="10 Meses",5,IF(F7="11 Meses",5.5,IF(F7="1 año",6,IF(F7="Indefinido",6,0))))))) -> 0 | H7: =(E7*G7*(IFERROR(VLOOKUP(D7,BaseSalarial!$B$20:$E$58,4,0)/G7,"0"))) -> 0 | I7: =IF(F7="4 MESES Semestre 1",H7*G7,IF(F7="4 MESES Semestre 2",0,IF(F7="8 Meses",H7*G7,IF(F7="10 Meses",H7*G7,IF(F7="11 Meses",H7*G7,IF(F7="1 Año",H7*G7,IF(F7="Indefinido",H7*G7,0))))))) -> 0 | J7: =IF(F7="4 MESES Semestre 1",0,IF(F7="4 MESES Semestre 2",H7*G7,IF(F7="8 Meses",H7*G7,IF(F7="10 Meses",H7*G7,IF(F7="11 Meses",H7*G7,IF(F7="1 Año",H7*G7,IF(F7="Indefinido",H7*G7,0))))))) -> 0 | K7: NO | L7: =IF(K7="SI",I7,IF(K7="NO",0,"Sin comprobar")) -> 0 | M7: =IF(K7="SI",J7,IF(K7="NO",0,"Sin comprobar")) -> 0
C8: Elija | F8: Elija | G8: =IF(F8="4 MESES Semestre 1",4,IF(F8="4 MESES Semestre 2",4,IF(F8="8 Meses",4,IF(F8="10 Meses",5,IF(F8="11 Meses",5.5,IF(F8="1 año",6,IF(F8="Indefinido",6,0))))))) -> 0 | H8: =(E8*G8*(IFERROR(VLOOKUP(D8,BaseSalarial!$B$20:$E$58,4,0)/G8,"0"))) -> 0 | I8: =IF(F8="4 MESES Semestre 1",H8*G8,IF(F8="4 MESES Semestre 2",0,IF(F8="8 Meses",H8*G8,IF(F8="10 Meses",H8*G8,IF(F8="11 Meses",H8*G8,IF(F8="1 Año",H8*G8,IF(F8="Indefinido",H8*G8,0))))))) -> 0 | J8: =IF(F8="4 MESES Semestre 1",0,IF(F8="4 MESES Semestre 2",H8*G8,IF(F8="8 Meses",H8*G8,IF(F8="10 Meses",H8*G8,IF(F8="11 Meses",H8*G8,IF(F8="1 Año",H8*G8,IF(F8="Indefinido",H8*G8,0))))))) -> 0 | K8: NO | L8: =IF(K8="SI",I8,IF(K8="NO",0,"Sin comprobar")) -> 0 | M8: =IF(K8="SI",J8,IF(K8="NO",0,"Sin comprobar")) -> 0
C9: Elija | F9: Elija | G9: =IF(F9="4 MESES Semestre 1",4,IF(F9="4 MESES Semestre 2",4,IF(F9="8 Meses",4,IF(F9="10 Meses",5,IF(F9="11 Meses",5.5,IF(F9="1 año",6,IF(F9="Indefinido",6,0))))))) -> 0 | H9: =(E9*G9*(IFERROR(VLOOKUP(D9,BaseSalarial!$B$20:$E$58,4,0)/G9,"0"))) -> 0 | I9: =IF(F9="4 MESES Semestre 1",H9*G9,IF(F9="4 MESES Semestre 2",0,IF(F9="8 Meses",H9*G9,IF(F9="10 Meses",H9*G9,IF(F9="11 Meses",H9*G9,IF(F9="1 Año",H9*G9,IF(F9="Indefinido",H9*G9,0))))))) -> 0 | J9: =IF(F9="4 MESES Semestre 1",0,IF(F9="4 MESES Semestre 2",H9*G9,IF(F9="8 Meses",H9*G9,IF(F9="10 Meses",H9*G9,IF(F9="11 Meses",H9*G9,IF(F9="1 Año",H9*G9,IF(F9="Indefinido",H9*G9,0))))))) -> 0 | K9: NO | L9: =IF(K9="SI",I9,IF(K9="NO",0,"Sin comprobar")) -> 0 | M9: =IF(K9="SI",J9,IF(K9="NO",0,"Sin comprobar")) -> 0
C10: Elija | F10: Elija | G10: =IF(F10="4 MESES Semestre 1",4,IF(F10="4 MESES Semestre 2",4,IF(F10="8 Meses",4,IF(F10="10 Meses",5,IF(F10="11 Meses",5.5,IF(F10="1 año",6,IF(F10="Indefinido",6,0))))))) -> 0 | H10: =(E10*G10*(IFERROR(VLOOKUP(D10,BaseSalarial!$B$20:$E$58,4,0)/G10,"0"))) -> 0 | I10: =IF(F10="4 MESES Semestre 1",H10*G10,IF(F10="4 MESES Semestre 2",0,IF(F10="8 Meses",H10*G10,IF(F10="10 Meses",H10*G10,IF(F10="11 Meses",H10*G10,IF(F10="1 Año",H10*G10,IF(F10="Indefinido",H10*G10,0))))))) -> 0 | J10: =IF(F10="4 MESES Semestre 1",0,IF(F10="4 MESES Semestre 2",H10*G10,IF(F10="8 Meses",H10*G10,IF(F10="10 Meses",H10*G10,IF(F10="11 Meses",H10*G10,IF(F10="1 Año",H10*G10,IF(F10="Indefinido",H10*G10,0))))))) -> 0 | K10: NO | L10: =IF(K10="SI",I10,IF(K10="NO",0,"Sin comprobar")) -> 0 | M10: =IF(K10="SI",J10,IF(K10="NO",0,"Sin comprobar")) -> 0
C11: Elija | F11: Elija | G11: =IF(F11="4 MESES Semestre 1",4,IF(F11="4 MESES Semestre 2",4,IF(F11="8 Meses",4,IF(F11="10 Meses",5,IF(F11="11 Meses",5.5,IF(F11="1 año",6,IF(F11="Indefinido",6,0))))))) -> 0 | H11: =(E11*G11*(IFERROR(VLOOKUP(D11,BaseSalarial!$B$20:$E$58,4,0)/G11,"0"))) -> 0 | I11: =IF(F11="4 MESES Semestre 1",H11*G11,IF(F11="4 MESES Semestre 2",0,IF(F11="8 Meses",H11*G11,IF(F11="10 Meses",H11*G11,IF(F11="11 Meses",H11*G11,IF(F11="1 Año",H11*G11,IF(F11="Indefinido",H11*G11,0))))))) -> 0 | J11: =IF(F11="4 MESES Semestre 1",0,IF(F11="4 MESES Semestre 2",H11*G11,IF(F11="8 Meses",H11*G11,IF(F11="10 Meses",H11*G11,IF(F11="11 Meses",H11*G11,IF(F11="1 Año",H11*G11,IF(F11="Indefinido",H11*G11,0))))))) -> 0 | K11: NO | L11: =IF(K11="SI",I11,IF(K11="NO",0,"Sin comprobar")) -> 0 | M11: =IF(K11="SI",J11,IF(K11="NO",0,"Sin comprobar")) -> 0
C12: Elija | F12: Elija | G12: =IF(F12="4 MESES Semestre 1",4,IF(F12="4 MESES Semestre 2",4,IF(F12="8 Meses",4,IF(F12="10 Meses",5,IF(F12="11 Meses",5.5,IF(F12="1 año",6,IF(F12="Indefinido",6,0))))))) -> 0 | H12: =(E12*G12*(IFERROR(VLOOKUP(D12,BaseSalarial!$B$20:$E$58,4,0)/G12,"0"))) -> 0 | I12: =IF(F12="4 MESES Semestre 1",H12*G12,IF(F12="4 MESES Semestre 2",0,IF(F12="8 Meses",H12*G12,IF(F12="10 Meses",H12*G12,IF(F12="11 Meses",H12*G12,IF(F12="1 Año",H12*G12,IF(F12="Indefinido",H12*G12,0))))))) -> 0 | J12: =IF(F12="4 MESES Semestre 1",0,IF(F12="4 MESES Semestre 2",H12*G12,IF(F12="8 Meses",H12*G12,IF(F12="10 Meses",H12*G12,IF(F12="11 Meses",H12*G12,IF(F12="1 Año",H12*G12,IF(F12="Indefinido",H12*G12,0))))))) -> 0 | K12: NO | L12: =IF(K12="SI",I12,IF(K12="NO",0,"Sin comprobar")) -> 0 | M12: =IF(K12="SI",J12,IF(K12="NO",0,"Sin comprobar")) -> 0
C13: Elija | F13: Elija | G13: =IF(F13="4 MESES Semestre 1",4,IF(F13="4 MESES Semestre 2",4,IF(F13="8 Meses",4,IF(F13="10 Meses",5,IF(F13="11 Meses",5.5,IF(F13="1 año",6,IF(F13="Indefinido",6,0))))))) -> 0 | H13: =(E13*G13*(IFERROR(VLOOKUP(D13,BaseSalarial!$B$20:$E$58,4,0)/G13,"0"))) -> 0 | I13: =IF(F13="4 MESES Semestre 1",H13*G13,IF(F13="4 MESES Semestre 2",0,IF(F13="8 Meses",H13*G13,IF(F13="10 Meses",H13*G13,IF(F13="11 Meses",H13*G13,IF(F13="1 Año",H13*G13,IF(F13="Indefinido",H13*G13,0))))))) -> 0 | J13: =IF(F13="4 MESES Semestre 1",0,IF(F13="4 MESES Semestre 2",H13*G13,IF(F13="8 Meses",H13*G13,IF(F13="10 Meses",H13*G13,IF(F13="11 Meses",H13*G13,IF(F13="1 Año",H13*G13,IF(F13="Indefinido",H13*G13,0))))))) -> 0 | K13: NO | L13: =IF(K13="SI",I13,IF(K13="NO",0,"Sin comprobar")) -> 0 | M13: =IF(K13="SI",J13,IF(K13="NO",0,"Sin comprobar")) -> 0
C14: Elija | F14: Elija | G14: =IF(F14="4 MESES Semestre 1",4,IF(F14="4 MESES Semestre 2",4,IF(F14="8 Meses",4,IF(F14="10 Meses",5,IF(F14="11 Meses",5.5,IF(F14="1 año",6,IF(F14="Indefinido",6,0))))))) -> 0 | H14: =(E14*G14*(IFERROR(VLOOKUP(D14,BaseSalarial!$B$20:$E$58,4,0)/G14,"0"))) -> 0 | I14: =IF(F14="4 MESES Semestre 1",H14*G14,IF(F14="4 MESES Semestre 2",0,IF(F14="8 Meses",H14*G14,IF(F14="10 Meses",H14*G14,IF(F14="11 Meses",H14*G14,IF(F14="1 Año",H14*G14,IF(F14="Indefinido",H14*G14,0))))))) -> 0 | J14: =IF(F14="4 MESES Semestre 1",0,IF(F14="4 MESES Semestre 2",H14*G14,IF(F14="8 Meses",H14*G14,IF(F14="10 Meses",H14*G14,IF(F14="11 Meses",H14*G14,IF(F14="1 Año",H14*G14,IF(F14="Indefinido",H14*G14,0))))))) -> 0 | K14: NO | L14: =IF(K14="SI",I14,IF(K14="NO",0,"Sin comprobar")) -> 0 | M14: =IF(K14="SI",J14,IF(K14="NO",0,"Sin comprobar")) -> 0
... C17: Elija | F17: Elija | G17: =IF(F17="4 MESES Semestre 1",4,IF(F17="4 MESES Semestre 2",4,IF(F17="8 Meses",4,IF(F17="10 Meses",5,IF(F17="11 Meses",5.5,IF(F17="1 año",6,IF(F17="Indefinido",6,0))))))) -> 0 | H17: =(E17*G17*(IFERROR(VLOOKUP(D17,BaseSalarial!$B$20:$E$58,4,0)/G17,"0"))) -> 0 | I17: =IF(F17="4 MESES Semestre 1",H17*G17,IF(F17="4 MESES Semestre 2",0,IF(F17="8 Meses",H17*G17,IF(F17="10 Meses",H17*G17,IF(F17="11 Meses",H17*G17,IF(F17="1 Año",H17*G17,IF(F17="Indefinido",H17*G17,0))))))) -> 0 | J17: =IF(F17="4 MESES Semestre 1",0,IF(F17="4 MESES Semestre 2",H17*G17,IF(F17="8 Meses",H17*G17,IF(F17="10 Meses",H17*G17,IF(F17="11 Meses",H17*G17,IF(F17="1 Año",H17*G17,IF(F17="Indefinido",H17*G17,0))))))) -> 0 | K17: NO | L17: =IF(K17="SI",I17,IF(K17="NO",0,"Sin comprobar")) -> 0 | M17: =IF(K17="SI",J17,IF(K17="NO",0,"Sin comprobar")) -> 0
I18: =SUM(I3:I17) -> 0 | J18: =SUM(J3:J17) -> 0 | L18: =SUM(L3:L17) -> 0 | M18: =SUM(M3:M17) -> 0 | O18: =SUM(O3:O17) -> 0

Sheet PRE
E1: Docentes Tiempo Completo
B2: Cantidad de Docentes | C2: Cualificación | D2: Función(Buscar) | E2: Periodo de contratación | F2: Costo por Semestre I | G2: Costo por Semestre II | H2: Aprobado SI-NO | I2: Costo Semestre 1 | J2: Costo Semestre 2 | K2: Observaciones | L2: Ejecución | M2: Observaciones de la Ejecución
B3: 0 | C3: Elija | D3: =IFERROR(VLOOKUP(C3,BaseSalarial!$B$13:$E$16,4,FALSE),0) -> 0 | E3: Elija | F3: =B3*(IF(E3="4 MESES Semestre 1",D3*4,IF(E3="4 MESES Semestre 2",0,IF(E3="8 Meses",D3*4,IF(E3="10 Meses",D3*5,IF(E3="11 Meses",D3*5.5,IF(E3="1 Año",D3*6,IF(E3="Indefinido",D3*6,0)))))))) -> 0 | G3: =B3*(IF(E3="4 MESES Semestre 1",0,IF(E3="4 MESES Semestre 2",D3*4,IF(E3="8 Meses",D3*4,IF(E3="10 Meses",D3*5,IF(E3="11 Meses",D3*5.5,IF(E3="1 Año",D3*6,IF(E3="Indefinido",D3*6,0)))))))) -> 0 | H3: NO | I3: =IF(H3="SI",F3,IF(H3="NO",0,"Sin comprobar")) -> 0 | J3: =IF(H3="SI",G3,IF(H3="NO",0,"Sin comprobar")) -> 0
B4: 0 | C4: Elija | D4: =IFERROR(VLOOKUP(C4,BaseSalarial!$B$13:$E$16,4,FALSE),0) -> 0 | E4: Elija | F4: =B4*(IF(E4="4 MESES Semestre 1",D4*4,IF(E4="4 MESES Semestre 2",0,IF(E4="8 Meses",D4*4,IF(E4="10 Meses",D4*5,IF(E4="11 Meses",D4*5.5,IF(E4="1 Año",D4*6,IF(E4="Indefinido",D4*6,0)))))))) -> 0 | G4: =B4*(IF(E4="4 MESES Semestre 1",0,IF(E4="4 MESES Semestre 2",D4*4,IF(E4="8 Meses",D4*4,IF(E4="10 Meses",D4*5,IF(E4="11 Meses",D4*5.5,IF(E4="1 Año",D4*6,IF(E4="Indefinido",D4*6,0)))))))) -> 0 | H4: NO | I4: =IF(H4="SI",F4,IF(H4="NO",0,"Sin comprobar")) -> 0 | J4: =IF(H4="SI",G4,IF(H4="NO",0,"Sin comprobar")) -> 0
B5: 0 | C5: Elija | D5: =IFERROR(VLOOKUP(C5,BaseSalarial!$B$13:$E$16,4,FALSE),0) -> 0 | E5: Elija | F5: =B5*(IF(E5="4 MESES Semestre 1",D5*4,IF(E5="4 MESES Semestre 2",0,IF(E5="8 Meses",D5*4,IF(E5="10 Meses",D5*5,IF(E5="11 Meses",D5*5.5,IF(E5="1 Año",D5*6,IF(E5="Indefinido",D5*6,0)))))))) -> 0 | G5: =B5*(IF(E5="4 MESES Semestre 1",0,IF(E5="4 MESES Semestre 2",D5*4,IF(E5="8 Meses",D5*4,IF(E5="10 Meses",D5*5,IF(E5="11 Meses",D5*5.5,IF(E5="1 Año",D5*6,IF(E5="Indefinido",D5*6,0)))))))) -> 0 | H5: NO | I5: =IF(H5="SI",F5,IF(H5="NO",0,"Sin comprobar")) -> 0 | J5: =IF(H5="SI",G5,IF(H5="NO",0,"Sin comprobar")) -> 0
B6: 0 | C6: Elija | D6: =IFERROR(VLOOKUP(C6,BaseSalarial!$B$13:$E$16,4,FALSE),0) -> 0 | E6: Elija | F6: =B6*(IF(E6="4 MESES Semestre 1",D6*4,IF(E6="4 MESES Semestre 2",0,IF(E6="8 Meses",D6*4,IF(E6="10 Meses",D6*5,IF(E6="11 Meses",D6*5.5,IF(E6="1 Año",D6*6,IF(E6="Indefinido",D6*6,0)))))))) -> 0 | G6: =B6*(IF(E6="4 MESES Semestre 1",0,IF(E6="4 MESES Semestre 2",D6*4,IF(E6="8 Meses",D6*4,IF(E6="10 Meses",D6*5,IF(E6="11 Meses",D6*5.5,IF(E6="1 Año",D6*6,IF(E6="Indefinido",D6*6,0)))))))) -> 0 | H6: NO | I6: =IF(H6="SI",F6,IF(H6="NO",0,"Sin comprobar")) -> 0 | J6: =IF(H6="SI",G6,IF(H6="NO",0,"Sin comprobar")) -> 0
B7: 0 | C7: Elija | D7: =IFERROR(VLOOKUP(C7,BaseSalarial!$B$13:$E$16,4,FALSE),0) -> 0 | E7: Elija | F7: =B7*(IF(E7="4 MESES Semestre 1",D7*4,IF(E7="4 MESES Semestre 2",0,IF(E7="8 Meses",D7*4,IF(E7="10 Meses",D7*5,IF(E7="11 Meses",D7*5.5,IF(E7="1 Año",D7*6,IF(E7="Indefinido",D7*6,0)))))))) -> 0 | G7: =B7*(IF(E7="4 MESES Semestre 1",0,IF(E7="4 MESES Semestre 2",D7*4,IF(E7="8 Meses",D7*4,IF(E7="10 Meses",D7*5,IF(E7="11 Meses",D7*5.5,IF(E7="1 Año",D7*6,IF(E7="Indefinido",D7*6,0)))))))) -> 0 | H7: NO | I7: =IF(H7="SI",F7,IF(H7="NO",0,"Sin comprobar")) -> 0 | J7: =IF(H7="SI",G7,IF(H7="NO",0,"Sin comprobar")) -> 0
B8: 0 | C8: Elija | D8: =IFERROR(VLOOKUP(C8,BaseSalarial!$B$13:$E$16,4,FALSE),0) -> 0 | E8: Elija | F8: =B8*(IF(E8="4 MESES Semestre 1",D8*4,IF(E8="4 MESES Semestre 2",0,IF(E8="8 Meses",D8*4,IF(E8="10 Meses",D8*5,IF(E8="11 Meses",D8*5.5,IF(E8="1 Año",D8*6,IF(E8="Indefinido",D8*6,0)))))))) -> 0 | G8: =B8*(IF(E8="4 MESES Semestre 1",0,IF(E8="4 MESES Semestre 2",D8*4,IF(E8="8 Meses",D8*4,IF(E8="10 Meses",D8*5,IF(E8="11 Meses",D8*5.5,IF(E8="1 Año",D8*6,IF(E8="Indefinido",D8*6,0)))))))) -> 0 | H8: NO | I8: =IF(H8="SI",F8,IF(H8="NO",0,"Sin comprobar")) -> 0 | J8: =IF(H8="SI",G8,IF(H8="NO",0,"Sin comprobar")) -> 0
B9: 0 | C9: Elija | D9: =IFERROR(VLOOKUP(C9,BaseSalarial!$B$13:$E$16,4,FALSE),0) -> 0 | E9: Elija | F9: =B9*(IF(E9="4 MESES Semestre 1",D9*4,IF(E9="4 MESES Semestre 2",0,IF(E9="8 Meses",D9*4,IF(E9="10 Meses",D9*5,IF(E9="11 Meses",D9*5.5,IF(E9="1 Año",D9*6,IF(E9="Indefinido",D9*6,0)))))))) -> 0 | G9: =B9*(IF(E9="4 MESES Semestre 1",0,IF(E9="4 MESES Semestre 2",D9*4,IF(E9="8 Meses",D9*4,IF(E9="10 Meses",D9*5,IF(E9="11 Meses",D9*5.5,IF(E9="1 Año",D9*6,IF(E9="Indefinido",D9*6,0)))))))) -> 0 | H9: NO | I9: =IF(H9="SI",F9,IF(H9="NO",0,"Sin comprobar")) -> 0 | J9: =IF(H9="SI",G9,IF(H9="NO",0,"Sin comprobar")) -> 0
B10: 0 | C10: Elija | D10: =IFERROR(VLOOKUP(C10,BaseSalarial!$B$13:$E$16,4,FALSE),0) -> 0 | E10: Elija | F10: =B10*(IF(E10="4 MESES Semestre 1",D10*4,IF(E10="4 MESES Semestre 2",0,IF(E10="8 Meses",D10*4,IF(E10="10 Meses",D10*5,IF(E10="11 Meses",D10*5.5,IF(E10="1 Año",D10*6,IF(E10="Indefinido",D10*6,0)))))))) -> 0 | G10: =B10*(IF(E10="4 MESES Semestre 1",0,IF(E10="4 MESES Semestre 2",D10*4,IF(E10="8 Meses",D10*4,IF(E10="10 Meses",D10*5,IF(E10="11 Meses",D10*5.5,IF(E10="1 Año",D10*6,IF(E10="Indefinido",D10*6,0)))))))) -> 0 | H10: NO | I10: =IF(H10="SI",F10,IF(H10="NO",0,"Sin comprobar")) -> 0 | J10: =IF(H10="SI",G10,IF(H10="NO",0,"Sin comprobar")) -> 0
B11: 0 | C11: Elija | D11: =IFERROR(VLOOKUP(C11,BaseSalarial!$B$13:$E$16,4,FALSE),0) -> 0 | E11: Elija | F11: =B11*(IF(E11="4 MESES Semestre 1",D11*4,IF(E11="4 MESES Semestre 2",0,IF(E11="8 Meses",D11*4,IF(E11="10 Meses",D11*5,IF(E11="11 Meses",D11*5.5,IF(E11="1 Año",D11*6,IF(E11="Indefinido",D11*6,0)))))))) -> 0 | G11: =B11*(IF(E11="4 MESES Semestre 1",0,IF(E11="4 MESES Semestre 2",D11*4,IF(E11="8 Meses",D11*4,IF(E11="10 Meses",D11*5,IF(E11="11 Meses",D11*5.5,IF(E11="1 Año",D11*6,IF(E11="Indefinido",D11*6,0)))))))) -> 0 | H11: NO | I11: =IF(H11="SI",F11,IF(H11="NO",0,"Sin comprobar")) -> 0 | J11: =IF(H11="SI",G11,IF(H11="NO",0,"Sin comprobar")) -> 0
B12: 0 | C12: Elija | D12: =IFERROR(VLOOKUP(C12,BaseSalarial!$B$13:$E$16,4,FALSE),0) -> 0 | E12: Elija | F12: =B12*(IF(E12="4 MESES Semestre 1",D12*4,IF(E12="4 MESES Semestre 2",0,IF(E12="8 Meses",D12*4,IF(E12="10 Meses",D12*5,IF(E12="11 Meses",D12*5.5,IF(E12="1 Año",D12*6,IF(E12="Indefinido",D12*6,0)))))))) -> 0 | G12: =B12*(IF(E12="4 MESES Semestre 1",0,IF(E12="4 MESES Semestre 2",D12*4,IF(E12="8 Meses",D12*4,IF(E12="10 Meses",D12*5,IF(E12="11 Meses",D12*5.5,IF(E12="1 Año",D12*6,IF(E12="Indefinido",D12*6,0)))))))) -> 0 | H12: NO | I12: =IF(H12="SI",F12,IF(H12="NO",0,"Sin comprobar")) -> 0 | J12: =IF(H12="SI",G12,IF(H12="NO",0,"Sin comprobar")) -> 0
B13: 0 | C13: Elija | D13: =IFERROR(VLOOKUP(C13,BaseSalarial!$B$13:$E$16,4,FALSE),0) -> 0 | E13: Elija | F13: =B13*(IF(E13="4 MESES Semestre 1",D13*4,IF(E13="4 MESES Semestre 2",0,IF(E13="8 Meses",D13*4,IF(E13="10 Meses",D13*5,IF(E13="11 Meses",D13*5.5,IF(E13="1 Año",D13*6,IF(E13="Indefinido",D13*6,0)))))))) -> 0 | G13: =B13*(IF(E13="4 MESES Semestre 1",0,IF(E13="4 MESES Semestre 2",D13*4,IF(E13="8 Meses",D13*4,IF(E13="10 Meses",D13*5,IF(E13="11 Meses",D13*5.5,IF(E13="1 Año",D13*6,IF(E13="Indefinido",D13*6,0)))))))) -> 0 | H13: NO | I13: =IF(H13="SI",F13,IF(H13="NO",0,"Sin comprobar")) -> 0 | J13: =IF(H13="SI",G13,IF(H13="NO",0,"Sin comprobar")) -> 0
B14: 0 | C14: Elija | D14: =IFERROR(VLOOKUP(C14,BaseSalarial!$B$13:$E$16,4,FALSE),0) -> 0 | E14: Elija | F14: =B14*(IF(E14="4 MESES Semestre 1",D14*4,IF(E14="4 MESES Semestre 2",0,IF(E14="8 Meses",D14*4,IF(E14="10 Meses",D14*5,IF(E14="11 Meses",D14*5.5,IF(E14="1 Año",D14*6,IF(E14="Indefinido",D14*6,0)))))))) -> 0 | G14: =B14*(IF(E14="4 MESES Semestre 1",0,IF(E14="4 MESES Semestre 2",D14*4,IF(E14="8 Meses",D14*4,IF(E14="10 Meses",D14*5,IF(E14="11 Meses",D14*5.5,IF(E14="1 Año",D14*6,IF(E14="Indefinido",D14*6,0)))))))) -> 0 | H14: NO | I14: =IF(H14="SI",F14,IF(H14="NO",0,"Sin comprobar")) -> 0 | J14: =IF(H14="SI",G14,IF(H14="NO",0,"Sin comprobar")) -> 0
... B17: 0 | C17: Elija | D17: =IFERROR(VLOOKUP(C17,BaseSalarial!$B$13:$E$16,4,FALSE),0) -> 0 | E17: Elija | F17: =B17*(IF(E17="4 MESES Semestre 1",D17*4,IF(E17="4 MESES Semestre 2",0,IF(E17="8 Meses",D17*4,IF(E17="10 Meses",D17*5,IF(E17="11 Meses",D17*5.5,IF(E17="1 Año",D17*6,IF(E17="Indefinido",D17*6,0)))))))) -> 0 | G17: =B17*(IF(E17="4 MESES Semestre 1",0,IF(E17="4 MESES Semestre 2",D17*4,IF(E17="8 Meses",D17*4,IF(E17="10 Meses",D17*5,IF(E17="11 Meses",D17*5.5,IF(E17="1 Año",D17*6,IF(E17="Indefinido",D17*6,0)))))))) -> 0 | H17: NO | I17: =IF(H17="SI",F17,IF(H17="NO",0,"Sin comprobar")) -> 0 | J17: =IF(H17="SI",G17,IF(H17="NO",0,"Sin comprobar")) -> 0
F18: =SUM(F3:F17) -> 0 | G18: =SUM(G3:G17) -> 0 | I18: =SUM(I3:I17) -> 0 | J18: =SUM(J3:J17) -> 0 | L18: =SUM(L3:L17) -> 0
E20: Docentes Medio Tiempo
B22: Cantidad de Docentes | C22: Cualificación | D22: Función(Buscar) | E22: Periodo de contratación | F22: Costo por Semestre I | G22: Costo por Semestre II | H22: Aprobado SI-NO | I22: Costo Semestre 1 | J22: Costo Semestre 2 | K22: Observaciones | L22: Ejecución | M22: Observaciones de la Ejecución
B23: 0 | C23: Elija | D23: =IFERROR(VLOOKUP(C23,BaseSalarial!$B$13:$J$16,8,FALSE),0) -> 0 | E23: Elija | F23: =B23*(IF(E23="4 MESES Semestre 1",D23*4,IF(E23="4 MESES Semestre 2",0,IF(E23="8 Meses",D23*4,IF(E23="10 Meses",D23*5,IF(E23="11 Meses",D23*5.5,IF(E23="1 Año",D23*6,IF(E23="Indefinido",D23*6,0)))))))) -> 0 | G23: =B23*(IF(E23="4 MESES Semestre 1",0,IF(E23="4 MESES Semestre 2",D23*4,IF(E23="8 Meses",D23*4,IF(E23="10 Meses",D23*5,IF(E23="11 Meses",D23*5.5,IF(E23="1 Año",D23*6,IF(E23="Indefinido",D23*6,0)))))))) -> 0 | H23: NO | I23: =IF(H23="SI",F23,IF(H23="NO",0,"Sin comprobar")) -> 0 | J23: =IF(H23="SI",G23,IF(H23="NO",0,"Sin comprobar")) -> 0
B24: 0 | C24: Elija | D24: =IFERROR(VLOOKUP(C24,BaseSalarial!$B$13:$J$16,8,FALSE),0) -> 0 | E24: Elija | F24: =B24*(IF(E24="4 MESES Semestre 1",D24*4,IF(E24="4 MESES Semestre 2",0,IF(E24="8 Meses",D24*4,IF(E24="10 Meses",D24*5,IF(E24="11 Meses",D24*5.5,IF(E24="1 Año",D24*6,IF(E24="Indefinido",D24*6,0)))))))) -> 0 | G24: =B24*(IF(E24="4 MESES Semestre 1",0,IF(E24="4 MESES Semestre 2",D24*4,IF(E24="8 Meses",D24*4,IF(E24="10 Meses",D24*5,IF(E24="11 Meses",D24*5.5,IF(E24="1 Año",D24*6,IF(E24="Indefinido",D24*6,0)))))))) -> 0 | H24: NO | I24: =IF(H24="SI",F24,IF(H24="NO",0,"Sin comprobar")) -> 0 | J24: =IF(H24="SI",G24,IF(H24="NO",0,"Sin comprobar")) -> 0
B25: 0 | C25: Elija | D25: =IFERROR(VLOOKUP(C25,BaseSalarial!$B$13:$J$16,8,FALSE),0) -> 0 | E25: Elija | F25: =B25*(IF(E25="4 MESES Semestre 1",D25*4,IF(E25="4 MESES Semestre 2",0,IF(E25="8 Meses",D25*4,IF(E25="10 Meses",D25*5,IF(E25="11 Meses",D25*5.5,IF(E25="1 Año",D25*6,IF(E25="Indefinido",D25*6,0)))))))) -> 0 | G25: =B25*(IF(E25="4 MESES Semestre 1",0,IF(E25="4 MESES Semestre 2",D25*4,IF(E25="8 Meses",D25*4,IF(E25="10 Meses",D25*5,IF(E25="11 Meses",D25*5.5,IF(E25="1 Año",D25*6,IF(E25="Indefinido",D25*6,0)))))))) -> 0 | H25: NO | I25: =IF(H25="SI",F25,IF(H25="NO",0,"Sin comprobar")) -> 0 | J25: =IF(H25="SI",G25,IF(H25="NO",0,"Sin comprobar")) -> 0
B26: 0 | C26: Elija | D26: =IFERROR(VLOOKUP(C26,BaseSalarial!$B$13:$J$16,8,FALSE),0) -> 0 | E26: Elija | F26: =B26*(IF(E26="4 MESES Semestre 1",D26*4,IF(E26="4 MESES Semestre 2",0,IF(E26="8 Meses",D26*4,IF(E26="10 Meses",D26*5,IF(E26="11 Meses",D26*5.5,IF(E26="1 Año",D26*6,IF(E26="Indefinido",D26*6,0)))))))) -> 0 | G26: =B26*(IF(E26="4 MESES Semestre 1",0,IF(E26="4 MESES Semestre 2",D26*4,IF(E26="8 Meses",D26*4,IF(E26="10 Meses",D26*5,IF(E26="11 Meses",D26*5.5,IF(E26="1 Año",D26*6,IF(E26="Indefinido",D26*6,0)))))))) -> 0 | H26: NO | I26: =IF(H26="SI",F26,IF(H26="NO",0,"Sin comprobar")) -> 0 | J26: =IF(H26="SI",G26,IF(H26="NO",0,"Sin comprobar")) -> 0
B27: 0 | C27: Elija | D27: =IFERROR(VLOOKUP(C27,BaseSalarial!$B$13:$J$16,8,FALSE),0) -> 0 | E27: Elija | F27: =B27*(IF(E27="4 MESES Semestre 1",D27*4,IF(E27="4 MESES Semestre 2",0,IF(E27="8 Meses",D27*4,IF(E27="10 Meses",D27*5,IF(E27="11 Meses",D27*5.5,IF(E27="1 Año",D27*6,IF(E27="Indefinido",D27*6,0)))))))) -> 0 | G27: =B27*(IF(E27="4 MESES Semestre 1",0,IF(E27="4 MESES Semestre 2",D27*4,IF(E27="8 Meses",D27*4,IF(E27="10 Meses",D27*5,IF(E27="11 Meses",D27*5.5,IF(E27="1 Año",D27*6,IF(E27="Indefinido",D27*6,0)))))))) -> 0 | H27: NO | I27: =IF(H27="SI",F27,IF(H27="NO",0,"Sin comprobar")) -> 0 | J27: =IF(H27="SI",G27,IF(H27="NO",0,"Sin comprobar")) -> 0
B28: 0 | C28: Elija | D28: =IFERROR(VLOOKUP(C28,BaseSalarial!$B$13:$J$16,8,FALSE),0) -> 0 | E28: Elija | F28: =B28*(IF(E28="4 MESES Semestre 1",D28*4,IF(E28="4 MESES Semestre 2",0,IF(E28="8 Meses",D28*4,IF(E28="10 Meses",D28*5,IF(E28="11 Meses",D28*5.5,IF(E28="1 Año",D28*6,IF(E28="Indefinido",D28*6,0)))))))) -> 0 | G28: =B28*(IF(E28="4 MESES Semestre 1",0,IF(E28="4 MESES Semestre 2",D28*4,IF(E28="8 Meses",D28*4,IF(E28="10 Meses",D28*5,IF(E28="11 Meses",D28*5.5,IF(E28="1 Año",D28*6,IF(E28="Indefinido",D28*6,0)))))))) -> 0 | H28: NO | I28: =IF(H28="SI",F28,IF(H28="NO",0,"Sin comprobar")) -> 0 | J28: =IF(H28="SI",G28,IF(H28="NO",0,"Sin comprobar")) -> 0
B29: 0 | C29: Elija | D29: =IFERROR(VLOOKUP(C29,BaseSalarial!$B$13:$J$16,8,FALSE),0) -> 0 | E29: Elija | F29: =B29*(IF(E29="4 MESES Semestre 1",D29*4,IF(E29="4 MESES Semestre 2",0,IF(E29="8 Meses",D29*4,IF(E29="10 Meses",D29*5,IF(E29="11 Meses",D29*5.5,IF(E29="1 Año",D29*6,IF(E29="Indefinido",D29*6,0)))))))) -> 0 | G29: =B29*(IF(E29="4 MESES Semestre 1",0,IF(E29="4 MESES Semestre 2",D29*4,IF(E29="8 Meses",D29*4,IF(E29="10 Meses",D29*5,IF(E29="11 Meses",D29*5.5,IF(E29="1 Año",D29*6,IF(E29="Indefinido",D29*6,0)))))))) -> 0 | H29: NO | I29: =IF(H29="SI",F29,IF(H29="NO",0,"Sin comprobar")) -> 0 | J29: =IF(H29="SI",G29,IF(H29="NO",0,"Sin comprobar")) -> 0
B30: 0 | C30: Elija | D30: =IFERROR(VLOOKUP(C30,BaseSalarial!$B$13:$J$16,8,FALSE),0) -> 0 | E30: Elija | F30: =B30*(IF(E30="4 MESES Semestre 1",D30*4,IF(E30="4 MESES Semestre 2",0,IF(E30="8 Meses",D30*4,IF(E30="10 Meses",D30*5,IF(E30="11 Meses",D30*5.5,IF(E30="1 Año",D30*6,IF(E30="Indefinido",D30*6,0)))))))) -> 0 | G30: =B30*(IF(E30="4 MESES Semestre 1",0,IF(E30="4 MESES Semestre 2",D30*4,IF(E30="8 Meses",D30*4,IF(E30="10 Meses",D30*5,IF(E30="11 Meses",D30*5.5,IF(E30="1 Año",D30*6,IF(E30="Indefinido",D30*6,0)))))))) -> 0 | H30: NO | I30: =IF(H30="SI",F30,IF(H30="NO",0,"Sin comprobar")) -> 0 | J30: =IF(H30="SI",G30,IF(H30="NO",0,"Sin comprobar")) -> 0
B31: 0 | C31: Elija | D31: =IFERROR(VLOOKUP(C31,BaseSalarial!$B$13:$J$16,8,FALSE),0) -> 0 | E31: Elija | F31: =B31*(IF(E31="4 MESES Semestre 1",D31*4,IF(E31="4 MESES Semestre 2",0,IF(E31="8 Meses",D31*4,IF(E31="10 Meses",D31*5,IF(E31="11 Meses",D31*5.5,IF(E31="1 Año",D31*6,IF(E31="Indefinido",D31*6,0)))))))) -> 0 | G31: =B31*(IF(E31="4 MESES Semestre 1",0,IF(E31="4 MESES Semestre 2",D31*4,IF(E31="8 Meses",D31*4,IF(E31="10 Meses",D31*5,IF(E31="11 Meses",D31*5.5,IF(E31="1 Año",D31*6,IF(E31="Indefinido",D31*6,0)))))))) -> 0 | H31: NO | I31: =IF(H31="SI",F31,IF(H31="NO",0,"Sin comprobar")) -> 0 | J31: =IF(H31="SI",G31,IF(H31="NO",0,"Sin comprobar")) -> 0
B32: 0 | C32: Elija | D32: =IFERROR(VLOOKUP(C32,BaseSalarial!$B$13:$J$16,8,FALSE),0) -> 0 | E32: Elija | F32: =B32*(IF(E32="4 MESES Semestre 1",D32*4,IF(E32="4 MESES Semestre 2",0,IF(E32="8 Meses",D32*4,IF(E32="10 Meses",D32*5,IF(E32="11 Meses",D32*5.5,IF(E32="1 Año",D32*6,IF(E32="Indefinido",D32*6,0)))))))) -> 0 | G32: =B32*(IF(E32="4 MESES Semestre 1",0,IF(E32="4 MESES Semestre 2",D32*4,IF(E32="8 Meses",D32*4,IF(E32="10 Meses",D32*5,IF(E32="11 Meses",D32*5.5,IF(E32="1 Año",D32*6,IF(E32="Indefinido",D32*6,0)))))))) -> 0 | H32: NO | I32: =IF(H32="SI",F32,IF(H32="NO",0,"Sin comprobar")) -> 0 | J32: =IF(H32="SI",G32,IF(H32="NO",0,"Sin comprobar")) -> 0
F33: =SUM(F23:F32) -> 0 | G33: =SUM(G23:G32) -> 0 | I33: =SUM(I23:I32) -> 0 | J33: =SUM(J23:J32) -> 0 | L33: =SUM(L23:L32) -> 0
E35: Docentes Tiempo Parcial / Hora Cátedra
B37: Máximo 8 Horas | C37: Valor semanal | D37: Función(Buscar) | E37: Periodo de contratación | F37: Costo por Semestre I | G37: Costo por Semestre II | H37: Aprobado SI-NO | I37: Costo Semestre 1 | J37: Costo Semestre 2 | K37: Observaciones | L37: Ejecución | M37: Observaciones de la Ejecución
C38: =IF(B38>8,0,B38*BaseSalarial!$D$9) -> 0 | D38: =IF(C38<=(BaseSalarial!$D$9*8),C38,0)*4 -> 0 | E38: Elija | F38: =IF(E38="4 MESES Semestre 1",D38*4,IF(E38="4 MESES Semestre 2",0,IF(E38="8 Meses",D38*4,IF(E38="10 Meses",D38*5,IF(E38="11 Meses",D38*5.5,IF(E38="1 Año",D38*6,0)))))) -> 0 | G38: =IF(E38="4 MESES Semestre 1",0,IF(E38="4 MESES Semestre 2",D38*4,IF(E38="8 Meses",D38*4,IF(E38="10 Meses",D38*5,IF(E38="11 Meses",D38*5.5,IF(E38="1 Año",D38*6,0)))))) -> 0 | H38: NO | I38: =IF(H38="SI",F38,IF(H38="NO",0,"Sin comprobar")) -> 0 | J38: =IF(H38="SI",G38,IF(H38="NO",0,"Sin comprobar")) -> 0
C39: =IF(B39>8,0,B39*BaseSalarial!$D$9) -> 0 | D39: =IF(C39<=(BaseSalarial!$D$9*8),C39,0)*4 -> 0 | E39: Elija | F39: =IF(E39="4 MESES Semestre 1",D39*4,IF(E39="4 MESES Semestre 2",0,IF(E39="8 Meses",D39*4,IF(E39="10 Meses",D39*5,IF(E39="11 Meses",D39*5.5,IF(E39="1 Año",D39*6,0)))))) -> 0 | G39: =IF(E39="4 MESES Semestre 1",0,IF(E39="4 MESES Semestre 2",D39*4,IF(E39="8 Meses",D39*4,IF(E39="10 Meses",D39*5,IF(E39="11 Meses",D39*5.5,IF(E39="1 Año",D39*6,0)))))) -> 0 | H39: NO | I39: =IF(H39="SI",F39,IF(H39="NO",0,"Sin comprobar")) -> 0 | J39: =IF(H39="SI",G39,IF(H39="NO",0,"Sin comprobar")) -> 0
C40: =IF(B40>8,0,B40*BaseSalarial!$D$9) -> 0 | D40: =IF(C40<=(BaseSalarial!$D$9*8),C40,0)*4 -> 0 | E40: Elija | F40: =IF(E40="4 MESES Semestre 1",D40*4,IF(E40="4 MESES Semestre 2",0,IF(E40="8 Meses",D40*4,IF(E40="10 Meses",D40*5,IF(E40="11 Meses",D40*5.5,IF(E40="1 Año",D40*6,0)))))) -> 0 | G40: =IF(E40="4 MESES Semestre 1",0,IF(E40="4 MESES Semestre 2",D40*4,IF(E40="8 Meses",D40*4,IF(E40="10 Meses",D40*5,IF(E40="11 Meses",D40*5.5,IF(E40="1 Año",D40*6,0)))))) -> 0 | H40: NO | I40: =IF(H40="SI",F40,IF(H40="NO",0,"Sin comprobar")) -> 0 | J40: =IF(H40="SI",G40,IF(H40="NO",0,"Sin comprobar")) -> 0
C41: =IF(B41>8,0,B41*BaseSalarial!$D$9) -> 0 | D41: =IF(C41<=(BaseSalarial!$D$9*8),C41,0)*4 -> 0 | E41: Elija | F41: =IF(E41="4 MESES Semestre 1",D41*4,IF(E41="4 MESES Semestre 2",0,IF(E41="8 Meses",D41*4,IF(E41="10 Meses",D41*5,IF(E41="11 Meses",D41*5.5,IF(E41="1 Año",D41*6,0)))))) -> 0 | G41: =IF(E41="4 MESES Semestre 1",0,IF(E41="4 MESES Semestre 2",D41*4,IF(E41="8 Meses",D41*4,IF(E41="10 Meses",D41*5,IF(E41="11 Meses",D41*5.5,IF(E41="1 Año",D41*6,0)))))) -> 0 | H41: NO | I41: =IF(H41="SI",F41,IF(H41="NO",0,"Sin comprobar")) -> 0 | J41: =IF(H41="SI",G41,IF(H41="NO",0,"Sin comprobar")) -> 0
C42: =IF(B42>8,0,B42*BaseSalarial!$D$9) -> 0 | D42: =IF(C42<=(BaseSalarial!$D$9*8),C42,0)*4 -> 0 | E42: Elija | F42: =IF(E42="4 MESES Semestre 1",D42*4,IF(E42="4 MESES Semestre 2",0,IF(E42="8 Meses",D42*4,IF(E42="10 Meses",D42*5,IF(E42="11 Meses",D42*5.5,IF(E42="1 Año",D42*6,0)))))) -> 0 | G42: =IF(E42="4 MESES Semestre 1",0,IF(E42="4 MESES Semestre 2",D42*4,IF(E42="8 Meses",D42*4,IF(E42="10 Meses",D42*5,IF(E42="11 Meses",D42*5.5,IF(E42="1 Año",D42*6,0)))))) -> 0 | H42: NO | I42: =IF(H42="SI",F42,IF(H42="NO",0,"Sin comprobar")) -> 0 | J42: =IF(H42="SI",G42,IF(H42="NO",0,"Sin comprobar")) -> 0
C43: =IF(B43>8,0,B43*BaseSalarial!$D$9) -> 0 | D43: =IF(C43<=(BaseSalarial!$D$9*8),C43,0)*4 -> 0 | E43: Elija | F43: =IF(E43="4 MESES Semestre 1",D43*4,IF(E43="4 MESES Semestre 2",0,IF(E43="8 Meses",D43*4,IF(E43="10 Meses",D43*5,IF(E43="11 Meses",D43*5.5,IF(E43="1 Año",D43*6,0)))))) -> 0 | G43: =IF(E43="4 MESES Semestre 1",0,IF(E43="4 MESES Semestre 2",D43*4,IF(E43="8 Meses",D43*4,IF(E43="10 Meses",D43*5,IF(E43="11 Meses",D43*5.5,IF(E43="1 Año",D43*6,0)))))) -> 0 | H43: NO | I43: =IF(H43="SI",F43,IF(H43="NO",0,"Sin comprobar")) -> 0 | J43: =IF(H43="SI",G43,IF(H43="NO",0,"Sin comprobar")) -> 0
C44: =IF(B44>8,0,B44*BaseSalarial!$D$9) -> 0 | D44: =IF(C44<=(BaseSalarial!$D$9*8),C44,0)*4 -> 0 | E44: Elija | F44: =IF(E44="4 MESES Semestre 1",D44*4,IF(E44="4 MESES Semestre 2",0,IF(E44="8 Meses",D44*4,IF(E44="10 Meses",D44*5,IF(E44="11 Meses",D44*5.5,IF(E44="1 Año",D44*6,0)))))) -> 0 | G44: =IF(E44="4 MESES Semestre 1",0,IF(E44="4 MESES Semestre 2",D44*4,IF(E44="8 Meses",D44*4,IF(E44="10 Meses",D44*5,IF(E44="11 Meses",D44*5.5,IF(E44="1 Año",D44*6,0)))))) -> 0 | H44: NO | I44: =IF(H44="SI",F44,IF(H44="NO",0,"Sin comprobar")) -> 0 | J44: =IF(H44="SI",G44,IF(H44="NO",0,"Sin comprobar")) -> 0
C45: =IF(B45>8,0,B45*BaseSalarial!$D$9) -> 0 | D45: =IF(C45<=(BaseSalarial!$D$9*8),C45,0)*4 -> 0 | E45: Elija | F45: =IF(E45="4 MESES Semestre 1",D45*4,IF(E45="4 MESES Semestre 2",0,IF(E45="8 Meses",D45*4,IF(E45="10 Meses",D45*5,IF(E45="11 Meses",D45*5.5,IF(E45="1 Año",D45*6,0)))))) -> 0 | G45: =IF(E45="4 MESES Semestre 1",0,IF(E45="4 MESES Semestre 2",D45*4,IF(E45="8 Meses",D45*4,IF(E45="10 Meses",D45*5,IF(E45="11 Meses",D45*5.5,IF(E45="1 Año",D45*6,0)))))) -> 0 | H45: NO | I45: =IF(H45="SI",F45,IF(H45="NO",0,"Sin comprobar")) -> 0 | J45: =IF(H45="SI",G45,IF(H45="NO",0,"Sin comprobar")) -> 0
C46: =IF(B46>8,0,B46*BaseSalarial!$D$9) -> 0 | D46: =IF(C46<=(BaseSalarial!$D$9*8),C46,0)*4 -> 0 | E46: Elija | F46: =IF(E46="4 MESES Semestre 1",D46*4,IF(E46="4 MESES Semestre 2",0,IF(E46="8 Meses",D46*4,IF(E46="10 Meses",D46*5,IF(E46="11 Meses",D46*5.5,IF(E46="1 Año",D46*6,0)))))) -> 0 | G46: =IF(E46="4 MESES Semestre 1",0,IF(E46="4 MESES Semestre 2",D46*4,IF(E46="8 Meses",D46*4,IF(E46="10 Meses",D46*5,IF(E46="11 Meses",D46*5.5,IF(E46="1 Año",D46*6,0)))))) -> 0 | H46: NO | I46: =IF(H46="SI",F46,IF(H46="NO",0,"Sin comprobar")) -> 0 | J46: =IF(H46="SI",G46,IF(H46="NO",0,"Sin comprobar")) -> 0
...

Sheet POS
A2: Seleccione la cualificación | B2: Relación Salario | C2: Total Docentes | D2: Cantidad Horas | E2: Periodo de contratación | F2: Totales | G2: Costo por Semestre I | H2: Costo por Semestre II | I2: Aprobado SI-NO | J2: Costo Semestre 1 | K2: Costo Semestre 2 | L2: Observaciones | M2: Ejecución | N2: Observaciones de la Ejecución
A3: Elija | B3: =IFERROR(VLOOKUP(A3,BaseSalarial!$G$20:$H$22,2,0),"0") -> 0 | E3: Elija | F3: =C3*D3*B3 -> 0 | G3: =IF(E3="Semestre 1",F3,IF(E3="Semestre 2",0,0)) -> 0 | H3: =IF(E3="Semestre 1",0,IF(E3="Semestre 2",F3,0)) -> 0 | I3: NO | J3: =IF(I3="SI",G3,IF(I3="NO",0,"Sin comprobar")) -> 0 | K3: =IF(I3="SI",H3,IF(I3="NO",0,"Sin comprobar")) -> 0
A4: Elija | B4: =IFERROR(VLOOKUP(A4,BaseSalarial!$G$20:$H$22,2,0),"0") -> 0 | E4: Elija | F4: =C4*D4*B4 -> 0 | G4: =IF(E4="Semestre 1",F4,IF(E4="Semestre 2",0,0)) -> 0 | H4: =IF(E4="Semestre 1",0,IF(E4="Semestre 2",F4,0)) -> 0 | I4: NO | J4: =IF(I4="SI",G4,IF(I4="NO",0,"Sin comprobar")) -> 0 | K4: =IF(I4="SI",H4,IF(I4="NO",0,"Sin comprobar")) -> 0
A5: Elija | B5: =IFERROR(VLOOKUP(A5,BaseSalarial!$G$20:$H$22,2,0),"0") -> 0 | E5: Elija | F5: =C5*D5*B5 -> 0 | G5: =IF(E5="Semestre 1",F5,IF(E5="Semestre 2",0,0)) -> 0 | H5: =IF(E5="Semestre 1",0,IF(E5="Semestre 2",F5,0)) -> 0 | I5: NO | J5: =IF(I5="SI",G5,IF(I5="NO",0,"Sin comprobar")) -> 0 | K5: =IF(I5="SI",H5,IF(I5="NO",0,"Sin comprobar")) -> 0
A6: Elija | B6: =IFERROR(VLOOKUP(A6,BaseSalarial!$G$20:$H$22,2,0),"0") -> 0 | E6: Elija | F6: =C6*D6*B6 -> 0 | G6: =IF(E6="Semestre 1",F6,IF(E6="Semestre 2",0,0)) -> 0 | H6: =IF(E6="Semestre 1",0,IF(E6="Semestre 2",F6,0)) -> 0 | I6: NO | J6: =IF(I6="SI",G6,IF(I6="NO",0,"Sin comprobar")) -> 0 | K6: =IF(I6="SI",H6,IF(I6="NO",0,"Sin comprobar")) -> 0
A7: Elija | B7: =IFERROR(VLOOKUP(A7,BaseSalarial!$G$20:$H$22,2,0),"0") -> 0 | E7: Elija | F7: =C7*D7*B7 -> 0 | G7: =IF(E7="Semestre 1",F7,IF(E7="Semestre 2",0,0)) -> 0 | H7: =IF(E7="Semestre 1",0,IF(E7="Semestre 2",F7,0)) -> 0 | I7: NO | J7: =IF(I7="SI",G7,IF(I7="NO",0,"Sin comprobar")) -> 0 | K7: =IF(I7="SI",H7,IF(I7="NO",0,"Sin comprobar")) -> 0
A8: Elija | B8: =IFERROR(VLOOKUP(A8,BaseSalarial!$G$20:$H$22,2,0),"0") -> 0 | E8: Elija | F8: =C8*D8*B8 -> 0 | G8: =IF(E8="Semestre 1",F8,IF(E8="Semestre 2",0,0)) -> 0 | H8: =IF(E8="Semestre 1",0,IF(E8="Semestre 2",F8,0)) -> 0 | I8: NO | J8: =IF(I8="SI",G8,IF(I8="NO",0,"Sin comprobar")) -> 0 | K8: =IF(I8="SI",H8,IF(I8="NO",0,"Sin comprobar")) -> 0
A9: Elija | B9: =IFERROR(VLOOKUP(A9,BaseSalarial!$G$20:$H$22,2,0),"0") -> 0 | E9: Elija | F9: =C9*D9*B9 -> 0 | G9: =IF(E9="Semestre 1",F9,IF(E9="Semestre 2",0,0)) -> 0 | H9: =IF(E9="Semestre 1",0,IF(E9="Semestre 2",F9,0)) -> 0 | I9: NO | J9: =IF(I9="SI",G9,IF(I9="NO",0,"Sin comprobar")) -> 0 | K9: =IF(I9="SI",H9,IF(I9="NO",0,"Sin comprobar")) -> 0
A10: Elija | B10: =IFERROR(VLOOKUP(A10,BaseSalarial!$G$20:$H$22,2,0),"0") -> 0 | E10: Elija | F10: =C10*D10*B10 -> 0 | G10: =IF(E10="Semestre 1",F10,IF(E10="Semestre 2",0,0)) -> 0 | H10: =IF(E10="Semestre 1",0,IF(E10="Semestre 2",F10,0)) -> 0 | I10: NO | J10: =IF(I10="SI",G10,IF(I10="NO",0,"Sin comprobar")) -> 0 | K10: =IF(I10="SI",H10,IF(I10="NO",0,"Sin comprobar")) -> 0
A11: Elija | B11: =IFERROR(VLOOKUP(A11,BaseSalarial!$G$20:$H$22,2,0),"0") -> 0 | E11: Elija | F11: =C11*D11*B11 -> 0 | G11: =IF(E11="Semestre 1",F11,IF(E11="Semestre 2",0,0)) -> 0 | H11: =IF(E11="Semestre 1",0,IF(E11="Semestre 2",F11,0)) -> 0 | I11: NO | J11: =IF(I11="SI",G11,IF(I11="NO",0,"Sin comprobar")) -> 0 | K11: =IF(I11="SI",H11,IF(I11="NO",0,"Sin comprobar")) -> 0
A12: Elija | B12: =IFERROR(VLOOKUP(A12,BaseSalarial!$G$20:$H$22,2,0),"0") -> 0 | E12: Elija | F12: =C12*D12*B12 -> 0 | G12: =IF(E12="Semestre 1",F12,IF(E12="Semestre 2",0,0)) -> 0 | H12: =IF(E12="Semestre 1",0,IF(E12="Semestre 2",F12,0)) -> 0 | I12: NO | J12: =IF(I12="SI",G12,IF(I12="NO",0,"Sin comprobar")) -> 0 | K12: =IF(I12="SI",H12,IF(I12="NO",0,"Sin comprobar")) -> 0
A13: Elija | B13: =IFERROR(VLOOKUP(A13,BaseSalarial!$G$20:$H$22,2,0),"0") -> 0 | E13: Elija | F13: =C13*D13*B13 -> 0 | G13: =IF(E13="Semestre 1",F13,IF(E13="Semestre 2",0,0)) -> 0 | H13: =IF(E13="Semestre 1",0,IF(E13="Semestre 2",F13,0)) -> 0 | I13: NO | J13: =IF(I13="SI",G13,IF(I13="NO",0,"Sin comprobar")) -> 0 | K13: =IF(I13="SI",H13,IF(I13="NO",0,"Sin comprobar")) -> 0
A14: Elija | B14: =IFERROR(VLOOKUP(A14,BaseSalarial!$G$20:$H$22,2,0),"0") -> 0 | E14: Elija | F14: =C14*D14*B14 -> 0 | G14: =IF(E14="Semestre 1",F14,IF(E14="Semestre 2",0,0)) -> 0 | H14: =IF(E14="Semestre 1",0,IF(E14="Semestre 2",F14,0)) -> 0 | I14: NO | J14: =IF(I14="SI",G14,IF(I14="NO",0,"Sin comprobar")) -> 0 | K14: =IF(I14="SI",H14,IF(I14="NO",0,"Sin comprobar")) -> 0
... A17: Elija | B17: =IFERROR(VLOOKUP(A17,BaseSalarial!$G$20:$H$22,2,0),"0") -> 0 | E17: Elija | F17: =C17*D17*B17 -> 0 | G17: =IF(E17="Semestre 1",F17,IF(E17="Semestre 2",0,0)) -> 0 | H17: =IF(E17="Semestre 1",0,IF(E17="Semestre 2",F17,0)) -> 0 | I17: NO | J17: =IF(I17="SI",G17,IF(I17="NO",0,"Sin comprobar")) -> 0 | K17: =IF(I17="SI",H17,IF(I17="NO",0,"Sin comprobar")) -> 0
F18: =SUM(F3:F17) -> 0 | G18: =SUM(G3:G17) -> 0 | H18: =SUM(H3:H17) -> 0 | J18: =SUM(J3:J17) -> 0 | K18: =SUM(K3:K17) -> 0 | M18: =SUM(M3:M17) -> 0

Sheet CONSOLIDADO
A2: Programa / Area / Proceso | B2: Proceso Misional ____________ Complementario | C2: I-COD | D2: MACROPROYECTO | E2: METAS PROYECTO | F2: indicador | G2: ENTREGABLE - EVIDENCIA | H2: ACTIVIDADES | I2: TIPO | J2: CANTIDAD ESPERADA PARA 2023 | K2: SEGUIMIENTO
K3: FECHA PREVISTA DE EVALUACIÓN Y SEGUIMIENTO | N3: FECHA PREVISTA DE EVALUACIÓN Y SEGUIMIENTO | Q3: FECHA PREVISTA DE EVALUACIÓN Y SEGUIMIENTO | T3: FECHA PREVISTA DE EVALUACIÓN Y SEGUIMIENTO
K4: Del 3 al 15 de abril de 2023 | N4: Del 6 al 17 de Junio | Q4: Del 2 al 14 de Octubre | T4: Del 13 al 25 de Noviembre
K5: % de cumplimiento | L5: Evidencia | M5: Observaciones | N5: % de cumplimiento | O5: Evidencia | P5: Observaciones | Q5: % de cumplimiento | R5: Evidencia | S5: Observaciones | T5: % de cumplimiento | U5: Evidencia | V5: Observaciones
A6: ADEMAGRO VIRTAL | B6: DOCENCIA | C6: DOC-03 | D6: 3. ACOMPAÑAMIENTO Y ÉXITO ESTUDIANTIL | E6: 3. Fortalecimiento del desempeño pruebas Saber pro, a través de estrategias académicas y culturales. | G6: Documento con analisis de resultados Actas de asistencia | H6: Análisis de los resultados de Pruebas SaberPro programas virtuales Talleres extra curriculares Capacitación docente del alcance de las pruebas y elaboración de cuestionarios afines a la metodología de las pruebas saber pro. | I6: IMPACTO
A7: ADEMAGRO VIRTAL | B7: DOCENCIA | C7: DOC-04 | D7: 3. ACOMPAÑAMIENTO Y ÉXITO ESTUDIANTIL | E7: 3. Fortalecimiento segundo idioma en docentes y estudiantes | G7: Curso de ingles virtualizado | H7: Diseño y Virtualización diplomado/seminario de ingles (120h) | I7: IMPACTO
A8: ADEMAGRO VIRTAL | B8: DOCENCIA | C8: DOC-05 | D8: 3. ACOMPAÑAMIENTO Y ÉXITO ESTUDIANTIL | E8: 3. Capacitación y actualización pedagógica de los docentes | G8: Actas de asistencia Memorias | H8: Capacitación en didactica y pedagogia virtual | I8: FORMACIÓN
A9: ADEMAGRO VIRTAL | B9: DOCENCIA | C9: DOC-06 | D9: 3. ACOMPAÑAMIENTO Y ÉXITO ESTUDIANTIL | E9: 3. Rubricas de Evaluación. | G9: Rubricas de evaluación | H9: Elaboración de rubricas de evaluación de las asignaturas de los programas virtuales | I9: IMPACTO
A10: ADEMAGRO VIRTAL | B10: EXTENSIÓN Y PROYECCIÓN SOCIAL | C10: EXT-01 | D10: 3. ACOMPAÑAMIENTO Y ÉXITO ESTUDIANTIL | E10: 3. Gestionar los programas, acciones y servicios de bienestar que contribuyen a la formación integral de la comunidad estudiantil, el mejoramiento de la calidad de vida y la construcción de comunidad | F10: EN CONSTRUCCIÓN | G10: Actas (Registro) de asistencia | H10: Socialización de los servicios de bienestar para los estudiantes virtuales. Establecer un canal virtual para la atención de estudiantes virtuales. | I10: IMPACTO
A11: ADEMAGRO VIRTAL | B11: EXTENSIÓN Y PROYECCIÓN SOCIAL | C11: EXT-02 | D11: 3. ACOMPAÑAMIENTO Y ÉXITO ESTUDIANTIL | E11: 3. Implementación de estrategias para la Disminución de la deserción y ausentismo de los estudiantes. | G11: Informe y actas de seguimiento | H11: Identificación de estudiantes ausentes y posibles causas Acompañamiento académico a estudiantes que presentan dificultades en su desarrollo academico | I11: IMPACTO
A12: ADEMAGRO VIRTAL | B12: COMPLETARIOS | C12: COM-04 | D12: 3. ACOMPAÑAMIENTO Y ÉXITO ESTUDIANTIL | E12: 3. Establecer canales de contacto eficientes. | G12: Medio de comunicación alterno | H12: Establecer un medio de comunicación alterno al correo institucional y plataforma UNIVIDA para la atención a la comunidad academica (programas virtuales) | I12: IMPACTO
A13: ADMINISTRACIÓN DE EMPRESAS | B13: DOCENCIA | C13: DOC-01 | D13: 3. ACOMPAÑAMIENTO Y ÉXITO ESTUDIANTIL | E13: 3. Fortalecimiento del desempeño pruebas Saber pro, a través de estrategias académicas y culturales. | G13: Informe de resultados de pruebas saber Pro, Informe de Analsis de resultados de los simulacros y las pruebas, Plan de Mejora. | H13: Discución en comité sobre resultados y elementos a mejorar 1. Convocatoria para inscripciones | I13: GESTIÓN
A14: ADMINISTRACIÓN DE EMPRESAS | B14: DOCENCIA | D14: 3. ACOMPAÑAMIENTO Y ÉXITO ESTUDIANTIL | E14: 3. Fortalecimiento del desempeño pruebas Saber pro, a través de estrategias académicas y culturales. | H14: 2. participacion en el simulacro | I14: GESTIÓN
A15: ADMINISTRACIÓN DE EMPRESAS | B15: DOCENCIA | D15: 3. ACOMPAÑAMIENTO Y ÉXITO ESTUDIANTIL | E15: 3. Fortalecimiento del desempeño pruebas Saber pro, a través de estrategias académicas y culturales. | H15: 3. realizacion del simulacro | I15: GESTIÓN
A16: ADMINISTRACIÓN DE EMPRESAS | B16: DOCENCIA | D16: 3. ACOMPAÑAMIENTO Y ÉXITO ESTUDIANTIL | E16: 3. Fortalecimiento del desempeño pruebas Saber pro, a través de estrategias académicas y culturales. | H16: 4. presentación de la prueba | I16: IMPACTO
A17: ADMINISTRACIÓN DE EMPRESAS | B17: DOCENCIA | D17: 3. ACOMPAÑAMIENTO Y ÉXITO ESTUDIANTIL | E17: 3. Fortalecimiento del desempeño pruebas Saber pro, a través de estrategias académicas y culturales. | H17: 5. Informe con analisi de resultados tanto del simulacro como de la prueba | I17: IMPACTO
A18: ADMINISTRACIÓN DE EMPRESAS | B18: DOCENCIA | D18: 3. ACOMPAÑAMIENTO Y ÉXITO ESTUDIANTIL | E18: 3. Fortalecimiento del desempeño pruebas Saber pro, a través de estrategias académicas y culturales. | H18: 6. Elaboración plan de mejora | I18: IMPACTO
A19: ADMINISTRACIÓN DE EMPRESAS | B19: DOCENCIA | C19: DOC-04 | D19: 3. ACOMPAÑAMIENTO Y ÉXITO ESTUDIANTIL | E19: 3. Fortalecimiento segundo idioma en docentes y estudiantes | G19: Certificado | H19: Participacion de curso de ingles para docentes y directivos. | I19: FORMACIÓN
A20: ADMINISTRACIÓN DE EMPRESAS | B20: DOCENCIA | C20: DOC-05 | D20: 3. ACOMPAÑAMIENTO Y ÉXITO ESTUDIANTIL | E20: 3. Fortalecimiento segundo idioma en docentes y estudiantes | G20: Microcurriculo | H20: Incluir en el microcurriculo de almenos una materia por semestre una actividad, lectura o taller en segundo idioma | I20: IMPACTO
A21: ADMINISTRACIÓN DE EMPRESAS | B21: DOCENCIA | C21: DOC-06 | D21: 3. ACOMPAÑAMIENTO Y ÉXITO ESTUDIANTIL | E21: 3. Visitas técnicas y salidas de campo. | G21: Informe de la visita técnica o salidas de campo, Microcurriculo que evdencie el resultado de aprendizage a partir de la salida tecnica | H21: Planeación de la visita técnica | I21: GESTIÓN
A22: ADMINISTRACIÓN DE EMPRESAS | B22: DOCENCIA | D22: 3. ACOMPAÑAMIENTO Y ÉXITO ESTUDIANTIL | E22: 3. Visitas técnicas y salidas de campo. | H22: Convocatoria a estudiantes de la visita técnica | I22: GESTIÓN
A23: ADMINISTRACIÓN DE EMPRESAS | B23: DOCENCIA | D23: 3. ACOMPAÑAMIENTO Y ÉXITO ESTUDIANTIL | E23: 3. Visitas técnicas y salidas de campo. | H23: Ejecuciónd de la visita | I23: IMPACTO
A24: ADMINISTRACIÓN DE EMPRESAS | B24: DOCENCIA | C24: DOC-07 | D24: 3. ACOMPAÑAMIENTO Y ÉXITO ESTUDIANTIL | E24: 3. Aumentar el material bibliográfico actual, a través de la compra de nuevos de nuevos ejemplares. | G24: Orden de compra del material bibliográfico | H24: Ejecuciónd de la visita | I24: IMPACTO
A25: ADMINISTRACIÓN DE EMPRESAS | B25: DOCENCIA | D25: 3. ACOMPAÑAMIENTO Y ÉXITO ESTUDIANTIL | E25: 3. Aumentar el material bibliográfico actual, a través de la compra de nuevos de nuevos ejemplares. | H25: Identificar necesidades de material bibliográfico requerido en comité curricular | I25: GESTIÓN
A26: ADMINISTRACIÓN DE EMPRESAS | B26: DOCENCIA | D26: 3. ACOMPAÑAMIENTO Y ÉXITO ESTUDIANTIL | E26: 3. Aumentar el material bibliográfico actual, a través de la compra de nuevos de nuevos ejemplares. | H26: Cotizar el material con el acompañamiento de la persona encargada de la biblioteca. | I26: IMPACTO
A27: ADMINISTRACIÓN DE EMPRESAS | B27: DOCENCIA | C27: DOC-08 | D27: 3. ACOMPAÑAMIENTO Y ÉXITO ESTUDIANTIL | E27: 3. Seguimiento de los estudiantes a través del Sistema de Alertas Tempranas. | G27: Informe de seguimiento a estudiantes identificados a traves de alertas tempranas y plan de mejora para los mismos. | H27: Revisar información de sistemas de alertas tempranas para estudiantes, en discusión en comité curricular, identificando las estrategias a utilizarse con dichos estudisntes en compañia de Bienestar institucional. | I27: IMPACTO
A28: ADMINISTRACIÓN DE EMPRESAS | B28: DOCENCIA | D28: 3. ACOMPAÑAMIENTO Y ÉXITO ESTUDIANTIL | E28: 3. Seguimiento de los estudiantes a través del Sistema de Alertas Tempranas. | H28: Diseño y ejecución de plan | I28: IMPACTO
A29: ADMINISTRACIÓN DE EMPRESAS | B29: COMPLETARIOS | C29: COM-06 | D29: 3. ACOMPAÑAMIENTO Y ÉXITO ESTUDIANTIL | E29: 3. Fortalecer los procesos de seguimiento y evaluación a la deserción estudiantil y repitencia. | F29: EN CONSTRUCCIÓN | G29: INFORMES Y LISTADOS DE ASISTENCIA A CURSOS INTRODUCTORIOS Y DE REFUERZO. | H29: Realizar cursos introductorios en competencias básicas y en los principales ejes disciplinares del programa para estudiantes de primer semestre. Ofertar cursos y talleres de refuerzo obligatorios para estudiantes en bajo rendimiento; asi como en el uso de herramientas ofimaticas nivel básico e intermedio. | I29: FORMACIÓN
A30: ARQUITECTURA POPAYÁN | B30: DOCENCIA | C30: DOC-10 | D30: 3. ACOMPAÑAMIENTO Y ÉXITO ESTUDIANTIL | E30: 3. Reconocer las capacidades en el estudiante, y fomentar su convivencia con el entorno en congruencia con una personalidad reflexiva, crítica, sensible, creativa y, responsable, tocando las dimensiones que como sujeto social. | F30: EN CONSTRUCCIÓN | G30: Documento interno con la caracterización, actas y listado de asistencia en la construcción de este. | H30: Diagnosticar los diferentes aspectos del estudiante que ingresa al programa, entendiendo las debilidades y fortalezas, en comprensión del contexto y de los posibles resultados para su formación en arquitectura. Realizar análisis continuo con el sector externo para verificar la concordancia de la meta propuesta con el sector Institucional. | I30: IMPACTO
A31: ARQUITECTURA POPAYÁN | B31: DOCENCIA | C31: DOC-11 | D31: 3. ACOMPAÑAMIENTO Y ÉXITO ESTUDIANTIL | E31: 3. Proyectar la formación de estudiantes con enfoque de sostenibilidad y comprensión de distintas formas de expresión y cultura. | F31: EN CONSTRUCCIÓN | G31: Talleres, seminarios y/o cursos. | H31: Realizar espacios educación continua con las diferentes instituciones en convenio y/o instituciones que puedan ser fortaleza interinstitucional. Jornadas de formación integral, lideradas por Bienestar Institucional que permitan evidenciar el resultado de la meta. | I31: IMPACTO
A32: ARQUITECTURA POPAYÁN | B32: DOCENCIA | C32: DOC-12 | D32: 3. ACOMPAÑAMIENTO Y ÉXITO ESTUDIANTIL | E32: 3. Autosostenibilidad: Implementar el plan de mercadeo para captar mayor volumen de estudiantes. | F32: EN CONSTRUCCIÓN | G32: Documento y listado de asistencia en la construcción de este. | H32: Estrategias derivadas de la construcción del diagnostico donde incluye la caracterización de estudiante del programa de arquitectura FUP. | I32: IMPACTO
A33: ARQUITECTURA POPAYÁN | B33: DOCENCIA | C33: DOC-13 | D33: 3. ACOMPAÑAMIENTO Y ÉXITO ESTUDIANTIL | E33: 3. Fomentar las estrategias de impacto del pensamiento crítico | F33: EN CONSTRUCCIÓN | G33: Talleres, seminarios y/o cursos, actas, correos y asistencias. | H33: Talleres en articulación con ingeniería de sistemas en la construcción de pensamientos diversos. Generar una estrategia con el entorno que permita evidenciar el aporte de egresado en la solución de problemáticas. | I33: FORMACIÓN
A34: ARQUITECTURA POPAYÁN | B34: DOCENCIA | C34: DOC-14 | D34: 3. ACOMPAÑAMIENTO Y ÉXITO ESTUDIANTIL | E34: 3. Fortalecimiento del desempeño pruebas Saber pro, a través de estrategias académicas y culturales. | F34: EN CONSTRUCCIÓN | G34: 2 pruebas simulacros e informe de resultados, actas y listado de asistencia en la construcción de este. | H34: Talleres en conjunto y/o simulacro pruebas saber desde la lectura y el pensamiento crítico. Análisis de resultados tanto de simulacros como de las pruebas Saber Pro. Estructuración de mecanismos para el Plan de Mejora. | I34: FORMACIÓN
A35: ARQUITECTURA POPAYÁN | B35: DOCENCIA | C35: DOC-15 | D35: 3. ACOMPAÑAMIENTO Y ÉXITO ESTUDIANTIL | E35: 3. Fortalecimiento de las competencias de estudiantes y docentes en habilidades blandas y comunicación asertiva. | F35: EN CONSTRUCCIÓN | G35: Talleres, seminarios y/o cursos, actas, correos, asistencias y documento que evidencia el análisis de la meta. | H35: 4 Talleres en alianza con programa de comunicaciones (escuela de lectoescritura) y con Bienestar Universitario, para el fortalecimiento al estudiante y el docente en estos aspectos. | I35: FORMACIÓN
A36: ARQUITECTURA POPAYÁN | B36: DOCENCIA | C36: DOC-16 | D36: 3. ACOMPAÑAMIENTO Y ÉXITO ESTUDIANTIL | E36: 3. Definir y/o estandarizar en el cuerpo de docente, para asumir las funciones de Docencia, Investigación y Proyección Social | F36: EN CONSTRUCCIÓN | G36: Documento final como apoyo al programa, actas y listado de asistencia en la construcción de este. | H36: A partir del diagnóstico realizado para los docentes del programa en el año 2022, formular la pertinencia de ellos en cada aspecto. Y con ello consolidar la comunidad de docentes para que contribuyan en el fortalecimiento de las funciones sustantivas, soportes de la cualificación docente y la distribución de labores del programa. | I36: IMPACTO
