Workbook

Sheet CORTE 1 G1
C4: PROGRAMA | N4: Grupo
C5: Asignatura | N5: Corte
C6: Docente | N6: Periodo | R6: Total
C8: Recursos Utilizados | D8: 0.01 | E8: Desarrollo | F8: 0.02 | G8: Dominio | M8: 0.95 | N8: Comunicación | O8: 0.01 | P8: Respeto | Q8: 0.01 | R8: =+D8+F8+M8+O8+Q8 -> 1
B9: EXCELENTE (4,01 a 5) | C9: Hace empleo adecuado de los recursos didácticos, sacándole el mayor provecho, lo que resulta favorable para su presentación | E9: Sabe ajustarse al tiempo asignado, tratando adecuadamente los diversos temas | G9: Excelente dominio del tema, comunica claramente las ideas y frente a las preguntas emite respuestas precisas | N9: Sabe aclarar todas las dudas sobre el tema, con ideas claras y precisas, incluso va más allá del límite de la respuesta | P9: Muestra respeto por el tema tratado y por sus compañeros que requieren algun aclaración
B10: BUENO (3,01 a 4) | C10: Presenta y utiliza recursos didácticos, aunque no le saca el mayor provecho a la presentación | E10: Se ajusta al tiempo asignado, exceptuando el final, donde se toma minutos adicionales. | G10: Dominio del tema aunque algunas ideas no quedan muy claras y hay error en la respuesta de alguna pregunta | N10: Sabe aclarar las dudas de los compañeros, sin ir más allá | P10: Muestra respeto por el tema tratado, pero su forma de responder a sus compañeros no es del todo correcta
B11: DEFICIENTE (2,01 a 3,0) | C11: Pocos recursos y solo son utilizados en algunos momentos de la presentación | E11: Dedica mucho tiempo a algunos aspectos, lo que hace que descuide el útimo tema a tratar | G11: Poco dominio, sus respuestas demuestran impresición que obligan a solicitar mayor aclaración | N11: En algunas preguntas emite respuestas adecuadas y en otras solo son superficiales | P11: Muestra poco respeto por el tema tratado y sus respuestas a sus compañeros denota sarcasmo y despectividad | R11: Ponderación (Nota Final Cargue en SIRES)
B12: INSUFICIENTE (0 a 2,0) | C12: Recursos presentados pero no utilizados | E12: No sabe utilizar el tiempo asignado y tampoco trabaja aecuadamente los temas | G12: No hay dominio del tema lo que no le permite responder correctamente las preguntas | N12: No sabe aclarar ninguna duda presentada por los compañeros | P12: No muestra respeto por el tema ni por sus compañeros, dando respuestas inapropiadas
A13: Código | B13: ESTUDIANTE | C13: =+C8 -> Recursos Utilizados | E13: =+E8 -> Desarrollo | G13: =+G8 -> Dominio | N13: =+N8 -> Comunicación | P13: =+P8 -> Respeto
L14: =SUM(G14:K14) -> 0 | M14: Final Dominio
D15: =C15*D$8 -> 0 | F15: =E15*F$8 -> 0 | L15: =+(G15*$G$14)+(H15*$H$14)+($I$14*I15)+($J$14*J15)+($K$14*K15) -> 0 | M15: =+L15*$M$8 -> 0 | O15: =N15*$O$8 -> 0 | Q15: =P15*$Q$8 -> 0 | R15: =+D15+F15+M15+O15+Q15 -> 0 | T15: =IF(R15=" "," ",IF(R15<1.95,"INSUFICIENTE",IF(R15<2.95,"DEFICIENTE",IF(R15<3.95,"BUENO","EXCELENTE")))) -> INSUFICIENTE
D16: =C16*D$8 -> 0 | F16: =E16*F$8 -> 0 | L16: =+(G16*$G$14)+(H16*$H$14)+($I$14*I16)+($J$14*J16)+($K$14*K16) -> 0 | M16: =+L16*$M$8 -> 0 | O16: =N16*$O$8 -> 0 | Q16: =P16*$Q$8 -> 0 | R16: =SUM(D16,F16,M16,O16,Q16) -> 0 | T16: =IF(R16=" "," ",IF(R16<1.95,"INSUFICIENTE",IF(R16<2.95,"DEFICIENTE",IF(R16<3.95,"BUENO","EXCELENTE")))) -> INSUFICIENTE
D17: =C17*D$8 -> 0 | F17: =E17*F$8 -> 0 | L17: =+(G17*$G$14)+(H17*$H$14)+($I$14*I17)+($J$14*J17)+($K$14*K17) -> 0 | M17: =+L17*$M$8 -> 0 | O17: =N17*$O$8 -> 0 | Q17: =P17*$Q$8 -> 0 | R17: =SUM(D17,F17,M17,O17,Q17) -> 0 | T17: =IF(R17=" "," ",IF(R17<1.95,"INSUFICIENTE",IF(R17<2.95,"DEFICIENTE",IF(R17<3.95,"BUENO","EXCELENTE")))) -> INSUFICIENTE
D18: =C18*D$8 -> 0 | F18: =E18*F$8 -> 0 | L18: =+(G18*$G$14)+(H18*$H$14)+($I$14*I18)+($J$14*J18)+($K$14*K18) -> 0 | M18: =+L18*$M$8 -> 0 | O18: =N18*$O$8 -> 0 | Q18: =P18*$Q$8 -> 0 | R18: =SUM(D18,F18,M18,O18,Q18) -> 0 | T18: =IF(R18=" "," ",IF(R18<1.95,"INSUFICIENTE",IF(R18<2.95,"DEFICIENTE",IF(R18<3.95,"BUENO","EXCELENTE")))) -> INSUFICIENTE
D19: =C19*D$8 -> 0 | F19: =E19*F$8 -> 0 | L19: =+(G19*$G$14)+(H19*$H$14)+($I$14*I19)+($J$14*J19)+($K$14*K19) -> 0 | M19: =+L19*$M$8 -> 0 | O19: =N19*$O$8 -> 0 | Q19: =P19*$Q$8 -> 0 | R19: =SUM(D19,F19,M19,O19,Q19) -> 0 | T19: =IF(R19=" "," ",IF(R19<1.95,"INSUFICIENTE",IF(R19<2.95,"DEFICIENTE",IF(R19<3.95,"BUENO","EXCELENTE")))) -> INSUFICIENTE
D20: =C20*D$8 -> 0 | F20: =E20*F$8 -> 0 | L20: =+(G20*$G$14)+(H20*$H$14)+($I$14*I20)+($J$14*J20)+($K$14*K20) -> 0 | M20: =+L20*$M$8 -> 0 | O20: =N20*$O$8 -> 0 | Q20: =P20*$Q$8 -> 0 | R20: =SUM(D20,F20,M20,O20,Q20) -> 0 | T20: =IF(R20=" "," ",IF(R20<1.95,"INSUFICIENTE",IF(R20<2.95,"DEFICIENTE",IF(R20<3.95,"BUENO","EXCELENTE")))) -> INSUFICIENTE
D21: =C21*D$8 -> 0 | F21: =E21*F$8 -> 0 | L21: =+(G21*$G$14)+(H21*$H$14)+($I$14*I21)+($J$14*J21)+($K$14*K21) -> 0 | M21: =+L21*$M$8 -> 0 | O21: =N21*$O$8 -> 0 | Q21: =P21*$Q$8 -> 0 | R21: =SUM(D21,F21,M21,O21,Q21) -> 0 | T21: =IF(R21=" "," ",IF(R21<1.95,"INSUFICIENTE",IF(R21<2.95,"DEFICIENTE",IF(R21<3.95,"BUENO","EXCELENTE")))) -> INSUFICIENTE
D22: =C22*D$8 -> 0 | F22: =E22*F$8 -> 0 | L22: =+(G22*$G$14)+(H22*$H$14)+($I$14*I22)+($J$14*J22)+($K$14*K22) -> 0 | M22: =+L22*$M$8 -> 0 | O22: =N22*$O$8 -> 0 | Q22: =P22*$Q$8 -> 0 | R22: =SUM(D22,F22,M22,O22,Q22) -> 0 | T22: =IF(R22=" "," ",IF(R22<1.95,"INSUFICIENTE",IF(R22<2.95,"DEFICIENTE",IF(R22<3.95,"BUENO","EXCELENTE")))) -> INSUFICIENTE
D23: =C23*D$8 -> 0 | F23: =E23*F$8 -> 0 | L23: =+(G23*$G$14)+(H23*$H$14)+($I$14*I23)+($J$14*J23)+($K$14*K23) -> 0 | M23: =+L23*$M$8 -> 0 | O23: =N23*$O$8 -> 0 | Q23: =P23*$Q$8 -> 0 | R23: =SUM(D23,F23,M23,O23,Q23) -> 0 | T23: =IF(R23=" "," ",IF(R23<1.95,"INSUFICIENTE",IF(R23<2.95,"DEFICIENTE",IF(R23<3.95,"BUENO","EXCELENTE")))) -> INSUFICIENTE
D24: =C24*D$8 -> 0 | F24: =E24*F$8 -> 0 | L24: =+(G24*$G$14)+(H24*$H$14)+($I$14*I24)+($J$14*J24)+($K$14*K24) -> 0 | M24: =+L24*$M$8 -> 0 | O24: =N24*$O$8 -> 0 | Q24: =P24*$Q$8 -> 0 | R24: =SUM(D24,F24,M24,O24,Q24) -> 0 | T24: =IF(R24=" "," ",IF(R24<1.95,"INSUFICIENTE",IF(R24<2.95,"DEFICIENTE",IF(R24<3.95,"BUENO","EXCELENTE")))) -> INSUFICIENTE
D25: =C25*D$8 -> 0 | F25: =E25*F$8 -> 0 | L25: =+(G25*$G$14)+(H25*$H$14)+($I$14*I25)+($J$14*J25)+($K$14*K25) -> 0 | M25: =+L25*$M$8 -> 0 | O25: =N25*$O$8 -> 0 | Q25: =P25*$Q$8 -> 0 | R25: =SUM(D25,F25,M25,O25,Q25) -> 0 | T25: =IF(R25=" "," ",IF(R25<1.95,"INSUFICIENTE",IF(R25<2.95,"DEFICIENTE",IF(R25<3.95,"BUENO","EXCELENTE")))) -> INSUFICIENTE
D26: =C26*D$8 -> 0 | F26: =E26*F$8 -> 0 | L26: =+(G26*$G$14)+(H26*$H$14)+($I$14*I26)+($J$14*J26)+($K$14*K26) -> 0 | M26: =+L26*$M$8 -> 0 | O26: =N26*$O$8 -> 0 | Q26: =P26*$Q$8 -> 0 | R26: =SUM(D26,F26,M26,O26,Q26) -> 0 | T26: =IF(R26=" "," ",IF(R26<1.95,"INSUFICIENTE",IF(R26<2.95,"DEFICIENTE",IF(R26<3.95,"BUENO","EXCELENTE")))) -> INSUFICIENTE
D27: =C27*D$8 -> 0 | F27: =E27*F$8 -> 0 | L27: =+(G27*$G$14)+(H27*$H$14)+($I$14*I27)+($J$14*J27)+($K$14*K27) -> 0 | M27: =+L27*$M$8 -> 0 | O27: =N27*$O$8 -> 0 | Q27: =P27*$Q$8 -> 0 | R27: =SUM(D27,F27,M27,O27,Q27) -> 0 | T27: =IF(R27=" "," ",IF(R27<1.95,"INSUFICIENTE",IF(R27<2.95,"DEFICIENTE",IF(R27<3.95,"BUENO","EXCELENTE")))) -> INSUFICIENTE
... D63: =C63*D$8 -> 0 | F63: =E63*F$8 -> 0 | L63: =+(G63*$G$14)+(H63*$H$14)+($I$14*I63)+($J$14*J63)+($K$14*K63) -> 0 | M63: =+L63*$M$8 -> 0 | O63: =N63*$O$8 -> 0 | Q63: =P63*$Q$8 -> 0 | R63: =SUM(D63,F63,M63,O63,Q63) -> 0 | T63: =IF(R63=" "," ",IF(R63<1.95,"INSUFICIENTE",IF(R63<2.95,"DEFICIENTE",IF(R63<3.95,"BUENO","EXCELENTE")))) -> INSUFICIENTE
C66: =COUNTIF(C15:C63,">3,95") -> 0 | E66: =COUNTIF(E15:E63,">3,95") -> 0 | G66: =COUNTIF(M15:M63,">3,95") -> 0 | N66: =COUNTIF(N15:N63,">3,95") -> 0 | P66: =COUNTIF(P15:P63,">3,95") -> 0 | R66: =COUNTIF(R15:R63,">3,95") -> 0 | T66: =COUNTIF(T$15:T$63,"EXCELENTE") -> 0
C67: =COUNTIFS(C15:C63,">2,95",C15:C63,"<3,95") -> 0 | E67: =COUNTIFS(E15:E63,">2,95",E15:E63,"<3,95") -> 0 | G67: =COUNTIFS(M15:M63,">2,95",M15:M63,"<3,95") -> 0 | N67: =COUNTIFS(N15:N63,">2,95",N15:N63,"<3,95") -> 0 | P67: =COUNTIFS(P15:P63,">2,95",P15:P63,"<3,95") -> 0 | R67: =COUNTIFS(R15:R63,">2,95",R15:R63,"<3,95") -> 0 | T67: =COUNTIF(T$15:T$63,"BUENO") -> 0
C68: =COUNTIFS(C15:C63,">1,95",C15:C63,"<2,95") -> 0 | E68: =COUNTIFS(E15:E63,">1,95",E15:E63,"<2,95") -> 0 | G68: =COUNTIFS(M15:M63,">1,95",M15:M63,"<2,95") -> 0 | N68: =COUNTIFS(N15:N63,">1,95",N15:N63,"<2,95") -> 0 | P68: =COUNTIFS(P15:P63,">1,95",P15:P63,"<2,95") -> 0 | R68: =COUNTIFS(R15:R63,">1,95",R15:R63,"<2,95") -> 0 | T68: =COUNTIF(T$15:T$63,"DEFICIENTE") -> 0
C69: =COUNTIFS(C15:C63,">=0",C15:C63,"<1,95") -> 0 | E69: =COUNTIFS(E15:E63,">=0",E15:E63,"<1,95") -> 0 | G69: =COUNTIFS(M15:M63,">=0,01",M15:M63,"<1,95") -> 0 | N69: =COUNTIFS(N15:N63,">=0",N15:N63,"<1,95") -> 0 | P69: =COUNTIFS(P15:P63,">=0",P15:P63,"<1,95") -> 0 | R69: =COUNTIFS(R15:R63,">=0",R15:R63,"<1,95") -> 49 | T69: =COUNTIF(T$15:T$63,"INSUFICIENTE") -> 49
B71: % | C71: =IFERROR(C66/COUNTA($A$15:$A$63)," ") | E71: =IFERROR(E66/COUNTA($A$15:$A$64)," ") | G71: =IFERROR(G66/COUNTA($A$15:$A$64)," ") | N71: =IFERROR(N66/COUNTA($A$15:$A$64)," ") | P71: =IFERROR(P66/COUNTA($A$15:$A$64)," ") | R71: =IFERROR(R66/COUNTA($A$15:$A$64)," ") | T71: =IFERROR(T66/COUNTA($A$15:$A$64)," ")
B72: % | C72: =IFERROR(C67/COUNTA($A$15:$A$63)," ") | E72: =IFERROR(E67/COUNTA($A$15:$A$64)," ") | G72: =IFERROR(G67/COUNTA($A$15:$A$64)," ") | N72: =IFERROR(N67/COUNTA($A$15:$A$64)," ") | P72: =IFERROR(P67/COUNTA($A$15:$A$64)," ") | R72: =IFERROR(R67/COUNTA($A$15:$A$64)," ") | T72: =IFERROR(T67/COUNTA($A$15:$A$64)," ")
B73: % | C73: =IFERROR(C68/COUNTA($A$15:$A$63)," ") | E73: =IFERROR(E68/COUNTA($A$15:$A$64)," ") | G73: =IFERROR(G68/COUNTA($A$15:$A$64)," ") | N73: =IFERROR(N68/COUNTA($A$15:$A$64)," ") | P73: =IFERROR(P68/COUNTA($A$15:$A$64)," ") | R73: =IFERROR(R68/COUNTA($A$15:$A$64)," ") | T73: =IFERROR(T68/COUNTA($A$15:$A$64)," ")
B74: % | C74: =IFERROR(C69/COUNTA($A$15:$A$64)," ") | E74: =IFERROR(E69/COUNTA($A$15:$A$64)," ") | G74: =IFERROR(G69/COUNTA($A$15:$A$63)," ") | N74: =IFERROR(N69/COUNTA($A$15:$A$64)," ") | P74: =IFERROR(P69/COUNTA($A$15:$A$64)," ") | R74: =IFERROR(R69/COUNTA($A$15:$A$64)," ") | T74: =IFERROR(T69/COUNTA($A$15:$A$64)," ")

Sheet CORTE 2 REAL
C4: PROGRAMA | E4: =+'CORTE 1 G1'!E4 -> 0 | N4: Grupo | P4: =+'CORTE 1 G1'!P4 -> 0
C5: Asignatura | E5: =+'CORTE 1 G1'!E5 -> 0 | N5: Corte | P5: 2
C6: Docente | E6: =+'CORTE 1 G1'!E6 -> 0 | N6: Periodo | P6: =+'CORTE 1 G1'!P6 -> 0 | R6: Total
C8: Recursos Utilizados | D8: =+'CORTE 1 G1'!D8 -> 0.01 | E8: Desarrollo | F8: =+'CORTE 1 G1'!F8 -> 0.02 | G8: Dominio | M8: =+'CORTE 1 G1'!M8 -> 0.95 | N8: Comunicación | O8: =+'CORTE 1 G1'!O8 -> 0.01 | P8: Respeto | Q8: =+'CORTE 1 G1'!Q8 -> 0.01 | R8: =+D8+F8+M8+O8+Q8 -> 1
B9: EXCELENTE (4,01 a 5) | C9: =+'CORTE 1 G1'!C9:D9 -> Hace empleo adecuado de los recursos didácticos, sacándole el mayor provecho, lo que resulta favorable para su presentación | E9: =+'CORTE 1 G1'!E9:F9 -> Sabe ajustarse al tiempo asignado, tratando adecuadamente los diversos temas | G9: =+'CORTE 1 G1'!G9:M9 -> Excelente dominio del tema, comunica claramente las ideas y frente a las preguntas emite respuestas precisas | N9: =+'CORTE 1 G1'!N9 -> Sabe aclarar todas las dudas sobre el tema, con ideas claras y precisas, incluso va más allá del límite de la respuesta | P9: =+'CORTE 1 G1'!P9 -> Muestra respeto por el tema tratado y por sus compañeros que requieren algun aclaración
B10: BUENO (3,01 a 4) | C10: =+'CORTE 1 G1'!C10:D10 -> Presenta y utiliza recursos didácticos, aunque no le saca el mayor provecho a la presentación | E10: =+'CORTE 1 G1'!E10:F10 -> Se ajusta al tiempo asignado, exceptuando el final, donde se toma minutos adicionales. | G10: =+'CORTE 1 G1'!G10:M10 -> Dominio del tema aunque algunas ideas no quedan muy claras y hay error en la respuesta de alguna pregunta | N10: =+'CORTE 1 G1'!N10 -> Sabe aclarar las dudas de los compañeros, sin ir más allá | P10: =+'CORTE 1 G1'!P10 -> Muestra respeto por el tema tratado, pero su forma de responder a sus compañeros no es del todo correcta
B11: DEFICIENTE (2,01 a 3,0) | C11: =+'CORTE 1 G1'!C11:D11 -> Pocos recursos y solo son utilizados en algunos momentos de la presentación | E11: =+'CORTE 1 G1'!E11:F11 -> Dedica mucho tiempo a algunos aspectos, lo que hace que descuide el útimo tema a tratar | G11: =+'CORTE 1 G1'!G11:M11 -> Poco dominio, sus respuestas demuestran impresición que obligan a solicitar mayor aclaración | N11: =+'CORTE 1 G1'!N11 -> En algunas preguntas emite respuestas adecuadas y en otras solo son superficiales | P11: =+'CORTE 1 G1'!P11 -> Muestra poco respeto por el tema tratado y sus respuestas a sus compañeros denota sarcasmo y despectividad | R11: Ponderación (Nota Final Cargue en SIRES)
B12: INSUFICIENTE (0 a 2,0) | C12: =+'CORTE 1 G1'!C12:D12 -> Recursos presentados pero no utilizados | E12: =+'CORTE 1 G1'!E12:F12 -> No sabe utilizar el tiempo asignado y tampoco trabaja aecuadamente los temas | G12: =+'CORTE 1 G1'!G12:M12 -> No hay dominio del tema lo que no le permite responder correctamente las preguntas | N12: =+'CORTE 1 G1'!N12 -> No sabe aclarar ninguna duda presentada por los compañeros | P12: =+'CORTE 1 G1'!P12 -> No muestra respeto por el tema ni por sus compañeros, dando respuestas inapropiadas
A13: Código | B13: ESTUDIANTE | C13: =+C8 -> Recursos Utilizados | E13: =+E8 -> Desarrollo | G13: =+G8 -> Dominio | N13: =+N8 -> Comunicación | P13: =+P8 -> Respeto
L14: =SUM(G14:K14) -> 0 | M14: Final Dominio
A15: =+'CORTE 1 G1'!A15 -> 0 | B15: =+'CORTE 1 G1'!B15:B15 -> 0 | D15: =C15*D$8 -> 0 | F15: =E15*F$8 -> 0 | L15: =+(G15*$G$14)+(H15*$H$14)+($I$14*I15)+($J$14*J15)+($K$14*K15) -> 0 | M15: =+L15*$M$8 -> 0 | O15: =N15*$O$8 -> 0 | Q15: =P15*$Q$8 -> 0 | R15: =SUM(D15,F15,M15,O15,Q15) -> 0 | T15: =IF(R15=" "," ",IF(R15<1.95,"INSUFICIENTE",IF(R15<2.95,"DEFICIENTE",IF(R15<3.95,"BUENO","EXCELENTE")))) -> INSUFICIENTE
A16: =+'CORTE 1 G1'!A16 -> 0 | B16: =+'CORTE 1 G1'!B16:B16 -> 0 | D16: =C16*D$8 -> 0 | F16: =E16*F$8 -> 0 | L16: =+(G16*$G$14)+(H16*$H$14)+($I$14*I16)+($J$14*J16)+($K$14*K16) -> 0 | M16: =+L16*$M$8 -> 0 | O16: =N16*$O$8 -> 0 | Q16: =P16*$Q$8 -> 0 | R16: =SUM(D16,F16,M16,O16,Q16) -> 0 | T16: =IF(R16=" "," ",IF(R16<1.95,"INSUFICIENTE",IF(R16<2.95,"DEFICIENTE",IF(R16<3.95,"BUENO","EXCELENTE")))) -> INSUFICIENTE
A17: =+'CORTE 1 G1'!A17 -> 0 | B17: =+'CORTE 1 G1'!B17:B17 -> 0 | D17: =C17*D$8 -> 0 | F17: =E17*F$8 -> 0 | L17: =+(G17*$G$14)+(H17*$H$14)+($I$14*I17)+($J$14*J17)+($K$14*K17) -> 0 | M17: =+L17*$M$8 -> 0 | O17: =N17*$O$8 -> 0 | Q17: =P17*$Q$8 -> 0 | R17: =SUM(D17,F17,M17,O17,Q17) -> 0 | T17: =IF(R17=" "," ",IF(R17<1.95,"INSUFICIENTE",IF(R17<2.95,"DEFICIENTE",IF(R17<3.95,"BUENO","EXCELENTE")))) -> INSUFICIENTE
A18: =+'CORTE 1 G1'!A18 -> 0 | B18: =+'CORTE 1 G1'!B18:B18 -> 0 | D18: =C18*D$8 -> 0 | F18: =E18*F$8 -> 0 | L18: =+(G18*$G$14)+(H18*$H$14)+($I$14*I18)+($J$14*J18)+($K$14*K18) -> 0 | M18: =+L18*$M$8 -> 0 | O18: =N18*$O$8 -> 0 | Q18: =P18*$Q$8 -> 0 | R18: =SUM(D18,F18,M18,O18,Q18) -> 0 | T18: =IF(R18=" "," ",IF(R18<1.95,"INSUFICIENTE",IF(R18<2.95,"DEFICIENTE",IF(R18<3.95,"BUENO","EXCELENTE")))) -> INSUFICIENTE
A19: =+'CORTE 1 G1'!A19 -> 0 | B19: =+'CORTE 1 G1'!B19:B19 -> 0 | D19: =C19*D$8 -> 0 | F19: =E19*F$8 -> 0 | L19: =+(G19*$G$14)+(H19*$H$14)+($I$14*I19)+($J$14*J19)+($K$14*K19) -> 0 | M19: =+L19*$M$8 -> 0 | O19: =N19*$O$8 -> 0 | Q19: =P19*$Q$8 -> 0 | R19: =SUM(D19,F19,M19,O19,Q19) -> 0 | T19: =IF(R19=" "," ",IF(R19<1.95,"INSUFICIENTE",IF(R19<2.95,"DEFICIENTE",IF(R19<3.95,"BUENO","EXCELENTE")))) -> INSUFICIENTE
A20: =+'CORTE 1 G1'!A20 -> 0 | B20: =+'CORTE 1 G1'!B20:B20 -> 0 | D20: =C20*D$8 -> 0 | F20: =E20*F$8 -> 0 | L20: =+(G20*$G$14)+(H20*$H$14)+($I$14*I20)+($J$14*J20)+($K$14*K20) -> 0 | M20: =+L20*$M$8 -> 0 | O20: =N20*$O$8 -> 0 | Q20: =P20*$Q$8 -> 0 | R20: =SUM(D20,F20,M20,O20,Q20) -> 0 | T20: =IF(R20=" "," ",IF(R20<1.95,"INSUFICIENTE",IF(R20<2.95,"DEFICIENTE",IF(R20<3.95,"BUENO","EXCELENTE")))) -> INSUFICIENTE
A21: =+'CORTE 1 G1'!A21 -> 0 | B21: =+'CORTE 1 G1'!B21:B21 -> 0 | D21: =C21*D$8 -> 0 | F21: =E21*F$8 -> 0 | L21: =+(G21*$G$14)+(H21*$H$14)+($I$14*I21)+($J$14*J21)+($K$14*K21) -> 0 | M21: =+L21*$M$8 -> 0 | O21: =N21*$O$8 -> 0 | Q21: =P21*$Q$8 -> 0 | R21: =SUM(D21,F21,M21,O21,Q21) -> 0 | T21: =IF(R21=" "," ",IF(R21<1.95,"INSUFICIENTE",IF(R21<2.95,"DEFICIENTE",IF(R21<3.95,"BUENO","EXCELENTE")))) -> INSUFICIENTE
A22: =+'CORTE 1 G1'!A22 -> 0 | B22: =+'CORTE 1 G1'!B22:B22 -> 0 | D22: =C22*D$8 -> 0 | F22: =E22*F$8 -> 0 | L22: =+(G22*$G$14)+(H22*$H$14)+($I$14*I22)+($J$14*J22)+($K$14*K22) -> 0 | M22: =+L22*$M$8 -> 0 | O22: =N22*$O$8 -> 0 | Q22: =P22*$Q$8 -> 0 | R22: =SUM(D22,F22,M22,O22,Q22) -> 0 | T22: =IF(R22=" "," ",IF(R22<1.95,"INSUFICIENTE",IF(R22<2.95,"DEFICIENTE",IF(R22<3.95,"BUENO","EXCELENTE")))) -> INSUFICIENTE
A23: =+'CORTE 1 G1'!A23 -> 0 | B23: =+'CORTE 1 G1'!B23:B23 -> 0 | D23: =C23*D$8 -> 0 | F23: =E23*F$8 -> 0 | L23: =+(G23*$G$14)+(H23*$H$14)+($I$14*I23)+($J$14*J23)+($K$14*K23) -> 0 | M23: =+L23*$M$8 -> 0 | O23: =N23*$O$8 -> 0 | Q23: =P23*$Q$8 -> 0 | R23: =SUM(D23,F23,M23,O23,Q23) -> 0 | T23: =IF(R23=" "," ",IF(R23<1.95,"INSUFICIENTE",IF(R23<2.95,"DEFICIENTE",IF(R23<3.95,"BUENO","EXCELENTE")))) -> INSUFICIENTE
A24: =+'CORTE 1 G1'!A24 -> 0 | B24: =+'CORTE 1 G1'!B24:B24 -> 0 | D24: =C24*D$8 -> 0 | F24: =E24*F$8 -> 0 | L24: =+(G24*$G$14)+(H24*$H$14)+($I$14*I24)+($J$14*J24)+($K$14*K24) -> 0 | M24: =+L24*$M$8 -> 0 | O24: =N24*$O$8 -> 0 | Q24: =P24*$Q$8 -> 0 | R24: =SUM(D24,F24,M24,O24,Q24) -> 0 | T24: =IF(R24=" "," ",IF(R24<1.95,"INSUFICIENTE",IF(R24<2.95,"DEFICIENTE",IF(R24<3.95,"BUENO","EXCELENTE")))) -> INSUFICIENTE
A25: =+'CORTE 1 G1'!A25 -> 0 | B25: =+'CORTE 1 G1'!B25:B25 -> 0 | D25: =C25*D$8 -> 0 | F25: =E25*F$8 -> 0 | L25: =+(G25*$G$14)+(H25*$H$14)+($I$14*I25)+($J$14*J25)+($K$14*K25) -> 0 | M25: =+L25*$M$8 -> 0 | O25: =N25*$O$8 -> 0 | Q25: =P25*$Q$8 -> 0 | R25: =SUM(D25,F25,M25,O25,Q25) -> 0 | T25: =IF(R25=" "," ",IF(R25<1.95,"INSUFICIENTE",IF(R25<2.95,"DEFICIENTE",IF(R25<3.95,"BUENO","EXCELENTE")))) -> INSUFICIENTE
A26: =+'CORTE 1 G1'!A26 -> 0 | B26: =+'CORTE 1 G1'!B26:B26 -> 0 | D26: =C26*D$8 -> 0 | F26: =E26*F$8 -> 0 | L26: =+(G26*$G$14)+(H26*$H$14)+($I$14*I26)+($J$14*J26)+($K$14*K26) -> 0 | M26: =+L26*$M$8 -> 0 | O26: =N26*$O$8 -> 0 | Q26: =P26*$Q$8 -> 0 | R26: =SUM(D26,F26,M26,O26,Q26) -> 0 | T26: =IF(R26=" "," ",IF(R26<1.95,"INSUFICIENTE",IF(R26<2.95,"DEFICIENTE",IF(R26<3.95,"BUENO","EXCELENTE")))) -> INSUFICIENTE
... A64: =+'CORTE 1 G1'!A64 -> 0 | B64: =+'CORTE 1 G1'!B64:B64 -> 0 | D64: =C64*D$8 -> 0 | F64: =E64*F$8 -> 0 | L64: =+(G64*$G$14)+(H64*$H$14)+($I$14*I64)+($J$14*J64)+($K$14*K64) -> 0 | M64: =+L64*$M$8 -> 0 | O64: =N64*$O$8 -> 0 | Q64: =P64*$Q$8 -> 0 | R64: =SUM(D64,F64,M64,O64,Q64) -> 0 | T64: =IF(R64=" "," ",IF(R64<1.95,"INSUFICIENTE",IF(R64<2.95,"DEFICIENTE",IF(R64<3.95,"BUENO","EXCELENTE")))) -> INSUFICIENTE
A65: =+'CORTE 1 G1'!A65 -> 0 | B65: =+'CORTE 1 G1'!B59:B59 -> 0 | D65: =C65*D$8 -> 0 | F65: =E65*F$8 -> 0 | L65: =+(G65*$G$14)+(H65*$H$14)+($I$14*I65)+($J$14*J65)+($K$14*K65) -> 0 | M65: =+L65*$M$8 -> 0 | O65: =N65*$O$8 -> 0 | Q65: =P65*$Q$8 -> 0 | R65: =SUM(D65,F65,M65,O65,Q65) -> 0 | T65: =IF(R65=" "," ",IF(R65<1.95,"INSUFICIENTE",IF(R65<2.95,"DEFICIENTE",IF(R65<3.95,"BUENO","EXCELENTE")))) -> INSUFICIENTE
C68: =COUNTIF(C15:C65,">3,95") -> 0 | E68: =COUNTIF(E15:E65,">3,95") -> 0 | G68: =COUNTIF(L15:L65,">3,95") -> 0 | N68: =COUNTIF(N15:N65,">3,95") -> 0 | P68: =COUNTIF(P15:P65,">3,95") -> 0 | R68: =COUNTIF(R15:R65,">3,95") -> 0 | T68: =COUNTIF(T$15:T$65,"EXCELENTE") -> 0
C69: =COUNTIFS(C15:C65,">2,95",C15:C65,"<3,95") -> 0 | E69: =COUNTIFS(E15:E65,">2,95",E15:E65,"<3,95") -> 0 | G69: =COUNTIFS(L15:L65,">2,95",L15:L65,"<3,95") -> 0 | N69: =COUNTIFS(N15:N65,">2,95",N15:N65,"<3,95") -> 0 | P69: =COUNTIFS(P15:P65,">2,95",P15:P65,"<3,95") -> 0 | R69: =COUNTIFS(R15:R65,">2,95",R15:R65,"<3,95") -> 0 | T69: =COUNTIF(T$15:T$65,"BUENO") -> 0
C70: =COUNTIFS(C15:C65,">1,95",C15:C65,"<2,95") -> 0 | E70: =COUNTIFS(E15:E65,">1,95",E15:E65,"<2,95") -> 0 | G70: =COUNTIFS(L15:L65,">1,95",L15:L65,"<2,95") -> 0 | N70: =COUNTIFS(N15:N65,">1,95",N15:N65,"<2,95") -> 0 | P70: =COUNTIFS(P15:P65,">1,95",P15:P65,"<2,95") -> 0 | R70: =COUNTIFS(R15:R65,">1,95",R15:R65,"<2,95") -> 0 | T70: =COUNTIF(T$15:T$65,"DEFICIENTE") -> 0
C71: =COUNTIFS(C15:C65,">=0",C15:C65,"<1,95") -> 0 | E71: =COUNTIFS(E15:E65,">=0",E15:E65,"<1,95") -> 0 | G71: =COUNTIFS(L15:L65,">=0",L15:L65,"<1,95") -> 51 | N71: =COUNTIFS(N15:N65,">=0",N15:N65,"<1,95") -> 0 | P71: =COUNTIFS(P15:P65,">=0",P15:P65,"<1,95") -> 0 | R71: =COUNTIFS(R15:R65,">=0",R15:R65,"<1,95") -> 51 | T71: =COUNTIF(T$15:T$65,"INSUFICIENTE") -> 51
B73: % | C73: =C68/COUNTA($A$15:$A$66) -> 0 | E73: =E68/COUNTA($A$15:$A$66) -> 0 | G73: =G68/COUNTA($A$15:$A$66) -> 0 | N73: =N68/COUNTA($A$15:$A$66) -> 0 | P73: =P68/COUNTA($A$15:$A$66) -> 0 | R73: =R68/COUNTA($A$15:$A$66) -> 0 | T73: =T68/COUNTA($A$15:$A$66) -> 0
B74: % | C74: =C69/COUNTA($A$15:$A$66) -> 0 | E74: =E69/COUNTA($A$15:$A$66) -> 0 | G74: =G69/COUNTA($A$15:$A$66) -> 0 | N74: =N69/COUNTA($A$15:$A$66) -> 0 | P74: =P69/COUNTA($A$15:$A$66) -> 0 | R74: =R69/COUNTA($A$15:$A$66) -> 0 | T74: =T69/COUNTA($A$15:$A$66) -> 0
B75: % | C75: =C70/COUNTA($A$15:$A$66) -> 0 | E75: =E70/COUNTA($A$15:$A$66) -> 0 | G75: =G70/COUNTA($A$15:$A$66) -> 0 | N75: =N70/COUNTA($A$15:$A$66) -> 0 | P75: =P70/COUNTA($A$15:$A$66) -> 0 | R75: =R70/COUNTA($A$15:$A$66) -> 0 | T75: =T70/COUNTA($A$15:$A$66) -> 0
B76: % | C76: =C71/COUNTA($A$15:$A$66) -> 0 | E76: =E71/COUNTA($A$15:$A$66) -> 0 | G76: =G71/COUNTA($A$15:$A$66) -> 1 | N76: =N71/COUNTA($A$15:$A$66) -> 0 | P76: =P71/COUNTA($A$15:$A$66) -> 0 | R76: =R71/COUNTA($A$15:$A$66) -> 1 | T76: =T71/COUNTA($A$15:$A$66) -> 1

Sheet CORTE 2 G1
A1: FUNDACIÓN UNIVERSITARIA DE POPAYÁN
D4: PROGRAMA | F4: Contaduría Pública | N4: Grupo | P4: 1
D5: Asignatura | F5: Teoría General de Sistemas | N5: Corte | P5: 1
D6: Docente | F6: Wadys Montilla Ortega | N6: Periodo | P6: 2022-1 | R6: Total
D8: Recursos Utilizados | E8: 0.1 | F8: Desarrollo | G8: 0.1 | H8: Dominio | M8: 0.6 | N8: Comunicación | O8: 0.1 | P8: Respeto | Q8: 0.1 | R8: =+E8+G8+M8+O8+Q8 -> 1
C9: EXCELENTE (4,01 a 5) | D9: Hace empleo adecuado de los recursos didácticos, sacándole el mayor provecho, lo que resulta favorable para su presentación | F9: Sabe ajustarse al tiempo asignado, tratando adecuadamente los diversos temas | H9: Excelente dominio del tema, comunica claramente las ideas y frente a las preguntas emite respuestas precisas | N9: Sabe aclarar todas las dudas sobre el tema, con ideas claras y precisas, incluso va más allá del límite de la respuesta | P9: Muestra respeto por el tema tratado y por sus compañeros que requieren algun aclaración
C10: BUENO (3,01 a 4) | D10: Presenta y utiliza recursos didácticos, aunque no le saca el mayor provecho a la presentación | F10: Se ajusta al tiempo asignado, exceptuando el final, donde se toma minutos adicionales. | H10: Dominio del tema aunque algunas ideas no quedan muy claras y hay error en la respuesta de alguna pregunta | N10: Sabe aclarar las dudas de los compañeros, sin ir más allá | P10: Muestra respeto por el tema tratado, pero su forma de responder a sus compañeros no es del todo correcta
C11: DEFICIENTE (2,01 a 3,0) | D11: Pocos recursos y solo son utilizados en algunos momentos de la presentación | F11: Dedica mucho tiempo a algunos aspectos, lo que hace que descuide el útimo tema a tratar | H11: Poco dominio, sus respuestas demuestran impresición que obligan a solicitar mayor aclaración | N11: En algunas preguntas emite respuestas adecuadas y en otras solo son superficiales | P11: Muestra poco respeto por el tema tratado y sus respuestas a sus compañeros denota sarcasmo y despectividad | R11: Ponderación
C12: INSUFICIENTE (0 a 2,0) | D12: Recursos presentados pero no utilizados | F12: No sabe utilizar el tiempo asignado y tampoco trabaja aecuadamente los temas | H12: No hay dominio del tema lo que no le permite responder correctamente las preguntas | N12: No sabe aclarar ninguna duda presentada por los compañeros | P12: No muestra respeto por el tema ni por sus compañeros, dando respuestas inapropiadas
D13: =+D8 -> Recursos Utilizados | F13: =+F8 -> Desarrollo | H13: =+H8 -> Dominio | N13: =+N8 -> Comunicación | P13: =+P8 -> Respeto
A14: Código | B14: ESTUDIANTE | H14: 0.1 | I14: 0.1 | J14: 0.2 | K14: 0.2 | L14: 0.4 | M14: =SUM(H14:L14) -> 1
A15: ='CORTE 1 G1'!A15 -> 0 | B15: ='CORTE 1 G1'!B15:B15 -> 0 | D15: 1 | E15: =D15*E$8 -> 0.1 | F15: 3 | G15: =F15*G$8 -> 0.3 | H15: 2.6 | I15: =H15*I$11 -> 0 | J15: 1.6 | K15: =J15*K$11 -> 0 | L15: 3 | M15: =(SUMPRODUCT(H15:L15,$H$14:$L$14)*M8) -> 1.068 | N15: =SUM(E15+G15+I15+K15+M15) -> 1.468 | P15: =IF(N15=" "," ",IF(N15<1.95,"INSUFICIENTE",IF(N15<2.95,"DEFICIENTE",IF(N15<3.95,"BUENO","EXCELENTE")))) -> INSUFICIENTE
A16: ='CORTE 1 G1'!A16 -> 0 | B16: ='CORTE 1 G1'!B16:B16 -> 0 | D16: 1 | E16: =D16*E$8 -> 0.1 | F16: 3 | G16: =F16*G$11 -> 0 | H16: 2.6 | I16: =H16*I$11 -> 0 | J16: 1.6 | K16: =J16*K$11 -> 0 | L16: 3 | M16: =(SUMPRODUCT(H16:L16,$H$14:$L$14)*M9) -> 0 | N16: =SUM(E16+G16+I16+K16+M16) -> 0.1 | P16: =IF(N16=" "," ",IF(N16<1.95,"INSUFICIENTE",IF(N16<2.95,"DEFICIENTE",IF(N16<3.95,"BUENO","EXCELENTE")))) -> INSUFICIENTE
A17: ='CORTE 1 G1'!A17 -> 0 | B17: ='CORTE 1 G1'!B17:B17 -> 0 | D17: 1 | E17: =D17*E$8 -> 0.1 | F17: 3 | G17: =F17*G$11 -> 0 | H17: 2.6 | I17: =H17*I$11 -> 0 | J17: 1.6 | K17: =J17*K$11 -> 0 | L17: 3 | M17: =(SUMPRODUCT(H17:L17,$H$14:$L$14)*M10) -> 0 | N17: =SUM(E17+G17+I17+K17+M17) -> 0.1 | P17: =IF(N17=" "," ",IF(N17<1.95,"INSUFICIENTE",IF(N17<2.95,"DEFICIENTE",IF(N17<3.95,"BUENO","EXCELENTE")))) -> INSUFICIENTE
A18: ='CORTE 1 G1'!A18 -> 0 | B18: ='CORTE 1 G1'!B18:B18 -> 0 | D18: 1 | E18: =D18*E$8 -> 0.1 | F18: 3 | G18: =F18*G$11 -> 0 | H18: 2.6 | I18: =H18*I$11 -> 0 | J18: 1.6 | K18: =J18*K$11 -> 0 | L18: 3 | M18: =(SUMPRODUCT(H18:L18,$H$14:$L$14)*M11) -> 0 | N18: =SUM(E18+G18+I18+K18+M18) -> 0.1 | P18: =IF(N18=" "," ",IF(N18<1.95,"INSUFICIENTE",IF(N18<2.95,"DEFICIENTE",IF(N18<3.95,"BUENO","EXCELENTE")))) -> INSUFICIENTE
A19: ='CORTE 1 G1'!A19 -> 0 | B19: ='CORTE 1 G1'!B19:B19 -> 0 | D19: 3 | E19: =D19*E$8 -> 0.3 | F19: 3.5 | G19: =F19*G$11 -> 0 | H19: 3.5 | I19: =H19*I$11 -> 0 | J19: 2 | K19: =J19*K$11 -> 0 | L19: 3 | M19: =(SUMPRODUCT(H19:L19,$H$14:$L$14)*M12) -> 0 | N19: =SUM(E19+G19+I19+K19+M19) -> 0.3 | P19: =IF(N19=" "," ",IF(N19<1.95,"INSUFICIENTE",IF(N19<2.95,"DEFICIENTE",IF(N19<3.95,"BUENO","EXCELENTE")))) -> INSUFICIENTE
A20: ='CORTE 1 G1'!A20 -> 0 | B20: ='CORTE 1 G1'!B20:B20 -> 0 | D20: 1 | E20: =D20*E$8 -> 0.1 | F20: 1 | G20: =F20*G$11 -> 0 | H20: 3 | I20: =H20*I$11 -> 0 | J20: 2.5 | K20: =J20*K$11 -> 0 | L20: 3.9 | M20: =(SUMPRODUCT(H20:L20,$H$14:$L$14)*M13) -> 0 | N20: =SUM(E20+G20+I20+K20+M20) -> 0.1 | P20: =IF(N20=" "," ",IF(N20<1.95,"INSUFICIENTE",IF(N20<2.95,"DEFICIENTE",IF(N20<3.95,"BUENO","EXCELENTE")))) -> INSUFICIENTE
A21: ='CORTE 1 G1'!A21 -> 0 | B21: ='CORTE 1 G1'!B21:B21 -> 0 | D21: 1 | E21: =D21*E$8 -> 0.1 | F21: 3 | G21: =F21*G$11 -> 0 | H21: 2.6 | I21: =H21*I$11 -> 0 | J21: 1.6 | K21: =J21*K$11 -> 0 | L21: 3 | M21: =(SUMPRODUCT(H21:L21,$H$14:$L$14)*M14) -> 1.78 | N21: =SUM(E21+G21+I21+K21+M21) -> 1.88 | P21: =IF(N21=" "," ",IF(N21<1.95,"INSUFICIENTE",IF(N21<2.95,"DEFICIENTE",IF(N21<3.95,"BUENO","EXCELENTE")))) -> INSUFICIENTE
A22: ='CORTE 1 G1'!A22 -> 0 | B22: ='CORTE 1 G1'!B22:B22 -> 0 | D22: 3 | E22: =D22*E$8 -> 0.3 | F22: 3 | G22: =F22*G$11 -> 0 | H22: 4 | I22: =H22*I$11 -> 0 | J22: 4 | K22: =J22*K$11 -> 0 | L22: 3 | M22: =(SUMPRODUCT(H22:L22,$H$14:$L$14)*M15) -> 2.5632 | N22: =SUM(E22+G22+I22+K22+M22) -> 2.8632 | P22: =IF(N22=" "," ",IF(N22<1.95,"INSUFICIENTE",IF(N22<2.95,"DEFICIENTE",IF(N22<3.95,"BUENO","EXCELENTE")))) -> DEFICIENTE
A23: ='CORTE 1 G1'!A23 -> 0 | B23: ='CORTE 1 G1'!B23:B23 -> 0 | D23: 4.6 | E23: =D23*E$8 -> 0.46 | F23: 3 | G23: =F23*G$11 -> 0 | H23: 2.6 | I23: =H23*I$11 -> 0 | J23: 1.6 | K23: =J23*K$11 -> 0 | L23: 3 | M23: =(SUMPRODUCT(H23:L23,$H$14:$L$14)*M16) -> 0 | N23: =SUM(E23+G23+I23+K23+M23) -> 0.46 | P23: =IF(N23=" "," ",IF(N23<1.95,"INSUFICIENTE",IF(N23<2.95,"DEFICIENTE",IF(N23<3.95,"BUENO","EXCELENTE")))) -> INSUFICIENTE
A24: ='CORTE 1 G1'!A24 -> 0 | B24: ='CORTE 1 G1'!B24:B24 -> 0 | D24: 1 | E24: =D24*E$8 -> 0.1 | F24: 3 | G24: =F24*G$11 -> 0 | H24: 2.6 | I24: =H24*I$11 -> 0 | J24: 1.6 | K24: =J24*K$11 -> 0 | L24: 3 | M24: =(SUMPRODUCT(H24:L24,$H$14:$L$14)*M17) -> 0 | N24: =SUM(E24+G24+I24+K24+M24) -> 0.1 | P24: =IF(N24=" "," ",IF(N24<1.95,"INSUFICIENTE",IF(N24<2.95,"DEFICIENTE",IF(N24<3.95,"BUENO","EXCELENTE")))) -> INSUFICIENTE
A25: ='CORTE 1 G1'!A25 -> 0 | B25: ='CORTE 1 G1'!B25:B25 -> 0 | D25: 1 | E25: =D25*E$8 -> 0.1 | F25: 3 | G25: =F25*G$11 -> 0 | H25: 2.6 | I25: =H25*I$11 -> 0 | J25: 1.6 | K25: =J25*K$11 -> 0 | L25: 3 | M25: =(SUMPRODUCT(H25:L25,$H$14:$L$14)*M18) -> 0 | N25: =SUM(E25+G25+I25+K25+M25) -> 0.1 | P25: =IF(N25=" "," ",IF(N25<1.95,"INSUFICIENTE",IF(N25<2.95,"DEFICIENTE",IF(N25<3.95,"BUENO","EXCELENTE")))) -> INSUFICIENTE
A26: ='CORTE 1 G1'!A26 -> 0 | B26: ='CORTE 1 G1'!B26:B26 -> 0 | D26: 2 | E26: =D26*E$8 -> 0.2 | F26: 3 | G26: =F26*G$11 -> 0 | H26: 2.6 | I26: =H26*I$11 -> 0 | J26: 1.6 | K26: =J26*K$11 -> 0 | L26: 3 | M26: =(SUMPRODUCT(H26:L26,$H$14:$L$14)*M19) -> 0 | N26: =SUM(E26+G26+I26+K26+M26) -> 0.2 | P26: =IF(N26=" "," ",IF(N26<1.95,"INSUFICIENTE",IF(N26<2.95,"DEFICIENTE",IF(N26<3.95,"BUENO","EXCELENTE")))) -> INSUFICIENTE
A27: ='CORTE 1 G1'!A27 -> 0 | B27: ='CORTE 1 G1'!B27:B27 -> 0 | D27: 1 | E27: =D27*E$8 -> 0.1 | F27: 3 | G27: =F27*G$11 -> 0 | H27: 2.6 | I27: =H27*I$11 -> 0 | J27: 1.6 | K27: =J27*K$11 -> 0 | L27: 3 | M27: =(SUMPRODUCT(H27:L27,$H$14:$L$14)*M20) -> 0 | N27: =SUM(E27+G27+I27+K27+M27) -> 0.1 | P27: =IF(N27=" "," ",IF(N27<1.95,"INSUFICIENTE",IF(N27<2.95,"DEFICIENTE",IF(N27<3.95,"BUENO","EXCELENTE")))) -> INSUFICIENTE
... A46: ='CORTE 1 G1'!A46 -> 0 | B46: ='CORTE 1 G1'!B46:B46 -> 0 | D46: 1 | E46: =D46*E$8 -> 0.1 | F46: 3 | G46: =F46*G$11 -> 0 | H46: 2.6 | I46: =H46*I$11 -> 0 | J46: 1.6 | K46: =J46*K$11 -> 0 | L46: 3 | M46: =(SUMPRODUCT(H46:L46,$H$14:$L$14)*M39) -> 0 | N46: =SUM(E46+G46+I46+K46+M46) -> 0.1 | P46: =IF(N46=" "," ",IF(N46<1.95,"INSUFICIENTE",IF(N46<2.95,"DEFICIENTE",IF(N46<3.95,"BUENO","EXCELENTE")))) -> INSUFICIENTE
A47: ='CORTE 1 G1'!A63 -> 0 | B47: ='CORTE 1 G1'!B63:B63 -> 0 | D47: 1 | E47: =D47*E$8 -> 0.1 | F47: 3 | G47: =F47*G$11 -> 0 | H47: 2.6 | I47: =H47*I$11 -> 0 | J47: 1.6 | K47: =J47*K$11 -> 0 | L47: 3 | M47: =(SUMPRODUCT(H47:L47,$H$14:$L$14)*M40) -> 0 | N47: =SUM(E47+G47+I47+K47+M47) -> 0.1 | P47: =IF(N47=" "," ",IF(N47<1.95,"INSUFICIENTE",IF(N47<2.95,"DEFICIENTE",IF(N47<3.95,"BUENO","EXCELENTE")))) -> INSUFICIENTE
C50: EXCELENTE | D50: =COUNTIF(D15:D47,">3,95") -> 5 | F50: =COUNTIF(F15:F47,">3,95") -> 0 | H50: =COUNTIF(H15:H47,">3,95") -> 3 | J50: =COUNTIF(J15:J47,">3,95") -> 2 | L50: =COUNTIF(L15:L47,">3,95") -> 2 | N50: =COUNTIF(N15:N47,">3,95") -> 5 | P50: =COUNTIF(P$15:P$47,"EXCELENTE") -> 5
C51: BUENO | D51: =COUNTIFS(D15:D47,">2,95",D15:D47,"<3,95") -> 4 | F51: =COUNTIFS(F15:F47,">2,95",F15:F47,"<3,95") -> 31 | H51: =COUNTIFS(H15:H47,">2,95",H15:H47,"<3,95") -> 2 | J51: =COUNTIFS(J15:J47,">2,95",J15:J47,"<3,95") -> 1 | L51: =COUNTIFS(L15:L47,">2,95",L15:L47,"<3,95") -> 31 | N51: =COUNTIFS(N15:N47,">2,95",N15:N47,"<3,95") -> 1 | P51: =COUNTIF(P$15:P$47,"BUENO") -> 1
C52: DEFICIENTE | D52: =COUNTIFS(D15:D47,">1,95",D15:D47,"<2,95") -> 6 | F52: =COUNTIFS(F15:F47,">1,95",F15:F47,"<2,95") -> 1 | H52: =COUNTIFS(H15:H47,">1,95",H15:H47,"<2,95") -> 28 | J52: =COUNTIFS(J15:J47,">1,95",J15:J47,"<2,95") -> 2 | L52: =COUNTIFS(L15:L47,">1,95",L15:L47,"<2,95") -> 0 | N52: =COUNTIFS(N15:N47,">1,95",N15:N47,"<2,95") -> 1 | P52: =COUNTIF(P$15:P$47,"DEFICIENTE") -> 1
C53: INSUFICIENTE | D53: =COUNTIFS(D15:D47,">=0",D15:D47,"<1,95") -> 18 | F53: =COUNTIFS(F15:F47,">=0",F15:F47,"<1,95") -> 1 | H53: =COUNTIFS(H15:H47,">=0",H15:H47,"<1,95") -> 0 | J53: =COUNTIFS(J15:J47,">=0",J15:J47,"<1,95") -> 28 | L53: =COUNTIFS(L15:L47,">=0",L15:L47,"<1,95") -> 0 | N53: =COUNTIFS(N15:N47,">=0",N15:N47,"<1,95") -> 26 | P53: =COUNTIF(P$15:P$47,"INSUFICIENTE") -> 26
B55: % | C55: EXCELENTE | D55: =D50/COUNTA($A$15:$A$48) -> 0.15151515 | F55: =F50/COUNTA($A$15:$A$48) -> 0 | H55: =H50/COUNTA($A$15:$A$48) -> 0.090909091 | J55: =J50/COUNTA($A$15:$A$48) -> 0.060606061 | L55: =L50/COUNTA($A$15:$A$48) -> 0.060606061 | N55: =N50/COUNTA($A$15:$A$48) -> 0.15151515 | P55: =P50/COUNTA($A$15:$A$48) -> 0.15151515
B56: % | C56: BUENO | D56: =D51/COUNTA($A$15:$A$48) -> 0.12121212 | F56: =F51/COUNTA($A$15:$A$48) -> 0.93939394 | H56: =H51/COUNTA($A$15:$A$48) -> 0.060606061 | J56: =J51/COUNTA($A$15:$A$48) -> 0.03030303 | L56: =L51/COUNTA($A$15:$A$48) -> 0.93939394 | N56: =N51/COUNTA($A$15:$A$48) -> 0.03030303 | P56: =P51/COUNTA($A$15:$A$48) -> 0.03030303
B57: % | C57: DEFICIENTE | D57: =D52/COUNTA($A$15:$A$48) -> 0.18181818 | F57: =F52/COUNTA($A$15:$A$48) -> 0.03030303 | H57: =H52/COUNTA($A$15:$A$48) -> 0.84848485 | J57: =J52/COUNTA($A$15:$A$48) -> 0.060606061 | L57: =L52/COUNTA($A$15:$A$48) -> 0 | N57: =N52/COUNTA($A$15:$A$48) -> 0.03030303 | P57: =P52/COUNTA($A$15:$A$48) -> 0.03030303
B58: % | C58: INSUFICIENTE | D58: =D53/COUNTA($A$15:$A$48) -> 0.54545455 | F58: =F53/COUNTA($A$15:$A$48) -> 0.03030303 | H58: =H53/COUNTA($A$15:$A$48) -> 0 | J58: =J53/COUNTA($A$15:$A$48) -> 0.84848485 | L58: =L53/COUNTA($A$15:$A$48) -> 0 | N58: =N53/COUNTA($A$15:$A$48) -> 0.78787879 | P58: =P53/COUNTA($A$15:$A$48) -> 0.78787879

Sheet CORTE 3 G1
D1: FUNDACIÓN UNIVERSITARIA DE POPAYÁN
D2: PROGRAMA | F2: Contaduría Pública | J2: Grupo | L2: 1
D3: Asignatura | F3: Teoría General de Sistemas | J3: Corte | L3: 3
D4: Docente | F4: Wadys Montilla Ortega | J4: Periodo | L4: 2022-1
D6: Recursos Utilizados | F6: Desarrollo | H6: Dominio | J6: Comunicación | L6: Respeto
C7: EXCELENTE (4,01 a 5) | D7: Hace empleo adecuado de los recursos didácticos, sacándole el mayor provecho, lo que resulta favorable para su presentación | F7: Sabe ajustarse al tiempo asignado, tratando aecuadamente los diversos temas | H7: ='CORTE 1 G1'!G9 -> Excelente dominio del tema, comunica claramente las ideas y frente a las preguntas emite respuestas precisas | J7: Sabe aclarar todas las dudas sobre el tema, con ideas claras y precisas, incluso va más allá del límite de la respuesta | L7: Muestra respeto por el tema tratado y por sus compañeros que requieren algun aclaración
C8: BUENO (3,01 a 4) | D8: Presenta y utiliza recursos didácticos, aunque no le saca el mayor provecho a la presentación | F8: Se ajusta al tiempo asignado, exceptuando el final, donde se toma minutos adicionales. | H8: ='CORTE 1 G1'!G10 -> Dominio del tema aunque algunas ideas no quedan muy claras y hay error en la respuesta de alguna pregunta | J8: Sabe aclarar las dudas de los compañeros, sin ir más allá | L8: Muestra respeto por el tema tratado, pero su forma de responder a sus compañeros no es del todo correcta
C9: DEFICIENTE (2,01 a 3,0) | D9: Pocos recursos y solo son utilizados en algunos momentos de la presentación | F9: Dedica mucho tiempo a algunos aspectos, lo que hace que descuide el útimo tema a tratar | H9: ='CORTE 1 G1'!G11 -> Poco dominio, sus respuestas demuestran impresición que obligan a solicitar mayor aclaración | J9: En algunas preguntas emite respuestas adecuadas y en otras solo son superficiales | L9: Muestra poco respeto por el tema tratado y sus respuestas a sus compañeros denota sarcasmo y despectividad | N9: Ponderación
C10: INSUFICIENTE (0 a 2,0) | D10: Recursos presentados pero no utilizados | F10: No sabe utilizar el tiempo asignado y tampoco trabaja aecuadamente los temas | H10: ='CORTE 1 G1'!G12 -> No hay dominio del tema lo que no le permite responder correctamente las preguntas | J10: No sabe aclarar ninguna duda presentada por los compañeros | L10: No muestra respeto por el tema ni por sus compañeros, dando respuestas inapropiadas
A11: Código | B11: ESTUDIANTE | E11: 0.15 | G11: 0.15 | I11: 0.4 | K11: 0.15 | M11: 0.15
A12: ='CORTE 1 G1'!A15 -> 0 | B12: ='CORTE 1 G1'!B15:B15 -> 0 | D12: 5 | E12: =D12*E$11 -> 0.75 | F12: 3 | G12: =F12*G$11 -> 0.45 | H12: 2.6 | I12: =H12*I$11 -> 1.04 | J12: 1.6 | K12: =J12*K$11 -> 0.24 | L12: 3 | M12: =L12*M$11 -> 0.45 | N12: =SUM(E12+G12+I12+K12+M12) -> 2.93 | P12: =IF(N12=" "," ",IF(N12<1.95,"INSUFICIENTE",IF(N12<2.95,"DEFICIENTE",IF(N12<3.95,"BUENO","EXCELENTE")))) -> DEFICIENTE
A13: ='CORTE 1 G1'!A16 -> 0 | B13: ='CORTE 1 G1'!B16:B16 -> 0 | D13: 3 | E13: =D13*E$11 -> 0.45 | F13: 3 | G13: =F13*G$11 -> 0.45 | H13: 2.6 | I13: =H13*I$11 -> 1.04 | J13: 1.6 | K13: =J13*K$11 -> 0.24 | L13: 3 | M13: =L13*M$11 -> 0.45 | N13: =SUM(E13+G13+I13+K13+M13) -> 2.63 | P13: =IF(N13=" "," ",IF(N13<1.95,"INSUFICIENTE",IF(N13<2.95,"DEFICIENTE",IF(N13<3.95,"BUENO","EXCELENTE")))) -> DEFICIENTE | R13: EXCELENTE
A14: ='CORTE 1 G1'!A17 -> 0 | B14: ='CORTE 1 G1'!B17:B17 -> 0 | D14: 2.1 | E14: =D14*E$11 -> 0.315 | F14: 3 | G14: =F14*G$11 -> 0.45 | H14: 2.6 | I14: =H14*I$11 -> 1.04 | J14: 1.6 | K14: =J14*K$11 -> 0.24 | L14: 3 | M14: =L14*M$11 -> 0.45 | N14: =SUM(E14+G14+I14+K14+M14) -> 2.495 | P14: =IF(N14=" "," ",IF(N14<1.95,"INSUFICIENTE",IF(N14<2.95,"DEFICIENTE",IF(N14<3.95,"BUENO","EXCELENTE")))) -> DEFICIENTE | R14: BUENO
A15: ='CORTE 1 G1'!A18 -> 0 | B15: ='CORTE 1 G1'!B18:B18 -> 0 | D15: 5 | E15: =D15*E$11 -> 0.75 | F15: 3 | G15: =F15*G$11 -> 0.45 | H15: 2.6 | I15: =H15*I$11 -> 1.04 | J15: 1.6 | K15: =J15*K$11 -> 0.24 | L15: 3 | M15: =L15*M$11 -> 0.45 | N15: =SUM(E15+G15+I15+K15+M15) -> 2.93 | P15: =IF(N15=" "," ",IF(N15<1.95,"INSUFICIENTE",IF(N15<2.95,"DEFICIENTE",IF(N15<3.95,"BUENO","EXCELENTE")))) -> DEFICIENTE | R15: SUFICIENTE
A16: ='CORTE 1 G1'!A19 -> 0 | B16: ='CORTE 1 G1'!B19:B19 -> 0 | D16: 4 | E16: =D16*E$11 -> 0.6 | F16: 3.5 | G16: =F16*G$11 -> 0.525 | H16: 4 | I16: =H16*I$11 -> 1.6 | J16: 4.8 | K16: =J16*K$11 -> 0.72 | L16: 4 | M16: =L16*M$11 -> 0.6 | N16: =SUM(E16+G16+I16+K16+M16) -> 4.045 | P16: =IF(N16=" "," ",IF(N16<1.95,"INSUFICIENTE",IF(N16<2.95,"DEFICIENTE",IF(N16<3.95,"BUENO","EXCELENTE")))) -> EXCELENTE | R16: INSUFICIENTE
A17: ='CORTE 1 G1'!A20 -> 0 | B17: ='CORTE 1 G1'!B20:B20 -> 0 | D17: 1 | E17: =D17*E$11 -> 0.15 | F17: 5 | G17: =F17*G$11 -> 0.75 | H17: 5 | I17: =H17*I$11 -> 2 | J17: 1 | K17: =J17*K$11 -> 0.15 | L17: 3 | M17: =L17*M$11 -> 0.45 | N17: =SUM(E17+G17+I17+K17+M17) -> 3.5 | P17: =IF(N17=" "," ",IF(N17<1.95,"INSUFICIENTE",IF(N17<2.95,"DEFICIENTE",IF(N17<3.95,"BUENO","EXCELENTE")))) -> BUENO
A18: ='CORTE 1 G1'!A21 -> 0 | B18: ='CORTE 1 G1'!B21:B21 -> 0 | D18: 3.2 | E18: =D18*E$11 -> 0.48 | F18: 3 | G18: =F18*G$11 -> 0.45 | H18: 2.6 | I18: =H18*I$11 -> 1.04 | J18: 1.6 | K18: =J18*K$11 -> 0.24 | L18: 3 | M18: =L18*M$11 -> 0.45 | N18: =SUM(E18+G18+I18+K18+M18) -> 2.66 | P18: =IF(N18=" "," ",IF(N18<1.95,"INSUFICIENTE",IF(N18<2.95,"DEFICIENTE",IF(N18<3.95,"BUENO","EXCELENTE")))) -> DEFICIENTE
A19: ='CORTE 1 G1'!A22 -> 0 | B19: ='CORTE 1 G1'!B22:B22 -> 0 | D19: 4 | E19: =D19*E$11 -> 0.6 | F19: 2 | G19: =F19*G$11 -> 0.3 | H19: 3 | I19: =H19*I$11 -> 1.2 | J19: 2.5 | K19: =J19*K$11 -> 0.375 | L19: 3 | M19: =L19*M$11 -> 0.45 | N19: =SUM(E19+G19+I19+K19+M19) -> 2.925 | P19: =IF(N19=" "," ",IF(N19<1.95,"INSUFICIENTE",IF(N19<2.95,"DEFICIENTE",IF(N19<3.95,"BUENO","EXCELENTE")))) -> DEFICIENTE
A20: ='CORTE 1 G1'!A23 -> 0 | B20: ='CORTE 1 G1'!B23:B23 -> 0 | D20: 4.6 | E20: =D20*E$11 -> 0.69 | F20: 3 | G20: =F20*G$11 -> 0.45 | H20: 2.6 | I20: =H20*I$11 -> 1.04 | J20: 1.6 | K20: =J20*K$11 -> 0.24 | L20: 3 | M20: =L20*M$11 -> 0.45 | N20: =SUM(E20+G20+I20+K20+M20) -> 2.87 | P20: =IF(N20=" "," ",IF(N20<1.95,"INSUFICIENTE",IF(N20<2.95,"DEFICIENTE",IF(N20<3.95,"BUENO","EXCELENTE")))) -> DEFICIENTE
A21: ='CORTE 1 G1'!A24 -> 0 | B21: ='CORTE 1 G1'!B24:B24 -> 0 | D21: 5 | E21: =D21*E$11 -> 0.75 | F21: 3 | G21: =F21*G$11 -> 0.45 | H21: 2.6 | I21: =H21*I$11 -> 1.04 | J21: 1.6 | K21: =J21*K$11 -> 0.24 | L21: 3 | M21: =L21*M$11 -> 0.45 | N21: =SUM(E21+G21+I21+K21+M21) -> 2.93 | P21: =IF(N21=" "," ",IF(N21<1.95,"INSUFICIENTE",IF(N21<2.95,"DEFICIENTE",IF(N21<3.95,"BUENO","EXCELENTE")))) -> DEFICIENTE
A22: ='CORTE 1 G1'!A25 -> 0 | B22: ='CORTE 1 G1'!B25:B25 -> 0 | D22: 5 | E22: =D22*E$11 -> 0.75 | F22: 3 | G22: =F22*G$11 -> 0.45 | H22: 2.6 | I22: =H22*I$11 -> 1.04 | J22: 1.6 | K22: =J22*K$11 -> 0.24 | L22: 3 | M22: =L22*M$11 -> 0.45 | N22: =SUM(E22+G22+I22+K22+M22) -> 2.93 | P22: =IF(N22=" "," ",IF(N22<1.95,"INSUFICIENTE",IF(N22<2.95,"DEFICIENTE",IF(N22<3.95,"BUENO","EXCELENTE")))) -> DEFICIENTE
A23: ='CORTE 1 G1'!A26 -> 0 | B23: ='CORTE 1 G1'!B26:B26 -> 0 | D23: 5 | E23: =D23*E$11 -> 0.75 | F23: 3 | G23: =F23*G$11 -> 0.45 | H23: 2.6 | I23: =H23*I$11 -> 1.04 | J23: 1.6 | K23: =J23*K$11 -> 0.24 | L23: 3 | M23: =L23*M$11 -> 0.45 | N23: =SUM(E23+G23+I23+K23+M23) -> 2.93 | P23: =IF(N23=" "," ",IF(N23<1.95,"INSUFICIENTE",IF(N23<2.95,"DEFICIENTE",IF(N23<3.95,"BUENO","EXCELENTE")))) -> DEFICIENTE
A24: ='CORTE 1 G1'!A27 -> 0 | B24: ='CORTE 1 G1'!B27:B27 -> 0 | D24: 5 | E24: =D24*E$11 -> 0.75 | F24: 3 | G24: =F24*G$11 -> 0.45 | H24: 2.6 | I24: =H24*I$11 -> 1.04 | J24: 1.6 | K24: =J24*K$11 -> 0.24 | L24: 3 | M24: =L24*M$11 -> 0.45 | N24: =SUM(E24+G24+I24+K24+M24) -> 2.93 | P24: =IF(N24=" "," ",IF(N24<1.95,"INSUFICIENTE",IF(N24<2.95,"DEFICIENTE",IF(N24<3.95,"BUENO","EXCELENTE")))) -> DEFICIENTE
A25: ='CORTE 1 G1'!A28 -> 0 | B25: ='CORTE 1 G1'!B28:B28 -> 0 | D25: 3 | E25: =D25*E$11 -> 0.45 | F25: 3 | G25: =F25*G$11 -> 0.45 | H25: 2.6 | I25: =H25*I$11 -> 1.04 | J25: 1.6 | K25: =J25*K$11 -> 0.24 | L25: 3 | M25: =L25*M$11 -> 0.45 | N25: =SUM(E25+G25+I25+K25+M25) -> 2.63 | P25: =IF(N25=" "," ",IF(N25<1.95,"INSUFICIENTE",IF(N25<2.95,"DEFICIENTE",IF(N25<3.95,"BUENO","EXCELENTE")))) -> DEFICIENTE
A26: ='CORTE 1 G1'!A29 -> 0 | B26: ='CORTE 1 G1'!B29:B29 -> 0 | D26: 4 | E26: =D26*E$11 -> 0.6 | F26: 3 | G26: =F26*G$11 -> 0.45 | H26: 2.6 | I26: =H26*I$11 -> 1.04 | J26: 1.6 | K26: =J26*K$11 -> 0.24 | L26: 3 | M26: =L26*M$11 -> 0.45 | N26: =SUM(E26+G26+I26+K26+M26) -> 2.78 | P26: =IF(N26=" "," ",IF(N26<1.95,"INSUFICIENTE",IF(N26<2.95,"DEFICIENTE",IF(N26<3.95,"BUENO","EXCELENTE")))) -> DEFICIENTE
A27: ='CORTE 1 G1'!A30 -> 0 | B27: ='CORTE 1 G1'!B30:B30 -> 0 | D27: 5 | E27: =D27*E$11 -> 0.75 | F27: 5 | G27: =F27*G$11 -> 0.75 | H27: 2.6 | I27: =H27*I$11 -> 1.04 | J27: 5 | K27: =J27*K$11 -> 0.75 | L27: 3 | M27: =L27*M$11 -> 0.45 | N27: =SUM(E27+G27+I27+K27+M27) -> 3.74 | P27: =IF(N27=" "," ",IF(N27<1.95,"INSUFICIENTE",IF(N27<2.95,"DEFICIENTE",IF(N27<3.95,"BUENO","EXCELENTE")))) -> BUENO
A28: ='CORTE 1 G1'!A31 -> 0 | B28: ='CORTE 1 G1'!B31:B31 -> 0 | D28: 2 | E28: =D28*E$11 -> 0.3 | F28: 3 | G28: =F28*G$11 -> 0.45 | H28: 2.6 | I28: =H28*I$11 -> 1.04 | J28: 1.6 | K28: =J28*K$11 -> 0.24 | L28: 3 | M28: =L28*M$11 -> 0.45 | N28: =SUM(E28+G28+I28+K28+M28) -> 2.48 | P28: =IF(N28=" "," ",IF(N28<1.95,"INSUFICIENTE",IF(N28<2.95,"DEFICIENTE",IF(N28<3.95,"BUENO","EXCELENTE")))) -> DEFICIENTE
... A43: ='CORTE 1 G1'!A46 -> 0 | B43: ='CORTE 1 G1'!B46:B46 -> 0 | D43: 5 | E43: =D43*E$11 -> 0.75 | F43: 3 | G43: =F43*G$11 -> 0.45 | H43: 2.6 | I43: =H43*I$11 -> 1.04 | J43: 1.6 | K43: =J43*K$11 -> 0.24 | L43: 3 | M43: =L43*M$11 -> 0.45 | N43: =SUM(E43+G43+I43+K43+M43) -> 2.93 | P43: =IF(N43=" "," ",IF(N43<1.95,"INSUFICIENTE",IF(N43<2.95,"DEFICIENTE",IF(N43<3.95,"BUENO","EXCELENTE")))) -> DEFICIENTE
A44: ='CORTE 1 G1'!A63 -> 0 | B44: ='CORTE 1 G1'!B63:B63 -> 0 | D44: 5 | E44: =D44*E$11 -> 0.75 | F44: 3 | G44: =F44*G$11 -> 0.45 | H44: 2.6 | I44: =H44*I$11 -> 1.04 | J44: 1.6 | K44: =J44*K$11 -> 0.24 | L44: 3 | M44: =L44*M$11 -> 0.45 | N44: =SUM(E44+G44+I44+K44+M44) -> 2.93 | P44: =IF(N44=" "," ",IF(N44<1.95,"INSUFICIENTE",IF(N44<2.95,"DEFICIENTE",IF(N44<3.95,"BUENO","EXCELENTE")))) -> DEFICIENTE
C47: EXCELENTE | D47: =COUNTIF(D12:D44,">3,95") -> 19 | F47: =COUNTIF(F12:F44,">3,95") -> 5 | H47: =COUNTIF(H12:H44,">3,95") -> 2 | J47: =COUNTIF(J12:J44,">3,95") -> 4 | L47: =COUNTIF(L12:L44,">3,95") -> 3 | N47: =COUNTIF(N12:N44,">3,95") -> 3 | P47: =COUNTIF(P$12:P$44,"EXCELENTE") -> 3
C48: BUENO | D48: =COUNTIFS(D12:D44,">2,95",D12:D44,"<3,95") -> 9 | F48: =COUNTIFS(F12:F44,">2,95",F12:F44,"<3,95") -> 27 | H48: =COUNTIFS(H12:H44,">2,95",H12:H44,"<3,95") -> 3 | J48: =COUNTIFS(J12:J44,">2,95",J12:J44,"<3,95") -> 0 | L48: =COUNTIFS(L12:L44,">2,95",L12:L44,"<3,95") -> 30 | N48: =COUNTIFS(N12:N44,">2,95",N12:N44,"<3,95") -> 2 | P48: =COUNTIF(P$12:P$44,"BUENO") -> 2
C49: DEFICIENTE | D49: =COUNTIFS(D12:D44,">1,95",D12:D44,"<2,95") -> 4 | F49: =COUNTIFS(F12:F44,">1,95",F12:F44,"<2,95") -> 1 | H49: =COUNTIFS(H12:H44,">1,95",H12:H44,"<2,95") -> 28 | J49: =COUNTIFS(J12:J44,">1,95",J12:J44,"<2,95") -> 1 | L49: =COUNTIFS(L12:L44,">1,95",L12:L44,"<2,95") -> 0 | N49: =COUNTIFS(N12:N44,">1,95",N12:N44,"<2,95") -> 28 | P49: =COUNTIF(P$12:P$44,"DEFICIENTE") -> 28
C50: INSUFICIENTE | D50: =COUNTIFS(D12:D44,">=0",D12:D44,"<1,95") -> 1 | F50: =COUNTIFS(F12:F44,">=0",F12:F44,"<1,95") -> 0 | H50: =COUNTIFS(H12:H44,">=0",H12:H44,"<1,95") -> 0 | J50: =COUNTIFS(J12:J44,">=0",J12:J44,"<1,95") -> 28 | L50: =COUNTIFS(L12:L44,">=0",L12:L44,"<1,95") -> 0 | N50: =COUNTIFS(N12:N44,">=0",N12:N44,"<1,95") -> 0 | P50: =COUNTIF(P$12:P$44,"INSUFICIENTE") -> 0
B52: % | C52: EXCELENTE | D52: =D47/COUNTA($A$12:$A$45) -> 0.57575758 | F52: =F47/COUNTA($A$12:$A$45) -> 0.15151515 | H52: =H47/COUNTA($A$12:$A$45) -> 0.060606061 | J52: =J47/COUNTA($A$12:$A$45) -> 0.12121212 | L52: =L47/COUNTA($A$12:$A$45) -> 0.090909091 | N52: =N47/COUNTA($A$12:$A$45) -> 0.090909091 | P52: =P47/COUNTA($A$12:$A$45) -> 0.090909091
B53: % | C53: BUENO | D53: =D48/COUNTA($A$12:$A$45) -> 0.27272727 | F53: =F48/COUNTA($A$12:$A$45) -> 0.81818182 | H53: =H48/COUNTA($A$12:$A$45) -> 0.090909091 | J53: =J48/COUNTA($A$12:$A$45) -> 0 | L53: =L48/COUNTA($A$12:$A$45) -> 0.90909091 | N53: =N48/COUNTA($A$12:$A$45) -> 0.060606061 | P53: =P48/COUNTA($A$12:$A$45) -> 0.060606061
B54: % | C54: DEFICIENTE | D54: =D49/COUNTA($A$12:$A$45) -> 0.12121212 | F54: =F49/COUNTA($A$12:$A$45) -> 0.03030303 | H54: =H49/COUNTA($A$12:$A$45) -> 0.84848485 | J54: =J49/COUNTA($A$12:$A$45) -> 0.03030303 | L54: =L49/COUNTA($A$12:$A$45) -> 0 | N54: =N49/COUNTA($A$12:$A$45) -> 0.84848485 | P54: =P49/COUNTA($A$12:$A$45) -> 0.84848485
B55: % | C55: INSUFICIENTE | D55: =D50/COUNTA($A$12:$A$45) -> 0.03030303 | F55: =F50/COUNTA($A$12:$A$45) -> 0 | H55: =H50/COUNTA($A$12:$A$45) -> 0 | J55: =J50/COUNTA($A$12:$A$45) -> 0.84848485 | L55: =L50/COUNTA($A$12:$A$45) -> 0 | N55: =N50/COUNTA($A$12:$A$45) -> 0 | P55: =P50/COUNTA($A$12:$A$45) -> 0

Sheet PERSONAL
C1: FUNDACIÓN UNIVERSITARIA DE POPAYÁN
A2: CÓDIGO | D2: PROGRAMA | F2: Contaduría Pública | H2: Grupo | J2: 1
A3: 18211055 | D3: Asignatura | F3: Teoría General de Sistemas | H3: Periodo | J3: 2022-1
D4: Docente | F4: Wadys Montilla Ortega
A6: ESTUDIANTE | B6: Corte | C6: ='CORTE 1 G1'!C8 -> Recursos Utilizados | E6: ='CORTE 1 G1'!E8 -> Desarrollo | G6: ='CORTE 1 G1'!G8 -> Dominio | I6: ='CORTE 1 G1'!N8 -> Comunicación | K6: ='CORTE 1 G1'!P8 -> Respeto | N6: DEF.
A7: =PROPER(VLOOKUP(A3,'CORTE 1 G1'!A15:T63,2,)) -> #N/A | B7: 1 | C7: =VLOOKUP(A$3,'CORTE 1 G1'!A$15:R$63,4,0) -> #N/A | D7: =IF(C7<1.95,'CORTE 1 G1'!C12,IF(C7<2.95,'CORTE 1 G1'!C11,IF(C7<3.95,'CORTE 1 G1'!C10,IF(C7<=5,'CORTE 1 G1'!C9)))) -> #N/A | E7: =VLOOKUP(A$3,'CORTE 1 G1'!A$15:R$63,6,0) -> #N/A | F7: =IF(E7<1.95,'CORTE 1 G1'!E12,IF(E7<2.95,'CORTE 1 G1'!E11,IF(E7<3.95,'CORTE 1 G1'!E10,IF(E7<=5,'CORTE 1 G1'!E9)))) -> #N/A | G7: =VLOOKUP(A$3,'CORTE 1 G1'!A$15:R$63,8,0) -> #N/A | H7: =IF(G7<1.95,'CORTE 1 G1'!G12,IF(G7<2.95,'CORTE 1 G1'!G11,IF(G7<3.95,'CORTE 1 G1'!G10,IF(G7<=5,'CORTE 1 G1'!G9)))) -> #N/A | I7: =VLOOKUP(A$3,'CORTE 1 G1'!A$15:R$63,10,0) -> #N/A | J7: =IF(I7<1.95,'CORTE 1 G1'!N12,IF(I7<2.95,'CORTE 1 G1'!N11,IF(I7<3.95,'CORTE 1 G1'!N10,IF(I7<=5,'CORTE 1 G1'!N9)))) -> #N/A | K7: =VLOOKUP(A$3,'CORTE 1 G1'!A$15:R$63,12,0) -> #N/A | L7: =IF(K7<1.95,'CORTE 1 G1'!P12,IF(K7<2.95,'CORTE 1 G1'!P11,IF(K7<3.95,'CORTE 1 G1'!P10,IF(K7<=5,'CORTE 1 G1'!P9)))) -> #N/A | N7: =VLOOKUP(A$3,'CORTE 1 G1'!A$15:R$63,14,0) -> #N/A
C8: ='CORTE 2 G1'!D6 -> Docente | E8: ='CORTE 2 G1'!F6 -> Wadys Montilla Ortega | G8: ='CORTE 2 G1'!H6 -> 0 | I8: ='CORTE 2 G1'!J6 -> 0 | K8: ='CORTE 2 G1'!L6 -> 0
B9: 2 | C9: =VLOOKUP(A$3,'CORTE 2 G1'!A$15:N$47,4,0) -> #N/A | D9: =IF(C9<1.95,'CORTE 2 G1'!D10,IF(C9<2.95,'CORTE 2 G1'!D9,IF(C9<3.95,'CORTE 2 G1'!D8,IF(C9<=5,'CORTE 2 G1'!D7)))) -> #N/A | E9: =VLOOKUP(A$3,'CORTE 2 G1'!A$15:N$47,6,0) -> #N/A | F9: =IF(E9<1.95,'CORTE 2 G1'!F10,IF(E9<2.95,'CORTE 2 G1'!F9,IF(E9<3.95,'CORTE 2 G1'!F8,IF(E9<=5,'CORTE 2 G1'!F7)))) -> #N/A | G9: =VLOOKUP(A$3,'CORTE 2 G1'!A$15:N$47,8,0) -> #N/A | H9: =IF(G9<1.95,'CORTE 1 G1'!G12,IF(G9<2.95,'CORTE 1 G1'!G11,IF(G9<3.95,'CORTE 1 G1'!G10,IF(G9<=5,'CORTE 1 G1'!G9)))) -> #N/A | I9: =VLOOKUP(A$3,'CORTE 2 G1'!A$15:N$47,10,0) -> #N/A | J9: =IF(I9<1.95,'CORTE 2 G1'!J10,IF(I9<2.95,'CORTE 2 G1'!J9,IF(I9<3.95,'CORTE 2 G1'!J8,IF(I9<=5,'CORTE 2 G1'!J7)))) -> #N/A | K9: =VLOOKUP(A$3,'CORTE 2 G1'!A$15:N$47,12,0) -> #N/A | L9: =IF(K9<1.95,'CORTE 2 G1'!L10,IF(K9<2.95,'CORTE 2 G1'!L9,IF(K9<3.95,'CORTE 2 G1'!L8,IF(K9<=5,'CORTE 2 G1'!L7)))) -> #N/A | N9: =VLOOKUP(A$3,'CORTE 2 G1'!A$15:N$47,14,0) -> #N/A
C10: ='CORTE 3 G1'!D6 -> Recursos Utilizados | E10: ='CORTE 3 G1'!F6 -> Desarrollo | G10: ='CORTE 3 G1'!H6 -> Dominio | I10: ='CORTE 3 G1'!J6 -> Comunicación | K10: ='CORTE 3 G1'!L6 -> Respeto
B11: 3 | C11: =VLOOKUP(A$3,'CORTE 3 G1'!A$12:N$44,4,0) -> #N/A | D11: =IF(C11<1.95,'CORTE 3 G1'!D10,IF(C11<2.95,'CORTE 3 G1'!D9,IF(C11<3.95,'CORTE 3 G1'!D8,IF(C11<=5,'CORTE 3 G1'!D7)))) -> #N/A | E11: =VLOOKUP(A$3,'CORTE 3 G1'!A$12:N$44,6,0) -> #N/A | F11: =IF(E11<1.95,'CORTE 3 G1'!F10,IF(E11<2.95,'CORTE 3 G1'!F9,IF(E11<3.95,'CORTE 3 G1'!F8,IF(E11<=5,'CORTE 3 G1'!F7)))) -> #N/A | G11: =VLOOKUP(A$3,'CORTE 3 G1'!A$12:N$44,8,0) -> #N/A | H11: =IF(G11<1.95,'CORTE 3 G1'!H10,IF(G11<2.95,'CORTE 3 G1'!H9,IF(G11<3.95,'CORTE 3 G1'!H8,IF(G11<=5,'CORTE 3 G1'!H7)))) -> #N/A | I11: =VLOOKUP(A$3,'CORTE 3 G1'!A$12:N$44,10,0) -> #N/A | J11: =IF(I11<1.95,'CORTE 3 G1'!J10,IF(I11<2.95,'CORTE 3 G1'!J9,IF(I11<3.95,'CORTE 3 G1'!J8,IF(I11<=5,'CORTE 3 G1'!J7)))) -> #N/A | K11: =VLOOKUP(A$3,'CORTE 3 G1'!A$12:N$44,12,0) -> #N/A | L11: =IF(K11<1.95,'CORTE 3 G1'!L10,IF(K11<2.95,'CORTE 3 G1'!L9,IF(K11<3.95,'CORTE 3 G1'!L8,IF(K11<=5,'CORTE 3 G1'!L7)))) -> #N/A | N11: =VLOOKUP(A$3,'CORTE 3 G1'!A$12:N$44,14,0) -> #N/A
N13: =(N7*30%)+(N9*30%)+(N11*40%) -> #N/A

Sheet CORTE 3 REAL
C4: Programa | E4: =+'CORTE 1 G1'!E4 -> 0 | N4: Grupo | P4: =+'CORTE 1 G1'!P4 -> 0
C5: Asignatura | E5: =+'CORTE 1 G1'!E5 -> 0 | N5: Corte | P5: 3
C6: Docente | E6: =+'CORTE 1 G1'!E6 -> 0 | N6: Periodo | P6: =+'CORTE 1 G1'!P6 -> 0 | R6: Total
C8: Recursos Utilizados | D8: =+'CORTE 1 G1'!D8 -> 0.01 | E8: Desarrollo | F8: =+'CORTE 1 G1'!F8 -> 0.02 | G8: Dominio | M8: =+'CORTE 1 G1'!M8 -> 0.95 | N8: Comunicación | O8: =+'CORTE 1 G1'!O8 -> 0.01 | P8: Respeto | Q8: =+'CORTE 1 G1'!Q8 -> 0.01 | R8: =+D8+F8+M8+O8+Q8 -> 1
B9: EXCELENTE (4,01 a 5) | C9: =+'CORTE 1 G1'!C9:D9 -> Hace empleo adecuado de los recursos didácticos, sacándole el mayor provecho, lo que resulta favorable para su presentación | E9: =+'CORTE 1 G1'!E9:F9 -> Sabe ajustarse al tiempo asignado, tratando adecuadamente los diversos temas | G9: =+'CORTE 1 G1'!G9:M9 -> Excelente dominio del tema, comunica claramente las ideas y frente a las preguntas emite respuestas precisas | N9: =+'CORTE 1 G1'!N9:O9 -> Sabe aclarar todas las dudas sobre el tema, con ideas claras y precisas, incluso va más allá del límite de la respuesta | P9: =+'CORTE 1 G1'!P9:Q9 -> Muestra respeto por el tema tratado y por sus compañeros que requieren algun aclaración
B10: BUENO (3,01 a 4) | C10: =+'CORTE 1 G1'!C10:D10 -> Presenta y utiliza recursos didácticos, aunque no le saca el mayor provecho a la presentación | E10: =+'CORTE 1 G1'!E10:F10 -> Se ajusta al tiempo asignado, exceptuando el final, donde se toma minutos adicionales. | G10: =+'CORTE 1 G1'!G10:M10 -> Dominio del tema aunque algunas ideas no quedan muy claras y hay error en la respuesta de alguna pregunta | N10: =+'CORTE 1 G1'!N10:O10 -> Sabe aclarar las dudas de los compañeros, sin ir más allá | P10: =+'CORTE 1 G1'!P10:Q10 -> Muestra respeto por el tema tratado, pero su forma de responder a sus compañeros no es del todo correcta
B11: DEFICIENTE (2,01 a 3,0) | C11: =+'CORTE 1 G1'!C11:D11 -> Pocos recursos y solo son utilizados en algunos momentos de la presentación | E11: =+'CORTE 1 G1'!E11:F11 -> Dedica mucho tiempo a algunos aspectos, lo que hace que descuide el útimo tema a tratar | G11: =+'CORTE 1 G1'!G11:M11 -> Poco dominio, sus respuestas demuestran impresición que obligan a solicitar mayor aclaración | N11: =+'CORTE 1 G1'!N11:O11 -> En algunas preguntas emite respuestas adecuadas y en otras solo son superficiales | P11: =+'CORTE 1 G1'!P11:Q11 -> Muestra poco respeto por el tema tratado y sus respuestas a sus compañeros denota sarcasmo y despectividad | R11: Ponderación (Nota Final Cargue en SIRES)
B12: INSUFICIENTE (0 a 2,0) | C12: =+'CORTE 1 G1'!C12:D12 -> Recursos presentados pero no utilizados | E12: =+'CORTE 1 G1'!E12:F12 -> No sabe utilizar el tiempo asignado y tampoco trabaja aecuadamente los temas | G12: =+'CORTE 1 G1'!G12:M12 -> No hay dominio del tema lo que no le permite responder correctamente las preguntas | N12: =+'CORTE 1 G1'!N12:O12 -> No sabe aclarar ninguna duda presentada por los compañeros | P12: =+'CORTE 1 G1'!P12:Q12 -> No muestra respeto por el tema ni por sus compañeros, dando respuestas inapropiadas
A13: Código | B13: ESTUDIANTE | C13: =+C8 -> Recursos Utilizados | E13: =+E8 -> Desarrollo | G13: =+G8 -> Dominio | N13: =+N8 -> Comunicación | P13: =+P8 -> Respeto
L14: =SUM(G14:K14) -> 0 | M14: Final Dominio
A15: =+'CORTE 1 G1'!A15 -> 0 | B15: =+'CORTE 1 G1'!B15:B15 -> 0 | D15: =C15*D$8 -> 0 | F15: =E15*F$8 -> 0 | L15: =+(G15*$G$14)+(H15*$H$14)+($I$14*I15)+($J$14*J15)+($K$14*K15) -> 0 | M15: =+L15*$M$8 -> 0 | O15: =N15*$O$8 -> 0 | Q15: =P15*$Q$8 -> 0 | R15: =SUM(D15,F15,M15,O15,Q15) -> 0 | T15: =IF(R15=" "," ",IF(R15<1.95,"INSUFICIENTE",IF(R15<2.95,"DEFICIENTE",IF(R15<3.95,"BUENO","EXCELENTE")))) -> INSUFICIENTE
A16: =+'CORTE 1 G1'!A16 -> 0 | B16: =+'CORTE 1 G1'!B16:B16 -> 0 | D16: =C16*D$8 -> 0 | F16: =E16*F$8 -> 0 | L16: =+(G16*$G$14)+(H16*$H$14)+($I$14*I16)+($J$14*J16)+($K$14*K16) -> 0 | M16: =+L16*$M$8 -> 0 | O16: =N16*$O$8 -> 0 | Q16: =P16*$Q$8 -> 0 | R16: =SUM(D16,F16,M16,O16,Q16) -> 0 | T16: =IF(R16=" "," ",IF(R16<1.95,"INSUFICIENTE",IF(R16<2.95,"DEFICIENTE",IF(R16<3.95,"BUENO","EXCELENTE")))) -> INSUFICIENTE
A17: =+'CORTE 1 G1'!A17 -> 0 | B17: =+'CORTE 1 G1'!B17:B17 -> 0 | D17: =C17*D$8 -> 0 | F17: =E17*F$8 -> 0 | L17: =+(G17*$G$14)+(H17*$H$14)+($I$14*I17)+($J$14*J17)+($K$14*K17) -> 0 | M17: =+L17*$M$8 -> 0 | O17: =N17*$O$8 -> 0 | Q17: =P17*$Q$8 -> 0 | R17: =SUM(D17,F17,M17,O17,Q17) -> 0 | T17: =IF(R17=" "," ",IF(R17<1.95,"INSUFICIENTE",IF(R17<2.95,"DEFICIENTE",IF(R17<3.95,"BUENO","EXCELENTE")))) -> INSUFICIENTE
A18: =+'CORTE 1 G1'!A18 -> 0 | B18: =+'CORTE 1 G1'!B18:B18 -> 0 | D18: =C18*D$8 -> 0 | F18: =E18*F$8 -> 0 | L18: =+(G18*$G$14)+(H18*$H$14)+($I$14*I18)+($J$14*J18)+($K$14*K18) -> 0 | M18: =+L18*$M$8 -> 0 | O18: =N18*$O$8 -> 0 | Q18: =P18*$Q$8 -> 0 | R18: =SUM(D18,F18,M18,O18,Q18) -> 0 | T18: =IF(R18=" "," ",IF(R18<1.95,"INSUFICIENTE",IF(R18<2.95,"DEFICIENTE",IF(R18<3.95,"BUENO","EXCELENTE")))) -> INSUFICIENTE
A19: =+'CORTE 1 G1'!A19 -> 0 | B19: =+'CORTE 1 G1'!B19:B19 -> 0 | D19: =C19*D$8 -> 0 | F19: =E19*F$8 -> 0 | L19: =+(G19*$G$14)+(H19*$H$14)+($I$14*I19)+($J$14*J19)+($K$14*K19) -> 0 | M19: =+L19*$M$8 -> 0 | O19: =N19*$O$8 -> 0 | Q19: =P19*$Q$8 -> 0 | R19: =SUM(D19,F19,M19,O19,Q19) -> 0 | T19: =IF(R19=" "," ",IF(R19<1.95,"INSUFICIENTE",IF(R19<2.95,"DEFICIENTE",IF(R19<3.95,"BUENO","EXCELENTE")))) -> INSUFICIENTE
A20: =+'CORTE 1 G1'!A20 -> 0 | B20: =+'CORTE 1 G1'!B20:B20 -> 0 | D20: =C20*D$8 -> 0 | F20: =E20*F$8 -> 0 | L20: =+(G20*$G$14)+(H20*$H$14)+($I$14*I20)+($J$14*J20)+($K$14*K20) -> 0 | M20: =+L20*$M$8 -> 0 | O20: =N20*$O$8 -> 0 | Q20: =P20*$Q$8 -> 0 | R20: =SUM(D20,F20,M20,O20,Q20) -> 0 | T20: =IF(R20=" "," ",IF(R20<1.95,"INSUFICIENTE",IF(R20<2.95,"DEFICIENTE",IF(R20<3.95,"BUENO","EXCELENTE")))) -> INSUFICIENTE
A21: =+'CORTE 1 G1'!A21 -> 0 | B21: =+'CORTE 1 G1'!B21:B21 -> 0 | D21: =C21*D$8 -> 0 | F21: =E21*F$8 -> 0 | L21: =+(G21*$G$14)+(H21*$H$14)+($I$14*I21)+($J$14*J21)+($K$14*K21) -> 0 | M21: =+L21*$M$8 -> 0 | O21: =N21*$O$8 -> 0 | Q21: =P21*$Q$8 -> 0 | R21: =SUM(D21,F21,M21,O21,Q21) -> 0 | T21: =IF(R21=" "," ",IF(R21<1.95,"INSUFICIENTE",IF(R21<2.95,"DEFICIENTE",IF(R21<3.95,"BUENO","EXCELENTE")))) -> INSUFICIENTE
A22: =+'CORTE 1 G1'!A22 -> 0 | B22: =+'CORTE 1 G1'!B22:B22 -> 0 | D22: =C22*D$8 -> 0 | F22: =E22*F$8 -> 0 | L22: =+(G22*$G$14)+(H22*$H$14)+($I$14*I22)+($J$14*J22)+($K$14*K22) -> 0 | M22: =+L22*$M$8 -> 0 | O22: =N22*$O$8 -> 0 | Q22: =P22*$Q$8 -> 0 | R22: =SUM(D22,F22,M22,O22,Q22) -> 0 | T22: =IF(R22=" "," ",IF(R22<1.95,"INSUFICIENTE",IF(R22<2.95,"DEFICIENTE",IF(R22<3.95,"BUENO","EXCELENTE")))) -> INSUFICIENTE
A23: =+'CORTE 1 G1'!A23 -> 0 | B23: =+'CORTE 1 G1'!B23:B23 -> 0 | D23: =C23*D$8 -> 0 | F23: =E23*F$8 -> 0 | L23: =+(G23*$G$14)+(H23*$H$14)+($I$14*I23)+($J$14*J23)+($K$14*K23) -> 0 | M23: =+L23*$M$8 -> 0 | O23: =N23*$O$8 -> 0 | Q23: =P23*$Q$8 -> 0 | R23: =SUM(D23,F23,M23,O23,Q23) -> 0 | T23: =IF(R23=" "," ",IF(R23<1.95,"INSUFICIENTE",IF(R23<2.95,"DEFICIENTE",IF(R23<3.95,"BUENO","EXCELENTE")))) -> INSUFICIENTE
A24: =+'CORTE 1 G1'!A24 -> 0 | B24: =+'CORTE 1 G1'!B24:B24 -> 0 | D24: =C24*D$8 -> 0 | F24: =E24*F$8 -> 0 | L24: =+(G24*$G$14)+(H24*$H$14)+($I$14*I24)+($J$14*J24)+($K$14*K24) -> 0 | M24: =+L24*$M$8 -> 0 | O24: =N24*$O$8 -> 0 | Q24: =P24*$Q$8 -> 0 | R24: =SUM(D24,F24,M24,O24,Q24) -> 0 | T24: =IF(R24=" "," ",IF(R24<1.95,"INSUFICIENTE",IF(R24<2.95,"DEFICIENTE",IF(R24<3.95,"BUENO","EXCELENTE")))) -> INSUFICIENTE
A25: =+'CORTE 1 G1'!A25 -> 0 | B25: =+'CORTE 1 G1'!B25:B25 -> 0 | D25: =C25*D$8 -> 0 | F25: =E25*F$8 -> 0 | L25: =+(G25*$G$14)+(H25*$H$14)+($I$14*I25)+($J$14*J25)+($K$14*K25) -> 0 | M25: =+L25*$M$8 -> 0 | O25: =N25*$O$8 -> 0 | Q25: =P25*$Q$8 -> 0 | R25: =SUM(D25,F25,M25,O25,Q25) -> 0 | T25: =IF(R25=" "," ",IF(R25<1.95,"INSUFICIENTE",IF(R25<2.95,"DEFICIENTE",IF(R25<3.95,"BUENO","EXCELENTE")))) -> INSUFICIENTE
A26: =+'CORTE 1 G1'!A26 -> 0 | B26: =+'CORTE 1 G1'!B26:B26 -> 0 | D26: =C26*D$8 -> 0 | F26: =E26*F$8 -> 0 | L26: =+(G26*$G$14)+(H26*$H$14)+($I$14*I26)+($J$14*J26)+($K$14*K26) -> 0 | M26: =+L26*$M$8 -> 0 | O26: =N26*$O$8 -> 0 | Q26: =P26*$Q$8 -> 0 | R26: =SUM(D26,F26,M26,O26,Q26) -> 0 | T26: =IF(R26=" "," ",IF(R26<1.95,"INSUFICIENTE",IF(R26<2.95,"DEFICIENTE",IF(R26<3.95,"BUENO","EXCELENTE")))) -> INSUFICIENTE
... A65: =+'CORTE 1 G1'!A65 -> 0 | B65: =+'CORTE 1 G1'!B65:B65 -> 0 | D65: =C65*D$8 -> 0 | F65: =E65*F$8 -> 0 | L65: =+(G65*$G$14)+(H65*$H$14)+($I$14*I65)+($J$14*J65)+($K$14*K65) -> 0 | M65: =+L65*$M$8 -> 0 | O65: =N65*$O$8 -> 0 | Q65: =P65*$Q$8 -> 0 | R65: =SUM(D65,F65,M65,O65,Q65) -> 0 | T65: =IF(R65=" "," ",IF(R65<1.95,"INSUFICIENTE",IF(R65<2.95,"DEFICIENTE",IF(R65<3.95,"BUENO","EXCELENTE")))) -> INSUFICIENTE
C68: =COUNTIF(C15:C65,">3,95") -> 0 | E68: =COUNTIF(E15:E65,">3,95") -> 0 | G68: =COUNTIF(L15:L65,">3,95") -> 0 | N68: =COUNTIF(N15:N65,">3,95") -> 0 | P68: =COUNTIF(P15:P65,">3,95") -> 0 | R68: =COUNTIF(R15:R65,">3,95") -> 0 | T68: =COUNTIF(T$15:T$65,"EXCELENTE") -> 0
C69: =COUNTIFS(C15:C65,">2,95",C15:C65,"<3,95") -> 0 | E69: =COUNTIFS(E15:E65,">2,95",E15:E65,"<3,95") -> 0 | G69: =COUNTIFS(L15:L65,">2,95",L15:L65,"<3,95") -> 0 | N69: =COUNTIFS(N15:N65,">2,95",N15:N65,"<3,95") -> 0 | P69: =COUNTIFS(P15:P65,">2,95",P15:P65,"<3,95") -> 0 | R69: =COUNTIFS(R15:R65,">2,95",R15:R65,"<3,95") -> 0 | T69: =COUNTIF(T$15:T$65,"BUENO") -> 0
C70: =COUNTIFS(C15:C65,">1,95",C15:C65,"<2,95") -> 0 | E70: =COUNTIFS(E15:E65,">1,95",E15:E65,"<2,95") -> 0 | G70: =COUNTIFS(L15:L65,">1,95",L15:L65,"<2,95") -> 0 | N70: =COUNTIFS(N15:N65,">1,95",N15:N65,"<2,95") -> 0 | P70: =COUNTIFS(P15:P65,">1,95",P15:P65,"<2,95") -> 0 | R70: =COUNTIFS(R15:R65,">1,95",R15:R65,"<2,95") -> 0 | T70: =COUNTIF(T$15:T$65,"DEFICIENTE") -> 0
