Workbook

Sheet Instrucciónes de Uso 
D1: INSTRUCCIONES PARA DILIGENCIAMIENTO DE LA PLANTILLA DE MICROCURRÍCULOS
A7: Notas de Aclaración:
A8: La plantilla esta compuesta de (6) partes de las cuales solo se puede diligenciar (5), en los espacios en blanco. Se debe tener en cuenta que, la última hoja denominada Principal, es la hoja que debe ser impresa y entregada a registro. Adicionalmente se debe aclarar que la hoja se encuentra protegida a excepción de la fecha de actualización, y el acta de comité donde se aprobó el microcurrículo.
A11: 1. INICIAL:
A12: Esta hoja corresponde a la información relacionada con el programa, código de asignatura, horas trabajo independiente, número de créditos, horas acompañamiento directo, conocimientos previos, descripción de la asignatura y determinar si es o no habilitable.
A15: 2. RAP - RAC
A16: Esta hoja corresponde a la información relacionada con los resultados de aprendizaje de programa (RAP) y los resultados de aprendizaje de curso (RAC). 1. Los resultados que se describan en este Microcurrilculo, debe ser nombrados todos los del programa 2. De acuerdo a los lineamientos institucionales por cada asignatura se debe generar un (1) ó máximo (2) resultados de aprendizaje de curso, el docente que genere o requeriera campos adicionales debe generar una solicitud a la coord.gestioncurricular@fup.edu.co para la edición de la plantilla. 3. Por cada Resultado de Aprendizaje de curso se debe marcar a cual RAP esta tributando.
A23: 3. ESTRATEG. APRENDIZAJE
A24: Esta hoja describe las diferentes estrategias que se utilizan para el aprendizaje, el docente debe marcar con una X al lado izquierdo, para mencionar la que va utilizar en el desarrollo de la asignatura. Si el docente no encuentra alguna estrategía con la cual se sienta identificado, en la parte inferior hay disponibles (3) renglones para mencionar la que utiliza.
A28: 4. CONTENIDO
A29: Esta hoja cuenta con un espacio para diligenciar el título de la tematica en cada unidad, y cuenta con 15 renglones para decribir los temas.
A31: 5. BIBLIOGRAFIA-CIBERGRAFIA
A32: Esta hoja cuenta con un espacio para diligenciar la bibliografia, y la cibergrafía, es importante recordar utilizar el material tambien generado por investigación intern, de los profes y estudiantes investigadores.
... A35: Esta hoja no es editable en su contenido, solo se puede actualizar la fecha de aprobación del comité curricular. NOTA: En esta hoja se encuentran descritas las rúbricas las cuales son lineamientos institucionales, si el docente genera rúbricas diferentes, al momento de entregar el archivo de notas, debe convertitrlas en las establoecidas de manera institucional.

Sheet 1. INICIAL
A1: SECCIÓN 1 INICIAL
A7: Programa Académico
A8: Nombre de la Asignatura
A9: Código de Asignatura | E9: Semestre:
A10: Número de Créditos: | B10: 2 | C10: Horas Acompañamiento Directo: | E10: 2 | F10: Horas Trabajo Independiente | H10: 4
A11: Asignatura Habilitable: | C11: Habilitable
A12: Conocimientos Previos
A13: 1
A14: 2
A15: 3
A16: 4
A17: 5
A18: 6
A19: 7
A20: 8
A21: 9
A22: 10
A24: Descripción de la Asignatura (Máximo 3,000 caracteres)

Sheet 2. RAP-RAC
A1: SECCIÓN 2 RAP-RAC
A7: RESULTADOS DE APRENDIZAJE DE PROGRAMA (RAP) (Que el micro currículo tributa)
A8: RAP 1
A9: RAP 2
A10: RAP 3
A11: RAP 4
A12: RAP 5
A13: RAP 6
A14: RAP 7
A15: RAP 8
A16: RAP 9
A17: RAP 10
... A19: RAC 1
A20: Tributa a RAP | B20: RAP 1 | D20: Revisar los verbos, de acuerdo al dominio del tema, de acuerdo la taxonomía de Bloom Recuerdar la estructura de creación del Resultado de Aprendizaje: Verbo en Infinitivo + Objeto y/o sujeto + Condición/ Contexto El resultado de Aprendizaje de Curso se escribe en la parte azul
B21: RAP 2
B22: RAP 3
B23: RAP 4
B24: RAP 5
B25: RAP 6
B26: RAP 7
B27: RAP 8
B28: RAP 9
B29: RAP 10
A30: RAC 2
A31: Tributa a RAP | B31: RAP 1 | D31: Si Aplica, poner un segundo RAC, poner en la recuadro azul claro Revisar los verbos, de acuerdo al dominio del tema, de acuerdo la taxonomía de Bloom Recuerdar la estructura de creación del Resultado de Aprendizaje: Verbo en Infinitivo + Objeto y/o sujeto + Condición/ Contexto
B32: RAP 2
B33: RAP 3 | J33: La elaboración de RAC, se realiza basado en la taxonomia de Bloom: Semestres de (9) y (10)
B34: RAP 4
B35: RAP 5
B36: RAP 6
B37: RAP 7
B38: RAP 8
B39: RAP 9
B40: RAP 10

Sheet BASE
B2: Nombre de los Programas | D2: Semestre | F2: Tipo del curso | H2: Asignatura Habilitable | J2: Marque X
B3: Administracion De Empresas | D3: I | F3: Teórico | H3: Habilitable | J3: X
B4: Administracion De Empresas - Mod. Virtual | D4: II | F4: Práctico | H4: No Habilitable
B5: Administracion De Empresas Agropecuarias | D5: III | F5: Teórico Práctico
B6: Administracion Empresas Agropecuarias - Mod.Virtual | D6: IV
B7: Arquitectura | D7: V
B8: Comunicacion Social | D8: VI
B9: Comunicacion Social - Mod. Virtual | D9: VII
B10: Contaduria Publica | D10: VIII
B11: Derecho | D11: IX
B12: Ecologia | D12: X
B13: Economia | D13: Posgrado
B14: Especializacion En Derecho Constitucional
B15: Especializacion En Derecho Procesal
B16: Especializacion En Riesgo de desastres integrada a la planificación Territorial
B17: Especializacion En Psicologia Educativa
B18: Especializacion En Psicologia Social Comunitaria
B19: Especializacion Gerencia Del Talento Humano
B20: Ingenieria De Sistemas
B21: Ingenieria Industrial
B22: Licenciatura En Educacion Basica Con Enfasis En Educacion Artistica
B23: Licenciatura En Educación Artística Y Cultural
B24: Psicologia
B25: Trabajo Social
B26: Ingeniería Agroecologica

Sheet 3. ESTRATEG. APRENDIZAJE
A1: SECCIÓN 3 ESTRATEGIA DE APRENDIZAJE
K2: N° | L2: Estrategias centrada en el alumno
K3: 1 | L3: El método de Problemas
K4: 2 | L4: El método del juego de roles
K5: 3 | L5: El método de situaciones (o de casos)
K6: 4 | L6: El método de indagación
A7: # Estrategia | B7: Seleccione | C7: Escoja la estrategia utilizar, marque con X al lado izquierdo | K7: 5 | L7: La tutoría
A8: 1 | B8: Lección Magistral | K8: 6 | L8: La enseñanza por descubrimiento
A9: 1_1 | C9: Exposición del Académico | K9: 7 | L9: El método de proyectos
A10: 1_2 | C10: Lectura dirigida
A11: 1_3 | C11: Revisión Bibliográfica
A12: 1_4 | C12: Seminario | K12: Estrategias centrada en el docente
A13: 1_5 | C13: Conferencia | K13: 1 | L13: La enseñanza tradicional
A14: 2 | B14: Estudios de Caso | K14: 2 | L14: La enseñanza expositiva
A15: 2_1 | C15: Problemas Reales | K15: 3 | L15: El método de situaciones (o de casos)
A16: 2_2 | C16: Análisis completo del Problema
A17: 2_3 | C17: Desarrollo de Guías
A18: 2_4 | C18: Visitas de Campo o empresarial | K18: 4 | L18: El método de indagación
A19: 2_5 | C19: Prácticas de Laboratorio | K19: 5 | L19: La tutoría
A20: 3 | B20: Aprendizaje Orientado a Proyecto | K20: 6 | L20: La enseñanza por descubrimiento
A21: 3_1 | C21: Realización de un Proyecto
A22: 3_2 | C22: Resolver problemas o Actividades.
A23: 3_3 | C23: Asumir Responsabilidades
A24: 3_4 | C24: Guías y procedimientos | K24: 7 | L24: El método de proyectos
A25: 3_5 | C25: Participación en Proyectos de Investigación
A26: 4 | B26: Aprendizaje Colaborativo
A27: 4_1 | C27: Integración de grupos
A28: 4_2 | C28: Panel de discusión
A29: 4_3 | C29: Foro del Diálogo | K29: Estrategias centrada en el proceso y/o mediaciones didácticas
A30: 5 | B30: Aprendizaje Basado en Problemas | K30: 1 | L30: La simulación.
A31: 5_1 | C31: Situaciones Problemáticas de contexto real | K31: 2 | L31: El seminario investigativo.
A32: 5_2 | C32: Simulaciones | K32: 3 | L32: El método de los cuatro pasos.
A33: 5_3 | C33: El profesor como facilitador | K33: 4 | L33: El modelo didáctico operativo.
A34: 5_4 | C34: Talleres teóricos - prácticos (Talleres teniendo en cuenta el ABP)
A35: 6 | B35: Otros (Describir cuales) y marcarlas al lado izquierdo con una X | K35: 5 | L35: La enseñanza mediante el conflicto cognitivo.
A36: 6_1 | C36: La clase Invertida - The Flipped Classroom. | K36: 6 | L36: La enseñanza mediante la investigación dirigida.
A37: 6_2 | C37: Mediación por Tics | K37: 7 | L37: El taller educativo
A38: 6_3 | C38: Recurso Multimedia | K38: Estrategias centradas en el objeto de conocimiento.
A39: 6_4 | K39: 1 | L39: La enseñanza basada en analogías o aprendizajes por transferencia análogica.
A40: 6_5 | K40: 2 | L40: La enseñanza por expliación y contrastación de modelos.
...

Sheet 4. Contenido
A1: SECCIÓN 4 CONTENIDO Esta sección se diligencia los contenidos orientados. Por favor no eliminar filas ni casillas
A7: CONTENIDO
A8: Nombre del Tema 1: | C8: objetivo especifico por Unidad 1 | D8: dia | E8: mes | F8: año | G8: Estrategía Pedagógica (Presencial) Revisar las del punto 3 | H8: Estrategía Pedagógica (Independiente) Revisar las del punto 3 | I8: Hr trabajo Presencial | J8: Hr Trabajo Independiente
K16: =13*40% -> 5.2
A24: Nombre del Tema 2: | C24: objetivo especifico por Unidad 2 | D24: dia | E24: mes | F24: año | G24: =+G8 -> Estrategía Pedagógica (Presencial) Revisar las del punto 3 | H24: =+H8 -> Estrategía Pedagógica (Independiente) Revisar las del punto 3 | I24: Hr trabajo Presencial | J24: Hr Trabajo Independiente
A40: Nombre del Tema 3: | C40: objetivo especifico por Unidad 3 | D40: dia | E40: mes | F40: año | G40: =+G24 -> Estrategía Pedagógica (Presencial) Revisar las del punto 3 | H40: =+H24 -> Estrategía Pedagógica (Independiente) Revisar las del punto 3 | I40: Hr trabajo Presencial | J40: Hr Trabajo Independiente
A56: Nombre del Tema 4: | C56: objetivo especifico por Unidad 4 | D56: dia | E56: mes | F56: año | G56: Estrategís Pedagógica (Presencial) Revisar las del punto 3 | H56: Estrategís Pedagógica (Independiente) Revisar las del punto 3 | I56: Hr trabajo Presencial | J56: Hr Trabajo Independiente
A72: Nombre del Tema 5: | C72: objetivo especifico por Unidad 5 | D72: dia | E72: mes | F72: año | G72: Estrategís Pedagógica (Presencial) | H72: Estrategís Pedagógica (Independiente) | I72: Hr trabajo Presencial | J72: Hr Trabajo Independiente
A88: Nombre del Tema 6: | C88: objetivo especifico por Unidad 6 | D88: dia | E88: mes | F88: año | G88: Estrategís Pedagógica (Presencial) | H88: Estrategís Pedagógica (Independiente) | I88: Hr trabajo Presencial | J88: Hr Trabajo Independiente

Sheet 5. BIBLIOGRAFIA-CIBERGRAFIA
A1: SECCIÓN 5 BIBLIOGRAFIA-CIBERGRAFIA
A7: BIBLIOGRAFIA | I7: N/A
A8: AUTOR (ES) | B8: TITULO | C8: Editorial | D8: Edición y/ o Año | I8: =+B9 -> 0
I9: =+B10 -> 0
I10: =+B11 -> 0
I11: =+B12 -> 0
I12: =+B13 -> 0
I13: =+B14 -> 0
I14: =+B15 -> 0
I15: =+B16 -> 0
I16: =+B17 -> 0
I17: =+B18 -> 0
I18: =+B19 -> 0
I19: =+B20 -> 0
I20: =+B21 -> 0
... I43: =+B44 -> 0
I44: =+B47 -> 0
A45: CIBERGRAFÍA | I45: =+B48 -> 0
A46: AUTOR (ES) | B46: TITULO | C46: Recuperado Día/Mes/Año | D46: Disponible en <URL> | I46: =+B49 -> 0
I47: =+B50 -> 0
I48: =+B51 -> 0
I49: =+B52 -> 0
I50: =+B53 -> 0
I51: =+B54 -> 0
I52: =+B55 -> 0
I53: =+B56 -> 0
I54: =+B57 -> 0
I55: =+B58 -> 0
I56: =+B59 -> 0
I57: =+B60 -> 0
I58: =+B61 -> 0
... I105: =+B108 -> 0

Sheet 6. Rúbricas
A1: SECCIÓN 6 RÚBRICAS
A7: Rubrica de Evaluación
A9: El saber | C9: Conocimientos, dominio del tema
A10: El saber hacer | C10: Recursos Utilizados, Desarrollo
A11: El ser | C11: Comunicación, Respeto
A12: Escala de valoración | C12: Criterio de Valoración | E12: Descripción del Desempeño
A13: Desde | B13: Hasta | D13: Recursos Utilizados | E13: Desarrollo | F13: Dominio/ Conocimiento | G13: Comunicación | H13: Respeto
A14: 4 | B14: 5 | C14: Excelente | D14: Hace empleo adecuado de los recursos didácticos, sacándole el mayor provecho, lo que resulta favorable para el desarrollo de su proceso académico. | E14: Aprovecha y se ajusta al tiempo asignado, para la entrega de sus actividades académicas. | F14: Tiene excelente dominio del tema, comunica claramente las ideas y frente a las preguntas emite respuestas precisas | G14: Sabe aclarar todas las dudas sobre el tema con ideas claras y precisas incluso va más allá del límite de la respuesta | H14: Muestra respeto por el tema tratado y por sus compañeros que requieren alguna aclaración
A15: 2.96 | B15: 3.99 | C15: Bueno | D15: Presenta y utiliza recursos didácticos, aunque no le saca el mayor provecho para el desarrollo de su proceso académico. | E15: Se ajusta al tiempo asignado, en algunas ocasiones,para la entrega de sus actividades académicas. | F15: Maneja el Dominio del tema, aunque algunas ideas no quedan muy claras y hay error en la respuesta de una pregunta | G15: Sabe aclarar las dudas de los compañeros sin ir más allá | H15: Muestra respeto por el tema tratado pero la forma de responder a sus compañeros no es del todo correcta
A16: 2 | B16: 2.95 | C16: Deficiente | D16: utiliza pocos recursos y solo son utilizados en algunos momentos de su proceso académico. | E16: Dedica mucho tiempo algunos aspectos, lo que hace que demore en la entrega de sus actividades. | F16: Poco dominio sus respuestas demuestran imprecisión que obligan a solicitar mayor aclaración | G16: En algunos en algunas preguntas emite respuestas adecuadas y en otras solo son superficiales | H16: Muestra poco respeto por el tema tratado y sus respuestas a sus compañeros denota sarcasmo y despectividad
A17: 0 | B17: 1.99 | C17: Insuficiente | D17: Presenta recursos pero no son utilizados | E17: El tiempo asignado no lo utiliza adecuadamente en la entrega de las actividades académicas. | F17: No hay dominio del tema lo que no le permite responder correctamente las preguntas | G17: No sabe aclarar ninguna duda presentada por los compañeros y del docente | H17: No demuestra respeto por el tema ni por sus compañeros dando respuestas inapropiadas

Sheet Documento Imprimir
C1: GESTIÓN CURRICULAR | G1: Código: FO-CU-005
G3: Versión: 01
C4: CONTENIDO MICRO-CURRICULAR
G5: Fecha : junio 2023
A7: Programa Académico | C7: =+'1. INICIAL'!C7:G7 -> 0
A8: Nombre de la Asignatura | C8: =+'1. INICIAL'!C8 -> 0
A9: Código de Asignatura | C9: =+'1. INICIAL'!C9:D9 -> 0 | E9: Semestre: | F9: =+'1. INICIAL'!F9:G9 -> 0
A10: Número de Créditos: | B10: =+'1. INICIAL'!B10 -> 2 | C10: Horas Acompañamiento Directo: | E10: =+'1. INICIAL'!E10 -> 2 | F10: Horas Trabajo Independiente | H10: =+'1. INICIAL'!H10 -> 4
A11: Asignatura Habilitable: | C11: Habilitable
A13: Conocimientos Previos
A14: 1 | B14: =+'1. INICIAL'!B13:H13 -> 0
A15: 2 | B15: =+'1. INICIAL'!B14:H14 -> 0
A16: 3 | B16: =+'1. INICIAL'!B15:H15 -> 0
A17: 4 | B17: =+'1. INICIAL'!B16:H16 -> 0
A18: 5 | B18: =+'1. INICIAL'!B17:H17 -> 0
A19: 6 | B19: =+'1. INICIAL'!B18:H18 -> 0
A20: 7 | B20: =+'1. INICIAL'!B19:H19 -> 0
A21: 8 | B21: =+'1. INICIAL'!B20:H20 -> 0
A22: 9 | B22: =+'1. INICIAL'!B21:H21 -> 0
A23: 10 | B23: =+'1. INICIAL'!B22:H22 -> 0
A25: Descripción de la Asignatura
A26: =+'1. INICIAL'!A25 -> 0
A52: RESULTADOS DE APRENDIZAJE DE PROGRAMA (RAP) (Que el micro currículo tributa)
A53: RAP 1 | B53: =+'2. RAP-RAC'!B8:H8 -> 0
A54: RAP 2 | B54: =+'2. RAP-RAC'!B9:H9 -> 0
A55: RAP 3 | B55: =+'2. RAP-RAC'!B10:H10 -> 0
A56: RAP 4 | B56: =+'2. RAP-RAC'!B11:H11 -> 0
A57: RAP 5 | B57: =+'2. RAP-RAC'!B12:H12 -> 0
A58: RAP 6 | B58: =+'2. RAP-RAC'!B13:H13 -> 0
A59: RAP 7 | B59: =+'2. RAP-RAC'!B14:H14 -> 0
A60: RAP 8 | B60: =+'2. RAP-RAC'!B15:H15 -> 0
A61: RAP 9 | B61: =+'2. RAP-RAC'!B16:H16 -> 0
A62: RAP 10 | B62: =+'2. RAP-RAC'!B17:H17 -> 0
A63: RESULTADOS DE APRENDIZAJE DEL CURSO (RAC) Nota: En caso de formular un RAC adicional inserte un cuadro adicional
A64: =+'2. RAP-RAC'!B19 -> 0 | G64: RAP 1 | H64: =+'2. RAP-RAC'!C20 -> 0
G65: RAP 2 | H65: =+'2. RAP-RAC'!C21 -> 0
G66: RAP 3 | H66: =+'2. RAP-RAC'!C22 -> 0
G67: RAP 4 | H67: =+'2. RAP-RAC'!C23 -> 0
G68: RAP 5 | H68: =+'2. RAP-RAC'!C24 -> 0
G69: RAP 6 | H69: =+'2. RAP-RAC'!C25 -> 0
...

Sheet Planeador Docente Imprimir
F1: DOCENCIA | S1: Código: FO-CU-07
S3: Versión: 01
F4: PLANEADOR DOCENTE
S5: Fecha : junio 2023
A8: Programa Académico | H8: =+'1. INICIAL'!C7 -> 0
A9: Nombre de la Asignatura: | H9: =+'1. INICIAL'!C8 -> 0
A10: Código de Asignatura | H10: =+'1. INICIAL'!C9 -> 0 | N10: Semestre: | P10: =+'1. INICIAL'!F9 -> 0
A11: Número de Créditos: | F11: =+'1. INICIAL'!B10 -> 2 | I11: Horas Acompañamiento Directo: | O11: =+'1. INICIAL'!E10 -> 2 | Q11: Horas Trabajo Independiente | T11: =+'1. INICIAL'!H10 -> 4
A12: Asignatura Habilitable: | F12: =+'1. INICIAL'!C11 -> Habilitable
A14: Nombre del Docente: | F14: Escribir el nombre del Docente
A15: Descripción de la Actividad Curricular: | F15: =+'1. INICIAL'!A25 -> 0
A16: RESULTADOS DE APRENDIZAJE DE PROGRAMA (RAP)
A17: RAP 1 | F17: =+'2. RAP-RAC'!B8 -> 0
A18: RAP 2 | F18: =+'2. RAP-RAC'!B9 -> 0
A19: RAP 3 | F19: =+'2. RAP-RAC'!B10 -> 0
A20: RAP 4 | F20: =+'2. RAP-RAC'!B11 -> 0
A21: RAP 5 | F21: =+'2. RAP-RAC'!B12 -> 0
A22: RAP 6 | F22: =+'2. RAP-RAC'!B13 -> 0
A23: RAP 7 | F23: =+'2. RAP-RAC'!B14 -> 0
A24: RAP 8 | F24: =+'2. RAP-RAC'!B15 -> 0
A25: RAP 9 | F25: =+'2. RAP-RAC'!B16 -> 0
A26: RAP 10 | F26: =+'2. RAP-RAC'!B17 -> 0
A27: RESULTADOS DE APRENDIZAJE DEL CURSO (RAC) Nota: En caso de formular un RAC adicional inserte un cuadro adicional
A28: =+'2. RAP-RAC'!B19 -> 0 | S28: RAP 1 | T28: =+'2. RAP-RAC'!C20 -> 0
S29: RAP 2 | T29: =+'2. RAP-RAC'!C21 -> 0
S30: RAP 3 | T30: =+'2. RAP-RAC'!C22 -> 0
S31: RAP 4 | T31: =+'2. RAP-RAC'!C23 -> 0
S32: RAP 5 | T32: =+'2. RAP-RAC'!C24 -> 0
S33: RAP 6 | T33: =+'2. RAP-RAC'!C25 -> 0
S34: RAP 7 | T34: =+'2. RAP-RAC'!C26 -> 0
S35: RAP 8 | T35: =+'2. RAP-RAC'!C27 -> 0
S36: RAP 9 | T36: =+'2. RAP-RAC'!C28 -> 0
S37: RAP 10 | T37: =+'2. RAP-RAC'!C29 -> 0
A38: RESULTADOS DE APRENDIZAJE DEL CURSO (RAC) Nota: En caso de formular un RAC adicional inserte un cuadro adicional
A39: =+'2. RAP-RAC'!B30 -> 0 | S39: RAP 1 | T39: =+'2. RAP-RAC'!C31 -> 0
S40: RAP 2 | T40: =+'2. RAP-RAC'!C32 -> 0
S41: RAP 3 | T41: =+'2. RAP-RAC'!C33 -> 0
S42: RAP 4 | T42: =+'2. RAP-RAC'!C34 -> 0
S43: RAP 5 | T43: =+'2. RAP-RAC'!C35 -> 0
S44: RAP 6 | T44: =+'2. RAP-RAC'!C36 -> 0
...

Sheet Hoja1
