Workbook

Sheet BASE DE DATOS DOCENTES
A4: PROGRAMA:
G7: Especialización | I7: Maestria
A9: ID | B9: NOMBRES Y APELLIDOS | C9: Dirección | D9: Teléfono | E9: Celular | F9: Profesión | G9: TITULADO | H9: EN CURSO | I9: TITULADO | J9: EN CURSO | K9: Otros | L9: CORREO ELECTRONICO
A100: 1 | B100: N.N.
L102: 1/1

Sheet OFERTA
A4: OFERTA ACADEMICA PERIODO: 20___ - ___
A6: CODIGO | B6: ASIGNATURA | C6: CR | D6: I.H.S. | E6: SEMESTRE | F6: PENSUM
A8: PROGRAMA:
F56: 1/1

Sheet B.D. CONTRATACIONES
A1: ID | B1: VINC | C1: cod | D1: asignatura | E1: Prog | F1: jor | G1: VINC | H1: cod | I1: asignatura | J1: Prog | K1: jor | L1: VINC | M1: cod | N1: asignatura | O1: Prog | P1: jor | Q1: VINC | R1: cod | S1: asignatura | T1: Prog | U1: jor | V1: VINC | W1: cod | X1: asignatura | Y1: Prog | Z1: jor | AA1: VINC | AB1: cod | AC1: asignatura | AD1: Prog | AE1: jor | AF1: VINC | AG1: cod | AH1: asignatura | AI1: Prog | AJ1: jor | AK1: VINC | AL1: cod | AM1: asignatura | AN1: Prog | AO1: jor | AP1: VINC | AQ1: cod | AR1: asignatura | AS1: Prog | AT1: jor | AU1: VINC | AV1: cod | AW1: asignatura | AX1: Prog | AY1: jor | AZ1: VINC | BA1: cod | BB1: asignatura | BC1: Prog | BD1: jor | BE1: VINC | BF1: cod | BG1: asignatura | BH1: Prog | BI1: jor | BJ1: VINC | BK1: cod | BL1: asignatura | BM1: Prog | BN1: jor | BO1: VINC | BP1: cod | BQ1: asignatura | BR1: Prog | BS1: jor | BT1: VINC | BU1: cod | BV1: asignatura | BW1: Prog | BX1: jor
A2: ='CARGA DOCENTE'!J10 -> 0 | B2: ='CARGA DOCENTE'!$H10 -> 0 | C2: =IF(OR(B2="TC",B2="MT"),'CARGA DOCENTE'!$A10," ") | D2: =IF(OR(B2="TC",B2="MT"),'CARGA DOCENTE'!$B10," ") | E2: =IF(OR(B2="TC",B2="MT"),'CARGA DOCENTE'!$C10," ") | F2: =IF(OR(B2="TC",B2="MT"),'CARGA DOCENTE'!$G10," ") | G2: ='CARGA DOCENTE'!$H11 -> 0 | H2: =IF(OR(G2="TC",G2="MT"),'CARGA DOCENTE'!$A11," ") | I2: =IF(OR(G2="TC",G2="MT"),'CARGA DOCENTE'!$B11," ") | J2: =IF(OR(G2="TC",G2="MT"),'CARGA DOCENTE'!$C11," ") | K2: =IF(OR(G2="TC",G2="MT"),'CARGA DOCENTE'!$G11," ") | L2: ='CARGA DOCENTE'!$H12 -> 0 | M2: =IF(OR(L2="TC",L2="MT"),'CARGA DOCENTE'!$A12," ") | N2: =IF(OR(L2="TC",L2="MT"),'CARGA DOCENTE'!$B12," ") | O2: =IF(OR(L2="TC",L2="MT"),'CARGA DOCENTE'!$C12," ") | P2: =IF(OR(L2="TC",L2="MT"),'CARGA DOCENTE'!$G12," ") | Q2: ='CARGA DOCENTE'!$H13 -> 0 | R2: =IF(OR(Q2="TC",Q2="MT"),'CARGA DOCENTE'!$A13," ") | S2: =IF(OR(Q2="TC",Q2="MT"),'CARGA DOCENTE'!$B13," ") | T2: =IF(OR(Q2="TC",Q2="MT"),'CARGA DOCENTE'!$C13," ") | U2: =IF(OR(Q2="TC",Q2="MT"),'CARGA DOCENTE'!$G13," ") | V2: ='CARGA DOCENTE'!$H14 -> 0 | W2: =IF(OR(V2="TC",V2="MT"),'CARGA DOCENTE'!$A14," ") | X2: =IF(OR(V2="TC",V2="MT"),'CARGA DOCENTE'!$B14," ") | Y2: =IF(OR(V2="TC",V2="MT"),'CARGA DOCENTE'!$C14," ") | Z2: =IF(OR(V2="TC",V2="MT"),'CARGA DOCENTE'!$G14," ") | AA2: ='CARGA DOCENTE'!$H15 -> 0 | AB2: =IF(OR(AA2="TC",AA2="MT"),'CARGA DOCENTE'!$A15," ") | AC2: =IF(OR(AA2="TC",AA2="MT"),'CARGA DOCENTE'!$B15," ") | AD2: =IF(OR(AA2="TC",AA2="MT"),'CARGA DOCENTE'!$C15," ") | AE2: =IF(OR(AA2="TC",AA2="MT"),'CARGA DOCENTE'!$G15," ") | AF2: ='CARGA DOCENTE'!$H16 -> 0 | AG2: =IF(OR(AF2="TC",AF2="MT"),'CARGA DOCENTE'!$A16," ") | AH2: =IF(OR(AF2="TC",AF2="MT"),'CARGA DOCENTE'!$B16," ") | AI2: =IF(OR(AF2="TC",AF2="MT"),'CARGA DOCENTE'!$C16," ") | AJ2: =IF(OR(AF2="TC",AF2="MT"),'CARGA DOCENTE'!$G16," ") | AK2: ='CARGA DOCENTE'!$H17 -> 0 | AL2: =IF(OR(AK2="TC",AK2="MT"),'CARGA DOCENTE'!$A17," ") | AM2: =IF(OR(AK2="TC",AK2="MT"),'CARGA DOCENTE'!$B17," ") | AN2: =IF(OR(AK2="TC",AK2="MT"),'CARGA DOCENTE'!$C17," ") | AO2: =IF(OR(AK2="TC",AK2="MT"),'CARGA DOCENTE'!$G17," ") | AP2: ='CARGA DOCENTE'!$H18 -> 0 | AQ2: =IF(OR(AP2="TC",AP2="MT"),'CARGA DOCENTE'!$A18," ") | AR2: =IF(OR(AP2="TC",AP2="MT"),'CARGA DOCENTE'!$B18," ") | AS2: =IF(OR(AP2="TC",AP2="MT"),'CARGA DOCENTE'!$C18," ") | AT2: =IF(OR(AP2="TC",AP2="MT"),'CARGA DOCENTE'!$G18," ") | AU2: ='CARGA DOCENTE'!$H19 -> 0 | AV2: =IF(OR(AU2="TC",AU2="MT"),'CARGA DOCENTE'!$A19," ") | AW2: =IF(OR(AU2="TC",AU2="MT"),'CARGA DOCENTE'!$B19," ") | AX2: =IF(OR(AU2="TC",AU2="MT"),'CARGA DOCENTE'!$C19," ") | AY2: =IF(OR(AU2="TC",AU2="MT"),'CARGA DOCENTE'!$G19," ") | AZ2: ='CARGA DOCENTE'!$H20 -> 0 | BA2: =IF(OR(AZ2="TC",AZ2="MT"),'CARGA DOCENTE'!$A20," ") | BB2: =IF(OR(AZ2="TC",AZ2="MT"),'CARGA DOCENTE'!$B20," ") | BC2: =IF(OR(AZ2="TC",AZ2="MT"),'CARGA DOCENTE'!$C20," ") | BD2: =IF(OR(AZ2="TC",AZ2="MT"),'CARGA DOCENTE'!$G20," ") | BE2: ='CARGA DOCENTE'!$H21 -> 0 | BF2: =IF(OR(BE2="TC",BE2="MT"),'CARGA DOCENTE'!$A21," ") | BG2: =IF(OR(BE2="TC",BE2="MT"),'CARGA DOCENTE'!$B21," ") | BH2: =IF(OR(BE2="TC",BE2="MT"),'CARGA DOCENTE'!$C21," ") | BI2: =IF(OR(BE2="TC",BE2="MT"),'CARGA DOCENTE'!$G21," ") | BJ2: ='CARGA DOCENTE'!$H22 -> 0 | BK2: =IF(OR(BJ2="TC",BJ2="MT"),'CARGA DOCENTE'!$A22," ") | BL2: =IF(OR(BJ2="TC",BJ2="MT"),'CARGA DOCENTE'!$B22," ") | BM2: =IF(OR(BJ2="TC",BJ2="MT"),'CARGA DOCENTE'!$C22," ") | BN2: =IF(OR(BJ2="TC",BJ2="MT"),'CARGA DOCENTE'!$G22," ") | BO2: ='CARGA DOCENTE'!$H23 -> 0 | BP2: =IF(OR(BO2="TC",BO2="MT"),'CARGA DOCENTE'!$A23," ") | BQ2: =IF(OR(BO2="TC",BO2="MT"),'CARGA DOCENTE'!$B23," ") | BR2: =IF(OR(BO2="TC",BO2="MT"),'CARGA DOCENTE'!$C23," ") | BS2: =IF(OR(BO2="TC",BO2="MT"),'CARGA DOCENTE'!$G23," ") | BT2: ='CARGA DOCENTE'!$H24 -> 0 | BU2: =IF(OR(BT2="TC",BT2="MT"),'CARGA DOCENTE'!$A24," ") | BV2: =IF(OR(BT2="TC",BT2="MT"),'CARGA DOCENTE'!$B24," ") | BW2: =IF(OR(BT2="TC",BT2="MT"),'CARGA DOCENTE'!$C24," ") | BX2: =IF(OR(BT2="TC",BT2="MT"),'CARGA DOCENTE'!$G24," ")
A3: ='CARGA DOCENTE'!J28 -> 0 | B3: ='CARGA DOCENTE'!$H28 -> 0 | C3: =IF(OR(B3="TC",B3="MT"),'CARGA DOCENTE'!$A28," ") | D3: =IF(OR(B3="TC",B3="MT"),'CARGA DOCENTE'!$B28," ") | E3: =IF(OR(B3="TC",B3="MT"),'CARGA DOCENTE'!$C28," ") | F3: =IF(OR(B3="TC",B3="MT"),'CARGA DOCENTE'!$G28," ") | G3: ='CARGA DOCENTE'!$H29 -> 0 | H3: =IF(OR(G3="TC",G3="MT"),'CARGA DOCENTE'!$A29," ") | I3: =IF(OR(G3="TC",G3="MT"),'CARGA DOCENTE'!$B29," ") | J3: =IF(OR(G3="TC",G3="MT"),'CARGA DOCENTE'!$C29," ") | K3: =IF(OR(G3="TC",G3="MT"),'CARGA DOCENTE'!$G29," ") | L3: ='CARGA DOCENTE'!$H30 -> 0 | M3: =IF(OR(L3="TC",L3="MT"),'CARGA DOCENTE'!$A30," ") | N3: =IF(OR(L3="TC",L3="MT"),'CARGA DOCENTE'!$B30," ") | O3: =IF(OR(L3="TC",L3="MT"),'CARGA DOCENTE'!$C30," ") | P3: =IF(OR(L3="TC",L3="MT"),'CARGA DOCENTE'!$G30," ") | Q3: ='CARGA DOCENTE'!$H31 -> 0 | R3: =IF(OR(Q3="TC",Q3="MT"),'CARGA DOCENTE'!$A31," ") | S3: =IF(OR(Q3="TC",Q3="MT"),'CARGA DOCENTE'!$B31," ") | T3: =IF(OR(Q3="TC",Q3="MT"),'CARGA DOCENTE'!$C31," ") | U3: =IF(OR(Q3="TC",Q3="MT"),'CARGA DOCENTE'!$G31," ") | V3: ='CARGA DOCENTE'!$H32 -> 0 | W3: =IF(OR(V3="TC",V3="MT"),'CARGA DOCENTE'!$A32," ") | X3: =IF(OR(V3="TC",V3="MT"),'CARGA DOCENTE'!$B32," ") | Y3: =IF(OR(V3="TC",V3="MT"),'CARGA DOCENTE'!$C32," ") | Z3: =IF(OR(V3="TC",V3="MT"),'CARGA DOCENTE'!$G32," ") | AA3: ='CARGA DOCENTE'!$H33 -> 0 | AB3: =IF(OR(AA3="TC",AA3="MT"),'CARGA DOCENTE'!$A33," ") | AC3: =IF(OR(AA3="TC",AA3="MT"),'CARGA DOCENTE'!$B33," ") | AD3: =IF(OR(AA3="TC",AA3="MT"),'CARGA DOCENTE'!$C33," ") | AE3: =IF(OR(AA3="TC",AA3="MT"),'CARGA DOCENTE'!$G33," ") | AF3: ='CARGA DOCENTE'!$H34 -> 0 | AG3: =IF(OR(AF3="TC",AF3="MT"),'CARGA DOCENTE'!$A34," ") | AH3: =IF(OR(AF3="TC",AF3="MT"),'CARGA DOCENTE'!$B34," ") | AI3: =IF(OR(AF3="TC",AF3="MT"),'CARGA DOCENTE'!$C34," ") | AJ3: =IF(OR(AF3="TC",AF3="MT"),'CARGA DOCENTE'!$G34," ") | AK3: ='CARGA DOCENTE'!$H35 -> 0 | AL3: =IF(OR(AK3="TC",AK3="MT"),'CARGA DOCENTE'!$A35," ") | AM3: =IF(OR(AK3="TC",AK3="MT"),'CARGA DOCENTE'!$B35," ") | AN3: =IF(OR(AK3="TC",AK3="MT"),'CARGA DOCENTE'!$C35," ") | AO3: =IF(OR(AK3="TC",AK3="MT"),'CARGA DOCENTE'!$G35," ") | AP3: ='CARGA DOCENTE'!$H36 -> 0 | AQ3: =IF(OR(AP3="TC",AP3="MT"),'CARGA DOCENTE'!$A36," ") | AR3: =IF(OR(AP3="TC",AP3="MT"),'CARGA DOCENTE'!$B36," ") | AS3: =IF(OR(AP3="TC",AP3="MT"),'CARGA DOCENTE'!$C36," ") | AT3: =IF(OR(AP3="TC",AP3="MT"),'CARGA DOCENTE'!$G36," ") | AU3: ='CARGA DOCENTE'!$H37 -> 0 | AV3: =IF(OR(AU3="TC",AU3="MT"),'CARGA DOCENTE'!$A37," ") | AW3: =IF(OR(AU3="TC",AU3="MT"),'CARGA DOCENTE'!$B37," ") | AX3: =IF(OR(AU3="TC",AU3="MT"),'CARGA DOCENTE'!$C37," ") | AY3: =IF(OR(AU3="TC",AU3="MT"),'CARGA DOCENTE'!$G37," ") | AZ3: ='CARGA DOCENTE'!$H38 -> 0 | BA3: =IF(OR(AZ3="TC",AZ3="MT"),'CARGA DOCENTE'!$A38," ") | BB3: =IF(OR(AZ3="TC",AZ3="MT"),'CARGA DOCENTE'!$B38," ") | BC3: =IF(OR(AZ3="TC",AZ3="MT"),'CARGA DOCENTE'!$C38," ") | BD3: =IF(OR(AZ3="TC",AZ3="MT"),'CARGA DOCENTE'!$G38," ") | BE3: ='CARGA DOCENTE'!$H39 -> 0 | BF3: =IF(OR(BE3="TC",BE3="MT"),'CARGA DOCENTE'!$A39," ") | BG3: =IF(OR(BE3="TC",BE3="MT"),'CARGA DOCENTE'!$B39," ") | BH3: =IF(OR(BE3="TC",BE3="MT"),'CARGA DOCENTE'!$C39," ") | BI3: =IF(OR(BE3="TC",BE3="MT"),'CARGA DOCENTE'!$G39," ") | BJ3: ='CARGA DOCENTE'!$H40 -> 0 | BK3: =IF(OR(BJ3="TC",BJ3="MT"),'CARGA DOCENTE'!$A40," ") | BL3: =IF(OR(BJ3="TC",BJ3="MT"),'CARGA DOCENTE'!$B40," ") | BM3: =IF(OR(BJ3="TC",BJ3="MT"),'CARGA DOCENTE'!$C40," ") | BN3: =IF(OR(BJ3="TC",BJ3="MT"),'CARGA DOCENTE'!$G40," ") | BO3: ='CARGA DOCENTE'!$H41 -> 0 | BP3: =IF(OR(BO3="TC",BO3="MT"),'CARGA DOCENTE'!$A41," ") | BQ3: =IF(OR(BO3="TC",BO3="MT"),'CARGA DOCENTE'!$B41," ") | BR3: =IF(OR(BO3="TC",BO3="MT"),'CARGA DOCENTE'!$C41," ") | BS3: =IF(OR(BO3="TC",BO3="MT"),'CARGA DOCENTE'!$G41," ") | BT3: ='CARGA DOCENTE'!$H42 -> 0 | BU3: =IF(OR(BT3="TC",BT3="MT"),'CARGA DOCENTE'!$A42," ") | BV3: =IF(OR(BT3="TC",BT3="MT"),'CARGA DOCENTE'!$B42," ") | BW3: =IF(OR(BT3="TC",BT3="MT"),'CARGA DOCENTE'!$C42," ") | BX3: =IF(OR(BT3="TC",BT3="MT"),'CARGA DOCENTE'!$G42," ")
A4: ='CARGA DOCENTE'!J46 -> 0 | B4: ='CARGA DOCENTE'!$H46 -> 0 | C4: =IF(OR(B4="TC",B4="MT"),'CARGA DOCENTE'!$A46," ") | D4: =IF(OR(B4="TC",B4="MT"),'CARGA DOCENTE'!$B46," ") | E4: =IF(OR(B4="TC",B4="MT"),'CARGA DOCENTE'!$C46," ") | F4: =IF(OR(B4="TC",B4="MT"),'CARGA DOCENTE'!$G46," ") | G4: ='CARGA DOCENTE'!$H47 -> 0 | H4: =IF(OR(G4="TC",G4="MT"),'CARGA DOCENTE'!$A47," ") | I4: =IF(OR(G4="TC",G4="MT"),'CARGA DOCENTE'!$B47," ") | J4: =IF(OR(G4="TC",G4="MT"),'CARGA DOCENTE'!$C47," ") | K4: =IF(OR(G4="TC",G4="MT"),'CARGA DOCENTE'!$G47," ") | L4: ='CARGA DOCENTE'!$H48 -> 0 | M4: =IF(OR(L4="TC",L4="MT"),'CARGA DOCENTE'!$A48," ") | N4: =IF(OR(L4="TC",L4="MT"),'CARGA DOCENTE'!$B48," ") | O4: =IF(OR(L4="TC",L4="MT"),'CARGA DOCENTE'!$C48," ") | P4: =IF(OR(L4="TC",L4="MT"),'CARGA DOCENTE'!$G48," ") | Q4: ='CARGA DOCENTE'!$H49 -> 0 | R4: =IF(OR(Q4="TC",Q4="MT"),'CARGA DOCENTE'!$A49," ") | S4: =IF(OR(Q4="TC",Q4="MT"),'CARGA DOCENTE'!$B49," ") | T4: =IF(OR(Q4="TC",Q4="MT"),'CARGA DOCENTE'!$C49," ") | U4: =IF(OR(Q4="TC",Q4="MT"),'CARGA DOCENTE'!$G49," ") | V4: ='CARGA DOCENTE'!$H50 -> 0 | W4: =IF(OR(V4="TC",V4="MT"),'CARGA DOCENTE'!$A50," ") | X4: =IF(OR(V4="TC",V4="MT"),'CARGA DOCENTE'!$B50," ") | Y4: =IF(OR(V4="TC",V4="MT"),'CARGA DOCENTE'!$C50," ") | Z4: =IF(OR(V4="TC",V4="MT"),'CARGA DOCENTE'!$G50," ") | AA4: ='CARGA DOCENTE'!$H51 -> 0 | AB4: =IF(OR(AA4="TC",AA4="MT"),'CARGA DOCENTE'!$A51," ") | AC4: =IF(OR(AA4="TC",AA4="MT"),'CARGA DOCENTE'!$B51," ") | AD4: =IF(OR(AA4="TC",AA4="MT"),'CARGA DOCENTE'!$C51," ") | AE4: =IF(OR(AA4="TC",AA4="MT"),'CARGA DOCENTE'!$G51," ") | AF4: ='CARGA DOCENTE'!$H52 -> 0 | AG4: =IF(OR(AF4="TC",AF4="MT"),'CARGA DOCENTE'!$A52," ") | AH4: =IF(OR(AF4="TC",AF4="MT"),'CARGA DOCENTE'!$B52," ") | AI4: =IF(OR(AF4="TC",AF4="MT"),'CARGA DOCENTE'!$C52," ") | AJ4: =IF(OR(AF4="TC",AF4="MT"),'CARGA DOCENTE'!$G52," ") | AK4: ='CARGA DOCENTE'!$H53 -> 0 | AL4: =IF(OR(AK4="TC",AK4="MT"),'CARGA DOCENTE'!$A53," ") | AM4: =IF(OR(AK4="TC",AK4="MT"),'CARGA DOCENTE'!$B53," ") | AN4: =IF(OR(AK4="TC",AK4="MT"),'CARGA DOCENTE'!$C53," ") | AO4: =IF(OR(AK4="TC",AK4="MT"),'CARGA DOCENTE'!$G53," ") | AP4: ='CARGA DOCENTE'!$H54 -> 0 | AQ4: =IF(OR(AP4="TC",AP4="MT"),'CARGA DOCENTE'!$A54," ") | AR4: =IF(OR(AP4="TC",AP4="MT"),'CARGA DOCENTE'!$B54," ") | AS4: =IF(OR(AP4="TC",AP4="MT"),'CARGA DOCENTE'!$C54," ") | AT4: =IF(OR(AP4="TC",AP4="MT"),'CARGA DOCENTE'!$G54," ") | AU4: ='CARGA DOCENTE'!$H55 -> 0 | AV4: =IF(OR(AU4="TC",AU4="MT"),'CARGA DOCENTE'!$A55," ") | AW4: =IF(OR(AU4="TC",AU4="MT"),'CARGA DOCENTE'!$B55," ") | AX4: =IF(OR(AU4="TC",AU4="MT"),'CARGA DOCENTE'!$C55," ") | AY4: =IF(OR(AU4="TC",AU4="MT"),'CARGA DOCENTE'!$G55," ") | AZ4: ='CARGA DOCENTE'!$H56 -> 0 | BA4: =IF(OR(AZ4="TC",AZ4="MT"),'CARGA DOCENTE'!$A56," ") | BB4: =IF(OR(AZ4="TC",AZ4="MT"),'CARGA DOCENTE'!$B56," ") | BC4: =IF(OR(AZ4="TC",AZ4="MT"),'CARGA DOCENTE'!$C56," ") | BD4: =IF(OR(AZ4="TC",AZ4="MT"),'CARGA DOCENTE'!$G56," ") | BE4: ='CARGA DOCENTE'!$H57 -> 0 | BF4: =IF(OR(BE4="TC",BE4="MT"),'CARGA DOCENTE'!$A57," ") | BG4: =IF(OR(BE4="TC",BE4="MT"),'CARGA DOCENTE'!$B57," ") | BH4: =IF(OR(BE4="TC",BE4="MT"),'CARGA DOCENTE'!$C57," ") | BI4: =IF(OR(BE4="TC",BE4="MT"),'CARGA DOCENTE'!$G57," ") | BJ4: ='CARGA DOCENTE'!$H58 -> 0 | BK4: =IF(OR(BJ4="TC",BJ4="MT"),'CARGA DOCENTE'!$A58," ") | BL4: =IF(OR(BJ4="TC",BJ4="MT"),'CARGA DOCENTE'!$B58," ") | BM4: =IF(OR(BJ4="TC",BJ4="MT"),'CARGA DOCENTE'!$C58," ") | BN4: =IF(OR(BJ4="TC",BJ4="MT"),'CARGA DOCENTE'!$G58," ") | BO4: ='CARGA DOCENTE'!$H59 -> 0 | BP4: =IF(OR(BO4="TC",BO4="MT"),'CARGA DOCENTE'!$A59," ") | BQ4: =IF(OR(BO4="TC",BO4="MT"),'CARGA DOCENTE'!$B59," ") | BR4: =IF(OR(BO4="TC",BO4="MT"),'CARGA DOCENTE'!$C59," ") | BS4: =IF(OR(BO4="TC",BO4="MT"),'CARGA DOCENTE'!$G59," ") | BT4: ='CARGA DOCENTE'!$H60 -> 0 | BU4: =IF(OR(BT4="TC",BT4="MT"),'CARGA DOCENTE'!$A60," ") | BV4: =IF(OR(BT4="TC",BT4="MT"),'CARGA DOCENTE'!$B60," ") | BW4: =IF(OR(BT4="TC",BT4="MT"),'CARGA DOCENTE'!$C60," ") | BX4: =IF(OR(BT4="TC",BT4="MT"),'CARGA DOCENTE'!$G60," ")
A5: ='CARGA DOCENTE'!J64 -> 0 | B5: ='CARGA DOCENTE'!$H64 -> 0 | C5: =IF(OR(B5="TC",B5="MT"),'CARGA DOCENTE'!$A64," ") | D5: =IF(OR(B5="TC",B5="MT"),'CARGA DOCENTE'!$B64," ") | E5: =IF(OR(B5="TC",B5="MT"),'CARGA DOCENTE'!$C64," ") | F5: =IF(OR(B5="TC",B5="MT"),'CARGA DOCENTE'!$G64," ") | G5: ='CARGA DOCENTE'!$H65 -> 0 | H5: =IF(OR(G5="TC",G5="MT"),'CARGA DOCENTE'!$A65," ") | I5: =IF(OR(G5="TC",G5="MT"),'CARGA DOCENTE'!$B65," ") | J5: =IF(OR(G5="TC",G5="MT"),'CARGA DOCENTE'!$C65," ") | K5: =IF(OR(G5="TC",G5="MT"),'CARGA DOCENTE'!$G65," ") | L5: ='CARGA DOCENTE'!$H66 -> 0 | M5: =IF(OR(L5="TC",L5="MT"),'CARGA DOCENTE'!$A66," ") | N5: =IF(OR(L5="TC",L5="MT"),'CARGA DOCENTE'!$B66," ") | O5: =IF(OR(L5="TC",L5="MT"),'CARGA DOCENTE'!$C66," ") | P5: =IF(OR(L5="TC",L5="MT"),'CARGA DOCENTE'!$G66," ") | Q5: ='CARGA DOCENTE'!$H67 -> 0 | R5: =IF(OR(Q5="TC",Q5="MT"),'CARGA DOCENTE'!$A67," ") | S5: =IF(OR(Q5="TC",Q5="MT"),'CARGA DOCENTE'!$B67," ") | T5: =IF(OR(Q5="TC",Q5="MT"),'CARGA DOCENTE'!$C67," ") | U5: =IF(OR(Q5="TC",Q5="MT"),'CARGA DOCENTE'!$G67," ") | V5: ='CARGA DOCENTE'!$H68 -> 0 | W5: =IF(OR(V5="TC",V5="MT"),'CARGA DOCENTE'!$A68," ") | X5: =IF(OR(V5="TC",V5="MT"),'CARGA DOCENTE'!$B68," ") | Y5: =IF(OR(V5="TC",V5="MT"),'CARGA DOCENTE'!$C68," ") | Z5: =IF(OR(V5="TC",V5="MT"),'CARGA DOCENTE'!$G68," ") | AA5: ='CARGA DOCENTE'!$H69 -> 0 | AB5: =IF(OR(AA5="TC",AA5="MT"),'CARGA DOCENTE'!$A69," ") | AC5: =IF(OR(AA5="TC",AA5="MT"),'CARGA DOCENTE'!$B69," ") | AD5: =IF(OR(AA5="TC",AA5="MT"),'CARGA DOCENTE'!$C69," ") | AE5: =IF(OR(AA5="TC",AA5="MT"),'CARGA DOCENTE'!$G69," ") | AF5: ='CARGA DOCENTE'!$H70 -> 0 | AG5: =IF(OR(AF5="TC",AF5="MT"),'CARGA DOCENTE'!$A70," ") | AH5: =IF(OR(AF5="TC",AF5="MT"),'CARGA DOCENTE'!$B70," ") | AI5: =IF(OR(AF5="TC",AF5="MT"),'CARGA DOCENTE'!$C70," ") | AJ5: =IF(OR(AF5="TC",AF5="MT"),'CARGA DOCENTE'!$G70," ") | AK5: ='CARGA DOCENTE'!$H71 -> 0 | AL5: =IF(OR(AK5="TC",AK5="MT"),'CARGA DOCENTE'!$A71," ") | AM5: =IF(OR(AK5="TC",AK5="MT"),'CARGA DOCENTE'!$B71," ") | AN5: =IF(OR(AK5="TC",AK5="MT"),'CARGA DOCENTE'!$C71," ") | AO5: =IF(OR(AK5="TC",AK5="MT"),'CARGA DOCENTE'!$G71," ") | AP5: ='CARGA DOCENTE'!$H72 -> 0 | AQ5: =IF(OR(AP5="TC",AP5="MT"),'CARGA DOCENTE'!$A72," ") | AR5: =IF(OR(AP5="TC",AP5="MT"),'CARGA DOCENTE'!$B72," ") | AS5: =IF(OR(AP5="TC",AP5="MT"),'CARGA DOCENTE'!$C72," ") | AT5: =IF(OR(AP5="TC",AP5="MT"),'CARGA DOCENTE'!$G72," ") | AU5: ='CARGA DOCENTE'!$H73 -> 0 | AV5: =IF(OR(AU5="TC",AU5="MT"),'CARGA DOCENTE'!$A73," ") | AW5: =IF(OR(AU5="TC",AU5="MT"),'CARGA DOCENTE'!$B73," ") | AX5: =IF(OR(AU5="TC",AU5="MT"),'CARGA DOCENTE'!$C73," ") | AY5: =IF(OR(AU5="TC",AU5="MT"),'CARGA DOCENTE'!$G73," ") | AZ5: ='CARGA DOCENTE'!$H74 -> 0 | BA5: =IF(OR(AZ5="TC",AZ5="MT"),'CARGA DOCENTE'!$A74," ") | BB5: =IF(OR(AZ5="TC",AZ5="MT"),'CARGA DOCENTE'!$B74," ") | BC5: =IF(OR(AZ5="TC",AZ5="MT"),'CARGA DOCENTE'!$C74," ") | BD5: =IF(OR(AZ5="TC",AZ5="MT"),'CARGA DOCENTE'!$G74," ") | BE5: ='CARGA DOCENTE'!$H75 -> 0 | BF5: =IF(OR(BE5="TC",BE5="MT"),'CARGA DOCENTE'!$A75," ") | BG5: =IF(OR(BE5="TC",BE5="MT"),'CARGA DOCENTE'!$B75," ") | BH5: =IF(OR(BE5="TC",BE5="MT"),'CARGA DOCENTE'!$C75," ") | BI5: =IF(OR(BE5="TC",BE5="MT"),'CARGA DOCENTE'!$G75," ") | BJ5: ='CARGA DOCENTE'!$H76 -> 0 | BK5: =IF(OR(BJ5="TC",BJ5="MT"),'CARGA DOCENTE'!$A76," ") | BL5: =IF(OR(BJ5="TC",BJ5="MT"),'CARGA DOCENTE'!$B76," ") | BM5: =IF(OR(BJ5="TC",BJ5="MT"),'CARGA DOCENTE'!$C76," ") | BN5: =IF(OR(BJ5="TC",BJ5="MT"),'CARGA DOCENTE'!$G76," ") | BO5: ='CARGA DOCENTE'!$H77 -> 0 | BP5: =IF(OR(BO5="TC",BO5="MT"),'CARGA DOCENTE'!$A77," ") | BQ5: =IF(OR(BO5="TC",BO5="MT"),'CARGA DOCENTE'!$B77," ") | BR5: =IF(OR(BO5="TC",BO5="MT"),'CARGA DOCENTE'!$C77," ") | BS5: =IF(OR(BO5="TC",BO5="MT"),'CARGA DOCENTE'!$G77," ") | BT5: ='CARGA DOCENTE'!$H78 -> 0 | BU5: =IF(OR(BT5="TC",BT5="MT"),'CARGA DOCENTE'!$A78," ") | BV5: =IF(OR(BT5="TC",BT5="MT"),'CARGA DOCENTE'!$B78," ") | BW5: =IF(OR(BT5="TC",BT5="MT"),'CARGA DOCENTE'!$C78," ") | BX5: =IF(OR(BT5="TC",BT5="MT"),'CARGA DOCENTE'!$G78," ")
A6: ='CARGA DOCENTE'!J82 -> 0 | B6: ='CARGA DOCENTE'!$H82 -> 0 | C6: =IF(OR(B6="TC",B6="MT"),'CARGA DOCENTE'!$A82," ") | D6: =IF(OR(B6="TC",B6="MT"),'CARGA DOCENTE'!$B82," ") | E6: =IF(OR(B6="TC",B6="MT"),'CARGA DOCENTE'!$C82," ") | F6: =IF(OR(B6="TC",B6="MT"),'CARGA DOCENTE'!$G82," ") | G6: ='CARGA DOCENTE'!$H83 -> 0 | H6: =IF(OR(G6="TC",G6="MT"),'CARGA DOCENTE'!$A83," ") | I6: =IF(OR(G6="TC",G6="MT"),'CARGA DOCENTE'!$B83," ") | J6: =IF(OR(G6="TC",G6="MT"),'CARGA DOCENTE'!$C83," ") | K6: =IF(OR(G6="TC",G6="MT"),'CARGA DOCENTE'!$G83," ") | L6: ='CARGA DOCENTE'!$H84 -> 0 | M6: =IF(OR(L6="TC",L6="MT"),'CARGA DOCENTE'!$A84," ") | N6: =IF(OR(L6="TC",L6="MT"),'CARGA DOCENTE'!$B84," ") | O6: =IF(OR(L6="TC",L6="MT"),'CARGA DOCENTE'!$C84," ") | P6: =IF(OR(L6="TC",L6="MT"),'CARGA DOCENTE'!$G84," ") | Q6: ='CARGA DOCENTE'!$H85 -> 0 | R6: =IF(OR(Q6="TC",Q6="MT"),'CARGA DOCENTE'!$A85," ") | S6: =IF(OR(Q6="TC",Q6="MT"),'CARGA DOCENTE'!$B85," ") | T6: =IF(OR(Q6="TC",Q6="MT"),'CARGA DOCENTE'!$C85," ") | U6: =IF(OR(Q6="TC",Q6="MT"),'CARGA DOCENTE'!$G85," ") | V6: ='CARGA DOCENTE'!$H86 -> 0 | W6: =IF(OR(V6="TC",V6="MT"),'CARGA DOCENTE'!$A86," ") | X6: =IF(OR(V6="TC",V6="MT"),'CARGA DOCENTE'!$B86," ") | Y6: =IF(OR(V6="TC",V6="MT"),'CARGA DOCENTE'!$C86," ") | Z6: =IF(OR(V6="TC",V6="MT"),'CARGA DOCENTE'!$G86," ") | AA6: ='CARGA DOCENTE'!$H87 -> 0 | AB6: =IF(OR(AA6="TC",AA6="MT"),'CARGA DOCENTE'!$A87," ") | AC6: =IF(OR(AA6="TC",AA6="MT"),'CARGA DOCENTE'!$B87," ") | AD6: =IF(OR(AA6="TC",AA6="MT"),'CARGA DOCENTE'!$C87," ") | AE6: =IF(OR(AA6="TC",AA6="MT"),'CARGA DOCENTE'!$G87," ") | AF6: ='CARGA DOCENTE'!$H88 -> 0 | AG6: =IF(OR(AF6="TC",AF6="MT"),'CARGA DOCENTE'!$A88," ") | AH6: =IF(OR(AF6="TC",AF6="MT"),'CARGA DOCENTE'!$B88," ") | AI6: =IF(OR(AF6="TC",AF6="MT"),'CARGA DOCENTE'!$C88," ") | AJ6: =IF(OR(AF6="TC",AF6="MT"),'CARGA DOCENTE'!$G88," ") | AK6: ='CARGA DOCENTE'!$H89 -> 0 | AL6: =IF(OR(AK6="TC",AK6="MT"),'CARGA DOCENTE'!$A89," ") | AM6: =IF(OR(AK6="TC",AK6="MT"),'CARGA DOCENTE'!$B89," ") | AN6: =IF(OR(AK6="TC",AK6="MT"),'CARGA DOCENTE'!$C89," ") | AO6: =IF(OR(AK6="TC",AK6="MT"),'CARGA DOCENTE'!$G89," ") | AP6: ='CARGA DOCENTE'!$H90 -> 0 | AQ6: =IF(OR(AP6="TC",AP6="MT"),'CARGA DOCENTE'!$A90," ") | AR6: =IF(OR(AP6="TC",AP6="MT"),'CARGA DOCENTE'!$B90," ") | AS6: =IF(OR(AP6="TC",AP6="MT"),'CARGA DOCENTE'!$C90," ") | AT6: =IF(OR(AP6="TC",AP6="MT"),'CARGA DOCENTE'!$G90," ") | AU6: ='CARGA DOCENTE'!$H91 -> 0 | AV6: =IF(OR(AU6="TC",AU6="MT"),'CARGA DOCENTE'!$A91," ") | AW6: =IF(OR(AU6="TC",AU6="MT"),'CARGA DOCENTE'!$B91," ") | AX6: =IF(OR(AU6="TC",AU6="MT"),'CARGA DOCENTE'!$C91," ") | AY6: =IF(OR(AU6="TC",AU6="MT"),'CARGA DOCENTE'!$G91," ") | AZ6: ='CARGA DOCENTE'!$H92 -> 0 | BA6: =IF(OR(AZ6="TC",AZ6="MT"),'CARGA DOCENTE'!$A92," ") | BB6: =IF(OR(AZ6="TC",AZ6="MT"),'CARGA DOCENTE'!$B92," ") | BC6: =IF(OR(AZ6="TC",AZ6="MT"),'CARGA DOCENTE'!$C92," ") | BD6: =IF(OR(AZ6="TC",AZ6="MT"),'CARGA DOCENTE'!$G92," ") | BE6: ='CARGA DOCENTE'!$H93 -> 0 | BF6: =IF(OR(BE6="TC",BE6="MT"),'CARGA DOCENTE'!$A93," ") | BG6: =IF(OR(BE6="TC",BE6="MT"),'CARGA DOCENTE'!$B93," ") | BH6: =IF(OR(BE6="TC",BE6="MT"),'CARGA DOCENTE'!$C93," ") | BI6: =IF(OR(BE6="TC",BE6="MT"),'CARGA DOCENTE'!$G93," ") | BJ6: ='CARGA DOCENTE'!$H94 -> 0 | BK6: =IF(OR(BJ6="TC",BJ6="MT"),'CARGA DOCENTE'!$A94," ") | BL6: =IF(OR(BJ6="TC",BJ6="MT"),'CARGA DOCENTE'!$B94," ") | BM6: =IF(OR(BJ6="TC",BJ6="MT"),'CARGA DOCENTE'!$C94," ") | BN6: =IF(OR(BJ6="TC",BJ6="MT"),'CARGA DOCENTE'!$G94," ") | BO6: ='CARGA DOCENTE'!$H95 -> 0 | BP6: =IF(OR(BO6="TC",BO6="MT"),'CARGA DOCENTE'!$A95," ") | BQ6: =IF(OR(BO6="TC",BO6="MT"),'CARGA DOCENTE'!$B95," ") | BR6: =IF(OR(BO6="TC",BO6="MT"),'CARGA DOCENTE'!$C95," ") | BS6: =IF(OR(BO6="TC",BO6="MT"),'CARGA DOCENTE'!$G95," ") | BT6: ='CARGA DOCENTE'!$H96 -> 0 | BU6: =IF(OR(BT6="TC",BT6="MT"),'CARGA DOCENTE'!$A96," ") | BV6: =IF(OR(BT6="TC",BT6="MT"),'CARGA DOCENTE'!$B96," ") | BW6: =IF(OR(BT6="TC",BT6="MT"),'CARGA DOCENTE'!$C96," ") | BX6: =IF(OR(BT6="TC",BT6="MT"),'CARGA DOCENTE'!$G96," ")
A7: ='CARGA DOCENTE'!J100 -> 0 | B7: ='CARGA DOCENTE'!$H100 -> 0 | C7: =IF(OR(B7="TC",B7="MT"),'CARGA DOCENTE'!$A100," ") | D7: =IF(OR(B7="TC",B7="MT"),'CARGA DOCENTE'!$B100," ") | E7: =IF(OR(B7="TC",B7="MT"),'CARGA DOCENTE'!$C100," ") | F7: =IF(OR(B7="TC",B7="MT"),'CARGA DOCENTE'!$G100," ") | G7: ='CARGA DOCENTE'!$H101 -> 0 | H7: =IF(OR(G7="TC",G7="MT"),'CARGA DOCENTE'!$A101," ") | I7: =IF(OR(G7="TC",G7="MT"),'CARGA DOCENTE'!$B101," ") | J7: =IF(OR(G7="TC",G7="MT"),'CARGA DOCENTE'!$C101," ") | K7: =IF(OR(G7="TC",G7="MT"),'CARGA DOCENTE'!$G101," ") | L7: ='CARGA DOCENTE'!$H102 -> 0 | M7: =IF(OR(L7="TC",L7="MT"),'CARGA DOCENTE'!$A102," ") | N7: =IF(OR(L7="TC",L7="MT"),'CARGA DOCENTE'!$B102," ") | O7: =IF(OR(L7="TC",L7="MT"),'CARGA DOCENTE'!$C102," ") | P7: =IF(OR(L7="TC",L7="MT"),'CARGA DOCENTE'!$G102," ") | Q7: ='CARGA DOCENTE'!$H103 -> 0 | R7: =IF(OR(Q7="TC",Q7="MT"),'CARGA DOCENTE'!$A103," ") | S7: =IF(OR(Q7="TC",Q7="MT"),'CARGA DOCENTE'!$B103," ") | T7: =IF(OR(Q7="TC",Q7="MT"),'CARGA DOCENTE'!$C103," ") | U7: =IF(OR(Q7="TC",Q7="MT"),'CARGA DOCENTE'!$G103," ") | V7: ='CARGA DOCENTE'!$H104 -> 0 | W7: =IF(OR(V7="TC",V7="MT"),'CARGA DOCENTE'!$A104," ") | X7: =IF(OR(V7="TC",V7="MT"),'CARGA DOCENTE'!$B104," ") | Y7: =IF(OR(V7="TC",V7="MT"),'CARGA DOCENTE'!$C104," ") | Z7: =IF(OR(V7="TC",V7="MT"),'CARGA DOCENTE'!$G104," ") | AA7: ='CARGA DOCENTE'!$H105 -> 0 | AB7: =IF(OR(AA7="TC",AA7="MT"),'CARGA DOCENTE'!$A105," ") | AC7: =IF(OR(AA7="TC",AA7="MT"),'CARGA DOCENTE'!$B105," ") | AD7: =IF(OR(AA7="TC",AA7="MT"),'CARGA DOCENTE'!$C105," ") | AE7: =IF(OR(AA7="TC",AA7="MT"),'CARGA DOCENTE'!$G105," ") | AF7: ='CARGA DOCENTE'!$H106 -> 0 | AG7: =IF(OR(AF7="TC",AF7="MT"),'CARGA DOCENTE'!$A106," ") | AH7: =IF(OR(AF7="TC",AF7="MT"),'CARGA DOCENTE'!$B106," ") | AI7: =IF(OR(AF7="TC",AF7="MT"),'CARGA DOCENTE'!$C106," ") | AJ7: =IF(OR(AF7="TC",AF7="MT"),'CARGA DOCENTE'!$G106," ") | AK7: ='CARGA DOCENTE'!$H107 -> 0 | AL7: =IF(OR(AK7="TC",AK7="MT"),'CARGA DOCENTE'!$A107," ") | AM7: =IF(OR(AK7="TC",AK7="MT"),'CARGA DOCENTE'!$B107," ") | AN7: =IF(OR(AK7="TC",AK7="MT"),'CARGA DOCENTE'!$C107," ") | AO7: =IF(OR(AK7="TC",AK7="MT"),'CARGA DOCENTE'!$G107," ") | AP7: ='CARGA DOCENTE'!$H108 -> 0 | AQ7: =IF(OR(AP7="TC",AP7="MT"),'CARGA DOCENTE'!$A108," ") | AR7: =IF(OR(AP7="TC",AP7="MT"),'CARGA DOCENTE'!$B108," ") | AS7: =IF(OR(AP7="TC",AP7="MT"),'CARGA DOCENTE'!$C108," ") | AT7: =IF(OR(AP7="TC",AP7="MT"),'CARGA DOCENTE'!$G108," ") | AU7: ='CARGA DOCENTE'!$H109 -> 0 | AV7: =IF(OR(AU7="TC",AU7="MT"),'CARGA DOCENTE'!$A109," ") | AW7: =IF(OR(AU7="TC",AU7="MT"),'CARGA DOCENTE'!$B109," ") | AX7: =IF(OR(AU7="TC",AU7="MT"),'CARGA DOCENTE'!$C109," ") | AY7: =IF(OR(AU7="TC",AU7="MT"),'CARGA DOCENTE'!$G109," ") | AZ7: ='CARGA DOCENTE'!$H110 -> 0 | BA7: =IF(OR(AZ7="TC",AZ7="MT"),'CARGA DOCENTE'!$A110," ") | BB7: =IF(OR(AZ7="TC",AZ7="MT"),'CARGA DOCENTE'!$B110," ") | BC7: =IF(OR(AZ7="TC",AZ7="MT"),'CARGA DOCENTE'!$C110," ") | BD7: =IF(OR(AZ7="TC",AZ7="MT"),'CARGA DOCENTE'!$G110," ") | BE7: ='CARGA DOCENTE'!$H111 -> 0 | BF7: =IF(OR(BE7="TC",BE7="MT"),'CARGA DOCENTE'!$A111," ") | BG7: =IF(OR(BE7="TC",BE7="MT"),'CARGA DOCENTE'!$B111," ") | BH7: =IF(OR(BE7="TC",BE7="MT"),'CARGA DOCENTE'!$C111," ") | BI7: =IF(OR(BE7="TC",BE7="MT"),'CARGA DOCENTE'!$G111," ") | BJ7: ='CARGA DOCENTE'!$H112 -> 0 | BK7: =IF(OR(BJ7="TC",BJ7="MT"),'CARGA DOCENTE'!$A112," ") | BL7: =IF(OR(BJ7="TC",BJ7="MT"),'CARGA DOCENTE'!$B112," ") | BM7: =IF(OR(BJ7="TC",BJ7="MT"),'CARGA DOCENTE'!$C112," ") | BN7: =IF(OR(BJ7="TC",BJ7="MT"),'CARGA DOCENTE'!$G112," ") | BO7: ='CARGA DOCENTE'!$H113 -> 0 | BP7: =IF(OR(BO7="TC",BO7="MT"),'CARGA DOCENTE'!$A113," ") | BQ7: =IF(OR(BO7="TC",BO7="MT"),'CARGA DOCENTE'!$B113," ") | BR7: =IF(OR(BO7="TC",BO7="MT"),'CARGA DOCENTE'!$C113," ") | BS7: =IF(OR(BO7="TC",BO7="MT"),'CARGA DOCENTE'!$G113," ") | BT7: ='CARGA DOCENTE'!$H114 -> 0 | BU7: =IF(OR(BT7="TC",BT7="MT"),'CARGA DOCENTE'!$A114," ") | BV7: =IF(OR(BT7="TC",BT7="MT"),'CARGA DOCENTE'!$B114," ") | BW7: =IF(OR(BT7="TC",BT7="MT"),'CARGA DOCENTE'!$C114," ") | BX7: =IF(OR(BT7="TC",BT7="MT"),'CARGA DOCENTE'!$G114," ")
A8: ='CARGA DOCENTE'!J118 -> 0 | B8: ='CARGA DOCENTE'!$H118 -> 0 | C8: =IF(OR(B8="TC",B8="MT"),'CARGA DOCENTE'!$A118," ") | D8: =IF(OR(B8="TC",B8="MT"),'CARGA DOCENTE'!$B118," ") | E8: =IF(OR(B8="TC",B8="MT"),'CARGA DOCENTE'!$C118," ") | F8: =IF(OR(B8="TC",B8="MT"),'CARGA DOCENTE'!$G118," ") | G8: ='CARGA DOCENTE'!$H119 -> 0 | H8: =IF(OR(G8="TC",G8="MT"),'CARGA DOCENTE'!$A119," ") | I8: =IF(OR(G8="TC",G8="MT"),'CARGA DOCENTE'!$B119," ") | J8: =IF(OR(G8="TC",G8="MT"),'CARGA DOCENTE'!$C119," ") | K8: =IF(OR(G8="TC",G8="MT"),'CARGA DOCENTE'!$G119," ") | L8: ='CARGA DOCENTE'!$H120 -> 0 | M8: =IF(OR(L8="TC",L8="MT"),'CARGA DOCENTE'!$A120," ") | N8: =IF(OR(L8="TC",L8="MT"),'CARGA DOCENTE'!$B120," ") | O8: =IF(OR(L8="TC",L8="MT"),'CARGA DOCENTE'!$C120," ") | P8: =IF(OR(L8="TC",L8="MT"),'CARGA DOCENTE'!$G120," ") | Q8: ='CARGA DOCENTE'!$H121 -> 0 | R8: =IF(OR(Q8="TC",Q8="MT"),'CARGA DOCENTE'!$A121," ") | S8: =IF(OR(Q8="TC",Q8="MT"),'CARGA DOCENTE'!$B121," ") | T8: =IF(OR(Q8="TC",Q8="MT"),'CARGA DOCENTE'!$C121," ") | U8: =IF(OR(Q8="TC",Q8="MT"),'CARGA DOCENTE'!$G121," ") | V8: ='CARGA DOCENTE'!$H122 -> 0 | W8: =IF(OR(V8="TC",V8="MT"),'CARGA DOCENTE'!$A122," ") | X8: =IF(OR(V8="TC",V8="MT"),'CARGA DOCENTE'!$B122," ") | Y8: =IF(OR(V8="TC",V8="MT"),'CARGA DOCENTE'!$C122," ") | Z8: =IF(OR(V8="TC",V8="MT"),'CARGA DOCENTE'!$G122," ") | AA8: ='CARGA DOCENTE'!$H123 -> 0 | AB8: =IF(OR(AA8="TC",AA8="MT"),'CARGA DOCENTE'!$A123," ") | AC8: =IF(OR(AA8="TC",AA8="MT"),'CARGA DOCENTE'!$B123," ") | AD8: =IF(OR(AA8="TC",AA8="MT"),'CARGA DOCENTE'!$C123," ") | AE8: =IF(OR(AA8="TC",AA8="MT"),'CARGA DOCENTE'!$G123," ") | AF8: ='CARGA DOCENTE'!$H124 -> 0 | AG8: =IF(OR(AF8="TC",AF8="MT"),'CARGA DOCENTE'!$A114," ") | AH8: =IF(OR(AF8="TC",AF8="MT"),'CARGA DOCENTE'!$B114," ") | AI8: =IF(OR(AF8="TC",AF8="MT"),'CARGA DOCENTE'!$C114," ") | AJ8: =IF(OR(AF8="TC",AF8="MT"),'CARGA DOCENTE'!$G114," ") | AK8: ='CARGA DOCENTE'!$H125 -> 0 | AL8: =IF(OR(AK8="TC",AK8="MT"),'CARGA DOCENTE'!$A125," ") | AM8: =IF(OR(AK8="TC",AK8="MT"),'CARGA DOCENTE'!$B125," ") | AN8: =IF(OR(AK8="TC",AK8="MT"),'CARGA DOCENTE'!$C125," ") | AO8: =IF(OR(AK8="TC",AK8="MT"),'CARGA DOCENTE'!$G125," ") | AP8: ='CARGA DOCENTE'!$H126 -> 0 | AQ8: =IF(OR(AP8="TC",AP8="MT"),'CARGA DOCENTE'!$A126," ") | AR8: =IF(OR(AP8="TC",AP8="MT"),'CARGA DOCENTE'!$B126," ") | AS8: =IF(OR(AP8="TC",AP8="MT"),'CARGA DOCENTE'!$C126," ") | AT8: =IF(OR(AP8="TC",AP8="MT"),'CARGA DOCENTE'!$G126," ") | AU8: ='CARGA DOCENTE'!$H127 -> 0 | AV8: =IF(OR(AU8="TC",AU8="MT"),'CARGA DOCENTE'!$A127," ") | AW8: =IF(OR(AU8="TC",AU8="MT"),'CARGA DOCENTE'!$B127," ") | AX8: =IF(OR(AU8="TC",AU8="MT"),'CARGA DOCENTE'!$C127," ") | AY8: =IF(OR(AU8="TC",AU8="MT"),'CARGA DOCENTE'!$G127," ") | AZ8: ='CARGA DOCENTE'!$H128 -> 0 | BA8: =IF(OR(AZ8="TC",AZ8="MT"),'CARGA DOCENTE'!$A128," ") | BB8: =IF(OR(AZ8="TC",AZ8="MT"),'CARGA DOCENTE'!$B128," ") | BC8: =IF(OR(AZ8="TC",AZ8="MT"),'CARGA DOCENTE'!$C128," ") | BD8: =IF(OR(AZ8="TC",AZ8="MT"),'CARGA DOCENTE'!$G128," ") | BE8: ='CARGA DOCENTE'!$H129 -> 0 | BF8: =IF(OR(BE8="TC",BE8="MT"),'CARGA DOCENTE'!$A129," ") | BG8: =IF(OR(BE8="TC",BE8="MT"),'CARGA DOCENTE'!$B129," ") | BH8: =IF(OR(BE8="TC",BE8="MT"),'CARGA DOCENTE'!$C129," ") | BI8: =IF(OR(BE8="TC",BE8="MT"),'CARGA DOCENTE'!$G129," ") | BJ8: ='CARGA DOCENTE'!$H130 -> 0 | BK8: =IF(OR(BJ8="TC",BJ8="MT"),'CARGA DOCENTE'!$A130," ") | BL8: =IF(OR(BJ8="TC",BJ8="MT"),'CARGA DOCENTE'!$B130," ") | BM8: =IF(OR(BJ8="TC",BJ8="MT"),'CARGA DOCENTE'!$C130," ") | BN8: =IF(OR(BJ8="TC",BJ8="MT"),'CARGA DOCENTE'!$G130," ") | BO8: ='CARGA DOCENTE'!$H131 -> 0 | BP8: =IF(OR(BO8="TC",BO8="MT"),'CARGA DOCENTE'!$A131," ") | BQ8: =IF(OR(BO8="TC",BO8="MT"),'CARGA DOCENTE'!$B131," ") | BR8: =IF(OR(BO8="TC",BO8="MT"),'CARGA DOCENTE'!$C131," ") | BS8: =IF(OR(BO8="TC",BO8="MT"),'CARGA DOCENTE'!$G131," ") | BT8: ='CARGA DOCENTE'!$H132 -> 0 | BU8: =IF(OR(BT8="TC",BT8="MT"),'CARGA DOCENTE'!$A132," ") | BV8: =IF(OR(BT8="TC",BT8="MT"),'CARGA DOCENTE'!$B132," ") | BW8: =IF(OR(BT8="TC",BT8="MT"),'CARGA DOCENTE'!$C132," ") | BX8: =IF(OR(BT8="TC",BT8="MT"),'CARGA DOCENTE'!$G132," ")
A9: ='CARGA DOCENTE'!J136 -> 0 | B9: ='CARGA DOCENTE'!$H136 -> 0 | C9: =IF(OR(B9="TC",B9="MT"),'CARGA DOCENTE'!$A136," ") | D9: =IF(OR(B9="TC",B9="MT"),'CARGA DOCENTE'!$B136," ") | E9: =IF(OR(B9="TC",B9="MT"),'CARGA DOCENTE'!$C136," ") | F9: =IF(OR(B9="TC",B9="MT"),'CARGA DOCENTE'!$G136," ") | G9: ='CARGA DOCENTE'!$H137 -> 0 | H9: =IF(OR(G9="TC",G9="MT"),'CARGA DOCENTE'!$A137," ") | I9: =IF(OR(G9="TC",G9="MT"),'CARGA DOCENTE'!$B137," ") | J9: =IF(OR(G9="TC",G9="MT"),'CARGA DOCENTE'!$C137," ") | K9: =IF(OR(G9="TC",G9="MT"),'CARGA DOCENTE'!$G137," ") | L9: ='CARGA DOCENTE'!$H138 -> 0 | M9: =IF(OR(L9="TC",L9="MT"),'CARGA DOCENTE'!$A138," ") | N9: =IF(OR(L9="TC",L9="MT"),'CARGA DOCENTE'!$B138," ") | O9: =IF(OR(L9="TC",L9="MT"),'CARGA DOCENTE'!$C138," ") | P9: =IF(OR(L9="TC",L9="MT"),'CARGA DOCENTE'!$G138," ") | Q9: ='CARGA DOCENTE'!$H139 -> 0 | R9: =IF(OR(Q9="TC",Q9="MT"),'CARGA DOCENTE'!$A139," ") | S9: =IF(OR(Q9="TC",Q9="MT"),'CARGA DOCENTE'!$B139," ") | T9: =IF(OR(Q9="TC",Q9="MT"),'CARGA DOCENTE'!$C139," ") | U9: =IF(OR(Q9="TC",Q9="MT"),'CARGA DOCENTE'!$G139," ") | V9: ='CARGA DOCENTE'!$H140 -> 0 | W9: =IF(OR(V9="TC",V9="MT"),'CARGA DOCENTE'!$A140," ") | X9: =IF(OR(V9="TC",V9="MT"),'CARGA DOCENTE'!$B140," ") | Y9: =IF(OR(V9="TC",V9="MT"),'CARGA DOCENTE'!$C140," ") | Z9: =IF(OR(V9="TC",V9="MT"),'CARGA DOCENTE'!$G140," ") | AA9: ='CARGA DOCENTE'!$H141 -> 0 | AB9: =IF(OR(AA9="TC",AA9="MT"),'CARGA DOCENTE'!$A141," ") | AC9: =IF(OR(AA9="TC",AA9="MT"),'CARGA DOCENTE'!$B141," ") | AD9: =IF(OR(AA9="TC",AA9="MT"),'CARGA DOCENTE'!$C141," ") | AE9: =IF(OR(AA9="TC",AA9="MT"),'CARGA DOCENTE'!$G141," ") | AF9: ='CARGA DOCENTE'!$H142 -> 0 | AG9: =IF(OR(AF9="TC",AF9="MT"),'CARGA DOCENTE'!$A142," ") | AH9: =IF(OR(AF9="TC",AF9="MT"),'CARGA DOCENTE'!$B142," ") | AI9: =IF(OR(AF9="TC",AF9="MT"),'CARGA DOCENTE'!$C142," ") | AJ9: =IF(OR(AF9="TC",AF9="MT"),'CARGA DOCENTE'!$G142," ") | AK9: ='CARGA DOCENTE'!$H143 -> 0 | AL9: =IF(OR(AK9="TC",AK9="MT"),'CARGA DOCENTE'!$A143," ") | AM9: =IF(OR(AK9="TC",AK9="MT"),'CARGA DOCENTE'!$B143," ") | AN9: =IF(OR(AK9="TC",AK9="MT"),'CARGA DOCENTE'!$C143," ") | AO9: =IF(OR(AK9="TC",AK9="MT"),'CARGA DOCENTE'!$G143," ") | AP9: ='CARGA DOCENTE'!$H144 -> 0 | AQ9: =IF(OR(AP9="TC",AP9="MT"),'CARGA DOCENTE'!$A144," ") | AR9: =IF(OR(AP9="TC",AP9="MT"),'CARGA DOCENTE'!$B144," ") | AS9: =IF(OR(AP9="TC",AP9="MT"),'CARGA DOCENTE'!$C144," ") | AT9: =IF(OR(AP9="TC",AP9="MT"),'CARGA DOCENTE'!$G144," ") | AU9: ='CARGA DOCENTE'!$H145 -> 0 | AV9: =IF(OR(AU9="TC",AU9="MT"),'CARGA DOCENTE'!$A145," ") | AW9: =IF(OR(AU9="TC",AU9="MT"),'CARGA DOCENTE'!$B145," ") | AX9: =IF(OR(AU9="TC",AU9="MT"),'CARGA DOCENTE'!$C145," ") | AY9: =IF(OR(AU9="TC",AU9="MT"),'CARGA DOCENTE'!$G145," ") | AZ9: ='CARGA DOCENTE'!$H146 -> 0 | BA9: =IF(OR(AZ9="TC",AZ9="MT"),'CARGA DOCENTE'!$A146," ") | BB9: =IF(OR(AZ9="TC",AZ9="MT"),'CARGA DOCENTE'!$B146," ") | BC9: =IF(OR(AZ9="TC",AZ9="MT"),'CARGA DOCENTE'!$C146," ") | BD9: =IF(OR(AZ9="TC",AZ9="MT"),'CARGA DOCENTE'!$G146," ") | BE9: ='CARGA DOCENTE'!$H147 -> 0 | BF9: =IF(OR(BE9="TC",BE9="MT"),'CARGA DOCENTE'!$A147," ") | BG9: =IF(OR(BE9="TC",BE9="MT"),'CARGA DOCENTE'!$B147," ") | BH9: =IF(OR(BE9="TC",BE9="MT"),'CARGA DOCENTE'!$C147," ") | BI9: =IF(OR(BE9="TC",BE9="MT"),'CARGA DOCENTE'!$G147," ") | BJ9: ='CARGA DOCENTE'!$H148 -> 0 | BK9: =IF(OR(BJ9="TC",BJ9="MT"),'CARGA DOCENTE'!$A148," ") | BL9: =IF(OR(BJ9="TC",BJ9="MT"),'CARGA DOCENTE'!$B148," ") | BM9: =IF(OR(BJ9="TC",BJ9="MT"),'CARGA DOCENTE'!$C148," ") | BN9: =IF(OR(BJ9="TC",BJ9="MT"),'CARGA DOCENTE'!$G148," ") | BO9: ='CARGA DOCENTE'!$H149 -> 0 | BP9: =IF(OR(BO9="TC",BO9="MT"),'CARGA DOCENTE'!$A149," ") | BQ9: =IF(OR(BO9="TC",BO9="MT"),'CARGA DOCENTE'!$B149," ") | BR9: =IF(OR(BO9="TC",BO9="MT"),'CARGA DOCENTE'!$C149," ") | BS9: =IF(OR(BO9="TC",BO9="MT"),'CARGA DOCENTE'!$G149," ") | BT9: ='CARGA DOCENTE'!$H150 -> 0 | BU9: =IF(OR(BT9="TC",BT9="MT"),'CARGA DOCENTE'!$A150," ") | BV9: =IF(OR(BT9="TC",BT9="MT"),'CARGA DOCENTE'!$B150," ") | BW9: =IF(OR(BT9="TC",BT9="MT"),'CARGA DOCENTE'!$C150," ") | BX9: =IF(OR(BT9="TC",BT9="MT"),'CARGA DOCENTE'!$G150," ")
A10: ='CARGA DOCENTE'!J154 -> 0 | B10: ='CARGA DOCENTE'!$H154 -> 0 | C10: =IF(OR(B10="TC",B10="MT"),'CARGA DOCENTE'!$A154," ") | D10: =IF(OR(B10="TC",B10="MT"),'CARGA DOCENTE'!$B154," ") | E10: =IF(OR(B10="TC",B10="MT"),'CARGA DOCENTE'!$C154," ") | F10: =IF(OR(B10="TC",B10="MT"),'CARGA DOCENTE'!$G154," ") | G10: ='CARGA DOCENTE'!$H155 -> 0 | H10: =IF(OR(G10="TC",G10="MT"),'CARGA DOCENTE'!$A155," ") | I10: =IF(OR(G10="TC",G10="MT"),'CARGA DOCENTE'!$B155," ") | J10: =IF(OR(G10="TC",G10="MT"),'CARGA DOCENTE'!$C155," ") | K10: =IF(OR(G10="TC",G10="MT"),'CARGA DOCENTE'!$G155," ") | L10: ='CARGA DOCENTE'!$H156 -> 0 | M10: =IF(OR(L10="TC",L10="MT"),'CARGA DOCENTE'!$A156," ") | N10: =IF(OR(L10="TC",L10="MT"),'CARGA DOCENTE'!$B156," ") | O10: =IF(OR(L10="TC",L10="MT"),'CARGA DOCENTE'!$C156," ") | P10: =IF(OR(L10="TC",L10="MT"),'CARGA DOCENTE'!$G156," ") | Q10: ='CARGA DOCENTE'!$H157 -> 0 | R10: =IF(OR(Q10="TC",Q10="MT"),'CARGA DOCENTE'!$A157," ") | S10: =IF(OR(Q10="TC",Q10="MT"),'CARGA DOCENTE'!$B157," ") | T10: =IF(OR(Q10="TC",Q10="MT"),'CARGA DOCENTE'!$C157," ") | U10: =IF(OR(Q10="TC",Q10="MT"),'CARGA DOCENTE'!$G157," ") | V10: ='CARGA DOCENTE'!$H158 -> 0 | W10: =IF(OR(V10="TC",V10="MT"),'CARGA DOCENTE'!$A158," ") | X10: =IF(OR(V10="TC",V10="MT"),'CARGA DOCENTE'!$B158," ") | Y10: =IF(OR(V10="TC",V10="MT"),'CARGA DOCENTE'!$C158," ") | Z10: =IF(OR(V10="TC",V10="MT"),'CARGA DOCENTE'!$G158," ") | AA10: ='CARGA DOCENTE'!$H159 -> 0 | AB10: =IF(OR(AA10="TC",AA10="MT"),'CARGA DOCENTE'!$A159," ") | AC10: =IF(OR(AA10="TC",AA10="MT"),'CARGA DOCENTE'!$B159," ") | AD10: =IF(OR(AA10="TC",AA10="MT"),'CARGA DOCENTE'!$C159," ") | AE10: =IF(OR(AA10="TC",AA10="MT"),'CARGA DOCENTE'!$G159," ") | AF10: ='CARGA DOCENTE'!$H160 -> 0 | AG10: =IF(OR(AF10="TC",AF10="MT"),'CARGA DOCENTE'!$A160," ") | AH10: =IF(OR(AF10="TC",AF10="MT"),'CARGA DOCENTE'!$B160," ") | AI10: =IF(OR(AF10="TC",AF10="MT"),'CARGA DOCENTE'!$C160," ") | AJ10: =IF(OR(AF10="TC",AF10="MT"),'CARGA DOCENTE'!$G160," ") | AK10: ='CARGA DOCENTE'!$H161 -> 0 | AL10: =IF(OR(AK10="TC",AK10="MT"),'CARGA DOCENTE'!$A161," ") | AM10: =IF(OR(AK10="TC",AK10="MT"),'CARGA DOCENTE'!$B161," ") | AN10: =IF(OR(AK10="TC",AK10="MT"),'CARGA DOCENTE'!$C161," ") | AO10: =IF(OR(AK10="TC",AK10="MT"),'CARGA DOCENTE'!$G161," ") | AP10: ='CARGA DOCENTE'!$H162 -> 0 | AQ10: =IF(OR(AP10="TC",AP10="MT"),'CARGA DOCENTE'!$A162," ") | AR10: =IF(OR(AP10="TC",AP10="MT"),'CARGA DOCENTE'!$B162," ") | AS10: =IF(OR(AP10="TC",AP10="MT"),'CARGA DOCENTE'!$C162," ") | AT10: =IF(OR(AP10="TC",AP10="MT"),'CARGA DOCENTE'!$G162," ") | AU10: ='CARGA DOCENTE'!$H163 -> 0 | AV10: =IF(OR(AU10="TC",AU10="MT"),'CARGA DOCENTE'!$A163," ") | AW10: =IF(OR(AU10="TC",AU10="MT"),'CARGA DOCENTE'!$B163," ") | AX10: =IF(OR(AU10="TC",AU10="MT"),'CARGA DOCENTE'!$C163," ") | AY10: =IF(OR(AU10="TC",AU10="MT"),'CARGA DOCENTE'!$G163," ") | AZ10: ='CARGA DOCENTE'!$H164 -> 0 | BA10: =IF(OR(AZ10="TC",AZ10="MT"),'CARGA DOCENTE'!$A164," ") | BB10: =IF(OR(AZ10="TC",AZ10="MT"),'CARGA DOCENTE'!$B164," ") | BC10: =IF(OR(AZ10="TC",AZ10="MT"),'CARGA DOCENTE'!$C164," ") | BD10: =IF(OR(AZ10="TC",AZ10="MT"),'CARGA DOCENTE'!$G164," ") | BE10: ='CARGA DOCENTE'!$H165 -> 0 | BF10: =IF(OR(BE10="TC",BE10="MT"),'CARGA DOCENTE'!$A165," ") | BG10: =IF(OR(BE10="TC",BE10="MT"),'CARGA DOCENTE'!$B165," ") | BH10: =IF(OR(BE10="TC",BE10="MT"),'CARGA DOCENTE'!$C165," ") | BI10: =IF(OR(BE10="TC",BE10="MT"),'CARGA DOCENTE'!$G165," ") | BJ10: ='CARGA DOCENTE'!$H166 -> 0 | BK10: =IF(OR(BJ10="TC",BJ10="MT"),'CARGA DOCENTE'!$A166," ") | BL10: =IF(OR(BJ10="TC",BJ10="MT"),'CARGA DOCENTE'!$B166," ") | BM10: =IF(OR(BJ10="TC",BJ10="MT"),'CARGA DOCENTE'!$C166," ") | BN10: =IF(OR(BJ10="TC",BJ10="MT"),'CARGA DOCENTE'!$G166," ") | BO10: ='CARGA DOCENTE'!$H167 -> 0 | BP10: =IF(OR(BO10="TC",BO10="MT"),'CARGA DOCENTE'!$A167," ") | BQ10: =IF(OR(BO10="TC",BO10="MT"),'CARGA DOCENTE'!$B167," ") | BR10: =IF(OR(BO10="TC",BO10="MT"),'CARGA DOCENTE'!$C167," ") | BS10: =IF(OR(BO10="TC",BO10="MT"),'CARGA DOCENTE'!$G167," ") | BT10: ='CARGA DOCENTE'!$H168 -> 0 | BU10: =IF(OR(BT10="TC",BT10="MT"),'CARGA DOCENTE'!$A168," ") | BV10: =IF(OR(BT10="TC",BT10="MT"),'CARGA DOCENTE'!$B168," ") | BW10: =IF(OR(BT10="TC",BT10="MT"),'CARGA DOCENTE'!$C168," ") | BX10: =IF(OR(BT10="TC",BT10="MT"),'CARGA DOCENTE'!$G168," ")
A11: ='CARGA DOCENTE'!J172 -> 0 | B11: ='CARGA DOCENTE'!$H172 -> 0 | C11: =IF(OR(B11="TC",B11="MT"),'CARGA DOCENTE'!$A172," ") | D11: =IF(OR(B11="TC",B11="MT"),'CARGA DOCENTE'!$B172," ") | E11: =IF(OR(B11="TC",B11="MT"),'CARGA DOCENTE'!$C172," ") | F11: =IF(OR(B11="TC",B11="MT"),'CARGA DOCENTE'!$G172," ") | G11: ='CARGA DOCENTE'!$H173 -> 0 | H11: =IF(OR(G11="TC",G11="MT"),'CARGA DOCENTE'!$A173," ") | I11: =IF(OR(G11="TC",G11="MT"),'CARGA DOCENTE'!$B173," ") | J11: =IF(OR(G11="TC",G11="MT"),'CARGA DOCENTE'!$C173," ") | K11: =IF(OR(G11="TC",G11="MT"),'CARGA DOCENTE'!$G173," ") | L11: ='CARGA DOCENTE'!$H174 -> 0 | M11: =IF(OR(L11="TC",L11="MT"),'CARGA DOCENTE'!$A174," ") | N11: =IF(OR(L11="TC",L11="MT"),'CARGA DOCENTE'!$B174," ") | O11: =IF(OR(L11="TC",L11="MT"),'CARGA DOCENTE'!$C174," ") | P11: =IF(OR(L11="TC",L11="MT"),'CARGA DOCENTE'!$G174," ") | Q11: ='CARGA DOCENTE'!$H175 -> 0 | R11: =IF(OR(Q11="TC",Q11="MT"),'CARGA DOCENTE'!$A175," ") | S11: =IF(OR(Q11="TC",Q11="MT"),'CARGA DOCENTE'!$B175," ") | T11: =IF(OR(Q11="TC",Q11="MT"),'CARGA DOCENTE'!$C175," ") | U11: =IF(OR(Q11="TC",Q11="MT"),'CARGA DOCENTE'!$G175," ") | V11: ='CARGA DOCENTE'!$H176 -> 0 | W11: =IF(OR(V11="TC",V11="MT"),'CARGA DOCENTE'!$A176," ") | X11: =IF(OR(V11="TC",V11="MT"),'CARGA DOCENTE'!$B176," ") | Y11: =IF(OR(V11="TC",V11="MT"),'CARGA DOCENTE'!$C176," ") | Z11: =IF(OR(V11="TC",V11="MT"),'CARGA DOCENTE'!$G176," ") | AA11: ='CARGA DOCENTE'!$H177 -> 0 | AB11: =IF(OR(AA11="TC",AA11="MT"),'CARGA DOCENTE'!$A177," ") | AC11: =IF(OR(AA11="TC",AA11="MT"),'CARGA DOCENTE'!$B177," ") | AD11: =IF(OR(AA11="TC",AA11="MT"),'CARGA DOCENTE'!$C177," ") | AE11: =IF(OR(AA11="TC",AA11="MT"),'CARGA DOCENTE'!$G177," ") | AF11: ='CARGA DOCENTE'!$H178 -> 0 | AG11: =IF(OR(AF11="TC",AF11="MT"),'CARGA DOCENTE'!$A178," ") | AH11: =IF(OR(AF11="TC",AF11="MT"),'CARGA DOCENTE'!$B178," ") | AI11: =IF(OR(AF11="TC",AF11="MT"),'CARGA DOCENTE'!$C178," ") | AJ11: =IF(OR(AF11="TC",AF11="MT"),'CARGA DOCENTE'!$G178," ") | AK11: ='CARGA DOCENTE'!$H179 -> 0 | AL11: =IF(OR(AK11="TC",AK11="MT"),'CARGA DOCENTE'!$A179," ") | AM11: =IF(OR(AK11="TC",AK11="MT"),'CARGA DOCENTE'!$B179," ") | AN11: =IF(OR(AK11="TC",AK11="MT"),'CARGA DOCENTE'!$C179," ") | AO11: =IF(OR(AK11="TC",AK11="MT"),'CARGA DOCENTE'!$G179," ") | AP11: ='CARGA DOCENTE'!$H180 -> 0 | AQ11: =IF(OR(AP11="TC",AP11="MT"),'CARGA DOCENTE'!$A180," ") | AR11: =IF(OR(AP11="TC",AP11="MT"),'CARGA DOCENTE'!$B180," ") | AS11: =IF(OR(AP11="TC",AP11="MT"),'CARGA DOCENTE'!$C180," ") | AT11: =IF(OR(AP11="TC",AP11="MT"),'CARGA DOCENTE'!$G180," ") | AU11: ='CARGA DOCENTE'!$H181 -> 0 | AV11: =IF(OR(AU11="TC",AU11="MT"),'CARGA DOCENTE'!$A181," ") | AW11: =IF(OR(AU11="TC",AU11="MT"),'CARGA DOCENTE'!$B181," ") | AX11: =IF(OR(AU11="TC",AU11="MT"),'CARGA DOCENTE'!$C181," ") | AY11: =IF(OR(AU11="TC",AU11="MT"),'CARGA DOCENTE'!$G181," ") | AZ11: ='CARGA DOCENTE'!$H182 -> 0 | BA11: =IF(OR(AZ11="TC",AZ11="MT"),'CARGA DOCENTE'!$A182," ") | BB11: =IF(OR(AZ11="TC",AZ11="MT"),'CARGA DOCENTE'!$B182," ") | BC11: =IF(OR(AZ11="TC",AZ11="MT"),'CARGA DOCENTE'!$C182," ") | BD11: =IF(OR(AZ11="TC",AZ11="MT"),'CARGA DOCENTE'!$G182," ") | BE11: ='CARGA DOCENTE'!$H183 -> 0 | BF11: =IF(OR(BE11="TC",BE11="MT"),'CARGA DOCENTE'!$A183," ") | BG11: =IF(OR(BE11="TC",BE11="MT"),'CARGA DOCENTE'!$B183," ") | BH11: =IF(OR(BE11="TC",BE11="MT"),'CARGA DOCENTE'!$C183," ") | BI11: =IF(OR(BE11="TC",BE11="MT"),'CARGA DOCENTE'!$G183," ") | BJ11: ='CARGA DOCENTE'!$H184 -> 0 | BK11: =IF(OR(BJ11="TC",BJ11="MT"),'CARGA DOCENTE'!$A184," ") | BL11: =IF(OR(BJ11="TC",BJ11="MT"),'CARGA DOCENTE'!$B184," ") | BM11: =IF(OR(BJ11="TC",BJ11="MT"),'CARGA DOCENTE'!$C184," ") | BN11: =IF(OR(BJ11="TC",BJ11="MT"),'CARGA DOCENTE'!$G184," ") | BO11: ='CARGA DOCENTE'!$H185 -> 0 | BP11: =IF(OR(BO11="TC",BO11="MT"),'CARGA DOCENTE'!$A185," ") | BQ11: =IF(OR(BO11="TC",BO11="MT"),'CARGA DOCENTE'!$B185," ") | BR11: =IF(OR(BO11="TC",BO11="MT"),'CARGA DOCENTE'!$C185," ") | BS11: =IF(OR(BO11="TC",BO11="MT"),'CARGA DOCENTE'!$G185," ") | BT11: ='CARGA DOCENTE'!$H186 -> 0 | BU11: =IF(OR(BT11="TC",BT11="MT"),'CARGA DOCENTE'!$A186," ") | BV11: =IF(OR(BT11="TC",BT11="MT"),'CARGA DOCENTE'!$B186," ") | BW11: =IF(OR(BT11="TC",BT11="MT"),'CARGA DOCENTE'!$C186," ") | BX11: =IF(OR(BT11="TC",BT11="MT"),'CARGA DOCENTE'!$G186," ")
A12: ='CARGA DOCENTE'!J190 -> 0 | B12: ='CARGA DOCENTE'!$H190 -> 0 | C12: =IF(OR(B12="TC",B12="MT"),'CARGA DOCENTE'!$A190," ") | D12: =IF(OR(B12="TC",B12="MT"),'CARGA DOCENTE'!$B190," ") | E12: =IF(OR(B12="TC",B12="MT"),'CARGA DOCENTE'!$C190," ") | F12: =IF(OR(B12="TC",B12="MT"),'CARGA DOCENTE'!$G190," ") | G12: ='CARGA DOCENTE'!$H191 -> 0 | H12: =IF(OR(G12="TC",G12="MT"),'CARGA DOCENTE'!$A191," ") | I12: =IF(OR(G12="TC",G12="MT"),'CARGA DOCENTE'!$B191," ") | J12: =IF(OR(G12="TC",G12="MT"),'CARGA DOCENTE'!$C191," ") | K12: =IF(OR(G12="TC",G12="MT"),'CARGA DOCENTE'!$G191," ") | L12: ='CARGA DOCENTE'!$H192 -> 0 | M12: =IF(OR(L12="TC",L12="MT"),'CARGA DOCENTE'!$A192," ") | N12: =IF(OR(L12="TC",L12="MT"),'CARGA DOCENTE'!$B192," ") | O12: =IF(OR(L12="TC",L12="MT"),'CARGA DOCENTE'!$C192," ") | P12: =IF(OR(L12="TC",L12="MT"),'CARGA DOCENTE'!$G192," ") | Q12: ='CARGA DOCENTE'!$H193 -> 0 | R12: =IF(OR(Q12="TC",Q12="MT"),'CARGA DOCENTE'!$A193," ") | S12: =IF(OR(Q12="TC",Q12="MT"),'CARGA DOCENTE'!$B193," ") | T12: =IF(OR(Q12="TC",Q12="MT"),'CARGA DOCENTE'!$C193," ") | U12: =IF(OR(Q12="TC",Q12="MT"),'CARGA DOCENTE'!$G193," ") | V12: ='CARGA DOCENTE'!$H194 -> 0 | W12: =IF(OR(V12="TC",V12="MT"),'CARGA DOCENTE'!$A194," ") | X12: =IF(OR(V12="TC",V12="MT"),'CARGA DOCENTE'!$B194," ") | Y12: =IF(OR(V12="TC",V12="MT"),'CARGA DOCENTE'!$C194," ") | Z12: =IF(OR(V12="TC",V12="MT"),'CARGA DOCENTE'!$G194," ") | AA12: ='CARGA DOCENTE'!$H195 -> 0 | AB12: =IF(OR(AA12="TC",AA12="MT"),'CARGA DOCENTE'!$A195," ") | AC12: =IF(OR(AA12="TC",AA12="MT"),'CARGA DOCENTE'!$B195," ") | AD12: =IF(OR(AA12="TC",AA12="MT"),'CARGA DOCENTE'!$C195," ") | AE12: =IF(OR(AA12="TC",AA12="MT"),'CARGA DOCENTE'!$G195," ") | AF12: ='CARGA DOCENTE'!$H196 -> 0 | AG12: =IF(OR(AF12="TC",AF12="MT"),'CARGA DOCENTE'!$A196," ") | AH12: =IF(OR(AF12="TC",AF12="MT"),'CARGA DOCENTE'!$B196," ") | AI12: =IF(OR(AF12="TC",AF12="MT"),'CARGA DOCENTE'!$C196," ") | AJ12: =IF(OR(AF12="TC",AF12="MT"),'CARGA DOCENTE'!$G196," ") | AK12: ='CARGA DOCENTE'!$H197 -> 0 | AL12: =IF(OR(AK12="TC",AK12="MT"),'CARGA DOCENTE'!$A197," ") | AM12: =IF(OR(AK12="TC",AK12="MT"),'CARGA DOCENTE'!$B197," ") | AN12: =IF(OR(AK12="TC",AK12="MT"),'CARGA DOCENTE'!$C197," ") | AO12: =IF(OR(AK12="TC",AK12="MT"),'CARGA DOCENTE'!$G197," ") | AP12: ='CARGA DOCENTE'!$H198 -> 0 | AQ12: =IF(OR(AP12="TC",AP12="MT"),'CARGA DOCENTE'!$A198," ") | AR12: =IF(OR(AP12="TC",AP12="MT"),'CARGA DOCENTE'!$B198," ") | AS12: =IF(OR(AP12="TC",AP12="MT"),'CARGA DOCENTE'!$C198," ") | AT12: =IF(OR(AP12="TC",AP12="MT"),'CARGA DOCENTE'!$G198," ") | AU12: ='CARGA DOCENTE'!$H199 -> 0 | AV12: =IF(OR(AU12="TC",AU12="MT"),'CARGA DOCENTE'!$A199," ") | AW12: =IF(OR(AU12="TC",AU12="MT"),'CARGA DOCENTE'!$B199," ") | AX12: =IF(OR(AU12="TC",AU12="MT"),'CARGA DOCENTE'!$C199," ") | AY12: =IF(OR(AU12="TC",AU12="MT"),'CARGA DOCENTE'!$G199," ") | AZ12: ='CARGA DOCENTE'!$H200 -> 0 | BA12: =IF(OR(AZ12="TC",AZ12="MT"),'CARGA DOCENTE'!$A200," ") | BB12: =IF(OR(AZ12="TC",AZ12="MT"),'CARGA DOCENTE'!$B200," ") | BC12: =IF(OR(AZ12="TC",AZ12="MT"),'CARGA DOCENTE'!$C200," ") | BD12: =IF(OR(AZ12="TC",AZ12="MT"),'CARGA DOCENTE'!$G200," ") | BE12: ='CARGA DOCENTE'!$H201 -> 0 | BF12: =IF(OR(BE12="TC",BE12="MT"),'CARGA DOCENTE'!$A201," ") | BG12: =IF(OR(BE12="TC",BE12="MT"),'CARGA DOCENTE'!$B201," ") | BH12: =IF(OR(BE12="TC",BE12="MT"),'CARGA DOCENTE'!$C201," ") | BI12: =IF(OR(BE12="TC",BE12="MT"),'CARGA DOCENTE'!$G201," ") | BJ12: ='CARGA DOCENTE'!$H202 -> 0 | BK12: =IF(OR(BJ12="TC",BJ12="MT"),'CARGA DOCENTE'!$A202," ") | BL12: =IF(OR(BJ12="TC",BJ12="MT"),'CARGA DOCENTE'!$B202," ") | BM12: =IF(OR(BJ12="TC",BJ12="MT"),'CARGA DOCENTE'!$C202," ") | BN12: =IF(OR(BJ12="TC",BJ12="MT"),'CARGA DOCENTE'!$G202," ") | BO12: ='CARGA DOCENTE'!$H203 -> 0 | BP12: =IF(OR(BO12="TC",BO12="MT"),'CARGA DOCENTE'!$A203," ") | BQ12: =IF(OR(BO12="TC",BO12="MT"),'CARGA DOCENTE'!$B203," ") | BR12: =IF(OR(BO12="TC",BO12="MT"),'CARGA DOCENTE'!$C203," ") | BS12: =IF(OR(BO12="TC",BO12="MT"),'CARGA DOCENTE'!$G203," ") | BT12: ='CARGA DOCENTE'!$H204 -> 0 | BU12: =IF(OR(BT12="TC",BT12="MT"),'CARGA DOCENTE'!$A204," ") | BV12: =IF(OR(BT12="TC",BT12="MT"),'CARGA DOCENTE'!$B204," ") | BW12: =IF(OR(BT12="TC",BT12="MT"),'CARGA DOCENTE'!$C204," ") | BX12: =IF(OR(BT12="TC",BT12="MT"),'CARGA DOCENTE'!$G204," ")
A13: ='CARGA DOCENTE'!J208 -> 0 | B13: ='CARGA DOCENTE'!$H208 -> 0 | C13: =IF(OR(B13="TC",B13="MT"),'CARGA DOCENTE'!$A208," ") | D13: =IF(OR(B13="TC",B13="MT"),'CARGA DOCENTE'!$B208," ") | E13: =IF(OR(B13="TC",B13="MT"),'CARGA DOCENTE'!$C208," ") | F13: =IF(OR(B13="TC",B13="MT"),'CARGA DOCENTE'!$G208," ") | G13: ='CARGA DOCENTE'!$H209 -> 0 | H13: =IF(OR(G13="TC",G13="MT"),'CARGA DOCENTE'!$A209," ") | I13: =IF(OR(G13="TC",G13="MT"),'CARGA DOCENTE'!$B209," ") | J13: =IF(OR(G13="TC",G13="MT"),'CARGA DOCENTE'!$C209," ") | K13: =IF(OR(G13="TC",G13="MT"),'CARGA DOCENTE'!$G209," ") | L13: ='CARGA DOCENTE'!$H210 -> 0 | M13: =IF(OR(L13="TC",L13="MT"),'CARGA DOCENTE'!$A210," ") | N13: =IF(OR(L13="TC",L13="MT"),'CARGA DOCENTE'!$B210," ") | O13: =IF(OR(L13="TC",L13="MT"),'CARGA DOCENTE'!$C210," ") | P13: =IF(OR(L13="TC",L13="MT"),'CARGA DOCENTE'!$G210," ") | Q13: ='CARGA DOCENTE'!$H211 -> 0 | R13: =IF(OR(Q13="TC",Q13="MT"),'CARGA DOCENTE'!$A211," ") | S13: =IF(OR(Q13="TC",Q13="MT"),'CARGA DOCENTE'!$B211," ") | T13: =IF(OR(Q13="TC",Q13="MT"),'CARGA DOCENTE'!$C211," ") | U13: =IF(OR(Q13="TC",Q13="MT"),'CARGA DOCENTE'!$G211," ") | V13: ='CARGA DOCENTE'!$H212 -> 0 | W13: =IF(OR(V13="TC",V13="MT"),'CARGA DOCENTE'!$A212," ") | X13: =IF(OR(V13="TC",V13="MT"),'CARGA DOCENTE'!$B212," ") | Y13: =IF(OR(V13="TC",V13="MT"),'CARGA DOCENTE'!$C212," ") | Z13: =IF(OR(V13="TC",V13="MT"),'CARGA DOCENTE'!$G212," ") | AA13: ='CARGA DOCENTE'!$H213 -> 0 | AB13: =IF(OR(AA13="TC",AA13="MT"),'CARGA DOCENTE'!$A213," ") | AC13: =IF(OR(AA13="TC",AA13="MT"),'CARGA DOCENTE'!$B213," ") | AD13: =IF(OR(AA13="TC",AA13="MT"),'CARGA DOCENTE'!$C213," ") | AE13: =IF(OR(AA13="TC",AA13="MT"),'CARGA DOCENTE'!$G213," ") | AF13: ='CARGA DOCENTE'!$H214 -> 0 | AG13: =IF(OR(AF13="TC",AF13="MT"),'CARGA DOCENTE'!$A214," ") | AH13: =IF(OR(AF13="TC",AF13="MT"),'CARGA DOCENTE'!$B214," ") | AI13: =IF(OR(AF13="TC",AF13="MT"),'CARGA DOCENTE'!$C214," ") | AJ13: =IF(OR(AF13="TC",AF13="MT"),'CARGA DOCENTE'!$G214," ") | AK13: ='CARGA DOCENTE'!$H215 -> 0 | AL13: =IF(OR(AK13="TC",AK13="MT"),'CARGA DOCENTE'!$A215," ") | AM13: =IF(OR(AK13="TC",AK13="MT"),'CARGA DOCENTE'!$B215," ") | AN13: =IF(OR(AK13="TC",AK13="MT"),'CARGA DOCENTE'!$C215," ") | AO13: =IF(OR(AK13="TC",AK13="MT"),'CARGA DOCENTE'!$G215," ") | AP13: ='CARGA DOCENTE'!$H216 -> 0 | AQ13: =IF(OR(AP13="TC",AP13="MT"),'CARGA DOCENTE'!$A216," ") | AR13: =IF(OR(AP13="TC",AP13="MT"),'CARGA DOCENTE'!$B216," ") | AS13: =IF(OR(AP13="TC",AP13="MT"),'CARGA DOCENTE'!$C216," ") | AT13: =IF(OR(AP13="TC",AP13="MT"),'CARGA DOCENTE'!$G216," ") | AU13: ='CARGA DOCENTE'!$H217 -> 0 | AV13: =IF(OR(AU13="TC",AU13="MT"),'CARGA DOCENTE'!$A217," ") | AW13: =IF(OR(AU13="TC",AU13="MT"),'CARGA DOCENTE'!$B217," ") | AX13: =IF(OR(AU13="TC",AU13="MT"),'CARGA DOCENTE'!$C217," ") | AY13: =IF(OR(AU13="TC",AU13="MT"),'CARGA DOCENTE'!$G217," ") | AZ13: ='CARGA DOCENTE'!$H218 -> 0 | BA13: =IF(OR(AZ13="TC",AZ13="MT"),'CARGA DOCENTE'!$A218," ") | BB13: =IF(OR(AZ13="TC",AZ13="MT"),'CARGA DOCENTE'!$B218," ") | BC13: =IF(OR(AZ13="TC",AZ13="MT"),'CARGA DOCENTE'!$C218," ") | BD13: =IF(OR(AZ13="TC",AZ13="MT"),'CARGA DOCENTE'!$G218," ") | BE13: ='CARGA DOCENTE'!$H219 -> 0 | BF13: =IF(OR(BE13="TC",BE13="MT"),'CARGA DOCENTE'!$A219," ") | BG13: =IF(OR(BE13="TC",BE13="MT"),'CARGA DOCENTE'!$B219," ") | BH13: =IF(OR(BE13="TC",BE13="MT"),'CARGA DOCENTE'!$C219," ") | BI13: =IF(OR(BE13="TC",BE13="MT"),'CARGA DOCENTE'!$G219," ") | BJ13: ='CARGA DOCENTE'!$H220 -> 0 | BK13: =IF(OR(BJ13="TC",BJ13="MT"),'CARGA DOCENTE'!$A220," ") | BL13: =IF(OR(BJ13="TC",BJ13="MT"),'CARGA DOCENTE'!$B220," ") | BM13: =IF(OR(BJ13="TC",BJ13="MT"),'CARGA DOCENTE'!$C220," ") | BN13: =IF(OR(BJ13="TC",BJ13="MT"),'CARGA DOCENTE'!$G220," ") | BO13: ='CARGA DOCENTE'!$H221 -> 0 | BP13: =IF(OR(BO13="TC",BO13="MT"),'CARGA DOCENTE'!$A221," ") | BQ13: =IF(OR(BO13="TC",BO13="MT"),'CARGA DOCENTE'!$B221," ") | BR13: =IF(OR(BO13="TC",BO13="MT"),'CARGA DOCENTE'!$C221," ") | BS13: =IF(OR(BO13="TC",BO13="MT"),'CARGA DOCENTE'!$G221," ") | BT13: ='CARGA DOCENTE'!$H222 -> 0 | BU13: =IF(OR(BT13="TC",BT13="MT"),'CARGA DOCENTE'!$A222," ") | BV13: =IF(OR(BT13="TC",BT13="MT"),'CARGA DOCENTE'!$B222," ") | BW13: =IF(OR(BT13="TC",BT13="MT"),'CARGA DOCENTE'!$C222," ") | BX13: =IF(OR(BT13="TC",BT13="MT"),'CARGA DOCENTE'!$G222," ")
A14: ='CARGA DOCENTE'!J226 -> 0 | B14: ='CARGA DOCENTE'!$H226 -> 0 | C14: =IF(OR(B14="TC",B14="MT"),'CARGA DOCENTE'!$A226," ") | D14: =IF(OR(B14="TC",B14="MT"),'CARGA DOCENTE'!$B226," ") | E14: =IF(OR(B14="TC",B14="MT"),'CARGA DOCENTE'!$C226," ") | F14: =IF(OR(B14="TC",B14="MT"),'CARGA DOCENTE'!$G226," ") | G14: ='CARGA DOCENTE'!$H227 -> 0 | H14: =IF(OR(G14="TC",G14="MT"),'CARGA DOCENTE'!$A227," ") | I14: =IF(OR(G14="TC",G14="MT"),'CARGA DOCENTE'!$B227," ") | J14: =IF(OR(G14="TC",G14="MT"),'CARGA DOCENTE'!$C227," ") | K14: =IF(OR(G14="TC",G14="MT"),'CARGA DOCENTE'!$G227," ") | L14: ='CARGA DOCENTE'!$H228 -> 0 | M14: =IF(OR(L14="TC",L14="MT"),'CARGA DOCENTE'!$A228," ") | N14: =IF(OR(L14="TC",L14="MT"),'CARGA DOCENTE'!$B228," ") | O14: =IF(OR(L14="TC",L14="MT"),'CARGA DOCENTE'!$C228," ") | P14: =IF(OR(L14="TC",L14="MT"),'CARGA DOCENTE'!$G228," ") | Q14: ='CARGA DOCENTE'!$H229 -> 0 | R14: =IF(OR(Q14="TC",Q14="MT"),'CARGA DOCENTE'!$A229," ") | S14: =IF(OR(Q14="TC",Q14="MT"),'CARGA DOCENTE'!$B229," ") | T14: =IF(OR(Q14="TC",Q14="MT"),'CARGA DOCENTE'!$C229," ") | U14: =IF(OR(Q14="TC",Q14="MT"),'CARGA DOCENTE'!$G229," ") | V14: ='CARGA DOCENTE'!$H230 -> 0 | W14: =IF(OR(V14="TC",V14="MT"),'CARGA DOCENTE'!$A230," ") | X14: =IF(OR(V14="TC",V14="MT"),'CARGA DOCENTE'!$B230," ") | Y14: =IF(OR(V14="TC",V14="MT"),'CARGA DOCENTE'!$C230," ") | Z14: =IF(OR(V14="TC",V14="MT"),'CARGA DOCENTE'!$G230," ") | AA14: ='CARGA DOCENTE'!$H231 -> 0 | AB14: =IF(OR(AA14="TC",AA14="MT"),'CARGA DOCENTE'!$A231," ") | AC14: =IF(OR(AA14="TC",AA14="MT"),'CARGA DOCENTE'!$B231," ") | AD14: =IF(OR(AA14="TC",AA14="MT"),'CARGA DOCENTE'!$C231," ") | AE14: =IF(OR(AA14="TC",AA14="MT"),'CARGA DOCENTE'!$G231," ") | AF14: ='CARGA DOCENTE'!$H232 -> 0 | AG14: =IF(OR(AF14="TC",AF14="MT"),'CARGA DOCENTE'!$A232," ") | AH14: =IF(OR(AF14="TC",AF14="MT"),'CARGA DOCENTE'!$B232," ") | AI14: =IF(OR(AF14="TC",AF14="MT"),'CARGA DOCENTE'!$C232," ") | AJ14: =IF(OR(AF14="TC",AF14="MT"),'CARGA DOCENTE'!$G232," ") | AK14: ='CARGA DOCENTE'!$H233 -> 0 | AL14: =IF(OR(AK14="TC",AK14="MT"),'CARGA DOCENTE'!$A233," ") | AM14: =IF(OR(AK14="TC",AK14="MT"),'CARGA DOCENTE'!$B233," ") | AN14: =IF(OR(AK14="TC",AK14="MT"),'CARGA DOCENTE'!$C233," ") | AO14: =IF(OR(AK14="TC",AK14="MT"),'CARGA DOCENTE'!$G233," ") | AP14: ='CARGA DOCENTE'!$H234 -> 0 | AQ14: =IF(OR(AP14="TC",AP14="MT"),'CARGA DOCENTE'!$A234," ") | AR14: =IF(OR(AP14="TC",AP14="MT"),'CARGA DOCENTE'!$B234," ") | AS14: =IF(OR(AP14="TC",AP14="MT"),'CARGA DOCENTE'!$C234," ") | AT14: =IF(OR(AP14="TC",AP14="MT"),'CARGA DOCENTE'!$G234," ") | AU14: ='CARGA DOCENTE'!$H235 -> 0 | AV14: =IF(OR(AU14="TC",AU14="MT"),'CARGA DOCENTE'!$A235," ") | AW14: =IF(OR(AU14="TC",AU14="MT"),'CARGA DOCENTE'!$B235," ") | AX14: =IF(OR(AU14="TC",AU14="MT"),'CARGA DOCENTE'!$C235," ") | AY14: =IF(OR(AU14="TC",AU14="MT"),'CARGA DOCENTE'!$G235," ") | AZ14: ='CARGA DOCENTE'!$H236 -> 0 | BA14: =IF(OR(AZ14="TC",AZ14="MT"),'CARGA DOCENTE'!$A236," ") | BB14: =IF(OR(AZ14="TC",AZ14="MT"),'CARGA DOCENTE'!$B236," ") | BC14: =IF(OR(AZ14="TC",AZ14="MT"),'CARGA DOCENTE'!$C236," ") | BD14: =IF(OR(AZ14="TC",AZ14="MT"),'CARGA DOCENTE'!$G236," ") | BE14: ='CARGA DOCENTE'!$H237 -> 0 | BF14: =IF(OR(BE14="TC",BE14="MT"),'CARGA DOCENTE'!$A237," ") | BG14: =IF(OR(BE14="TC",BE14="MT"),'CARGA DOCENTE'!$B237," ") | BH14: =IF(OR(BE14="TC",BE14="MT"),'CARGA DOCENTE'!$C237," ") | BI14: =IF(OR(BE14="TC",BE14="MT"),'CARGA DOCENTE'!$G237," ") | BJ14: ='CARGA DOCENTE'!$H238 -> 0 | BK14: =IF(OR(BJ14="TC",BJ14="MT"),'CARGA DOCENTE'!$A238," ") | BL14: =IF(OR(BJ14="TC",BJ14="MT"),'CARGA DOCENTE'!$B238," ") | BM14: =IF(OR(BJ14="TC",BJ14="MT"),'CARGA DOCENTE'!$C238," ") | BN14: =IF(OR(BJ14="TC",BJ14="MT"),'CARGA DOCENTE'!$G238," ") | BO14: ='CARGA DOCENTE'!$H239 -> 0 | BP14: =IF(OR(BO14="TC",BO14="MT"),'CARGA DOCENTE'!$A239," ") | BQ14: =IF(OR(BO14="TC",BO14="MT"),'CARGA DOCENTE'!$B239," ") | BR14: =IF(OR(BO14="TC",BO14="MT"),'CARGA DOCENTE'!$C239," ") | BS14: =IF(OR(BO14="TC",BO14="MT"),'CARGA DOCENTE'!$G239," ") | BT14: ='CARGA DOCENTE'!$H240 -> 0 | BU14: =IF(OR(BT14="TC",BT14="MT"),'CARGA DOCENTE'!$A240," ") | BV14: =IF(OR(BT14="TC",BT14="MT"),'CARGA DOCENTE'!$B240," ") | BW14: =IF(OR(BT14="TC",BT14="MT"),'CARGA DOCENTE'!$C240," ") | BX14: =IF(OR(BT14="TC",BT14="MT"),'CARGA DOCENTE'!$G240," ")
A15: ='CARGA DOCENTE'!J244 -> 0 | B15: ='CARGA DOCENTE'!$H244 -> 0 | C15: =IF(OR(B15="TC",B15="MT"),'CARGA DOCENTE'!$A244," ") | D15: =IF(OR(B15="TC",B15="MT"),'CARGA DOCENTE'!$B244," ") | E15: =IF(OR(B15="TC",B15="MT"),'CARGA DOCENTE'!$C244," ") | F15: =IF(OR(B15="TC",B15="MT"),'CARGA DOCENTE'!$G244," ") | G15: ='CARGA DOCENTE'!$H245 -> 0 | H15: =IF(OR(G15="TC",G15="MT"),'CARGA DOCENTE'!$A245," ") | I15: =IF(OR(G15="TC",G15="MT"),'CARGA DOCENTE'!$B245," ") | J15: =IF(OR(G15="TC",G15="MT"),'CARGA DOCENTE'!$C245," ") | K15: =IF(OR(G15="TC",G15="MT"),'CARGA DOCENTE'!$G245," ") | L15: ='CARGA DOCENTE'!$H246 -> 0 | M15: =IF(OR(L15="TC",L15="MT"),'CARGA DOCENTE'!$A246," ") | N15: =IF(OR(L15="TC",L15="MT"),'CARGA DOCENTE'!$B246," ") | O15: =IF(OR(L15="TC",L15="MT"),'CARGA DOCENTE'!$C246," ") | P15: =IF(OR(L15="TC",L15="MT"),'CARGA DOCENTE'!$G246," ") | Q15: ='CARGA DOCENTE'!$H247 -> 0 | R15: =IF(OR(Q15="TC",Q15="MT"),'CARGA DOCENTE'!$A247," ") | S15: =IF(OR(Q15="TC",Q15="MT"),'CARGA DOCENTE'!$B247," ") | T15: =IF(OR(Q15="TC",Q15="MT"),'CARGA DOCENTE'!$C247," ") | U15: =IF(OR(Q15="TC",Q15="MT"),'CARGA DOCENTE'!$G247," ") | V15: ='CARGA DOCENTE'!$H248 -> 0 | W15: =IF(OR(V15="TC",V15="MT"),'CARGA DOCENTE'!$A248," ") | X15: =IF(OR(V15="TC",V15="MT"),'CARGA DOCENTE'!$B248," ") | Y15: =IF(OR(V15="TC",V15="MT"),'CARGA DOCENTE'!$C248," ") | Z15: =IF(OR(V15="TC",V15="MT"),'CARGA DOCENTE'!$G248," ") | AA15: ='CARGA DOCENTE'!$H249 -> 0 | AB15: =IF(OR(AA15="TC",AA15="MT"),'CARGA DOCENTE'!$A249," ") | AC15: =IF(OR(AA15="TC",AA15="MT"),'CARGA DOCENTE'!$B249," ") | AD15: =IF(OR(AA15="TC",AA15="MT"),'CARGA DOCENTE'!$C249," ") | AE15: =IF(OR(AA15="TC",AA15="MT"),'CARGA DOCENTE'!$G249," ") | AF15: ='CARGA DOCENTE'!$H250 -> 0 | AG15: =IF(OR(AF15="TC",AF15="MT"),'CARGA DOCENTE'!$A250," ") | AH15: =IF(OR(AF15="TC",AF15="MT"),'CARGA DOCENTE'!$B250," ") | AI15: =IF(OR(AF15="TC",AF15="MT"),'CARGA DOCENTE'!$C250," ") | AJ15: =IF(OR(AF15="TC",AF15="MT"),'CARGA DOCENTE'!$G250," ") | AK15: ='CARGA DOCENTE'!$H251 -> 0 | AL15: =IF(OR(AK15="TC",AK15="MT"),'CARGA DOCENTE'!$A251," ") | AM15: =IF(OR(AK15="TC",AK15="MT"),'CARGA DOCENTE'!$B251," ") | AN15: =IF(OR(AK15="TC",AK15="MT"),'CARGA DOCENTE'!$C251," ") | AO15: =IF(OR(AK15="TC",AK15="MT"),'CARGA DOCENTE'!$G251," ") | AP15: ='CARGA DOCENTE'!$H252 -> 0 | AQ15: =IF(OR(AP15="TC",AP15="MT"),'CARGA DOCENTE'!$A252," ") | AR15: =IF(OR(AP15="TC",AP15="MT"),'CARGA DOCENTE'!$B252," ") | AS15: =IF(OR(AP15="TC",AP15="MT"),'CARGA DOCENTE'!$C252," ") | AT15: =IF(OR(AP15="TC",AP15="MT"),'CARGA DOCENTE'!$G252," ") | AU15: ='CARGA DOCENTE'!$H253 -> 0 | AV15: =IF(OR(AU15="TC",AU15="MT"),'CARGA DOCENTE'!$A253," ") | AW15: =IF(OR(AU15="TC",AU15="MT"),'CARGA DOCENTE'!$B253," ") | AX15: =IF(OR(AU15="TC",AU15="MT"),'CARGA DOCENTE'!$C253," ") | AY15: =IF(OR(AU15="TC",AU15="MT"),'CARGA DOCENTE'!$G253," ") | AZ15: ='CARGA DOCENTE'!$H254 -> 0 | BA15: =IF(OR(AZ15="TC",AZ15="MT"),'CARGA DOCENTE'!$A254," ") | BB15: =IF(OR(AZ15="TC",AZ15="MT"),'CARGA DOCENTE'!$B254," ") | BC15: =IF(OR(AZ15="TC",AZ15="MT"),'CARGA DOCENTE'!$C254," ") | BD15: =IF(OR(AZ15="TC",AZ15="MT"),'CARGA DOCENTE'!$G254," ") | BE15: ='CARGA DOCENTE'!$H255 -> 0 | BF15: =IF(OR(BE15="TC",BE15="MT"),'CARGA DOCENTE'!$A255," ") | BG15: =IF(OR(BE15="TC",BE15="MT"),'CARGA DOCENTE'!$B255," ") | BH15: =IF(OR(BE15="TC",BE15="MT"),'CARGA DOCENTE'!$C255," ") | BI15: =IF(OR(BE15="TC",BE15="MT"),'CARGA DOCENTE'!$G255," ") | BJ15: ='CARGA DOCENTE'!$H256 -> 0 | BK15: =IF(OR(BJ15="TC",BJ15="MT"),'CARGA DOCENTE'!$A256," ") | BL15: =IF(OR(BJ15="TC",BJ15="MT"),'CARGA DOCENTE'!$B256," ") | BM15: =IF(OR(BJ15="TC",BJ15="MT"),'CARGA DOCENTE'!$C256," ") | BN15: =IF(OR(BJ15="TC",BJ15="MT"),'CARGA DOCENTE'!$G256," ") | BO15: ='CARGA DOCENTE'!$H257 -> 0 | BP15: =IF(OR(BO15="TC",BO15="MT"),'CARGA DOCENTE'!$A257," ") | BQ15: =IF(OR(BO15="TC",BO15="MT"),'CARGA DOCENTE'!$B257," ") | BR15: =IF(OR(BO15="TC",BO15="MT"),'CARGA DOCENTE'!$C257," ") | BS15: =IF(OR(BO15="TC",BO15="MT"),'CARGA DOCENTE'!$G257," ") | BT15: ='CARGA DOCENTE'!$H258 -> 0 | BU15: =IF(OR(BT15="TC",BT15="MT"),'CARGA DOCENTE'!$A258," ") | BV15: =IF(OR(BT15="TC",BT15="MT"),'CARGA DOCENTE'!$B258," ") | BW15: =IF(OR(BT15="TC",BT15="MT"),'CARGA DOCENTE'!$C258," ") | BX15: =IF(OR(BT15="TC",BT15="MT"),'CARGA DOCENTE'!$G258," ")
