Workbook
Name Especialización: Hoja1!$B$2:$B$11
Name Pregrado_Presencial: Hoja1!$C$2:$C$15
Name Pregrado_Virtual: Hoja1!$D$2:$D$4

Sheet Hoja1
A1: Elija | B1: Elija | C1: Elija | E1: Elija | J1: Elija | K1: Elija
A2: Especialización | B2: Comunicación para el Desarrollo Territorial | C2: Administración de Empresas | D2: Administración de Empresas - Virtual | E2: 1 | F2: Comunicación para el Desarrollo Territorial | G2: 109540 | H2: 8450000 | I2: 8450000 | J2: 0 | K2: Aprobado | L2: Elija | M2: Elija | N2: Elija | O2: Elija | P2: Elija | Q2: Elija
A3: Pregrado_Presencial | B3: Data Analytics para Marketing Digital | C3: Administración de Empresas Agropecuarias | D3: Administración de Empresas Agropecuarias - Virtual | E3: 2 | F3: Data Analytics para Marketing Digital | G3: 109301 | H3: 8450000 | I3: 8450000 | J3: 0.01 | K3: No aprobado | L3: POPAYAN | M3: Nueva Beca | N3: Vinculado | O3: 2023 - II | P3: 1 | Q3: SI
A4: Pregrado_Virtual | B4: Derecho Constitucional | C4: Arquitectura | D4: Comunicación Social - Virtual | E4: 3 | F4: Derecho Constitucional | G4: 109778 | H4: 8450000 | I4: 8450000 | J4: 0.02 | K4: En estudio | L4: SANTANDER DE QUILICHAO | M4: Renovación de Beca | N4: No Vinculado | O4: 2024-I | P4: 2 | Q4: NO
B5: Derecho Procesal | C5: Comunicación Social | E5: 4 | F5: Derecho Procesal | G5: 109255 | H5: 8450000 | I5: 8450000 | J5: 0.03 | N5: Pendiente | O5: 2024-II | P5: 3
B6: Gerencia de Agronegocios Sostenibles | C6: Contaduría Pública | E6: 5 | F6: Gerencia de Agronegocios Sostenibles | G6: 109452 | H6: 8450000 | I6: 8450000 | J6: 0.04 | O6: 2025-I | P6: 4
B7: Gerencia del Talento Humano | C7: Derecho | E7: 6 | F7: Gerencia del Talento Humano | G7: 107237 | H7: 7800000 | I7: 7800000 | J7: 0.05 | O7: 2025-II | P7: 5
B8: Gestión del Riesgo de Desastres Integrada a la Planificación Territorial | C8: Ecología | E8: 7 | F8: Gestión del Riesgo de Desastres Integrada a la Planificación Territorial | G8: 104916 | H8: No aplica | I8: No aplica | J8: 0.06 | O8: 2026-I | P8: 6
B9: Gerencia Social | C9: Economía | E9: 8 | F9: Gerencia Social | G9: 110409 | H9: 8450000 | I9: 8450000 | J9: 0.07 | O9: 2026-II | P9: 7
B10: Psicología Educativa | C10: Ingeniería de Sistemas | E10: 9 | F10: Psicología Educativa | G10: 106237 | H10: 8450000 | I10: 8450000 | J10: 0.08 | O10: 2027-I | P10: 8
B11: Psicología Social Comunitaria | C11: Ingeniería Industrial | E11: 10 | F11: Psicología Social Comunitaria | G11: 106238 | H11: 8450000 | I11: 8450000 | J11: 0.09 | O11: 2028-II | P11: 9
C12: Ingeniería Agroecológica | E12: Terminó asignaturas | F12: Administración de Empresas | G12: 105530 | H12: 2609594 | I12: 3232624 | J12: 0.1 | O12: 2028-I | P12: 10
C13: LEAC | F13: Administración de Empresas Agropecuarias | G13: 4245 | H13: 2609594 | I13: 3232624 | J13: 0.11 | P13: ninguno
C14: Psicología | F14: Arquitectura | G14: 3615 | H14: 3014923 | I14: 3637953 | J14: 0.12
C15: Trabajo Social | F15: Comunicación Social | G15: 106807 | H15: 2609594 | I15: 3232624 | J15: 0.13
F16: Contaduría Pública | G16: 54462 | H16: 2609594 | I16: 3232624 | J16: 0.14
F17: Derecho | G17: 90886 | H17: 3482822 | I17: 4105852 | J17: 0.15
F18: Ecología | G18: 105030 | H18: 2609594 | I18: 3232624 | J18: 0.16
F19: Economía | G19: 105308 | H19: No aplica | I19: No aplica | J19: 0.17
F20: Ingeniería de Sistemas | G20: 2612 | H20: 2609594 | I20: 3232624 | J20: 0.18
F21: Ingeniería Industrial | G21: 2555 | H21: 2882995 | I21: 3506025 | J21: 0.19
F22: Ingeniería Agroecológica | G22: 111046 | H22: 2609594 | I22: 3232624 | J22: 0.2
F23: LEAC | G23: 105817 | H23: 2110400 | I23: 2733430 | J23: 0.21
F24: Psicología | G24: 3087 | H24: 2882995 | I24: 3506025 | J24: 0.22
F25: Trabajo Social | G25: 54694 | H25: 2882995 | I25: 3506025 | J25: 0.23
F26: Administración de Empresas - Virtual | G26: 105448 | H26: 1676920 | I26: 2299950 | J26: 0.24
F27: Administración de Empresas Agropecuarias - Virtual | G27: 103089 | H27: 1676920 | I27: 2299950 | J27: 0.25
F28: Comunicación Social - Virtual | G28: 106233 | H28: 1676920 | I28: 2299950 | J28: 0.26
J29: 0.27
J30: 0.28
J31: 0.29
J32: 0.3
J33: 0.31
J34: 0.32
J35: 0.33
J36: 0.34
J37: 0.35
J38: 0.36
J39: 0.37
J40: 0.38
...

Sheet BECAS TRABAJADORES
A7: INFORMACIÓN SOBRE EL TRABAJADOR | J7: INFORMACIÓN SOBRE EL PROGRAMA ACADÉMICO | S7: INFORMACIÓN SOBRE APOYOS ANTERIORES | U7: SITUACIÓN RELEVANTE | V7: % ASIGNADO POR COMITÉ DE BECAS | W7: VALOR DEL DESCUENTO | X7: VALOR ASUMIDO POR ESTUDIANTE | Y7: OBSERVACIONES | Z7: ESTADO
A8: NOMBRE DEL TRABAJADOR | B8: IDENTIFICACIÓN | C8: CARGO | D8: VINCULACIÓN | E8: CUENTA CON VINCULACIÓN REQUERIDA? | F8: SEDE DE LABORES | G8: CORREO | H8: CONTACTO TELEFÓNICO | I8: ESTADO DE LA BECA | J8: SEDE DE ESTUDIOS | K8: ¿Matrícula extraordinaria? | L8: NIVEL DE FORMACIÓN | M8: PROGRAMA ACADÉMICO | N8: SNIES | O8: VALOR DE LA MATRÍCUAL | P8: PROMEDIO DE SEMESTRE ANTERIOR | Q8: SEMESTRE DESDE EL CUAL SE LE BENEFICIA | R8: SEMESTRE A CURSAR | S8: NO. APOYOS ANTERIORES | T8: % ÚLTIMO APOYO GENERADO
D9: Elija | E9: Elija | F9: Elija | I9: Elija | J9: Elija | K9: Elija | L9: Elija | N9: =IFERROR(VLOOKUP(M9,Hoja1!$F$2:$H$28,2,0)," ") | O9: =IFERROR(IF(K9="NO",VLOOKUP(M9,Hoja1!$F$2:$I$28,3,0),VLOOKUP(M9,Hoja1!$F$2:$I$28,4,0))," ") | Q9: Elija | R9: Elija | V9: 0.1 | W9: =V9*O9 -> #VALUE! | X9: =O9-W9 -> #VALUE! | Z9: En estudio
D10: Elija | E10: Elija | F10: Elija | I10: Elija | J10: Elija | K10: Elija | L10: Elija | N10: =IFERROR(VLOOKUP(M10,Hoja1!$F$2:$H$28,2,0)," ") | O10: =IFERROR(IF(K10="NO",VLOOKUP(M10,Hoja1!$F$2:$I$28,3,0),VLOOKUP(M10,Hoja1!$F$2:$I$28,4,0))," ") | Q10: Elija | R10: Elija | V10: Elija | W10: =V10*O10 -> #VALUE! | X10: =O10-W10 -> #VALUE! | Z10: En estudio
D11: Elija | E11: Elija | F11: Elija | I11: Elija | J11: Elija | K11: Elija | L11: Elija | N11: =IFERROR(VLOOKUP(M11,Hoja1!$F$2:$H$28,2,0)," ") | O11: =IFERROR(IF(K11="NO",VLOOKUP(M11,Hoja1!$F$2:$I$28,3,0),VLOOKUP(M11,Hoja1!$F$2:$I$28,4,0))," ") | Q11: Elija | R11: Elija | V11: Elija | W11: =V11*O11 -> #VALUE! | X11: =O11-W11 -> #VALUE! | Z11: En estudio
D12: Elija | E12: Elija | F12: Elija | I12: Elija | J12: Elija | K12: Elija | L12: Elija | N12: =IFERROR(VLOOKUP(M12,Hoja1!$F$2:$H$28,2,0)," ") | O12: =IFERROR(IF(K12="NO",VLOOKUP(M12,Hoja1!$F$2:$I$28,3,0),VLOOKUP(M12,Hoja1!$F$2:$I$28,4,0))," ") | Q12: Elija | R12: Elija | V12: Elija | W12: =V12*O12 -> #VALUE! | X12: =O12-W12 -> #VALUE! | Z12: En estudio
D13: Elija | E13: Elija | F13: Elija | I13: Elija | J13: Elija | K13: Elija | L13: Elija | N13: =IFERROR(VLOOKUP(M13,Hoja1!$F$2:$H$28,2,0)," ") | O13: =IFERROR(IF(K13="NO",VLOOKUP(M13,Hoja1!$F$2:$I$28,3,0),VLOOKUP(M13,Hoja1!$F$2:$I$28,4,0))," ") | Q13: Elija | R13: Elija | V13: Elija | W13: =V13*O13 -> #VALUE! | X13: =O13-W13 -> #VALUE! | Z13: En estudio
D14: Elija | E14: Elija | F14: Elija | I14: Elija | J14: Elija | K14: Elija | L14: Elija | N14: =IFERROR(VLOOKUP(M14,Hoja1!$F$2:$H$28,2,0)," ") | O14: =IFERROR(IF(K14="NO",VLOOKUP(M14,Hoja1!$F$2:$I$28,3,0),VLOOKUP(M14,Hoja1!$F$2:$I$28,4,0))," ") | Q14: Elija | R14: Elija | V14: Elija | W14: =V14*O14 -> #VALUE! | X14: =O14-W14 -> #VALUE! | Z14: En estudio
D15: Elija | E15: Elija | F15: Elija | I15: Elija | J15: Elija | K15: Elija | L15: Elija | N15: =IFERROR(VLOOKUP(M15,Hoja1!$F$2:$H$28,2,0)," ") | O15: =IFERROR(IF(K15="NO",VLOOKUP(M15,Hoja1!$F$2:$I$28,3,0),VLOOKUP(M15,Hoja1!$F$2:$I$28,4,0))," ") | Q15: Elija | R15: Elija | V15: Elija | W15: =V15*O15 -> #VALUE! | X15: =O15-W15 -> #VALUE! | Z15: En estudio
D16: Elija | E16: Elija | F16: Elija | I16: Elija | J16: Elija | K16: Elija | L16: Elija | N16: =IFERROR(VLOOKUP(M16,Hoja1!$F$2:$H$28,2,0)," ") | O16: =IFERROR(IF(K16="NO",VLOOKUP(M16,Hoja1!$F$2:$I$28,3,0),VLOOKUP(M16,Hoja1!$F$2:$I$28,4,0))," ") | Q16: Elija | R16: Elija | V16: Elija | W16: =V16*O16 -> #VALUE! | X16: =O16-W16 -> #VALUE! | Z16: En estudio
D17: Elija | E17: Elija | F17: Elija | I17: Elija | J17: Elija | K17: Elija | L17: Elija | N17: =IFERROR(VLOOKUP(M17,Hoja1!$F$2:$H$28,2,0)," ") | O17: =IFERROR(IF(K17="NO",VLOOKUP(M17,Hoja1!$F$2:$I$28,3,0),VLOOKUP(M17,Hoja1!$F$2:$I$28,4,0))," ") | Q17: Elija | R17: Elija | V17: Elija | W17: =V17*O17 -> #VALUE! | X17: =O17-W17 -> #VALUE! | Z17: En estudio
D18: Elija | E18: Elija | F18: Elija | I18: Elija | J18: Elija | K18: Elija | L18: Elija | N18: =IFERROR(VLOOKUP(M18,Hoja1!$F$2:$H$28,2,0)," ") | O18: =IFERROR(IF(K18="NO",VLOOKUP(M18,Hoja1!$F$2:$I$28,3,0),VLOOKUP(M18,Hoja1!$F$2:$I$28,4,0))," ") | Q18: Elija | R18: Elija | V18: Elija | W18: =V18*O18 -> #VALUE! | X18: =O18-W18 -> #VALUE! | Z18: En estudio
D19: Elija | E19: Elija | F19: Elija | I19: Elija | J19: Elija | K19: Elija | L19: Elija | N19: =IFERROR(VLOOKUP(M19,Hoja1!$F$2:$H$28,2,0)," ") | O19: =IFERROR(IF(K19="NO",VLOOKUP(M19,Hoja1!$F$2:$I$28,3,0),VLOOKUP(M19,Hoja1!$F$2:$I$28,4,0))," ") | Q19: Elija | R19: Elija | V19: Elija | W19: =V19*O19 -> #VALUE! | X19: =O19-W19 -> #VALUE! | Z19: En estudio
D20: Elija | E20: Elija | F20: Elija | I20: Elija | J20: Elija | K20: Elija | L20: Elija | N20: =IFERROR(VLOOKUP(M20,Hoja1!$F$2:$H$28,2,0)," ") | O20: =IFERROR(IF(K20="NO",VLOOKUP(M20,Hoja1!$F$2:$I$28,3,0),VLOOKUP(M20,Hoja1!$F$2:$I$28,4,0))," ") | Q20: Elija | R20: Elija | V20: Elija | W20: =V20*O20 -> #VALUE! | X20: =O20-W20 -> #VALUE! | Z20: En estudio
D21: Elija | E21: Elija | F21: Elija | I21: Elija | J21: Elija | K21: Elija | L21: Elija | N21: =IFERROR(VLOOKUP(M21,Hoja1!$F$2:$H$28,2,0)," ") | O21: =IFERROR(IF(K21="NO",VLOOKUP(M21,Hoja1!$F$2:$I$28,3,0),VLOOKUP(M21,Hoja1!$F$2:$I$28,4,0))," ") | Q21: Elija | R21: Elija | V21: Elija | W21: =V21*O21 -> #VALUE! | X21: =O21-W21 -> #VALUE! | Z21: En estudio
... D70: Elija | E70: Elija | F70: Elija | I70: Elija | J70: Elija | K70: Elija | L70: Elija | N70: =IFERROR(VLOOKUP(M70,Hoja1!$F$2:$H$28,2,0)," ") | O70: =IFERROR(IF(K70="NO",VLOOKUP(M70,Hoja1!$F$2:$I$28,3,0),VLOOKUP(M70,Hoja1!$F$2:$I$28,4,0))," ") | Q70: Elija | R70: Elija | V70: Elija | W70: =V70*O70 -> #VALUE! | X70: =O70-W70 -> #VALUE! | Z70: En estudio

Sheet BECAS PARA HIJOS DE TRABAJADOR
A7: INFORMACIÓN SOBRE EL TRABAJADOR | L7: INFORMACIÓN SOBRE EL PROGRAMA ACADÉMICO | T7: SITUACIÓN RELEVANTE | U7: % ASIGNADO POR COMITÉ DE BECAS | V7: VALOR DEL DESCUENTO | W7: VALOR ASUMIDO POR ESTUDIANTE | X7: OBSERVACIONES | Y7: ESTADO
A8: NOMBRE DEL TRABAJADOR | B8: IDENTIFICACIÓN | C8: CARGO | D8: VINCULACIÓN | E8: CUENTA CON VINCULACIÓN SUCESIVA MAYOR A 2 SEMESTRES | F8: SEDE DE LABORES | G8: CORREO | H8: CONTACTO TELEFÓNICO | I8: NOMBRE DEL HIJO | J8: IDENTIFICACIÓN DEL HIJO | K8: ESTADO DE LA BECA | L8: SEDE DE ESTUDIOS | M8: ¿MATRÍCULA EXTRAORDINARIA? | N8: NIVEL DE FORMACIÓN | O8: PROGRAMA ACADÉMICO | P8: SNIES | Q8: VALOR DE LA MATRÍCUAL | R8: PROMEDIO DE SEMESTRE ANTERIOR | S8: SEMESTRE A CURSAR
D9: Elija | F9: Elija | K9: Elija | L9: Elija | M9: Elija | N9: Elija | P9: =IFERROR(VLOOKUP(O9,Hoja1!$F$2:$H$28,2,0)," ") | Q9: =IFERROR(IF(M9="NO",VLOOKUP(O9,Hoja1!$F$2:$I$28,3,0),VLOOKUP(O9,Hoja1!$F$2:$I$28,4,0))," ") | S9: Elija | U9: Elija | V9: =U9*Q9 -> #VALUE! | W9: =Q9-V9 -> #VALUE! | Y9: En estudio
D10: Elija | F10: Elija | K10: Elija | L10: Elija | M10: Elija | N10: Elija | P10: =IFERROR(VLOOKUP(O10,Hoja1!$F$2:$H$28,2,0)," ") | Q10: =IFERROR(IF(M10="NO",VLOOKUP(O10,Hoja1!$F$2:$I$28,3,0),VLOOKUP(O10,Hoja1!$F$2:$I$28,4,0))," ") | S10: Elija | U10: Elija | V10: =U10*Q10 -> #VALUE! | W10: =Q10-V10 -> #VALUE! | Y10: En estudio
D11: Elija | F11: Elija | K11: Elija | L11: Elija | M11: Elija | N11: Elija | P11: =IFERROR(VLOOKUP(O11,Hoja1!$F$2:$H$28,2,0)," ") | Q11: =IFERROR(IF(M11="NO",VLOOKUP(O11,Hoja1!$F$2:$I$28,3,0),VLOOKUP(O11,Hoja1!$F$2:$I$28,4,0))," ") | S11: Elija | U11: Elija | V11: =U11*Q11 -> #VALUE! | W11: =Q11-V11 -> #VALUE! | Y11: En estudio
D12: Elija | F12: Elija | K12: Elija | L12: Elija | M12: Elija | N12: Elija | P12: =IFERROR(VLOOKUP(O12,Hoja1!$F$2:$H$28,2,0)," ") | Q12: =IFERROR(IF(M12="NO",VLOOKUP(O12,Hoja1!$F$2:$I$28,3,0),VLOOKUP(O12,Hoja1!$F$2:$I$28,4,0))," ") | S12: Elija | U12: Elija | V12: =U12*Q12 -> #VALUE! | W12: =Q12-V12 -> #VALUE! | Y12: En estudio
D13: Elija | F13: Elija | K13: Elija | L13: Elija | M13: Elija | N13: Elija | P13: =IFERROR(VLOOKUP(O13,Hoja1!$F$2:$H$28,2,0)," ") | Q13: =IFERROR(IF(M13="NO",VLOOKUP(O13,Hoja1!$F$2:$I$28,3,0),VLOOKUP(O13,Hoja1!$F$2:$I$28,4,0))," ") | S13: Elija | U13: Elija | V13: =U13*Q13 -> #VALUE! | W13: =Q13-V13 -> #VALUE! | Y13: En estudio
D14: Elija | F14: Elija | K14: Elija | L14: Elija | M14: Elija | N14: Elija | P14: =IFERROR(VLOOKUP(O14,Hoja1!$F$2:$H$28,2,0)," ") | Q14: =IFERROR(IF(M14="NO",VLOOKUP(O14,Hoja1!$F$2:$I$28,3,0),VLOOKUP(O14,Hoja1!$F$2:$I$28,4,0))," ") | S14: Elija | U14: Elija | V14: =U14*Q14 -> #VALUE! | W14: =Q14-V14 -> #VALUE! | Y14: En estudio
D15: Elija | F15: Elija | K15: Elija | L15: Elija | M15: Elija | N15: Elija | P15: =IFERROR(VLOOKUP(O15,Hoja1!$F$2:$H$28,2,0)," ") | Q15: =IFERROR(IF(M15="NO",VLOOKUP(O15,Hoja1!$F$2:$I$28,3,0),VLOOKUP(O15,Hoja1!$F$2:$I$28,4,0))," ") | S15: Elija | U15: Elija | V15: =U15*Q15 -> #VALUE! | W15: =Q15-V15 -> #VALUE! | Y15: En estudio
D16: Elija | F16: Elija | K16: Elija | L16: Elija | M16: Elija | N16: Elija | P16: =IFERROR(VLOOKUP(O16,Hoja1!$F$2:$H$28,2,0)," ") | Q16: =IFERROR(IF(M16="NO",VLOOKUP(O16,Hoja1!$F$2:$I$28,3,0),VLOOKUP(O16,Hoja1!$F$2:$I$28,4,0))," ") | S16: Elija | U16: Elija | V16: =U16*Q16 -> #VALUE! | W16: =Q16-V16 -> #VALUE! | Y16: En estudio
D17: Elija | F17: Elija | K17: Elija | L17: Elija | M17: Elija | N17: Elija | P17: =IFERROR(VLOOKUP(O17,Hoja1!$F$2:$H$28,2,0)," ") | Q17: =IFERROR(IF(M17="NO",VLOOKUP(O17,Hoja1!$F$2:$I$28,3,0),VLOOKUP(O17,Hoja1!$F$2:$I$28,4,0))," ") | S17: Elija | U17: Elija | V17: =U17*Q17 -> #VALUE! | W17: =Q17-V17 -> #VALUE! | Y17: En estudio
D18: Elija | F18: Elija | K18: Elija | L18: Elija | M18: Elija | N18: Elija | P18: =IFERROR(VLOOKUP(O18,Hoja1!$F$2:$H$28,2,0)," ") | Q18: =IFERROR(IF(M18="NO",VLOOKUP(O18,Hoja1!$F$2:$I$28,3,0),VLOOKUP(O18,Hoja1!$F$2:$I$28,4,0))," ") | S18: Elija | U18: Elija | V18: =U18*Q18 -> #VALUE! | W18: =Q18-V18 -> #VALUE! | Y18: En estudio
D19: Elija | F19: Elija | K19: Elija | L19: Elija | M19: Elija | N19: Elija | P19: =IFERROR(VLOOKUP(O19,Hoja1!$F$2:$H$28,2,0)," ") | Q19: =IFERROR(IF(M19="NO",VLOOKUP(O19,Hoja1!$F$2:$I$28,3,0),VLOOKUP(O19,Hoja1!$F$2:$I$28,4,0))," ") | S19: Elija | U19: Elija | V19: =U19*Q19 -> #VALUE! | W19: =Q19-V19 -> #VALUE! | Y19: En estudio
D20: Elija | F20: Elija | K20: Elija | L20: Elija | M20: Elija | N20: Elija | P20: =IFERROR(VLOOKUP(O20,Hoja1!$F$2:$H$28,2,0)," ") | Q20: =IFERROR(IF(M20="NO",VLOOKUP(O20,Hoja1!$F$2:$I$28,3,0),VLOOKUP(O20,Hoja1!$F$2:$I$28,4,0))," ") | S20: Elija | U20: Elija | V20: =U20*Q20 -> #VALUE! | W20: =Q20-V20 -> #VALUE! | Y20: En estudio
... D64: Elija | F64: Elija | K64: Elija | L64: Elija | M64: Elija | N64: Elija | P64: =IFERROR(VLOOKUP(O64,Hoja1!$F$2:$H$28,2,0)," ") | Q64: =IFERROR(IF(M64="NO",VLOOKUP(O64,Hoja1!$F$2:$I$28,3,0),VLOOKUP(O64,Hoja1!$F$2:$I$28,4,0))," ") | S64: Elija | U64: Elija | V64: =U64*Q64 -> #VALUE! | W64: =Q64-V64 -> #VALUE! | Y64: En estudio
M65: Elija
M66: Elija
M67: Elija
M68: Elija
M69: Elija
M70: Elija

Sheet SOLICITUDES EXTERNAS
A7: INFORMACIÓN SOBRE EL SOLICITANTE | F7: INFORMACIÓN SOBRE EL PROGRAMA ACADÉMICO | N7: INFORMACIÓN SOBRE APOYOS ANTERIORES | P7: VALOR CON QUE CUENTA ESTUDIANTE | Q7: SITUACIÓN RELEVANTE | R7: % ASIGNADO POR COMITÉ DE BECAS | S7: VALOR DEL DESCUENTO | T7: VALOR ASUMIDO POR ESTUDIANTE | U7: OBSERVACIONES | V7: ESTADO
A8: NOMBRE DEL SOLICITANTE | B8: NOMBRE DEL ESTUDIANTE O ASPIRANTE | C8: IDENTIFICACIÓN | D8: CORREO | E8: CONTACTO TELEFÓNICO | F8: SEDE DE ESTUDIOS | G8: ¿Matrícula extraordinaria? | H8: ¿MATRÍCULA EXTRAORDINADIA? | I8: PROGRAMA ACADÉMICO | J8: SNIES | K8: VALOR DE LA MATRÍCUAL | L8: PROMEDIO DE SEMESTRE ANTERIOR | M8: SEMESTRE A CURSAR | N8: # APOYOS ANTERIORES | O8: % ÚLTIMO APOYO GENERADO
F9: POPAYAN | G9: Elija | H9: Elija | J9: =IFERROR(VLOOKUP(I9,Hoja1!$F$2:$I$28,2,0)," ") | K9: =IFERROR(IF(G9="NO",VLOOKUP(I9,Hoja1!$F$2:$I$28,3,0),VLOOKUP(I9,Hoja1!$F$2:$I$28,4,0))," ") | M9: Elija | R9: Elija | S9: =R9*K9 -> #VALUE! | T9: =K9-S9 -> #VALUE! | V9: En estudio
F10: Elija | G10: Elija | H10: Elija | J10: =IFERROR(VLOOKUP(I10,Hoja1!$F$2:$I$28,2,0)," ") | K10: =IFERROR(IF(G10="NO",VLOOKUP(I10,Hoja1!$F$2:$I$28,3,0),VLOOKUP(I10,Hoja1!$F$2:$I$28,4,0))," ") | M10: Elija | R10: Elija | S10: =R10*K10 -> #VALUE! | T10: =K10-S10 -> #VALUE! | V10: En estudio
F11: Elija | G11: Elija | H11: Elija | J11: =IFERROR(VLOOKUP(I11,Hoja1!$F$2:$I$28,2,0)," ") | K11: =IFERROR(IF(G11="NO",VLOOKUP(I11,Hoja1!$F$2:$I$28,3,0),VLOOKUP(I11,Hoja1!$F$2:$I$28,4,0))," ") | M11: Elija | R11: Elija | S11: =R11*K11 -> #VALUE! | T11: =K11-S11 -> #VALUE! | V11: En estudio
F12: Elija | G12: Elija | H12: Elija | J12: =IFERROR(VLOOKUP(I12,Hoja1!$F$2:$I$28,2,0)," ") | K12: =IFERROR(IF(G12="NO",VLOOKUP(I12,Hoja1!$F$2:$I$28,3,0),VLOOKUP(I12,Hoja1!$F$2:$I$28,4,0))," ") | M12: Elija | R12: Elija | S12: =R12*K12 -> #VALUE! | T12: =K12-S12 -> #VALUE! | V12: En estudio
F13: Elija | G13: Elija | H13: Elija | J13: =IFERROR(VLOOKUP(I13,Hoja1!$F$2:$I$28,2,0)," ") | K13: =IFERROR(IF(G13="NO",VLOOKUP(I13,Hoja1!$F$2:$I$28,3,0),VLOOKUP(I13,Hoja1!$F$2:$I$28,4,0))," ") | M13: Elija | R13: Elija | S13: =R13*K13 -> #VALUE! | T13: =K13-S13 -> #VALUE! | V13: En estudio
F14: Elija | G14: Elija | H14: Elija | J14: =IFERROR(VLOOKUP(I14,Hoja1!$F$2:$I$28,2,0)," ") | K14: =IFERROR(IF(G14="NO",VLOOKUP(I14,Hoja1!$F$2:$I$28,3,0),VLOOKUP(I14,Hoja1!$F$2:$I$28,4,0))," ") | M14: Elija | R14: Elija | S14: =R14*K14 -> #VALUE! | T14: =K14-S14 -> #VALUE! | V14: En estudio
F15: Elija | G15: Elija | H15: Elija | J15: =IFERROR(VLOOKUP(I15,Hoja1!$F$2:$I$28,2,0)," ") | K15: =IFERROR(IF(G15="NO",VLOOKUP(I15,Hoja1!$F$2:$I$28,3,0),VLOOKUP(I15,Hoja1!$F$2:$I$28,4,0))," ") | M15: Elija | R15: Elija | S15: =R15*K15 -> #VALUE! | T15: =K15-S15 -> #VALUE! | V15: En estudio
F16: Elija | G16: Elija | H16: Elija | J16: =IFERROR(VLOOKUP(I16,Hoja1!$F$2:$I$28,2,0)," ") | K16: =IFERROR(IF(G16="NO",VLOOKUP(I16,Hoja1!$F$2:$I$28,3,0),VLOOKUP(I16,Hoja1!$F$2:$I$28,4,0))," ") | M16: Elija | R16: Elija | S16: =R16*K16 -> #VALUE! | T16: =K16-S16 -> #VALUE! | V16: En estudio
F17: Elija | G17: Elija | H17: Elija | J17: =IFERROR(VLOOKUP(I17,Hoja1!$F$2:$I$28,2,0)," ") | K17: =IFERROR(IF(G17="NO",VLOOKUP(I17,Hoja1!$F$2:$I$28,3,0),VLOOKUP(I17,Hoja1!$F$2:$I$28,4,0))," ") | M17: Elija | R17: Elija | S17: =R17*K17 -> #VALUE! | T17: =K17-S17 -> #VALUE! | V17: En estudio
F18: Elija | G18: Elija | H18: Elija | J18: =IFERROR(VLOOKUP(I18,Hoja1!$F$2:$I$28,2,0)," ") | K18: =IFERROR(IF(G18="NO",VLOOKUP(I18,Hoja1!$F$2:$I$28,3,0),VLOOKUP(I18,Hoja1!$F$2:$I$28,4,0))," ") | M18: Elija | R18: Elija | S18: =R18*K18 -> #VALUE! | T18: =K18-S18 -> #VALUE! | V18: En estudio
F19: Elija | G19: Elija | H19: Elija | J19: =IFERROR(VLOOKUP(I19,Hoja1!$F$2:$I$28,2,0)," ") | K19: =IFERROR(IF(G19="NO",VLOOKUP(I19,Hoja1!$F$2:$I$28,3,0),VLOOKUP(I19,Hoja1!$F$2:$I$28,4,0))," ") | M19: Elija | R19: Elija | S19: =R19*K19 -> #VALUE! | T19: =K19-S19 -> #VALUE! | V19: En estudio
F20: Elija | G20: Elija | H20: Elija | J20: =IFERROR(VLOOKUP(I20,Hoja1!$F$2:$I$28,2,0)," ") | K20: =IFERROR(IF(G20="NO",VLOOKUP(I20,Hoja1!$F$2:$I$28,3,0),VLOOKUP(I20,Hoja1!$F$2:$I$28,4,0))," ") | M20: Elija | R20: Elija | S20: =R20*K20 -> #VALUE! | T20: =K20-S20 -> #VALUE! | V20: En estudio
... F109: Elija | G109: Elija | H109: Elija | J109: =IFERROR(VLOOKUP(I109,Hoja1!$F$2:$I$28,2,0)," ") | K109: =IFERROR(IF(G109="NO",VLOOKUP(I109,Hoja1!$F$2:$I$28,3,0),VLOOKUP(I109,Hoja1!$F$2:$I$28,4,0))," ") | M109: Elija | R109: Elija | S109: =R109*K109 -> #VALUE! | T109: =K109-S109 -> #VALUE! | V109: En estudio
F110: Elija | G110: Elija | H110: Elija | J110: =IFERROR(VLOOKUP(I110,Hoja1!$F$2:$I$28,2,0)," ") | K110: =IFERROR(IF(G110="NO",VLOOKUP(I110,Hoja1!$F$2:$I$28,3,0),VLOOKUP(I110,Hoja1!$F$2:$I$28,4,0))," ") | M110: 1 | R110: 1 | S110: =R110*K110 -> #VALUE! | T110: =K110-S110 -> #VALUE! | V110: En estudio
F111: Elija | G111: Elija | H111: Elija | J111: =IFERROR(VLOOKUP(I111,Hoja1!$F$2:$I$28,2,0)," ") | K111: =IFERROR(IF(G111="NO",VLOOKUP(I111,Hoja1!$F$2:$I$28,3,0),VLOOKUP(I111,Hoja1!$F$2:$I$28,4,0))," ") | M111: Elija | R111: Elija | S111: =R111*K111 -> #VALUE! | T111: =K111-S111 -> #VALUE! | V111: En estudio
F112: Elija | G112: Elija | H112: Elija | J112: =IFERROR(VLOOKUP(I112,Hoja1!$F$2:$I$28,2,0)," ") | K112: =IFERROR(IF(G112="NO",VLOOKUP(I112,Hoja1!$F$2:$I$28,3,0),VLOOKUP(I112,Hoja1!$F$2:$I$28,4,0))," ") | M112: Elija | R112: Elija | S112: =R112*K112 -> #VALUE! | T112: =K112-S112 -> #VALUE! | V112: En estudio
F113: Elija | G113: Elija | H113: Elija | J113: =IFERROR(VLOOKUP(I113,Hoja1!$F$2:$I$28,2,0)," ") | K113: =IFERROR(IF(G113="NO",VLOOKUP(I113,Hoja1!$F$2:$I$28,3,0),VLOOKUP(I113,Hoja1!$F$2:$I$28,4,0))," ") | M113: Elija | R113: Elija | S113: =R113*K113 -> #VALUE! | T113: =K113-S113 -> #VALUE! | V113: En estudio
F114: Elija | G114: Elija | H114: Elija | J114: =IFERROR(VLOOKUP(I114,Hoja1!$F$2:$I$28,2,0)," ") | K114: =IFERROR(IF(G114="NO",VLOOKUP(I114,Hoja1!$F$2:$I$28,3,0),VLOOKUP(I114,Hoja1!$F$2:$I$28,4,0))," ") | M114: Elija | R114: Elija | S114: =R114*K114 -> #VALUE! | T114: =K114-S114 -> #VALUE! | V114: En estudio
F115: Elija | G115: Elija | H115: Elija | J115: =IFERROR(VLOOKUP(I115,Hoja1!$F$2:$I$28,2,0)," ") | K115: =IFERROR(IF(G115="NO",VLOOKUP(I115,Hoja1!$F$2:$I$28,3,0),VLOOKUP(I115,Hoja1!$F$2:$I$28,4,0))," ") | M115: Elija | R115: Elija | S115: =R115*K115 -> #VALUE! | T115: =K115-S115 -> #VALUE! | V115: En estudio
F116: Elija | G116: Elija | H116: Elija | J116: =IFERROR(VLOOKUP(I116,Hoja1!$F$2:$I$28,2,0)," ") | K116: =IFERROR(IF(G116="NO",VLOOKUP(I116,Hoja1!$F$2:$I$28,3,0),VLOOKUP(I116,Hoja1!$F$2:$I$28,4,0))," ") | M116: Elija | R116: Elija | S116: =R116*K116 -> #VALUE! | T116: =K116-S116 -> #VALUE! | V116: En estudio
F117: Elija | G117: Elija | H117: Elija | J117: =IFERROR(VLOOKUP(I117,Hoja1!$F$2:$I$28,2,0)," ") | K117: =IFERROR(IF(G117="NO",VLOOKUP(I117,Hoja1!$F$2:$I$28,3,0),VLOOKUP(I117,Hoja1!$F$2:$I$28,4,0))," ") | M117: Elija | R117: Elija | S117: =R117*K117 -> #VALUE! | T117: =K117-S117 -> #VALUE! | V117: En estudio
F118: Elija | G118: Elija | H118: Elija | J118: =IFERROR(VLOOKUP(I118,Hoja1!$F$2:$I$28,2,0)," ") | K118: =IFERROR(IF(G118="NO",VLOOKUP(I118,Hoja1!$F$2:$I$28,3,0),VLOOKUP(I118,Hoja1!$F$2:$I$28,4,0))," ") | M118: Elija | R118: Elija | S118: =R118*K118 -> #VALUE! | T118: =K118-S118 -> #VALUE! | V118: En estudio
F119: Elija | G119: Elija | H119: Elija | J119: =IFERROR(VLOOKUP(I119,Hoja1!$F$2:$I$28,2,0)," ") | K119: =IFERROR(IF(G119="NO",VLOOKUP(I119,Hoja1!$F$2:$I$28,3,0),VLOOKUP(I119,Hoja1!$F$2:$I$28,4,0))," ") | M119: Elija | R119: Elija | S119: =R119*K119 -> #VALUE! | T119: =K119-S119 -> #VALUE! | V119: En estudio
F120: Elija | G120: Elija | H120: Elija | J120: =IFERROR(VLOOKUP(I120,Hoja1!$F$2:$I$28,2,0)," ") | K120: =IFERROR(IF(G120="NO",VLOOKUP(I120,Hoja1!$F$2:$I$28,3,0),VLOOKUP(I120,Hoja1!$F$2:$I$28,4,0))," ") | M120: Elija | R120: Elija | S120: =R120*K120 -> #VALUE! | T120: =K120-S120 -> #VALUE! | V120: En estudio
F121: Elija | G121: Elija | H121: Elija | J121: =IFERROR(VLOOKUP(I121,Hoja1!$F$2:$I$28,2,0)," ") | K121: =IFERROR(IF(G121="NO",VLOOKUP(I121,Hoja1!$F$2:$I$28,3,0),VLOOKUP(I121,Hoja1!$F$2:$I$28,4,0))," ") | M121: Elija | R121: Elija | S121: =R121*K121 -> #VALUE! | T121: =K121-S121 -> #VALUE! | V121: En estudio
F122: Elija | G122: Elija | H122: Elija | J122: =IFERROR(VLOOKUP(I122,Hoja1!$F$2:$I$28,2,0)," ") | K122: =IFERROR(IF(G122="NO",VLOOKUP(I122,Hoja1!$F$2:$I$28,3,0),VLOOKUP(I122,Hoja1!$F$2:$I$28,4,0))," ") | M122: Elija | R122: Elija | S122: =R122*K122 -> #VALUE! | T122: =K122-S122 -> #VALUE! | V122: En estudio
... F125: Elija | G125: Elija | H125: Elija | J125: =IFERROR(VLOOKUP(I125,Hoja1!$F$2:$I$28,2,0)," ") | K125: =IFERROR(IF(G125="NO",VLOOKUP(I125,Hoja1!$F$2:$I$28,3,0),VLOOKUP(I125,Hoja1!$F$2:$I$28,4,0))," ") | M125: Elija | R125: Elija | S125: =R125*K125 -> #VALUE! | T125: =K125-S125 -> #VALUE! | V125: En estudio
F126: Elija | G126: Elija | H126: Elija | J126: =IFERROR(VLOOKUP(I126,Hoja1!$F$2:$I$28,2,0)," ") | K126: =IFERROR(IF(G126="NO",VLOOKUP(I126,Hoja1!$F$2:$I$28,3,0),VLOOKUP(I126,Hoja1!$F$2:$I$28,4,0))," ") | M126: Elija | R126: 0 | S126: =R126*K126 -> #VALUE! | T126: =K126-S126 -> #VALUE! | V126: En estudio

Sheet ESTÍMULOS
A7: INFORMACIÓN SOBRE EL SOLICITANTE | G7: INFORMACIÓN SOBRE EL PROGRAMA ACADÉMICO | O7: INFORMACIÓN SOBRE APOYOS ANTERIORES | Q7: VALOR CON QUE CUENTA ESTUDIANTE | R7: SITUACIÓN RELEVANTE | S7: % ASIGNADO POR COMITÉ DE BECAS | T7: VALOR DEL DESCUENTO | U7: VALOR ASUMIDO POR ESTUDIANTE | V7: OBSERVACIONES | W7: ESTADO
A8: SOLICITANTE | B8: ESTÍMULO | C8: NOMBRE DEL ESTUDIANTE | D8: IDENTIFICACIÓN | E8: CORREO | F8: CONTACTO TELEFÓNICO | G8: SEDE DE ESTUDIOS | H8: ¿Matrícula extraordinaria? | I8: NIVEL DE FORMACIÓN | J8: PROGRAMA ACADÉMICO | K8: SNIES | L8: VALOR DE LA MATRÍCUAL | M8: PROMEDIO DE SEMESTRE ANTERIOR | N8: SEMESTRE A CURSAR | O8: NO. APOYOS ANTERIORES | P8: % ÚLTIMO APOYO GENERADO
G9: Elija | H9: Elija | I9: Elija | K9: =IFERROR(VLOOKUP(J9,Hoja1!$F$2:$H$28,2,0)," ") | L9: =IFERROR(IF(H9="NO",VLOOKUP(J9,Hoja1!$F$2:$I$28,3,0),VLOOKUP(J9,Hoja1!$F$2:$I$28,4,0))," ") | S9: Elija | T9: =S9*L9 -> #VALUE! | U9: =L9-T9 -> #VALUE! | W9: En estudio
G10: Elija | H10: Elija | I10: Elija | K10: =IFERROR(VLOOKUP(J10,Hoja1!$F$2:$H$28,2,0)," ") | L10: =IFERROR(IF(H10="NO",VLOOKUP(J10,Hoja1!$F$2:$I$28,3,0),VLOOKUP(J10,Hoja1!$F$2:$I$28,4,0))," ") | S10: Elija | T10: =S10*L10 -> #VALUE! | U10: =L10-T10 -> #VALUE! | W10: En estudio
G11: Elija | H11: Elija | I11: Elija | K11: =IFERROR(VLOOKUP(J11,Hoja1!$F$2:$H$28,2,0)," ") | L11: =IFERROR(IF(H11="NO",VLOOKUP(J11,Hoja1!$F$2:$I$28,3,0),VLOOKUP(J11,Hoja1!$F$2:$I$28,4,0))," ") | S11: Elija | T11: =S11*L11 -> #VALUE! | U11: =L11-T11 -> #VALUE! | W11: En estudio
G12: Elija | H12: Elija | I12: Elija | K12: =IFERROR(VLOOKUP(J12,Hoja1!$F$2:$H$28,2,0)," ") | L12: =IFERROR(IF(H12="NO",VLOOKUP(J12,Hoja1!$F$2:$I$28,3,0),VLOOKUP(J12,Hoja1!$F$2:$I$28,4,0))," ") | S12: Elija | T12: =S12*L12 -> #VALUE! | U12: =L12-T12 -> #VALUE! | W12: En estudio
G13: Elija | H13: Elija | I13: Elija | K13: =IFERROR(VLOOKUP(J13,Hoja1!$F$2:$H$28,2,0)," ") | L13: =IFERROR(IF(H13="NO",VLOOKUP(J13,Hoja1!$F$2:$I$28,3,0),VLOOKUP(J13,Hoja1!$F$2:$I$28,4,0))," ") | S13: Elija | T13: =S13*L13 -> #VALUE! | U13: =L13-T13 -> #VALUE! | W13: En estudio
G14: Elija | H14: Elija | I14: Elija | K14: =IFERROR(VLOOKUP(J14,Hoja1!$F$2:$H$28,2,0)," ") | L14: =IFERROR(IF(H14="NO",VLOOKUP(J14,Hoja1!$F$2:$I$28,3,0),VLOOKUP(J14,Hoja1!$F$2:$I$28,4,0))," ") | S14: Elija | T14: =S14*L14 -> #VALUE! | U14: =L14-T14 -> #VALUE! | W14: En estudio
G15: Elija | H15: Elija | I15: Elija | K15: =IFERROR(VLOOKUP(J15,Hoja1!$F$2:$H$28,2,0)," ") | L15: =IFERROR(IF(H15="NO",VLOOKUP(J15,Hoja1!$F$2:$I$28,3,0),VLOOKUP(J15,Hoja1!$F$2:$I$28,4,0))," ") | S15: Elija | T15: =S15*L15 -> #VALUE! | U15: =L15-T15 -> #VALUE! | W15: En estudio
G16: Elija | H16: Elija | I16: Elija | K16: =IFERROR(VLOOKUP(J16,Hoja1!$F$2:$H$28,2,0)," ") | L16: =IFERROR(IF(H16="NO",VLOOKUP(J16,Hoja1!$F$2:$I$28,3,0),VLOOKUP(J16,Hoja1!$F$2:$I$28,4,0))," ") | S16: Elija | T16: =S16*L16 -> #VALUE! | U16: =L16-T16 -> #VALUE! | W16: En estudio
G17: Elija | H17: Elija | I17: Elija | K17: =IFERROR(VLOOKUP(J17,Hoja1!$F$2:$H$28,2,0)," ") | L17: =IFERROR(IF(H17="NO",VLOOKUP(J17,Hoja1!$F$2:$I$28,3,0),VLOOKUP(J17,Hoja1!$F$2:$I$28,4,0))," ") | S17: Elija | T17: =S17*L17 -> #VALUE! | U17: =L17-T17 -> #VALUE! | W17: En estudio
G18: Elija | H18: Elija | I18: Elija | K18: =IFERROR(VLOOKUP(J18,Hoja1!$F$2:$H$28,2,0)," ") | L18: =IFERROR(IF(H18="NO",VLOOKUP(J18,Hoja1!$F$2:$I$28,3,0),VLOOKUP(J18,Hoja1!$F$2:$I$28,4,0))," ") | S18: Elija | T18: =S18*L18 -> #VALUE! | U18: =L18-T18 -> #VALUE! | W18: En estudio
G19: Elija | H19: Elija | I19: Elija | K19: =IFERROR(VLOOKUP(J19,Hoja1!$F$2:$H$28,2,0)," ") | L19: =IFERROR(IF(H19="NO",VLOOKUP(J19,Hoja1!$F$2:$I$28,3,0),VLOOKUP(J19,Hoja1!$F$2:$I$28,4,0))," ") | S19: Elija | T19: =S19*L19 -> #VALUE! | U19: =L19-T19 -> #VALUE! | W19: En estudio
G20: Elija | H20: Elija | I20: Elija | K20: =IFERROR(VLOOKUP(J20,Hoja1!$F$2:$H$28,2,0)," ") | L20: =IFERROR(IF(H20="NO",VLOOKUP(J20,Hoja1!$F$2:$I$28,3,0),VLOOKUP(J20,Hoja1!$F$2:$I$28,4,0))," ") | S20: Elija | T20: =S20*L20 -> #VALUE! | U20: =L20-T20 -> #VALUE! | W20: En estudio
... G66: Elija | H66: Elija | I66: Elija | K66: =IFERROR(VLOOKUP(J66,Hoja1!$F$2:$H$28,2,0)," ") | L66: =IFERROR(IF(H66="NO",VLOOKUP(J66,Hoja1!$F$2:$I$28,3,0),VLOOKUP(J66,Hoja1!$F$2:$I$28,4,0))," ") | S66: Elija | T66: =S66*L66 -> #VALUE! | U66: =L66-T66 -> #VALUE! | W66: En estudio

Sheet CANJES
A7: INFORMACIÓN SOBRE EL SOLICITANTE | F7: INFORMACIÓN SOBRE EL PROGRAMA ACADÉMICO | N7: INFORMACIÓN SOBRE APOYOS ANTERIORES | P7: VALOR CON QUE CUENTA ESTUDIANTE | Q7: SITUACIÓN RELEVANTE | R7: % ASIGNADO POR COMITÉ DE BECAS | S7: VALOR DEL DESCUENTO | T7: VALOR ASUMIDO POR ESTUDIANTE | U7: OBSERVACIONES | V7: ESTADO
A8: NOMBRE DEL SOLICITANTE | B8: NOMBRE DEL ESTUDIANTE O ASPIRANTE | C8: IDENTIFICACIÓN | D8: CORREO | E8: CONTACTO TELEFÓNICO | F8: SEDE DE ESTUDIOS | G8: ¿Matrícula extraordinaria? | H8: NIVEL DE FORMACIÓN | I8: PROGRAMA ACADÉMICO | J8: SNIES | K8: VALOR DE LA MATRÍCUAL | L8: PROMEDIO DE SEMESTRE ANTERIOR | M8: SEMESTRE A CURSAR | N8: NO. APOYOS ANTERIORES | O8: % ÚLTIMO APOYO GENERADO
F9: Elija | G9: Elija | H9: Elija | J9: =IFERROR(VLOOKUP(I9,Hoja1!$F$2:$H$28,2,0)," ") | K9: =IFERROR(IF(G9="NO",VLOOKUP(I9,Hoja1!$F$2:$I$28,3,0),VLOOKUP(I9,Hoja1!$F$2:$I$28,4,0))," ") | M9: Elija | R9: Elija | S9: =R9*K9 -> #VALUE! | T9: =K9-S9 -> #VALUE! | V9: En estudio
F10: Elija | G10: Elija | H10: Elija | J10: =IFERROR(VLOOKUP(I10,Hoja1!$F$2:$H$28,2,0)," ") | K10: =IFERROR(VLOOKUP(I10,Hoja1!$F$2:$H$28,3,0)," ") | M10: Elija | R10: Elija | S10: =R10*K10 -> #VALUE! | T10: =K10-S10 -> #VALUE! | V10: En estudio
F11: Elija | G11: Elija | H11: Elija | J11: =IFERROR(VLOOKUP(I11,Hoja1!$F$2:$H$28,2,0)," ") | K11: =IFERROR(VLOOKUP(I11,Hoja1!$F$2:$H$28,3,0)," ") | M11: Elija | R11: Elija | S11: =R11*K11 -> #VALUE! | T11: =K11-S11 -> #VALUE! | V11: En estudio
F12: Elija | G12: Elija | H12: Elija | J12: =IFERROR(VLOOKUP(I12,Hoja1!$F$2:$H$28,2,0)," ") | K12: =IFERROR(VLOOKUP(I12,Hoja1!$F$2:$H$28,3,0)," ") | M12: Elija | R12: Elija | S12: =R12*K12 -> #VALUE! | T12: =K12-S12 -> #VALUE! | V12: En estudio
F13: Elija | G13: Elija | H13: Elija | J13: =IFERROR(VLOOKUP(I13,Hoja1!$F$2:$H$28,2,0)," ") | K13: =IFERROR(VLOOKUP(I13,Hoja1!$F$2:$H$28,3,0)," ") | M13: Elija | R13: Elija | S13: =R13*K13 -> #VALUE! | T13: =K13-S13 -> #VALUE! | V13: En estudio
F14: Elija | G14: Elija | H14: Elija | J14: =IFERROR(VLOOKUP(I14,Hoja1!$F$2:$H$28,2,0)," ") | K14: =IFERROR(VLOOKUP(I14,Hoja1!$F$2:$H$28,3,0)," ") | M14: Elija | R14: Elija | S14: =R14*K14 -> #VALUE! | T14: =K14-S14 -> #VALUE! | V14: En estudio
F15: Elija | G15: Elija | H15: Elija | J15: =IFERROR(VLOOKUP(I15,Hoja1!$F$2:$H$28,2,0)," ") | K15: =IFERROR(VLOOKUP(I15,Hoja1!$F$2:$H$28,3,0)," ") | M15: Elija | R15: Elija | S15: =R15*K15 -> #VALUE! | T15: =K15-S15 -> #VALUE! | V15: En estudio
F16: Elija | G16: Elija | H16: Elija | J16: =IFERROR(VLOOKUP(I16,Hoja1!$F$2:$H$28,2,0)," ") | K16: =IFERROR(VLOOKUP(I16,Hoja1!$F$2:$H$28,3,0)," ") | M16: Elija | R16: Elija | S16: =R16*K16 -> #VALUE! | T16: =K16-S16 -> #VALUE! | V16: En estudio
F17: Elija | G17: Elija | H17: Elija | J17: =IFERROR(VLOOKUP(I17,Hoja1!$F$2:$H$28,2,0)," ") | K17: =IFERROR(VLOOKUP(I17,Hoja1!$F$2:$H$28,3,0)," ") | M17: Elija | R17: Elija | S17: =R17*K17 -> #VALUE! | T17: =K17-S17 -> #VALUE! | V17: En estudio
F18: Elija | G18: Elija | H18: Elija | J18: =IFERROR(VLOOKUP(I18,Hoja1!$F$2:$H$28,2,0)," ") | K18: =IFERROR(VLOOKUP(I18,Hoja1!$F$2:$H$28,3,0)," ") | M18: Elija | R18: Elija | S18: =R18*K18 -> #VALUE! | T18: =K18-S18 -> #VALUE! | V18: En estudio
F19: Elija | G19: Elija | H19: Elija | J19: =IFERROR(VLOOKUP(I19,Hoja1!$F$2:$H$28,2,0)," ") | K19: =IFERROR(VLOOKUP(I19,Hoja1!$F$2:$H$28,3,0)," ") | M19: Elija | R19: Elija | S19: =R19*K19 -> #VALUE! | T19: =K19-S19 -> #VALUE! | V19: En estudio
F20: Elija | G20: Elija | H20: Elija | J20: =IFERROR(VLOOKUP(I20,Hoja1!$F$2:$H$28,2,0)," ") | K20: =IFERROR(VLOOKUP(I20,Hoja1!$F$2:$H$28,3,0)," ") | M20: Elija | R20: Elija | S20: =R20*K20 -> #VALUE! | T20: =K20-S20 -> #VALUE! | V20: En estudio
F21: Elija | G21: Elija | H21: Elija | J21: =IFERROR(VLOOKUP(I21,Hoja1!$F$2:$H$28,2,0)," ") | K21: =IFERROR(VLOOKUP(I21,Hoja1!$F$2:$H$28,3,0)," ") | M21: Elija | R21: Elija | S21: =R21*K21 -> #VALUE! | T21: =K21-S21 -> #VALUE! | V21: En estudio
... F148: Elija | G148: Elija | H148: Elija | J148: =IFERROR(VLOOKUP(I148,Hoja1!$F$2:$H$28,2,0)," ") | K148: =IFERROR(VLOOKUP(I148,Hoja1!$F$2:$H$28,3,0)," ") | M148: Elija | R148: Elija | S148: =R148*K148 -> #VALUE! | T148: =K148-S148 -> #VALUE! | V148: En estudio
