Workbook
Name OBE: [1]Convencionales!$J$3:$J$17

Sheet INICIO
B16: Programa: | D16: Elija
B17: Nombre Director(a): | L17: Ir
B18: Sede: | D18: Elija
D20: Nombre | H20: Cargo
B21: Participantes: | C21: P1
C22: P2
C23: P3
C24: P4
C25: P5
C26: P6
C27: P7
C28: P8
C29: P9
C30: P10
C31: P11
C32: P12
B34: Fecha de elaboración: | D34: DD | E34: MM | F34: AAAA | H34: Periodo: | I34: Elija

Sheet F1
A1: Factor | B1: % | C1: Justificación
A2: F1. PROYECTO EDUCATIVO DEL PROGRAMA E IDENTIDAD INSTITUCIONAL | B2: ='Res.'!D5 -> #DIV/0!
D5: NIVEL DE IMPORTANCIA DE LA CARACTERÍSTICA
A6: Característica | D6: P1 | E6: P2 | F6: P3 | G6: P4 | H6: P5 | I6: P6 | J6: P7 | K6: P8 | L6: P9 | M6: P10
A7: 1. Proyecto educativo del programa
A8: 2. Relevancia académica y pertinencia social del programa académico
A11: Característica | B11: NIV | C11: % | D11: Justificación
A12: =A7 -> 1. Proyecto educativo del programa | B12: =AVERAGE(D7:M7) -> #DIV/0! | C12: =B12/SUM($B$12:$B$13) -> #DIV/0!
A13: =A8 -> 2. Relevancia académica y pertinencia social del programa académico | B13: =AVERAGE(D8:M8) -> #DIV/0! | C13: =B13/SUM($B$12:$B$13) -> #DIV/0!

Sheet F2
A1: Factor | B1: % | C1: Justificación
A2: F2. ESTUDIANTES | B2: ='Res.'!D8 -> #DIV/0!
D5: NIVEL DE IMPORTANCIA DE LA CARACTERÍSTICA
A6: Característica | D6: P1 | E6: P2 | F6: P3 | G6: P4 | H6: P5 | I6: P6 | J6: P7 | K6: P8 | L6: P9 | M6: P10
A7: 3. Participación en actividades de formación integral
A8: 4. Orientación y seguimiento a estudiantes
A9: 5. Capacidad de trabajo autónomo
A10: 6. Reglamento estudiantil y política académica
A11: 7. Estímulos y apoyos para estudiantes
A14: Característica | B14: NIV | C14: % | D14: Justificación
A15: =A7 -> 3. Participación en actividades de formación integral | B15: =AVERAGE(D7:M7) -> #DIV/0! | C15: =B15/SUM($B$15:$B$19) -> #DIV/0!
A16: =A8 -> 4. Orientación y seguimiento a estudiantes | B16: =AVERAGE(D8:M8) -> #DIV/0! | C16: =B16/SUM($B$15:$B$19) -> #DIV/0!
A17: =A9 -> 5. Capacidad de trabajo autónomo | B17: =AVERAGE(D9:M9) -> #DIV/0! | C17: =B17/SUM($B$15:$B$19) -> #DIV/0!
A18: =A10 -> 6. Reglamento estudiantil y política académica | B18: =AVERAGE(D11:M11) -> #DIV/0! | C18: =B18/SUM($B$15:$B$19) -> #DIV/0!
A19: =A11 -> 7. Estímulos y apoyos para estudiantes | B19: =AVERAGE(D11:M11) -> #DIV/0! | C19: =B19/SUM($B$15:$B$19) -> #DIV/0!

Sheet F3
A1: Factor | B1: % | C1: Justificación
A2: F3. PROFESORES | B2: ='Res.'!D14 -> #DIV/0!
D5: NIVEL DE IMPORTANCIA DE LA CARACTERÍSTICA
A6: Característica | D6: P1 | E6: P2 | F6: P3 | G6: P4 | H6: P5 | I6: P6 | J6: P7 | K6: P8 | L6: P9 | M6: P10
A7: 8. Selección, vinculación y permanencia
A8: 9. Estatuto profesoral
A9: 10. Número, dedicación, nivel de formación y experiencia de los profesores
A10: 11. Desarrollo profesoral
A11: 12. Estímulos a la trayectoria profesoral
A12: 13. Producción, pertinencia, utilización e impacto de material docente
A13: 14. Remuneración por méritos
A14: 15. Evaluación de profesores
A17: Característica | B17: NIV | C17: % | D17: Justificación
A18: =A7 -> 8. Selección, vinculación y permanencia | B18: =AVERAGE(D7:M7) -> #DIV/0! | C18: =B18/SUM($B$18:$B$25) -> #DIV/0!
A19: =A8 -> 9. Estatuto profesoral | B19: =AVERAGE(D8:M8) -> #DIV/0! | C19: =B19/SUM($B$18:$B$25) -> #DIV/0!
A20: =A9 -> 10. Número, dedicación, nivel de formación y experiencia de los profesores | B20: =AVERAGE(D9:M9) -> #DIV/0! | C20: =B20/SUM($B$18:$B$25) -> #DIV/0!
A21: =A10 -> 11. Desarrollo profesoral | B21: =AVERAGE(D10:M10) -> #DIV/0! | C21: =B21/SUM($B$18:$B$25) -> #DIV/0!
A22: =A11 -> 12. Estímulos a la trayectoria profesoral | B22: =AVERAGE(D11:M11) -> #DIV/0! | C22: =B22/SUM($B$18:$B$25) -> #DIV/0!
A23: =A12 -> 13. Producción, pertinencia, utilización e impacto de material docente | B23: =AVERAGE(D12:M12) -> #DIV/0! | C23: =B23/SUM($B$18:$B$25) -> #DIV/0!
A24: =A13 -> 14. Remuneración por méritos | B24: =AVERAGE(D13:M13) -> #DIV/0! | C24: =B24/SUM($B$18:$B$25) -> #DIV/0!
A25: =A14 -> 15. Evaluación de profesores | B25: =AVERAGE(D14:M14) -> #DIV/0! | C25: =B25/SUM($B$18:$B$25) -> #DIV/0!

Sheet F4
A1: Factor | B1: % | C1: Justificación
A2: F4. EGRESADOS | B2: ='Res.'!D23 -> #DIV/0!
D5: NIVEL DE IMPORTANCIA DE LA CARACTERÍSTICA
A6: Característica | D6: P1 | E6: P2 | F6: P3 | G6: P4 | H6: P5 | I6: P6 | J6: P7 | K6: P8 | L6: P9 | M6: P10
A7: 16. Seguimiento a los egresados
A8: 17. Impacto de los egresados en el medio social y académico
A11: Característica | B11: NIV | C11: % | D11: Justificación
A12: =A7 -> 16. Seguimiento a los egresados | B12: =AVERAGE(D7:M7) -> #DIV/0! | C12: =B12/SUM($B$12:$B$13) -> #DIV/0!
A13: =A8 -> 17. Impacto de los egresados en el medio social y académico | B13: =AVERAGE(D8:M8) -> #DIV/0! | C13: =B13/SUM($B$12:$B$13) -> #DIV/0!

Sheet F5
A1: Factor | B1: % | C1: Justificación
A2: F5. ASPECTOS ACADÉMICOS Y RESULTADOS DE APRENDIZAJE | B2: ='Res.'!D26 -> #DIV/0!
D5: NIVEL DE IMPORTANCIA DE LA CARACTERÍSTICA
A6: Característica | D6: P1 | E6: P2 | F6: P3 | G6: P4 | H6: P5 | I6: P6 | J6: P7 | K6: P8 | L6: P9 | M6: P10
A7: 18. Integralidad de los aspectos currículares
A8: 19. Flexibilidad de los aspectos currículares
A9: 20. Interdisciplinariedad
A10: 21. Estrategias Pedagógicas
A11: 22. Sistema de evaluación de estudiantes
A12: 23. Resultados de aprendizaje
A13: 24. Competencias
A14: 25. Evaluación y autoregulación del programa académico
A15: 26. Vinculación e interacción social
A18: Característica | B18: NIV | C18: % | D18: Justificación
A19: =A7 -> 18. Integralidad de los aspectos currículares | B19: =AVERAGE(D7:M7) -> #DIV/0! | C19: =B19/SUM($B$19:$B$27) -> #DIV/0!
A20: =A8 -> 19. Flexibilidad de los aspectos currículares | B20: =AVERAGE(D8:M8) -> #DIV/0! | C20: =B20/SUM($B$19:$B$27) -> #DIV/0!
A21: =A9 -> 20. Interdisciplinariedad | B21: =AVERAGE(D9:M9) -> #DIV/0! | C21: =B21/SUM($B$19:$B$27) -> #DIV/0!
A22: =A10 -> 21. Estrategias Pedagógicas | B22: =AVERAGE(D10:M10) -> #DIV/0! | C22: =B22/SUM($B$19:$B$27) -> #DIV/0!
A23: =A11 -> 22. Sistema de evaluación de estudiantes | B23: =AVERAGE(D11:M11) -> #DIV/0! | C23: =B23/SUM($B$19:$B$27) -> #DIV/0!
A24: =A12 -> 23. Resultados de aprendizaje | B24: =AVERAGE(D12:M12) -> #DIV/0! | C24: =B24/SUM($B$19:$B$27) -> #DIV/0!
A25: =A13 -> 24. Competencias | B25: =AVERAGE(D13:M13) -> #DIV/0! | C25: =B25/SUM($B$19:$B$27) -> #DIV/0!
A26: =A14 -> 25. Evaluación y autoregulación del programa académico | B26: =AVERAGE(D14:M14) -> #DIV/0! | C26: =B26/SUM($B$19:$B$27) -> #DIV/0!
A27: =A15 -> 26. Vinculación e interacción social | B27: =AVERAGE(D15:M15) -> #DIV/0! | C27: =B27/SUM($B$19:$B$27) -> #DIV/0!

Sheet F6
A1: Factor | B1: % | C1: Justificación
A2: F6. PERMANENCIA Y GRADUACIÓN | B2: ='Res.'!D36 -> #DIV/0!
D5: NIVEL DE IMPORTANCIA DE LA CARACTERÍSTICA
A6: Característica | D6: P1 | E6: P2 | F6: P3 | G6: P4 | H6: P5 | I6: P6 | J6: P7 | K6: P8 | L6: P9 | M6: P10
A7: 27. Políticas estrategias y estructura para la permanencia y graduación
A8: 28. Caracterización de estudiantes y sistema de alertas tempranas
A9: 29. Ajustes a los aspectos curriculares
A10: 30. Mecanismos de Selección
A13: Característica | B13: NIV | C13: % | D13: Justificación
A14: =A7 -> 27. Políticas estrategias y estructura para la permanencia y graduación | B14: =AVERAGE(D7:M7) -> #DIV/0! | C14: =B14/SUM($B$14:$B$17) -> #DIV/0!
A15: =A8 -> 28. Caracterización de estudiantes y sistema de alertas tempranas | B15: =AVERAGE(D8:M8) -> #DIV/0! | C15: =B15/SUM($B$14:$B$17) -> #DIV/0!
A16: =A9 -> 29. Ajustes a los aspectos curriculares | B16: =AVERAGE(D9:M9) -> #DIV/0! | C16: =B16/SUM($B$14:$B$17) -> #DIV/0!
A17: =A10 -> 30. Mecanismos de Selección | B17: =AVERAGE(D10:M10) -> #DIV/0! | C17: =B17/SUM($B$14:$B$17) -> #DIV/0!

Sheet F7
A1: Factor | B1: % | C1: Justificación
A2: F7. INTERACCIÓN CON EL ENTORNO NACIONAL E INTERNACIONAL | B2: ='Res.'!D41 -> #DIV/0!
D5: NIVEL DE IMPORTANCIA DE LA CARACTERÍSTICA
A6: Característica | D6: P1 | E6: P2 | F6: P3 | G6: P4 | H6: P5 | I6: P6 | J6: P7 | K6: P8 | L6: P9 | M6: P10
A7: 31. Inserción del programa en contextos académicos nacionales e internacionales
A8: 32. Relaciones externas de profesores y estudiantes
A9: 33. Habilidades comunicativas en segunda lengua
A12: Característica | B12: NIV | C12: % | D12: Justificación
A13: =A7 -> 31. Inserción del programa en contextos académicos nacionales e internacionales | B13: =AVERAGE(D7:M7) -> #DIV/0! | C13: =B13/SUM($B$13:$B$15) -> #DIV/0!
A14: =A8 -> 32. Relaciones externas de profesores y estudiantes | B14: =AVERAGE(D8:M8) -> #DIV/0! | C14: =B14/SUM($B$13:$B$15) -> #DIV/0!
A15: =A9 -> 33. Habilidades comunicativas en segunda lengua | B15: =AVERAGE(D9:M9) -> #DIV/0! | C15: =B15/SUM($B$13:$B$15) -> #DIV/0!

Sheet F8
A1: Factor | B1: % | C1: Justificación
A2: F8. APORTES EN LA INVESTIGACIÓN, LA INNOVACIÓN, EL DESARROLLO TECNOLÓGICO Y LA CREACIÓN, ASOCIADOS AL PROGRAMA ACDÉMICO | B2: ='Res.'!D45 -> #DIV/0!
D5: NIVEL DE IMPORTANCIA DE LA CARACTERÍSTICA
A6: Característica | D6: P1 | E6: P2 | F6: P3 | G6: P4 | H6: P5 | I6: P6 | J6: P7 | K6: P8 | L6: P9 | M6: P10
A7: 34. Formación para la investigación, desarrollo tecnológico, la innovación y la creación
A8: 35. Compromiso con la investigación, desarrollo tecnológico, la innovación y la creación
A11: Característica | B11: NIV | C11: % | D11: Justificación
A12: 29. Formación para la investigación, la innovación y la creación artística y cultural | B12: =AVERAGE(D7:M7) -> #DIV/0! | C12: =B12/SUM($B$12:$B$13) -> #DIV/0!
A13: 30. Compromiso con la investigación, la innovación y la creación artística y cultural | B13: =AVERAGE(D8:M8) -> #DIV/0! | C13: =B13/SUM($B$12:$B$13) -> #DIV/0!

Sheet F9
A1: Factor | B1: % | C1: Justificación
A2: F9. BIENESTAR DE LA COMUNIDAD ACADÉMICA DEL PROGRAMA | B2: ='Res.'!D48 -> #DIV/0!
D5: NIVEL DE IMPORTANCIA DE LA CARACTERÍSTICA
A6: Característica | D6: P1 | E6: P2 | F6: P3 | G6: P4 | H6: P5 | I6: P6 | J6: P7 | K6: P8 | L6: P9 | M6: P10
A7: 36. Programas y servicios
A8: 37. Participación y seguimiento
A11: Característica | B11: NIV | C11: % | D11: Justificación
A12: =A7 -> 36. Programas y servicios | B12: =AVERAGE(D7:M7) -> #DIV/0! | C12: =B12/SUM($B$12:$B$13) -> #DIV/0!
A13: =A8 -> 37. Participación y seguimiento | B13: =AVERAGE(D8:M8) -> #DIV/0! | C13: =B13/SUM($B$12:$B$13) -> #DIV/0!

Sheet F10
A1: Factor | B1: % | C1: Justificación
A2: F10. MEDIOS EDUCATIVOS Y AMBIENTES DE APRENDIZAJE | B2: ='Res.'!D51 -> #DIV/0!
D5: NIVEL DE IMPORTANCIA DE LA CARACTERÍSTICA
A6: Característica | D6: P1 | E6: P2 | F6: P3 | G6: P4 | H6: P5 | I6: P6 | J6: P7 | K6: P8 | L6: P9 | M6: P10
A7: 38. Estrategias y recursos de apoyo a profesores
A8: 39. Estrategias y recursos de apoyo a estudiantes
A9: 40. Recursos bibliográficos y de información
A12: Característica | B12: NIV | C12: % | D12: Justificación
A13: =A7 -> 38. Estrategias y recursos de apoyo a profesores | B13: =AVERAGE(D7:M7) -> #DIV/0! | C13: =B13/SUM($B$13:$B$15) -> #DIV/0!
A14: =A8 -> 39. Estrategias y recursos de apoyo a estudiantes | B14: =AVERAGE(D8:M8) -> #DIV/0! | C14: =B14/SUM($B$13:$B$15) -> #DIV/0!
A15: =A9 -> 40. Recursos bibliográficos y de información | B15: =AVERAGE(D9:M9) -> #DIV/0! | C15: =B15/SUM($B$13:$B$15) -> #DIV/0!

Sheet F11
A1: Factor | B1: % | C1: Justificación
A2: F11. ORGANIZACIÓN, ADMINISTRACIÓN Y FINANCIACIÓN DEL PROGRAMA ACADÉMICO | B2: ='Res.'!D55 -> #DIV/0!
D5: NIVEL DE IMPORTANCIA DE LA CARACTERÍSTICA
A6: Característica | D6: P1 | E6: P2 | F6: P3 | G6: P4 | H6: P5 | I6: P6 | J6: P7 | K6: P8 | L6: P9 | M6: P10
A7: 41. Organización y administración
A8: 42. Dirección y gestión
A9: 43. Sistemas de comunicación e información
A10: 44. Estudiantes y capacidad institucional
A11: 45. Financiación del programa académico
A12: 46. Aseguramiento de la alta calidad y la mejora continua
A15: Característica | B15: NIV | C15: % | D15: Justificación
A16: =A7 -> 41. Organización y administración | B16: =AVERAGE(D7:M7) -> #DIV/0! | C16: =B16/SUM($B$16:$B$21) -> #DIV/0!
A17: =A8 -> 42. Dirección y gestión | B17: =AVERAGE(D8:M8) -> #DIV/0! | C17: =B17/SUM($B$16:$B$21) -> #DIV/0!
A18: =A9 -> 43. Sistemas de comunicación e información | B18: =AVERAGE(D9:M9) -> #DIV/0! | C18: =B18/SUM($B$16:$B$21) -> #DIV/0!
A19: =A10 -> 44. Estudiantes y capacidad institucional | B19: =AVERAGE(D10:M10) -> #DIV/0! | C19: =B19/SUM($B$16:$B$21) -> #DIV/0!
A20: =A11 -> 45. Financiación del programa académico | B20: =AVERAGE(D11:M11) -> #DIV/0! | C20: =B20/SUM($B$16:$B$21) -> #DIV/0!
A21: =A12 -> 46. Aseguramiento de la alta calidad y la mejora continua | B21: =AVERAGE(D12:M12) -> #DIV/0! | C21: =B21/SUM($B$16:$B$21) -> #DIV/0!

Sheet F12
A1: Factor | B1: % | C1: Justificación
A2: F12. RECURSOS FÍSICOS Y TECNOLÓGICOS | B2: ='Res.'!D62 -> #DIV/0!
D5: NIVEL DE IMPORTANCIA DE LA CARACTERÍSTICA
A6: Característica | D6: P1 | E6: P2 | F6: P3 | G6: P4 | H6: P5 | I6: P6 | J6: P7 | K6: P8 | L6: P9 | M6: P10
A7: 47. Recursos de infraestructura física y tecnológica
A8: 48. Recursos informáticos y de comunicación
A11: Característica | B11: NIV | C11: % | D11: Justificación
A12: =A7 -> 47. Recursos de infraestructura física y tecnológica | B12: =AVERAGE(D7:M7) -> #DIV/0! | C12: =B12/SUM($B$12:$B$13) -> #DIV/0!
A13: =A8 -> 48. Recursos informáticos y de comunicación | B13: =AVERAGE(D8:M8) -> #DIV/0! | C13: =B13/SUM($B$12:$B$13) -> #DIV/0!

Sheet Res.
B1: PONDERACIÓN
B3: Factor | C3: Peso | D3: Peso Fac. | F3: Característica | G3: Calificación | H3: Peso Car.
B5: ='F1'!A2 -> F1. PROYECTO EDUCATIVO DEL PROGRAMA E IDENTIDAD INSTITUCIONAL | C5: =AVERAGE(G5:G6) -> #DIV/0! | D5: =C5/C65 -> #DIV/0! | F5: ='F1'!A12 -> 1. Proyecto educativo del programa | G5: ='F1'!B12 -> #DIV/0! | H5: ='F1'!C12 -> #DIV/0!
F6: ='F1'!A13 -> 2. Relevancia académica y pertinencia social del programa académico | G6: ='F1'!B13 -> #DIV/0! | H6: ='F1'!C13 -> #DIV/0!
B8: ='F2'!A2 -> F2. ESTUDIANTES | C8: =AVERAGE(G8:G12) -> #DIV/0! | D8: =C8/C65 -> #DIV/0! | F8: ='F2'!A15 -> 3. Participación en actividades de formación integral | G8: ='F2'!B15 -> #DIV/0! | H8: ='F2'!C15 -> #DIV/0!
F9: ='F2'!A16 -> 4. Orientación y seguimiento a estudiantes | G9: ='F2'!B16 -> #DIV/0! | H9: ='F2'!C16 -> #DIV/0!
F10: ='F2'!A17 -> 5. Capacidad de trabajo autónomo | G10: ='F2'!B17 -> #DIV/0! | H10: ='F2'!C17 -> #DIV/0!
F11: ='F2'!A18 -> 6. Reglamento estudiantil y política académica | G11: ='F2'!B18 -> #DIV/0! | H11: ='F2'!C18 -> #DIV/0!
F12: ='F2'!A19 -> 7. Estímulos y apoyos para estudiantes | G12: ='F2'!B19 -> #DIV/0! | H12: ='F2'!C19 -> #DIV/0!
B14: ='F3'!A2 -> F3. PROFESORES | C14: =AVERAGE(G14:G21) -> #DIV/0! | D14: =C14/C65 -> #DIV/0! | F14: ='F3'!A18 -> 8. Selección, vinculación y permanencia | G14: ='F3'!B18 -> #DIV/0! | H14: ='F3'!C18 -> #DIV/0!
F15: ='F3'!A19 -> 9. Estatuto profesoral | G15: ='F3'!B19 -> #DIV/0! | H15: ='F3'!C19 -> #DIV/0!
F16: ='F3'!A20 -> 10. Número, dedicación, nivel de formación y experiencia de los profesores | G16: ='F3'!B20 -> #DIV/0! | H16: ='F3'!C20 -> #DIV/0!
F17: ='F3'!A21 -> 11. Desarrollo profesoral | G17: ='F3'!B21 -> #DIV/0! | H17: ='F3'!C21 -> #DIV/0!
F18: ='F3'!A22 -> 12. Estímulos a la trayectoria profesoral | G18: ='F3'!B22 -> #DIV/0! | H18: ='F3'!C22 -> #DIV/0!
F19: ='F3'!A23 -> 13. Producción, pertinencia, utilización e impacto de material docente | G19: ='F3'!B23 -> #DIV/0! | H19: ='F3'!C23 -> #DIV/0!
F20: ='F3'!A24 -> 14. Remuneración por méritos | G20: ='F3'!B24 -> #DIV/0! | H20: ='F3'!C24 -> #DIV/0!
F21: ='F3'!A25 -> 15. Evaluación de profesores | G21: ='F3'!B25 -> #DIV/0! | H21: ='F3'!C25 -> #DIV/0!
B23: ='F4'!A2 -> F4. EGRESADOS | C23: =AVERAGE(G23:G24) -> #DIV/0! | D23: =C23/C65 -> #DIV/0! | F23: ='F4'!A12 -> 16. Seguimiento a los egresados | G23: ='F4'!B12 -> #DIV/0! | H23: ='F4'!C12 -> #DIV/0!
F24: ='F4'!A13 -> 17. Impacto de los egresados en el medio social y académico | G24: ='F4'!B13 -> #DIV/0! | H24: ='F4'!C13 -> #DIV/0!
B26: ='F5'!A2 -> F5. ASPECTOS ACADÉMICOS Y RESULTADOS DE APRENDIZAJE | C26: =AVERAGE(G26:G34) -> #DIV/0! | D26: =C26/C65 -> #DIV/0! | F26: ='F5'!A19 -> 18. Integralidad de los aspectos currículares | G26: ='F5'!B19 -> #DIV/0! | H26: ='F5'!C19 -> #DIV/0!
F27: ='F5'!A20 -> 19. Flexibilidad de los aspectos currículares | G27: ='F5'!B20 -> #DIV/0! | H27: ='F5'!C20 -> #DIV/0!
F28: ='F5'!A21 -> 20. Interdisciplinariedad | G28: ='F5'!B21 -> #DIV/0! | H28: ='F5'!C21 -> #DIV/0!
F29: ='F5'!A22 -> 21. Estrategias Pedagógicas | G29: ='F5'!B22 -> #DIV/0! | H29: ='F5'!C22 -> #DIV/0!
F30: ='F5'!A23 -> 22. Sistema de evaluación de estudiantes | G30: ='F5'!B23 -> #DIV/0! | H30: ='F5'!C23 -> #DIV/0!
F31: ='F5'!A24 -> 23. Resultados de aprendizaje | G31: ='F5'!B24 -> #DIV/0! | H31: ='F5'!C24 -> #DIV/0!
F32: ='F5'!A25 -> 24. Competencias | G32: ='F5'!B25 -> #DIV/0! | H32: ='F5'!C25 -> #DIV/0!
F33: ='F5'!A26 -> 25. Evaluación y autoregulación del programa académico | G33: ='F5'!B26 -> #DIV/0! | H33: ='F5'!C26 -> #DIV/0!
F34: ='F5'!A27 -> 26. Vinculación e interacción social | G34: ='F5'!B27 -> #DIV/0! | H34: ='F5'!C27 -> #DIV/0!
B36: ='F6'!A2 -> F6. PERMANENCIA Y GRADUACIÓN | C36: =AVERAGE(G36:G39) -> #DIV/0! | D36: =C36/C65 -> #DIV/0! | F36: ='F6'!A14 -> 27. Políticas estrategias y estructura para la permanencia y graduación | G36: ='F6'!B14 -> #DIV/0! | H36: ='F6'!C14 -> #DIV/0!
F37: ='F6'!A15 -> 28. Caracterización de estudiantes y sistema de alertas tempranas | G37: ='F6'!B15 -> #DIV/0! | H37: ='F6'!C15 -> #DIV/0!
F38: ='F6'!A16 -> 29. Ajustes a los aspectos curriculares | G38: ='F6'!B16 -> #DIV/0! | H38: ='F6'!C16 -> #DIV/0!
F39: ='F6'!A17 -> 30. Mecanismos de Selección | G39: ='F6'!B17 -> #DIV/0! | H39: ='F6'!C17 -> #DIV/0!
B41: ='F7'!A2 -> F7. INTERACCIÓN CON EL ENTORNO NACIONAL E INTERNACIONAL | C41: =AVERAGE(G41:G43) -> #DIV/0! | D41: =C41/C65 -> #DIV/0! | F41: ='F7'!A13 -> 31. Inserción del programa en contextos académicos nacionales e internacionales | G41: ='F7'!B13 -> #DIV/0! | H41: ='F7'!C13 -> #DIV/0!
F42: ='F7'!A14 -> 32. Relaciones externas de profesores y estudiantes | G42: ='F7'!B14 -> #DIV/0! | H42: ='F7'!C14 -> #DIV/0!
F43: ='F7'!A15 -> 33. Habilidades comunicativas en segunda lengua | G43: ='F7'!B15 -> #DIV/0! | H43: ='F7'!C15 -> #DIV/0!
B45: ='F8'!A2 -> F8. APORTES EN LA INVESTIGACIÓN, LA INNOVACIÓN, EL DESARROLLO TECNOLÓGICO Y LA CREACIÓN, ASOCIADOS AL PROGRAMA ACDÉMICO | C45: =AVERAGE(G45:G46) -> #DIV/0! | D45: =C45/C65 -> #DIV/0! | F45: ='F8'!A12 -> 29. Formación para la investigación, la innovación y la creación artística y cultural | G45: ='F11'!B16 -> #DIV/0! | H45: ='F11'!C16 -> #DIV/0!
F46: ='F8'!A13 -> 30. Compromiso con la investigación, la innovación y la creación artística y cultural | G46: ='F11'!B17 -> #DIV/0! | H46: ='F11'!C17 -> #DIV/0!
B48: ='F9'!A2 -> F9. BIENESTAR DE LA COMUNIDAD ACADÉMICA DEL PROGRAMA | C48: =AVERAGE(G48:G49) -> #DIV/0! | D48: =C48/C65 -> #DIV/0! | F48: ='F9'!A12 -> 36. Programas y servicios | G48: ='F9'!B12 -> #DIV/0! | H48: ='F9'!C12 -> #DIV/0!
F49: ='F9'!A13 -> 37. Participación y seguimiento | G49: ='F9'!B13 -> #DIV/0! | H49: ='F9'!C13 -> #DIV/0!
B51: ='F10'!A2 -> F10. MEDIOS EDUCATIVOS Y AMBIENTES DE APRENDIZAJE | C51: =AVERAGE(G51:G53) -> #DIV/0! | D51: =C51/C65 -> #DIV/0! | F51: ='F10'!A13 -> 38. Estrategias y recursos de apoyo a profesores | G51: ='F10'!B13 -> #DIV/0! | H51: ='F10'!C13 -> #DIV/0!
...

Sheet D.Car.
B2: Característica | D2: Elija
B4: NOMBRE | D4: DESCRIPCIÓN | M4: ASPECTOS A EVALUAR
B6: =IFERROR(VLOOKUP(D2,Hoja2!A1:D49,2,0)," ") | D6: =IFERROR(VLOOKUP(D2,Hoja2!A1:D49,3,0)," ") | M6: =IFERROR(VLOOKUP(D2,Hoja2!A1:D49,4,0)," ")

Sheet Hoja1
A1: 0 | B1: 1 | C1: 0 | D1: 1 | E1: Elija | F1: Elija | G1: DD | H1: MM | I1: AAAA | J1: Elija | K1: Elija
A2: 1 | B2: 2 | C2: 1 | D2: 1.1 | E2: 1 | F2: Administración de Empresas Agropecuarias | G2: 1 | H2: Enero | I2: 2017 | J2: I | K2: Popayán
A3: 2 | B3: 3 | C3: 1.1 | D3: 1.2 | E3: 2 | F3: Administración de Empresas | G3: 2 | H3: Febrero | I3: 2018 | J3: II | K3: Santander de Quilichao
A4: 3 | B4: 4 | C4: 1.2 | D4: 1.3 | E4: 3 | F4: Arquitectura | G4: 3 | H4: Marzo | I4: 2019
A5: 4 | B5: 5 | C5: 1.3 | D5: 1.4 | E5: 4 | F5: Comunicación Social | G5: 4 | H5: Abril | I5: 2020
A6: 5 | B6: 6 | C6: 1.4 | D6: 1.5 | E6: 5 | F6: Contaduría Pública | G6: 5 | H6: Mayo | I6: 2021
A7: 6 | B7: 7 | C7: 1.5 | D7: 1.6 | E7: 6 | F7: Derecho | G7: 6 | H7: Junio | I7: 2022
A8: 7 | B8: 8 | C8: 1.6 | D8: 1.7 | E8: 7 | F8: Ecología | G8: 7 | H8: Julio | I8: 2023
A9: 8 | B9: 9 | C9: 1.7 | D9: 1.8 | E9: 8 | F9: Ingeniería Agroecológica | G9: 8 | H9: Agosto | I9: 2024
A10: 9 | B10: 10 | C10: 1.8 | D10: 1.9 | E10: 9 | F10: Ingeniería de Sistemas | G10: 9 | H10: Septiembre | I10: 2025
A11: 10 | C11: 1.9 | D11: 2 | E11: 10 | F11: Ingeniería Industrial | G11: 10 | H11: Octubre | I11: 2026
C12: 2 | D12: 2.1 | E12: 11 | F12: Licenciatura en Educación Artística y Cultural | G12: 11 | H12: Noviembre | I12: 2027
C13: 2.1 | D13: 2.2 | E13: 12 | F13: Psicología | G13: 12 | H13: Diciembre | I13: 2028
C14: 2.2 | D14: 2.3 | E14: 13 | F14: Trabajo Social | G14: 13
C15: 2.3 | D15: 2.4 | E15: 14 | F15: Comunicación Social - Virtual | G15: 14
C16: 2.4 | D16: 2.5 | E16: 15 | F16: Esp. Data Analytics para Marketing Digital | G16: 15
C17: 2.5 | D17: 2.6 | E17: 16 | F17: Esp. Derecho Procesal | G17: 16
C18: 2.6 | D18: 2.7 | E18: 17 | F18: Esp. Comunicación para el desarrollo territorial | G18: 17
C19: 2.7 | D19: 2.8 | E19: 18 | F19: Esp. en Gerencia de Agronegocios Sostenibles | G19: 18
C20: 2.8 | D20: 2.9 | E20: 19 | F20: Esp. Derecho Constitucional | G20: 19
C21: 2.9 | D21: 3 | E21: 20 | F21: Esp. en Gerencia Social | G21: 20
C22: 3 | D22: 3.1 | E22: 21 | F22: Esp. Gerencia del Talento Humano | G22: 21
C23: 3.1 | D23: 3.2 | E23: 22 | G23: 22
C24: 3.2 | D24: 3.3 | E24: 23 | G24: 23
C25: 3.3 | D25: 3.4 | E25: 24 | G25: 24
C26: 3.4 | D26: 3.5 | E26: 25 | G26: 25
C27: 3.5 | D27: 3.6 | E27: 26 | G27: 26
C28: 3.6 | D28: 3.7 | E28: 27 | G28: 27
C29: 3.7 | D29: 3.8 | E29: 28 | G29: 28
C30: 3.8 | D30: 3.9 | E30: 29 | G30: 29
C31: 3.9 | D31: 4 | E31: 30 | G31: 30
C32: 4 | D32: 4.1 | E32: 31 | G32: 31
C33: 4.1 | D33: 4.2 | E33: 32
C34: 4.2 | D34: 4.3 | E34: 33
C35: 4.3 | D35: 4.4 | E35: 34
C36: 4.4 | D36: 4.5 | E36: 35
C37: 4.5 | D37: 4.6 | E37: 36
C38: 4.6 | D38: 4.7 | E38: 37
C39: 4.7 | D39: 4.8 | E39: 38
C40: 4.8 | D40: 4.9 | E40: 39
...

Sheet Hoja2
A1: # | B1: Característica | C1: Descripción | D1: Aspectos a Evaluar
A2: 1 | B2: 1. PROYECTO EDUCATIVO DEL PROGRAMA | C2: "Para el programa académico se ha definido un proyecto educativo que es coherente con la misión y la identidad institucional, así como con los campos de acción de las profesiones o disciplinas, y que orienta el desarrollo de labores formativas, académicas, docentes, científicas y culturales. Según el nivel de formación y modalidad, el proyecto educativo del programa define claramente los objetivos de formación y los resultados de aprendizaje contemplados en los aspectos curriculares, las políticas y estrategias de planeación y evaluación curricular, y la propuesta de mejoramiento continuo en el marco del sistema interno de aseguramiento de la calidad. Los documentos en los cuales se desarrolla el proyecto educativo del programa o lo que haga sus veces deben ser de conocimiento público”. En el caso de los programas académicos del área de la salud, además, se tendrá en cuenta la relación y coherencia que debe existir entre la institución de educación superior y los escenarios de práctica donde se realizan las prácticas formativas. | D2: 1) Demostrar coherencia del Proyecto Educativo del Programa (PEP) o el que haga sus veces, con los lineamientos y políticas institucionales, así como en la definición de objetivos de formación y resultados de aprendizaje y la manera cómo el PEP ha ido mejorando, como resultado de los procesos de aseguramiento de la calidad, la consolidación de la identidad institucional y la relación que mantiene con la comunidad y sus grupos de interés.
A3: 2 | B3: 2. RELEVANCIA ACADÉMICA Y PERTINENCIA SOCIAL DEL PROGRAMA ACADÉMICO | C3: De acuerdo con el nivel de formación en el que se oferta, el programa académico responde a necesidades locales, regionales, nacionales o internacionales previamente definidas y sustentadas, independientemente de la(s) modalidad(es) en la(s) que se oferta”. | D3: 1) Análisis sobre las tendencias, necesidades y líneas de desarrollo de la disciplina o profesión, en el contexto regional, nacional e internacional. 2) Estudio de la pertinencia social del programa desde la perspectiva de la comunidad académica y de sus grupos de interés con el fin de identificar necesidades y requerimientos del entorno local, regional o nacional en términos productivos y de competitividad, tecnológicos, culturales, científicos y de talento humano. 3) Evidencia de las transformaciones sociales pertinentes para el contexto y el territorio en el que se ofrece el programa académico, y del entorno tanto nacional como internacional.
A4: 3 | B4: 3.PARTICIPACIÓN EN ACTIVIDADES DE FORMACIÓN INTEGRAL | C4: Se demuestra la participación de los estudiantes en actividades de investigación, desarrollo tecnológico, innovación, creación artística y cultural, y deportivas, así como en proyectos de desarrollo empresarial, relacionamiento nacional e internacional y en otras acciones de formación complementaria, en un ambiente propicio para la formación integral, de acuerdo con el nivel deformación y la modalidad del programa académico | D4: 1) Apreciación de los estudiantes en relación con su participación en las actividades de investigación, desarrollo tecnológico, creación artística, culturales, deportivas y de extensión, que contribuyen a su formación integral, junto con las acciones emprendidas como resultado de dichas apreciaciones. 2) Resultados del análisis de la participación y principales logros de los estudiantes en actividades de investigación, desarrollo tecnológico, innovación, creación artística, culturales y deportivas y de extensión. 3) Resultados del análisis de la participación y principales logros de los estudiantes en proyectos de desarrollo empresarial, relacionamiento nacional e internacional. 4) Resultados del análisis de la participación y principales logros de los estudiantes en otras acciones de formación complementaria, que promuevan la comprensión de la realidad social, la empatía, la ética, habilidades blandas, así como el relacionamiento con otras culturas y lenguas, de acuerdo con el nivel de formación y la modalidad del programa. 6) Apreciación de los estudiantes y profesores sobre las actividades de formación integral.
A5: 4 | B5: 4. ORIENTACIÓN Y SEGUIMIENTO A ESTUDIANTES | C5: El programa académico demuestra procesos de orientación y seguimiento académico a sus estudiantes, con impacto evidente en su formación de acuerdo con la caracterización realizada en el momento del ingreso | D5: 1) Evidencia de los efectos en la formación de los estudiantes, a partir de los procesos de orientación y seguimiento de los estudiantes, teniendo como referencia sus características de ingreso.
A6: 5 | B6: 5. CAPACIDAD DE TRABAJO AUTÓNOMO | C6: Los estudiantes evidencian habilidades y destrezas para el trabajo autónomo que el programa académico reconoce, evalúa, fomenta y desarrolla en el proceso de aprendizaje. La Institución genera los medios, espacios y ambientes necesarios para promover el trabajo autónomo; promueve estrategias de seguimiento y desarrolla actividades de mejoramiento de estas | D6: 1) Evidencia de los resultados de las estrategias de seguimiento y evaluación de los resultados de aprendizaje en el desarrollo de capacidades para el del trabajo autónomo del estudiante.
A7: 6 | B7: 6. REGLAMENTO ESTUDIANTIL Y POLÍTICA ACADÉMICA | C7: La institución demuestra la divulgación, aplicación y actualización de los reglamentos estudiantiles y las políticas académicas aprobados, en los que se definen, entre otros aspectos, los deberes y derechos, el régimen disciplinario, la participación de la comunidad académica en la toma de decisiones y las condiciones y exigencias académicas de permanencia y graduación, de acuerdo con el nivel de formación y la modalidad del programa académico | D7: 1) Apreciación de estudiantes y profesores del programa sobre la pertinencia, vigencia y aplicación del reglamento estudiantil y las políticas académicas y, sobre las estrategias de divulgación de dicha reglamentación, junto con las acciones emprendidas como resultado de dichas apreciaciones. 2) Evidencia de los mecanismos para la aplicación, actualización y divulgación del reglamento estudiantil.
A8: 7 | B8: 7. ESTÍMULOS Y APOYOS PARA ESTUDIANTES | C8: La institución demuestra la aplicación de un estatuto que promueve la trayectoria profesoral, la inclusión, el reconocimiento de los méritos y el ascenso en el escalafón, de acuerdo con el nivel de formación y modalidad del programa académico | D8: 1) Evidencia de los beneficios generados por el otorgamiento de estímulos académicos y apoyos socioeconómicos a los estudiantes. 2) Apreciación de los estudiantes del programa frente a la aplicación de los estímulos académicos y apoyos socioeconómicos, y el cumplimiento institucional de estas medidas, junto con las acciones emprendidas como resultado de dichas apreciaciones.
A9: 8 | B9: 8. SELECCIÓN, VINCULACIÓN Y PERMANENCIA | C9: La institución demuestra la aplicación transparente y eficaz de los criterios establecidos para la selección, vinculación y permanencia de profesores, de acuerdo con el nivel de formación y modalidad del programa académico | D9: 1) Evidencia de la aplicación de los procesos de selección, vinculación y permanencia de los profesores, en coherencia con el nivel de formación, modalidad del programa académico y lugar de desarrollo. 2) Apreciación de los profesores sobre la aplicación, pertinencia y vigencia de las políticas, normas y criterios académicos establecidos por la institución para su selección, vinculación y permanencia, junto con las acciones emprendidas como resultado de dichas apreciaciones.
A10: 9 | B10: 9. ESTATUTO PROFESORAL | C10: La institución demuestra la aplicación de un estatuto que promueve la trayectoria profesoral, la inclusión, el reconocimiento de los méritos y el ascenso en el escalafón, de acuerdo con el nivel de formación y modalidad del programa académico. | D10: 1) Evidencia que demuestren los resultados de la aplicación del estatuto profesoral, o el que haga sus veces, sobre la trayectoria profesoral, la inclusión, el reconocimiento de méritos y el ascenso en el escalafón, de acuerdo con el nivel de formación y la modalidad del programa. 2) Resultados en el mejoramiento de la calidad del programa, a partir de la aplicación de un estatuto que promueve la trayectoria profesoral, la inclusión, el reconocimiento de los méritos y el ascenso en el escalafón. 3) Apreciación de los profesores sobre la aplicación y pertinencia del estatuto profesoral y de las políticas que establecen distinciones, estímulos que promueven la trayectoria profesoral, junto con las acciones emprendidas como resultado de dichas apreciaciones.
A11: 10 | B11: 10. . NÚMERO, DEDICACIÓN, NIVEL DE FORMACIÓN Y EXPERIENCIA | C11: "El programa académico cuenta con un número de profesores con la dedicación, nivel de formación y experiencia requeridos para el desarrollo de las labores formativas, académicas, docentes, científicas, culturales y de extensión, con el fin de atenderla totalidad de los estudiantes matriculados, de acuerdo con el nivel de formación y modalidad del programa académico, directamente o a través de la facultad, escuela o departamento respectivo. | D11: 1) Evidencia de la coherencia entre el número, dedicación, nivel de formación y experiencia de los profesores de tiempo completo, con el número de estudiantes, nivel de formación y modalidad del programa académico. 2) Evidencia de la existencia de un núcleo básico de profesores de tiempo completo, preferiblemente con contratación a término indefinido, y su relación con la formación de la comunidad académica del programa y el cumplimiento con alta calidad de las funciones esenciales del programa. 3) Evidencia de la vinculación de una planta profesoral pertinente con el área disciplinar del programa con título de especialistas, magísteres y/o doctores con experiencia o formación pedagógica y profesional certificada, que garantice el logro de los resultados de aprendizaje de los estudiantes y el cumplimiento de las funciones asignadas en condiciones de calidad, atendiendo a estándares internacionales, en coherencia con el nivel de formación y modalidad del programa.
A12: 11 | B12: 11. DESARROLLO PROFESORAL | C12: En relación con las políticas de la institución, las necesidades y los objetivos de formación del programa académico, se demuestran los resultados del desarrollo profesoral, de acuerdo con el nivel de formación y la modalidad del programa académico. El desarrollo profesoral atiende a la diversidad de los estudiantes, a las modalidades de la docencia y a los requerimientos de internacionalización y de inter y multiculturalidad de profesores y estudiantes | D12: 1) Análisis de los resultados de la aplicación de políticas y estrategias institucionales en materia de desarrollo integral del profesorado, que incluya la capacitación y la actualización en los aspectos académicos, profesionales y pedagógicos relacionados con la naturaleza, nivel de formación y modalidad del programa. 2) Evidencia de cómo el desarrollo profesoral atiende a la diversidad de los estudiantes, a las modalidades de la docencia y a los requerimientos de internacionalización y de inter y multiculturalidad de profesores y estudiantes. 3) Apreciación de directivos y profesores del programa sobre los resultados que han tenido las acciones orientadas al desarrollo integral de los profesores, en el mejoramiento de las competencias pedagógicas, científicas y sociales para el sostenimiento de las funciones misionales, junto con las acciones emprendidas como resultado de dichas apreciaciones.
A13: 12 | B13: 12. ESTÍMULOS A LA TRAYECTORIA PROFESORAL | C13: La institución y el programa académico demuestran la divulgación, aplicación y actualización de criterios académicos en un régimen de estímulos que reconoce y favorece el ejercicio calificado de las labores formativas, académicas, docentes, científicas y culturales | D13: 1) Evidencia de los efectos generados en el desempeño de las labores de docencia, investigación y extensión con el otorgamiento de estímulos a los profesores. 2) Apreciación de directivos y profesores del programa, sobre el efecto que ha tenido el régimen de estímulos al profesorado en el ejercicio cualificado de la docencia, la investigación, la innovación, la creación artística y cultural, la extensión o proyección social, en los aportes al desarrollo técnico y tecnológico y la cooperación internacional, junto con las acciones emprendidas como resultado de dichas apreciaciones.
... A49: 48 | B49: 48 .RECURSOS INFORMÁTICOS Y DE COMUNICACIÓN | C49: El programa académico deberá demostrar que cuenta con las plataformas informáticas y los equipos computacionales y de telecomunicaciones (hardware y software licenciado) actualizados y adecuados para el diseño y la producción de contenidos, la implementación de estrategias pedagógicas y el continuo apoyo y seguimiento de las actividades académicas de los estudiantes, acordes con el nivel de formación y la modalidad | D49: 1) Evidencia de la coherencia entre los recursos informáticos y de comunicación con las necesidades para el desarrollo y cumplimiento de las labores formativas, académicas, docentes, científicas, culturales del programa en el lugar de desarrollo y en los escenarios de práctica. 2) Apreciación de directivos, profesores y estudiantes del programa sobre la pertinencia, correspondencia y suficiencia de los recursos informáticos y de comunicación con que cuenta el programa.
