Workbook
Name caracteristicas: ' Hoja2'!$A$2:$A$41
Name CARGO_DEL_RESPONSABLE: 'Año 2'!#REF!
Name CARGO_DEL_RESPONSABLE: 'Año 1'!#REF!
Name CARGO_DEL_RESPONSABLE: 'Año 1'!#REF!
Name CARGO_DEL_RESPONSABLE: 'Año 1'!#REF!
Name Condición: [1]Hoja1!$B$3:$B$18
Name Cumplimiento: 'Resultado año 1'!$M$7
Name DESCRIPCIÓN__DE_LA_ACTIVIDAD: 'Año 2'!#REF!
Name DESCRIPCIÓN__DE_LA_ACTIVIDAD: 'Año 1'!#REF!
Name Escala_de_Ejecución: 'Resultado año 1'!$M$7
Name Factor1: 'Lista Antigua'!$E$4:$E$6
Name Factor10: 'Lista Antigua'!$W$4:$W$6
Name Factor2: 'Lista Antigua'!$G$4:$G$7
Name Factor3: 'Lista Antigua'!$I$4:$I$11
Name Factor4: 'Lista Antigua'!$K$4:$K$14
Name Factor5: 'Lista Antigua'!$M$4:$M$5
Name Factor6: 'Lista Antigua'!$O$4:$O$5
Name Factor7: 'Lista Antigua'!$Q$4:$Q$5
Name Factor8: 'Lista Antigua'!$S$4:$S$7
Name Factor9: 'Lista Antigua'!$U$4:$U$5
Name Factores: 'Lista Antigua'!$B$3:$B$13
Name FECHA__INICIO_–_FIN: 'Año 2'!#REF!
Name FECHA__INICIO_–_FIN: 'Año 1'!#REF!
Name FECHA__INICIO_–_FIN: 'Año 1'!#REF!
Name FECHA__INICIO_–_FIN: 'Año 1'!#REF!
Name MEDIO_DE_VERIFICACIÓN: 'Año 2'!$L$6
Name MEDIO_DE_VERIFICACIÓN: 'Año 1'!$L$6
Name META: 'Año 2'!$R$6
Name META: 'Año 1'!$R$6
Name NIVEL_DE_CUMPLIMENTO: 'Año 2'!$K$5
Name NIVEL_DE_CUMPLIMENTO: 'Año 1'!$K$5
Name NIVEL_DE_CUMPLIMIENTO_DE_LA_META: 'Año 2'!$S$6
Name NIVEL_DE_CUMPLIMIENTO_DE_LA_META: 'Año 1'!$S$6
Name numero1: ' Hoja2'!$D$4:$D$9
Name numero10: ' Hoja2'!$V$4:$V$11
Name numero11: ' Hoja2'!$X$4:$X$9
Name numero12: ' Hoja2'!$Z$4:$Z$6
Name numero13: ' Hoja2'!$AB$4:$AB$7
Name numero14: ' Hoja2'!$AD$4:$AD$6
Name numero15: ' Hoja2'!$AF$4:$AF$8
Name numero16: ' Hoja2'!$AH$4:$AH$13
Name numero17: ' Hoja2'!$AJ$4:$AJ$13
Name numero18: ' Hoja2'!$AL$4:$AL$6
Name numero19: ' Hoja2'!$AN$4:$AN$17
Name numero2: ' Hoja2'!$F$4:$F$7
Name numero20: ' Hoja2'!$AP$4:$AP$9
Name numero21: ' Hoja2'!$AR$4:$AR$8
Name numero22: ' Hoja2'!$AT$4:$AT$7
Name numero23: ' Hoja2'!$AV$4:$AV$11
Name numero24: ' Hoja2'!$AX$4:$AX$8
Name numero25: ' Hoja2'!$AZ$4:$AZ$9
Name numero26: ' Hoja2'!$BB$4:$BB$8
Name numero27: ' Hoja2'!$BD$4:$BD$12
Name numero28: ' Hoja2'!$BF$4:$BF$11
Name numero29: ' Hoja2'!$BH$4:$BH$14
Name numero3: ' Hoja2'!$H$4:$H$12
Name numero30: ' Hoja2'!$BJ$4:$BJ$10
Name numero31: ' Hoja2'!$BL$4:$BL$11
Name numero32: ' Hoja2'!$BN$4:$BN$6
Name numero33: ' Hoja2'!$BP$4:$BP$10

Sheet Velocimetro
B3: VELOCIMETRO AÑO 1
B4: punto de equilibrio | D4: 1
B5: promedio total | D5: ='Resultado año 1'!F5 -> #DIV/0!
B6: por cumplir | D6: =$D$4-D5 -> #DIV/0!
B8: VELOCIMETRO AÑO 2
B9: punto de equilibrio | D9: 1
B10: promedio total | D10: ='Resultado año 2'!F5 -> #REF!
B11: por cumplir | D11: =$D$4-D10 -> #REF!
B13: CONSOLIDADO FINAL
B14: punto de equilibrio | D14: 1
B15: promedio total | D15: ='Consolidado Final'!F5 -> #REF!
B16: por cumplir | D16: =$D$4-D15 -> #REF!

Sheet Termometro
A1: Ejemplo 1 | C1: http://www.exceldashboardwidgets.com/index-es.html
A2: Extraido y adaptado de:
A3: Entrada de datos | D3: TERMOMETRO AÑO 1
A4: Nombre de la serie: | C4: misdatos
B5: Valor Actual: | C5: ='Resultado año 1'!$I$5 -> #DIV/0!
B6: Mínimo: | C6: 0
B7: Máximo: | C7: 1
A9: Entrada de datos | D9: TERMOMETRO AÑO 2
A10: Nombre de la serie: | C10: misdatos
B11: Valor Actual: | C11: ='Resultado año 2'!I5 -> #REF!
B12: Mínimo: | C12: 0
B13: Máximo: | C13: 1
A15: Entrada de datos | D15: CONSOLIDADO FINAL
A16: Nombre de la serie: | C16: misdatos
B17: Valor Actual: | C17: ='Consolidado Final'!I5 -> #REF!
B18: Mínimo: | C18: 0
B19: Máximo: | C19: 1
A33: Datos de calculo
A35: E) Thermometer Widget
B37: Value | D37: x | E37: y
A38: Min | B38: =C6 -> 0 | D38: 0 | E38: =B40 -> #DIV/0! | F38: =E38 -> #DIV/0!
A39: Max | B39: =C7 -> 1
A40: Actual | B40: =C5 -> #DIV/0! | E40: =IF(E38>0.5,CHAR(241),CHAR(242)) -> #DIV/0!
A41: Scale1 | B41: =(B39-B38)/5 -> 0.2
A42: Scale2 | B42: =(B39-B38)*2/5 -> 0.4
A43: Scale3 | B43: =(B39-B38)*3/5 -> 0.6
A44: Scale4 | B44: =(B39-B38)*4/5 -> 0.8

Sheet INICIO
B15: Programa:
B16: Nombre Director(a):
B17: Sede:
B19: Fecha de elaboración: | D19: DD | E19: MM | F19: AAAA | H19: Periodo: | I19: Elija

Sheet Hoja1 (2)
A1: 1 | B1: 1 | C1: Elija | D1: Elija | E1: DD | F1: MM | G1: AAAA | H1: Elija | I1: Elija
A2: 2 | B2: 1.1 | C2: 1 | D2: Administración de Empresas Agropecuarias | E2: 1 | F2: Enero | G2: 2017 | H2: I | I2: Popayán
A3: 3 | B3: 1.2 | C3: 2 | D3: Administración de Empresas | E3: 2 | F3: Febrero | G3: 2018 | H3: II | I3: Santander de Quilichao
A4: 4 | B4: 1.3 | C4: 3 | D4: Arquitectura | E4: 3 | F4: Marzo | G4: 2019
A5: 5 | B5: 1.4 | C5: 4 | D5: Comunicación Social | E5: 4 | F5: Abril | G5: 2020
A6: 6 | B6: 1.5 | C6: 5 | D6: Contaduría Pública | E6: 5 | F6: Mayo | G6: 2021
A7: 7 | B7: 1.6 | C7: 6 | D7: Derecho | E7: 6 | F7: Junio | G7: 2022
A8: 8 | B8: 1.7 | C8: 7 | D8: Ecología | E8: 7 | F8: Julio | G8: 2023
A9: 9 | B9: 1.8 | C9: 8 | D9: Economía | E9: 8 | F9: Agosto | G9: 2024
A10: 10 | B10: 1.9 | C10: 9 | D10: Ingeniería de Sistemas | E10: 9 | F10: Septiembre | G10: 2025
B11: 2 | C11: 10 | D11: Ingeniería Industrial | E11: 10 | F11: Octubre | G11: 2026
B12: 2.1 | C12: 11 | D12: Licenciatura en Educación Básica y Cultural | E12: 11 | F12: Noviembre | G12: 2027
B13: 2.2 | C13: 12 | D13: Psicología | E13: 12 | F13: Diciembre | G13: 2028
B14: 2.3 | C14: 13 | D14: Trabajo Social | E14: 13
B15: 2.4 | C15: 14 | D15: Administración de Empresas Agropecuarias - Virtual | E15: 14
B16: 2.5 | C16: 15 | D16: Administración de Empresas - Virtual | E16: 15
B17: 2.6 | C17: 16 | D17: Comunicación Social - Virtual | E17: 16
B18: 2.7 | C18: 17 | E18: 17
B19: 2.8 | C19: 18 | E19: 18
B20: 2.9 | C20: 19 | E20: 19
B21: 3 | C21: 20 | E21: 20
B22: 3.1 | C22: 21 | E22: 21
B23: 3.2 | C23: 22 | E23: 22
B24: 3.3 | C24: 23 | E24: 23
B25: 3.4 | C25: 24 | E25: 24
B26: 3.5 | C26: 25 | E26: 25
B27: 3.6 | C27: 26 | E27: 26
B28: 3.7 | C28: 27 | E28: 27
B29: 3.8 | C29: 28 | E29: 28
... B32: 4.1 | C32: 31 | E32: 31
B33: 4.2 | C33: 32
B34: 4.3 | C34: 33
B35: 4.4 | C35: 34
B36: 4.5 | C36: 35
B37: 4.6 | C37: 36
B38: 4.7 | C38: 37
B39: 4.8 | C39: 38
B40: 4.9 | C40: 39
B41: 5 | C41: 40

Sheet Año 1
B1: PLAN MEJORAMIENTO PROCESO DE AUTOEVALUACIÓN-PROGRAMAS ACADEMICOS 2023
A2: PROGRAMA:
A3: RESPONSABLE DEL PROCESO:
A4: NOMBRE DEL RESPONSABLE DEL PROCESO
A5: Modelo de Autoevaluación | S5: Seguimiento Autoevaluación
A6: Factor (CNA) | B6: Característica (CNA) | C6: OPORTUNIDADES DE MEJORA | D6: ACTIVIDADES/ACCIONES | E6: INDICADOR P PROCESO AUTOEVALUACIÓN (2023) | F6: FECHA INICIO PROGRAMADA | I6: FECHA FINAL PROGRAMADA | L6: EVIDENCIA | M6: LINK DE VERIFICACIÓN | N6: RESPONSABLE ASIGNADO | O6: RECURSOS REQUERIDOS | R6: Meta | S6: Nivel de Cumplimieto de lA Meta (%) | T6: Observaciones | X6: ∑ de Tareas | Y6: # Tarea realizada | AA6: # Tarea sin realizar | AB6: Estado | AC6: D
F7: DÍA | G7: MES | H7: AÑO | I7: DÍA | J7: MES | K7: AÑO | O7: TÉCNICOS | P7: HUMANOS | Q7: FINANCIEROS | AA7: =+X7-Y7 -> 0 | AB7: =IF(AA7=0,"Cumple",IF(AA7>0,"Falta",IF(AA7<0,"Error",0))) -> Cumple | AC7: =(F7-#REF!) -> #VALUE!
A8: 1. PROYECTO EDUCATIVO DEL PROGRAMA E IDENTIDAD INSTITUCIONAL | B8: 1. PROYECTO EDUCATIVO DEL PROGRAMA | AA8: =+X8-Y8 -> 0 | AB8: =IF(AA8=0,"Cumple",IF(AA8>0,"Falta",IF(AA8<0,"Error",0))) -> Cumple | AC8: =(F8-#REF!) -> #REF!
AA9: =+X9-Y9 -> 0 | AB9: =IF(AA9=0,"Cumple",IF(AA9>0,"Falta",IF(AA9<0,"Error",0))) -> Cumple | AC9: =(F9-#REF!) -> #REF!
AA10: =+X10-Y10 -> 0 | AB10: =IF(AA10=0,"Cumple",IF(AA10>0,"Falta",IF(AA10<0,"Error",0))) -> Cumple | AC10: =(F10-#REF!) -> #REF!
AA11: =+X11-Y11 -> 0 | AB11: =IF(AA11=0,"Cumple",IF(AA11>0,"Falta",IF(AA11<0,"Error",0))) -> Cumple | AC11: =(F11-#REF!) -> #REF!
AA12: =+X12-Y12 -> 0 | AB12: =IF(AA12=0,"Cumple",IF(AA12>0,"Falta",IF(AA12<0,"Error",0))) -> Cumple | AC12: =(F12-#REF!) -> #REF!
AA13: =+X13-Y13 -> 0 | AB13: =IF(AA13=0,"Cumple",IF(AA13>0,"Falta",IF(AA13<0,"Error",0))) -> Cumple | AC13: =(F13-#REF!) -> #REF!
AA14: =+X14-Y14 -> 0 | AB14: =IF(AA14=0,"Cumple",IF(AA14>0,"Falta",IF(AA14<0,"Error",0))) -> Cumple | AC14: =(F14-#REF!) -> #REF!
AA15: =+X15-Y15 -> 0 | AB15: =IF(AA15=0,"Cumple",IF(AA15>0,"Falta",IF(AA15<0,"Error",0))) -> Cumple | AC15: =(F15-#REF!) -> #REF!
AA16: =+X16-Y16 -> 0 | AB16: =IF(AA16=0,"Cumple",IF(AA16>0,"Falta",IF(AA16<0,"Error",0))) -> Cumple | AC16: =(F16-#REF!) -> #REF!
AA17: =+X17-Y17 -> 0 | AB17: =IF(AA17=0,"Cumple",IF(AA17>0,"Falta",IF(AA17<0,"Error",0))) -> Cumple | AC17: =(F17-#REF!) -> #REF!
AA18: =+X18-Y18 -> 0 | AB18: =IF(AA18=0,"Cumple",IF(AA18>0,"Falta",IF(AA18<0,"Error",0))) -> Cumple | AC18: =(F18-#REF!) -> #REF!
AA19: =+X19-Y19 -> 0 | AB19: =IF(AA19=0,"Cumple",IF(AA19>0,"Falta",IF(AA19<0,"Error",0))) -> Cumple | AC19: =(F19-#REF!) -> #REF!
AA20: =+X20-Y20 -> 0 | AB20: =IF(AA20=0,"Cumple",IF(AA20>0,"Falta",IF(AA20<0,"Error",0))) -> Cumple | AC20: =(F20-#REF!) -> #REF!
... AA61: =+X61-Y61 -> 0 | AB61: =IF(AA61=0,"Cumple",IF(AA61>0,"Falta",IF(AA61<0,"Error",0))) -> Cumple | AC61: =(F61-#REF!) -> #REF!
AA62: =+X62-Y62 -> 0 | AB62: =IF(AA62=0,"Cumple",IF(AA62>0,"Falta",IF(AA62<0,"Error",0))) -> Cumple | AC62: =(H62-#REF!) -> #REF!
AA63: =+X63-Y63 -> 0 | AB63: =IF(AA63=0,"Cumple",IF(AA63>0,"Falta",IF(AA63<0,"Error",0))) -> Cumple | AC63: =(H63-#REF!) -> #REF!
AA64: =+X64-Y64 -> 0 | AB64: =IF(AA64=0,"Cumple",IF(AA64>0,"Falta",IF(AA64<0,"Error",0))) -> Cumple | AC64: =(H64-#REF!) -> #REF!
AA65: =+X65-Y65 -> 0 | AB65: =IF(AA65=0,"Cumple",IF(AA65>0,"Falta",IF(AA65<0,"Error",0))) -> Cumple | AC65: =(H65-#REF!) -> #REF!
AA66: =+X66-Y66 -> 0 | AB66: =IF(AA66=0,"Cumple",IF(AA66>0,"Falta",IF(AA66<0,"Error",0))) -> Cumple | AC66: =(H66-#REF!) -> #REF!
AA67: =+X67-Y67 -> 0 | AB67: =IF(AA67=0,"Cumple",IF(AA67>0,"Falta",IF(AA67<0,"Error",0))) -> Cumple | AC67: =(H67-#REF!) -> #REF!
AA68: =+X68-Y68 -> 0 | AB68: =IF(AA68=0,"Cumple",IF(AA68>0,"Falta",IF(AA68<0,"Error",0))) -> Cumple | AC68: =(H68-#REF!) -> #REF!
AA69: =+X69-Y69 -> 0 | AB69: =IF(AA69=0,"Cumple",IF(AA69>0,"Falta",IF(AA69<0,"Error",0))) -> Cumple | AC69: =(H69-#REF!) -> #REF!
AA70: =+X70-Y70 -> 0 | AB70: =IF(AA70=0,"Cumple",IF(AA70>0,"Falta",IF(AA70<0,"Error",0))) -> Cumple | AC70: =(H70-#REF!) -> #REF!
AA71: =+X71-Y71 -> 0 | AB71: =IF(AA71=0,"Cumple",IF(AA71>0,"Falta",IF(AA71<0,"Error",0))) -> Cumple | AC71: =(H71-#REF!) -> #REF!
AA72: =+X72-Y72 -> 0 | AB72: =IF(AA72=0,"Cumple",IF(AA72>0,"Falta",IF(AA72<0,"Error",0))) -> Cumple | AC72: =(H72-#REF!) -> #REF!
AA73: =+X73-Y73 -> 0 | AB73: =IF(AA73=0,"Cumple",IF(AA73>0,"Falta",IF(AA73<0,"Error",0))) -> Cumple | AC73: =(H73-#REF!) -> #REF!
... AA77: =+X77-Y77 -> 0 | AB77: =IF(AA77=0,"Cumple",IF(AA77>0,"Falta",IF(AA77<0,"Error",0))) -> Cumple | AC77: =(H77-#REF!) -> #REF!
A78: -- | B78: -- | C78: -- | E78: -- | F78: -- | H78: -- | K78: -- | L78: -- | N78: -- | Q78: -- | R78: -- | S78: -- | T78: --

Sheet Listas Nuevas
A2: Factores CNA Prog. | B2: Características
A3: 1. PROYECTO EDUCATIVO DEL PROGRAMA E IDENTIDAD INSTITUCIONAL | B3: 1. PROYECTO EDUCATIVO DEL PROGRAMA
A4: 2. ESTUDIANTES | B4: 2. RELEVANCIA ACADÉMICA Y PERTINENCIA SOCIAL DEL PROGRAMA ACADÉMICO
A5: 3. PROFESORES | B5: 3. PARTICIPACIÓN EN ACTIVIDADES DE FORMACIÓN INTEGRAL
A6: 4. EGRESADOS | B6: 4. ORIENTACIÓN Y SEGUIMIENTO A ESTUDIANTES
A7: 5. ASPECTOS ACADÉMICOS Y RESULTADOS DE APRENDIZAJE | B7: 5. CAPACIDAD DE TRABAJO AUTÓNOMO
A8: 6. PERMANENCIA Y GRADUACIÓN | B8: 6. REGLAMENTO ESTUDIANTIL Y POLÍTICA ACADÉMICA
A9: 7. INTERACCIÓN CON EL ENTORNO NACIONAL E INTERNACIONAL | B9: 7. ESTÍMULOS Y APOYOS PARA ESTUDIANTES
A10: 8. APORTES DE LA INVESTIGACIÓN, LA INNOVACIÓN, EL DESARROLLO TECNOLÓGICO Y LA CREACIÓN, ASOCIADOS AL PROGRAMA ACADÉMICO | B10: 8. SELECCIÓN, VINCULACIÓN Y PERMANENCIA
A11: 9. BIENESTAR DE LA COMUNIDAD ACADÉMICA DEL PROGRAMA. | B11: 9. ESTATUTO PROFESORAL
A12: 10. MEDIOS EDUCATIVOS Y AMBIENTES DE APRENDIZAJE | B12: 10. NÚMERO, DEDICACIÓN, NIVEL DE FORMACIÓN Y EXPERIENCIA
A13: 11. ORGANIZACIÓN, ADMINISTRACIÓN Y FINANCIACIÓN DEL PROGRAMA ACADÉMICO | B13: 11. DESARROLLO PROFESORAL
A14: 12. RECURSOS FÍSICOS Y TECNOLÓGICOS | B14: 12. ESTÍMULOS A LA TRAYECTORIA PROFESORAL
B15: 13. PRODUCCIÓN, PERTINENCIA, UTILIZACIÓN E IMPACTO DE MATERIAL DOCENTE
B16: 14. REMUNERACIÓN POR MÉRITOS
B17: 15. EVALUACIÓN DE PROFESORES
B18: 16. SEGUIMIENTO DE LOS EGRESADOS
B19: 17. IMPACTO DE LOS EGRESADOS EN EL MEDIO SOCIAL Y ACADÉMICO
B20: 18. INTEGRALIDAD DE LOS ASPECTOS CURRICULARES
B21: 19. FLEXIBILIDAD DE LOS ASPECTOS CURRICULARES
B22: 20. INTERDISCIPLINARIEDAD
B23: 21. ESTRATEGIAS PEDAGÓGICAS
B24: 22. SISTEMA DE EVALUACIÓN DE ESTUDIANTES
B25: 23. RESULTADOS DE APRENDIZAJE
B26: 24. COMPETENCIAS
... B50: 48. RECURSOS INFORMÁTICOS Y DE COMUNICACIÓN

Sheet Lista Antigua
B2: Factores | E2: Factor 1 | G2: Factor 2 | I2: Factor 3 | K2: Factor 4 | M2: Factor 5 | O2: Factor 6 | Q2: Factor 7 | S2: Factor 8 | U2: Factor 9 | W2: Factor 10
B3: Elija
B4: 1. Misión, Proyecto Institucional Y De Programa | C4: Factor1 | E4: 1. Misión, Visión Y Proyecto Insitucional | G4: 4. Mecanismos De Selección E Ingreso | I4: 8. Selección, Vinculación Y Permanencia De Profesores | K4: 16. Integralidad Del Currículo | M4: 27. Inserción Del Programa En Contextos Académicos Nacionales E Internacionales | O4: 29. Formación Para La Investigación, La Innovación Y La Creación Artística Y Cultural | Q4: 31. Políticas, Programas Y Servicios De Bienestar Universitario | S4: 33. Organización, Administración Y Gestión Del Programa | U4: 36. Seguimiento De Los Egresados | W4: 38. Recursos Físicos
B5: 2. Estudiantes | C5: Factor2 | E5: 2. Proyecto Edcativo El Programa | G5: 5. Estudiantes Admitidos Y Capacidad Institucional | I5: 9. Estatuto Profesoral | K5: 17. Flexibilidad Del Currículo | M5: 28. Relaciones Externas De Profesores Y Estudantes | O5: 30. Compromiso Con La Investigación, La Innovación Y La Creación Artística Y Cultural | Q5: 32. Permanencia Y Retención Estudiantil | S5: 34. Sistemas De Comunicación E Información | U5: 37. Impacto De Los Egresados En El Medio Social Y Académico | W5: 39. Presupuesto Del Programa
B6: 3. Profesores | C6: Factor3 | E6: 3. Elevancia Académica Y Pertinencia Social Del Programa | G6: 6. Participación En Actividades De Formación Integral | I6: 10. Número, Dedicación, Nivel De Formación Y Experiencia De Los Profesores | K6: 18. Nterdisciplinariedad | S6: 35. Dirección Del Programa | W6: 40. Administración De Recursos
B7: 4. Procesos Académicos | C7: Factor4 | G7: 7. Reglamentos Estudiantil Y Académico | I7: 11. Desarrollo Profesoral | K7: 19. Metodologías De Enseñanza Y Aprendizaje
B8: 5. Visibilidad Nacional E Internaciona | C8: Factor5 | I8: 12. Estímulos A La Docencia, Investigación, Creación Artística Y Cultural, | K8: 20. Sistema De Evaluación De Estudiantes
B9: 6. Investigación, Innovación Y Creación Artística Y Cultural | C9: Factor6 | I9: 13. Producción, Pertinencia, Utilización E Impacto De Material Docente | K9: 21. Trabajos De Los Estudiantes
B10: 7. Bienestar Institucional | C10: Factor7 | I10: 14. Remuneración Por Méritos | K10: 22. Evaluación Y Autorregulación Del Programa
B11: 8. Organización, Administración Y Gestión | C11: Factor8 | I11: 15. Evaluación De Profesores | K11: 23. Extensión O Proyección Social
B12: 9. Impacto De Los Egresados En El Medio | C12: Factor9 | K12: 24. Recursos Bibliográficos
B13: 10. Recursos Físicos Y Financieros | C13: Factor10 | K13: 25. Recursos Informáticos Y De Comunicación
K14: 26. Recursos De Apoyo Docente

Sheet Resultado año 1
B2: PORCENTAJE TAREAS PLAN DE MEJORA AÑO 1
B4: ∑ de Tareas | C4: # Tareas realizadas | D4: # Tareas sin realizar | F4: % tareas realizadas | I4: % tareas sin realizar
B5: =SUM('Año 1'!X7:X77) -> 0 | C5: =SUM('Año 1'!Y7:Y77) -> 0 | D5: =B5-C5 -> 0 | F5: =C5/$B$5 -> #DIV/0! | I5: =D5/$B$5 -> #DIV/0!
M7: Escala de Valoración
M8: % | N8: Estado de Ejecución
M10: 75% - 100% | N10: Satisfactorio
M11: 50% - 74% | N11: Aceptable
M12: 0% - 49% | N12: Deficiente
M14: =IF(F5>=75%,"Satisfactorio",IF(F5>=50%,"Aceptable","Deficiente")) -> #DIV/0!
B20: SEGUIMIENTO AL PLAN DE MEJORA
C21: Nombre | H21: Cargo
B22: QUIEN RECIBE:
B23: QUIEN REALIZA: | C23: Luisa Marcela Toro | H23: Coordinadora Autoevaluación Institucional
B24: Fecha: | C24: DD | D24: Diciembre | E24: AAAA

Sheet Año 2
B1: PLAN MEJORAMIENTO PROCESO DE AUTOEVALUACIÓN PROGRAMAS ACADEMICOS 2023
A2: PROGRAMA:
A3: RESPONSABLE DEL PROCESO:
A4: NOMBRE RESPONSABLE PROCESO:
A5: Modelo de Autoevaluación | S5: Seguimiento Autoevaluación
A6: Factor (CNA) | B6: Característica (CNA) | C6: Oportunidad de mejora | D6: ACTIVIDADES/ACCIONES | E6: INDICADOR PROCESO AUTOEVALUACIÓN (2023) | F6: FECHA INICIO PROGRAMADA | I6: FECHA FINAL PROGRAMADA | L6: EVIDENCIA | M6: LINK DE VERIFICACIÓN | N6: RESPONSABLE ASIGNADO | O6: RECURSOS REQUERIDOS | R6: Meta | S6: Nivel de Cumplimieto de lA Meta (%) | T6: Observaciones | X6: ∑ de Tareas | Y6: # Tarea realizada | AA6: # Tarea sin realizar | AB6: Estado | AC6: D
F7: DÍA | G7: MES | H7: AÑO | I7: DÍA | J7: MES | K7: AÑO | O7: TÉCNICOS | P7: HUMANOS | Q7: FINANCIEROS | AA7: =+X7-Y7 -> 0 | AB7: =IF(AA7=0,"Cumple",IF(AA7>0,"Falta",IF(AA7<0,"Error",0))) -> Cumple | AC7: =(F7-#REF!) -> #VALUE!
AA8: =+X8-Y8 -> 0 | AB8: =IF(AA8=0,"Cumple",IF(AA8>0,"Falta",IF(AA8<0,"Error",0))) -> Cumple | AC8: =(F8-#REF!) -> #REF!
AA9: =+X9-Y9 -> 0 | AB9: =IF(AA9=0,"Cumple",IF(AA9>0,"Falta",IF(AA9<0,"Error",0))) -> Cumple | AC9: =(F9-#REF!) -> #REF!
AA10: =+X10-Y10 -> 0 | AB10: =IF(AA10=0,"Cumple",IF(AA10>0,"Falta",IF(AA10<0,"Error",0))) -> Cumple | AC10: =(F10-#REF!) -> #REF!
AA11: =+X11-Y11 -> 0 | AB11: =IF(AA11=0,"Cumple",IF(AA11>0,"Falta",IF(AA11<0,"Error",0))) -> Cumple | AC11: =(F11-#REF!) -> #REF!
AA12: =+X12-Y12 -> 0 | AB12: =IF(AA12=0,"Cumple",IF(AA12>0,"Falta",IF(AA12<0,"Error",0))) -> Cumple | AC12: =(F12-#REF!) -> #REF!
AA13: =+X13-Y13 -> 0 | AB13: =IF(AA13=0,"Cumple",IF(AA13>0,"Falta",IF(AA13<0,"Error",0))) -> Cumple | AC13: =(F13-#REF!) -> #REF!
AA14: =+X14-Y14 -> 0 | AB14: =IF(AA14=0,"Cumple",IF(AA14>0,"Falta",IF(AA14<0,"Error",0))) -> Cumple | AC14: =(F14-#REF!) -> #REF!
AA15: =+X15-Y15 -> 0 | AB15: =IF(AA15=0,"Cumple",IF(AA15>0,"Falta",IF(AA15<0,"Error",0))) -> Cumple | AC15: =(F15-#REF!) -> #REF!
AA16: =+X16-Y16 -> 0 | AB16: =IF(AA16=0,"Cumple",IF(AA16>0,"Falta",IF(AA16<0,"Error",0))) -> Cumple | AC16: =(F16-#REF!) -> #REF!
AA17: =+X17-Y17 -> 0 | AB17: =IF(AA17=0,"Cumple",IF(AA17>0,"Falta",IF(AA17<0,"Error",0))) -> Cumple | AC17: =(F17-#REF!) -> #REF!
AA18: =+X18-Y18 -> 0 | AB18: =IF(AA18=0,"Cumple",IF(AA18>0,"Falta",IF(AA18<0,"Error",0))) -> Cumple | AC18: =(F18-#REF!) -> #REF!
AA19: =+X19-Y19 -> 0 | AB19: =IF(AA19=0,"Cumple",IF(AA19>0,"Falta",IF(AA19<0,"Error",0))) -> Cumple | AC19: =(F19-#REF!) -> #REF!
... AA61: =+X61-Y61 -> 0 | AB61: =IF(AA61=0,"Cumple",IF(AA61>0,"Falta",IF(AA61<0,"Error",0))) -> Cumple | AC61: =(F61-#REF!) -> #REF!
AA62: =+X62-Y62 -> 0 | AB62: =IF(AA62=0,"Cumple",IF(AA62>0,"Falta",IF(AA62<0,"Error",0))) -> Cumple | AC62: =(H62-#REF!) -> #REF!
AA63: =+X63-Y63 -> 0 | AB63: =IF(AA63=0,"Cumple",IF(AA63>0,"Falta",IF(AA63<0,"Error",0))) -> Cumple | AC63: =(H63-#REF!) -> #REF!
AA64: =+X64-Y64 -> 0 | AB64: =IF(AA64=0,"Cumple",IF(AA64>0,"Falta",IF(AA64<0,"Error",0))) -> Cumple | AC64: =(H64-#REF!) -> #REF!
AA65: =+X65-Y65 -> 0 | AB65: =IF(AA65=0,"Cumple",IF(AA65>0,"Falta",IF(AA65<0,"Error",0))) -> Cumple | AC65: =(H65-#REF!) -> #REF!
AA66: =+X66-Y66 -> 0 | AB66: =IF(AA66=0,"Cumple",IF(AA66>0,"Falta",IF(AA66<0,"Error",0))) -> Cumple | AC66: =(H66-#REF!) -> #REF!
AA67: =+X67-Y67 -> 0 | AB67: =IF(AA67=0,"Cumple",IF(AA67>0,"Falta",IF(AA67<0,"Error",0))) -> Cumple | AC67: =(H67-#REF!) -> #REF!
AA68: =+X68-Y68 -> 0 | AB68: =IF(AA68=0,"Cumple",IF(AA68>0,"Falta",IF(AA68<0,"Error",0))) -> Cumple | AC68: =(H68-#REF!) -> #REF!
AA69: =+X69-Y69 -> 0 | AB69: =IF(AA69=0,"Cumple",IF(AA69>0,"Falta",IF(AA69<0,"Error",0))) -> Cumple | AC69: =(H69-#REF!) -> #REF!
AA70: =+X70-Y70 -> 0 | AB70: =IF(AA70=0,"Cumple",IF(AA70>0,"Falta",IF(AA70<0,"Error",0))) -> Cumple | AC70: =(H70-#REF!) -> #REF!
AA71: =+X71-Y71 -> 0 | AB71: =IF(AA71=0,"Cumple",IF(AA71>0,"Falta",IF(AA71<0,"Error",0))) -> Cumple | AC71: =(H71-#REF!) -> #REF!
AA72: =+X72-Y72 -> 0 | AB72: =IF(AA72=0,"Cumple",IF(AA72>0,"Falta",IF(AA72<0,"Error",0))) -> Cumple | AC72: =(H72-#REF!) -> #REF!
AA73: =+X73-Y73 -> 0 | AB73: =IF(AA73=0,"Cumple",IF(AA73>0,"Falta",IF(AA73<0,"Error",0))) -> Cumple | AC73: =(H73-#REF!) -> #REF!
... AA77: =+X77-Y77 -> 0 | AB77: =IF(AA77=0,"Cumple",IF(AA77>0,"Falta",IF(AA77<0,"Error",0))) -> Cumple | AC77: =(H77-#REF!) -> #REF!
A78: -- | B78: -- | C78: -- | E78: -- | F78: -- | H78: -- | K78: -- | L78: -- | N78: -- | Q78: -- | R78: -- | S78: -- | T78: --

Sheet Resultado año 2
B2: PORCENTAJE TAREAS PLAN DE MEJORA AÑO 2
B4: ∑ de Tareas | C4: # Tareas realizadas | D4: # Tareas sin realizar | F4: % tareas realizadas | I4: % tareas sin realizar
B5: =SUM(#REF!) -> #REF! | C5: =SUM(#REF!) -> #REF! | D5: =B5-C5 -> #REF! | F5: =C5/$B$5 -> #REF! | I5: =D5/$B$5 -> #REF!
M7: Escala de Valoración
M8: % | N8: Estado de Ejecución
M10: 75% - 100% | N10: Satisfactorio
M11: 50% - 74% | N11: Aceptable
M12: 0% - 49% | N12: Deficiente
M14: =IF(F5>=75%,"Satisfactorio",IF(F5>=50%,"Aceptable","Deficiente")) -> #REF!
B20: SEGUIMIENTO AL PLAN DE MEJORA
C21: Nombre | H21: Cargo
B22: QUIEN RECIBE:
B23: QUIEN REALIZA:
B24: Fecha: | C24: DD | D24: MM | E24: AAAA

Sheet Consolidado Final
B2: PORCENTAJE CONSOLIDADO FINAL
B4: ∑ de Tareas | C4: # Tareas realizadas | D4: # Tareas sin realizar | F4: % tareas realizadas | I4: % tareas sin realizar
B5: =SUM('Resultado año 1'!B5+'Resultado año 2'!B5) -> #REF! | C5: =SUM('Resultado año 1'!C5+'Resultado año 2'!C5) -> #REF! | D5: =B5-C5 -> #REF! | F5: =C5/$B$5 -> #REF! | I5: =D5/$B$5 -> #REF!
M7: Escala de Valoración
M8: % | N8: Estado de Ejecución
M10: 75% - 100% | N10: Satisfactorio
M11: 50% - 74% | N11: Aceptable
M12: 0% - 49% | N12: Deficiente
M14: =IF(F5>=75%,"Satisfactorio",IF(F5>=50%,"Aceptable","Deficiente")) -> #REF!

Sheet Hoja3 (2)
A1: Características
A2: Elija
A3: 1. Denominación | B3: numero1 | D3: numero 1 | F3: numero 2 | H3: numero 3 | J3: numero 4 | L3: numero 5 | N3: numero 6 | P3: numero 7 | R3: numero 8 | T3: numero 9 | V3: numero 10 | X3: numero 11 | Z3: numero 12 | AB3: numero 13 | AD3: numero 14 | AF3: numero 15 | AH3: numero 16 | AJ3: numero 17 | AL3: numero 18 | AN3: numero 19 | AP3: numero 20 | AR3: numero 21 | AT3: numero 22 | AV3: numero 23 | AX3: numero 24 | AZ3: numero 25 | BB3: numero 26 | BD3: numero 27 | BF3: numero 28 | BH3: numero 29
A4: 2.1. Pertinencia | B4: numero2 | D4: a. Hay correspondencia entre el titulo que se va a ofrecer con los contenidos curriculares del programa | F4: a. Son relevantes los aspectos con los cuales se justifica la pertinencia del Programa en el marco de un contexto globalizado. | H4: a. Demuestra el Programa, con claridad y coherencia, la existencia de oportunidades reales -o potenciales- de desempeño en el campo profesional al cual pertenece. | J4: a. Existen rasgos o características que diferencian al Programa de otros existentes en el país, la región o la localidad. | L4: a. El enfoque o enfoques teóricos relevantes del campo o campos de conocimiento/prácticas influyen en el enfoque teórico del Programa. | N4: a. Se identifican y enuncian con claridad en el Programa los propósitos de formación | P4: a. Existen criterios académicos de la institución para la definición de los créditos en el plan de estudios. | R4: a. Favorece la organización curricular del Programa el trabajo interdisciplinario | T4: a. Se identifica con claridad la organización curricular del Programa | V4: a. Favorecen las estrategias y mediaciones pedagógicas planteadas en el Programa, el desarrollo de competencias para el aprendizaje autónomo en las distintas áreas y componentes de formación académica | X4: a. Corresponden las actividades académicas al plan de estudios presentados por el programa. | Z4: a. El programa plantea estrategias que motivan al estudiante a apropiarse de un segundo idioma. | AB4: a. Son claras las propuestas para la organización y desarrollo de las actividades académicas (Laboratorios talleres seminarios etc.). | AD4: a. Se hace explícito, o se evidencia, en el Plan de estudios del Programa la existencia de la formación investigativa. | AF4: a. Existe una concepción de la institución sobre la relación con el sector externo. | AH4: a. Garantizan el número, la dedicación y los niveles de formación profesional y pedagógica de los profesores la calidad de la formación en el Programa | AJ4: a. Cuenta la institución con una biblioteca y una hemeroteca dotada con el material bibliográfico suficiente en el campo de conocimiento del Programa | AL4: a. Posee la institución una red interna de comunicaciones (intranet) y está conectada con redes de información, nacionales e internacionales | AN4: a. Se puede identificar con claridad qué campos de práctica o de experimentación requiere el Programa | AP4: a. Cuenta la institución con políticas y estrategias adecuadas para la adquisición, mantenimiento y reposición de equipos | AR4: a. Valorar el grado en el cual el Programa de educación a distancia, o el ofrecido a través de tecnologías de información y comunicación, cuenta con: | AT4: a. Valorar hasta qué punto el Programa a distancia expresa con claridad las políticas y mecanismos que tiene establecidos para la producción, la distribución, la evaluación y edición de los materiales propios de los cursos, así como de adquisición de equipos y medios requeridos. De igual manera, la aplicación de la legislación sobre derechos de autor. | AV4: a. Cuenta el Programa con suficientes aulas y espacios para el desarrollo de los cursos y demás actividades académicas y administrativas | AX4: a. Hace explícito la institución, a quiénes va dirigido el Programa Qué condiciones se exigen para el ingreso | AZ4: a. Posee la institución una estructura académico-administrativa estable | BB4: a. Tiene la institución políticas y estrategias de autoevaluación con fines de mejoramiento de sus Programas | BD4: a. Posee el Programa políticas y estrategias de seguimiento a sus egresados | BF4: a. Existe coherencia entre las políticas de Bienestar Universitario, el PEI y las necesidades de la comunidad universitaria | BH4: a. Existen en la institución políticas y estrategias claras en materia presupuestal, que posibiliten la viabilidad, permanencia y desarrollo del Programa
A5: 2.2. Necesidades del país o de la región. | B5: numero3 | D5: b. Hay coherencia entre la denominación del Programa que se ofrece y la identidad propia del campo profesional al cual pertenece.. | F5: b. Hay articulación entre los argumentos presentados para demostrar la pertinencia del Programa y las necesidades del país y la región, | H5: b. Se hacen explícitas las oportunidades de desempeño que en el campo del Programa existen. | J5: b. Son relevantes las características básicas que describe el Programa, y que le permiten definir su identidad o particularidad. | L5: b. Se plantea explícitamente la fundamentación teórica del Programa. | N5: b. Se percibe coherencia entre los propósitos de formación del Programa y aquellos definidos en el PEI | P5: b. Según la naturaleza del Programa, prevé la institución los tiempos, espacios y medios necesarios para facilitar el desarrollo de las responsabilidades propias del estudiante. | R5: b. Favorece el trabajo interdisciplinario en el Programa nuevas formas de organización de sus profesores y estudiantes | T5: b. Hay correspondencia entre los lineamientos curriculares establecidos en la resolución del MEN sobre los aspectos curriculares básicos del Programa y los lineamientos pedagógicos y curriculares de éste | V5: b. Hay estrategias, medios y contextos que prevé el Programa para el desarrollo del aprendizaje | X5: b. Son las actividades académicas pertinentes con el titulo ofrecido por el programa. | Z5: b. Los contenidos de las actividades académicas crean la necesidad de adquirir competencias en un segundo idioma | AB5: b. Las estrategias para la organización de las actividades académicas guardan coherencias con sus componentes y metodología de desarrollo. | AD5: b. Se concibe en la institución la formación investigativa Cuál es su relación con la investigación propiamente dicha en la institución | AF5: b. Tiene el programa políticas, estrategias, planes y Programas para su relación con el sector externo y responden éstos a la concepción y al modelo definido por la institución | AH5: b. Posee la institución políticas, normas y criterios institucionales para la selección, y vinculación del profesorado de planta y de cátedra | AJ5: b. se actualiza permanentemente el material bibliográfico relacionado con el Programa | AL5: b. Dispone la institución de conexiones a correo electrónico para estudiantes y profesores | AN5: b. Dispone la institución de los materiales y medios didácticos necesarios para apoyar el desarrollo del Programa | AP5: b. Tiene la institución una plan de inversiones adecuado (en materia de adquisición de, medios y equipos, tecnologías, material audiovisual, adquisición de software) para garantizar el desarrollo del Programa | AR5: b. Estrategias que aseguren tanto a estudiantes como a profesores el acceso efectivo a los recursos bibliográficos, informáticos y telemáticos y computacionales incorporados en los cursos y actividades del Programa curricular. Este acceso efectivo puede lograrse a través de contratos y condiciones de licenciamiento de software desde redes distintas a las que posee la institución en su campus. | AT5: b. Así mismo, valorar si el Programa a distancia, o el ofrecido a través de tecnologías de información y comunicación, garantiza que los estudiantes tengan acceso a los materiales que apoyan el desarrollo de los cursos, al menos para los tres primeros semestres. Estos materiales deberán incluir módulos que desarrollen los contenidos básicos, guías del aprendizaje, ejercicios de auto y heteroevaluación y soportes-bibliográficos | AV5: b. Son los espacios para el desarrollo de las actividades presenciales o de acompañamiento por el profesor bien iluminados y ventilados | AX5: b. Hay un nivel exigido para el ingreso y cuál es el proceso de selección | AZ5: b. Se soporta la estructura académico-administrativa en órganos especializados de consulta, de asesoría y de decisión | BB5: b. Existe un Comité de Autoevaluación Institucional | BD5: b. Permite el seguimiento hecho a los egresados del Programa identificar fortalezas y debilidades de la formación que ofrece la institución | BF5: b. Existe una política de Bienestar en la institución orientada a favorecer la formación integral de los estudiantes, profesores y egresados | BH5: b. Existen normas relacionadas con la Programación y ejecución del presupuesto de inversión y funcionamiento del Programa
A6: 2.3. Atributos o factores que constituyen rasgos distintivos del programa. | B6: numero4 | D6: c. Se muestra congruencia entre la denominación del Programa y su correspondiente titulación, con la naturaleza, nivel académico, ciclo propedéutico y modalidad de formación. | H6: c. Se presentan argumentos para privilegiar una o varias tendencias del ejercicio profesional. | J6: c. Responden las características del Programa a las necesidades regionales y del país. | L6: c. Se identifican problemas a los cuales se puede dar respuesta con base en los desarrollos científico-técnicos propios del campo al cual pertenece el Programa. | N6: c. Son coherentes los propósitos de formación con la naturaleza del campo de conocimiento naturaleza, nivel académico, ciclo propedéutico y modalidad de formación al cual pertenece el Programa | P6: c. En el Programa, qué incidencia tiene la flexibilidad en “el volumen de trabajo académico del estudiante” | R6: c. Se presentan en el Programa proyectos o acciones que exigen el desarrollo del trabajo interdisciplinario | T6: c. Se hace explícita la fundamentación que sustenta la estructura curricular propuesta | V6: c. Se explicitan las estrategias pedagógicas utilizadas en el Programa en los diferentes cursos y actividades académicas | X6: c. Existe una proporción entre las actividades académicas que depende de los objetivos trazados por el programa. | Z6: c. La bibliografía presentada para el desarrollo de las actividades académicas exige habilidades cognitivas en un segundo idioma. | AB6: c. El desarrollo de las actividades académicas permiten alcanzar las metas de formación. | AD6: c. Existen políticas y normas claras que administran, estimulan y favorecen el desarrollo de la investigación tanto en la institución como en el Programa | AF6: c. Se incorporan en el Programa estrategias específicas que permitan vincular los contenidos formativos a las prácticas con el sector externo | AH6: c. Hay permanencia en la vinculación del profesorado que presta servicios al Programa | AJ6: c. Permite la cantidad del material bibliográfico (número de volúmenes, número de títulos, bases de datos y elementos anexos y complementarios) disponible para el Programa el acceso, sin dificultad a todos los estudiantes | AL6: c. Hay mecanismos ágiles y flexibles para facilitar la consulta bibliográfica y el acceso a bases de datos oportunamente | AN6: c. Cuenta la institución con todos los laboratorios, equipos o talleres que se requieren para el desarrollo del Programa | AP6: c. Existen convenios interinstitucionales para el uso de equipos o talleres | AR6: c. Convenios que garanticen las condiciones logísticas e institucionales suficientes para el desarrollo de las prácticas profesionales. | AT6: c. En el caso de Programas apoyados en Tecnologías de la Información y la Comunicación (análogas y digitales), considerar y valorar la calidad de los recursos y estrategias que aprovechen de manera óptima las posibilidades y oportunidades de interacción, comunicación sincrónica y asincrónica. También valorar la incorporación de contenidos en formato multimedia e hipertextual y el desarrollo de estrategias de trabajo colaborativo | AV6: c. Están los espacios de trabajo y su dotación en buen estado | AX6: c. Existen Programas especiales de admisión dirigidos a las poblaciones más vulnerables de la sociedad | AZ6: c. Depende el Programa de una unidad académica pertinente | BB6: c. Existen comités de autoevaluación en las unidades académicas | BD6: c. Permiten las políticas y estrategias valorar el impacto social del Programa y el desempeño laboral de sus egresados | BF6: c. Involucra el Bienestar Universitario a todos los estamentos de la comunidad educativa de manera amplia y participativa | BH6: c. Es coherente el presupuesto del Programa con su plan de desarrollo
A7: 3.1. Fundamentación teórica del programa | B7: numero5 | H7: d. Hace el Programa explícita la relación entre las tendencias del ejercicio profesional y las oportunidades potenciales o existentes de desempeño, con base en el observatorio laboral del MEN y otras fuentes de información. | J7: d. Se consideran otros aspectos de otras condiciones para establecer las características que constituyen su particularidad. | N7: d. Se presenta en el Programa una conceptualización relevante sobre la formación y desarrollo de competencias, que oriente su selección en éste | P7: d. Hay volumen de trabajo académico del estudiante en la relación entre el tiempo presencial o de acompañamiento directo del docente (TP) y el tiempo independiente (TI) | R7: d. Se presentan evidencias de que el Programa tiene una tradición de trabajo interdisciplinario | T7: d. Existe forma de organización de los contenidos (estructura curricular) que privilegia el Programa Áreas Componentes Asignaturas Cursos Núcleos temáticos Núcleos problemáticos Proyectos etc. | V7: d. Son suficientes las estrategias, medios (materiales y virtuales) y contextos para garantizar el aprendizaje de los estudiantes | X7: d. Presenta estrategias el programa para la realización de cada actividad académica. | AB7: d. La propuesta de organización de actividades académicas incluye el desarrollo de prácticas formativas y laboratorios supervisadas por profesores responsables. | AD7: d. Está organizada la formación investigativa en el Programa | AF7: d. Es posible establecer en el Programa alguna articulación entre la formación investigativa y su relación con el sector externo. | AH7: d. Cuenta la institución con un número suficiente de profesores de tiempo completo para desarrollar las labores académicas al servicio del Programa | AJ7: d. ermite la calidad del material bibliográfico disponible para el Programa el acceso a materiales que apoyen el análisis crítico y la investigación | AL7: d. Dispone la institución de software, en cantidad y calidad, para garantizar el apoyo y desarrollo del Programa propuesto | AN7: d. Es adecuada la dotación de los laboratorios en equipos e insumos | AP7: d. Cuenta el Programa con personal profesional calificado para el manejo de equipos y talleres | AR7: d. Según sea el caso, laboratorios de apoyo a la actividad académica e investigativa, señalando las estrategias para atender a estudiantes. | AV7: d. Son las instalaciones y muebles de la biblioteca confortables y están en buen estado | AX7: d. Son claras las condiciones para la transferencia de estudiantes y homologación de cursos | AZ7: d. Establece la estructura académico-administrativa líneas de comunicación ágiles entre el Programa y las demás dependencias de la institución | BB7: d. Hay periodicidad para realizan las prácticas de autoevaluación en los Programas | BD7: d. Se utilizan los resultados del seguimiento a los egresados en el mejoramiento académico del Programa | BF7: d. Trasciende la concepción de Bienestar la simple prestación de servicios y realización de actividades | BH7: d. Es adecuado el presupuesto del Programa para el desarrollo de actividades de docencia, investigación y proyección social
A8: 3.2. Propósitos de formación del programa, competencias y perfiles definidos | B8: numero6 | J8: e. Se puede establecer qué necesidades adicionales satisface el Programa, comparativamente con otras ofertas de Programas similares existentes. | N8: e. Se privilegian competencias en el Programa. | P8: e. Según la naturaleza del Programa, qué importancia asigna el Programa al tiempo independiente que tiene el estudiante para el logro de los propósitos del Programa y, de manera específica, del aprendizaje autónomo | R8: e. Existe integración de equipos de profesores para el tratamiento de los contenidos de un mismo curso De cursos diferentes | T8: e. Si existe, Se expresa la flexibilidad curricular en el Programa En la organización de los contenidos En el incremento de asignaturas, cursos o actividades académicas electivas (de libre escogencia por parte del estudiante) | V8: e. Corresponden las estrategias de aprendizaje al número de estudiantes por curso y por actividad académica | X8: e. Hay coherencia entre las actividades académicas propuestas. | AB8: e. La organización de las actividades académicas disponen de los escenarios apropiados para su realización. | AD8: e. Se cuenta en el presupuesto de la institución con recursos económicos apropiados que permiten el desarrollo de la actividad investigativa | AF8: e. Responden las políticas, estrategias y Programas de vinculación al sector externo a los problemas y necesidades de la comunidad nacional, regional o local | AH8: e. Cuenta la institución con un escalafón que valore la calidad académica del profesorado | AJ8: e. Tiene facilidad el estudiante para encontrar el material bibliográfico que se le recomienda en la bibliografía del curso | AL8: e. Se planea racionalmente el uso de los recursos informáticos existentes para garantizar la cobertura y la calidad del servicio | AN8: e. Existen normas de higiene y seguridad para el uso de laboratorios Se divulgan entre los usuarios de los laboratorios | AP8: e. Tiene la institución un plan de mantenimiento y renovación de equipos | AR8: e. Materiales de apoyo multimedial (audio, video, animaciones interactivas, simulaciones, etc.) según el caso, que servirán de complemento para el desarrollo de los cursos y actividades del Programa de formación.. | AV8: e. Dispone la biblioteca de medios ágiles para la consulta bibliográfica | AX8: e. Conocen los aspirantes las normas y procedimientos que la institución tiene sobre el proceso de selección | AZ8: e. Existen mecanismos claros para la selección del director del Programa | BB8: e. Existe en la institución una cultura consolidada de autoevaluación | BD8: e. Cuenta la institución con canales de comunicación adecuados con los egresados | BF8: e. Existe una articulación entre las prácticas académicas, de gestión y de bienestar en la institución | BH8: e. Existen documentos e informes que demuestren el origen, monto y distribución de los recursos presupuestales destinados al Programa
A9: 3.3. Plan general de estudios representado en créditos académicos | B9: numero7 | N9: f. Hay coherencia entre las competencias que se describen y la naturaleza del campo de conocimiento, nivel académico, o ciclo propedéutico al cual pertenece el Programa. | P9: f. Hay proporcionalidad entre el volumen de contenidos seleccionados en los diferentes cursos y actividades académicas del plan de estudios del Programa y el tiempo asignado al trabajo independiente del estudiante. | T9: f. Es posible, a partir del análisis de la relación entre los cursos y actividades académicas obligatorias o electivas, definir el grado de flexibilidad en el Programa | V9: f. Orientan las estrategias y mediaciones pedagógicas a que el estudiante desarrolle su curiosidad intelectual, su iniciativa, su responsabilidad y compromiso consigo mismo, así como su capacidad de trabajar en equipo | X9: f. Refleja el plan de estudios la pertinencia adecuada con el perfil de estudiante que se quiere formar. | AB9: f. La organización de las actividades académicas demuestran flexibilidad en su desarrollo y son permanentemente evaluados sus resultados. | AD9: f. Posee la institución un sistema de estímulos y reconocimientos para el personal que participa en y contribuye al desarrollo de la investigación | AF9: f. Se basa el desarrollo de la relación con el sector externo, en planes y Programas específicos que impliquen investigación o intervención (Como en el caso de proyectos relacionados con promoción y prevención de salud, desarrollo de pequeñas empresas, trabajo con el sector agropecuario, consultoría jurídica, proyectos productivos, innovación tecnológica, desarrollo de tecnologías alternativas, etc.). | AH9: f. Tiene la institución políticas y estrategias concretas de mejoramiento de la calidad de la formación del profesorado (Programas de capacitación y de perfeccionamiento para docentes e investigadores, estudios de postgrado, cursos, seminarios, pasantías, otras) | AJ9: f. Cuenta la institución con políticas y estrategias adecuadas para la adquisición, mantenimiento y reposición de material bibliográfico, equipos y laboratorios | AL9: f. Cuenta la institución con políticas y estrategias adecuadas para la adquisición, mantenimiento y reposición de equipos y laboratorios | AN9: f. Presentan los laboratorios condiciones de seguridad que garanticen el uso de sus instalaciones, materiales y equipos-- | AV9: f. Cuenta la biblioteca con salas de lectura, adecuadas y confortables | AX9: f. Se puede inferir que las condiciones, criterios y procesos de selección son justos y equitativos | AZ9: f. Existe un manual de funciones que determine el quehacer del director del Programa | BB9: f. Permite la autoevaluación obtener información clara, objetiva y confiable sobre el estado del Programa | BD9: f. Se realizan estudios sobre la ubicación laboral y el desempeño de los egresados del Programa (Observatorio laboral) | BF9: f. Desarrolla el Bienestar Universitario actividades específicas para favorecer el cuidado de la salud | BH9: f. Qué porcentaje de los ingresos de la institución se dedican a la inversión en el Programa
A10: 3.4. Componente de interdisciplinariedad | B10: numero8 | N10: g. Hay coherencia entre las competencias que se describen los propósitos de formación del Programa y el perfil enunciado | P10: g. Es coherente el tiempo asignado al trabajo académico del estudiante con el volumen de contenidos formativos seleccionados | T10: g. Si existe, favorece la flexibilidad curricular la integración o articulación de los contenidos del Programa. | V10: g. Permiten las estrategias y mediaciones pedagógicas que el estudiante pueda actuar en diferentes contextos propios del campo de ejercicio profesional, al cual pertenece Programa | X10: g. Responden las actividades académicas a las necesidades profesionales que requiere la región y el país | AD10: g. Cuenta la institución con las fuentes de financiación internas y externas suficientes para garantizar el desarrollo de las líneas de investigación | AF10: g. Se apoya el desarrollo de las prácticas de relación con el sector externo en convenios interinstitucionales | AH10: g. Se han diseñado mecanismos claros y objetivos de evaluación del desempeño docente que permitan el mejoramiento de la docencia y la retroalimentación de los profesores | AJ10: g. Tiene la institución una plan de inversiones adecuado (en materia de adquisición de material bibliográfico, medios y equipos paras laboratorios, tecnologías, material audiovisual, adquisición de software) para garantizar el desarrollo del Programa | AL10: g. Tiene la institución una plan de inversiones adecuado (en materia de adquisición de medios y equipos paras laboratorios, tecnologías, material audiovisual, adquisición de software) para garantizar el desarrollo del Programa | AN10: g. Cuenta la institución con políticas y estrategias adecuadas para la adquisición, mantenimiento y reposición de material bibliográfico, equipos y laboratorios | AV10: g. Brinda la institución amplias oportunidades para el uso de la biblioteca | AX10: g. Cuenta la institución con estudios sobre las características socio-culturales y económicas de la población a la que está dirigido el Programa, de modo que se definan las condiciones, intereses y necesidades de los estudiantes | AZ10: g. Existe un comité de Programa que atienda y resuelva eficaz y oportunamente los problemas académicos y curriculares del Programa | BB10: g. Han generado los resultados de la autoevaluación la necesidad de cambios en las prácticas de formación En la organización académico-administrativa de la institución | BD10: g. Mantiene la institución una relación permanente con sus egresados que le permita reconocer sus necesidades en el campo de formación | BF10: g. Fomenta el Bienestar Universitario las actividades deportivas, culturales y recreativas en la comunidad educativa
A11: 3.5. Estrategias de flexibilización para el desarrollo del programa | B11: numero9 | N11: h. Se percibe coherencia entre las competencias que se describen y los campos de ejercicio profesional en los cuales va a actuar o intervenir el futuro egresado | P11: h. Es coherente el tiempo asignado al trabajo académico del estudiante con el conjunto de actividades de aprendizaje que se requieren para desarrollar contenidos y competencias | T11: h. Hay estrategias para el logro de la integración de los contenidos en el plan de estudios (cualquiera sea su organización) | V11: h. Se prevén estrategias para el desarrollo de proyectos que respondan a las exigencias prácticas de diversos contextos de desempeño profesional en los que sea necesaria la interacción con otras disciplinas | AD11: h. Cuenta la institución con políticas y normas claras para regular la actividad de publicación y divulgación de la investigación | AF11: h. Cuenta la institución con centros de prácticas adecuados que garanticen la formación de los estudiantes | AH11: h. Tiene la institución un plan de vinculación de docentes de acuerdo con la propuesta presenta, que incluya perfiles, funciones y tipo de vinculación | AJ11: h. Se efectúan permanentemente registros de consulta bibliotecaria Es útil la utilización que se da a esa información (Se presentan estudios al respecto). | AL11: h. Existen convenios interinstitucionales para el uso de laboratorios, equipos o talleres | AN11: h. Tiene la institución una plan de inversiones adecuado (en materia de adquisición de medios y equipos paras laboratorios, tecnologías, material audiovisual, adquisición de software) para garantizar el desarrollo del Programa | AX11: h. Tiene la institución estudios prospectivos sobre el número de estudiantes que recibirá el Programa, las promociones que se pretenden formar y el tiempo de dedicación de los estudiantes | AZ11: h. Afecta la estructura académico-administrativa de la institución el desarrollo del Programa | BB11: h. Participan en la autoevaluación los diversos estamentos de la institución educativa | BD11: h. Tiene la institución políticas de vinculación de egresados, con logros académicos y profesionales sobresalientes, a la planta docente | BF11: h. Hay estrategias de difusión de los Programas que desarrolla Bienestar Universitario entre la comunidad educativa
A12: 3.6. Lineamientos pedagógicos y didácticos | B12: numero10 | N12: i. Contribuyen los Principios y competencias que plantea el Programa al desarrollo de la formación integral | P12: i. Clasifica el Programa las actividades de acompañamiento directo del docente o tiempo presencial y las de tiempo independiente del estudiante | T12: i. Favorece la flexibilidad curricular el desarrollo de cursos y actividades académicas y culturales diferentes a las propias del campo específico del Programa | V12: i. Prevé el Programa tiempos, espacios y medios para el desarrollo de las responsabilidades propias del estudiante | AD12: i. Cuenta la institución con grupos de investigación consolidados Grupos de investigación en proceso de consolidación Grupos incipientes Grupos inscritos a COLCIENCIAS | AF12: i. El Programa desarrolla modalidades de práctica de relación con el sector externo básicas como un sistema de tutorías calificado que garantice el apoyo permanente a las prácticas de proyección de los estudiantes | AH12: i. Prevé el Programa el apoyo de profesores visitantes, de asesores y de expertos. | AJ12: i. Existen convenios interinstitucionales con bibliotecas o centros de información para la realización de intercambios | AL12: i. Cuenta el Programa con personal profesional calificado para el manejo de laboratorios, equipos y talleres | AN12: i. Existen convenios interinstitucionales para el uso de laboratorios, equipos o talleres | AX12: i. Realiza la institución, estudios sobre tasas de deserción, repitencia, o mortalidad académica de los estudiantes | AZ12: i. Existen en la institución unidades académicas consolidadas que posibiliten la prestación de un servicio eficiente al Programa | BB12: i. Se publican los resultados de la autoevaluación oportunamente y se difunden ampliamente | BD12: i. Existen políticas para la formación postgraduada de los egresados a través de recursos propios de la institución, o mediante acuerdos y convenios interinstitucionales, nacionales o internacionales | BF12: i. Cuentan los Programas que desarrolla el Bienestar Universitario con la aceptación y buena calificación por parte de los miembros de la comunidad educativa
A13: 3.7. El contenido general de las actividades académicas | B13: numero11 | P13: j. Se prevén estrategias para el monitoreo y seguimiento del tiempo independiente del estudiante | AD13: j. Existen líneas de investigación relacionadas con el Programa de formación -Posee el Programa sus propias líneas de investigación | AF13: j. Concibe la institución su relación con el sector externo como un diálogo permanente institución–sociedad sobre propósitos, intereses y proyectos comunes o, por el contrario, la concibe exclusivamente como el ofrecimiento de Programas –cursos, diplomados, etcétera– definidos a criterio de la institución | AH13: j. Existe un plan de formación docente que promueva el mejoramiento de la calidad de los procesos de docencia, investigación y extensión. | AJ13: j. Cuenta el Programa con personal profesional calificado para el manejo de la biblioteca | AL13: j. Tiene la institución un plan de mantenimiento y renovación de equipos | AN13: j. Cuenta el Programa con personal profesional calificado para el manejo de laboratorios, equipos y talleres | AX13: j. Se hacen explícitos en el reglamento estudiantil los criterios de permanencia y de promoción de los estudiantes en el Programa | AZ13: j. Existe una estructura organizativa, sistemas de información y mecanismos de gestión que permitan ejecutar procesos de planeación, administración, evaluación y seguimiento de los contenidos curriculares, de las experiencias investigativas y de los diferentes servicios y recursos. | BB13: j. Existen evidencias de ejecución y resultado de los planes de mejoramiento basados en los indicadores de gestión | BD13: j. Existen políticas, estrategias y recursos para la implementación de cursos de educación continuada | BF13: j. Aplica la institución criterios claros y compartidos para el otorgamiento de becas, créditos, premios y distinciones
A14: 3.8. Estrategias pedagógicas que apunten al desarrollo de competencias comunicativas en un segundo idioma | B14: numero12 | P14: k. Cuenta la institución con un cuerpo de docentes suficiente para apoyar el trabajo académico autónomo de los estudiantes | AD14: k. Existe relación entre las líneas de investigación y las áreas y componentes del Programa | AF14: k. Cuenta la institución y el Programa con planes de seguimiento y evaluación de los estudiantes en la práctica (docente-asistencial y comunitaria, empresarial, etc.). | AH14: k. Posee la institución un régimen salarial del profesorado coherente con el escalafón docente. | AN14: k Tiene la institución un plan de mantenimiento y renovación de equipos | AX14: k. Existen mecanismos de difusión de las políticas y de las normas para la admisión de los estudiantes (Pagina Web Institucional) | AZ14: k. La infraestructura y sistemas de información de las cuales disponga la institución deben garantizar, entre otros aspectos, conectividad que facilite el intercambio y reporte electrónico de información con el Ministerio de Educación Nacional | BF14: k. Existen estadísticas institucionales en relación con la prestación de los servicios del Bienestar Universitario
A15: 4. Organización de las actividades académicas | B15: numero13 | P15: l. Se tiene previsto algún plan de capacitación de los docentes sobre la labor de acompañamiento de las actividades de los estudiantes en el marco de la flexibilización | AD15: l. Se han establecido mecanismos para que la investigación propiamente dicha retroalimente efectivamente el desarrollo del Programa de formación | AF15: l. Se tienen evidencias de los resultados e impacto de la relación con el sector externo en los sectores locales y regionales | AH15: l. Existe y se aplica un estatuto o reglamento docente. | AX15: l. Hay criterios para el otorgamiento de becas, créditos, premios y distinciones | BF15: l. Cuenta la institución con el personal suficiente, los medios, los recursos y los espacios adecuados y necesarios para el desarrollo del bienestar universitario
A16: 5. Investigación | B16: numero14 | P16: m. Existen créditos académicos que se asignen a los cursos o actividades académicas electivas. | AD16: m. Se brindan suficientes oportunidades para que los estudiantes, participen en proyectos de investigación de los profesores (Estas oportunidades pueden expresarse en la posibilidad de desarrollar trabajos de grado, prácticas académicas y otro tipo de actividades pertinentes). | AF16: m. Se hace explícito, o se evidencia, cómo en el Plan de estudios del Programa está presente el desarrollo de la relación con el sector externo.
A17: 6. Relación con el sector externo | B17: numero15 | P17: n. Presenta el Programa una variedad de cursos y actividades académicas electivas | AD17: n. Es posible enmarcar las tesis o trabajos de grado dentro de las líneas de investigación que desarrolla la institución | AF17: n. Existe una organización administrativa institucional adecuada para el desarrollo de la relación institucional con el sector externo.
A18: 7. Personal docente | B18: numero16 | P18: o. Ha definido la institución un sistema de reconocimiento de créditos, y de homologaciones de conocimientos y de experiencias | AD18: o. Cuenta la institución, la facultad o la unidad administrativa encargada de la investigación con órganos de difusión | AF18: o. Cuenta la institución con recursos financieros adecuados para garantizar el desarrollo de los Programas de relación con el sector externo
A19: 8.1 Recursos bibliográficos y de hemeroteca | B19: numero17 | P19: p. Se remunera a los docentes por su apoyo al trabajo académico autónomo de los estudiantes | AD19: p. Hay periodicidad y amplia cobertura de las publicaciones institucionales
A20: 8.2. Dotación de equipos de cómputo y software | B20: numero18 | P20: q. Ha reglamentado la institución el límite razonable de créditos que puede tomar el estudiante nocturno que labora. | AD20: q. Hay facilidad para difundir los resultados de las investigaciones de profesores y estudiantes A través de qué medios (publicaciones, eventos)
A21: 8.3. Dotación de equipos de laboratorio | B21: numero19 | AD21: r. Tienen los cursos y actividades académicas definidos en el plan de estudios del Programa relación con prácticas de investigación
A22: 8.4. Audiovisuales | B22: numero20 | AD22: s. Hay estrategias de la institución para el fomento y desarrollo de la formación investigativa (Pueden considerarse, entre otras, la vinculación de los estudiantes a un grupo de investigación, el desarrollo del trabajo de grado, la oferta de cursos electivos y de profundización y la creación y participación de estudiantes en semilleros de investigación).
A23: 8.5. Medios educativos para educación a distancia o para programas ofrecidos a través de tecnologías de información y comunicación | B23: numero21
A24: 8.6. Materiales de los cursos | B24: numero22
A25: 9. Infraestructura física | B25: numero23
A26: 10. Mecanismos de selección y evaluación | B26: numero24
A27: 11. Estructura administrativa y académica | B27: numero25
A28: 12.Autoevaluación | B28: numero26 | U28: =LOWER(U3)
A29: 13. Programa de egresados | B29: numero27
A30: 14. Bienestar universitario | B30: numero28
A31: 15. Recursos financieros suficientes | B31: numero29

Sheet  Hoja2
A1: Caracteristicas
A2: Elija
A3: 1. Misión, Visión Y Proyecto Insitucional | B3: Numero1 | D3: numero 1 | F3: numero 2 | H3: numero 3 | J3: numero 4 | L3: numero 5 | N3: numero 6 | P3: numero 7 | R3: numero 8 | T3: numero 9 | V3: numero 10 | X3: numero 11 | Z3: numero 12 | AB3: numero 13 | AD3: numero 14 | AF3: numero 15 | AH3: numero 16 | AJ3: numero 17 | AL3: numero 18 | AN3: numero 19 | AP3: numero 20 | AR3: numero 21 | AT3: numero 22 | AV3: numero 23 | AX3: numero 24 | AZ3: numero 25 | BB3: numero 26 | BD3: numero 27 | BF3: numero 28 | BH3: numero 29 | BJ3: numero 30 | BL3: numero 31 | BN3: numero 32 | BP3: numero 33 | BR3: numero 34 | BT3: numero 35 | BV3: numero 36 | BX3: numero 37 | BZ3: numero 38 | CB3: numero 39 | CD3: numero 40
