Workbook
Name OBE: [1]Convencionales!$J$3:$J$17

Sheet INICIO
L11: Ir
B12: Nombre Director(a):
D14: Nombre | H14: Cargo
B15: Participantes: | C15: P1
C16: P2
C17: P3
C18: P4
C19: P5
C20: P6
C21: P7
C22: P8
C23: P9
C24: P10
C25: P11
C26: P12
B28: Fecha de elaboración: | D28: DD | E28: MM | F28: AAAA | H28: Periodo: | I28: Elija

Sheet F1
A1: Factor | B1: % | C1: Justificación
A2: F1. IDENTIDAD INSTITUCIONAL
D5: NIVEL DE IMPORTANCIA DE LA CARACTERÍSTICA | O5: VALORACIÓN
A6: Característica | D6: P1 | E6: P2 | F6: P3 | G6: P4 | H6: P5 | I6: P6 | J6: P7 | K6: P8 | L6: P9 | M6: P10 | O6: % | P6: Cal. | Q6: Res. | R6: ∑ | S6: Valoración
A7: 1. Coherencia y pertinencia de la misión | O7: =C13 -> 0 | Q7: =O7*P7 -> 0 | R7: =SUM(Q7:Q9) -> 0 | S7: =IF(R7>=4.1,"Cumple Plenamente",IF(R7>=3.1,"cumple Satisfactoriamente",IF(R7>=2.1,"Cumple Aceptablemente",IF(R7=0," ","No Cumple "))))
A8: 2. Orientaciones y estrategias del Proyecto Educativo Institucional o lo que haga sus veces | O8: =C14 -> 0 | Q8: =O8*P8 -> 0
A9: 3. Formación Integral y Construcción de identidad | O9: =C15 -> 0 | Q9: =O9*P9 -> 0
A12: Característica | B12: NIV | C12: % | D12: Justificación
A13: =A7 -> 1. Coherencia y pertinencia de la misión | B13: =AVERAGE(D7:M7) -> #DIV/0!
A14: =A8 -> 2. Orientaciones y estrategias del Proyecto Educativo Institucional o lo que haga sus veces | B14: =AVERAGE(D8:M8) -> #DIV/0!
A15: =A9 -> 3. Formación Integral y Construcción de identidad | B15: =AVERAGE(D9:M9) -> #DIV/0!

Sheet F2
A1: Factor | B1: % | C1: Justificación
A2: F2. GOBIERNO INSTITUCIONAL Y TRANSPARENCIA | B2: =Res.!D10 -> #DIV/0!
D5: NIVEL DE IMPORTANCIA DE LA CARACTERÍSTICA | O5: VALORACIÓN
A6: Característica | D6: P1 | E6: P2 | F6: P3 | G6: P4 | H6: P5 | I6: P6 | J6: P7 | K6: P8 | L6: P9 | M6: P10 | O6: % | P6: Cal. | Q6: Res. | R6: ∑ | S6: Valoración
A7: 4. Buen gobierno y máximo órgano de gobierno | O7: =C13 -> 0 | Q7: =O7*P7 -> 0 | R7: =SUM(Q7:Q9) -> 0 | S7: =IF(R7>=4.1,"Cumple Plenamente",IF(R7>=3.1,"cumple Satisfactoriamente",IF(R7>=2.1,"Cumple Aceptablemente",IF(R7=0," ","No Cumple "))))
A8: 5. Relación congrupos de interés | O8: =C14 -> 0 | Q8: =O8*P8 -> 0
A9: 6. Rendición de cuentas | O9: =C15 -> 0 | Q9: =O9*P9 -> 0
A12: Característica | B12: NIV | C12: % | D12: Justificación
A13: =A7 -> 4. Buen gobierno y máximo órgano de gobierno | B13: =AVERAGE(D7:M7) -> #DIV/0!
A14: =A8 -> 5. Relación congrupos de interés | B14: =AVERAGE(D8:M8) -> #DIV/0!
A15: =A9 -> 6. Rendición de cuentas | B15: =AVERAGE(D9:M9) -> #DIV/0!

Sheet F3
A1: Factor | B1: % | C1: Justificación
A2: F3. DESARROLLO, GESTIÓN Y SOSTENIBILIDAD INSTITUCIONAL | B2: =Res.!D14 -> #DIV/0!
D5: NIVEL DE IMPORTANCIA DE LA CARACTERÍSTICA | O5: VALORACIÓN
A6: Característica | D6: P1 | E6: P2 | F6: P3 | G6: P4 | H6: P5 | I6: P6 | J6: P7 | K6: P8 | L6: P9 | M6: P10 | O6: % | P6: Cal. | Q6: Res. | R6: ∑ | S6: Valoración
A7: 7. Administración y gestión | O7: =C16 -> 0 | Q7: =O7*P7 -> 0 | R7: =SUM(Q7:Q12) -> 0 | S7: =IF(R7>=4.1,"Cumple Plenamente",IF(R7>=3.1,"cumple Satisfactoriamente",IF(R7>=2.1,"Cumple Aceptablemente",IF(R7=0," ","No Cumple "))))
A8: 8. Procesos de Comunicación | O8: =C17 -> 0 | Q8: =O8*P8 -> 0
A9: 9. Capacidad de gestión | O9: =C18 -> 0 | Q9: =O9*P9 -> 0
A10: 10. Recursos de apoyo académico | O10: =C19 -> 0 | Q10: =O10*P10 -> 0
A11: 11. Infraestructura fisica y tecnologica | O11: =C20 -> 0 | Q11: =O11*P11 -> 0
A12: 12. Recursos y gestión financiera | O12: =C21 -> 0 | Q12: =O12*P12 -> 0
A15: Característica | B15: NIV | C15: % | D15: Justificación
A16: =A7 -> 7. Administración y gestión | B16: =AVERAGE(D7:M7) -> #DIV/0!
A17: =A8 -> 8. Procesos de Comunicación | B17: =AVERAGE(D8:M8) -> #DIV/0!
A18: =A9 -> 9. Capacidad de gestión | B18: =AVERAGE(D9:M9) -> #DIV/0!
A19: =A10 -> 10. Recursos de apoyo académico | B19: =AVERAGE(D10:M10) -> #DIV/0!
A20: =A11 -> 11. Infraestructura fisica y tecnologica | B20: =AVERAGE(D11:M11) -> #DIV/0!
A21: =A12 -> 12. Recursos y gestión financiera | B21: =AVERAGE(D12:M12) -> #DIV/0!

Sheet F4
A1: Factor | B1: % | C1: Justificación
A2: F4. MEJORAMIENTO CONTINUO Y AUTORREGULACIÓN | B2: =Res.!D21 -> #DIV/0!
D5: NIVEL DE IMPORTANCIA DE LA CARACTERÍSTICA | O5: VALORACIÓN
A6: Característica | D6: P1 | E6: P2 | F6: P3 | G6: P4 | H6: P5 | I6: P6 | J6: P7 | K6: P8 | L6: P9 | M6: P10 | O6: % | P6: Cal. | Q6: Res. | R6: ∑ | S6: Valoración
A7: 13. Cultura de la Autoevaluación | O7: =C14 -> 0.35 | Q7: =O7*P7 -> 0 | R7: =SUM(Q7:Q8) -> 0 | S7: =IF(R7>=4.1,"Cumple Plenamente",IF(R7>=3.1,"cumple Satisfactoriamente",IF(R7>=2.1,"Cumple Aceptablemente",IF(R7=0," ","No Cumple "))))
A8: 14. Procesos de autorregulación | O8: =C15 -> 0.2 | Q8: =O8*P8 -> 0
A9: 15. Sistema Interno de Aseguramiento de la Calidad | O9: =C16 -> 0.3 | Q9: =O9*P9 -> 0
A10: 16. Evaluación de directivas, profesores y personal administrativo | O10: =C17 -> 0.25 | Q10: =O10*P10 -> 0
A13: Característica | B13: NIV | C13: % | D13: Justificación
A14: =A7 -> 13. Cultura de la Autoevaluación | B14: =AVERAGE(D7:M7) -> #DIV/0! | C14: 0.35
A15: =A8 -> 14. Procesos de autorregulación | B15: =AVERAGE(D8:M8) -> #DIV/0! | C15: 0.2
A16: =A9 -> 15. Sistema Interno de Aseguramiento de la Calidad | B16: =AVERAGE(D9:M9) -> #DIV/0! | C16: 0.3
A17: =A10 -> 16. Evaluación de directivas, profesores y personal administrativo | B17: =AVERAGE(D10:M10) -> #DIV/0! | C17: 0.25

Sheet F5
A1: Factor | B1: % | C1: Justificación
A2: F5. ESTRUCTURA Y PROCESOS ACADÉMICOS | B2: =Res.!D26 -> #DIV/0!
D5: NIVEL DE IMPORTANCIA DE LA CARACTERÍSTICA | O5: VALORACIÓN
A6: Característica | D6: P1 | E6: P2 | F6: P3 | G6: P4 | H6: P5 | I6: P6 | J6: P7 | K6: P8 | L6: P9 | M6: P10 | O6: % | P6: Cal. | Q6: Res. | R6: ∑ | S6: Valoración
A7: 17. Componentes formativos | O7: =C14 -> 0 | Q7: =O7*P7 -> 0 | R7: =SUM(Q7:Q10) -> 0 | S7: =IF(R7>=4.1,"Cumple Plenamente",IF(R7>=3.1,"cumple Satisfactoriamente",IF(R7>=2.1,"Cumple Aceptablemente",IF(R7=0," ","No Cumple "))))
A8: 18. Componentes pedagógicos y de evaluación | O8: =C15 -> 0 | Q8: =O8*P8 -> 0
A9: 19. Componente de interacción y relevancia social | O9: =C16 -> 0 | Q9: =O9*P9 -> 0
A10: 20. Procesos de creación, modificación y ampliación de programas académicos | O10: =C17 -> 0 | Q10: =O10*P10 -> 0
A13: Característica | B13: NIV | C13: % | D13: Justificación
A14: =A7 -> 17. Componentes formativos | B14: =AVERAGE(D7:M7) -> #DIV/0!
A15: =A8 -> 18. Componentes pedagógicos y de evaluación | B15: =AVERAGE(D8:M8) -> #DIV/0!
A16: =A9 -> 19. Componente de interacción y relevancia social | B16: =AVERAGE(D9:M9) -> #DIV/0!
A17: =A10 -> 20. Procesos de creación, modificación y ampliación de programas académicos | B17: =AVERAGE(D10:M10) -> #DIV/0!

Sheet F6
A1: Factor | B1: % | C1: Justificación
A2: F6. APORTES DE LA INVESTIGACIÓN, LA INNOVACIÓN, EL DESARROLLO TECNOLÓGICO Y LA CREACIÓN AL ENTORNO | B2: =Res.!D31 -> #DIV/0!
D5: NIVEL DE IMPORTANCIA DE LA CARACTERÍSTICA | O5: VALORACIÓN
A6: Característica | D6: P1 | E6: P2 | F6: P3 | G6: P4 | H6: P5 | I6: P6 | J6: P7 | K6: P8 | L6: P9 | M6: P10 | O6: % | P6: Cal. | Q6: Res. | R6: ∑ | S6: Valoración
A7: 21. Formación para la investigación, creación e innovación | O7: =C12 -> #DIV/0! | Q7: =O7*P7 -> #DIV/0! | R7: =SUM(Q7:Q8) -> #DIV/0! | S7: =IF(R7>=4.1,"Cumple Plenamente",IF(R7>=3.1,"cumple Satisfactoriamente",IF(R7>=2.1,"Cumple Aceptablemente",IF(R7=0," ","No Cumple ")))) -> #DIV/0!
A8: 22. Investigación, desarrollo tecnológico, innovación y creación | O8: =C13 -> #DIV/0! | Q8: =O8*P8 -> #DIV/0!
A11: Característica | B11: NIV | C11: % | D11: Justificación
A12: =A7 -> 21. Formación para la investigación, creación e innovación | B12: =AVERAGE(D7:M7) -> #DIV/0! | C12: =B12/SUM($B$12:$B$13) -> #DIV/0!
A13: =A8 -> 22. Investigación, desarrollo tecnológico, innovación y creación | B13: =AVERAGE(D8:M8) -> #DIV/0! | C13: =B13/SUM($B$12:$B$13) -> #DIV/0!

Sheet F7
A1: Factor | B1: % | C1: Justificación
A2: F7. IMPACTO SOCIAL | B2: =Res.!D34 -> #DIV/0!
D5: NIVEL DE IMPORTANCIA DE LA CARACTERÍSTICA | O5: VALORACIÓN
A6: Característica | D6: P1 | E6: P2 | F6: P3 | G6: P4 | H6: P5 | I6: P6 | J6: P7 | K6: P8 | L6: P9 | M6: P10 | O6: % | P6: Cal. | Q6: Res. | R6: ∑ | S6: Valoración
A7: 23. Institución y entorno | O7: =C12 -> 0.6 | Q7: =O7*P7 -> 0 | R7: =SUM(Q7:Q8) -> 0 | S7: =IF(R7>=4.1,"Cumple Plenamente",IF(R7>=3.1,"cumple Satisfactoriamente",IF(R7>=2.1,"Cumple Aceptablemente",IF(R7=0," ","No Cumple "))))
A8: 24. Impacto cultural y artístico | O8: =C13 -> 0.4 | Q8: =O8*P8 -> 0
A11: Característica | B11: NIV | C11: % | D11: Justificación
A12: =A7 -> 23. Institución y entorno | B12: =AVERAGE(D7:M7) -> #DIV/0! | C12: 0.6
A13: =A8 -> 24. Impacto cultural y artístico | B13: =AVERAGE(D8:M8) -> #DIV/0! | C13: 0.4

Sheet F8
A1: Factor | B1: % | C1: Justificación
A2: F8. VISIBILIDAD NACIONAL E INTERNACIONAL | B2: =Res.!D37 -> #DIV/0!
D5: NIVEL DE IMPORTANCIA DE LA CARACTERÍSTICA | O5: VALORACIÓN
A6: Característica | D6: P1 | E6: P2 | F6: P3 | G6: P4 | H6: P5 | I6: P6 | J6: P7 | K6: P8 | L6: P9 | M6: P10 | O6: % | P6: Cal. | Q6: Res. | R6: ∑ | S6: Valoración
A7: 25. Inserción de la institución en contextos académicos nacionales e internacionales | O7: =C12 -> 0.5 | Q7: =O7*P7 -> 0 | R7: =SUM(Q7:Q8) -> 0 | S7: =IF(R7>=4.1,"Cumple Plenamente",IF(R7>=3.1,"cumple Satisfactoriamente",IF(R7>=2.1,"Cumple Aceptablemente",IF(R7=0," ","No Cumple "))))
A8: 26. Relaciones externas de profesores y estudiantes | O8: =C13 -> 0.5 | Q8: =O8*P8 -> 0
A11: Característica | B11: NIV | C11: % | D11: Justificación
A12: =A7 -> 25. Inserción de la institución en contextos académicos nacionales e internacionales | B12: =AVERAGE(D7:M7) -> #DIV/0! | C12: 0.5
A13: =A8 -> 26. Relaciones externas de profesores y estudiantes | B13: =AVERAGE(D8:M8) -> #DIV/0! | C13: 0.5

Sheet F9
A1: Factor | B1: % | C1: Justificación
A2: F9. BIENESTAR INSTITUCIONAL | B2: =Res.!D40 -> #DIV/0!
D5: NIVEL DE IMPORTANCIA DE LA CARACTERÍSTICA | O5: VALORACIÓN
A6: Característica | D6: P1 | E6: P2 | F6: P3 | G6: P4 | H6: P5 | I6: P6 | J6: P7 | K6: P8 | L6: P9 | M6: P10 | O6: % | P6: Cal. | Q6: Res. | R6: ∑ | S6: Valoración
A7: 27. Estructura y funcionamiento del bienestar institucional | O7: =C11 -> #DIV/0! | Q7: =O7*P7 -> #DIV/0! | R7: =SUM(Q7:Q7) -> #DIV/0! | S7: =IF(R7>=4.1,"Cumple Plenamente",IF(R7>=3.1,"cumple Satisfactoriamente",IF(R7>=2.1,"Cumple Aceptablemente",IF(R7=0," ","No Cumple ")))) -> #DIV/0!
A10: Característica | B10: NIV | C10: % | D10: Justificación
A11: =A7 -> 27. Estructura y funcionamiento del bienestar institucional | B11: =AVERAGE(D7:M7) -> #DIV/0! | C11: =B11/SUM($B$11:$B$11) -> #DIV/0!

Sheet F10
A1: Factor | B1: % | C1: Justificación
A2: F10. COMUNIDAD DE PROFESORES | B2: =Res.!D42 -> #DIV/0!
D5: NIVEL DE IMPORTANCIA DE LA CARACTERÍSTICA | O5: VALORACIÓN
A6: Característica | D6: P1 | E6: P2 | F6: P3 | G6: P4 | H6: P5 | I6: P6 | J6: P7 | K6: P8 | L6: P9 | M6: P10 | O6: % | P6: Cal. | Q6: Res. | R6: ∑ | S6: Valoración
A7: 28. Derechos y deberes de los profesores | O7: =C15 -> 0.1 | Q7: =O7*P7 -> 0 | R7: =SUM(Q7:Q11) -> 0 | S7: =IF(R7>=4.1,"Cumple Plenamente",IF(R7>=3.1,"cumple Satisfactoriamente",IF(R7>=2.1,"Cumple Aceptablemente",IF(R7=0," ","No Cumple "))))
A8: 29. Planta profesoral | O8: =C16 -> 0.25 | Q8: =O8*P8 -> 0
A9: 30. Trayectoria profesoral | O9: =C17 -> 0.3 | Q9: =O9*P9 -> 0
A10: 31. Desarrollo profesoral | O10: =C18 -> 0.2 | Q10: =O10*P10 -> 0
A11: 32. Interacción académica de los profesores | O11: =C19 -> 0.15 | Q11: =O11*P11 -> 0
A14: Característica | B14: NIV | C14: % | D14: Justificación
A15: =A7 -> 28. Derechos y deberes de los profesores | B15: =AVERAGE(D7:M7) -> #DIV/0! | C15: 0.1
A16: =A8 -> 29. Planta profesoral | B16: =AVERAGE(D8:M8) -> #DIV/0! | C16: 0.25
A17: =A9 -> 30. Trayectoria profesoral | B17: =AVERAGE(D9:M9) -> #DIV/0! | C17: 0.3
A18: =A10 -> 31. Desarrollo profesoral | B18: =AVERAGE(D10:M10) -> #DIV/0! | C18: 0.2
A19: =A11 -> 32. Interacción académica de los profesores | B19: =AVERAGE(D11:M11) -> #DIV/0! | C19: 0.15

Sheet F11
A1: Factor | B1: % | C1: Justificación
A2: F11. COMUNIDAD DE ESTUDIANTES | B2: =Res.!D48 -> #DIV/0!
D5: NIVEL DE IMPORTANCIA DE LA CARACTERÍSTICA | O5: VALORACIÓN
A6: Característica | D6: P1 | E6: P2 | F6: P3 | G6: P4 | H6: P5 | I6: P6 | J6: P7 | K6: P8 | L6: P9 | M6: P10 | O6: % | P6: Cal. | Q6: Res. | R6: ∑ | S6: Valoración
A7: 33. Derechos y deberes de los estudiantes | O7: =C13 -> 0.2 | Q7: =O7*P7 -> 0 | R7: =SUM(Q7:Q9) -> 0 | S7: =IF(R7>=4.1,"Cumple Plenamente",IF(R7>=3.1,"cumple Satisfactoriamente",IF(R7>=2.1,"Cumple Aceptablemente",IF(R7=0," ","No Cumple "))))
A8: 34. Admisión y permanencia de los estudiantes | O8: =C14 -> 0.5 | Q8: =O8*P8 -> 0
A9: 35. Estímulos y apoyos para estudiantes | O9: =C15 -> 0.3 | Q9: =O9*P9 -> 0
A12: Característica | B12: NIV | C12: % | D12: Justificación
A13: =A7 -> 33. Derechos y deberes de los estudiantes | B13: =AVERAGE(D7:M7) -> #DIV/0! | C13: 0.2
A14: =A8 -> 34. Admisión y permanencia de los estudiantes | B14: =AVERAGE(D8:M8) -> #DIV/0! | C14: 0.5
A15: =A9 -> 35. Estímulos y apoyos para estudiantes | B15: =AVERAGE(D9:M9) -> #DIV/0! | C15: 0.3

Sheet F12
A1: Factor | B1: % | C1: Justificación
A2: F12. COMUNIDAD DE EGRESADOS | B2: =Res.!D52 -> #DIV/0!
D5: NIVEL DE IMPORTANCIA DE LA CARACTERÍSTICA | O5: VALORACIÓN
A6: Característica | D6: P1 | E6: P2 | F6: P3 | G6: P4 | H6: P5 | I6: P6 | J6: P7 | K6: P8 | L6: P9 | M6: P10 | O6: % | P6: Cal. | Q6: Res. | R6: ∑ | S6: Valoración
A7: 36. Seguimiento a egresados | O7: =C13 -> 0.4 | Q7: =O7*P7 -> 0 | R7: =SUM(Q7:Q9) -> 0 | S7: =IF(R7>=4.1,"Cumple Plenamente",IF(R7>=3.1,"cumple Satisfactoriamente",IF(R7>=2.1,"Cumple Aceptablemente",IF(R7=0," ","No Cumple "))))
A8: 37. Egresados y programas académicos | O8: =C14 -> 0.3 | Q8: =O8*P8 -> 0
A9: 38. Relación de los egresados con la Institución | O9: =C15 -> 0.3 | Q9: =O9*P9 -> 0
A12: Característica | B12: NIV | C12: % | D12: Justificación
A13: =A7 -> 36. Seguimiento a egresados | B13: =AVERAGE(D7:M7) -> #DIV/0! | C13: 0.4
A14: =A8 -> 37. Egresados y programas académicos | B14: =AVERAGE(D8:M8) -> #DIV/0! | C14: 0.3
A15: =A9 -> 38. Relación de los egresados con la Institución | B15: =AVERAGE(D9:M9) -> #DIV/0! | C15: 0.3

Sheet Res.
B2: PONDERACIÓN | J2: VALORACIÓN
B4: Factor | C4: Peso | D4: Peso Fac. | F4: Característica | G4: Calificación | H4: Peso Car. | J4: Cal. | K4: ∑ | L4: Valoración | N4: Res. x Fac.
B6: ='F1'!A2 -> F1. IDENTIDAD INSTITUCIONAL | C6: =AVERAGE(G6:G7) -> #DIV/0! | D6: =C6/C56 -> #DIV/0! | F6: ='F1'!A13 -> 1. Coherencia y pertinencia de la misión | G6: ='F1'!B13 -> #DIV/0! | H6: ='F1'!O7 -> 0 | J6: ='F1'!P7 -> 0 | K6: ='F1'!R7 -> 0 | L6: =IF(K6>=4.1,"Cumple Plenamente",IF(K6>=3.1,"Cumple Satisfactoriamente",IF(K6>=2.1,"Cumple Aceptablemente",IF(K6=0," ","No Cumple")))) | N6: =K6*D6 -> #DIV/0!
F7: ='F1'!A14 -> 2. Orientaciones y estrategias del Proyecto Educativo Institucional o lo que haga sus veces | G7: ='F1'!B14 -> #DIV/0! | H7: ='F1'!O8 -> 0 | J7: ='F1'!P8 -> 0
F8: 3. Formación Integral y Construcción de identidad | G8: ='F1'!B15 -> #DIV/0! | H8: ='F1'!O9 -> 0
B10: ='F2'!A2 -> F2. GOBIERNO INSTITUCIONAL Y TRANSPARENCIA | C10: =AVERAGE(G10:G12) -> #DIV/0! | D10: =C10/C56 -> #DIV/0! | F10: ='F2'!A13 -> 4. Buen gobierno y máximo órgano de gobierno | G10: ='F2'!B13 -> #DIV/0! | H10: ='F2'!O7 -> 0 | J10: ='F2'!P7 -> 0 | K10: ='F2'!R7 -> 0 | L10: =IF(K10>=4.1,"Cumple Plenamente",IF(K10>=3.1,"Cumple Satisfactoriamente",IF(K10>=2.1,"Cumple Aceptablemente",IF(K10=0," ","No Cumple")))) | N10: =K10*D10 -> #DIV/0!
F11: ='F2'!A14 -> 5. Relación congrupos de interés | G11: ='F2'!B14 -> #DIV/0! | H11: ='F2'!O8 -> 0 | J11: ='F2'!P8 -> 0
F12: ='F2'!A15 -> 6. Rendición de cuentas | G12: ='F2'!B15 -> #DIV/0! | H12: ='F2'!O9 -> 0 | J12: ='F2'!P9 -> 0
B14: ='F3'!A2 -> F3. DESARROLLO, GESTIÓN Y SOSTENIBILIDAD INSTITUCIONAL | C14: =AVERAGE(G14:G19) -> #DIV/0! | D14: =C14/C56 -> #DIV/0! | F14: ='F3'!A16 -> 7. Administración y gestión | G14: ='F3'!B16 -> #DIV/0! | H14: ='F3'!O7 -> 0 | J14: ='F3'!P7 -> 0 | K14: ='F3'!R7 -> 0 | L14: =IF(K14>=4.1,"Cumple Plenamente",IF(K14>=3.1,"Cumple Satisfactoriamente",IF(K14>=2.1,"Cumple Aceptablemente",IF(K14=0," ","No Cumple")))) | N14: =K14*D14 -> #DIV/0!
F15: ='F3'!A17 -> 8. Procesos de Comunicación | G15: ='F3'!B17 -> #DIV/0! | H15: ='F3'!O8 -> 0 | J15: ='F3'!P8 -> 0
F16: ='F3'!A18 -> 9. Capacidad de gestión | G16: ='F3'!B18 -> #DIV/0! | H16: ='F3'!O9 -> 0 | J16: ='F3'!P9 -> 0
F17: ='F3'!A19 -> 10. Recursos de apoyo académico | G17: ='F3'!B19 -> #DIV/0! | H17: ='F3'!O10 -> 0 | J17: ='F3'!P10 -> 0
F18: ='F3'!A20 -> 11. Infraestructura fisica y tecnologica | G18: ='F3'!B20 -> #DIV/0! | H18: ='F3'!O11 -> 0 | J18: ='F3'!P11 -> 0
F19: ='F3'!A21 -> 12. Recursos y gestión financiera | G19: ='F3'!B21 -> #DIV/0! | H19: ='F3'!O12 -> 0 | J19: ='F3'!P12 -> 0
B21: ='F4'!A2 -> F4. MEJORAMIENTO CONTINUO Y AUTORREGULACIÓN | C21: =AVERAGE(G21:G22) -> #DIV/0! | D21: =C21/C56 -> #DIV/0! | F21: ='F4'!A14 -> 13. Cultura de la Autoevaluación | G21: ='F4'!B14 -> #DIV/0! | H21: ='F4'!O7 -> 0.35 | J21: ='F4'!P7 -> 0 | K21: ='F4'!R7 -> 0 | L21: =IF(K21>=4.1,"Cumple Plenamente",IF(K21>=3.1,"Cumple Satisfactoriamente",IF(K21>=2.1,"Cumple Aceptablemente",IF(K21=0," ","No Cumple")))) | N21: =D21*K21 -> #DIV/0!
F22: ='F4'!A15 -> 14. Procesos de autorregulación | G22: ='F4'!B15 -> #DIV/0! | H22: ='F4'!O8 -> 0.2 | J22: ='F4'!P8 -> 0
F23: 15. Sistema Interno de Aseguramiento de la Calidad | G23: ='F4'!B16 -> #DIV/0! | H23: ='F4'!O9 -> 0.3
F24: 16. Evaluación de directivas, profesores y personal administrativo | G24: ='F4'!B17 -> #DIV/0! | H24: ='F4'!O10 -> 0.25
B26: ='F5'!A2 -> F5. ESTRUCTURA Y PROCESOS ACADÉMICOS | C26: =AVERAGE(G26:G29) -> #DIV/0! | D26: =C26/C56 -> #DIV/0! | F26: ='F5'!A14 -> 17. Componentes formativos | G26: ='F5'!B14 -> #DIV/0! | H26: ='F4'!O7 -> 0.35 | J26: ='F5'!P7 -> 0 | K26: ='F5'!R7 -> 0 | L26: =IF(K26>=4.1,"Cumple Plenamente",IF(K26>=3.1,"Cumple Satisfactoriamente",IF(K26>=2.1,"Cumple Aceptablemente",IF(K26=0," ","No Cumple")))) | N26: =K26*D26 -> #DIV/0!
F27: ='F5'!A15 -> 18. Componentes pedagógicos y de evaluación | G27: ='F5'!B15 -> #DIV/0! | H27: ='F4'!O8 -> 0.2 | J27: ='F5'!P8 -> 0
F28: ='F5'!A16 -> 19. Componente de interacción y relevancia social | G28: ='F5'!B16 -> #DIV/0! | H28: ='F4'!O9 -> 0.3 | J28: ='F5'!P9 -> 0
F29: ='F5'!A17 -> 20. Procesos de creación, modificación y ampliación de programas académicos | G29: ='F5'!B17 -> #DIV/0! | H29: ='F4'!O10 -> 0.25 | J29: ='F5'!P10 -> 0
B31: ='F6'!A2 -> F6. APORTES DE LA INVESTIGACIÓN, LA INNOVACIÓN, EL DESARROLLO TECNOLÓGICO Y LA CREACIÓN AL ENTORNO | C31: =AVERAGE(G31:G32) -> #DIV/0! | D31: =C31/C56 -> #DIV/0! | F31: ='F6'!A12 -> 21. Formación para la investigación, creación e innovación | G31: ='F6'!B12 -> #DIV/0! | H31: ='F6'!O7 -> #DIV/0! | J31: ='F6'!P7 -> 0 | K31: ='F6'!R7 -> #DIV/0! | L31: =IF(K31>=4.1,"Cumple Plenamente",IF(K31>=3.1,"Cumple Satisfactoriamente",IF(K31>=2.1,"Cumple Aceptablemente",IF(K31=0," ","No Cumple")))) -> #DIV/0! | N31: =K31*D31 -> #DIV/0!
F32: ='F6'!A13 -> 22. Investigación, desarrollo tecnológico, innovación y creación | G32: ='F6'!B13 -> #DIV/0! | H32: ='F6'!O8 -> #DIV/0! | J32: ='F6'!P8 -> 0
B34: ='F7'!A2 -> F7. IMPACTO SOCIAL | C34: =AVERAGE(G34:G35) -> #DIV/0! | D34: =C34/C56 -> #DIV/0! | F34: ='F7'!A12 -> 23. Institución y entorno | G34: ='F7'!B12 -> #DIV/0! | H34: ='F7'!O7 -> 0.6 | J34: ='F7'!P7 -> 0 | K34: ='F7'!R7 -> 0 | L34: =IF(K34>=4.1,"Cumple Plenamente",IF(K34>=3.1,"Cumple Satisfactoriamente",IF(K34>=2.1,"Cumple Aceptablemente",IF(K34=0," ","No Cumple")))) | N34: =K34*D34 -> #DIV/0!
F35: ='F7'!A13 -> 24. Impacto cultural y artístico | G35: ='F7'!B13 -> #DIV/0! | H35: ='F7'!O8 -> 0.4 | J35: ='F7'!P8 -> 0
B37: ='F8'!A2 -> F8. VISIBILIDAD NACIONAL E INTERNACIONAL | C37: =AVERAGE(G37:G38) -> #DIV/0! | D37: =C37/C56 -> #DIV/0! | F37: ='F8'!A12 -> 25. Inserción de la institución en contextos académicos nacionales e internacionales | G37: ='F8'!B12 -> #DIV/0! | H37: ='F8'!O7 -> 0.5 | J37: ='F8'!P7 -> 0 | K37: ='F8'!R7 -> 0 | L37: =IF(K37>=4.1,"Cumple Plenamente",IF(K37>=3.1,"Cumple Satisfactoriamente",IF(K37>=2.1,"Cumple Aceptablemente",IF(K37=0," ","No Cumple")))) | N37: =K37*D37 -> #DIV/0!
F38: ='F8'!A13 -> 26. Relaciones externas de profesores y estudiantes | G38: ='F8'!B13 -> #DIV/0! | H38: ='F8'!O8 -> 0.5 | J38: ='F8'!P8 -> 0
B40: ='F9'!A2 -> F9. BIENESTAR INSTITUCIONAL | C40: =AVERAGE(G40:G40) -> #DIV/0! | D40: =C40/C56 -> #DIV/0! | F40: ='F9'!A11 -> 27. Estructura y funcionamiento del bienestar institucional | G40: ='F9'!B11 -> #DIV/0! | H40: ='F9'!O7 -> #DIV/0! | J40: ='F9'!P7 -> 0 | K40: ='F9'!R7 -> #DIV/0! | L40: =IF(K40>=4.1,"Cumple Plenamente",IF(K40>=3.1,"Cumple Satisfactoriamente",IF(K40>=2.1,"Cumple Aceptablemente",IF(K40=0," ","No Cumple")))) -> #DIV/0! | N40: =K40*D40 -> #DIV/0!
B42: ='F10'!A2 -> F10. COMUNIDAD DE PROFESORES | C42: =AVERAGE(G42:G44) -> #DIV/0! | D42: =C42/C56 -> #DIV/0! | F42: ='F10'!A15 -> 28. Derechos y deberes de los profesores | G42: ='F10'!B15 -> #DIV/0! | H42: ='F10'!O7 -> 0.1 | J42: ='F10'!P7 -> 0 | K42: ='F10'!R7 -> 0 | L42: =IF(K42>=4.1,"Cumple Plenamente",IF(K42>=3.1,"Cumple Satisfactoriamente",IF(K42>=2.1,"Cumple Aceptablemente",IF(K42=0," ","No Cumple")))) | N42: =K42*D42 -> #DIV/0!
F43: ='F10'!A16 -> 29. Planta profesoral | G43: ='F10'!B16 -> #DIV/0! | H43: ='F10'!O8 -> 0.25 | J43: ='F10'!P8 -> 0
F44: ='F10'!A17 -> 30. Trayectoria profesoral | G44: ='F10'!B17 -> #DIV/0! | H44: ='F10'!O9 -> 0.3 | J44: ='F10'!P11 -> 0
F45: 31. Desarrollo profesoral | G45: ='F10'!B18 -> #DIV/0! | H45: ='F10'!O10 -> 0.2
F46: 32. Interacción académica de los profesores | G46: ='F10'!B19 -> #DIV/0! | H46: ='F10'!O11 -> 0.15
B48: ='F11'!A2 -> F11. COMUNIDAD DE ESTUDIANTES | C48: =AVERAGE(G48:G50) -> #DIV/0! | D48: =C48/C56 -> #DIV/0! | F48: ='F11'!A13 -> 33. Derechos y deberes de los estudiantes | G48: ='F11'!B13 -> #DIV/0! | H48: ='F11'!O7 -> 0.2 | J48: ='F11'!P7 -> 0 | K48: ='F11'!R7 -> 0 | L48: =IF(K48>=4.1,"Cumple Plenamente",IF(K48>=3.1,"Cumple Satisfactoriamente",IF(K48>=2.1,"Cumple Aceptablemente",IF(K48=0," ","No Cumple")))) | N48: =K48*D48 -> #DIV/0!
F49: ='F11'!A14 -> 34. Admisión y permanencia de los estudiantes | G49: ='F11'!B14 -> #DIV/0! | H49: ='F11'!O8 -> 0.5 | J49: ='F11'!P8 -> 0
F50: ='F11'!A15 -> 35. Estímulos y apoyos para estudiantes | G50: ='F11'!B15 -> #DIV/0! | H50: ='F11'!O9 -> 0.3 | J50: ='F11'!P9 -> 0
B52: ='F12'!A2 -> F12. COMUNIDAD DE EGRESADOS | C52: =AVERAGE(G52:G54) -> #DIV/0! | D52: =C52/C56 -> #DIV/0! | F52: ='F12'!A13 -> 36. Seguimiento a egresados | G52: ='F12'!B13 -> #DIV/0! | H52: ='F12'!O7 -> 0.4 | J52: ='F12'!P7 -> 0 | K52: ='F12'!R7 -> 0 | L52: =IF(K52>=4.1,"Cumple Plenamente",IF(K52>=3.1,"Cumple Satisfactoriamente",IF(K52>=2.1,"Cumple Aceptablemente",IF(K52=0," ","No Cumple")))) | N52: =K52*D52 -> #DIV/0!
F53: 37. Egresados y programas académicos | G53: 8 | H53: ='F12'!O8 -> 0.3
F54: ='F12'!A15 -> 38. Relación de los egresados con la Institución | G54: ='F12'!B15 -> #DIV/0! | H54: ='F12'!O9 -> 0.3 | J54: ='F12'!P9 -> 0
...

Sheet D.Car.
B2: Característica | D2: Elija
B4: NOMBRE | D4: DESCRIPCIÓN | M4: ASPECTOS A EVALUAR
B6: =IFERROR(VLOOKUP(D2,Hoja2!A1:D39,2,0)," ") | D6: =IFERROR(VLOOKUP(D2,Hoja2!A1:D39,3,0)," ") | M6: =IFERROR(VLOOKUP(D2,Hoja2!A1:D39,4,0)," ")

Sheet Hoja1
A1: 0 | B1: 1 | C1: 0 | D1: 1 | E1: Elija | F1: Elija | G1: DD | H1: MM | I1: AAAA | J1: Elija | K1: Elija
A2: 1 | B2: 2 | C2: 1 | D2: 1.1 | E2: 1 | F2: Administración de Empresas Agropecuarias | G2: 1 | H2: Enero | I2: 2017 | J2: I | K2: Popayán
A3: 2 | B3: 3 | C3: 1.1 | D3: 1.2 | E3: 2 | F3: Administración de Empresas | G3: 2 | H3: Febrero | I3: 2018 | J3: II | K3: Santander de Quilichao
A4: 3 | B4: 4 | C4: 1.2 | D4: 1.3 | E4: 3 | F4: Arquitectura | G4: 3 | H4: Marzo | I4: 2019
A5: 4 | B5: 5 | C5: 1.3 | D5: 1.4 | E5: 4 | F5: Comunicación Social | G5: 4 | H5: Abril | I5: 2020
A6: 5 | B6: 6 | C6: 1.4 | D6: 1.5 | E6: 5 | F6: Contaduría Pública | G6: 5 | H6: Mayo | I6: 2021
A7: 6 | B7: 7 | C7: 1.5 | D7: 1.6 | E7: 6 | F7: Derecho | G7: 6 | H7: Junio | I7: 2022
A8: 7 | B8: 8 | C8: 1.6 | D8: 1.7 | E8: 7 | F8: Ecología | G8: 7 | H8: Julio | I8: 2023
A9: 8 | B9: 9 | C9: 1.7 | D9: 1.8 | E9: 8 | F9: Economía | G9: 8 | H9: Agosto | I9: 2024
A10: 9 | B10: 10 | C10: 1.8 | D10: 1.9 | E10: 9 | F10: Ingeniería de Sistemas | G10: 9 | H10: Septiembre | I10: 2025
A11: 10 | C11: 1.9 | D11: 2 | E11: 10 | F11: Ingeniería Industrial | G11: 10 | H11: Octubre | I11: 2026
C12: 2 | D12: 2.1 | E12: 11 | F12: Licenciatura en Educación Básica y Cultural | G12: 11 | H12: Noviembre | I12: 2027
C13: 2.1 | D13: 2.2 | E13: 12 | F13: Psicología | G13: 12 | H13: Diciembre | I13: 2028
C14: 2.2 | D14: 2.3 | E14: 13 | F14: Trabajo Social | G14: 13
C15: 2.3 | D15: 2.4 | E15: 14 | F15: Administración de Empresas Agropecuarias - Virtual | G15: 14
C16: 2.4 | D16: 2.5 | E16: 15 | F16: Administración de Empresas - Virtual | G16: 15
C17: 2.5 | D17: 2.6 | E17: 16 | F17: Comunicación Social - Virtual | G17: 16
C18: 2.6 | D18: 2.7 | E18: 17 | G18: 17
C19: 2.7 | D19: 2.8 | E19: 18 | G19: 18
C20: 2.8 | D20: 2.9 | E20: 19 | G20: 19
C21: 2.9 | D21: 3 | E21: 20 | G21: 20
C22: 3 | D22: 3.1 | E22: 21 | G22: 21
C23: 3.1 | D23: 3.2 | E23: 22 | G23: 22
C24: 3.2 | D24: 3.3 | E24: 23 | G24: 23
C25: 3.3 | D25: 3.4 | E25: 24 | G25: 24
C26: 3.4 | D26: 3.5 | E26: 25 | G26: 25
C27: 3.5 | D27: 3.6 | E27: 26 | G27: 26
C28: 3.6 | D28: 3.7 | E28: 27 | G28: 27
C29: 3.7 | D29: 3.8 | E29: 28 | G29: 28
... C32: 4 | D32: 4.1 | E32: 31 | G32: 31
C33: 4.1 | D33: 4.2 | E33: 32
C34: 4.2 | D34: 4.3 | E34: 33
C35: 4.3 | D35: 4.4 | E35: 34
C36: 4.4 | D36: 4.5 | E36: 35
C37: 4.5 | D37: 4.6 | E37: 36
C38: 4.6 | D38: 4.7 | E38: 37
C39: 4.7 | D39: 4.8 | E39: 38
C40: 4.8 | D40: 4.9 | E40: 39
C41: 4.9 | D41: 5 | E41: 40
C42: 5 | E42: 41
...

Sheet Hoja2
A1: # | B1: Característica | C1: Descripción | D1: Aspectos a Evaluar
A2: 1 | B2: 1. COHERENCIA Y PERTINENCIA DE LA MISIÓN | C2: La institución de alta calidad se reconoce porque cuenta con una misión que es coherente y pertinente con el medio social, cultural y ambiental, de acuerdo con su naturaleza jurídica, identidad, tipología y contexto. Dicha misión es dinámica en la medida que implica una evaluación sistemática, es coherente y está articulada con los cambios del entorno; a su vez, debe desplegarse en los objetivos y los procesos académicos y administrativos | D2: a) Evidencia de la coherencia y pertinencia de la misión con la naturaleza jurídica, tradición, objetivos y logros institucionales; el entorno social, cultural, ambiental y productivo; los procesos académicos y administrativos; la información que suministra y la imagen que da a la sociedad. b) Demostración de los procesos de reflexión colectiva y valoración sistemática en relación con los principios y apuestas misionales y la relación con el entorno. c) Demostración de los cambios implementados, si los hubiere, en la misión y visión institucional como resultado de las evaluaciones sistemáticas y periódicas realizadas por la institución en el tiempo, y su impacto en el medio social, cultural y ambiental.
A3: 2 | B3: 2. ORIENTACIONES Y ESTRATEGIAS DEL PROYECTO EDUCATIVO INSTITUCIONAL O LO QUE HAGA SUS VECES | C3: La institución de alta calidad se reconoce porque cuenta con un proyecto educativo institucional, o lo que haga sus veces, como fundamento para el gobierno institucional, la planeación, la administración, la evaluación y la autorregulación, y el desarrollo y proyección de sus labores formativas, académicas, docentes, científicas, culturales y de extensión. De igual manera, es el referente en la definición de los requerimientos para el desarrollo del bienestar institucional y la demanda de los recursos físicos, tecnológicos y financieros, así como en el fortalecimiento de las relaciones nacionales e internacionales. Lo anterior, de acuerdo con su naturaleza jurídica, identidad, misión, tipología y un contexto determinado | D3: a) Existencia de procesos de actualización de las orientaciones y estrategias del proyecto educativo institucional o lo que haga sus veces, en correspondencia con su naturaleza jurídica, organización, administración, evaluación y autorregulación de la docencia, investigación, y extensión o proyección social, así como del bienestar, la internacionalización, los recursos físicos, tecnológicos y financieros, y el análisis del impacto de dichos procesos de actualización en el mejoramiento del desarrollo de las funciones sustantivas anteriormente mencionadas. b) Evidencia de acciones orientadas a reflexionar con la comunidad académica y la sociedad sobre el proyecto educativo institucional, o lo que haga sus veces, los ajustes a este y el resultado de estas valoraciones. c) Apreciación por parte de la comunidad académica en relación con los estudios orientados a evaluar la pertinencia del proyecto educativo institucional con las dinámicas y prácticas para la organización, toma de decisiones, administración, evaluación y autorregulación de las labores académicas, formativas, docentes, científicas, culturales y de extensión, así como del bienestar, la internacionalización y los recursos físicos, tecnológicos y financieros. Incorporación de los análisis de apreciaciones sistematizadas y periódicas en planes de mejoramiento institucional.
A4: 3 | B4: 3. FORMACIÓN INTEGRAL Y CONSTRUCCIÓN DE IDENTIDAD | C4: La institución de alta calidad se reconoce porque, además de una formación académica y profesional de alto nivel, brinda oportunidades para el desarrollo personal en todas las dimensiones del ser humano, al tiempo que fortalece la comunidad académica en un ambiente que incentiva el bienestar institucional, de acuerdo con su identidad. Todo lo anterior se evidencia en el reconocimiento de la identidad institucional por parte de la sociedad en general, a través de la impronta común que la comunidad académica demuestra en su quehacer cotidiano y en el ejercicio de su profesión | D4: a) Apreciación por parte de la comunidad académica en relación con la existencia de orientaciones y estrategias para el fomento de la formación integral de los estudiantes y el fortalecimiento de la comunidad académica en un ambiente institucional adecuado, incluyente, de responsabilidad social y con valores éticos. Incorporación de los análisis de apreciaciones sistematizadas y periódicas en planes de mejoramiento institucional. b) Apreciación por parte de la comunidad académica y los grupos de interés de la institución en relación con las evidencias que permiten corroborar ante la sociedad que sus egresados reciben una formación integral y desarrollo de su pensamiento crítico. Incorporación de los análisis de apreciaciones sistematizadas y periódicas en planes de mejoramiento institucional. c) Apreciación por parte de la comunidad académica y de los grupos de interés de la institución, relacionada con la evidencia de las estrategias y programas que la institución implementa para propiciar la formación integral de los estudiantes, la consolidación de su identidad y el reconocimiento social. Incorporación de los análisis de apreciaciones sistematizadas y periódicas en planes de mejoramiento institucional. d) Presentación resultados de estudios sistemáticos y periódicos que evalúen el cumplimiento del logro de una formación integral y pensamiento crítico de sus estudiantes. e) Existencia de orientaciones y estrategias para el fomento de la formación integral de los estudiantes y el fortalecimiento de la comunidad académica en un ambiente institucional que brinde las condiciones adecuadas para hacerlo y sea además incluyente
A5: 4 | B5: 4. BUEN GOBIERNO Y MÁXIMO ORGANO DE GOBIERNO | C5: La institución de alta calidad se reconoce porque las orientaciones estratégicas y las decisiones de política y desarrollo institucional se toman en su máximo órgano de gobierno, el cual cuenta con la participación, entre otros, de representantes de los sectores externos, de los profesores y los estudiantes, en coherencia con su naturaleza jurídica, identidad, misión y tipología | D5: a) Apreciación por parte de los miembros de la comunidad académica de los mecanismos y formas de convocatoria, selección y participación de la representación democrática de estudiantes, profesores y egresados en el máximo órgano de gobierno de la institución, así como de los sectores de la sociedad. Incorporación de los análisis de apreciaciones sistematizadas y periódicas en planes de mejoramiento institucional. b) Evaluación y análisis sistemáticos y periódicos del impacto de la aplicación de las normas institucionales, según su naturaleza jurídica, y del código de buen gobierno en el funcionamiento del máximo órgano de dirección y demás órganos colegiados. Incorporación de los resultados de dichos análisis en planes de mejoramiento institucional. c) Demostración de acciones de mejora a partir de la evaluación sistemática del funcionamiento y de las decisiones tomadas por el máximo órgano de gobierno y demás órganos colegiados. d) Apreciación de la comunidad académica sobre la eficiencia, trasparencia y buenas prácticas de los órganos de gobierno institucional y sus integrantes.
A6: 5 | B6: 5. RELACIÓN CON GRUPOS DE INTERÉS | C6: La Institución de alta calidad se reconoce porque demuestra la existencia de múltiples relaciones e interacciones con los grupos de interés de la sociedad y los actores del Sistema de Aseguramiento de la Calidad de la Educación Superior. Lo anterior en consonancia con la naturaleza jurídica, identidad, misión y tipología de las instituciones, de manera que se articulen las políticas de la educación y del desarrollo en general, mediante la generación de reflexiones y prospectivas que contribuyan a las labores académicas, formativas, docentes, científicas, culturales y de extensión | D6: a) Presentación de los resultados de los procesos participativos y colegiados de los gruposde interés en la construcción del proyecto educativo institucional o lo que haga sus veces y de la planeación institucional, y la construcción de sus respectivos planes estratégicos. b) Presentación de análisis sistemáticos y periódicos de los resultados derivados de la existencia de estamentos, políticas, estrategias, documentos que orientan la articulación y participación de la institución con diversos grupos de interés. Incorporación de los resultados de dichos análisis en planes de mejoramiento institucional. c) Demostración del número de organizaciones de la sociedad en la región, el país y del extranjero con las que ha establecido relación, identificar el grado e intensidad de dicha relación y análisis de los aportes de dichas organizaciones en el buen cumplimiento de las funciones yapuestas misionales declaradas por la institución. d) Evidencia del nivel y eficiencia de la comunicación bidireccional con sus grupos de interés.
A7: 6 | B7: 6. RENDICIÓN DE CUENTAS | C7: La institución de alta calidad se reconoce porque demuestra que desarrolla mecanismos de rendición de cuentas periódicos a todos sus grupos de interés y a la comunidad académica, mediante procesos y mecanismos reflexivos, estructurados y documentados, que permiten un análisis objetivo de los compromisos establecidos | D7: a) Presentación de la evaluación y análisis de los mecanismos de rendición de cuentas en los diferentes niveles que evidencian espacios de reflexión, estructurados y documentados, en donde participan la comunidad académica y la sociedad, y sus resultados se incorporan en la planeación, mejoramiento continuo y en la toma de decisiones. b) Demostración y presentación, de forma sistemática y periódica, de las opiniones brindadas por la comunidad académica, recogidas a través de canales institucionales de comunicación propiciados por la institución para la rendición de cuentas. c) Evidencia documental, testimonial y estadística sobre la existencia de mecanismos de rendición de cuentas y su impacto en la mejora institucional.
A8: 7 | B8: 7. ADMINISTRACIÓN Y GESTIÓN | C8: La institución de alta calidad se reconoce porque demuestra que su administración y su gestión están orientadas al apoyo y acompañamiento para una eficiente ejecución de sus labores formativas, académicas, docentes, científicas, culturales y de extensión, definidas por ella en el marco de la constitución y la ley, según su naturaleza jurídica, tipología, identidad y misión. Asimismo, la institución desarrolla políticas de estímulo, promoción y cualificación de sus funcionarios, e implementa un modelo de arquitectura institucional que se expresa en la articulación de la organización, los procesos y los cargos, con un seguimiento periódico que le permite evidenciar oportunidades de mejora e implementarlas | D8: a) Presentación de análisis sistemáticos y periódicos de los resultados de la aplicación de políticas administrativas orientadas al desarrollo de la docencia, la investigación y la extensión o proyección social. Incorporación de las recomendaciones de dichos análisis en procesos de mejoramiento. b) Presentación del análisis sistemático y periódico de la aplicación de políticas de estímulos, capacitación y promoción del personal administrativo que contribuyan a la cualificación del desempeño de sus actividades y procesos. Incorporación de los resultados de dichos análisis en procesos de mejoramiento. c) Evidencia de sistemas de información y de gestión documental incorporados, acorde con la normativa y trazabilidad de los procesos documentales propios de la historia académica de los estudiantes, historia académica y laboral de profesores e historia laboral del personal administrativo, así como la memoria de la gestión administrativa. d) Apreciación por parte de los miembros de la comunidad académica acerca de la eficiencia de la estructura y función administrativa en el desarrollo de la docencia, investigación, internacionalización, extensión y proyección social. Incorporación de las recomendaciones de los análisis sistemáticos y periódicos de dichas apreciaciones en planes de mejoramiento institucional. e) Presentación de análisis sistemáticos y periódicos de los resultados de la aplicación de políticas de estímulos, capacitación y promoción del personal administrativo que contribuyan a la cualificación del desempeño de los funcionarios en el ejercicio de sus actividades y procesos. Incorporación de las recomendaciones de dichos análisis en procesos de mejoramiento.
A9: 8 | B9: 8. PROCESOS DE COMUNICACIÓN | C9: La institución de alta calidad se reconoce porque demuestra que mantiene, con responsabilidad y alta cobertura, procesos y mecanismos de comunicación eficientes, actualizados, que promueven y garantizan el derecho de acceso a la información y la protección de datos, con observancia de los enfoques diferenciales, de manera que la información y los datos sean apropiados por los destinatarios | D9: a) Presentación de análisis sistemáticos y periódicos de la efectividad de los sistemas de información integrados y de mecanismos eficaces en la comunicación interna y externa de la institución. Incorporación de los resultados de dichos análisis en procesos de mejoramiento. b) Evidencia del sitio web institucional, debidamente actualizado para mantener informados a la comunidad y a los usuarios sobre la oferta formativa, las dinámicas institucionales y los actores que la conforman, de acuerdo con la normatividad vigente. c) Demostración de canales de comunicación de la institución que evidencien ampliación de la cobertura, accesibilidad y calidad, así como, su eficiencia y permanente actualización tecnológica. d) Apreciación por parte de los miembros de la comunidad académica de la pertinencia, accesibilidad y usabilidad de la plataforma tecnológica adecuada para garantizar la conectividad a todos los miembros de la comunidad académica. Incorporación de los resultados de estos análisis de apreciaciones sistematizadas y periódicas en planes de mejoramiento institucional. e) Existencia de mecanismos de comunicación con enfoque diferencial que brinden facilidad y oportunidad para que la población institucional tenga acceso a la información. f) Apreciación por parte de los miembros de la comunidad académica acerca de la existencia de políticas, mecanismos, plataformas, medios de comunicación y recursos humanos que le permitan mantener interconexión y a los agentes externos acceder a información pertinente, actualizada y veraz sobre las políticas, servicios, actores y dinámicas institucionales. Incorporación de los resultados de los análisis de estas apreciaciones en planes de mejoramiento institucional.
A10: 9 | B10: 9. CAPACIDAD DE GESTIÓN | C10: La institución de alta calidad se reconoce porque demuestra que la gestión se ejerce con liderazgo y que sus orientaciones están claramente definidas, son conocidas por los distintos estamentos y contribuyen efectivamente a la estabilidad administrativa de la institución y a la continuidad de sus políticas académicas asociadas a currículo, resultados de aprendizaje, créditos y actividades, políticas de gestión institucional y bienestar, y políticas de investigación, innovación y creación | D10: a) Apreciación por parte de los miembros de la comunidad académica en relación con la estructura organizacional y administrativa coherente con las características institucionales y su proyecto educativo institucional o lo que haga sus veces. Incorporación de los análisis de apreciaciones sistematizadas y periódicas en planes de mejoramiento institucional. b) Apreciación por parte de los miembros de la comunidad universitaria acerca del liderazgo, integridad e idoneidad de los responsables de la dirección de la institución y sus dependencias. Incorporación de los análisis de apreciaciones sistematizadas y periódicas en planes de mejoramiento institucional. c) Evidencia de la coherencia de las actuaciones de los responsables de la institución y sus dependencias con los compromisos derivados de la misión y del proyecto educativo institucional o lo que haga sus veces. d) Apreciación por parte de los miembros de la comunidad académica, en relación con los mecanismos transparentes para la designación de los cargos de dirección y asignación de responsabilidades, funciones, roles y de los procedimientos que deben seguirse dentro de la institución. Incorporación de los análisis de apreciaciones sistematizadas y periódicas en planes de mejoramiento institucional.
A11: 10 | B11: 10. RECURSOS DE APOYO ACADÉMICO | C11: La institución de alta calidad se reconoce porque demuestra que cuenta con la dotación de equipos, mobiliario, plataformas tecnológicas, sistemas informáticos y lo que haga sus veces, recursos bibliográficos físicos y/o digitales, bases de datos, recursos de aprendizaje e información, que garantizan la disponibilidad, el acceso, la adaptabilidad y aceptabilidad en los ambientes de aprendizaje físicos y virtuales de que dispone. Asimismo, atiende los requerimientos particulares de la comunidad académica para que estos recursos sean utilizados apropiadamente en el desarrollo de las labores formativas, académicas, docentes, científicas, culturales y de extensión, dando alcance a los diferentes niveles de formación y modalidades de sus programas académicos, en correspondencia con su naturaleza jurídica, identidad, misión, tipología y contexto regional | D11: a) Evidencia de políticas, recursos y presupuestos de inversión en equipos de laboratorio, sitios de práctica, bibliotecas, recursos didácticos y demás elementos para garantizar la calidad del proceso formativo, teniendo en cuenta directrices nacionales para la inclusión, entre otros. b) Apreciación por parte de profesores y estudiantes acerca de las colecciones bibliográficas, documentales y de archivo, bases de datos y revistas suficientes para la capacidad de la institución, pertinentes y actualizadas para respaldar las labores académicas, formativas, de investigación, culturales y de extensión. Incorporación de los análisis de apreciaciones sistematizadas y periódicas en planes de mejoramiento institucional. c) Apreciación por parte de los miembros de la comunidad académica, acerca de la accesibilidad, disponibilidad, pertinencia y calidad de los laboratorios y sitios de práctica para las labores académicas de la institución (docencia, investigación, extensión o proyección social).Incorporación de los análisis de apreciaciones sistematizadas y periódicas en planes de mejoramiento institucional. d) Apreciación por parte de los miembros de la comunidad académica acerca de la existencia de mecanismos para la compra, mantenimiento, renovación y acceso a los equipos, mobiliario, plataformas tecnológicas, sistemas informáticos y lo que haga sus veces, recursos bibliográficos físicos y/o digitales, bases de datos y recursos de aprendizaje e información, acordes con los diferentes niveles de formación y modalidades de sus programas académicos, en correspondencia con su naturaleza jurídica, identidad, misión, tipología y contexto regional. Incorporación de los análisis de apreciaciones sistematizadas y periódicas en planes de mejoramiento institucional.
A12: 11 | B12: 11. DESARROLLO PROFESORAL | C12: La institución de alta calidad se reconoce porque demuestra la efectividad de una infraestructura física y tecnológica con espacios físicos y virtuales e instalaciones para el desarrollo de las labores formativas, académicas, docentes, científicas, culturales y de extensión en ambientes de bienestar | D12: a) Evidencia del cumplimiento de las normas técnicas que garanticen suficiencia, seguridad, salubridad, iluminación, disponibilidad, dotación, facilidades de transporte y acceso a las áreas académicas, administrativas, recreativas y deportivas. b) Evidencia de disponibilidad de espacios incluyentes como rampas, ascensores, señalización para personas en condición de discapacidad visual o de movilidad, entre otros. c) Evidencia de la disponibilidad de ambientes tecnológicos incluyentes para el apoyo a personasen condición de discapacidad visual, auditiva o de movilidad, entre otros. d) Evidencia de mediciones de la capacidad instalada y su uso o carga sostenible en el tiempo. e) Apreciación por parte de los miembros de la comunidad académica, acerca de la calidad, disponibilidad y accesibilidad de los distintos ambientes de aprendizaje propios de las modalidades de oferta académica que declarala institución, para el buen desarrollo de las distintas actividades curriculares y extracurriculares, así como de las asociadas con el bienestar general de sus miembros en ambientes institucionales. Incorporación de los análisis de apreciaciones sistematizadas y periódicas en planes de mejoramiento institucional.
A13: 12 | B13: 12. RECURSOS Y GESTIÓN FINANCIERA | C13: Una institución de alta calidad de muestra que cuenta con patrimonio propio, solidez financiera y una asignación apropiada de recursos financieros para la operación y la inversión, de acuerdo con el desarrollo de las labores formativas, académicas, docentes, científicas, culturales y de extensión, en coherencia con su naturaleza jurídica, tipología e identidad institucional y con las modalidades en que ofrece sus programas académicos. En consecuencia, la Institución planea, ejecuta y proyecta las asignaciones presupuestales de acuerdo con las exigencias previstas en los procesos de planeación y mejoramiento continuo. A su vez, la Institución cuenta con mecanismos para la revisión periódica en el manejo de los recursos financieros que demuestren responsabilidad, eficiencia, transparencia y sostenibilidad. Asimismo, demuestra que implementa estrategias para la diversificación de ingresos y optimización de gastos | D13: a) Presentación de información acerca de las fuentes de financiamiento, los recursos provenientes del Estado, otras fuentes externas y recursos propios. b) Demostración de estabilidad y solidez financiera que garantice el cumplimiento, a mediano plazo, de las acciones propuestas en el plan de desarrollo institucional, complementada con ejercicios de auditoría y control fiscal. c) Apreciación por parte de los miembros de la comunidad académica en relación con las políticas y estrategias para la asignación, ejecución y evaluación presupuestal, y de administración financiera, en atención al cumplimiento del proyecto educativo institucional o lo que haga sus veces, y el logro de las metas del plan de desarrollo institucional. d) Incorporación de los análisis de apreciaciones sistematizadas y periódicas en planes de mejoramiento institucional. e) Demostración de la reinversión de sus excedentes en su desarrollo misional y la cualificación de sus bienes y servicios. f) Evidencia de la gestión para la diversificación de las fuentes de ingreso que contribuyan a la estabilidad financiera y al desarrollo de la institución, de acuerdo con sus planes de desarrollo.
... A32: 31 | B32: 31. DESARROLLO PROFESORAL | C32: La institución deberá demostrar que aplica políticas y adelanta programas de desarrollo profesoral, así como de reconocimiento al ejercicio calificado de las labores formativas, académicas, docentes, científicas, culturales y de extensión, de conformidad con los objetivos de la educación superior y de la institución. Estos programas deben incluir a todos los profesores vinculados a la institución por las distintas formas de contratación y en todas las modalidades. El desarrollo profesoral debe involucrar el desenvolvimiento en habilidades y destrezas pedagógicas necesarias para atender a los estudiantes que ingresan a la Institución, de acuerdo con las modalidades de los programas académicos en los cuales participan | D32: a) Demostración de los resultados y mediciones que ilustren los impactos de la política institucional en la cualificación profesional y pedagógica de sus profesores. b) Apreciación por parte de los miembros de la comunidad académica de la institución, en relación con la existencia, cobertura, calidad y pertinencia de los programas de desarrollo profesoral. Incorporación de los análisis de apreciaciones sistematizadas y periódicas en planes de mejoramiento institucional. c) Apreciación por parte de los miembros de la comunidad académica de la institución, en relación con la aplicación de los criterios de reconocimiento y estímulo al ejercicio calificado de las labores formativas, académicas, docentes, científicas, culturales y de extensión. Incorporación de los análisis de apreciaciones sistematizadas y periódicas en planes de mejoramiento institucional. d) Apreciación por parte de los miembros de la comunidad académica de la institución, en relación con las evidencias de las evaluaciones realizadas a la normativa sobre profesores, teniendo en cuenta la naturaleza jurídica institucional, su eficiencia, transparencia y eficacia para el desarrollo profesoral. Incorporación de los análisis de apreciaciones sistematizadas y periódicas en planes de mejoramiento institucional. e) Apreciación por parte de los miembros de la comunidad académica de la institución, en relación con las evidencias de las capacitaciones realizadas a los profesores de la institución y sus resultados. Incorporación de los análisis de apreciaciones sistematizadas y periódicas en planes de mejoramiento institucional.
A33: 32 | B33: 32. INTERACCIÓN ACADÉMICA DE LOS PROFESORES | C33: La institución deberá demostrar que aplica políticas para promover la interacción de sus profesores con comunidades académicas del orden nacional e internacional, en coherencia con su naturaleza jurídica, identidad, misión y tipología, así como con el nivel y las modalidades de sus programas académicos, para lo cual incluye dentro de su plan de desarrollo profesoral el fortalecimiento de habilidades y competencias necesarias para interactuar y pertenecer a redes de carácterglobal, local y regional. | D33: a) Presentación del análisis sistemático y periódico por parte de los miembros de la comunidad académica de la institución, en relación con la existencia y desarrollo de políticas y estrategias orientadas a facilitar la constitución de comunidades académicas en la institución y su interacción con otras homólogas del orden nacional e internacional. Incorporación de los resultados de los análisis en planes de mejoramiento institucional. b) Presentación del análisis sistemático y periódico por parte de los miembros de la comunidad académica de la institución, en relación con el estado de la interacción académica del profesorado por áreas de conocimiento, con comunidades académicas nacionales y extranjeras. Incorporación de los resultados de los análisis en planes de mejoramiento institucional. c) Evidencia de resultados de los estudios realizados sobre la pertinencia y efectividad de la interacción académica del profesorado con comunidades académicas nacionales y extranjeras. Incorporación del análisisde los resultados en planes de mejoramiento institucional. d) Evidencia de resultados de la interacción y participación de los profesores de la institución en convenios académicos, a nivel nacional e internacional. | F33: Escala de Valoración
A34: 33 | B34: 33. DERECHOS YD EBERES DE LOS ESTUDIANTES | C34: La institución deberá demostrar que aplica las disposiciones establecidas en el estatuto o reglamento estudiantil en el que se expresan, entre otros aspectos, sus derechos y deberes, el régimen disciplinario y los criterios académicos de ingreso, permanencia, promoción, transferencia y graduación en coherencia con los distintos niveles de formación y modalidades de los programas académicos. La institución deberá demostrar que tiene un compromiso permanente y sistemático con el ciclo de vida del estudiante en la institución y que, por lo tanto, acompaña su proceso formativo e incentiva su interés por aprendizaje a lo largo de la vida. | D34: a) Evidencia de la existencia y aplicación de un reglamento estudiantil que establezca las condiciones de ingreso, permanencia, evaluación y graduación, y los derechos y deberes de los estudiantes de los diferentes programas de la institución. Incorporación de los análisis de apreciaciones sistematizadas y periódicas en planes de mejoramiento institucional. b) Apreciación por parte de los miembros de la comunidad académica de la institución, en relación con la aplicación de los criterios de ingreso y permanencia de los estudiantes. Incorporación de los análisis de apreciaciones sistematizadas y periódicas en planes de mejoramiento institucional. c) Apreciación por parte de los miembros de la comunidad académica de la institución, en relación con la aplicación de los criterios de promoción, transferencia y grado. Incorporación de los análisis de apreciaciones sistematizadas y periódicas en planes de mejoramiento institucional. d) Apreciación por parte de los miembros de la comunidad académica de la institución, en relación con la participación de los estudiantes en los organismos de decisión de la Institución. Incorporación de los análisis de apreciaciones sistematizadas y periódicas en planes de mejoramiento institucional. e) Apreciación por parte de los miembros de la comunidad académica de la institución, en relación con la trasparencia en la aplicación de mecanismos predeterminados para la elección de representantes estudiantiles en los organismos de decisión. Incorporación de los análisis de apreciaciones sistematizadas y periódicas en planes de mejoramiento institucional. f) Apreciación por parte de los miembros de la comunidad académica de la institución, en relación con la existencia de políticas sobre equidad de género y su implementación, a través de comités y organismos que promuevan la igualdad y el respeto en la comunidad académica. Incorporación de los análisis de apreciaciones sistematizadas y periódicas en planes de mejoramiento institucional. g) Estudios de impacto en la comunidad académica de la institución, en relación con las políticas de inclusión en particular sobre la inserción de estudiantes con capacidades especiales o en condición de discapacidad. Incorporación de los análisis de apreciaciones sistematizadas y periódicas, en planes de mejoramiento institucional.
A35: 34 | B35: 34. ADMISIÓN Y PERMANENCIA DE ESTUDIANTES | C35: La institución deberá demostrar que la admisión, la permanencia y el seguimiento de los estudiantes en la institución, y el desarrollo integral de ellos, se enmarcan en criterios académicos y se expresan en políticas equitativas e incluyentes, en coherencia con los distintos niveles de formación y modalidades de los programas académicos. Por lo tanto, la institución presenta evidencias de un compromiso visible con la efectividad de los procesos formativos de los estudiantes, quienes, por ello, tienen un mejor desempeño que el promedio nacional en indicadores como la permanencia y la deserción por cohorte. Adicionalmente, mostrará que realiza un ejercicio activo de caracterización de sus estudiantes al ingreso, con el fin de realizar programas sistemáticos de acompañamiento a su proceso formativo, de tal forma que el estudiante logre el cumplimiento de los resultados de aprendizaje propuestos por la institución | D35: a) Demostración del impacto de las estrategias para la integración de los estudiantes a las diferentes dinámicas institucionales. b) Evidencia del impacto del acompañamiento y/o de otras estrategias institucionales para la disminución de la deserción estudiantil y la graduación en los tiempos establecidos curricularmente. c) Existencia de procesos de orientación que permitan a los estudiantes identificar rutas de formación acordes con sus capacidades e intereses y la superación de sus dificulta desde aprendizaje, a fin de garantizar su permanencia y la culminación adecuada de su proceso formativo. d) Apreciación por parte de los miembros de la comunidad académica de la institución, en relación con la aplicación de políticas y estrategias para la admisión y permanencia de los estudiantes, y en relación con políticas y directrices nacionales. Incorporación de los análisis de apreciaciones sistematizadas y periódicas en planes de mejoramiento institucional. e) Apreciación por parte de los miembros de la comunidad académica de la institución, en relación con estrategias para garantizar la integración de los estudiantes a la institución, en consideración a su heterogeneidad social y cultural. Incorporación de los análisis de apreciaciones sistematizadas y periódicas en planes de mejoramiento institucional. f) Apreciación por parte de los miembros de la comunidad académica de la Institución, en relación con la existencia de programas orientados a la disminución de la deserción de estudiantes, análisis de causas y estrategias de permanencia. Incorporación de los análisis de apreciaciones sistematizadas y periódicas en planes de mejoramiento institucional. g) Apreciación por parte de los miembros de la comunidad académica de la institución, en relación con la existencia y aplicación de criterios y estrategias para admitir estudiantes procedentes de otras instituciones nacionales e internacionales, y reglas claras para el intercambio estudiantil. Incorporación de los análisis de apreciaciones sistematizadas y periódicas en planes de mejoramiento institucional. Apreciación por parte de los miembros de la comunidad académica de la institución, en relación con la aplicación de las políticas y estrategias para la admisión y permanencia de los estudiantes. Incorporación de los análisis de apreciaciones sistematizadas y periódicas en planes de mejoramiento institucional. | F35: Cumple Plenamente | H35: 4.1 - 5
