Workbook

Sheet FO-GC-021
AD2: Instrucciones para el diligenciamiento del Informe de Auditoría Interna
AE4: INFORMACIÓN GENERAL DE LA AUDITORIA
AD5: 1. | AE5: Registre el ciclo de la Auditoría. Ejemplo: "2025" para ciclos anuales o "2025-F1" para ciclos semestrales.
AD6: 2. | AE6: Registre la fecha en que se ejecutó la auditoria interna.
AD7: 3. | AE7: Seleccione la locación en donde se ejecutó la auditoria.
AD8: 4. | AE8: Este campo está formulado. El ID corresponderá al mismo asignado en el Programa de Auditoría.
B9: INFORMACIÓN GENERAL DE LA AUDITORÍA
B11: 1. Ciclo AI | E11: 2. Fecha AI | H11: 3. Locación AI | L11: 4. ID-AI | N11: 5. Proceso / Programa Académico | V11: 6. Colaborador Auditado | AD11: 5. | AE11: Seleccione la auditoria realizada desplegando el listado de procesos y programas a auditar.
L12: =IFERROR(VLOOKUP(N12,'Auditorias Prog.'!C:E,3,0),"") | V12: Nombre | AD12: 6. | AE12: Registre el colaborador de la Institución que recibió la auditoria.
V13: Cargo | AD13: 7. | AE13: Revise en el Programa de Auditorías Internas el Objetivo de la Auditoría definido para el presente ciclo.
B15: 7. Objetivo de la Auditoría | K15: 8. Alcance de la Auditoría | T15: 9. Criterios de Auditoría | AD15: 8. | AE15: Revise en el Programa de Auditorías Internas el Alcance de la Auditoría definido para el presente ciclo.
AD16: 9. 10. 11. | AE16: Registre los criterios de auditoría establecidos en el Programa de Auditorias Interna del presente ciclo. Seleccione los auditores que participaron en el presente ciclo con los roles de "Líder", Principal", y "Asistente". Realice una descripción breve de las actividades desarrolladas como observaciones en campo o desplazamientos hacia otras locaciones. Se recomienda registrar en este campo los nombres del equipo de trabajo que apoyaron al Líder auditado durante el proceso de auditoría.
B18: 10. Equipo Auditor | E18: Auditor Líder | M18: Auditor Principal | U18: Auditor Asistente | AD18: 12. | AE18: Destacar en este campo los aspectos que facilitan el desarrollo del proceso y/o el cumplimiento al propósito del mismo.
B21: 11. Actividades Desarrolladas | AD21: 13. | AE21: Destacar en este campo los aspectos que dificultan el desarrollo del proceso y/o el cumplimiento al propósito del mismo.
AD22: 14. | AE22: Mencionar en este campo aquellos aspectos que se pueden mejorar para facilitar la ejecución del proceso. HALLAZGOS DE AUDITORIA
B24: 12. Fortalezas Identificadas | AD24: 15. | AE24: En esta sección se listan las No Conformidades identificadas: • ID-NC: El formato asigna automáticamente el código para cada NC, de manera que se facilite la consolidación de la información en la Oficina de Calidad. • Req. ISO 9001: En este campo despliegue el listado de requisitos ISO 9001 y seleccione el indicado. En caso de que se requiera registrar en este campo varios requisitos, seleccione el primero y a continuación ingrese a la celda y registre los demás requisitos serados por una "," o por un "/". • Ref. Normativa / Documental: Registre en este campo el requisito, referencia normativa o documental relacionada con la No Conformidad identificada. • Descripción de la No Conformidad: Basado en la descripción del hallazgo registrada en la "Hoja de Verificación para Auditorías", redacte la No Conformidad teniendo en cuenta el contexto del hallazgo (Ciclo de auditoría, fecha de ejecución, proceso auditado, verificación realizada y evidencia encontrada), y los aspectos relevantes del hallazgo, describiendo que es lo que no se cumple y los requisitos de la norma ISO 9001, legales y/o normativos de la Institución que se están incumpliendo.
B27: 13. Debilidades Identificadas
B30: 14. Oportunidades de Mejora
B33: HALLAZGOS DE AUDITORIA | AD33: 16. | AE33: En esta sección se listan las Observaciones identificadas: • ID-OB: El formato asigna automáticamente el código para cada OB, de manera que se facilite la consolidación de la información en la Oficina de Calidad. • Req. ISO 9001: En este campo despliegue el listado de requisitos ISO 9001 y seleccione el indicado. En caso de que se requiera registrar en este campo varios requisitos, seleccione el primero y a continuación ingrese a la celda y registre los demás requisitos serados por una "," o por un "/". • Ref. Normativa / Documental: Registre en este campo el requisito, referencia normativa o documental relacionada con la Observación identificada. • Descripción de la Observación: Basado en la descripción del hallazgo registrada en la "Hoja de Verificación para Auditorías", redacte la observación teniendo en cuenta el contexto del hallazgo (Ciclo de auditoría, fecha de ejecución, proceso auditado, verificación realizada y evidencia encontrada), y los aspectos relevantes del hallazgo, describiendo lo que tendría riesgo de incumplimiento, junto con los requisitos de la norma ISO 9001, legales y/o normativos de la Institución que se podrían incumplir.
B35: 15. No Conformidades
B36: ID-NC | D36: Req. ISO 9001 | F36: Ref. Normativa / Documental | J36: Descripción de la No Conformidad
A37: =COUNTA(B$37:B37) -> 1 | B37: =IF(J37="","",CONCATENATE($B$12,"-NC-",COUNTA(J$37:J37),"-",IFERROR(VLOOKUP($N$12,'Auditorias Prog.'!$C:$G,5,0),"Error")))
A38: =COUNTA(B$37:B38) -> 2 | B38: =IF(J38="","",CONCATENATE($B$12,"-NC-",COUNTA(J$37:J38),"-",IFERROR(VLOOKUP($N$12,'Auditorias Prog.'!$C:$G,5,0),"Error")))
A39: =COUNTA(B$37:B39) -> 3 | B39: =IF(J39="","",CONCATENATE($B$12,"-NC-",COUNTA(J$37:J39),"-",IFERROR(VLOOKUP($N$12,'Auditorias Prog.'!$C:$G,5,0),"Error"))) | AD39: 17. | AE39: CONCLUSIONES DE LA AUDITORIA Registre el balance general de la auditoría, teniendo en cuenta las actividades de desarrolladas, la disposición de los auditados y los aspectos relevantes y concluyentes de la auditoría al proceso.
A40: =COUNTA(B$37:B40) -> 4 | B40: =IF(J40="","",CONCATENATE($B$12,"-NC-",COUNTA(J$37:J40),"-",IFERROR(VLOOKUP($N$12,'Auditorias Prog.'!$C:$G,5,0),"Error")))
A41: =COUNTA(B$37:B41) -> 5 | B41: =IF(J41="","",CONCATENATE($B$12,"-NC-",COUNTA(J$37:J41),"-",IFERROR(VLOOKUP($N$12,'Auditorias Prog.'!$C:$G,5,0),"Error")))
A42: =COUNTA(B$37:B42) -> 6 | B42: =IF(J42="","",CONCATENATE($B$12,"-NC-",COUNTA(J$37:J42),"-",IFERROR(VLOOKUP($N$12,'Auditorias Prog.'!$C:$G,5,0),"Error")))
A43: =COUNTA(B$37:B43) -> 7 | B43: =IF(J43="","",CONCATENATE($B$12,"-NC-",COUNTA(J$37:J43),"-",IFERROR(VLOOKUP($N$12,'Auditorias Prog.'!$C:$G,5,0),"Error")))
A44: =COUNTA(B$37:B44) -> 8 | B44: =IF(J44="","",CONCATENATE($B$12,"-NC-",COUNTA(J$37:J44),"-",IFERROR(VLOOKUP($N$12,'Auditorias Prog.'!$C:$G,5,0),"Error")))
A45: =COUNTA(B$37:B45) -> 9 | B45: =IF(J45="","",CONCATENATE($B$12,"-NC-",COUNTA(J$37:J45),"-",IFERROR(VLOOKUP($N$12,'Auditorias Prog.'!$C:$G,5,0),"Error")))
A46: =COUNTA(B$37:B46) -> 10 | B46: =IF(J46="","",CONCATENATE($B$12,"-NC-",COUNTA(J$37:J46),"-",IFERROR(VLOOKUP($N$12,'Auditorias Prog.'!$C:$G,5,0),"Error")))
A47: =COUNTA(B$37:B47) -> 10
B48: 16. Observaciones
B49: ID-OB | D49: Req. ISO 9001 | F49: Ref. Normativa / Documental | J49: Descripción de la Observación
A50: =COUNTA(B$50:B50) -> 1 | B50: =IF(J50="","",CONCATENATE($B$12,"-OB-",COUNTA(J$50:J50),"-",IFERROR(VLOOKUP($N$12,'Auditorias Prog.'!$C:$G,5,0),"Error")))
A51: =COUNTA(B$50:B51) -> 2 | B51: =IF(J51="","",CONCATENATE($B$12,"-OB-",COUNTA(J$50:J51),"-",IFERROR(VLOOKUP($N$12,'Auditorias Prog.'!$C:$G,5,0),"Error")))
A52: =COUNTA(B$50:B52) -> 3 | B52: =IF(J52="","",CONCATENATE($B$12,"-OB-",COUNTA(J$50:J52),"-",IFERROR(VLOOKUP($N$12,'Auditorias Prog.'!$C:$G,5,0),"Error")))
A53: =COUNTA(B$50:B53) -> 4 | B53: =IF(J53="","",CONCATENATE($B$12,"-OB-",COUNTA(J$50:J53),"-",IFERROR(VLOOKUP($N$12,'Auditorias Prog.'!$C:$G,5,0),"Error")))
A54: =COUNTA(B$50:B54) -> 5 | B54: =IF(J54="","",CONCATENATE($B$12,"-OB-",COUNTA(J$50:J54),"-",IFERROR(VLOOKUP($N$12,'Auditorias Prog.'!$C:$G,5,0),"Error")))
A55: =COUNTA(B$50:B55) -> 6 | B55: =IF(J55="","",CONCATENATE($B$12,"-OB-",COUNTA(J$50:J55),"-",IFERROR(VLOOKUP($N$12,'Auditorias Prog.'!$C:$G,5,0),"Error")))
...

Sheet Resumen AI
D1: ='FO-GC-021'!L12 | E1: ='FO-GC-021'!N12 -> 0
D2: =VLOOKUP(E1,'Auditorias Prog.'!C:H,6,0) -> #N/A
C3: Actividades de la Caracterización de proceso | G3: LISTADO NO CONFORMIDADES | M3: LISTADO OBSERVACIONES
B4: No. | C4: Id | D4: PHVA | E4: Actividad | G4: ID-NC | H4: Req. ISO 9001 | I4: Ref. Normativa / Documental | J4: Descripción de la No Conformidad | K4: Actividad Asociada SGC Vigente | M4: ID-OB | N4: Req. ISO 9001 | O4: Ref. Normativa / Documental | P4: Descripción de la No Conformidad | Q4: Actividad Asociada SGC Vigente
B5: 1 | C5: =CONCATENATE(MID($D$2,1,FIND(".",$D$2,1)-1),"-",B5) -> #N/A | D5: =IFERROR(VLOOKUP($C5,#REF!,2,0),"") | E5: =IFERROR(VLOOKUP($C5,#REF!,3,0),"") | F5: 1 | G5: =IFERROR(VLOOKUP($F5,'FO-GC-021'!$A$36:$J$47,2,0),"") | H5: =IF($G5="","",VLOOKUP($F5,'FO-GC-021'!$A$36:$J$47,4,0)) | I5: =IF($G5="","",VLOOKUP($F5,'FO-GC-021'!$A$36:$J$47,6,0)) | J5: =IF($G5="","",VLOOKUP($F5,'FO-GC-021'!$A$36:$J$47,10,0)) | M5: =IFERROR(VLOOKUP($F5,'FO-GC-021'!$A$49:$J$60,2,0),"") | N5: =IF($G5="","",VLOOKUP($F5,'FO-GC-021'!$A$49:$J$60,4,0)) | O5: =IF($G5="","",VLOOKUP($F5,'FO-GC-021'!$A$49:$J$60,6,0)) | P5: =IF($G5="","",VLOOKUP($F5,'FO-GC-021'!$A$49:$J$60,10,0))
B6: =B5+1 -> 2 | C6: =CONCATENATE(MID($D$2,1,FIND(".",$D$2,1)-1),"-",B6) -> #N/A | D6: =IFERROR(VLOOKUP($C6,#REF!,2,0),"") | E6: =IFERROR(VLOOKUP($C6,#REF!,3,0),"") | F6: =F5+1 -> 2 | G6: =IFERROR(VLOOKUP($F6,'FO-GC-021'!$A$36:$J$47,2,0),"") | H6: =IF($G6="","",VLOOKUP($F6,'FO-GC-021'!$A$36:$J$47,4,0)) | I6: =IF($G6="","",VLOOKUP($F6,'FO-GC-021'!$A$36:$J$47,6,0)) | J6: =IF($G6="","",VLOOKUP($F6,'FO-GC-021'!$A$36:$J$47,10,0)) | M6: =IFERROR(VLOOKUP($F6,'FO-GC-021'!$A$49:$J$60,2,0),"") | N6: =IF($G6="","",VLOOKUP($F6,'FO-GC-021'!$A$49:$J$60,4,0)) | O6: =IF($G6="","",VLOOKUP($F6,'FO-GC-021'!$A$49:$J$60,6,0)) | P6: =IF($G6="","",VLOOKUP($F6,'FO-GC-021'!$A$49:$J$60,10,0))
B7: =B6+1 -> 3 | C7: =CONCATENATE(MID($D$2,1,FIND(".",$D$2,1)-1),"-",B7) -> #N/A | D7: =IFERROR(VLOOKUP($C7,#REF!,2,0),"") | E7: =IFERROR(VLOOKUP($C7,#REF!,3,0),"") | F7: =F6+1 -> 3 | G7: =IFERROR(VLOOKUP($F7,'FO-GC-021'!$A$36:$J$47,2,0),"") | H7: =IF($G7="","",VLOOKUP($F7,'FO-GC-021'!$A$36:$J$47,4,0)) | I7: =IF($G7="","",VLOOKUP($F7,'FO-GC-021'!$A$36:$J$47,6,0)) | J7: =IF($G7="","",VLOOKUP($F7,'FO-GC-021'!$A$36:$J$47,10,0)) | M7: =IFERROR(VLOOKUP($F7,'FO-GC-021'!$A$49:$J$60,2,0),"") | N7: =IF($G7="","",VLOOKUP($F7,'FO-GC-021'!$A$49:$J$60,4,0)) | O7: =IF($G7="","",VLOOKUP($F7,'FO-GC-021'!$A$49:$J$60,6,0)) | P7: =IF($G7="","",VLOOKUP($F7,'FO-GC-021'!$A$49:$J$60,10,0))
B8: =B7+1 -> 4 | C8: =CONCATENATE(MID($D$2,1,FIND(".",$D$2,1)-1),"-",B8) -> #N/A | D8: =IFERROR(VLOOKUP($C8,#REF!,2,0),"") | E8: =IFERROR(VLOOKUP($C8,#REF!,3,0),"") | F8: =F7+1 -> 4 | G8: =IFERROR(VLOOKUP($F8,'FO-GC-021'!$A$36:$J$47,2,0),"") | H8: =IF($G8="","",VLOOKUP($F8,'FO-GC-021'!$A$36:$J$47,4,0)) | I8: =IF($G8="","",VLOOKUP($F8,'FO-GC-021'!$A$36:$J$47,6,0)) | J8: =IF($G8="","",VLOOKUP($F8,'FO-GC-021'!$A$36:$J$47,10,0)) | M8: =IFERROR(VLOOKUP($F8,'FO-GC-021'!$A$49:$J$60,2,0),"") | N8: =IF($G8="","",VLOOKUP($F8,'FO-GC-021'!$A$49:$J$60,4,0)) | O8: =IF($G8="","",VLOOKUP($F8,'FO-GC-021'!$A$49:$J$60,6,0)) | P8: =IF($G8="","",VLOOKUP($F8,'FO-GC-021'!$A$49:$J$60,10,0))
B9: =B8+1 -> 5 | C9: =CONCATENATE(MID($D$2,1,FIND(".",$D$2,1)-1),"-",B9) -> #N/A | D9: =IFERROR(VLOOKUP($C9,#REF!,2,0),"") | E9: =IFERROR(VLOOKUP($C9,#REF!,3,0),"") | F9: =F8+1 -> 5 | G9: =IFERROR(VLOOKUP($F9,'FO-GC-021'!$A$36:$J$47,2,0),"") | H9: =IF($G9="","",VLOOKUP($F9,'FO-GC-021'!$A$36:$J$47,4,0)) | I9: =IF($G9="","",VLOOKUP($F9,'FO-GC-021'!$A$36:$J$47,6,0)) | J9: =IF($G9="","",VLOOKUP($F9,'FO-GC-021'!$A$36:$J$47,10,0)) | M9: =IFERROR(VLOOKUP($F9,'FO-GC-021'!$A$49:$J$60,2,0),"") | N9: =IF($G9="","",VLOOKUP($F9,'FO-GC-021'!$A$49:$J$60,4,0)) | O9: =IF($G9="","",VLOOKUP($F9,'FO-GC-021'!$A$49:$J$60,6,0)) | P9: =IF($G9="","",VLOOKUP($F9,'FO-GC-021'!$A$49:$J$60,10,0))
B10: =B9+1 -> 6 | C10: =CONCATENATE(MID($D$2,1,FIND(".",$D$2,1)-1),"-",B10) -> #N/A | D10: =IFERROR(VLOOKUP($C10,#REF!,2,0),"") | E10: =IFERROR(VLOOKUP($C10,#REF!,3,0),"") | F10: =F9+1 -> 6 | G10: =IFERROR(VLOOKUP($F10,'FO-GC-021'!$A$36:$J$47,2,0),"") | H10: =IF($G10="","",VLOOKUP($F10,'FO-GC-021'!$A$36:$J$47,4,0)) | I10: =IF($G10="","",VLOOKUP($F10,'FO-GC-021'!$A$36:$J$47,6,0)) | J10: =IF($G10="","",VLOOKUP($F10,'FO-GC-021'!$A$36:$J$47,10,0)) | M10: =IFERROR(VLOOKUP($F10,'FO-GC-021'!$A$49:$J$60,2,0),"") | N10: =IF($G10="","",VLOOKUP($F10,'FO-GC-021'!$A$49:$J$60,4,0)) | O10: =IF($G10="","",VLOOKUP($F10,'FO-GC-021'!$A$49:$J$60,6,0)) | P10: =IF($G10="","",VLOOKUP($F10,'FO-GC-021'!$A$49:$J$60,10,0))
B11: =B10+1 -> 7 | C11: =CONCATENATE(MID($D$2,1,FIND(".",$D$2,1)-1),"-",B11) -> #N/A | D11: =IFERROR(VLOOKUP($C11,#REF!,2,0),"") | E11: =IFERROR(VLOOKUP($C11,#REF!,3,0),"") | F11: =F10+1 -> 7 | G11: =IFERROR(VLOOKUP($F11,'FO-GC-021'!$A$36:$J$47,2,0),"") | H11: =IF($G11="","",VLOOKUP($F11,'FO-GC-021'!$A$36:$J$47,4,0)) | I11: =IF($G11="","",VLOOKUP($F11,'FO-GC-021'!$A$36:$J$47,6,0)) | J11: =IF($G11="","",VLOOKUP($F11,'FO-GC-021'!$A$36:$J$47,10,0)) | M11: =IFERROR(VLOOKUP($F11,'FO-GC-021'!$A$49:$J$60,2,0),"") | N11: =IF($G11="","",VLOOKUP($F11,'FO-GC-021'!$A$49:$J$60,4,0)) | O11: =IF($G11="","",VLOOKUP($F11,'FO-GC-021'!$A$49:$J$60,6,0)) | P11: =IF($G11="","",VLOOKUP($F11,'FO-GC-021'!$A$49:$J$60,10,0))
B12: =B11+1 -> 8 | C12: =CONCATENATE(MID($D$2,1,FIND(".",$D$2,1)-1),"-",B12) -> #N/A | D12: =IFERROR(VLOOKUP($C12,#REF!,2,0),"") | E12: =IFERROR(VLOOKUP($C12,#REF!,3,0),"") | F12: =F11+1 -> 8 | G12: =IFERROR(VLOOKUP($F12,'FO-GC-021'!$A$36:$J$47,2,0),"") | H12: =IF($G12="","",VLOOKUP($F12,'FO-GC-021'!$A$36:$J$47,4,0)) | I12: =IF($G12="","",VLOOKUP($F12,'FO-GC-021'!$A$36:$J$47,6,0)) | J12: =IF($G12="","",VLOOKUP($F12,'FO-GC-021'!$A$36:$J$47,10,0)) | M12: =IFERROR(VLOOKUP($F12,'FO-GC-021'!$A$49:$J$60,2,0),"") | N12: =IF($G12="","",VLOOKUP($F12,'FO-GC-021'!$A$49:$J$60,4,0)) | O12: =IF($G12="","",VLOOKUP($F12,'FO-GC-021'!$A$49:$J$60,6,0)) | P12: =IF($G12="","",VLOOKUP($F12,'FO-GC-021'!$A$49:$J$60,10,0))
B13: =B12+1 -> 9 | C13: =CONCATENATE(MID($D$2,1,FIND(".",$D$2,1)-1),"-",B13) -> #N/A | D13: =IFERROR(VLOOKUP($C13,#REF!,2,0),"") | E13: =IFERROR(VLOOKUP($C13,#REF!,3,0),"") | F13: =F12+1 -> 9 | G13: =IFERROR(VLOOKUP($F13,'FO-GC-021'!$A$36:$J$47,2,0),"") | H13: =IF($G13="","",VLOOKUP($F13,'FO-GC-021'!$A$36:$J$47,4,0)) | I13: =IF($G13="","",VLOOKUP($F13,'FO-GC-021'!$A$36:$J$47,6,0)) | J13: =IF($G13="","",VLOOKUP($F13,'FO-GC-021'!$A$36:$J$47,10,0)) | M13: =IFERROR(VLOOKUP($F13,'FO-GC-021'!$A$49:$J$60,2,0),"") | N13: =IF($G13="","",VLOOKUP($F13,'FO-GC-021'!$A$49:$J$60,4,0)) | O13: =IF($G13="","",VLOOKUP($F13,'FO-GC-021'!$A$49:$J$60,6,0)) | P13: =IF($G13="","",VLOOKUP($F13,'FO-GC-021'!$A$49:$J$60,10,0))
B14: =B13+1 -> 10 | C14: =CONCATENATE(MID($D$2,1,FIND(".",$D$2,1)-1),"-",B14) -> #N/A | D14: =IFERROR(VLOOKUP($C14,#REF!,2,0),"") | E14: =IFERROR(VLOOKUP($C14,#REF!,3,0),"") | F14: =F13+1 -> 10 | G14: =IFERROR(VLOOKUP($F14,'FO-GC-021'!$A$36:$J$47,2,0),"") | H14: =IF($G14="","",VLOOKUP($F14,'FO-GC-021'!$A$36:$J$47,4,0)) | I14: =IF($G14="","",VLOOKUP($F14,'FO-GC-021'!$A$36:$J$47,6,0)) | J14: =IF($G14="","",VLOOKUP($F14,'FO-GC-021'!$A$36:$J$47,10,0)) | M14: =IFERROR(VLOOKUP($F14,'FO-GC-021'!$A$49:$J$60,2,0),"") | N14: =IF($G14="","",VLOOKUP($F14,'FO-GC-021'!$A$49:$J$60,4,0)) | O14: =IF($G14="","",VLOOKUP($F14,'FO-GC-021'!$A$49:$J$60,6,0)) | P14: =IF($G14="","",VLOOKUP($F14,'FO-GC-021'!$A$49:$J$60,10,0))
B15: =B14+1 -> 11 | C15: =CONCATENATE(MID($D$2,1,FIND(".",$D$2,1)-1),"-",B15) -> #N/A | D15: =IFERROR(VLOOKUP($C15,#REF!,2,0),"") | E15: =IFERROR(VLOOKUP($C15,#REF!,3,0),"") | F15: =F14+1 -> 11 | G15: =IFERROR(VLOOKUP($F15,'FO-GC-021'!$A$36:$J$47,2,0),"") | H15: =IF($G15="","",VLOOKUP($F15,'FO-GC-021'!$A$36:$J$47,4,0)) | I15: =IF($G15="","",VLOOKUP($F15,'FO-GC-021'!$A$36:$J$47,6,0)) | J15: =IF($G15="","",VLOOKUP($F15,'FO-GC-021'!$A$36:$J$47,10,0)) | M15: =IFERROR(VLOOKUP($F15,'FO-GC-021'!$A$49:$J$60,2,0),"") | N15: =IF($G15="","",VLOOKUP($F15,'FO-GC-021'!$A$49:$J$60,4,0)) | O15: =IF($G15="","",VLOOKUP($F15,'FO-GC-021'!$A$49:$J$60,6,0)) | P15: =IF($G15="","",VLOOKUP($F15,'FO-GC-021'!$A$49:$J$60,10,0))
B16: =B15+1 -> 12 | C16: =CONCATENATE(MID($D$2,1,FIND(".",$D$2,1)-1),"-",B16) -> #N/A | D16: =IFERROR(VLOOKUP($C16,#REF!,2,0),"") | E16: =IFERROR(VLOOKUP($C16,#REF!,3,0),"") | F16: =F15+1 -> 12 | G16: =IFERROR(VLOOKUP($F16,'FO-GC-021'!$A$36:$J$47,2,0),"") | H16: =IF($G16="","",VLOOKUP($F16,'FO-GC-021'!$A$36:$J$47,4,0)) | I16: =IF($G16="","",VLOOKUP($F16,'FO-GC-021'!$A$36:$J$47,6,0)) | J16: =IF($G16="","",VLOOKUP($F16,'FO-GC-021'!$A$36:$J$47,10,0)) | M16: =IFERROR(VLOOKUP($F16,'FO-GC-021'!$A$49:$J$60,2,0),"") | N16: =IF($G16="","",VLOOKUP($F16,'FO-GC-021'!$A$49:$J$60,4,0)) | O16: =IF($G16="","",VLOOKUP($F16,'FO-GC-021'!$A$49:$J$60,6,0)) | P16: =IF($G16="","",VLOOKUP($F16,'FO-GC-021'!$A$49:$J$60,10,0))
B17: =B16+1 -> 13 | C17: =CONCATENATE(MID($D$2,1,FIND(".",$D$2,1)-1),"-",B17) -> #N/A | D17: =IFERROR(VLOOKUP($C17,#REF!,2,0),"") | E17: =IFERROR(VLOOKUP($C17,#REF!,3,0),"") | F17: =F16+1 -> 13 | G17: =IFERROR(VLOOKUP($F17,'FO-GC-021'!$A$36:$J$47,2,0),"") | H17: =IF($G17="","",VLOOKUP($F17,'FO-GC-021'!$A$36:$J$47,4,0)) | I17: =IF($G17="","",VLOOKUP($F17,'FO-GC-021'!$A$36:$J$47,6,0)) | J17: =IF($G17="","",VLOOKUP($F17,'FO-GC-021'!$A$36:$J$47,10,0)) | M17: =IFERROR(VLOOKUP($F17,'FO-GC-021'!$A$49:$J$60,2,0),"") | N17: =IF($G17="","",VLOOKUP($F17,'FO-GC-021'!$A$49:$J$60,4,0)) | O17: =IF($G17="","",VLOOKUP($F17,'FO-GC-021'!$A$49:$J$60,6,0)) | P17: =IF($G17="","",VLOOKUP($F17,'FO-GC-021'!$A$49:$J$60,10,0))
... B32: =B31+1 -> 28 | C32: =CONCATENATE(MID($D$2,1,FIND(".",$D$2,1)-1),"-",B32) -> #N/A | D32: =IFERROR(VLOOKUP($C32,#REF!,2,0),"") | E32: =IFERROR(VLOOKUP($C32,#REF!,3,0),"") | F32: =F31+1 -> 28 | G32: =IFERROR(VLOOKUP($F32,'FO-GC-021'!$A$36:$J$47,2,0),"") | H32: =IF($G32="","",VLOOKUP($F32,'FO-GC-021'!$A$36:$J$47,4,0)) | I32: =IF($G32="","",VLOOKUP($F32,'FO-GC-021'!$A$36:$J$47,6,0)) | J32: =IF($G32="","",VLOOKUP($F32,'FO-GC-021'!$A$36:$J$47,10,0)) | M32: =IFERROR(VLOOKUP($F32,'FO-GC-021'!$A$49:$J$60,2,0),"") | N32: =IF($G32="","",VLOOKUP($F32,'FO-GC-021'!$A$49:$J$60,4,0)) | O32: =IF($G32="","",VLOOKUP($F32,'FO-GC-021'!$A$49:$J$60,6,0)) | P32: =IF($G32="","",VLOOKUP($F32,'FO-GC-021'!$A$49:$J$60,10,0))

Sheet Req. ISO 9001-2015
B1: Requisitos ISO 9001:2015
A2: Num. | C2: Requisito
A4: 9 | B4: 4. | C4: CONTEXTO DE LA ORGANIXZACIÓN
A5: =COUNTIF(#REF!,"X") -> #REF! | B5: 4.1. | C5: Comprensión de la Organización y de su contexto
A6: =COUNTIF(#REF!,"X") -> #REF! | B6: 4.2. | C6: Comprensión de las necesidades y expectativas de las partes interesadas
A7: =COUNTIF(#REF!,"X") -> #REF! | B7: 4.3. | C7: Determinación del alcance del Sistema de Gestión de Calidad
A8: =COUNTIF(#REF!,"X") -> #REF! | B8: 4.4. | C8: Sistema de Gestión de Calidad y sus Procesos
A9: =COUNTIF(#REF!,"X") -> #REF! | B9: 4.4.1. | C9: Establecer, implementar, mantener y mejorar el SGC, incluidos los procesos necesarios y sus interaccionas
A10: =COUNTIF(#REF!,"X") -> #REF! | B10: 4.4.2. | C10: Mantener información documentada y conservarla para tener confianza de que los procesos se realizan según lo planificado
A11: =COUNTIF(#REF!,"X") -> #REF!
A12: 9 | B12: 5. | C12: LIDERAZGO
A13: =COUNTIF(#REF!,"X") -> #REF! | B13: 5.1. | C13: Liderazgo y Compromiso
A14: =COUNTIF(#REF!,"X") -> #REF! | B14: 5.1.1. | C14: Generalidades. La Organización debe demostrar liderazgo y compromiso con respecto al SGC. (a, b, c, d, e, f, g, h, i, j.)
A15: =COUNTIF(#REF!,"X") -> #REF! | B15: 5.1.2. | C15: Enfoque al Cliente. La Alta Dirección debe asegurarse que se determinan, comprenden y cumplen los Requisitos del Cliente, los legales y reglamentarios aplicables
A16: =COUNTIF(#REF!,"X") -> #REF! | B16: 5.2. | C16: Política
A17: =COUNTIF(#REF!,"X") -> #REF! | B17: 5.2.1. | C17: Establecimiento de la Política de Calidad
A18: =COUNTIF(#REF!,"X") -> #REF! | B18: 5.2.2. | C18: Comunicación de la Política de Calidad
A19: =COUNTIF(#REF!,"X") -> #REF! | B19: 5.3. | C19: Roles, responsabilidades y autoridades en la Organización. Asegurarse que para los roles pertinentes se asignen, se comuniquen y se entiendan en la Org. (a, b, c.)
A20: =COUNTIF(#REF!,"X") -> #REF!
A21: 9 | B21: 6. | C21: PLANIFICACIÓN
A22: =COUNTIF(#REF!,"X") -> #REF! | B22: 6.1. | C22: Acciones para abordar riesgos y oportunidades
A23: =COUNTIF(#REF!,"X") -> #REF! | B23: 6.1.1. | C23: La Organización debe considerar las cuestiones referidas en (4.1.) y requisitos referidos en (4.2.)
A24: =COUNTIF(#REF!,"X") -> #REF! | B24: 6.1.2. | C24: La Organización de planificar: * Acciones para abordar riesgos y oportunidades. * La manera de integrar e implementar acciones en sus procesos del SGC y evaluar la eficacia de estas acciones. "Las acciones para abordar los riesgos y oportunidades deben ser proporcionales al impacto potencial en la conformidad de los productos y los servicios.
A25: =COUNTIF(#REF!,"X") -> #REF! | B25: 6.2. | C25: Objetivos de la Calidad y planificación para lograrlos
A26: =COUNTIF(#REF!,"X") -> #REF! | B26: 6.2.1. | C26: La Organización debe establecer Objetivos de Calidad
A27: =COUNTIF(#REF!,"X") -> #REF! | B27: 6.2.2. | C27: Al planificar como lograr los O.C. la Org. Debe determinar: a) que va a hacer, b) recursos, c) responsables, d) cuando se finalizará y e) cómo se evaluarán los resultados
A28: =COUNTIF(#REF!,"X") -> #REF! | B28: 6.3. | C28: Planificación de Cambios. Cuando la Org. Determine la necesidad de cambios al SGC, estos se deben llevar de manera planificada (4.4.), considerar a), b), c), d)
A29: =COUNTIF(#REF!,"X") -> #REF!
A30: 9 | B30: 7. | C30: APOYO
A31: =COUNTIF(#REF!,"X") -> #REF! | B31: 7.1. | C31: Recursos
A32: =COUNTIF(#REF!,"X") -> #REF! | B32: 7.1.1. | C32: Generalidades. Determinar y proporcionar los recursos necesario para el SGC. La Org. Debe considerar las capacidades y limitaciones de recursos existentes y qué se necesita obtener de los proveedores externos
A33: =COUNTIF(#REF!,"X") -> #REF! | B33: 7.1.2. | C33: Personas. La Organización debe determinar y proporcionar las personas necesarias para la implementación eficaz del SGC y para la operación y control de sus procesos
A34: =COUNTIF(#REF!,"X") -> #REF! | B34: 7.1.3. | C34: Infraestructura. La Org. debe determinar, proporcionar y mantener la infraestructura necesaria para la operación de sus procesos y lograr la conformidad del servicio
A35: =COUNTIF(#REF!,"X") -> #REF! | B35: 7.1.4. | C35: Ambiente para la operación de los procesos. La Orq. debe mantener el ambiente necesario para la operación de sus procesos y para lograr la conformidad del servicio
A36: =COUNTIF(#REF!,"X") -> #REF! | B36: 7.1.5. | C36: Recursos de seguimeinto y medición.
A37: =COUNTIF(#REF!,"X") -> #REF! | B37: 7.1.5.1. | C37: Generalidades
A38: =COUNTIF(#REF!,"X") -> #REF! | B38: 7.1.5.2. | C38: Trazabilidad de las mediciones
A39: =COUNTIF(#REF!,"X") -> #REF! | B39: 7.1.6. | C39: Conocimientos de la Organización. La Org. debe determinar los conocimeintos necesarios para la operación de sus procesos y para lograr la conformidad del servicio.
A40: =COUNTIF(#REF!,"X") -> #REF! | B40: 7.2. | C40: Competencia. a) Determinar la competencia necesaria de las personas, b) Asegurarse de que las personas sean competentes basándose en la educación, formación o experiencia apropiadas. c) Cuando sea aplicable tomar acciones para adquirir competencia necesaria y evaluar eficacia de las acciones, d) conservar la documentación apropiada como evidencia de la competencia.
A41: =COUNTIF(#REF!,"X") -> #REF! | B41: 7.3. | C41: Toma de Conciencia. Política de Calidad, Objetivos de Calidad, contribución a la eficacia del SGC.
...

Sheet Eq. Auditor (2025)
E1: Equipo Auditor FUP - Ciclo: | G1: 2022 | M1: =SUM(M$3:M$62) -> 18 | N1: =SUM(N$3:N$62) -> 32 | O1: =SUM(O$3:O$62) -> 0 | P1: =SUM(P$3:P$62) -> 48 | Q1: =SUM(Q$3:Q$62) -> 2
E2: Id | F2: Nombre y Apellido | G2: Cargo | H2: Correo Electrónico | I2: Asignación | J2: Disp. Inter | K2: CATEGORIA | L2: Exp. | M2: AI - *P 2020 | N2: AI - *P 2021 | O2: AI - A 2021 | P2: AI - *P 2022 | Q2: AI - A 2022 | R2: AI - *P 2023 | S2: AI - A 2023 | T2: AI - *P 2024 | U2: AI - A 2024
A3: =E3 -> 1 | B3: =IFERROR(CONCATENATE(IF(MID(VLOOKUP(A3,C:I,7,0),1,1)="P","*",""),VLOOKUP(A3,C:F,4,0)),"") -> *Aida Marcela Correa Benavides | C3: =IF(J3="Si",COUNTIF(J$3:J3,"Si"),"") -> 1 | D3: =TEXT(ISEVEN(E3),0) -> FALSO | E3: =IF(F3="","",COUNTA(F$3:F3)) -> 1 | F3: Aida Marcela Correa Benavides | G3: Compras | H3: compras@fup.edu.co | I3: Principal | J3: Si | K3: ORO | L3: =SUM(M3:V3) -> 12 | N3: 2 | P3: 2 | R3: 3 | S3: 2 | T3: 3
A4: =E4 -> 2 | B4: =IFERROR(CONCATENATE(IF(MID(VLOOKUP(A4,C:I,7,0),1,1)="P","*",""),VLOOKUP(A4,C:F,4,0)),"") -> Ana Adela Baos | C4: =IF(J4="Si",COUNTIF(J$3:J4,"Si"),"") | D4: =TEXT(ISEVEN(E4),0) -> VERDADERO | E4: =IF(F4="","",COUNTA(F$3:F4)) -> 2 | F4: Alex Fabián Rivera Muñoz | G4: Docente | H4: alex.rivera@docente.fup.edu.co | I4: Asistente | J4: No | L4: =SUM(M4:V4) -> 0 | P4: =IFERROR(VLOOKUP(CONCATENATE(IF(MID($I4,1,1)="P","*",""),$F4),'[1]Programación x Auditor'!$C:$E,2,0),"") | Q4: =IFERROR(VLOOKUP(CONCATENATE(IF(MID($I4,1,1)="P","*",""),$F4),'[1]Programación x Auditor'!$C:$E,3,0),"")
A5: =E5 -> 3 | B5: =IFERROR(CONCATENATE(IF(MID(VLOOKUP(A5,C:I,7,0),1,1)="P","*",""),VLOOKUP(A5,C:F,4,0)),"") -> Andrea Karina Ballagan Estrada | C5: =IF(J5="Si",COUNTIF(J$3:J5,"Si"),"") | D5: =TEXT(ISEVEN(E5),0) -> FALSO | E5: =IF(F5="","",COUNTA(F$3:F5)) -> 3 | F5: Alexander Luna Nieto | G5: Docente | H5: alexander.luna@docente.fup.edu.co | I5: Asistente | J5: No | K5: PLATA | L5: =SUM(M5:V5) -> 6 | N5: 2 | P5: 2 | S5: 2
A6: =E6 -> 4 | B6: =IFERROR(CONCATENATE(IF(MID(VLOOKUP(A6,C:I,7,0),1,1)="P","*",""),VLOOKUP(A6,C:F,4,0)),"") -> *Carlos Andrés Durán Enríquez | C6: =IF(J6="Si",COUNTIF(J$3:J6,"Si"),"") -> 2 | D6: =TEXT(ISEVEN(E6),0) -> VERDADERO | E6: =IF(F6="","",COUNTA(F$3:F6)) -> 4 | F6: Ana Adela Baos | G6: Apoyo leac | H6: apoyo.leac@fup.edu.co profesional.gca@fup.edu.co | I6: Asistente | J6: Si | K6: PLATA | L6: =SUM(M6:V6) -> 5 | M6: 2 | P6: =IFERROR(VLOOKUP(CONCATENATE(IF(MID($I6,1,1)="P","*",""),$F6),'[1]Programación x Auditor'!$C:$E,2,0),"") -> 0 | S6: 2 | U6: 1
A7: =E7 -> 5 | B7: =IFERROR(CONCATENATE(IF(MID(VLOOKUP(A7,C:I,7,0),1,1)="P","*",""),VLOOKUP(A7,C:F,4,0)),"") -> *Daisy Ximena Valencia Palomino | C7: =IF(J7="Si",COUNTIF(J$3:J7,"Si"),"") -> 3 | D7: =TEXT(ISEVEN(E7),0) -> FALSO | E7: =IF(F7="","",COUNTA(F$3:F7)) -> 5 | F7: Andrea Karina Ballagan Estrada | G7: Auxiliar Académica | H7: auxiliaracademico.tsocial@fup.edu.co | I7: Asistente | J7: Si | K7: PLATA | L7: =SUM(M7:V7) -> 7 | P7: 2 | Q7: =IFERROR(VLOOKUP(CONCATENATE(IF(MID($I7,1,1)="P","*",""),$F7),'[1]Programación x Auditor'!$C:$E,3,0),"") -> 2 | S7: 2 | U7: 1
A8: =E8 -> 6 | B8: =IFERROR(CONCATENATE(IF(MID(VLOOKUP(A8,C:I,7,0),1,1)="P","*",""),VLOOKUP(A8,C:F,4,0)),"") -> *Depsi Johana Córdoba Mompotes | C8: =IF(J8="Si",COUNTIF(J$3:J8,"Si"),"") -> 4 | D8: =TEXT(ISEVEN(E8),0) -> VERDADERO | E8: =IF(F8="","",COUNTA(F$3:F8)) -> 6 | F8: Carlos Andrés Durán Enríquez | G8: Decano Facultad Ciencias Ambientales y Agrarias | H8: decanatura.ambientalesyagrarias@fup.edu.co ingenieria.agroecologica@fup.edu.co | I8: Principal | J8: Si | K8: ORO | L8: =SUM(M8:V8) -> 11 | N8: 2 | P8: 2 | R8: 2 | S8: 2 | T8: 3
A9: =E9 -> 7 | B9: =IFERROR(CONCATENATE(IF(MID(VLOOKUP(A9,C:I,7,0),1,1)="P","*",""),VLOOKUP(A9,C:F,4,0)),"") -> *Diego Fabian Bolaños Sarria | C9: =IF(J9="Si",COUNTIF(J$3:J9,"Si"),"") | D9: =TEXT(ISEVEN(E9),0) -> FALSO | E9: =IF(F9="","",COUNTA(F$3:F9)) -> 7 | F9: Carlos Fernando Mina Zape | G9: Director Programa de Psicologia | I9: Principal | J9: No | K9: ORO | L9: =SUM(M9:V9) -> 8 | N9: 2 | P9: 2 | S9: 1 | T9: 3
A10: =E10 -> 8 | B10: =IFERROR(CONCATENATE(IF(MID(VLOOKUP(A10,C:I,7,0),1,1)="P","*",""),VLOOKUP(A10,C:F,4,0)),"") -> *Gabriela Andrea Rivera Macias | C10: =IF(J10="Si",COUNTIF(J$3:J10,"Si"),"") | D10: =TEXT(ISEVEN(E10),0) -> VERDADERO | E10: =IF(F10="","",COUNTA(F$3:F10)) -> 8 | F10: Clara Eugenia Satizábal Serna | G10: Directora Programa de Ingeniería de Sistemas | I10: Principal | J10: No | K10: ORO | L10: =SUM(M10:V10) -> 8 | M10: 2 | P10: 2 | R10: 1 | T10: 3
A11: =E11 -> 9 | B11: =IFERROR(CONCATENATE(IF(MID(VLOOKUP(A11,C:I,7,0),1,1)="P","*",""),VLOOKUP(A11,C:F,4,0)),"") -> *Julio Cesar Garcia Buitron | C11: =IF(J11="Si",COUNTIF(J$3:J11,"Si"),"") -> 5 | D11: =TEXT(ISEVEN(E11),0) -> FALSO | E11: =IF(F11="","",COUNTA(F$3:F11)) -> 9 | F11: Daisy Ximena Valencia Palomino | G11: Decana Ciencias Sociales | H11: decanatura.cienciassociales@fup.edu.co | I11: Principal | J11: Si | K11: ORO | L11: =SUM(M11:V11) -> 9 | N11: 3 | P11: 2 | R11: 2 | T11: 2
A12: =E12 -> 10 | B12: =IFERROR(CONCATENATE(IF(MID(VLOOKUP(A12,C:I,7,0),1,1)="P","*",""),VLOOKUP(A12,C:F,4,0)),"") -> *Karen Viviana Quiñones Mosquera | C12: =IF(J12="Si",COUNTIF(J$3:J12,"Si"),"") | D12: =TEXT(ISEVEN(E12),0) -> VERDADERO | E12: =IF(F12="","",COUNTA(F$3:F12)) -> 10 | F12: Daniel Andres Feriz Garcia | G12: Director investigación | H12: daniel.feriz@docente.fup.edu.co | I12: Principal | J12: No | K12: ORO | L12: =SUM(M12:V12) -> 11 | M12: 2 | N12: 2 | P12: 2 | R12: 2 | S12: 1 | T12: 2
A13: =E13 -> 11 | B13: =IFERROR(CONCATENATE(IF(MID(VLOOKUP(A13,C:I,7,0),1,1)="P","*",""),VLOOKUP(A13,C:F,4,0)),"") -> *Liliana Erazo | C13: =IF(J13="Si",COUNTIF(J$3:J13,"Si"),"") -> 6 | D13: =TEXT(ISEVEN(E13),0) -> FALSO | E13: =IF(F13="","",COUNTA(F$3:F13)) -> 11 | F13: Depsi Johana Córdoba Mompotes | G13: Coordinadora de Gestión Curricular | H13: direccion.aseguramientodelacalidad@fup.edu.co | I13: Principal | J13: Si | K13: PLATA | L13: =SUM(M13:V13) -> 8 | P13: 2 | R13: 3 | T13: 3
A14: =E14 -> 12 | B14: =IFERROR(CONCATENATE(IF(MID(VLOOKUP(A14,C:I,7,0),1,1)="P","*",""),VLOOKUP(A14,C:F,4,0)),"") -> *Omar Andrés Acosta Caicedo | C14: =IF(J14="Si",COUNTIF(J$3:J14,"Si"),"") -> 7 | D14: =TEXT(ISEVEN(E14),0) -> VERDADERO | E14: =IF(F14="","",COUNTA(F$3:F14)) -> 12 | F14: Diego Fabian Bolaños Sarria | G14: Decano Facultad de Ingenierías | H14: ori@fup.edu.co auditoria@fup.edu.co | I14: Principal | J14: Si | K14: ORO | L14: =SUM(M14:V14) -> 10 | M14: 2 | N14: 2 | P14: 2 | R14: 1 | T14: 3
A15: =E15 -> 13 | B15: =IFERROR(CONCATENATE(IF(MID(VLOOKUP(A15,C:I,7,0),1,1)="P","*",""),VLOOKUP(A15,C:F,4,0)),"") -> *Tatiana Mejia Rondon | C15: =IF(J15="Si",COUNTIF(J$3:J15,"Si"),"") -> 8 | D15: =TEXT(ISEVEN(E15),0) -> FALSO | E15: =IF(F15="","",COUNTA(F$3:F15)) -> 13 | F15: Gabriela Andrea Rivera Macias | G15: Docente Tiempo Completo | H15: seguridadysaludeneltrabajo@fup.edu.co | I15: Principal | J15: Si | L15: =SUM(M15:V15) -> 6 | M15: 2 | N15: 2 | P15: =IFERROR(VLOOKUP(CONCATENATE(IF(MID($I15,1,1)="P","*",""),$F15),'[1]Programación x Auditor'!$C:$E,2,0),"") -> 2 | Q15: =IFERROR(VLOOKUP(CONCATENATE(IF(MID($I15,1,1)="P","*",""),$F15),'[1]Programación x Auditor'!$C:$E,3,0),"") -> 0
A16: =E16 -> 14 | B16: =IFERROR(CONCATENATE(IF(MID(VLOOKUP(A16,C:I,7,0),1,1)="P","*",""),VLOOKUP(A16,C:F,4,0)),"") -> *Wadys Montilla Ortega | C16: =IF(J16="Si",COUNTIF(J$3:J16,"Si"),"") | D16: =TEXT(ISEVEN(E16),0) -> VERDADERO | E16: =IF(F16="","",COUNTA(F$3:F16)) -> 14 | F16: Jaime Vente Garcés | G16: Docente TC | I16: Asistente | J16: No | K16: PLATA | L16: =SUM(M16:V16) -> 3 | P16: 2 | Q16: =IFERROR(VLOOKUP(CONCATENATE(IF(MID($I16,1,1)="P","*",""),$F16),'[1]Programación x Auditor'!$C:$E,3,0),"") | U16: 1
A17: =E17 -> 15 | B17: =IFERROR(CONCATENATE(IF(MID(VLOOKUP(A17,C:I,7,0),1,1)="P","*",""),VLOOKUP(A17,C:F,4,0)),"") -> *Luisa Marcela Toro Medina | C17: =IF(J17="Si",COUNTIF(J$3:J17,"Si"),"") | D17: =TEXT(ISEVEN(E17),0) -> FALSO | E17: =IF(F17="","",COUNTA(F$3:F17)) -> 15 | F17: José Fernando Ruíz López | G17: Docente | H17: jose.ruiz@docente.fup.edu.co rep.docenteconsejosuperior@fup.edu.co | I17: Asistente | J17: No | L17: =SUM(M17:V17) -> 3 | P17: =IFERROR(VLOOKUP(CONCATENATE(IF(MID($I17,1,1)="P","*",""),$F17),'[1]Programación x Auditor'!$C:$E,2,0),"") | Q17: =IFERROR(VLOOKUP(CONCATENATE(IF(MID($I17,1,1)="P","*",""),$F17),'[1]Programación x Auditor'!$C:$E,3,0),"") | S17: 2 | U17: 1
A18: =E18 -> 16 | B18: =IFERROR(CONCATENATE(IF(MID(VLOOKUP(A18,C:I,7,0),1,1)="P","*",""),VLOOKUP(A18,C:F,4,0)),"") -> Jeferson Esteban Cordoba Molano | C18: =IF(J18="Si",COUNTIF(J$3:J18,"Si"),"") | D18: =TEXT(ISEVEN(E18),0) -> VERDADERO | E18: =IF(F18="","",COUNTA(F$3:F18)) -> 16 | F18: Juan David Cortés León | G18: Coordinador Academico | H18: coordinacion.arquitectura@fup.edu.co coordacad1@fup.edu.co | I18: Principal | J18: No | K18: PLATA | L18: =SUM(M18:V18) -> 9 | P18: 2 | Q18: =IFERROR(VLOOKUP(CONCATENATE(IF(MID($I18,1,1)="P","*",""),$F18),'[1]Programación x Auditor'!$C:$E,3,0),"") | R18: 3 | S18: 2 | T18: 1 | U18: 1
A19: =E19 -> 17 | B19: =IFERROR(CONCATENATE(IF(MID(VLOOKUP(A19,C:I,7,0),1,1)="P","*",""),VLOOKUP(A19,C:F,4,0)),"") -> Diana Carolina Vasquez Zambrano | C19: =IF(J19="Si",COUNTIF(J$3:J19,"Si"),"") | D19: =TEXT(ISEVEN(E19),0) -> FALSO | E19: =IF(F19="","",COUNTA(F$3:F19)) -> 17 | F19: Julian Camilo Ortega Gomez | G19: Docente - Coordinador de Egresados Ingeniería Industrial | H19: julian.ortega@docente.fup.edu.co | I19: Principal | J19: No | K19: PLATA | L19: =SUM(M19:V19) -> 5 | N19: 2 | P19: =IFERROR(VLOOKUP(CONCATENATE(IF(MID($I19,1,1)="P","*",""),$F19),'[1]Programación x Auditor'!$C:$E,2,0),"") | Q19: =IFERROR(VLOOKUP(CONCATENATE(IF(MID($I19,1,1)="P","*",""),$F19),'[1]Programación x Auditor'!$C:$E,3,0),"") | S19: 2 | T19: 1
A20: =E20 -> 18 | B20: =IFERROR(CONCATENATE(IF(MID(VLOOKUP(A20,C:I,7,0),1,1)="P","*",""),VLOOKUP(A20,C:F,4,0)),"") -> Yudi Andrea Acalo Higon | C20: =IF(J20="Si",COUNTIF(J$3:J20,"Si"),"") -> 9 | D20: =TEXT(ISEVEN(E20),0) -> VERDADERO | E20: =IF(F20="","",COUNTA(F$3:F20)) -> 18 | F20: Julio Cesar Garcia Buitron | G20: Contador | H20: contador@fup.edu.co | I20: Principal | J20: Si | K20: ORO | L20: =SUM(M20:V20) -> 10 | M20: 2 | N20: 2 | P20: 1 | R20: 2 | T20: 3
A21: =E21 -> 19 | B21: =IFERROR(CONCATENATE(IF(MID(VLOOKUP(A21,C:I,7,0),1,1)="P","*",""),VLOOKUP(A21,C:F,4,0)),"") -> Arnol Arias Hoyos | C21: =IF(J21="Si",COUNTIF(J$3:J21,"Si"),"") | D21: =TEXT(ISEVEN(E21),0) -> FALSO | E21: =IF(F21="","",COUNTA(F$3:F21)) -> 19 | F21: Karen Jisset Zuñiga Ramos | G21: Coordinadora Trabajo Social Sede Norte | H21: trabajo.social.santander@fup.edu.co | I21: Asistente | J21: No | K21: ORO | L21: =SUM(M21:V21) -> 6 | N21: 2 | P21: 1 | S21: 2 | U21: 1
A22: =E22 -> 20 | B22: =IFERROR(CONCATENATE(IF(MID(VLOOKUP(A22,C:I,7,0),1,1)="P","*",""),VLOOKUP(A22,C:F,4,0)),"") -> Lina Fernanda Gutiérrez Montoya | C22: =IF(J22="Si",COUNTIF(J$3:J22,"Si"),"") -> 10 | D22: =TEXT(ISEVEN(E22),0) -> VERDADERO | E22: =IF(F22="","",COUNTA(F$3:F22)) -> 20 | F22: Karen Viviana Quiñones Mosquera | G22: COORDINADORA DE GESTION PARA LA INVESTIGACION | H22: coor.gestiondeinvestigacion@fup.edu.co | I22: Principal | J22: Si | K22: ORO | L22: =SUM(M22:V22) -> 12 | N22: 1 | P22: 2 | R22: 3 | S22: 2 | T22: 4
A23: =E23 -> 21 | B23: =IFERROR(CONCATENATE(IF(MID(VLOOKUP(A23,C:I,7,0),1,1)="P","*",""),VLOOKUP(A23,C:F,4,0)),"") -> Fabian Felipe Mera Hurtado | C23: =IF(J23="Si",COUNTIF(J$3:J23,"Si"),"") | D23: =TEXT(ISEVEN(E23),0) -> FALSO | E23: =IF(F23="","",COUNTA(F$3:F23)) -> 21 | F23: Kener Mauricio Quina Velarde | G23: Auxiliar de Planeación | H23: auxiliar.planeacion@fup.edu.co | I23: Principal | J23: No | K23: PLATA | L23: =SUM(M23:V23) -> 9 | P23: 2 | Q23: =IFERROR(VLOOKUP(CONCATENATE(IF(MID($I23,1,1)="P","*",""),$F23),'[1]Programación x Auditor'!$C:$E,3,0),"") | R23: 3 | S23: 3 | T23: 1
A24: =E24 -> 22 | B24: =IFERROR(CONCATENATE(IF(MID(VLOOKUP(A24,C:I,7,0),1,1)="P","*",""),VLOOKUP(A24,C:F,4,0)),"") -> Diego Fernando Ordoñez Trullo | C24: =IF(J24="Si",COUNTIF(J$3:J24,"Si"),"") | D24: =TEXT(ISEVEN(E24),0) -> VERDADERO | E24: =IF(F24="","",COUNTA(F$3:F24)) -> 22 | F24: Laura María Orozco García | G24: Docente - Coordinadora Autoevaluación Ing. Sistemas | H24: laura.orozco@docente.fup.edu.co | I24: Asistente | J24: No | L24: =SUM(M24:V24) -> 0 | P24: =IFERROR(VLOOKUP(CONCATENATE(IF(MID($I24,1,1)="P","*",""),$F24),'[1]Programación x Auditor'!$C:$E,2,0),"") | Q24: =IFERROR(VLOOKUP(CONCATENATE(IF(MID($I24,1,1)="P","*",""),$F24),'[1]Programación x Auditor'!$C:$E,3,0),"")
A25: =E25 -> 23 | B25: =IFERROR(CONCATENATE(IF(MID(VLOOKUP(A25,C:I,7,0),1,1)="P","*",""),VLOOKUP(A25,C:F,4,0)),"") -> Angela Milena Velásquez Vargas | C25: =IF(J25="Si",COUNTIF(J$3:J25,"Si"),"") -> 11 | D25: =TEXT(ISEVEN(E25),0) -> FALSO | E25: =IF(F25="","",COUNTA(F$3:F25)) -> 23 | F25: Liliana Erazo | G25: Asistente Administrativo | H25: asistente.posgrados@fup.edu.co | I25: Principal | J25: Si | K25: ORO | L25: =SUM(M25:V25) -> 10 | M25: 2 | N25: 1 | P25: 2 | R25: 3 | T25: 1 | U25: 1
A26: =E26 -> 24 | B26: =IFERROR(CONCATENATE(IF(MID(VLOOKUP(A26,C:I,7,0),1,1)="P","*",""),VLOOKUP(A26,C:F,4,0)),"") -> Julieth Alexandra Chacón Paja | C26: =IF(J26="Si",COUNTIF(J$3:J26,"Si"),"") | D26: =TEXT(ISEVEN(E26),0) -> VERDADERO | E26: =IF(F26="","",COUNTA(F$3:F26)) -> 24 | F26: Martha Lucia Bolaños Imbachi | G26: Docente | H26: martha.bolanos@docente.fup.edu.co | I26: Asistente | J26: No | K26: BRONCE | L26: =SUM(M26:V26) -> 0 | P26: =IFERROR(VLOOKUP(CONCATENATE(IF(MID($I26,1,1)="P","*",""),$F26),'[1]Programación x Auditor'!$C:$E,2,0),"") | Q26: =IFERROR(VLOOKUP(CONCATENATE(IF(MID($I26,1,1)="P","*",""),$F26),'[1]Programación x Auditor'!$C:$E,3,0),"")
A27: =E27 -> 25 | B27: =IFERROR(CONCATENATE(IF(MID(VLOOKUP(A27,C:I,7,0),1,1)="P","*",""),VLOOKUP(A27,C:F,4,0)),"") -> *Maria Camila Toro Gonzalez | C27: =IF(J27="Si",COUNTIF(J$3:J27,"Si"),"") | D27: =TEXT(ISEVEN(E27),0) -> FALSO | E27: =IF(F27="","",COUNTA(F$3:F27)) -> 25 | F27: Miguel Dario Calvachy | G27: Docente | H27: miguel.calvachy@docente.fup.edu.co | I27: Asistente | J27: No | K27: PLATA | L27: =SUM(M27:V27) -> 5 | M27: 2 | N27: 2 | P27: =IFERROR(VLOOKUP(CONCATENATE(IF(MID($I27,1,1)="P","*",""),$F27),'[1]Programación x Auditor'!$C:$E,2,0),"") | Q27: =IFERROR(VLOOKUP(CONCATENATE(IF(MID($I27,1,1)="P","*",""),$F27),'[1]Programación x Auditor'!$C:$E,3,0),"") | S27: 1
A28: =E28 -> 26 | B28: =IFERROR(CONCATENATE(IF(MID(VLOOKUP(A28,C:I,7,0),1,1)="P","*",""),VLOOKUP(A28,C:F,4,0)),"") -> Juan Manuel Prado Quintero | C28: =IF(J28="Si",COUNTIF(J$3:J28,"Si"),"") | D28: =TEXT(ISEVEN(E28),0) -> VERDADERO | E28: =IF(F28="","",COUNTA(F$3:F28)) -> 26 | F28: Natalia Córdoba Claros | G28: Docente | H28: natalia.cordoba@docente.fup.edu.co | I28: Asistente | J28: No | K28: PLATA | L28: =SUM(M28:V28) -> 6 | P28: 2 | Q28: =IFERROR(VLOOKUP(CONCATENATE(IF(MID($I28,1,1)="P","*",""),$F28),'[1]Programación x Auditor'!$C:$E,3,0),"") | R28: 3 | U28: 1
A29: =E29 -> 27 | B29: =IFERROR(CONCATENATE(IF(MID(VLOOKUP(A29,C:I,7,0),1,1)="P","*",""),VLOOKUP(A29,C:F,4,0)),"") -> Laura Melissa Muñoz Burbano | C29: =IF(J29="Si",COUNTIF(J$3:J29,"Si"),"") | D29: =TEXT(ISEVEN(E29),0) -> FALSO | E29: =IF(F29="","",COUNTA(F$3:F29)) -> 27 | F29: Neiby Alejandra López Montenegro | G29: Coordinación Académica Ingenierías | H29: coordinacionacademica.ingenierias@fup.edu.co coordacadfcsh@fup.edu.co | I29: Principal | J29: No | K29: ORO | L29: =SUM(M29:V29) -> 10 | N29: 2 | P29: 2 | R29: 3 | T29: 1 | U29: 2
A30: =E30 -> 28 | B30: =IFERROR(CONCATENATE(IF(MID(VLOOKUP(A30,C:I,7,0),1,1)="P","*",""),VLOOKUP(A30,C:F,4,0)),"") | C30: =IF(J30="Si",COUNTIF(J$3:J30,"Si"),"") -> 12 | D30: =TEXT(ISEVEN(E30),0) -> VERDADERO | E30: =IF(F30="","",COUNTA(F$3:F30)) -> 28 | F30: Omar Andrés Acosta Caicedo | G30: Director de Programa Ingenieria Industrial | H30: industrial@fup.edu.co | I30: Principal | J30: Si | K30: ORO | L30: =SUM(M30:V30) -> 9 | P30: 2 | R30: 3 | S30: 2 | T30: 2
A31: =E31 -> 29 | B31: =IFERROR(CONCATENATE(IF(MID(VLOOKUP(A31,C:I,7,0),1,1)="P","*",""),VLOOKUP(A31,C:F,4,0)),"") | C31: =IF(J31="Si",COUNTIF(J$3:J31,"Si"),"") | D31: =TEXT(ISEVEN(E31),0) -> FALSO | E31: =IF(F31="","",COUNTA(F$3:F31)) -> 29 | F31: Oscar Eduardo Torres Fernandez | G31: Docente TC | H31: oscar.torres@docente.fup.edu.co | I31: Asistente | J31: No | L31: =SUM(M31:V31) -> 1 | P31: =IFERROR(VLOOKUP(CONCATENATE(IF(MID($I31,1,1)="P","*",""),$F31),'[1]Programación x Auditor'!$C:$E,2,0),"") | Q31: =IFERROR(VLOOKUP(CONCATENATE(IF(MID($I31,1,1)="P","*",""),$F31),'[1]Programación x Auditor'!$C:$E,3,0),"") | U31: 1
A32: =E32 -> 30 | B32: =IFERROR(CONCATENATE(IF(MID(VLOOKUP(A32,C:I,7,0),1,1)="P","*",""),VLOOKUP(A32,C:F,4,0)),"") | C32: =IF(J32="Si",COUNTIF(J$3:J32,"Si"),"") | D32: =TEXT(ISEVEN(E32),0) -> VERDADERO | E32: =IF(F32="","",COUNTA(F$3:F32)) -> 30 | F32: Sandra Johanna Pinzón Hermosa | G32: Coordinadora Académica Prog. Administración de Empresas | H32: coordinacionacademica.faceca@fup.edu.co | I32: Asistente | J32: No | L32: =SUM(M32:V32) -> 8 | N32: 2 | P32: 2 | R32: 3 | S32: 1
A33: =E33 -> 31 | B33: =IFERROR(CONCATENATE(IF(MID(VLOOKUP(A33,C:I,7,0),1,1)="P","*",""),VLOOKUP(A33,C:F,4,0)),"") | C33: =IF(J33="Si",COUNTIF(J$3:J33,"Si"),"") -> 13 | D33: =TEXT(ISEVEN(E33),0) -> FALSO | E33: =IF(F33="","",COUNTA(F$3:F33)) -> 31 | F33: Tatiana Mejia Rondon | G33: Coordinadora trabajo social | H33: direccion.extyproyeccionsocial@fup.edu.co | I33: Principal | J33: Si | K33: PLATA | L33: =SUM(M33:V33) -> 9 | P33: 2 | R33: 3 | S33: 2 | U33: 2
A34: =E34 -> 32 | B34: =IFERROR(CONCATENATE(IF(MID(VLOOKUP(A34,C:I,7,0),1,1)="P","*",""),VLOOKUP(A34,C:F,4,0)),"") | C34: =IF(J34="Si",COUNTIF(J$3:J34,"Si"),"") -> 14 | D34: =TEXT(ISEVEN(E34),0) -> VERDADERO | E34: =IF(F34="","",COUNTA(F$3:F34)) -> 32 | F34: Wadys Montilla Ortega | G34: Coordinador Académico General | H34: sistemas@fup.edu.co | I34: Principal | J34: Si | K34: ORO | L34: =SUM(M34:V34) -> 10 | M34: 2 | N34: 1 | P34: 2 | R34: 2 | T34: 3
A35: =E35 -> 33 | B35: =IFERROR(CONCATENATE(IF(MID(VLOOKUP(A35,C:I,7,0),1,1)="P","*",""),VLOOKUP(A35,C:F,4,0)),"") | C35: =IF(J35="Si",COUNTIF(J$3:J35,"Si"),"") | D35: =TEXT(ISEVEN(E35),0) -> FALSO | E35: =IF(F35="","",COUNTA(F$3:F35)) -> 33 | F35: Yaqueline Rivera López | G35: Coordinador de Registro Calificado | H35: registro.calificado@fup.edu.co | I35: Principal | J35: No | K35: PLATA | L35: =SUM(M35:V35) -> 8 | P35: 2 | R35: 3 | T35: 3
A36: =E36 -> 34 | B36: =IFERROR(CONCATENATE(IF(MID(VLOOKUP(A36,C:I,7,0),1,1)="P","*",""),VLOOKUP(A36,C:F,4,0)),"") | C36: =IF(J36="Si",COUNTIF(J$3:J36,"Si"),"") -> 15 | E36: =IF(F36="","",COUNTA(F$3:F36)) -> 34 | F36: Luisa Marcela Toro Medina | G36: Coordinadora Autoevaluacion | H36: coord.autoevaluacion@fup.edu.co | I36: Principal | J36: Si | K36: PLATA | L36: =SUM(M36:V36) -> 7 | R36: 3 | T36: 4
A37: =E37 -> 35 | C37: =IF(J37="Si",COUNTIF(J$3:J37,"Si"),"") | E37: =IF(F37="","",COUNTA(F$3:F37)) -> 35 | F37: Nora Fernanda Arciniegas Sanchez | G37: Docente | H37: fernanda.arciniegas@docente.fup.edu.co | I37: Asistente | J37: No | K37: BRONCE | L37: =SUM(M37:V37) -> 1 | U37: 1
A38: =E38 -> 36 | B38: =IFERROR(CONCATENATE(IF(MID(VLOOKUP(A38,C:I,7,0),1,1)="P","*",""),VLOOKUP(A38,C:F,4,0)),"") | C38: =IF(J38="Si",COUNTIF(J$3:J38,"Si"),"") -> 16 | E38: =IF(F38="","",COUNTA(F$3:F38)) -> 36 | F38: Jeferson Esteban Cordoba Molano | G38: Auxiliar Contable | H38: auxiliar2.tesoreria@fup.edu.co | I38: Asistente | J38: Si | K38: BRONCE | L38: =SUM(M38:V38) -> 2 | U38: 2
A39: =E39 -> 37 | B39: =IFERROR(CONCATENATE(IF(MID(VLOOKUP(A39,C:I,7,0),1,1)="P","*",""),VLOOKUP(A39,C:F,4,0)),"") | C39: =IF(J39="Si",COUNTIF(J$3:J39,"Si"),"") -> 17 | E39: =IF(F39="","",COUNTA(F$3:F39)) -> 37 | F39: Diana Carolina Vasquez Zambrano | G39: Auxiliar | H39: asis.secretariageneral@fup.edu.co | I39: Asistente | J39: Si | K39: BRONCE | L39: =SUM(M39:V39) -> 1 | U39: 1
A40: =E40 -> 38 | B40: =IFERROR(CONCATENATE(IF(MID(VLOOKUP(A40,C:I,7,0),1,1)="P","*",""),VLOOKUP(A40,C:F,4,0)),"") | C40: =IF(J40="Si",COUNTIF(J$3:J40,"Si"),"") -> 18 | E40: =IF(F40="","",COUNTA(F$3:F40)) -> 38 | F40: Yudi Andrea Acalo Higon | G40: Directora | H40: trabajo.social@fup.edu.co | I40: Asistente | J40: Si | K40: BRONCE | L40: =SUM(M40:V40) -> 2 | U40: 2
...

Sheet Auditorias Prog.
C2: Auditorias Internas de Calidad Programadas | E2: Ciclo | F2: ='FO-GC-021'!B12 -> 0 | J2: Locaciones
C3: Proceso / Subproceso / Programa Académico | D3: Cargo Líder de Proceso | E3: ID | F3: Categoría | G3: Cód. | H3: BD Act. | J3: Nombre Sede "Abreviado"
A4: =TEXT(ISEVEN(E4),0) -> FALSO | C4: Registro Académico | D4: Coordinador Registro Académico | E4: =IF(C4="","",COUNTA(C$4:C4)) -> 1 | F4: proceso | G4: RA | H4: 1. Direccionamiento Estratégico | J4: Claustro San José
A5: =TEXT(ISEVEN(E5),0) -> VERDADERO | C5: Gestión Curricular | D5: Director SIAC | E5: =IF(C5="","",COUNTA(C$4:C5)) -> 2 | F5: proceso | G5: CU | H5: 2. Planeacion Institucional | J5: Claustro San Camilo
A6: =TEXT(ISEVEN(E6),0) -> FALSO | C6: Investigación, Desarrollo e Innovación | D6: Coordinador SIDI | E6: =IF(C6="","",COUNTA(C$4:C6)) -> 3 | F6: proceso | G6: IN | H6: 3. Autoevaluacion Institucional | J6: Los Robles
A7: =TEXT(ISEVEN(E7),0) -> VERDADERO | C7: Extensión y Proyección Social | D7: Director de Proyección y Extensión Social | E7: =IF(C7="","",COUNTA(C$4:C7)) -> 4 | F7: proceso | G7: EP | H7: 4. Calidad Institucional | J7: Alvaro Ulcué Chocué
A8: =TEXT(ISEVEN(E8),0) -> FALSO | C8: Gestión de Egresados | D8: Coordinador Gestión de Egresados | E8: =IF(C8="","",COUNTA(C$4:C8)) -> 5 | F8: programa | G8: GE | H8: 7. Docencia
A9: =TEXT(ISEVEN(E9),0) -> VERDADERO | C9: Educación Continuada | D9: Coordinador Educación Continuada | E9: =IF(C9="","",COUNTA(C$4:C9)) -> 6 | F9: programa | G9: EC | H9: 7. Docencia
A10: =TEXT(ISEVEN(E10),0) -> FALSO | C10: Escuela de Formación Para el TDH | D10: Director Escuela de Formación | E10: =IF(C10="","",COUNTA(C$4:C10)) -> 7 | F10: programa | G10: EO | H10: 7. Docencia
A11: =TEXT(ISEVEN(E11),0) -> VERDADERO | C11: Gestión de Sistemas de Información | D11: Director Gestión de Sistemas de información | E11: =IF(C11="","",COUNTA(C$4:C11)) -> 8 | F11: programa | G11: SI | H11: 7. Docencia
A12: =TEXT(ISEVEN(E12),0) -> FALSO | C12: Calidad Institucional | D12: Profesional Calidad Institucional | E12: =IF(C12="","",COUNTA(C$4:C12)) -> 9 | F12: programa | G12: GC | H12: 7. Docencia
A13: =TEXT(ISEVEN(E13),0) -> VERDADERO | C13: Autoevaluación Institucional | D13: Coordinador de Autoevaluación Institucional | E13: =IF(C13="","",COUNTA(C$4:C13)) -> 10 | F13: programa | G13: AU | H13: 7. Docencia
A14: =TEXT(ISEVEN(E14),0) -> FALSO | C14: Registro Calificado | D14: Director SIAC | E14: =IF(C14="","",COUNTA(C$4:C14)) -> 11 | F14: programa | G14: RC | H14: 7. Docencia
A15: =TEXT(ISEVEN(E15),0) -> VERDADERO | C15: Relaciones Interinstitucionales-ORI | D15: Director ORI | E15: =IF(C15="","",COUNTA(C$4:C15)) -> 12 | F15: programa | G15: VN | H15: 7. Docencia
A16: =TEXT(ISEVEN(E16),0) -> FALSO | C16: Mercadeo-Admisiones | D16: Coordinador de Mercadeo Admisiones | E16: =IF(C16="","",COUNTA(C$4:C16)) -> 13 | F16: programa | G16: MA | H16: 7. Docencia
A17: =TEXT(ISEVEN(E17),0) -> VERDADERO | C17: Comunicaciones Institucional | D17: Coordinador Comunicaciones Institucional | E17: =IF(C17="","",COUNTA(C$4:C17)) -> 14 | F17: programa | G17: CO | H17: 7. Docencia
A18: =TEXT(ISEVEN(E18),0) -> FALSO | C18: Bienestar Institucional | D18: Director Bienestar Institucional | E18: =IF(C18="","",COUNTA(C$4:C18)) -> 15 | F18: programa | G18: BI | H18: 7. Docencia
A19: =TEXT(ISEVEN(E19),0) -> VERDADERO | C19: Gestión del Talento Humano | D19: Director de Talento Humano | E19: =IF(C19="","",COUNTA(C$4:C19)) -> 16 | F19: programa | G19: TH | H19: 7. Docencia
... A28: =TEXT(ISEVEN(E28),0) -> FALSO | C28: Recursos Físicos | D28: Profesional de Recursos Físicos | E28: =IF(C28="","",COUNTA(C$4:C28)) -> 25 | F28: proceso | G28: RT | H28: 14. Recursos Educativos
C29: Docencia | D29: Coordinadora General Académica | E29: =IF(C29="","",COUNTA(C$4:C29)) -> 26 | F29: proceso | G29: DO
A30: =TEXT(ISEVEN(E30),0) -> FALSO | C30: Prog. Administración de Empresas | D30: Director Programa Administración de Empresas | E30: =IF(C30="","",COUNTA(C$4:C30)) -> 27 | F30: programa | G30: DO-1 | H30: 10. Recursos Tecnologicos
A31: =TEXT(ISEVEN(E31),0) -> VERDADERO | C31: Prog. Arquitectura | D31: Director y Coordinador Programa Arquitectura | E31: =IF(C31="","",COUNTA(C$4:C31)) -> 28 | F31: programa | G31: DO-2 | H31: 11. Mercadeo
A32: =TEXT(ISEVEN(E32),0) -> FALSO | C32: Prog. Derecho | D32: Director y Coordinador Programa Derecho | E32: =IF(C32="","",COUNTA(C$4:C32)) -> 29 | F32: programa | G32: DO-3 | H32: 9. Talento Humano
A33: =TEXT(ISEVEN(E33),0) -> VERDADERO | C33: Prog. Licenciatura Ed. Art. y Cultural | D33: Director y Coordinador Programa LEAC | E33: =IF(C33="","",COUNTA(C$4:C33)) -> 30 | F33: programa | G33: DO-4 | H33: 13. Financiera
A34: =TEXT(ISEVEN(E34),0) -> FALSO | C34: Prog. Psicología | D34: Director y Coordinador Programa Psicología | E34: =IF(C34="","",COUNTA(C$4:C34)) -> 31 | F34: programa | G34: DO-5 | H34: 16. Bienes y Servicios
A35: =TEXT(ISEVEN(E35),0) -> VERDADERO | C35: Prog. Trabajo Social | D35: Director y Coordinador Programa Trabajo Social | E35: =IF(C35="","",COUNTA(C$4:C35)) -> 32 | F35: programa | G35: DO-6
C36: PPN - Prog. Ecología | D36: Director de Programa Ecología | E36: =IF(C36="","",COUNTA(C$4:C36)) -> 33 | F36: proceso | G36: DO-7
C37: PPN - Prog. Ingeniería de Sistemas | D37: Director Programa Ingeniería de Sistemas | E37: =IF(C37="","",COUNTA(C$4:C37)) -> 34 | F37: proceso | G37: DO-8
C38: PPN - Prog. Ingeneiría Industrial | D38: Director de Programa Ingeniería Industrial | E38: =IF(C38="","",COUNTA(C$4:C38)) -> 35 | F38: proceso | G38: DO-9
C39: PPN - Prog. Licenciatura Ed. Art. y Cultural | D39: Director de Programa de Licenciatura | E39: =IF(C39="","",COUNTA(C$4:C39)) -> 36 | F39: proceso | G39: DO-10
C40: PPN - Prog. Psicología | D40: Director de Programa Psicología | E40: =IF(C40="","",COUNTA(C$4:C40)) -> 37 | F40: proceso | G40: DO-11
C41: PPN - Prog. Trabajo Social | D41: Director Programa de Trabajo Social | E41: =IF(C41="","",COUNTA(C$4:C41)) -> 38 | F41: proceso | G41: DO-12
C42: PPN - Prog. Ingenieria Agroecológica | D42: Decano Ciencias Ambientales y Agrarias | E42: =IF(C42="","",COUNTA(C$4:C42)) -> 39 | F42: proceso | G42: DO-13
C43: STQ - Prog. Arquitectura | D43: Coordinador Prog. Arquitectura Campus Alvaro Ulcué Chocué | E43: =IF(C43="","",COUNTA(C$4:C43)) -> 40 | F43: proceso | G43: DO-14
C44: STQ - Prog. Derecho | D44: Coordinador Prog. Derecho Campus Alvaro Ulcué Chocué | E44: 44 | F44: proceso | G44: DO-15
C45: STQ - Prog. Licenciatura Ed. Art. y Cultural | D45: Coordinador Prog. LEAC Campus Alvaro Ulcué Chocué | E45: =IF(C45="","",COUNTA(C$4:C45)) -> 42 | F45: proceso | G45: DO-16
C46: STQ - Prog. Psicología | D46: Coordinador Prog. Psicología Campus Alvaro Ulcué Chocué | E46: =IF(C46="","",COUNTA(C$4:C46)) -> 43 | F46: proceso | G46: DO-17
C47: STQ - Prog. Trabajo Social | D47: Coordinador Prog. Trabajo Social Campus Alvaro Ulcué Chocué | E47: =IF(C47="","",COUNTA(C$4:C47)) -> 44 | F47: proceso | G47: DO-18
C48: STQ - Prog. Ingeniería Industrial | D48: Coordinador Prog. Ing. Industrial Campus Alvaro Ulcué Chocué | E48: =IF(C48="","",COUNTA(C$4:C48)) -> 45 | F48: proceso | G48: DO-19
