Workbook

Sheet FO-GC-012
K9: OBJETIVO DE LA AUDITORIA | W9: ALCANCE DE LA AUDITORIA | AI9: CRITERIOS DE AUDITORIA
K13: RIESGOS DE AUDITORÍA | AA13: RECURSOS REQUERIDOS | AR13: Ciclo de Auditoría
D16: 1 | E16: 2 | F16: 3 | G16: 4 | H16: 5 | AV16: Ejec.
D17: FECHA PROGR. / REPROGR. | F17: Ini | G17: Fin | H17: P-R | K17: ID | L17: Proceso / Subproceso / Programa Académico | S17: Líder de Proceso / Director Programa | W17: Locación | AA17: Fecha Progr. / Reprog. | AD17: Fecha de Ejecucuón | AG17: Duración hrs : min | AJ17: Horario | AO17: Equipo Auditor (*Principal / Asistente) | AV17: =CONCATENATE(COUNT(AD20:AF109)-2," / ",COUNTA(S20:V109)-2) -> -2 / 43 | AW17: ID | AX17: Fecha | AY17: Auditoría | AZ17: Auditado | BA17: Hora Inicio | BB17: Hora Fin | BC17: Auditor P | BD17: Auditor A | BE17: Ejecutado | BF17: Entrega Informe
A18: =CONCATENATE("P-",AO18) -> P- | B18: =IF(AA19="",CONCATENATE(AA18,"-",L18),CONCATENATE(AA19,"-",L18)) -> -Reunión de Apertura | C18: =CONCATENATE(AO18," / ",AO19) -> / | D18: =IF(AA19="",CONCATENATE(AA18,"-",AO18),CONCATENATE(AA19,"-",AO18)) -> - | E18: =L18 -> Reunión de Apertura | F18: =AL18 -> 0 | G18: =AL19 -> 0 | H18: =IF(AA19="","P","R") -> P | K18: =IF(OR(L18="",L18="Reunión de Apertura",L18="Reunión de Cierre"),"*",COUNT(K15:K$17)+1) -> * | L18: Reunión de Apertura | S18: =IFERROR(VLOOKUP(L18,'Listas Desplegables'!B:D,3,0),"") -> Camia Toro/ Sergio Lozano | W18: Claustro San Camilo | AJ18: Inicio | AW18: =K18 -> * | AX18: =IF(AA19="",AA18,AA19) -> 0 | AY18: =L18 -> Reunión de Apertura | AZ18: =S18 -> Camia Toro/ Sergio Lozano | BA18: =AL18 -> 0 | BB18: =AL19 -> 0 | BC18: =AO18 -> 0 | BD18: =IF(AO19="","",AO19) | BE18: =IF(AD18="","",AD18) | BF18: =IF(OR(L18='Listas Desplegables'!$B$4,L18='Listas Desplegables'!$B$5),"",WORKDAY(AX18,7,'Listas Desplegables'!$J$11:$J$18))
A19: =CONCATENATE("A-",AO19) -> A- | D19: =IF(AA19="",CONCATENATE(AA18,"-",AO19),CONCATENATE(AA19,"-",AO19)) -> - | E19: =L18 -> Reunión de Apertura | F19: =AL18 -> 0 | G19: =AL19 -> 0 | H19: =IF(AA19="","P","R") -> P | AJ19: Fin
A20: =CONCATENATE("P-",AO20) -> P- | B20: =IF(AA21="",CONCATENATE(AA20,"-",L20),CONCATENATE(AA21,"-",L20)) -> -Registro Académico | C20: =CONCATENATE(AO20," / ",AO21) -> / | D20: =IF(AA21="",CONCATENATE(AA20,"-",AO20),CONCATENATE(AA21,"-",AO20)) -> - | E20: =L20 -> Registro Académico | F20: =AL20 -> 0 | G20: =AL21 -> 0 | H20: =IF(AA21="","P","R") -> P | K20: =IF(OR(L20="",L20="Reunión de Apertura",L20="Reunión de Cierre"),"*",COUNT(K$17:K17)+1) -> 1 | L20: Registro Académico | S20: =IFERROR(VLOOKUP(L20,'Listas Desplegables'!B:D,3,0),"") -> Maria Fernanda Bonilla | W20: Claustro San Camilo | AJ20: Inicio | AW20: =K20 -> 1 | AX20: =IF(AA21="",AA20,AA21) -> 0 | AY20: =L20 -> Registro Académico | AZ20: =S20 -> Maria Fernanda Bonilla | BA20: =AL20 -> 0 | BB20: =AL21 -> 0 | BC20: =AO20 -> 0 | BD20: =IF(AO21="","",AO21) | BE20: =IF(AD20="","",AD20) | BF20: =IF(OR(L20='Listas Desplegables'!$B$4,L20='Listas Desplegables'!$B$5),"",WORKDAY(AX20,7,'Listas Desplegables'!$J$11:$J$18)) -> 10
A21: =CONCATENATE("A-",AO21) -> A- | D21: =IF(AA21="",CONCATENATE(AA20,"-",AO21),CONCATENATE(AA21,"-",AO21)) -> - | E21: =L20 -> Registro Académico | F21: =AL20 -> 0 | G21: =AL21 -> 0 | H21: =IF(AA21="","P","R") -> P | AJ21: Fin
A22: =CONCATENATE("P-",AO22) -> P- | B22: =IF(AA23="",CONCATENATE(AA22,"-",L22),CONCATENATE(AA23,"-",L22)) -> -Gestión Curricular | C22: =CONCATENATE(AO22," / ",AO23) -> / | D22: =IF(AA23="",CONCATENATE(AA22,"-",AO22),CONCATENATE(AA23,"-",AO22)) -> - | E22: =L22 -> Gestión Curricular | F22: =AL22 -> 0 | G22: =AL23 -> 0 | H22: =IF(AA23="","P","R") -> P | K22: =IF(OR(L22="",L22="Reunión de Apertura",L22="Reunión de Cierre"),"*",COUNT(K$17:K21)+1) -> 2 | L22: Gestión Curricular | S22: =IFERROR(VLOOKUP(L22,'Listas Desplegables'!B:D,3,0),"") -> Depsi Johana Cordoba | W22: Claustro San José | AG22: =IF(SUM(AL23-AL22)=0,"",AL23-AL22) | AJ22: Inicio | AW22: =K22 -> 2 | AX22: =IF(AA23="",AA22,AA23) -> 0 | AY22: =L22 -> Gestión Curricular | AZ22: =S22 -> Depsi Johana Cordoba | BA22: =AL22 -> 0 | BB22: =AL23 -> 0 | BC22: =AO22 -> 0 | BD22: =IF(AO23="","",AO23) | BE22: =IF(AD22="","",AD22) | BF22: =IF(OR(L22='Listas Desplegables'!$B$4,L22='Listas Desplegables'!$B$5),"",WORKDAY(AX22,7,'Listas Desplegables'!$J$11:$J$18)) -> 10
A23: =CONCATENATE("A-",AO23) -> A- | D23: =IF(AA23="",CONCATENATE(AA22,"-",AO23),CONCATENATE(AA23,"-",AO23)) -> - | E23: =L22 -> Gestión Curricular | F23: =AL22 -> 0 | G23: =AL23 -> 0 | H23: =IF(AA23="","P","R") -> P | AJ23: Fin
A24: =CONCATENATE("P-",AO24) -> P- | B24: =IF(AA25="",CONCATENATE(AA24,"-",L24),CONCATENATE(AA25,"-",L24)) -> -Investigación, Desarrollo e Innovación | C24: =CONCATENATE(AO24," / ",AO25) -> / | D24: =IF(AA25="",CONCATENATE(AA24,"-",AO24),CONCATENATE(AA25,"-",AO24)) -> - | E24: =L24 -> Investigación, Desarrollo e Innovación | F24: =AL24 -> 0 | G24: =AL25 -> 0 | H24: =IF(AA25="","P","R") -> P | K24: =IF(OR(L24="",L24="Reunión de Apertura",L24="Reunión de Cierre"),"*",COUNT(K$17:K23)+1) -> 3 | L24: Investigación, Desarrollo e Innovación | S24: =IFERROR(VLOOKUP(L24,'Listas Desplegables'!B:D,3,0),"") -> Daniel Feriz | W24: Claustro San José | AG24: =IF(SUM(AL25-AL24)=0,"",AL25-AL24) | AJ24: Inicio | AW24: =K24 -> 3 | AX24: =IF(AA25="",AA24,AA25) -> 0 | AY24: =L24 -> Investigación, Desarrollo e Innovación | AZ24: =S24 -> Daniel Feriz | BA24: =AL24 -> 0 | BB24: =AL25 -> 0 | BC24: =AO24 -> 0 | BD24: =IF(AO25="","",AO25) | BE24: =IF(AD24="","",AD24) | BF24: =IF(OR(L24='Listas Desplegables'!$B$4,L24='Listas Desplegables'!$B$5),"",WORKDAY(AX24,7,'Listas Desplegables'!$J$11:$J$18)) -> 10
A25: =CONCATENATE("A-",AO25) -> A- | D25: =IF(AA25="",CONCATENATE(AA24,"-",AO25),CONCATENATE(AA25,"-",AO25)) -> - | E25: =L24 -> Investigación, Desarrollo e Innovación | F25: =AL24 -> 0 | G25: =AL25 -> 0 | H25: =IF(AA25="","P","R") -> P | AJ25: Fin
A26: =CONCATENATE("P-",AO26) -> P- | B26: =IF(AA27="",CONCATENATE(AA26,"-",L26),CONCATENATE(AA27,"-",L26)) -> -Extensión y Proyección Social | C26: =CONCATENATE(AO26," / ",AO27) -> / | D26: =IF(AA27="",CONCATENATE(AA26,"-",AO26),CONCATENATE(AA27,"-",AO26)) -> - | E26: =L26 -> Extensión y Proyección Social | F26: =AL26 -> 0 | G26: =AL27 -> 0 | H26: =IF(AA27="","P","R") -> P | K26: =IF(OR(L26="",L26="Reunión de Apertura",L26="Reunión de Cierre"),"*",COUNT(K$17:K25)+1) -> 4 | L26: Extensión y Proyección Social | S26: =IFERROR(VLOOKUP(L26,'Listas Desplegables'!B:D,3,0),"") -> Andres Cisneros | W26: Claustro San José | AG26: =IF(SUM(AL27-AL26)=0,"",AL27-AL26) | AJ26: Inicio | AW26: =K26 -> 4 | AX26: =IF(AA27="",AA26,AA27) -> 0 | AY26: =L26 -> Extensión y Proyección Social | AZ26: =S26 -> Andres Cisneros | BA26: =AL26 -> 0 | BB26: =AL27 -> 0 | BC26: =AO26 -> 0 | BD26: =IF(AO27="","",AO27) | BE26: =IF(AD26="","",AD26) | BF26: =IF(OR(L26='Listas Desplegables'!$B$4,L26='Listas Desplegables'!$B$5),"",WORKDAY(AX26,7,'Listas Desplegables'!$J$11:$J$18)) -> 10
A27: =CONCATENATE("A-",AO27) -> A- | D27: =IF(AA27="",CONCATENATE(AA26,"-",AO27),CONCATENATE(AA27,"-",AO27)) -> - | E27: =L26 -> Extensión y Proyección Social | F27: =AL26 -> 0 | G27: =AL27 -> 0 | H27: =IF(AA27="","P","R") -> P | AJ27: Fin
A28: =CONCATENATE("P-",AO28) -> P- | B28: =IF(AA29="",CONCATENATE(AA28,"-",L28),CONCATENATE(AA29,"-",L28)) -> -Emprendimiento | C28: =CONCATENATE(AO28," / ",AO29) -> / | D28: =IF(AA29="",CONCATENATE(AA28,"-",AO28),CONCATENATE(AA29,"-",AO28)) -> - | E28: =L28 -> Emprendimiento | F28: =AL28 -> 0 | G28: =AL29 -> 0 | H28: =IF(AA29="","P","R") -> P | K28: =IF(OR(L28="",L28="Reunión de Apertura",L28="Reunión de Cierre"),"*",COUNT(K$17:K27)+1) -> 5 | L28: Emprendimiento | S28: =IFERROR(VLOOKUP(L28,'Listas Desplegables'!B:D,3,0),"") -> Derly Vivian Valencia | W28: Monseñor Samuel Silverio | AG28: =IF(SUM(AL29-AL28)=0,"",AL29-AL28) | AJ28: Inicio | AW28: =K28 -> 5 | AX28: =IF(AA29="",AA28,AA29) -> 0 | AY28: =L28 -> Emprendimiento | AZ28: =S28 -> Derly Vivian Valencia | BA28: =AL28 -> 0 | BB28: =AL29 -> 0 | BC28: =AO28 -> 0 | BD28: =IF(AO29="","",AO29) | BE28: =IF(AD28="","",AD28) | BF28: =IF(OR(L28='Listas Desplegables'!$B$4,L28='Listas Desplegables'!$B$5),"",WORKDAY(AX28,7,'Listas Desplegables'!$J$11:$J$18)) -> 10
A29: =CONCATENATE("A-",AO29) -> A- | D29: =IF(AA29="",CONCATENATE(AA28,"-",AO29),CONCATENATE(AA29,"-",AO29)) -> - | E29: =L28 -> Emprendimiento | F29: =AL28 -> 0 | G29: =AL29 -> 0 | H29: =IF(AA29="","P","R") -> P | AJ29: Fin
A30: =CONCATENATE("P-",AO30) -> P- | B30: =IF(AA31="",CONCATENATE(AA30,"-",L30),CONCATENATE(AA31,"-",L30)) -> -Gestión de Egresados | C30: =CONCATENATE(AO30," / ",AO31) -> / | D30: =IF(AA31="",CONCATENATE(AA30,"-",AO30),CONCATENATE(AA31,"-",AO30)) -> - | E30: =L30 -> Gestión de Egresados | F30: =AL30 -> 0 | G30: =AL31 -> 0 | H30: =IF(AA31="","P","R") -> P | K30: =IF(OR(L30="",L30="Reunión de Apertura",L30="Reunión de Cierre"),"*",COUNT(K$17:K29)+1) -> 6 | L30: Gestión de Egresados | S30: =IFERROR(VLOOKUP(L30,'Listas Desplegables'!B:D,3,0),"") -> Gloria Patricia Castro | W30: Claustro San José | AG30: =IF(SUM(AL31-AL30)=0,"",AL31-AL30) | AJ30: Inicio | AW30: =K30 -> 6 | AX30: =IF(AA31="",AA30,AA31) -> 0 | AY30: =L30 -> Gestión de Egresados | AZ30: =S30 -> Gloria Patricia Castro | BA30: =AL30 -> 0 | BB30: =AL31 -> 0 | BC30: =AO30 -> 0 | BD30: =IF(AO31="","",AO31) | BE30: =IF(AD30="","",AD30) | BF30: =IF(OR(L30='Listas Desplegables'!$B$4,L30='Listas Desplegables'!$B$5),"",WORKDAY(AX30,7,'Listas Desplegables'!$J$11:$J$18)) -> 10
A31: =CONCATENATE("A-",AO31) -> A- | D31: =IF(AA31="",CONCATENATE(AA30,"-",AO31),CONCATENATE(AA31,"-",AO31)) -> - | E31: =L30 -> Gestión de Egresados | F31: =AL30 -> 0 | G31: =AL31 -> 0 | H31: =IF(AA31="","P","R") -> P | AJ31: Fin
A32: =CONCATENATE("P-",AO32) -> P- | B32: =IF(AA33="",CONCATENATE(AA32,"-",L32),CONCATENATE(AA33,"-",L32)) -> -Educación Continuada | C32: =CONCATENATE(AO32," / ",AO33) -> / | D32: =IF(AA33="",CONCATENATE(AA32,"-",AO32),CONCATENATE(AA33,"-",AO32)) -> - | E32: =L32 -> Educación Continuada | F32: =AL32 -> 0 | G32: =AL33 -> 0 | H32: =IF(AA33="","P","R") -> P | K32: =IF(OR(L32="",L32="Reunión de Apertura",L32="Reunión de Cierre"),"*",COUNT(K$17:K31)+1) -> 7 | L32: Educación Continuada | S32: =IFERROR(VLOOKUP(L32,'Listas Desplegables'!B:D,3,0),"") -> 0 | W32: Claustro San Camilo | AG32: =IF(SUM(AL33-AL32)=0,"",AL33-AL32) | AJ32: Inicio | AW32: =K32 -> 7 | AX32: =IF(AA33="",AA32,AA33) -> 0 | AY32: =L32 -> Educación Continuada | AZ32: =S32 -> 0 | BA32: =AL32 -> 0 | BB32: =AL33 -> 0 | BC32: =AO32 -> 0 | BD32: =IF(AO33="","",AO33) | BE32: =IF(AD32="","",AD32) | BF32: =IF(OR(L32='Listas Desplegables'!$B$4,L32='Listas Desplegables'!$B$5),"",WORKDAY(AX32,7,'Listas Desplegables'!$J$11:$J$18)) -> 10
A33: =CONCATENATE("A-",AO33) -> A- | D33: =IF(AA33="",CONCATENATE(AA32,"-",AO33),CONCATENATE(AA33,"-",AO33)) -> - | E33: =L32 -> Educación Continuada | F33: =AL32 -> 0 | G33: =AL33 -> 0 | H33: =IF(AA33="","P","R") -> P | AJ33: Fin
A34: =CONCATENATE("P-",AO34) -> P- | B34: =IF(AA35="",CONCATENATE(AA34,"-",L34),CONCATENATE(AA35,"-",L34)) -> -Escuela de Formación Para el TDH | C34: =CONCATENATE(AO34," / ",AO35) -> / | D34: =IF(AA35="",CONCATENATE(AA34,"-",AO34),CONCATENATE(AA35,"-",AO34)) -> - | E34: =L34 -> Escuela de Formación Para el TDH | F34: =AL34 -> 0 | G34: =AL35 -> 0 | H34: =IF(AA35="","P","R") -> P | K34: =IF(OR(L34="",L34="Reunión de Apertura",L34="Reunión de Cierre"),"*",COUNT(K$17:K33)+1) -> 8 | L34: Escuela de Formación Para el TDH | S34: =IFERROR(VLOOKUP(L34,'Listas Desplegables'!B:D,3,0),"") -> Juan Carlos Rojas | W34: Claustro San José | AG34: =IF(SUM(AL35-AL34)=0,"",AL35-AL34) | AJ34: Inicio | AW34: =K34 -> 8 | AX34: =IF(AA35="",AA34,AA35) -> 0 | AY34: =L34 -> Escuela de Formación Para el TDH | AZ34: =S34 -> Juan Carlos Rojas | BA34: =AL34 -> 0 | BB34: =AL35 -> 0 | BC34: =AO34 -> 0 | BD34: =IF(AO35="","",AO35) | BE34: =IF(AD34="","",AD34) | BF34: =IF(OR(L34='Listas Desplegables'!$B$4,L34='Listas Desplegables'!$B$5),"",WORKDAY(AX34,7,'Listas Desplegables'!$J$11:$J$18)) -> 10
A35: =CONCATENATE("A-",AO35) -> A- | D35: =IF(AA35="",CONCATENATE(AA34,"-",AO35),CONCATENATE(AA35,"-",AO35)) -> - | E35: =L34 -> Escuela de Formación Para el TDH | F35: =AL34 -> 0 | G35: =AL35 -> 0 | H35: =IF(AA35="","P","R") -> P | AJ35: Fin
A36: =CONCATENATE("P-",AO36) -> P- | B36: =IF(AA37="",CONCATENATE(AA36,"-",L36),CONCATENATE(AA37,"-",L36)) -> -Direccionamiento Estratégico | C36: =CONCATENATE(AO36," / ",AO37) -> / | D36: =IF(AA37="",CONCATENATE(AA36,"-",AO36),CONCATENATE(AA37,"-",AO36)) -> - | E36: =L36 -> Direccionamiento Estratégico | F36: =AL36 -> 0 | G36: =AL37 -> 0 | H36: =IF(AA37="","P","R") -> P | K36: =IF(OR(L36="",L36="Reunión de Apertura",L36="Reunión de Cierre"),"*",COUNT(K$17:K35)+1) -> 9 | L36: Direccionamiento Estratégico | S36: =IFERROR(VLOOKUP(L36,'Listas Desplegables'!B:D,3,0),"") -> Padre Danilo Díaz, cjm | W36: Claustro San José | AG36: =IF(SUM(AL37-AL36)=0,"",AL37-AL36) | AJ36: Inicio | AW36: =K36 -> 9 | AX36: =IF(AA37="",AA36,AA37) -> 0 | AY36: =L36 -> Direccionamiento Estratégico | AZ36: =S36 -> Padre Danilo Díaz, cjm | BA36: =AL36 -> 0 | BB36: =AL37 -> 0 | BC36: =AO36 -> 0 | BD36: =IF(AO37="","",AO37) | BE36: =IF(AD36="","",AD36) | BF36: =IF(OR(L36='Listas Desplegables'!$B$4,L36='Listas Desplegables'!$B$5),"",WORKDAY(AX36,7,'Listas Desplegables'!$J$11:$J$18)) -> 10
A37: =CONCATENATE("A-",AO37) -> A- | D37: =IF(AA37="",CONCATENATE(AA36,"-",AO37),CONCATENATE(AA37,"-",AO37)) -> - | E37: =L36 -> Direccionamiento Estratégico | F37: =AL36 -> 0 | G37: =AL37 -> 0 | H37: =IF(AA37="","P","R") -> P | AJ37: Fin
A38: =CONCATENATE("P-",AO38) -> P- | B38: =IF(AA39="",CONCATENATE(AA38,"-",L38),CONCATENATE(AA39,"-",L38)) -> -Planeación Institucional | C38: =CONCATENATE(AO38," / ",AO39) -> / | D38: =IF(AA39="",CONCATENATE(AA38,"-",AO38),CONCATENATE(AA39,"-",AO38)) -> - | E38: =L38 -> Planeación Institucional | F38: =AL38 -> 0 | G38: =AL39 -> 0 | H38: =IF(AA39="","P","R") -> P | K38: =IF(OR(L38="",L38="Reunión de Apertura",L38="Reunión de Cierre"),"*",COUNT(K$17:K37)+1) -> 10 | L38: Planeación Institucional | S38: =IFERROR(VLOOKUP(L38,'Listas Desplegables'!B:D,3,0),"") -> Sergio Lozano | W38: Claustro San José | AG38: =IF(SUM(AL39-AL38)=0,"",AL39-AL38) | AJ38: Inicio | AW38: =K38 -> 10 | AX38: =IF(AA39="",AA38,AA39) -> 0 | AY38: =L38 -> Planeación Institucional | AZ38: =S38 -> Sergio Lozano | BA38: =AL38 -> 0 | BB38: =AL39 -> 0 | BC38: =AO38 -> 0 | BD38: =IF(AO39="","",AO39) | BE38: =IF(AD38="","",AD38) | BF38: =IF(OR(L38='Listas Desplegables'!$B$4,L38='Listas Desplegables'!$B$5),"",WORKDAY(AX38,7,'Listas Desplegables'!$J$11:$J$18)) -> 10
A39: =CONCATENATE("A-",AO39) -> A- | D39: =IF(AA39="",CONCATENATE(AA38,"-",AO39),CONCATENATE(AA39,"-",AO39)) -> - | E39: =L38 -> Planeación Institucional | F39: =AL38 -> 0 | G39: =AL39 -> 0 | H39: =IF(AA39="","P","R") -> P | AJ39: Fin
A40: =CONCATENATE("P-",AO40) -> P- | B40: =IF(AA41="",CONCATENATE(AA40,"-",L40),CONCATENATE(AA41,"-",L40)) -> -Gestión de Sistemas de Información | C40: =CONCATENATE(AO40," / ",AO41) -> / | D40: =IF(AA41="",CONCATENATE(AA40,"-",AO40),CONCATENATE(AA41,"-",AO40)) -> - | E40: =L40 -> Gestión de Sistemas de Información | F40: =AL40 -> 0 | G40: =AL41 -> 0 | H40: =IF(AA41="","P","R") -> P | K40: =IF(OR(L40="",L40="Reunión de Apertura",L40="Reunión de Cierre"),"*",COUNT(K$17:K39)+1) -> 11 | L40: Gestión de Sistemas de Información | S40: =IFERROR(VLOOKUP(L40,'Listas Desplegables'!B:D,3,0),"") -> Luis Emiro Mosquera | W40: Claustro San José | AG40: =IF(SUM(AL41-AL40)=0,"",AL41-AL40) | AJ40: Inicio | AW40: =K40 -> 11 | AX40: =IF(AA41="",AA40,AA41) -> 0 | AY40: =L40 -> Gestión de Sistemas de Información | AZ40: =S40 -> Luis Emiro Mosquera | BA40: =AL40 -> 0 | BB40: =AL41 -> 0 | BC40: =AO40 -> 0 | BD40: =IF(AO41="","",AO41) | BE40: =IF(AD40="","",AD40) | BF40: =IF(OR(L40='Listas Desplegables'!$B$4,L40='Listas Desplegables'!$B$5),"",WORKDAY(AX40,7,'Listas Desplegables'!$J$11:$J$18)) -> 10
A41: =CONCATENATE("A-",AO41) -> A- | D41: =IF(AA41="",CONCATENATE(AA40,"-",AO41),CONCATENATE(AA41,"-",AO41)) -> - | E41: =L40 -> Gestión de Sistemas de Información | F41: =AL40 -> 0 | G41: =AL41 -> 0 | H41: =IF(AA41="","P","R") -> P | AJ41: Fin
A42: =CONCATENATE("P-",AO42) -> P- | B42: =IF(AA43="",CONCATENATE(AA42,"-",L42),CONCATENATE(AA43,"-",L42)) -> -Gestión de Proyectos Institucionales | C42: =CONCATENATE(AO42," / ",AO43) -> / | D42: =IF(AA43="",CONCATENATE(AA42,"-",AO42),CONCATENATE(AA43,"-",AO42)) -> - | E42: =L42 -> Gestión de Proyectos Institucionales | F42: =AL42 -> 0 | G42: =AL43 -> 0 | H42: =IF(AA43="","P","R") -> P | K42: =IF(OR(L42="",L42="Reunión de Apertura",L42="Reunión de Cierre"),"*",COUNT(K$17:K41)+1) -> 12 | L42: Gestión de Proyectos Institucionales | S42: Luz Mery Lopez | W42: Claustro San José | AG42: =IF(SUM(AL43-AL42)=0,"",AL43-AL42) | AJ42: Inicio | AW42: =K42 -> 12 | AX42: =IF(AA43="",AA42,AA43) -> 0 | AY42: =L42 -> Gestión de Proyectos Institucionales | AZ42: =S42 -> Luz Mery Lopez | BA42: =AL42 -> 0 | BB42: =AL43 -> 0 | BC42: =AO42 -> 0 | BD42: =IF(AO43="","",AO43) | BE42: =IF(AD42="","",AD42) | BF42: =IF(OR(L42='Listas Desplegables'!$B$4,L42='Listas Desplegables'!$B$5),"",WORKDAY(AX42,7,'Listas Desplegables'!$J$11:$J$18)) -> 10
A43: =CONCATENATE("A-",AO43) -> A- | D43: =IF(AA43="",CONCATENATE(AA42,"-",AO43),CONCATENATE(AA43,"-",AO43)) -> - | E43: =L42 -> Gestión de Proyectos Institucionales | F43: =AL42 -> 0 | G43: =AL43 -> 0 | H43: =IF(AA43="","P","R") -> P | AJ43: Fin
A44: =CONCATENATE("P-",AO44) -> P- | B44: =IF(AA45="",CONCATENATE(AA44,"-",L44),CONCATENATE(AA45,"-",L44)) -> -Calidad Institucional | C44: =CONCATENATE(AO44," / ",AO45) -> / | D44: =IF(AA45="",CONCATENATE(AA44,"-",AO44),CONCATENATE(AA45,"-",AO44)) -> - | E44: =L44 -> Calidad Institucional | F44: =AL44 -> 0 | G44: =AL45 -> 0 | H44: =IF(AA45="","P","R") -> P | K44: =IF(OR(L44="",L44="Reunión de Apertura",L44="Reunión de Cierre"),"*",COUNT(K$17:K43)+1) -> 13 | L44: Calidad Institucional | S44: =IFERROR(VLOOKUP(L44,'Listas Desplegables'!B:D,3,0),"") -> Maria Camila Toro Gonzalez | W44: Claustro San José | AG44: =IF(SUM(AL45-AL44)=0,"",AL45-AL44) | AJ44: Inicio | AW44: =K44 -> 13 | AX44: =IF(AA45="",AA44,AA45) -> 0 | AY44: =L44 -> Calidad Institucional | AZ44: =S44 -> Maria Camila Toro Gonzalez | BA44: =AL44 -> 0 | BB44: =AL45 -> 0 | BC44: =AO44 -> 0 | BD44: =IF(AO45="","",AO45) | BE44: =IF(AD44="","",AD44) | BF44: =IF(OR(L44='Listas Desplegables'!$B$4,L44='Listas Desplegables'!$B$5),"",WORKDAY(AX44,7,'Listas Desplegables'!$J$11:$J$18)) -> 10
A45: =CONCATENATE("A-",AO45) -> A- | D45: =IF(AA45="",CONCATENATE(AA44,"-",AO45),CONCATENATE(AA45,"-",AO45)) -> - | E45: =L44 -> Calidad Institucional | F45: =AL44 -> 0 | G45: =AL45 -> 0 | H45: =IF(AA45="","P","R") -> P | AJ45: Fin
A46: =CONCATENATE("P-",AO46) -> P- | B46: =IF(AA47="",CONCATENATE(AA46,"-",L46),CONCATENATE(AA47,"-",L46)) -> -Autoevaluación Institucional | C46: =CONCATENATE(AO46," / ",AO47) -> / | D46: =IF(AA47="",CONCATENATE(AA46,"-",AO46),CONCATENATE(AA47,"-",AO46)) -> - | E46: =L46 -> Autoevaluación Institucional | F46: =AL46 -> 0 | G46: =AL47 -> 0 | H46: =IF(AA47="","P","R") -> P | K46: =IF(OR(L46="",L46="Reunión de Apertura",L46="Reunión de Cierre"),"*",COUNT(K$17:K45)+1) -> 14 | L46: Autoevaluación Institucional | S46: =IFERROR(VLOOKUP(L46,'Listas Desplegables'!B:D,3,0),"") -> Luisa Marcela Toro Medina | W46: Claustro San José | AG46: =IF(SUM(AL47-AL46)=0,"",AL47-AL46) | AJ46: Inicio | AW46: =K46 -> 14 | AX46: =IF(AA47="",AA46,AA47) -> 0 | AY46: =L46 -> Autoevaluación Institucional | AZ46: =S46 -> Luisa Marcela Toro Medina | BA46: =AL46 -> 0 | BB46: =AL47 -> 0 | BC46: =AO46 -> 0 | BD46: =IF(AO47="","",AO47) | BE46: =IF(AD46="","",AD46) | BF46: =IF(OR(L46='Listas Desplegables'!$B$4,L46='Listas Desplegables'!$B$5),"",WORKDAY(AX46,7,'Listas Desplegables'!$J$11:$J$18)) -> 10
A47: =CONCATENATE("A-",AO47) -> A- | D47: =IF(AA47="",CONCATENATE(AA46,"-",AO47),CONCATENATE(AA47,"-",AO47)) -> - | E47: =L46 -> Autoevaluación Institucional | F47: =AL46 -> 0 | G47: =AL47 -> 0 | H47: =IF(AA47="","P","R") -> P | AJ47: Fin
A48: =CONCATENATE("P-",AO48) -> P- | B48: =IF(AA49="",CONCATENATE(AA48,"-",L48),CONCATENATE(AA49,"-",L48)) -> -Registro Calificado | C48: =CONCATENATE(AO48," / ",AO49) -> / | D48: =IF(AA49="",CONCATENATE(AA48,"-",AO48),CONCATENATE(AA49,"-",AO48)) -> - | E48: =L48 -> Registro Calificado | F48: =AL48 -> 0 | G48: =AL49 -> 0 | H48: =IF(AA49="","P","R") -> P | K48: =IF(OR(L48="",L48="Reunión de Apertura",L48="Reunión de Cierre"),"*",COUNT(K$17:K47)+1) -> 15 | L48: Registro Calificado | S48: =IFERROR(VLOOKUP(L48,'Listas Desplegables'!B:D,3,0),"") -> Yaqueline Rivera Lopez | W48: Claustro San José | AG48: =IF(SUM(AL49-AL48)=0,"",AL49-AL48) | AJ48: Inicio | AW48: =K48 -> 15 | AX48: =IF(AA49="",AA48,AA49) -> 0 | AY48: =L48 -> Registro Calificado | AZ48: =S48 -> Yaqueline Rivera Lopez | BA48: =AL48 -> 0 | BB48: =AL49 -> 0 | BC48: =AO48 -> 0 | BD48: =IF(AO49="","",AO49) | BE48: =IF(AD48="","",AD48) | BF48: =IF(OR(L48='Listas Desplegables'!$B$4,L48='Listas Desplegables'!$B$5),"",WORKDAY(AX48,7,'Listas Desplegables'!$J$11:$J$18)) -> 10
A49: =CONCATENATE("A-",AO49) -> A- | D49: =IF(AA49="",CONCATENATE(AA48,"-",AO49),CONCATENATE(AA49,"-",AO49)) -> - | E49: =L48 -> Registro Calificado | F49: =AL48 -> 0 | G49: =AL49 -> 0 | H49: =IF(AA49="","P","R") -> P | AJ49: Fin
A50: =CONCATENATE("P-",AO50) -> P- | B50: =IF(AA51="",CONCATENATE(AA50,"-",L50),CONCATENATE(AA51,"-",L50)) -> -Relaciones Interinstitucionales-ORI | C50: =CONCATENATE(AO50," / ",AO51) -> / | D50: =IF(AA51="",CONCATENATE(AA50,"-",AO50),CONCATENATE(AA51,"-",AO50)) -> - | E50: =L50 -> Relaciones Interinstitucionales-ORI | F50: =AL50 -> 0 | G50: =AL51 -> 0 | H50: =IF(AA51="","P","R") -> P | K50: =IF(OR(L50="",L50="Reunión de Apertura",L50="Reunión de Cierre"),"*",COUNT(K$17:K49)+1) -> 16 | L50: Relaciones Interinstitucionales-ORI | S50: =IFERROR(VLOOKUP(L50,'Listas Desplegables'!B:D,3,0),"") -> Sonia del Consuelo Gaviria | W50: Claustro San José | AG50: =IF(SUM(AL51-AL50)=0,"",AL51-AL50) | AJ50: Inicio | AW50: =K50 -> 16 | AX50: =IF(AA51="",AA50,AA51) -> 0 | AY50: =L50 -> Relaciones Interinstitucionales-ORI | AZ50: =S50 -> Sonia del Consuelo Gaviria | BA50: =AL50 -> 0 | BB50: =AL51 -> 0 | BC50: =AO50 -> 0 | BD50: =IF(AO51="","",AO51) | BE50: =IF(AD50="","",AD50) | BF50: =IF(OR(L50='Listas Desplegables'!$B$4,L50='Listas Desplegables'!$B$5),"",WORKDAY(AX50,7,'Listas Desplegables'!$J$11:$J$18)) -> 10
A51: =CONCATENATE("A-",AO51) -> A- | D51: =IF(AA51="",CONCATENATE(AA50,"-",AO51),CONCATENATE(AA51,"-",AO51)) -> - | E51: =L50 -> Relaciones Interinstitucionales-ORI | F51: =AL50 -> 0 | G51: =AL51 -> 0 | H51: =IF(AA51="","P","R") -> P | AJ51: Fin
A52: =CONCATENATE("P-",AO52) -> P- | B52: =IF(AA53="",CONCATENATE(AA52,"-",L52),CONCATENATE(AA53,"-",L52)) -> -Mercadeo-Admisiones | C52: =CONCATENATE(AO52," / ",AO53) -> / | D52: =IF(AA53="",CONCATENATE(AA52,"-",AO52),CONCATENATE(AA53,"-",AO52)) -> - | E52: =L52 -> Mercadeo-Admisiones | F52: =AL52 -> 0 | G52: =AL53 -> 0 | H52: =IF(AA53="","P","R") -> P | K52: =IF(OR(L52="",L52="Reunión de Apertura",L52="Reunión de Cierre"),"*",COUNT(K$17:K51)+1) -> 17 | L52: Mercadeo-Admisiones | S52: =IFERROR(VLOOKUP(L52,'Listas Desplegables'!B:D,3,0),"") -> Maria Alejandra Lopez Collazos | W52: Claustro San Camilo | AG52: =IF(SUM(AL53-AL52)=0,"",AL53-AL52) | AJ52: Inicio | AW52: =K52 -> 17 | AX52: =IF(AA53="",AA52,AA53) -> 0 | AY52: =L52 -> Mercadeo-Admisiones | AZ52: =S52 -> Maria Alejandra Lopez Collazos | BA52: =AL52 -> 0 | BB52: =AL53 -> 0 | BC52: =AO52 -> 0 | BD52: =IF(AO53="","",AO53) | BE52: =IF(AD52="","",AD52) | BF52: =IF(OR(L52='Listas Desplegables'!$B$4,L52='Listas Desplegables'!$B$5),"",WORKDAY(AX52,7,'Listas Desplegables'!$J$11:$J$18)) -> 10
A53: =CONCATENATE("A-",AO53) -> A- | D53: =IF(AA53="",CONCATENATE(AA52,"-",AO53),CONCATENATE(AA53,"-",AO53)) -> - | E53: =L52 -> Mercadeo-Admisiones | F53: =AL52 -> 0 | G53: =AL53 -> 0 | H53: =IF(AA53="","P","R") -> P | AJ53: Fin
...

Sheet Seguimiento AIC x Fecha
A1: =CONCATENATE("SEGUIMIENTO AIC - ",'FO-GC-012'!AR15," x FECHA DE EJECUCIÓN") -> SEGUIMIENTO AIC - x FECHA DE EJECUCIÓN | G1: =COUNT(H:H)/COUNT(I:I) -> #DIV/0! | H1: Ejecución Ciclo AI
G2: =CONCATENATE(COUNT(H:H)," / ",COUNT(I:I)) -> 0 / 0
A4: Fecha | B4: ID | C4: Auditoría | D4: Auditado | E4: Horas | F4: Auditor P | G4: Auditor A | H4: Ejecutado | I4: Entrega Informe
A5: (en blanco) | B5: (en blanco) | C5: (en blanco) | D5: (en blanco) | E5: <0/01/1900
A6: Total (en blanco)

Sheet Programación x Auditor
G1: 1 | H1: =COUNT(H4:H42) -> 0 | K1: =G1+1 -> 2 | L1: =COUNT(L4:L42) -> 0 | O1: =K1+1 -> 3 | P1: =COUNT(P4:P42) -> 0 | S1: =O1+1 -> 4 | T1: =COUNT(T4:T42) -> 0 | W1: =S1+1 -> 5 | X1: =COUNT(X4:X42) -> 0 | AA1: =W1+1 -> 6 | AB1: =COUNT(AB4:AB42) -> 0 | AE1: =AA1+1 -> 7 | AF1: =COUNT(AF4:AF42) -> 0 | AI1: =AE1+1 -> 8 | AJ1: =COUNT(AJ4:AJ42) -> 0 | AM1: =AI1+1 -> 9 | AN1: =COUNT(AN4:AN42) -> 0 | AQ1: =AM1+1 -> 10 | AR1: =COUNT(AR4:AR42) -> 0 | AU1: =AQ1+1 -> 11 | AV1: =COUNT(AV4:AV42) -> 0 | AY1: =AU1+1 -> 12 | AZ1: =COUNT(AZ4:AZ42) -> 0 | BC1: =AY1+1 -> 13 | BD1: =COUNT(BD4:BD42) -> 0 | BG1: =BC1+1 -> 14 | BH1: =COUNT(BH4:BH42) -> 0 | BK1: =BG1+1 -> 15 | BL1: =COUNT(BL4:BL42) -> 0 | BO1: =BK1+1 -> 16 | BP1: =COUNT(BP4:BP42) -> 0 | BS1: =BO1+1 -> 17 | BT1: =COUNT(BT4:BT42) -> 0 | BW1: =BS1+1 -> 18 | BX1: =COUNT(BX4:BX42) -> 0 | CA1: =BW1+1 -> 19 | CB1: =COUNT(CB4:CB42) -> 0 | CE1: =CA1+1 -> 20 | CF1: =COUNT(CF4:CF42) -> 0
B2: Programación x Auditor | D2: Principal / Asistente | G2: Fecha Programada | K2: Fecha Re-Programada
B3: # | C3: Auditor Convocado | D3: Prin | E3: Asis | F3: Total | G3: =IFERROR(VLOOKUP(G1,'Listas Desplegables'!G:I,3,0),"") -> 374010 | J3: P-R | K3: =IFERROR(VLOOKUP(K1,'Listas Desplegables'!$G:$I,3,0),"") -> 374011 | N3: P-R | O3: =IFERROR(VLOOKUP(O1,'Listas Desplegables'!$G:$I,3,0),"") -> 374012 | R3: P-R | S3: =IFERROR(VLOOKUP(S1,'Listas Desplegables'!$G:$I,3,0),"") -> 374013 | V3: P-R | W3: =IFERROR(VLOOKUP(W1,'Listas Desplegables'!$G:$I,3,0),"") -> 374014 | Z3: P-R | AA3: =IFERROR(VLOOKUP(AA1,'Listas Desplegables'!$G:$I,3,0),"") -> 374015 | AD3: P-R | AE3: =IFERROR(VLOOKUP(AE1,'Listas Desplegables'!$G:$I,3,0),"") -> 374016 | AH3: P-R | AI3: =IFERROR(VLOOKUP(AI1,'Listas Desplegables'!$G:$I,3,0),"") -> 374017 | AL3: P-R | AM3: =IFERROR(VLOOKUP(AM1,'Listas Desplegables'!$G:$I,3,0),"") -> 374018 | AP3: P-R | AQ3: =IFERROR(VLOOKUP(AQ1,'Listas Desplegables'!$G:$I,3,0),"") -> 0 | AT3: P-R | AU3: =IFERROR(VLOOKUP(AU1,'Listas Desplegables'!$G:$I,3,0),"") -> 0 | AX3: P-R | AY3: =IFERROR(VLOOKUP(AY1,'Listas Desplegables'!$G:$I,3,0),"") -> 0 | BB3: P-R | BC3: =IFERROR(VLOOKUP(BC1,'Listas Desplegables'!$G:$I,3,0),"") -> 0 | BF3: P-R | BG3: =IFERROR(VLOOKUP(BG1,'Listas Desplegables'!$G:$I,3,0),"") -> 0 | BJ3: P-R | BK3: =IFERROR(VLOOKUP(BK1,'Listas Desplegables'!$G:$I,3,0),"") -> 0 | BN3: P-R | BO3: =IFERROR(VLOOKUP(BO1,'Listas Desplegables'!$G:$I,3,0),"") -> 0 | BR3: P-R | BS3: =IFERROR(VLOOKUP(BS1,'Listas Desplegables'!$G:$I,3,0),"") -> 0 | BV3: P-R | BW3: =IFERROR(VLOOKUP(BW1,'Listas Desplegables'!$G:$I,3,0),"") -> 0 | BZ3: P-R | CA3: =IFERROR(VLOOKUP(CA1,'Listas Desplegables'!$G:$I,3,0),"") -> 0 | CD3: P-R | CE3: =IFERROR(VLOOKUP(CE1,'Listas Desplegables'!$G:$I,3,0),"") -> 0 | CH3: P-R
B4: =IF(C4="","",COUNTA(C$4:C4)) | C4: ='Eq. Auditor'!B3 | D4: =IF(C4="","",COUNTIF('FO-GC-012'!A:A,CONCATENATE("P-",C4))) | E4: =IF(C4="","",COUNTIF('FO-GC-012'!A:A,CONCATENATE("A-",C4))) | F4: =IF(C4="","",SUM(D4:E4)) | G4: =IF($C4="","",IFERROR(VLOOKUP(CONCATENATE(G$3,"-",$C4),'FO-GC-012'!$D$20:$H$109,2,0),"")) | H4: =IF($C4="","",IFERROR(VLOOKUP(CONCATENATE(G$3,"-",$C4),'FO-GC-012'!$D$20:$H$109,3,0),"")) | I4: =IF($C4="","",IFERROR(VLOOKUP(CONCATENATE(G$3,"-",$C4),'FO-GC-012'!$D$20:$H$109,4,0),"")) | J4: =IF($C4="","",IFERROR(VLOOKUP(CONCATENATE(G$3,"-",$C4),'FO-GC-012'!$D$20:$H$109,5,0),"")) | K4: =IF($C4="","",IFERROR(VLOOKUP(CONCATENATE(K$3,"-",$C4),'FO-GC-012'!$D$20:$H$109,2,0),"")) | L4: =IF($C4="","",IFERROR(VLOOKUP(CONCATENATE(K$3,"-",$C4),'FO-GC-012'!$D$20:$H$109,3,0),"")) | M4: =IF($C4="","",IFERROR(VLOOKUP(CONCATENATE(K$3,"-",$C4),'FO-GC-012'!$D$20:$H$109,4,0),"")) | N4: =IF($C4="","",IFERROR(VLOOKUP(CONCATENATE(K$3,"-",$C4),'FO-GC-012'!$D$20:$H$109,5,0),"")) | O4: =IF($C4="","",IFERROR(VLOOKUP(CONCATENATE(O$3,"-",$C4),'FO-GC-012'!$D$20:$H$109,2,0),"")) | P4: =IF($C4="","",IFERROR(VLOOKUP(CONCATENATE(O$3,"-",$C4),'FO-GC-012'!$D$20:$H$109,3,0),"")) | Q4: =IF($C4="","",IFERROR(VLOOKUP(CONCATENATE(O$3,"-",$C4),'FO-GC-012'!$D$20:$H$109,4,0),"")) | R4: =IF($C4="","",IFERROR(VLOOKUP(CONCATENATE(O$3,"-",$C4),'FO-GC-012'!$D$20:$H$109,5,0),"")) | S4: =IF($C4="","",IFERROR(VLOOKUP(CONCATENATE(S$3,"-",$C4),'FO-GC-012'!$D$20:$H$109,2,0),"")) | T4: =IF($C4="","",IFERROR(VLOOKUP(CONCATENATE(S$3,"-",$C4),'FO-GC-012'!$D$20:$H$109,3,0),"")) | U4: =IF($C4="","",IFERROR(VLOOKUP(CONCATENATE(S$3,"-",$C4),'FO-GC-012'!$D$20:$H$109,4,0),"")) | V4: =IF($C4="","",IFERROR(VLOOKUP(CONCATENATE(S$3,"-",$C4),'FO-GC-012'!$D$20:$H$109,5,0),"")) | W4: =IF($C4="","",IFERROR(VLOOKUP(CONCATENATE(W$3,"-",$C4),'FO-GC-012'!$D$20:$H$109,2,0),"")) | X4: =IF($C4="","",IFERROR(VLOOKUP(CONCATENATE(W$3,"-",$C4),'FO-GC-012'!$D$20:$H$109,3,0),"")) | Y4: =IF($C4="","",IFERROR(VLOOKUP(CONCATENATE(W$3,"-",$C4),'FO-GC-012'!$D$20:$H$109,4,0),"")) | Z4: =IF($C4="","",IFERROR(VLOOKUP(CONCATENATE(W$3,"-",$C4),'FO-GC-012'!$D$20:$H$109,5,0),"")) | AA4: =IF($C4="","",IFERROR(VLOOKUP(CONCATENATE(AA$3,"-",$C4),'FO-GC-012'!$D$20:$H$109,2,0),"")) | AB4: =IF($C4="","",IFERROR(VLOOKUP(CONCATENATE(AA$3,"-",$C4),'FO-GC-012'!$D$20:$H$109,3,0),"")) | AC4: =IF($C4="","",IFERROR(VLOOKUP(CONCATENATE(AA$3,"-",$C4),'FO-GC-012'!$D$20:$H$109,4,0),"")) | AD4: =IF($C4="","",IFERROR(VLOOKUP(CONCATENATE(AA$3,"-",$C4),'FO-GC-012'!$D$20:$H$109,5,0),"")) | AE4: =IF($C4="","",IFERROR(VLOOKUP(CONCATENATE(AE$3,"-",$C4),'FO-GC-012'!$D$20:$H$109,2,0),"")) | AF4: =IF($C4="","",IFERROR(VLOOKUP(CONCATENATE(AE$3,"-",$C4),'FO-GC-012'!$D$20:$H$109,3,0),"")) | AG4: =IF($C4="","",IFERROR(VLOOKUP(CONCATENATE(AE$3,"-",$C4),'FO-GC-012'!$D$20:$H$109,4,0),"")) | AH4: =IF($C4="","",IFERROR(VLOOKUP(CONCATENATE(AE$3,"-",$C4),'FO-GC-012'!$D$20:$H$109,5,0),"")) | AI4: =IF($C4="","",IFERROR(VLOOKUP(CONCATENATE(AI$3,"-",$C4),'FO-GC-012'!$D$20:$H$109,2,0),"")) | AJ4: =IF($C4="","",IFERROR(VLOOKUP(CONCATENATE(AI$3,"-",$C4),'FO-GC-012'!$D$20:$H$109,3,0),"")) | AK4: =IF($C4="","",IFERROR(VLOOKUP(CONCATENATE(AI$3,"-",$C4),'FO-GC-012'!$D$20:$H$109,4,0),"")) | AL4: =IF($C4="","",IFERROR(VLOOKUP(CONCATENATE(AI$3,"-",$C4),'FO-GC-012'!$D$20:$H$109,5,0),"")) | AM4: =IF($C4="","",IFERROR(VLOOKUP(CONCATENATE(AM$3,"-",$C4),'FO-GC-012'!$D$20:$H$109,2,0),"")) | AN4: =IF($C4="","",IFERROR(VLOOKUP(CONCATENATE(AM$3,"-",$C4),'FO-GC-012'!$D$20:$H$109,3,0),"")) | AO4: =IF($C4="","",IFERROR(VLOOKUP(CONCATENATE(AM$3,"-",$C4),'FO-GC-012'!$D$20:$H$109,4,0),"")) | AP4: =IF($C4="","",IFERROR(VLOOKUP(CONCATENATE(AM$3,"-",$C4),'FO-GC-012'!$D$20:$H$109,5,0),"")) | AQ4: =IF($C4="","",IFERROR(VLOOKUP(CONCATENATE(AQ$3,"-",$C4),'FO-GC-012'!$D$20:$H$109,2,0),"")) | AR4: =IF($C4="","",IFERROR(VLOOKUP(CONCATENATE(AQ$3,"-",$C4),'FO-GC-012'!$D$20:$H$109,3,0),"")) | AS4: =IF($C4="","",IFERROR(VLOOKUP(CONCATENATE(AQ$3,"-",$C4),'FO-GC-012'!$D$20:$H$109,4,0),"")) | AT4: =IF($C4="","",IFERROR(VLOOKUP(CONCATENATE(AQ$3,"-",$C4),'FO-GC-012'!$D$20:$H$109,5,0),"")) | AU4: =IF($C4="","",IFERROR(VLOOKUP(CONCATENATE(AU$3,"-",$C4),'FO-GC-012'!$D$20:$H$109,2,0),"")) | AV4: =IF($C4="","",IFERROR(VLOOKUP(CONCATENATE(AU$3,"-",$C4),'FO-GC-012'!$D$20:$H$109,3,0),"")) | AW4: =IF($C4="","",IFERROR(VLOOKUP(CONCATENATE(AU$3,"-",$C4),'FO-GC-012'!$D$20:$H$109,4,0),"")) | AX4: =IF($C4="","",IFERROR(VLOOKUP(CONCATENATE(AU$3,"-",$C4),'FO-GC-012'!$D$20:$H$109,5,0),"")) | AY4: =IF($C4="","",IFERROR(VLOOKUP(CONCATENATE(AY$3,"-",$C4),'FO-GC-012'!$D$20:$H$109,2,0),"")) | AZ4: =IF($C4="","",IFERROR(VLOOKUP(CONCATENATE(AY$3,"-",$C4),'FO-GC-012'!$D$20:$H$109,3,0),"")) | BA4: =IF($C4="","",IFERROR(VLOOKUP(CONCATENATE(AY$3,"-",$C4),'FO-GC-012'!$D$20:$H$109,4,0),"")) | BB4: =IF($C4="","",IFERROR(VLOOKUP(CONCATENATE(AY$3,"-",$C4),'FO-GC-012'!$D$20:$H$109,5,0),"")) | BC4: =IF($C4="","",IFERROR(VLOOKUP(CONCATENATE(BC$3,"-",$C4),'FO-GC-012'!$D$20:$H$109,2,0),"")) | BD4: =IF($C4="","",IFERROR(VLOOKUP(CONCATENATE(BC$3,"-",$C4),'FO-GC-012'!$D$20:$H$109,3,0),"")) | BE4: =IF($C4="","",IFERROR(VLOOKUP(CONCATENATE(BC$3,"-",$C4),'FO-GC-012'!$D$20:$H$109,4,0),"")) | BF4: =IF($C4="","",IFERROR(VLOOKUP(CONCATENATE(BC$3,"-",$C4),'FO-GC-012'!$D$20:$H$109,5,0),"")) | BG4: =IF($C4="","",IFERROR(VLOOKUP(CONCATENATE(BG$3,"-",$C4),'FO-GC-012'!$D$20:$H$109,2,0),"")) | BH4: =IF($C4="","",IFERROR(VLOOKUP(CONCATENATE(BG$3,"-",$C4),'FO-GC-012'!$D$20:$H$109,3,0),"")) | BI4: =IF($C4="","",IFERROR(VLOOKUP(CONCATENATE(BG$3,"-",$C4),'FO-GC-012'!$D$20:$H$109,4,0),"")) | BJ4: =IF($C4="","",IFERROR(VLOOKUP(CONCATENATE(BG$3,"-",$C4),'FO-GC-012'!$D$20:$H$109,5,0),"")) | BK4: =IF($C4="","",IFERROR(VLOOKUP(CONCATENATE(BK$3,"-",$C4),'FO-GC-012'!$D$20:$H$109,2,0),"")) | BL4: =IF($C4="","",IFERROR(VLOOKUP(CONCATENATE(BK$3,"-",$C4),'FO-GC-012'!$D$20:$H$109,3,0),"")) | BM4: =IF($C4="","",IFERROR(VLOOKUP(CONCATENATE(BK$3,"-",$C4),'FO-GC-012'!$D$20:$H$109,4,0),"")) | BN4: =IF($C4="","",IFERROR(VLOOKUP(CONCATENATE(BK$3,"-",$C4),'FO-GC-012'!$D$20:$H$109,5,0),"")) | BO4: =IF($C4="","",IFERROR(VLOOKUP(CONCATENATE(BO$3,"-",$C4),'FO-GC-012'!$D$20:$H$109,2,0),"")) | BP4: =IF($C4="","",IFERROR(VLOOKUP(CONCATENATE(BO$3,"-",$C4),'FO-GC-012'!$D$20:$H$109,3,0),"")) | BQ4: =IF($C4="","",IFERROR(VLOOKUP(CONCATENATE(BO$3,"-",$C4),'FO-GC-012'!$D$20:$H$109,4,0),"")) | BR4: =IF($C4="","",IFERROR(VLOOKUP(CONCATENATE(BO$3,"-",$C4),'FO-GC-012'!$D$20:$H$109,5,0),"")) | BS4: =IF($C4="","",IFERROR(VLOOKUP(CONCATENATE(BS$3,"-",$C4),'FO-GC-012'!$D$20:$H$109,2,0),"")) | BT4: =IF($C4="","",IFERROR(VLOOKUP(CONCATENATE(BS$3,"-",$C4),'FO-GC-012'!$D$20:$H$109,3,0),"")) | BU4: =IF($C4="","",IFERROR(VLOOKUP(CONCATENATE(BS$3,"-",$C4),'FO-GC-012'!$D$20:$H$109,4,0),"")) | BV4: =IF($C4="","",IFERROR(VLOOKUP(CONCATENATE(BS$3,"-",$C4),'FO-GC-012'!$D$20:$H$109,5,0),"")) | BW4: =IF($C4="","",IFERROR(VLOOKUP(CONCATENATE(BW$3,"-",$C4),'FO-GC-012'!$D$20:$H$109,2,0),"")) | BX4: =IF($C4="","",IFERROR(VLOOKUP(CONCATENATE(BW$3,"-",$C4),'FO-GC-012'!$D$20:$H$109,3,0),"")) | BY4: =IF($C4="","",IFERROR(VLOOKUP(CONCATENATE(BW$3,"-",$C4),'FO-GC-012'!$D$20:$H$109,4,0),"")) | BZ4: =IF($C4="","",IFERROR(VLOOKUP(CONCATENATE(BW$3,"-",$C4),'FO-GC-012'!$D$20:$H$109,5,0),"")) | CA4: =IF($C4="","",IFERROR(VLOOKUP(CONCATENATE(CA$3,"-",$C4),'FO-GC-012'!$D$20:$H$109,2,0),"")) | CB4: =IF($C4="","",IFERROR(VLOOKUP(CONCATENATE(CA$3,"-",$C4),'FO-GC-012'!$D$20:$H$109,3,0),"")) | CC4: =IF($C4="","",IFERROR(VLOOKUP(CONCATENATE(CA$3,"-",$C4),'FO-GC-012'!$D$20:$H$109,4,0),"")) | CD4: =IF($C4="","",IFERROR(VLOOKUP(CONCATENATE(CA$3,"-",$C4),'FO-GC-012'!$D$20:$H$109,5,0),"")) | CE4: =IF($C4="","",IFERROR(VLOOKUP(CONCATENATE(CE$3,"-",$C4),'FO-GC-012'!$D$20:$H$109,2,0),"")) | CF4: =IF($C4="","",IFERROR(VLOOKUP(CONCATENATE(CE$3,"-",$C4),'FO-GC-012'!$D$20:$H$109,3,0),"")) | CG4: =IF($C4="","",IFERROR(VLOOKUP(CONCATENATE(CE$3,"-",$C4),'FO-GC-012'!$D$20:$H$109,4,0),"")) | CH4: =IF($C4="","",IFERROR(VLOOKUP(CONCATENATE(CE$3,"-",$C4),'FO-GC-012'!$D$20:$H$109,5,0),""))
B5: =IF(C5="","",COUNTA(C$4:C5)) -> 2 | C5: ='Eq. Auditor'!B4 -> Alexander Luna Nieto | D5: =IF(C5="","",COUNTIF('FO-GC-012'!A:A,CONCATENATE("P-",C5))) -> 0 | E5: =IF(C5="","",COUNTIF('FO-GC-012'!A:A,CONCATENATE("A-",C5))) -> 0 | F5: =IF(C5="","",SUM(D5:E5)) -> 0 | G5: =IF($C5="","",IFERROR(VLOOKUP(CONCATENATE(G$3,"-",$C5),'FO-GC-012'!$D$20:$H$109,2,0),"")) | H5: =IF($C5="","",IFERROR(VLOOKUP(CONCATENATE(G$3,"-",$C5),'FO-GC-012'!$D$20:$H$109,3,0),"")) | I5: =IF($C5="","",IFERROR(VLOOKUP(CONCATENATE(G$3,"-",$C5),'FO-GC-012'!$D$20:$H$109,4,0),"")) | J5: =IF($C5="","",IFERROR(VLOOKUP(CONCATENATE(G$3,"-",$C5),'FO-GC-012'!$D$20:$H$109,5,0),"")) | K5: =IF($C5="","",IFERROR(VLOOKUP(CONCATENATE(K$3,"-",$C5),'FO-GC-012'!$D$20:$H$109,2,0),"")) | L5: =IF($C5="","",IFERROR(VLOOKUP(CONCATENATE(K$3,"-",$C5),'FO-GC-012'!$D$20:$H$109,3,0),"")) | M5: =IF($C5="","",IFERROR(VLOOKUP(CONCATENATE(K$3,"-",$C5),'FO-GC-012'!$D$20:$H$109,4,0),"")) | N5: =IF($C5="","",IFERROR(VLOOKUP(CONCATENATE(K$3,"-",$C5),'FO-GC-012'!$D$20:$H$109,5,0),"")) | O5: =IF($C5="","",IFERROR(VLOOKUP(CONCATENATE(O$3,"-",$C5),'FO-GC-012'!$D$20:$H$109,2,0),"")) | P5: =IF($C5="","",IFERROR(VLOOKUP(CONCATENATE(O$3,"-",$C5),'FO-GC-012'!$D$20:$H$109,3,0),"")) | Q5: =IF($C5="","",IFERROR(VLOOKUP(CONCATENATE(O$3,"-",$C5),'FO-GC-012'!$D$20:$H$109,4,0),"")) | R5: =IF($C5="","",IFERROR(VLOOKUP(CONCATENATE(O$3,"-",$C5),'FO-GC-012'!$D$20:$H$109,5,0),"")) | S5: =IF($C5="","",IFERROR(VLOOKUP(CONCATENATE(S$3,"-",$C5),'FO-GC-012'!$D$20:$H$109,2,0),"")) | T5: =IF($C5="","",IFERROR(VLOOKUP(CONCATENATE(S$3,"-",$C5),'FO-GC-012'!$D$20:$H$109,3,0),"")) | U5: =IF($C5="","",IFERROR(VLOOKUP(CONCATENATE(S$3,"-",$C5),'FO-GC-012'!$D$20:$H$109,4,0),"")) | V5: =IF($C5="","",IFERROR(VLOOKUP(CONCATENATE(S$3,"-",$C5),'FO-GC-012'!$D$20:$H$109,5,0),"")) | W5: =IF($C5="","",IFERROR(VLOOKUP(CONCATENATE(W$3,"-",$C5),'FO-GC-012'!$D$20:$H$109,2,0),"")) | X5: =IF($C5="","",IFERROR(VLOOKUP(CONCATENATE(W$3,"-",$C5),'FO-GC-012'!$D$20:$H$109,3,0),"")) | Y5: =IF($C5="","",IFERROR(VLOOKUP(CONCATENATE(W$3,"-",$C5),'FO-GC-012'!$D$20:$H$109,4,0),"")) | Z5: =IF($C5="","",IFERROR(VLOOKUP(CONCATENATE(W$3,"-",$C5),'FO-GC-012'!$D$20:$H$109,5,0),"")) | AA5: =IF($C5="","",IFERROR(VLOOKUP(CONCATENATE(AA$3,"-",$C5),'FO-GC-012'!$D$20:$H$109,2,0),"")) | AB5: =IF($C5="","",IFERROR(VLOOKUP(CONCATENATE(AA$3,"-",$C5),'FO-GC-012'!$D$20:$H$109,3,0),"")) | AC5: =IF($C5="","",IFERROR(VLOOKUP(CONCATENATE(AA$3,"-",$C5),'FO-GC-012'!$D$20:$H$109,4,0),"")) | AD5: =IF($C5="","",IFERROR(VLOOKUP(CONCATENATE(AA$3,"-",$C5),'FO-GC-012'!$D$20:$H$109,5,0),"")) | AE5: =IF($C5="","",IFERROR(VLOOKUP(CONCATENATE(AE$3,"-",$C5),'FO-GC-012'!$D$20:$H$109,2,0),"")) | AF5: =IF($C5="","",IFERROR(VLOOKUP(CONCATENATE(AE$3,"-",$C5),'FO-GC-012'!$D$20:$H$109,3,0),"")) | AG5: =IF($C5="","",IFERROR(VLOOKUP(CONCATENATE(AE$3,"-",$C5),'FO-GC-012'!$D$20:$H$109,4,0),"")) | AH5: =IF($C5="","",IFERROR(VLOOKUP(CONCATENATE(AE$3,"-",$C5),'FO-GC-012'!$D$20:$H$109,5,0),"")) | AI5: =IF($C5="","",IFERROR(VLOOKUP(CONCATENATE(AI$3,"-",$C5),'FO-GC-012'!$D$20:$H$109,2,0),"")) | AJ5: =IF($C5="","",IFERROR(VLOOKUP(CONCATENATE(AI$3,"-",$C5),'FO-GC-012'!$D$20:$H$109,3,0),"")) | AK5: =IF($C5="","",IFERROR(VLOOKUP(CONCATENATE(AI$3,"-",$C5),'FO-GC-012'!$D$20:$H$109,4,0),"")) | AL5: =IF($C5="","",IFERROR(VLOOKUP(CONCATENATE(AI$3,"-",$C5),'FO-GC-012'!$D$20:$H$109,5,0),"")) | AM5: =IF($C5="","",IFERROR(VLOOKUP(CONCATENATE(AM$3,"-",$C5),'FO-GC-012'!$D$20:$H$109,2,0),"")) | AN5: =IF($C5="","",IFERROR(VLOOKUP(CONCATENATE(AM$3,"-",$C5),'FO-GC-012'!$D$20:$H$109,3,0),"")) | AO5: =IF($C5="","",IFERROR(VLOOKUP(CONCATENATE(AM$3,"-",$C5),'FO-GC-012'!$D$20:$H$109,4,0),"")) | AP5: =IF($C5="","",IFERROR(VLOOKUP(CONCATENATE(AM$3,"-",$C5),'FO-GC-012'!$D$20:$H$109,5,0),"")) | AQ5: =IF($C5="","",IFERROR(VLOOKUP(CONCATENATE(AQ$3,"-",$C5),'FO-GC-012'!$D$20:$H$109,2,0),"")) | AR5: =IF($C5="","",IFERROR(VLOOKUP(CONCATENATE(AQ$3,"-",$C5),'FO-GC-012'!$D$20:$H$109,3,0),"")) | AS5: =IF($C5="","",IFERROR(VLOOKUP(CONCATENATE(AQ$3,"-",$C5),'FO-GC-012'!$D$20:$H$109,4,0),"")) | AT5: =IF($C5="","",IFERROR(VLOOKUP(CONCATENATE(AQ$3,"-",$C5),'FO-GC-012'!$D$20:$H$109,5,0),"")) | AU5: =IF($C5="","",IFERROR(VLOOKUP(CONCATENATE(AU$3,"-",$C5),'FO-GC-012'!$D$20:$H$109,2,0),"")) | AV5: =IF($C5="","",IFERROR(VLOOKUP(CONCATENATE(AU$3,"-",$C5),'FO-GC-012'!$D$20:$H$109,3,0),"")) | AW5: =IF($C5="","",IFERROR(VLOOKUP(CONCATENATE(AU$3,"-",$C5),'FO-GC-012'!$D$20:$H$109,4,0),"")) | AX5: =IF($C5="","",IFERROR(VLOOKUP(CONCATENATE(AU$3,"-",$C5),'FO-GC-012'!$D$20:$H$109,5,0),"")) | AY5: =IF($C5="","",IFERROR(VLOOKUP(CONCATENATE(AY$3,"-",$C5),'FO-GC-012'!$D$20:$H$109,2,0),"")) | AZ5: =IF($C5="","",IFERROR(VLOOKUP(CONCATENATE(AY$3,"-",$C5),'FO-GC-012'!$D$20:$H$109,3,0),"")) | BA5: =IF($C5="","",IFERROR(VLOOKUP(CONCATENATE(AY$3,"-",$C5),'FO-GC-012'!$D$20:$H$109,4,0),"")) | BB5: =IF($C5="","",IFERROR(VLOOKUP(CONCATENATE(AY$3,"-",$C5),'FO-GC-012'!$D$20:$H$109,5,0),"")) | BC5: =IF($C5="","",IFERROR(VLOOKUP(CONCATENATE(BC$3,"-",$C5),'FO-GC-012'!$D$20:$H$109,2,0),"")) | BD5: =IF($C5="","",IFERROR(VLOOKUP(CONCATENATE(BC$3,"-",$C5),'FO-GC-012'!$D$20:$H$109,3,0),"")) | BE5: =IF($C5="","",IFERROR(VLOOKUP(CONCATENATE(BC$3,"-",$C5),'FO-GC-012'!$D$20:$H$109,4,0),"")) | BF5: =IF($C5="","",IFERROR(VLOOKUP(CONCATENATE(BC$3,"-",$C5),'FO-GC-012'!$D$20:$H$109,5,0),"")) | BG5: =IF($C5="","",IFERROR(VLOOKUP(CONCATENATE(BG$3,"-",$C5),'FO-GC-012'!$D$20:$H$109,2,0),"")) | BH5: =IF($C5="","",IFERROR(VLOOKUP(CONCATENATE(BG$3,"-",$C5),'FO-GC-012'!$D$20:$H$109,3,0),"")) | BI5: =IF($C5="","",IFERROR(VLOOKUP(CONCATENATE(BG$3,"-",$C5),'FO-GC-012'!$D$20:$H$109,4,0),"")) | BJ5: =IF($C5="","",IFERROR(VLOOKUP(CONCATENATE(BG$3,"-",$C5),'FO-GC-012'!$D$20:$H$109,5,0),"")) | BK5: =IF($C5="","",IFERROR(VLOOKUP(CONCATENATE(BK$3,"-",$C5),'FO-GC-012'!$D$20:$H$109,2,0),"")) | BL5: =IF($C5="","",IFERROR(VLOOKUP(CONCATENATE(BK$3,"-",$C5),'FO-GC-012'!$D$20:$H$109,3,0),"")) | BM5: =IF($C5="","",IFERROR(VLOOKUP(CONCATENATE(BK$3,"-",$C5),'FO-GC-012'!$D$20:$H$109,4,0),"")) | BN5: =IF($C5="","",IFERROR(VLOOKUP(CONCATENATE(BK$3,"-",$C5),'FO-GC-012'!$D$20:$H$109,5,0),"")) | BO5: =IF($C5="","",IFERROR(VLOOKUP(CONCATENATE(BO$3,"-",$C5),'FO-GC-012'!$D$20:$H$109,2,0),"")) | BP5: =IF($C5="","",IFERROR(VLOOKUP(CONCATENATE(BO$3,"-",$C5),'FO-GC-012'!$D$20:$H$109,3,0),"")) | BQ5: =IF($C5="","",IFERROR(VLOOKUP(CONCATENATE(BO$3,"-",$C5),'FO-GC-012'!$D$20:$H$109,4,0),"")) | BR5: =IF($C5="","",IFERROR(VLOOKUP(CONCATENATE(BO$3,"-",$C5),'FO-GC-012'!$D$20:$H$109,5,0),"")) | BS5: =IF($C5="","",IFERROR(VLOOKUP(CONCATENATE(BS$3,"-",$C5),'FO-GC-012'!$D$20:$H$109,2,0),"")) | BT5: =IF($C5="","",IFERROR(VLOOKUP(CONCATENATE(BS$3,"-",$C5),'FO-GC-012'!$D$20:$H$109,3,0),"")) | BU5: =IF($C5="","",IFERROR(VLOOKUP(CONCATENATE(BS$3,"-",$C5),'FO-GC-012'!$D$20:$H$109,4,0),"")) | BV5: =IF($C5="","",IFERROR(VLOOKUP(CONCATENATE(BS$3,"-",$C5),'FO-GC-012'!$D$20:$H$109,5,0),"")) | BW5: =IF($C5="","",IFERROR(VLOOKUP(CONCATENATE(BW$3,"-",$C5),'FO-GC-012'!$D$20:$H$109,2,0),"")) | BX5: =IF($C5="","",IFERROR(VLOOKUP(CONCATENATE(BW$3,"-",$C5),'FO-GC-012'!$D$20:$H$109,3,0),"")) | BY5: =IF($C5="","",IFERROR(VLOOKUP(CONCATENATE(BW$3,"-",$C5),'FO-GC-012'!$D$20:$H$109,4,0),"")) | BZ5: =IF($C5="","",IFERROR(VLOOKUP(CONCATENATE(BW$3,"-",$C5),'FO-GC-012'!$D$20:$H$109,5,0),"")) | CA5: =IF($C5="","",IFERROR(VLOOKUP(CONCATENATE(CA$3,"-",$C5),'FO-GC-012'!$D$20:$H$109,2,0),"")) | CB5: =IF($C5="","",IFERROR(VLOOKUP(CONCATENATE(CA$3,"-",$C5),'FO-GC-012'!$D$20:$H$109,3,0),"")) | CC5: =IF($C5="","",IFERROR(VLOOKUP(CONCATENATE(CA$3,"-",$C5),'FO-GC-012'!$D$20:$H$109,4,0),"")) | CD5: =IF($C5="","",IFERROR(VLOOKUP(CONCATENATE(CA$3,"-",$C5),'FO-GC-012'!$D$20:$H$109,5,0),"")) | CE5: =IF($C5="","",IFERROR(VLOOKUP(CONCATENATE(CE$3,"-",$C5),'FO-GC-012'!$D$20:$H$109,2,0),"")) | CF5: =IF($C5="","",IFERROR(VLOOKUP(CONCATENATE(CE$3,"-",$C5),'FO-GC-012'!$D$20:$H$109,3,0),"")) | CG5: =IF($C5="","",IFERROR(VLOOKUP(CONCATENATE(CE$3,"-",$C5),'FO-GC-012'!$D$20:$H$109,4,0),"")) | CH5: =IF($C5="","",IFERROR(VLOOKUP(CONCATENATE(CE$3,"-",$C5),'FO-GC-012'!$D$20:$H$109,5,0),""))
B6: =IF(C6="","",COUNTA(C$4:C6)) -> 3 | C6: ='Eq. Auditor'!B5 -> Ana Baos | D6: =IF(C6="","",COUNTIF('FO-GC-012'!A:A,CONCATENATE("P-",C6))) -> 0 | E6: =IF(C6="","",COUNTIF('FO-GC-012'!A:A,CONCATENATE("A-",C6))) -> 0 | F6: =IF(C6="","",SUM(D6:E6)) -> 0 | G6: =IF($C6="","",IFERROR(VLOOKUP(CONCATENATE(G$3,"-",$C6),'FO-GC-012'!$D$20:$H$109,2,0),"")) | H6: =IF($C6="","",IFERROR(VLOOKUP(CONCATENATE(G$3,"-",$C6),'FO-GC-012'!$D$20:$H$109,3,0),"")) | I6: =IF($C6="","",IFERROR(VLOOKUP(CONCATENATE(G$3,"-",$C6),'FO-GC-012'!$D$20:$H$109,4,0),"")) | J6: =IF($C6="","",IFERROR(VLOOKUP(CONCATENATE(G$3,"-",$C6),'FO-GC-012'!$D$20:$H$109,5,0),"")) | K6: =IF($C6="","",IFERROR(VLOOKUP(CONCATENATE(K$3,"-",$C6),'FO-GC-012'!$D$20:$H$109,2,0),"")) | L6: =IF($C6="","",IFERROR(VLOOKUP(CONCATENATE(K$3,"-",$C6),'FO-GC-012'!$D$20:$H$109,3,0),"")) | M6: =IF($C6="","",IFERROR(VLOOKUP(CONCATENATE(K$3,"-",$C6),'FO-GC-012'!$D$20:$H$109,4,0),"")) | N6: =IF($C6="","",IFERROR(VLOOKUP(CONCATENATE(K$3,"-",$C6),'FO-GC-012'!$D$20:$H$109,5,0),"")) | O6: =IF($C6="","",IFERROR(VLOOKUP(CONCATENATE(O$3,"-",$C6),'FO-GC-012'!$D$20:$H$109,2,0),"")) | P6: =IF($C6="","",IFERROR(VLOOKUP(CONCATENATE(O$3,"-",$C6),'FO-GC-012'!$D$20:$H$109,3,0),"")) | Q6: =IF($C6="","",IFERROR(VLOOKUP(CONCATENATE(O$3,"-",$C6),'FO-GC-012'!$D$20:$H$109,4,0),"")) | R6: =IF($C6="","",IFERROR(VLOOKUP(CONCATENATE(O$3,"-",$C6),'FO-GC-012'!$D$20:$H$109,5,0),"")) | S6: =IF($C6="","",IFERROR(VLOOKUP(CONCATENATE(S$3,"-",$C6),'FO-GC-012'!$D$20:$H$109,2,0),"")) | T6: =IF($C6="","",IFERROR(VLOOKUP(CONCATENATE(S$3,"-",$C6),'FO-GC-012'!$D$20:$H$109,3,0),"")) | U6: =IF($C6="","",IFERROR(VLOOKUP(CONCATENATE(S$3,"-",$C6),'FO-GC-012'!$D$20:$H$109,4,0),"")) | V6: =IF($C6="","",IFERROR(VLOOKUP(CONCATENATE(S$3,"-",$C6),'FO-GC-012'!$D$20:$H$109,5,0),"")) | W6: =IF($C6="","",IFERROR(VLOOKUP(CONCATENATE(W$3,"-",$C6),'FO-GC-012'!$D$20:$H$109,2,0),"")) | X6: =IF($C6="","",IFERROR(VLOOKUP(CONCATENATE(W$3,"-",$C6),'FO-GC-012'!$D$20:$H$109,3,0),"")) | Y6: =IF($C6="","",IFERROR(VLOOKUP(CONCATENATE(W$3,"-",$C6),'FO-GC-012'!$D$20:$H$109,4,0),"")) | Z6: =IF($C6="","",IFERROR(VLOOKUP(CONCATENATE(W$3,"-",$C6),'FO-GC-012'!$D$20:$H$109,5,0),"")) | AA6: =IF($C6="","",IFERROR(VLOOKUP(CONCATENATE(AA$3,"-",$C6),'FO-GC-012'!$D$20:$H$109,2,0),"")) | AB6: =IF($C6="","",IFERROR(VLOOKUP(CONCATENATE(AA$3,"-",$C6),'FO-GC-012'!$D$20:$H$109,3,0),"")) | AC6: =IF($C6="","",IFERROR(VLOOKUP(CONCATENATE(AA$3,"-",$C6),'FO-GC-012'!$D$20:$H$109,4,0),"")) | AD6: =IF($C6="","",IFERROR(VLOOKUP(CONCATENATE(AA$3,"-",$C6),'FO-GC-012'!$D$20:$H$109,5,0),"")) | AE6: =IF($C6="","",IFERROR(VLOOKUP(CONCATENATE(AE$3,"-",$C6),'FO-GC-012'!$D$20:$H$109,2,0),"")) | AF6: =IF($C6="","",IFERROR(VLOOKUP(CONCATENATE(AE$3,"-",$C6),'FO-GC-012'!$D$20:$H$109,3,0),"")) | AG6: =IF($C6="","",IFERROR(VLOOKUP(CONCATENATE(AE$3,"-",$C6),'FO-GC-012'!$D$20:$H$109,4,0),"")) | AH6: =IF($C6="","",IFERROR(VLOOKUP(CONCATENATE(AE$3,"-",$C6),'FO-GC-012'!$D$20:$H$109,5,0),"")) | AI6: =IF($C6="","",IFERROR(VLOOKUP(CONCATENATE(AI$3,"-",$C6),'FO-GC-012'!$D$20:$H$109,2,0),"")) | AJ6: =IF($C6="","",IFERROR(VLOOKUP(CONCATENATE(AI$3,"-",$C6),'FO-GC-012'!$D$20:$H$109,3,0),"")) | AK6: =IF($C6="","",IFERROR(VLOOKUP(CONCATENATE(AI$3,"-",$C6),'FO-GC-012'!$D$20:$H$109,4,0),"")) | AL6: =IF($C6="","",IFERROR(VLOOKUP(CONCATENATE(AI$3,"-",$C6),'FO-GC-012'!$D$20:$H$109,5,0),"")) | AM6: =IF($C6="","",IFERROR(VLOOKUP(CONCATENATE(AM$3,"-",$C6),'FO-GC-012'!$D$20:$H$109,2,0),"")) | AN6: =IF($C6="","",IFERROR(VLOOKUP(CONCATENATE(AM$3,"-",$C6),'FO-GC-012'!$D$20:$H$109,3,0),"")) | AO6: =IF($C6="","",IFERROR(VLOOKUP(CONCATENATE(AM$3,"-",$C6),'FO-GC-012'!$D$20:$H$109,4,0),"")) | AP6: =IF($C6="","",IFERROR(VLOOKUP(CONCATENATE(AM$3,"-",$C6),'FO-GC-012'!$D$20:$H$109,5,0),"")) | AQ6: =IF($C6="","",IFERROR(VLOOKUP(CONCATENATE(AQ$3,"-",$C6),'FO-GC-012'!$D$20:$H$109,2,0),"")) | AR6: =IF($C6="","",IFERROR(VLOOKUP(CONCATENATE(AQ$3,"-",$C6),'FO-GC-012'!$D$20:$H$109,3,0),"")) | AS6: =IF($C6="","",IFERROR(VLOOKUP(CONCATENATE(AQ$3,"-",$C6),'FO-GC-012'!$D$20:$H$109,4,0),"")) | AT6: =IF($C6="","",IFERROR(VLOOKUP(CONCATENATE(AQ$3,"-",$C6),'FO-GC-012'!$D$20:$H$109,5,0),"")) | AU6: =IF($C6="","",IFERROR(VLOOKUP(CONCATENATE(AU$3,"-",$C6),'FO-GC-012'!$D$20:$H$109,2,0),"")) | AV6: =IF($C6="","",IFERROR(VLOOKUP(CONCATENATE(AU$3,"-",$C6),'FO-GC-012'!$D$20:$H$109,3,0),"")) | AW6: =IF($C6="","",IFERROR(VLOOKUP(CONCATENATE(AU$3,"-",$C6),'FO-GC-012'!$D$20:$H$109,4,0),"")) | AX6: =IF($C6="","",IFERROR(VLOOKUP(CONCATENATE(AU$3,"-",$C6),'FO-GC-012'!$D$20:$H$109,5,0),"")) | AY6: =IF($C6="","",IFERROR(VLOOKUP(CONCATENATE(AY$3,"-",$C6),'FO-GC-012'!$D$20:$H$109,2,0),"")) | AZ6: =IF($C6="","",IFERROR(VLOOKUP(CONCATENATE(AY$3,"-",$C6),'FO-GC-012'!$D$20:$H$109,3,0),"")) | BA6: =IF($C6="","",IFERROR(VLOOKUP(CONCATENATE(AY$3,"-",$C6),'FO-GC-012'!$D$20:$H$109,4,0),"")) | BB6: =IF($C6="","",IFERROR(VLOOKUP(CONCATENATE(AY$3,"-",$C6),'FO-GC-012'!$D$20:$H$109,5,0),"")) | BC6: =IF($C6="","",IFERROR(VLOOKUP(CONCATENATE(BC$3,"-",$C6),'FO-GC-012'!$D$20:$H$109,2,0),"")) | BD6: =IF($C6="","",IFERROR(VLOOKUP(CONCATENATE(BC$3,"-",$C6),'FO-GC-012'!$D$20:$H$109,3,0),"")) | BE6: =IF($C6="","",IFERROR(VLOOKUP(CONCATENATE(BC$3,"-",$C6),'FO-GC-012'!$D$20:$H$109,4,0),"")) | BF6: =IF($C6="","",IFERROR(VLOOKUP(CONCATENATE(BC$3,"-",$C6),'FO-GC-012'!$D$20:$H$109,5,0),"")) | BG6: =IF($C6="","",IFERROR(VLOOKUP(CONCATENATE(BG$3,"-",$C6),'FO-GC-012'!$D$20:$H$109,2,0),"")) | BH6: =IF($C6="","",IFERROR(VLOOKUP(CONCATENATE(BG$3,"-",$C6),'FO-GC-012'!$D$20:$H$109,3,0),"")) | BI6: =IF($C6="","",IFERROR(VLOOKUP(CONCATENATE(BG$3,"-",$C6),'FO-GC-012'!$D$20:$H$109,4,0),"")) | BJ6: =IF($C6="","",IFERROR(VLOOKUP(CONCATENATE(BG$3,"-",$C6),'FO-GC-012'!$D$20:$H$109,5,0),"")) | BK6: =IF($C6="","",IFERROR(VLOOKUP(CONCATENATE(BK$3,"-",$C6),'FO-GC-012'!$D$20:$H$109,2,0),"")) | BL6: =IF($C6="","",IFERROR(VLOOKUP(CONCATENATE(BK$3,"-",$C6),'FO-GC-012'!$D$20:$H$109,3,0),"")) | BM6: =IF($C6="","",IFERROR(VLOOKUP(CONCATENATE(BK$3,"-",$C6),'FO-GC-012'!$D$20:$H$109,4,0),"")) | BN6: =IF($C6="","",IFERROR(VLOOKUP(CONCATENATE(BK$3,"-",$C6),'FO-GC-012'!$D$20:$H$109,5,0),"")) | BO6: =IF($C6="","",IFERROR(VLOOKUP(CONCATENATE(BO$3,"-",$C6),'FO-GC-012'!$D$20:$H$109,2,0),"")) | BP6: =IF($C6="","",IFERROR(VLOOKUP(CONCATENATE(BO$3,"-",$C6),'FO-GC-012'!$D$20:$H$109,3,0),"")) | BQ6: =IF($C6="","",IFERROR(VLOOKUP(CONCATENATE(BO$3,"-",$C6),'FO-GC-012'!$D$20:$H$109,4,0),"")) | BR6: =IF($C6="","",IFERROR(VLOOKUP(CONCATENATE(BO$3,"-",$C6),'FO-GC-012'!$D$20:$H$109,5,0),"")) | BS6: =IF($C6="","",IFERROR(VLOOKUP(CONCATENATE(BS$3,"-",$C6),'FO-GC-012'!$D$20:$H$109,2,0),"")) | BT6: =IF($C6="","",IFERROR(VLOOKUP(CONCATENATE(BS$3,"-",$C6),'FO-GC-012'!$D$20:$H$109,3,0),"")) | BU6: =IF($C6="","",IFERROR(VLOOKUP(CONCATENATE(BS$3,"-",$C6),'FO-GC-012'!$D$20:$H$109,4,0),"")) | BV6: =IF($C6="","",IFERROR(VLOOKUP(CONCATENATE(BS$3,"-",$C6),'FO-GC-012'!$D$20:$H$109,5,0),"")) | BW6: =IF($C6="","",IFERROR(VLOOKUP(CONCATENATE(BW$3,"-",$C6),'FO-GC-012'!$D$20:$H$109,2,0),"")) | BX6: =IF($C6="","",IFERROR(VLOOKUP(CONCATENATE(BW$3,"-",$C6),'FO-GC-012'!$D$20:$H$109,3,0),"")) | BY6: =IF($C6="","",IFERROR(VLOOKUP(CONCATENATE(BW$3,"-",$C6),'FO-GC-012'!$D$20:$H$109,4,0),"")) | BZ6: =IF($C6="","",IFERROR(VLOOKUP(CONCATENATE(BW$3,"-",$C6),'FO-GC-012'!$D$20:$H$109,5,0),"")) | CA6: =IF($C6="","",IFERROR(VLOOKUP(CONCATENATE(CA$3,"-",$C6),'FO-GC-012'!$D$20:$H$109,2,0),"")) | CB6: =IF($C6="","",IFERROR(VLOOKUP(CONCATENATE(CA$3,"-",$C6),'FO-GC-012'!$D$20:$H$109,3,0),"")) | CC6: =IF($C6="","",IFERROR(VLOOKUP(CONCATENATE(CA$3,"-",$C6),'FO-GC-012'!$D$20:$H$109,4,0),"")) | CD6: =IF($C6="","",IFERROR(VLOOKUP(CONCATENATE(CA$3,"-",$C6),'FO-GC-012'!$D$20:$H$109,5,0),"")) | CE6: =IF($C6="","",IFERROR(VLOOKUP(CONCATENATE(CE$3,"-",$C6),'FO-GC-012'!$D$20:$H$109,2,0),"")) | CF6: =IF($C6="","",IFERROR(VLOOKUP(CONCATENATE(CE$3,"-",$C6),'FO-GC-012'!$D$20:$H$109,3,0),"")) | CG6: =IF($C6="","",IFERROR(VLOOKUP(CONCATENATE(CE$3,"-",$C6),'FO-GC-012'!$D$20:$H$109,4,0),"")) | CH6: =IF($C6="","",IFERROR(VLOOKUP(CONCATENATE(CE$3,"-",$C6),'FO-GC-012'!$D$20:$H$109,5,0),""))
B7: =IF(C7="","",COUNTA(C$4:C7)) -> 4 | C7: ='Eq. Auditor'!B6 -> *Carlos Andrés Durán Enríquez | D7: =IF(C7="","",COUNTIF('FO-GC-012'!A:A,CONCATENATE("P-",C7))) -> 0 | E7: =IF(C7="","",COUNTIF('FO-GC-012'!A:A,CONCATENATE("A-",C7))) -> 0 | F7: =IF(C7="","",SUM(D7:E7)) -> 0 | G7: =IF($C7="","",IFERROR(VLOOKUP(CONCATENATE(G$3,"-",$C7),'FO-GC-012'!$D$20:$H$109,2,0),"")) | H7: =IF($C7="","",IFERROR(VLOOKUP(CONCATENATE(G$3,"-",$C7),'FO-GC-012'!$D$20:$H$109,3,0),"")) | I7: =IF($C7="","",IFERROR(VLOOKUP(CONCATENATE(G$3,"-",$C7),'FO-GC-012'!$D$20:$H$109,4,0),"")) | J7: =IF($C7="","",IFERROR(VLOOKUP(CONCATENATE(G$3,"-",$C7),'FO-GC-012'!$D$20:$H$109,5,0),"")) | K7: =IF($C7="","",IFERROR(VLOOKUP(CONCATENATE(K$3,"-",$C7),'FO-GC-012'!$D$20:$H$109,2,0),"")) | L7: =IF($C7="","",IFERROR(VLOOKUP(CONCATENATE(K$3,"-",$C7),'FO-GC-012'!$D$20:$H$109,3,0),"")) | M7: =IF($C7="","",IFERROR(VLOOKUP(CONCATENATE(K$3,"-",$C7),'FO-GC-012'!$D$20:$H$109,4,0),"")) | N7: =IF($C7="","",IFERROR(VLOOKUP(CONCATENATE(K$3,"-",$C7),'FO-GC-012'!$D$20:$H$109,5,0),"")) | O7: =IF($C7="","",IFERROR(VLOOKUP(CONCATENATE(O$3,"-",$C7),'FO-GC-012'!$D$20:$H$109,2,0),"")) | P7: =IF($C7="","",IFERROR(VLOOKUP(CONCATENATE(O$3,"-",$C7),'FO-GC-012'!$D$20:$H$109,3,0),"")) | Q7: =IF($C7="","",IFERROR(VLOOKUP(CONCATENATE(O$3,"-",$C7),'FO-GC-012'!$D$20:$H$109,4,0),"")) | R7: =IF($C7="","",IFERROR(VLOOKUP(CONCATENATE(O$3,"-",$C7),'FO-GC-012'!$D$20:$H$109,5,0),"")) | S7: =IF($C7="","",IFERROR(VLOOKUP(CONCATENATE(S$3,"-",$C7),'FO-GC-012'!$D$20:$H$109,2,0),"")) | T7: =IF($C7="","",IFERROR(VLOOKUP(CONCATENATE(S$3,"-",$C7),'FO-GC-012'!$D$20:$H$109,3,0),"")) | U7: =IF($C7="","",IFERROR(VLOOKUP(CONCATENATE(S$3,"-",$C7),'FO-GC-012'!$D$20:$H$109,4,0),"")) | V7: =IF($C7="","",IFERROR(VLOOKUP(CONCATENATE(S$3,"-",$C7),'FO-GC-012'!$D$20:$H$109,5,0),"")) | W7: =IF($C7="","",IFERROR(VLOOKUP(CONCATENATE(W$3,"-",$C7),'FO-GC-012'!$D$20:$H$109,2,0),"")) | X7: =IF($C7="","",IFERROR(VLOOKUP(CONCATENATE(W$3,"-",$C7),'FO-GC-012'!$D$20:$H$109,3,0),"")) | Y7: =IF($C7="","",IFERROR(VLOOKUP(CONCATENATE(W$3,"-",$C7),'FO-GC-012'!$D$20:$H$109,4,0),"")) | Z7: =IF($C7="","",IFERROR(VLOOKUP(CONCATENATE(W$3,"-",$C7),'FO-GC-012'!$D$20:$H$109,5,0),"")) | AA7: =IF($C7="","",IFERROR(VLOOKUP(CONCATENATE(AA$3,"-",$C7),'FO-GC-012'!$D$20:$H$109,2,0),"")) | AB7: =IF($C7="","",IFERROR(VLOOKUP(CONCATENATE(AA$3,"-",$C7),'FO-GC-012'!$D$20:$H$109,3,0),"")) | AC7: =IF($C7="","",IFERROR(VLOOKUP(CONCATENATE(AA$3,"-",$C7),'FO-GC-012'!$D$20:$H$109,4,0),"")) | AD7: =IF($C7="","",IFERROR(VLOOKUP(CONCATENATE(AA$3,"-",$C7),'FO-GC-012'!$D$20:$H$109,5,0),"")) | AE7: =IF($C7="","",IFERROR(VLOOKUP(CONCATENATE(AE$3,"-",$C7),'FO-GC-012'!$D$20:$H$109,2,0),"")) | AF7: =IF($C7="","",IFERROR(VLOOKUP(CONCATENATE(AE$3,"-",$C7),'FO-GC-012'!$D$20:$H$109,3,0),"")) | AG7: =IF($C7="","",IFERROR(VLOOKUP(CONCATENATE(AE$3,"-",$C7),'FO-GC-012'!$D$20:$H$109,4,0),"")) | AH7: =IF($C7="","",IFERROR(VLOOKUP(CONCATENATE(AE$3,"-",$C7),'FO-GC-012'!$D$20:$H$109,5,0),"")) | AI7: =IF($C7="","",IFERROR(VLOOKUP(CONCATENATE(AI$3,"-",$C7),'FO-GC-012'!$D$20:$H$109,2,0),"")) | AJ7: =IF($C7="","",IFERROR(VLOOKUP(CONCATENATE(AI$3,"-",$C7),'FO-GC-012'!$D$20:$H$109,3,0),"")) | AK7: =IF($C7="","",IFERROR(VLOOKUP(CONCATENATE(AI$3,"-",$C7),'FO-GC-012'!$D$20:$H$109,4,0),"")) | AL7: =IF($C7="","",IFERROR(VLOOKUP(CONCATENATE(AI$3,"-",$C7),'FO-GC-012'!$D$20:$H$109,5,0),"")) | AM7: =IF($C7="","",IFERROR(VLOOKUP(CONCATENATE(AM$3,"-",$C7),'FO-GC-012'!$D$20:$H$109,2,0),"")) | AN7: =IF($C7="","",IFERROR(VLOOKUP(CONCATENATE(AM$3,"-",$C7),'FO-GC-012'!$D$20:$H$109,3,0),"")) | AO7: =IF($C7="","",IFERROR(VLOOKUP(CONCATENATE(AM$3,"-",$C7),'FO-GC-012'!$D$20:$H$109,4,0),"")) | AP7: =IF($C7="","",IFERROR(VLOOKUP(CONCATENATE(AM$3,"-",$C7),'FO-GC-012'!$D$20:$H$109,5,0),"")) | AQ7: =IF($C7="","",IFERROR(VLOOKUP(CONCATENATE(AQ$3,"-",$C7),'FO-GC-012'!$D$20:$H$109,2,0),"")) | AR7: =IF($C7="","",IFERROR(VLOOKUP(CONCATENATE(AQ$3,"-",$C7),'FO-GC-012'!$D$20:$H$109,3,0),"")) | AS7: =IF($C7="","",IFERROR(VLOOKUP(CONCATENATE(AQ$3,"-",$C7),'FO-GC-012'!$D$20:$H$109,4,0),"")) | AT7: =IF($C7="","",IFERROR(VLOOKUP(CONCATENATE(AQ$3,"-",$C7),'FO-GC-012'!$D$20:$H$109,5,0),"")) | AU7: =IF($C7="","",IFERROR(VLOOKUP(CONCATENATE(AU$3,"-",$C7),'FO-GC-012'!$D$20:$H$109,2,0),"")) | AV7: =IF($C7="","",IFERROR(VLOOKUP(CONCATENATE(AU$3,"-",$C7),'FO-GC-012'!$D$20:$H$109,3,0),"")) | AW7: =IF($C7="","",IFERROR(VLOOKUP(CONCATENATE(AU$3,"-",$C7),'FO-GC-012'!$D$20:$H$109,4,0),"")) | AX7: =IF($C7="","",IFERROR(VLOOKUP(CONCATENATE(AU$3,"-",$C7),'FO-GC-012'!$D$20:$H$109,5,0),"")) | AY7: =IF($C7="","",IFERROR(VLOOKUP(CONCATENATE(AY$3,"-",$C7),'FO-GC-012'!$D$20:$H$109,2,0),"")) | AZ7: =IF($C7="","",IFERROR(VLOOKUP(CONCATENATE(AY$3,"-",$C7),'FO-GC-012'!$D$20:$H$109,3,0),"")) | BA7: =IF($C7="","",IFERROR(VLOOKUP(CONCATENATE(AY$3,"-",$C7),'FO-GC-012'!$D$20:$H$109,4,0),"")) | BB7: =IF($C7="","",IFERROR(VLOOKUP(CONCATENATE(AY$3,"-",$C7),'FO-GC-012'!$D$20:$H$109,5,0),"")) | BC7: =IF($C7="","",IFERROR(VLOOKUP(CONCATENATE(BC$3,"-",$C7),'FO-GC-012'!$D$20:$H$109,2,0),"")) | BD7: =IF($C7="","",IFERROR(VLOOKUP(CONCATENATE(BC$3,"-",$C7),'FO-GC-012'!$D$20:$H$109,3,0),"")) | BE7: =IF($C7="","",IFERROR(VLOOKUP(CONCATENATE(BC$3,"-",$C7),'FO-GC-012'!$D$20:$H$109,4,0),"")) | BF7: =IF($C7="","",IFERROR(VLOOKUP(CONCATENATE(BC$3,"-",$C7),'FO-GC-012'!$D$20:$H$109,5,0),"")) | BG7: =IF($C7="","",IFERROR(VLOOKUP(CONCATENATE(BG$3,"-",$C7),'FO-GC-012'!$D$20:$H$109,2,0),"")) | BH7: =IF($C7="","",IFERROR(VLOOKUP(CONCATENATE(BG$3,"-",$C7),'FO-GC-012'!$D$20:$H$109,3,0),"")) | BI7: =IF($C7="","",IFERROR(VLOOKUP(CONCATENATE(BG$3,"-",$C7),'FO-GC-012'!$D$20:$H$109,4,0),"")) | BJ7: =IF($C7="","",IFERROR(VLOOKUP(CONCATENATE(BG$3,"-",$C7),'FO-GC-012'!$D$20:$H$109,5,0),"")) | BK7: =IF($C7="","",IFERROR(VLOOKUP(CONCATENATE(BK$3,"-",$C7),'FO-GC-012'!$D$20:$H$109,2,0),"")) | BL7: =IF($C7="","",IFERROR(VLOOKUP(CONCATENATE(BK$3,"-",$C7),'FO-GC-012'!$D$20:$H$109,3,0),"")) | BM7: =IF($C7="","",IFERROR(VLOOKUP(CONCATENATE(BK$3,"-",$C7),'FO-GC-012'!$D$20:$H$109,4,0),"")) | BN7: =IF($C7="","",IFERROR(VLOOKUP(CONCATENATE(BK$3,"-",$C7),'FO-GC-012'!$D$20:$H$109,5,0),"")) | BO7: =IF($C7="","",IFERROR(VLOOKUP(CONCATENATE(BO$3,"-",$C7),'FO-GC-012'!$D$20:$H$109,2,0),"")) | BP7: =IF($C7="","",IFERROR(VLOOKUP(CONCATENATE(BO$3,"-",$C7),'FO-GC-012'!$D$20:$H$109,3,0),"")) | BQ7: =IF($C7="","",IFERROR(VLOOKUP(CONCATENATE(BO$3,"-",$C7),'FO-GC-012'!$D$20:$H$109,4,0),"")) | BR7: =IF($C7="","",IFERROR(VLOOKUP(CONCATENATE(BO$3,"-",$C7),'FO-GC-012'!$D$20:$H$109,5,0),"")) | BS7: =IF($C7="","",IFERROR(VLOOKUP(CONCATENATE(BS$3,"-",$C7),'FO-GC-012'!$D$20:$H$109,2,0),"")) | BT7: =IF($C7="","",IFERROR(VLOOKUP(CONCATENATE(BS$3,"-",$C7),'FO-GC-012'!$D$20:$H$109,3,0),"")) | BU7: =IF($C7="","",IFERROR(VLOOKUP(CONCATENATE(BS$3,"-",$C7),'FO-GC-012'!$D$20:$H$109,4,0),"")) | BV7: =IF($C7="","",IFERROR(VLOOKUP(CONCATENATE(BS$3,"-",$C7),'FO-GC-012'!$D$20:$H$109,5,0),"")) | BW7: =IF($C7="","",IFERROR(VLOOKUP(CONCATENATE(BW$3,"-",$C7),'FO-GC-012'!$D$20:$H$109,2,0),"")) | BX7: =IF($C7="","",IFERROR(VLOOKUP(CONCATENATE(BW$3,"-",$C7),'FO-GC-012'!$D$20:$H$109,3,0),"")) | BY7: =IF($C7="","",IFERROR(VLOOKUP(CONCATENATE(BW$3,"-",$C7),'FO-GC-012'!$D$20:$H$109,4,0),"")) | BZ7: =IF($C7="","",IFERROR(VLOOKUP(CONCATENATE(BW$3,"-",$C7),'FO-GC-012'!$D$20:$H$109,5,0),"")) | CA7: =IF($C7="","",IFERROR(VLOOKUP(CONCATENATE(CA$3,"-",$C7),'FO-GC-012'!$D$20:$H$109,2,0),"")) | CB7: =IF($C7="","",IFERROR(VLOOKUP(CONCATENATE(CA$3,"-",$C7),'FO-GC-012'!$D$20:$H$109,3,0),"")) | CC7: =IF($C7="","",IFERROR(VLOOKUP(CONCATENATE(CA$3,"-",$C7),'FO-GC-012'!$D$20:$H$109,4,0),"")) | CD7: =IF($C7="","",IFERROR(VLOOKUP(CONCATENATE(CA$3,"-",$C7),'FO-GC-012'!$D$20:$H$109,5,0),"")) | CE7: =IF($C7="","",IFERROR(VLOOKUP(CONCATENATE(CE$3,"-",$C7),'FO-GC-012'!$D$20:$H$109,2,0),"")) | CF7: =IF($C7="","",IFERROR(VLOOKUP(CONCATENATE(CE$3,"-",$C7),'FO-GC-012'!$D$20:$H$109,3,0),"")) | CG7: =IF($C7="","",IFERROR(VLOOKUP(CONCATENATE(CE$3,"-",$C7),'FO-GC-012'!$D$20:$H$109,4,0),"")) | CH7: =IF($C7="","",IFERROR(VLOOKUP(CONCATENATE(CE$3,"-",$C7),'FO-GC-012'!$D$20:$H$109,5,0),""))
