Workbook

Sheet FO-GC-015
A1: =COLUMN() -> 1 | B1: =COLUMN() -> 2 | C1: =COLUMN() -> 3 | D1: =COLUMN() -> 4 | E1: =COLUMN() -> 5 | F1: =COLUMN() -> 6 | G1: =COLUMN() -> 7 | H1: =COLUMN() -> 8 | ... AL1: =COLUMN() -> 38
I3: 2Reconocimiento 202 | AO3: Instrucciones para el diligenciamiento de la "Hoja de Verificación de Auditorías"
AO5: 1. | AP5: Registre el cilco de la Auditoría. Ejemplo: "2025" para ciclos anuales o "2025-S1" para ciclos semestrales.
AO6: 2. | AP6: Registre los criterios de auditoría establecidos en el Programa de Auditoria del ciclo correspondiente.
AO7: 3. | AP7: Seleccione la auditoria a realizar desplegando el listado de procesos y programas a auditar.
AO8: 4. | AP8: Este campo está fomulado. El ID corresponderá al mismo asignado en el Programa de Auditoría. Previamente el Auditor Líder a cargado en este formato el listado de auditorias programadas.
C10: 1. Ciclo Auditoria | E10: 2. Criterios de Auditoria | U10: 3. Proceso / Programa Académico | AB10: 4. ID | AD10: 5. Colaborador Auditado
AB11: =IFERROR(VLOOKUP(U11,Listas!C:E,3,0),"") | AD11: Nombre | AO11: 5. | AP11: Registre el día de la auditoría el colaborador de la Institución que recibió la auditoria.
AD12: Cargo | AO12: 6. | AP12: Este campo está fomulado. Una vez que se selecciona la auditoría a realizar, el formulario traerá la información correspondiente a la propuesta de valor del proceso, es decir el Objetivo del Proceso, el cual está registrado en las Caracterizaciones de Proceso.
C14: 6. Propuesta de Valor del Proceso (Objetivo del Proceso) | Z14: 8. Requisitos ISO 9001:2015 | AF14: 9. Fecha Ejecución de la Auditoría
C15: =IFERROR(VLOOKUP($U$11,'SGC-Vigente'!C:F,2,0),"***") -> *** | Z15: =IFERROR(VLOOKUP($U$11,'SGC-Vigente'!C:F,4,0),"***") -> *** | AO15: 7. | AP15: Este campo está fomulado. Una vez que se selecciona la auditoría a realizar, el formulario traerá la información correspondiente a la propuesta de valor del proceso, es decir el Objetivo del Proceso, el cual está registrado en las Caracterizaciones de Proceso.
AF16: 10. Locación
AF17: 11. Auditor Principal | AO17: 8. | AP17: Este campo está fomulado. Una vez que se selecciona la auditoría a realizar, el formulario traerá la información correspondiente a los requisitos de la ISO 9001:2015 Aplicables.
C18: 7. Requisitos de Ley Aplicables | F18: =IFERROR(VLOOKUP($U$11,'SGC-Vigente'!C:F,3,0),"***") -> ***
AF19: 12. Auditor Asistente | AO19: 9. | AP19: Registre la fecha en que se ejecutó la auditoria interna.
AO20: 10. | AP20: Seleccione la locación en donde se desarrolla la auditoria.
C22: 13. Referencia Normativa / Documento | F22: 14. Pregunta / Verificación | P22: 15. Registro / Evidencia | X22: 16. Hallazgos | AA22: 17. Req. ISO 9001 | AC22: 18. Descripción del Hallazgo Breve descripción del incumplimiento (NC) o riesgo de incumplimeinto (Obs) | AO22: 11. | AP22: Seleccione el Auditor Principal asignado, según el Programa de Auditoría para el presente ciclo.
X23: Con | Y23: NC | Z23: Obs | AO23: 12. | AP23: Seleccione el Auditor Asistente asignado, según el Programa de Auditoría para el presente ciclo.
X24: =COUNTIF(X25:X56,"X") -> 0 | Y24: =COUNTIF(Y25:Y56,"X") -> 0 | Z24: =COUNTIF(Z25:Z56,"X") -> 0
A25: =IF(Y25="X",CONCATENATE("NC-",COUNTA(Y$25:Y25)),IF(Z25="X",CONCATENATE("Obs-",COUNTA(Z$25:Z25)),"-")) -> - | AO25: 13. | AP25: Registre el requisito, referencia normativa o documental relacionada con la pregunta o verificación colocada en el el siguiente campo "14. Pregunta / Verificación". Ejemplo: Puede ser una Ley, decreto, resolución o un acto administrativo Institucional (Resolución) aplicables, un requisito específico de la nomra ISO 9001:2015, o un documento del Sistema de Gestión de Calidad relacionado con el proceso.
A26: =IF(Y26="X",CONCATENATE("NC-",COUNTA(Y$25:Y26)),IF(Z26="X",CONCATENATE("Obs-",COUNTA(Z$25:Z26)),"-")) -> - | AO26: 14. | AP26: Registre la pregunta o verificación a validar durante la auditoría.
A27: =IF(Y27="X",CONCATENATE("NC-",COUNTA(Y$25:Y27)),IF(Z27="X",CONCATENATE("Obs-",COUNTA(Z$25:Z27)),"-")) -> - | AO27: 15. | AP27: Registre la evidencia verificada durante la auditoria, especificando el nombre de la evidencia y el periodo en que se generó.
A28: =IF(Y28="X",CONCATENATE("NC-",COUNTA(Y$25:Y28)),IF(Z28="X",CONCATENATE("Obs-",COUNTA(Z$25:Z28)),"-")) -> - | AO28: 16. | AP28: Seleccione con una "X" el tipo de hallazgo de auditoría (Con: "Conforme" / NC: "No Conformidad" / Obs: "Observación") • Conforme: Cumplimiento del requisito, • No Conformidad: Incumplimiento del requisito, • Obs: Observación: Hallazgo de auditoría, el cual indica una situación que conlleva una oportunidad de mejora o un riesgo potencial de constituirse en No Conformidad.
A29: =IF(Y29="X",CONCATENATE("NC-",COUNTA(Y$25:Y29)),IF(Z29="X",CONCATENATE("Obs-",COUNTA(Z$25:Z29)),"-")) -> - | AO29: 17. | AP29: Seleccione el requisito de la ISO 9001:2015 al que se le asigna el hallazgo de auditoria. Se desea especificar mas de un requisito, proceda a escribirlos en este campo separados por un "/".
A30: =IF(Y30="X",CONCATENATE("NC-",COUNTA(Y$25:Y30)),IF(Z30="X",CONCATENATE("Obs-",COUNTA(Z$25:Z30)),"-")) -> - | AO30: 18. | AP30: Realice una breve descripción del hallazgo, especificando desde el inicio si "se cumple" o "no se cumple" con la verificación realizada según la evidencia observada frente a la referencia normativa aplicable. Esta información permitirá estructurar en el informe de auditoria la redacción de la No Conformidad u Observación, o para resaltar una fortaleza o debilidad evidenciada en el proceso / programa académico.
A31: =IF(Y31="X",CONCATENATE("NC-",COUNTA(Y$25:Y31)),IF(Z31="X",CONCATENATE("Obs-",COUNTA(Z$25:Z31)),"-")) -> - | AO31: 19. | AP31: Al realizar la verificación del desempeño del proceso o programa académico, registre en este campo el nombre del indicador del proceso validado en la auditoría.
A32: =IF(Y32="X",CONCATENATE("NC-",COUNTA(Y$25:Y32)),IF(Z32="X",CONCATENATE("Obs-",COUNTA(Z$25:Z32)),"-")) -> - | AO32: 20. | AP32: Registre la meta especificada en la hoja de vida del indicador.
A33: =IF(Y33="X",CONCATENATE("NC-",COUNTA(Y$25:Y33)),IF(Z33="X",CONCATENATE("Obs-",COUNTA(Z$25:Z33)),"-")) -> - | AO33: 21. | AP33: Registre la medición registrada en la hoja de vida del indicador.
A34: =IF(Y34="X",CONCATENATE("NC-",COUNTA(Y$25:Y34)),IF(Z34="X",CONCATENATE("Obs-",COUNTA(Z$25:Z34)),"-")) -> - | AO34: 22. | AP34: Registre el periodo al que corresponde la medición del indicador registrada en la hoja de vida correspondiente.
A35: =IF(Y35="X",CONCATENATE("NC-",COUNTA(Y$25:Y35)),IF(Z35="X",CONCATENATE("Obs-",COUNTA(Z$25:Z35)),"-")) -> - | AO35: 23. | AP35: En esta sección registre la documentación verificada en el proceso o programa académico. Inicie registrando el código del documento si este tiene asociado alguno. En caso contrario deje este campo vacío.
A36: =IF(Y36="X",CONCATENATE("NC-",COUNTA(Y$25:Y36)),IF(Z36="X",CONCATENATE("Obs-",COUNTA(Z$25:Z36)),"-")) -> - | AO36: 24. | AP36: Registre la versión del documento, si este tiene la información de la vigencia. En caso contrario deje este campo vacío.
... A38: =IF(Y38="X",CONCATENATE("NC-",COUNTA(Y$25:Y38)),IF(Z38="X",CONCATENATE("Obs-",COUNTA(Z$25:Z38)),"-")) -> - | AO38: 26. | AP38: Registre las Observaciones Generales de la Auditoria, iniciando por la fortalezas del proceso o programa académico que le permitirán dar cumplimiento a la propuesta de valo u objetivo del proceso. De igual manera, mencione las debilidades que podrían poner en riesgo el cumplimiento del Objetivo del Proceso.
A39: =IF(Y39="X",CONCATENATE("NC-",COUNTA(Y$25:Y39)),IF(Z39="X",CONCATENATE("Obs-",COUNTA(Z$25:Z39)),"-")) -> - | AP39: Mencione el equipo de colaboradores que acompañaron al Líder del Proceso o Programa Académico a recibir la auditoría y la disposición general de la misma para presentar las evidencias solicitadas y la disposición para mejorar los hallazgos identificados.
A40: =IF(Y40="X",CONCATENATE("NC-",COUNTA(Y$25:Y40)),IF(Z40="X",CONCATENATE("Obs-",COUNTA(Z$25:Z40)),"-")) -> -
A41: =IF(Y41="X",CONCATENATE("NC-",COUNTA(Y$25:Y41)),IF(Z41="X",CONCATENATE("Obs-",COUNTA(Z$25:Z41)),"-")) -> -
A42: =IF(Y42="X",CONCATENATE("NC-",COUNTA(Y$25:Y42)),IF(Z42="X",CONCATENATE("Obs-",COUNTA(Z$25:Z42)),"-")) -> -
A43: =IF(Y43="X",CONCATENATE("NC-",COUNTA(Y$25:Y43)),IF(Z43="X",CONCATENATE("Obs-",COUNTA(Z$25:Z43)),"-")) -> -
A44: =IF(Y44="X",CONCATENATE("NC-",COUNTA(Y$25:Y44)),IF(Z44="X",CONCATENATE("Obs-",COUNTA(Z$25:Z44)),"-")) -> -
A45: =IF(Y45="X",CONCATENATE("NC-",COUNTA(Y$25:Y45)),IF(Z45="X",CONCATENATE("Obs-",COUNTA(Z$25:Z45)),"-")) -> -
A46: =IF(Y46="X",CONCATENATE("NC-",COUNTA(Y$25:Y46)),IF(Z46="X",CONCATENATE("Obs-",COUNTA(Z$25:Z46)),"-")) -> -
...

Sheet Req. ISO 9001-2015
B1: Requisitos ISO 9001:2015
A2: Num. | C2: Requisito
A4: 9 | B4: 4. | C4: CONTEXTO DE LA ORGANIXZACIÓN
A5: =COUNTIF(#REF!,"X") -> #REF! | B5: 4.1. | C5: Comprensión de la Organización y de su contexto
A6: =COUNTIF(#REF!,"X") -> #REF! | B6: 4.2. | C6: Comprensión de las necesidades y expectativas de las partes interesadas
A7: =COUNTIF(#REF!,"X") -> #REF! | B7: 4.3. | C7: Determinación del alcance del Sistema de Gestión de Calidad
A8: =COUNTIF(#REF!,"X") -> #REF! | B8: 4.4. | C8: Sistema de Gestión de Calidad y sus Procesos
A9: =COUNTIF(#REF!,"X") -> #REF! | B9: 4.4.1. | C9: Establecer, implementar, mantener y mejorar el SGC, incluidos los procesos necesarios y sus interaccionas
A10: =COUNTIF(#REF!,"X") -> #REF! | B10: 4.4.2. | C10: Mantener información documentada y conservarla para tener confianza de que los procesos se realizan según lo planificado
A11: =COUNTIF(#REF!,"X") -> #REF!
A12: 9 | B12: 5. | C12: LIDERAZGO
A13: =COUNTIF(#REF!,"X") -> #REF! | B13: 5.1. | C13: Liderazgo y Compromiso
A14: =COUNTIF(#REF!,"X") -> #REF! | B14: 5.1.1. | C14: Generalidades. La Organización debe demostrar liderazgo y compromiso con respecto al SGC. (a, b, c, d, e, f, g, h, i, j.)
A15: =COUNTIF(#REF!,"X") -> #REF! | B15: 5.1.2. | C15: Enfoque al Cliente. La Alta Dirección debe asegurarse que se determinan, comprenden y cumplen los Requisitos del Cliente, los legales y reglamentarios aplicables
A16: =COUNTIF(#REF!,"X") -> #REF! | B16: 5.2. | C16: Política
A17: =COUNTIF(#REF!,"X") -> #REF! | B17: 5.2.1. | C17: Establecimiento de la Política de Calidad
A18: =COUNTIF(#REF!,"X") -> #REF! | B18: 5.2.2. | C18: Comunicación de la Política de Calidad
A19: =COUNTIF(#REF!,"X") -> #REF! | B19: 5.3. | C19: Roles, responsabilidades y autoridades en la Organización. Asegurarse que para los roles pertinentes se asignen, se comuniquen y se entiendan en la Org. (a, b, c.)
A20: =COUNTIF(#REF!,"X") -> #REF!
A21: 9 | B21: 6. | C21: PLANIFICACIÓN
A22: =COUNTIF(#REF!,"X") -> #REF! | B22: 6.1. | C22: Acciones para abordar riesgos y oportunidades
A23: =COUNTIF(#REF!,"X") -> #REF! | B23: 6.1.1. | C23: La Organización debe considerar las cuestiones referidas en (4.1.) y requisitos referidos en (4.2.)
A24: =COUNTIF(#REF!,"X") -> #REF! | B24: 6.1.2. | C24: La Organización de planificar: * Acciones para abordar riesgos y oportunidades. * La manera de integrar e implementar acciones en sus procesos del SGC y evaluar la eficacia de estas acciones. "Las acciones para abordar los riesgos y oportunidades deben ser proporcionales al impacto potencial en la conformidad de los productos y los servicios.
A25: =COUNTIF(#REF!,"X") -> #REF! | B25: 6.2. | C25: Objetivos de la Calidad y planificación para lograrlos
A26: =COUNTIF(#REF!,"X") -> #REF! | B26: 6.2.1. | C26: La Organización debe establecer Objetivos de Calidad
A27: =COUNTIF(#REF!,"X") -> #REF! | B27: 6.2.2. | C27: Al planificar como lograr los O.C. la Org. Debe determinar: a) que va a hacer, b) recursos, c) responsables, d) cuando se finalizará y e) cómo se evaluarán los resultados
A28: =COUNTIF(#REF!,"X") -> #REF! | B28: 6.3. | C28: Planificación de Cambios. Cuando la Org. Determine la necesidad de cambios al SGC, estos se deben llevar de manera planificada (4.4.), considerar a), b), c), d)
A29: =COUNTIF(#REF!,"X") -> #REF!
A30: 9 | B30: 7. | C30: APOYO
A31: =COUNTIF(#REF!,"X") -> #REF! | B31: 7.1. | C31: Recursos
A32: =COUNTIF(#REF!,"X") -> #REF! | B32: 7.1.1. | C32: Generalidades. Determinar y proporcionar los recursos necesario para el SGC. La Org. Debe considerar las capacidades y limitaciones de recursos existentes y qué se necesita obtener de los proveedores externos
A33: =COUNTIF(#REF!,"X") -> #REF! | B33: 7.1.2. | C33: Personas. La Organización debe determinar y proporcionar las personas necesarias para la implementación eficaz del SGC y para la operación y control de sus procesos
A34: =COUNTIF(#REF!,"X") -> #REF! | B34: 7.1.3. | C34: Infraestructura. La Org. debe determinar, proporcionar y mantener la infraestructura necesaria para la operación de sus procesos y lograr la conformidad del servicio
A35: =COUNTIF(#REF!,"X") -> #REF! | B35: 7.1.4. | C35: Ambiente para la operación de los procesos. La Orq. debe mantener el ambiente necesario para la operación de sus procesos y para lograr la conformidad del servicio
A36: =COUNTIF(#REF!,"X") -> #REF! | B36: 7.1.5. | C36: Recursos de seguimeinto y medición.
A37: =COUNTIF(#REF!,"X") -> #REF! | B37: 7.1.5.1. | C37: Generalidades
A38: =COUNTIF(#REF!,"X") -> #REF! | B38: 7.1.5.2. | C38: Trazabilidad de las mediciones
A39: =COUNTIF(#REF!,"X") -> #REF! | B39: 7.1.6. | C39: Conocimientos de la Organización. La Org. debe determinar los conocimeintos necesarios para la operación de sus procesos y para lograr la conformidad del servicio.
A40: =COUNTIF(#REF!,"X") -> #REF! | B40: 7.2. | C40: Competencia. a) Determinar la competencia necesaria de las personas, b) Asegurarse de que las personas sean competentes basándose en la educación, formación o experiencia apropiadas. c) Cuando sea aplicable tomar acciones para adquirir competencia necesaria y evaluar eficacia de las acciones, d) conservar la documentación apropiada como evidencia de la competencia.
A41: =COUNTIF(#REF!,"X") -> #REF! | B41: 7.3. | C41: Toma de Conciencia. Política de Calidad, Objetivos de Calidad, contribución a la eficacia del SGC.
...

Sheet SGC-Vigente
A1: BD SGC - Vigente
A2: ID | B2: Cód. | C2: Proceso / Subproceso / Programa Académico | D2: Objetivo del Proceso | E2: Requisitos de Ley | F2: Requisito ISO 9001:2015 Aplicable | G2: Requisitos del Usuario | H2: Requisitos de la Institución | I2: Indicadores | J2: Documentación Vigente
A3: =COUNTA(C$3:C3) -> 1 | B3: DO | C3: Docencia | D3: Gestionar las diferentes actividades del currículo encaminado a la formación integral de profesionales como gestores de cambio y transformación en los diferentes contextos sociales. | E3: • Ley 30 de 1992 y decretos asociados • Ley 1740 del 2014 • Decreto único 1075 circular # 31 MEN • Decreto 1330 de 2019 del MEN • Acuerdo 02 del CESU • Ley de emprendimiento | F3: 4.4 • 5.1.2 • 6.1 • 7.1.1 • 7.1.2 • 7.1.3 • 7.1.4 • 7.1.5 • 7.1.6 • 7.4 • 7.5.1 • 7.5.2 • 7.5.3 • 8.1 • 8.2.1 • 8.2.2 • 8.2.3 • 8.2.4 • 8.3.1 • 8.3.2 • 8.3.3 • 8.3.4 • 8.3.5 • 8.3.6 • 8.5.1 • 8.5.2 • 8.5.3 • 8.5.4 • 8.5.5 • 8.5.6 • 8.6 • 8.7 • 9.1.1 • 9.1.2 • 9.1.3 • 10.2 • 10.3 | G3: • Información veraz, pertinente y oportuna • Servicio de Educación Superior acorde con los lineamientos del MEN. | H3: • Estatuto General • Estatuto Docente • Reglamento Estudiantil • Reglamento Consultorio Jurídico • Reglamento Alternativas de Grado • Reglamento Prácticas Universitarias Psicología • Reglamento Uso del Correo Institucional • Acuerdos de los Consejos Superior y Académico • Manual de Funciones • Resoluciones de Rectoría • Política de Protección de Datos Personales * Política de Educación Virtual y a Distancia | I3: Tasa técnica ( # de estudiantes / # de docentes tiempo completo) Deserción (# estudiantes desertores / # de estudiantes matriculados) Tasa de Graduación (tiempo de graduación cohorte) Bajo rendimiento (# estudiantes en bajo rendimiento /# de estudiantes matriculados) Evaluación Docente (# docentes con calificación >=4/ # de docentes evaluados) | J3: • PR-GC-004 "Acciones Correctivas"
A4: =COUNTA(C$3:C4) -> 2 | B4: RA | C4: Registro Académico | D4: Administrar el sistema de registro y control académico, asegurando el cumplimiento de los criterios institucionales en lo concerniente a los asuntos académicos basado en la normativa institucional. | E4: • Ley 594 del 2000 Bases de datos Ley 1581 de 2012. | F4: • 7.1 • 7.2 • 7.3 • 7.5 • 7.5.1 • 7.5.2 • 7.5.3 • 8.7 • 9.1 • 9.1.1 • 9.1.2 • 9.1.3 •10.2 • 10.3 | G4: • Información veraz y oportuna, confidencialidad y ética. | H4: Reglamento estudiantil, estatutos y Política de tratamiento de datos personales | I4: • Efectividad de las certificaciones expedidas | J4: • PR-RA-004 "Emisión de Constancias y Certificaciones Académicas" • PR-DO-001"Procedimiento Homologación Interna y Externa" • PR-GC-004 "Acciones Correctivas"
A5: =COUNTA(C$3:C5) -> 3 | B5: CU | C5: Gestión Curricular | D5: Garantizar la efectividad del diseño curricular de la institución atendiendo los lineamientos del Ministerio de Educación Nacional y Normativa Interna. | E5: Decreto 1330 de 2019 del MEN | F5: 4.4 • 6.1 • 7.1 • 7.2 • 7.4 • 7.5 • 7.5.1 • 7.5.2 • 7.5.3 •8.2 • 8.3 • 8.5.2 • 8.5.4 • 8.5.5 • 8.5.6 • 9.1 • 10 | G5: • Información veraz, pertinente y oportuna • Servicio de Educación Superior acorde con los lineamientos del MEN. | H5: * Política de Créditos* Política de Gestión Curricular* Lineamientos de Gestión Curricular* Acuerdos de los Consejos Superior y Académico que apliquen.* Resoluciones de Rectoría | J5: PR-CU-001 Procedimiento Gestión Curricular V1 PR-GC-004 "Acciones Correctivas"
A6: =COUNTA(C$3:C6) -> 4 | B6: IN | C6: Investigación, Desarrollo e Innovación | D6: Promover la investigación científica y formativa en la Institución impulsando el pensamiento creativo y crítico, el desarrollo tecnológico, la innovación y el desarrollo cultural aportando al fortalecimiento del proceso de enseñanza y aprendizaje en la región. | E6: • Decreto 1295 • Política de propiedad intelectual • Ley SPINOFF • Política de apropiación social de la ciencia, la tecnología y la innovación • Plan estratégico nacional de investigación ambiental • PECTIA 2017-2027 • Política Nacional de Ciencia, tecnología e innovación 2021-2030 • Decreto 1330 • CESU 02 | F6: • 4.4 • 6.1 • 7.1 • 7.1.1 • 7.1.2 • 7.1.3 • 7.1.4 • 7.1.5 • 7.1.6 • 7.4 • 7.5 • 7.5.1 • 7.5.2 • 7.5.3 • 8.7 1 • 9.1.2 • 9.1.3 • 10.2 • 10.3 | G6: • Información veraz, pertinente y oportuna. | H6: • Estatuto General • Política del Sistema de Investigación, Desarrollo e Innovación • Política de Responsabilidad y Sostenibilidad Ambiental • Reglamento Estudiantil •Política Editorial • Reglamento de Propiedad Intelectual | I6: • Docentes Investigadores • Productos de Investigación • Grupos de Investigación clasificados en Colciencias • Semilleros de Investigación | J6: •MA-IN-002"ManualdeGestióndeGruposdeInvestigación" •MA-IN-003"ManualdeGestióndeSemillerosdeInvestigación" •PR-IN-001"GestióndelasFormasOrganizativasdelaInvestigación" •PR-IN-002"ConvocatoriaInternayExternaparaProyectosdeInvestigación" •PR-IN-003"SolicituddeApoyoFinancieroalSIDI" •PR-IN-006"PresentaciónProyectosdeInvestigaciónenConvocatoriasExternas" •PR-IN-007"ElaboraciónyTrámitedelActadePropiedadIntelectual" •PR-IN-010"ContrataciónJóvenInvestigador" •PR-GC-004 "Acciones Correctivas"
A7: =COUNTA(C$3:C7) -> 5 | B7: EX | C7: Extensión y Proyección Social | D7: Aportar en el desarrollo y transformación social de la comunidad mediante la implementación de estrategias, proyectos y servicios que impacten a los grupos de interés. | E7: • Ley 115 de 1994 (Art. 1), • Ley 30 de 1992 (Art. 1 - Cap. 1º) - (Art. 120) • Decreto 1075 de 2015 • Decreto 1330 de 2019 del MEN • Ley 1014 del 26-Ene-2006. | F7: • 4.4 • 6.1 • 7.1 • 7.1.1 • 7.1.2 • 7.1.3 • 7.1.4 • 7.1.5 • 7.1.6 • 7.4 • 7.5 • 7.5.1 • 7.5.2 • 7.5.3 • 8.7 1 • 9.1.2 • 9.1.3 • 10.2 • 10.3 | G7: • Información veraz y oportuna • Asesoramiento metodológico • Seguimiento a los avances • Respuesta oportuna a problemáticas planteadas • Comunicación efectiva y • Servicio eficiente. | H7: • Acuerdo 091 de 19-may-2010 • Acuerdo 015 del 22-Nov-2009 • Acuerdo 03 del 24-Ago-2012. . | I7: • Beneficiados de los Procesos de Extensión | J7: • CP-EC-001 “Educación Continuada” • CP-GE-001 “Gestión de Egresados” • CP-EM-001 “Emprendimiento” • PR-GC-004 "Acciones Correctivas"
A8: =COUNTA(C$3:C8) -> 6 | B8: EM | C8: Emprendimiento | D8: Contribuir al desarrollo del espiritu emprendedor a través de acciones interdiscipinarias que aporten a soluciones integrales a los retos del contexto local y regional | E8: • Ley 115 de 1994 (Art. 1), • Ley 30 de 1992 (Art. 1 - Cap. 1º) - (Art. 120) •Decreto 1075 de 2015 • Decreto 1330 de 2019 del MEN • Ley 1014 del 26-Ene-2006. | F8: • 4.4 • 6.1 • 7.1 • 7.1.1 • 7.1.2 • 7.1.3 • 7.1.4 • 7.1.5 • 7.1.6 • 7.4 • 7.5 • 7.5.1 • 7.5.2 • 7.5.3 • 8.7 1 • 9.1.2 • 9.1.3 • 10.2 • 10.3 | G8: • Información veraz y oportuna • Asesoramiento metodológico • Seguimiento a los avances • Respuesta oportuna a problemáticas planteadas • Comunicación efectiva y • Servicio eficiente. | H8: • Política Institucional de Emprendimiento • Acuerdo 091 de 19-may-2010 • Acuerdo 015 del 22-Nov-2009 • Acuerdo 03 del 24-Ago-2012. | I8: • %Carcaterización de emprendimeitno atendidos • % Estudiantes atendidos en la unidad de emprendimiento | J8: • PR-GC-004 "Acciones Correctivas"
A9: =COUNTA(C$3:C9) -> 7 | B9: GE | C9: Gestión de Egresados | D9: Realizar seguimiento a los egresados de la Institución, identificando las necesidades del entorno y la correspondencia del perfil profesional frente a su ubicación laboral para generar espacios de vinculación, inclusión y participación activa de los egresados en actividades Institucionales que contribuyan con su desarrollo profesional. | E9: • Ley 30 de 1992 (Art. 1 - Cap. 1º) - (Art. 120) • Decreto 1330 de 2019 del MEN • Cesu Acuerdo 02 de 2020 | F9: •4.4 • 6.1 • 7.1 • 7.1.1 • 7.1.2 • 7.1.3 • 7.1.4 • 7.1.5 • 7.1.6 • 7.4 • 7.5 • 7.5.1 • 7.5.2 • 7.5.3 • 8.7 1 • 9.1.2 • 9.1.3 • 10.2 • 10.3 | G9: • Información veraz y oportuna • Asesoramiento metodológico • Comunicación efectiva • Servicio eficiente. | H9: "• Política de Egresados • Política de Extensión y Proyección Social" | I9: • Contactabilidad de los egresados. | J9: • PR-GC-004 "Acciones Correctivas"
A10: =COUNTA(C$3:C10) -> 8 | B10: EC | C10: Educación Continuada | D10: Promover la formación y capacitación permanente a lo largo de la vida en procesos de competencias laborales y capacitación a través de la Educación No Formal con el fin de fortalecer habilidades, destrezas y competencias que mejoren no solo la posición si no la inserción laboral de personas que deseen mejorar o actualizar sus capacidades y desarrollarse de manera integral. | E10: •Ley 30 de 1992, título VI, Capítulo I, Art. 120•Ley 115 de 1994, Capítulo II•Decreto 114 del 15 de enero de 1996, Capítulo I y II•Resolución 626 de 2007 Modificada por la Resolución 1622 de 2007 | F10: 4.1. 4.2. 4.3. 4.4. 6.1. 6.2. 6.2.2. 6.3. 7.1.3. 7.1.4. 7.2. 7.5. 7.5.3. 7.5.3.1 8.1. 8.2.1. 8.2.2. 8.2.3.1. 8.4.2. 8.5.1. 8.6. 8.7. 8.7.2. 9.1. 9.1.2. 9.3.2. 10.2.1. | G10: • Información confiable, veráz y oportuna. | H10: • Política de Extensión y Proyección Social • Acuerdo 012 del 18 de mayo de 2023 Lineamientos de Educación Continuada | I10: Tasa de participación oferta educación continuada = número de estudiantes que tomaron la oferta / número de aspirantes inscritos * 100 Cumplimiento de metas financieras = ingresos recibidos / ingresos proyectados Satisfacción de los usuarios = promedio de calificación de satisfacción de 4 en el 75% de la población a partir de un formulario en línea | J10: MA-EC-001 "Manual de Procedimientos Educación Continuada" PR-GC-004 "Acciones Correctivas"
A11: =COUNTA(C$3:C11) -> 9 | B11: PE | C11: Gestión de Proyectos de Extensión | D11: Administrar, planificar, coordinar la ejecución y realizar seguimiento y control de las actividades y recursos asignados a los proyectos de extensión y proyección social de la Institución, de manera que se cumpla el alcance en el tiempo establecido y con los costos presupuestados. | E11: • Ley 115 de 1994 (Art. 1), • Ley 30 de 1992 (Art. 1 - Cap. 1º) - (Art. 120) • Decreto 1075 de 2015 • Decreto 1330 de 2019 del MEN • Ley 1014 del 26-Ene-2006. | F11: • 4.4 • 6.1 • 7.1 • 7.1.1 • 7.1.2 • 7.1.3 • 7.1.4 • 7.1.5 • 7.1.6 • 7.4 • 7.5 • 7.5.1 • 7.5.2 • 7.5.3 • 8.7 1 • 9.1.2 • 9.1.3 • 10.2 • 10.3 | G11: • Información confiable, veráz y oportuna. | H11: Politica Extensión y Proyección Social
A12: =COUNTA(C$3:C12) -> 10 | B12: EF | C12: Escuela de Formación para el TDH | D12: Ofertar programas de educación continuada para el desarrollo laboral y fortalecimiento de competencias de la comunidad académica en general | E12: • Ley 30 de 1992 • Ley 115 de 1994 • Ley 715 de 2001 • Decreto 1075 de 2015 • Licencia de Funcionamiento • Directrices y Lineamientos de Entes Gubernamentales | F12: • 4.4 • 5.1.2 • 6.1 • 7.1.1 • 7.1.2 • 7.1.3 • 7.1.4 • 7.1.5 • 7.1.6 • 7.4 • 7.5.1 • 7.5.2 • 7.5.3 • 8.1 • 8.2.1 • 8.2.2 • 8.2.3 • 8.2.4 • 8.3.1 • 8.3.2 • 8.3.3 • 8.3.4 • 8.3.5 • 8.3.6 • 8.5.1 • 8.5.2 • 8.5.3 • 8.5.4 • 8.5.5 • 8.5.6 • 8.6 • 8.7 • 9.1.2 • 9.1.3 • 10.2 • 10.3 | G12: • Información veraz y oportuna • Cumplimiento de los horarios. | H12: • Información oportuna y confiable • Cumplimiento de funciones. | I12: • Estudiantes atendidos | J12: • MA-EF-03 "Manual de Procedimientos Escuela de Formación" • MA-EF-04 "Manual de Procedimientos Escuela Informus" • MA-EF-03 "Manual de Procedimientos Escuela de Formación" • MA-EF-04 "Manual de Procedimientos Escuela Informus" • MA-EF-03 "Manual de Procedimientos Escuela de Formación" • MA-EF-04 "Manual de Procedimientos Escuela Informus" • MA-EF-03 "Manual de Procedimientos Escuela de Formación" • MA-EF-04 "Manual de Procedimientos Escuela Informus" • PR-GC-004 "Acciones Correctivas"
A13: =COUNTA(C$3:C13) -> 11 | B13: DE | C13: Direccionamiento Estratégico | D13: Establecer los lineamientos para la estructuración del Plan de Desarrollo institucional mediante la implementación de estrategias, objetivos estratégicos y planes de mejoramiento Institucional que garanticen la satisfacción de los usuarios y las expectativas de los grupos de interés. | E13: • Ley 30 • Ley 715 • Ley 115 • Ley 30 • Decreto 1075 de 2015 • Ley 152 orgánica del plan de desarrollo | F13: • 4.1 . 4.2 . 4.3 . 4.4 . 5.1 . 5.1.1 . 5.1.2 . 5.2 . 5.2.1 . 5.2.2 . 5.3 . 6.1 . 6.2 . 7.1 . 7.1.2 . 7.1.3 . 7.1.4 . 7.5 . 7.5.1 . 7.5.2 . 7.5.3 . 9.3 . 9.3.1 . 9.3.2 . 9.3.3 . | G13: • Información veraz y oportuna | H13: • Cumplimiento Estatutos Institucionales | I13: • Cumplimiento Total del Plan de Desarrollo Institucional • Satisfacción del Usuario | J13: • PR-GC-004 "Acciones Correctivas"
A14: =COUNTA(C$3:C14) -> 12 | B14: PL | C14: Planeación Institucional | D14: Asegurar la alineación de las estrategias, objetivos estratégicos y planes de mejoramiento Institucional con el Plan de Desarrollo Institucional y Proyecto Educativo Institucional, teniendo como marco de referencia los lineamientos establecidos por la Alta Dirección, del gobierno nacional y las tendencias internacionales, nacionales y regionales . | E14: • Ley 30 • Ley 115 • Ley 152 orgánica del plan de desarrollo • Acuerdo 02 CNA | F14: • 4.1 • 4.2 • 5.1 • 5.1.1 • 5.1.2 • 5.2 • 5.2.1 . 5.2.2 5.3 • 6.1 • 6.2 . 7.1 . 7.1.2 . 7.1.3 . 7.1.4 . 7.1.5 . 7.1.6• 9.1 • 9.1.1 . 9.1.2 . 9.1.3 • 10.1 • 10.2 • 10.3 | G14: • Información veraz y oportuna | H14: •Acuerdo 019 Plan de desarrollo 2024 - 2032 • Política de Buen Gobierno y Rendición de Cuentas | I14: • Cumplimiento del Plan de Desarrollo Institucional. | J14: •PR-PL-003 "Seguimiento al Formato Único de Gestión"• PR-GC-004 "Acciones Correctivas" *PR-PL-003 "Seguimiento al Formato Único de Gestión"
A15: =COUNTA(C$3:C15) -> 13 | B15: SI | C15: Gestión de Sistemas de Información | D15: Planificar, desarrollar e implementar soluciones tecnológicas asociadas al Sistema de Información de Registro Estudiantil (SIRES), garantizando la integridad, veracidad y disponibilidad de la información por parte de la Comunidad Académica que la requiera. | E15: Ley 1581 de 2012 Ley de proteccióde datos personales | F15: • 7.1.3 • 7.5.3 • 8.2 • 8.2.1 . 8.2.2 . 8.2.3 . 8.2.4 .8.5.2 • 8.5.3 • 9.1.1 • 9.1.2 . 9.1.3 . 10.2 • 10.3 | G15: • Información veraz y oportuna | H15: • Política de protección de datos personales | I15: • Accesibilidad del Sistemas de Información (SIRES) • Avance de los desarrollos asociados al sistema de información SIRES en curso | J15: • MA-SI-001 "Manual Desarrollo Soluciones Tecnológicas Asociadas al SIRES" • PR-GC-004 "Acciones Correctivas"
A16: =COUNTA(C$3:C16) -> 14 | B16: GC | C16: Gestión de Calidad | D16: Administrar, mantener y apropiar el Sistema de Gestión de Calidad mediante la gestión por procesos para dar cumplimiento con los requisitos legales y reglamentarios aplicables basado en la norma ISO 9001:2015. | E16: • Ley 1188 del 2008 • Decreto 1330 de 2019 del MEN • Acuerdo CESU 02 de 2020 • Lineamientos para la acreditación de programas de pregrado CNA 2020 | F16: • 4.1 • 4.2 • 4.3 • 4.4 • 5.1.2 • 5.2 • 6.2 • 6.3 • 7.5 • 7.5.1 • 7.5.2 • 7.5.3 • 8.2 • 8.7 • 9.1 • 9.1.2 • 9.2 • 10.2 • 10.3 | G16: • Satisfacción del usuario | H16: • Política de Calidad • Resolución Rectoral 101 del 20 de septiembre 2022 | I16: • Índice de Quejas • Eficacia de acciones programadas | J16: • MA-GC-001 "Manual de Calidad" • PR-GC-001 "Elaboración y control de documentos" • PR-GC-002 "Control de registros" • PR-GC-003 Tratamiento Salidas No Conforme • PR-GC-004 "Acciones Correctivas" • PR-GC-005 "Auditorías internas de calidad" • PR-GC-006 "Petición, Quejas y Reclamos" • PR-GC-007 "Matriz de riesgos y oportunidades" • PR-GC-008 "Planificación de cambios al SGC"
A17: =COUNTA(C$3:C17) -> 15 | B17: AU | C17: Autoevaluación Institucional | D17: Coordinar los procesos de, Autoevaluación y Acreditación de los programas académicos e insitucional para cumplir con los requerimientos del Ministerio de Educación Nacional (MEN) y del Consejo Nacional de Acreditación (CNA), a través de la cultura del aseguramiento de la calidad. | E17: • Ley 1188 del 2008 • Decreto 1330 de 2019 del MEN • Acuerdo CESU 02 de 2020 • Lineamientos para la acreditación de programas de pregrado CNA 2020 • Resolución 15224 de 2020 • Resolución 21795 de 2020 | F17: • 7.5 * 7.5.1 * 7.5.2 * 7.5.3 * 8.1 * 8.2 * 8.2.1 * 8.2.2 * 8.2.3 * 8.3 * 8.3.1 * 8.3.2 * 8.3.3 * 8.3.4 * 8.3.5 * 8.3.6 * 8.5 * 8.5.1 * 8.5.2 * 8.5.3 * 8.5.4 * 8.5.5 * 8.5.6 * 9.1 * 9.1.3 * 10.2 | G17: • Información confiable • Soporte Institucional para desarrollar el proceso de autoevaluación • Lineamientos claros y amigables. | H17: • Sistema Interno de Aseguramiento de la Calidad - SIAC | I17: • % de cumplimiento implementación de los Planes de Mejoramiento Institucional (Derivados de la autoevaluación) • % de cumplimiento implementación de los Planes de Mejoramiento del Programa (Derivados de la autoevaluación) • # de procesos de autoevaluación realizados • # de procesos de autoevaluación con fines de acreditación realizado | J17: • PR-AU-001 "Procedimiento Autoevaluación Institucional y Programas Académicos" • Modelo de Autoevaluación Institucional" • Formato Plan de Mejora AE Institucional • Modelo de Autoevaluación Institucional" "Modelo de Autoevaluación para Programas Académicos" • Modelo de Autoevaluación para Programas Académicos" • PR-GC-004 "Acciones Correctivas"
A18: =COUNTA(C$3:C18) -> 16 | B18: RC | C18: Registro Calificado | D18: Asesorar, acompañar y gestionar los procesos de pre radicación y radicación de solicitudes para la obtención, modificación y renovación de registros calificados, atendiendo los requerimientos legales y normativos vigentes. | E18: • Ley 115 de 1994 • Ley 30 de 1992 • Decreto 1295 de 2010 •Resolución 2590 de 2012 • Resolución 12220 de 2016 • Resolución10414 de 2018 • Decreto 1330 de 2019 •Resolución 02265 de 2023• Decreto1174 de 2023, demás normas aplicables. | F18: • 7.5 • 7.5.1 • 7.5.2 • 7.5.3 • 8.1 • 8.2 • 8.2.1 • 8.2.2 • 8.2.3 • 8.3 • 8.3.1 • 8.3.2 • 8.3.3 • 8.3.4 • 8.3.5 • 8.3.6 • 8.5 • 8.5.1 * 8.5.2 * 8.53 * 8.5.4 * 8.5.5 * 8.5.6 * 9.1 • 9.1.3 • 9.1.3 * 10.2 | G18: • Vigencia de los registros calificados o duración de la acreditación | H18: • Acto administrativo otorgado por el MEN - Autorización para la oferta de programas académicos • Sistema Interno de Aseguramiento de la Calidad • Acuerdo 002 de 2012 • Acuerdo 001 de 2018 • Acuerdo 004 de 2018 • Acuerdo 001 de 2019 • Acuerdo 004 de 2019 • Acuerdo 012 de 2019 • Acuerdo 009 de 2021 • Acuerdo 019 de 2021 • Acuerdo 001 de 2023, demás normatividad interna aplicable | I18: • Solicitudes radicadas para obtención de Registros Calificados • Solicitudes radicadas para renovación de Registros Calificados • Eficacia en la radicación de solicitudes de registro calificado | J18: • MA-RC-002 "Manual de Procedimientos Registro Calificado" • MA-RC-002 "Manual de Procedimientos Registro Calificado" • PR-GC-004 "Acciones Correctivas"
A19: =COUNTA(C$3:C19) -> 17 | B19: VN | C19: Relaciones Interinstitucionales - ORI | D19: Brindar oportunidades a estudiantes, docentes, administrativos y egresados en escenarios académicos nacionales e internacionales que permitan la adquisición y/o fortalecimiento de competencias multiculturales en un dialogo global intercultural, mediante el fortalecimiento de las alianzas y redes interintitucionales. | E19: • Normatividad Vigente emanada del MEN | F19: • 7.5.1 • 7.5.2 • 5.1.2 • 5.2 • 5.3 • 7.1.1 • 7.1.3 • 7.1.4 • 9.1.1 • 9.1.3 • 10.2 • 10.3 | G19: • Vigencia de los convenios interinstitucionales | H19: • PEI • Política de Internacionalización •PDI | I19: • Actividad de los convenios Interinstitucionales vigentes (Convenios Interinstitucionales utilizados / Total de Convenios Interinstitucionales vigentes) | J19: • MA-VN-001 "Manual Relacionamiento Interinstitucional" • PR-VN-001 "Movilidad entrante y saliente" • MA-VN-001 "Manual Relacionamiento Interinstitucional" • PR-GC-004 "Acciones Correctivas"
A20: =COUNTA(C$3:C20) -> 18 | B20: MA | C20: Mercadeo - Admisiones | D20: Ofertar los servicios de la Institución con la comunidad académica de la región suministrando la orientación adecuada que garantice a los aspirantes realizar su proceso de inscripción, admisión y matrícula para su ingreso eficaz a alguno de los programas académicos de la FUP. | E20: • Resolución 12220 de 20 de junio de 2016 • Ley 1581 de 2012 de habeas datas, • Decreto reglamentario 1377 de 2013. | F20: • 5.1.2 • 7.1.1 • 7.1.3 • 7.1.4 •7.5 • 7.5.1 • 7.5.2 • 7.5.3 • 9.1 • 9.1.1 • 9.1.3 • 10.2 • 10.3 | G20: • Información confiable, veraz y oportuna | H20: • Cumplimiento del Reglamento Estudiantil y estatutos Institucionales • Política de Admisiones.. | I20: • Estudiantes matriculados en primer semestre | J20: • MA-MA-001 "Manual de Mercadeo" • MA-MA-001 "Manual de Mercadeo" • MA-MA-001 "Manual de Mercadeo" • PR-MA-001 "Inscripción y Matrícula de Estudiantes" • PR-RA-006 "Procedimiento Homologación Interna y Externa" • PR-MA-001 "Inscripción y Matrícula de Estudiantes" • PR-MA-001 "Inscripción y Matrícula de Estudiantes" • PR-GC-004 "Acciones Correctivas"
A21: =COUNTA(C$3:C21) -> 19 | B21: CO | C21: Comunicaciones Institucional | D21: Gestionar dinámicas de comunicación Institucional a nivel interno y externo, administrando los canales de comunicación garantizando el cumplimiento de los lineamientos de imagen corporativa. | E21: • Ley 1581 de 2012 - Habeas Data • Ley 23 de 1982 - Derechos de Autor • Resolución 12220 de 2016 - Regulación de publicidad de las Instituciones de Educación Superior • Sayco y Acinpro | F21: • 7.5 • 7.5.1 • 7.5.2 • 7.5.3 * 7.4 • 8.2.1 • 9.1 • 9.1.1 • 9.1.3 • 10.1 * 10.2 * 10.3 | G21: • Información veraz y oportuna | H21: • Cumplimiento de estatutos Acuerdo 011 de 29 de abril de 2003 • Acuerdo 005 de 22 de marzo de 2019 emitido por la Institución para la protección de los datos personales por la FUP | I21: • Divulgación de información en medios de comunicación | J21: • MA-CO-001 "Manual de procedimientos de Comunicaciones Institucional" • MA-CO-001 "Manual de procedimientos de Comunicaciones Institucional" • MA-CO-001 "Manual de procedimientos de Comunicaciones Institucional" • MA-CO-001 "Manual de procedimientos de Comunicaciones Institucional" • PR-GC-004 "Acciones Correctivas" • Cumplimiento de estatutos Acuerdo 011 de 29 de abril de 2003 • Acuerdo 005 de 22 de marzo de 2019 emitido por la Institución para la protección de los datos personales por la FUP
A22: =COUNTA(C$3:C22) -> 20 | B22: BI | C22: Bienestar Institucional | D22: Contribuir con la formación integral, el desarrollo humano, la cultura Institucional y la formación ciudadana de la comunidad académica para su desarrollo potencial, individual y colectivo que permitan el logro de los fines misionales. | E22: Ley 1188 de 2008 • Ley 30 de 1992 • Decreto 1075 de 2015 • Acuerdo 02 CESU 1 julio de 2020 • Ley 1188 de 2008 • Decreto 1330 de 2019 | F22: 7.1.2• 7.5 • 7.5.1 • 7.5.2 • 7.1.2 • 9.1 • 9.1.1 • 9.1.3 • 10.3 | G22: • Información veraz y oportuna • Cumplimiento de lo programado • Citas oportunas • Transporte adecuado | H22: • Política de Bienestar Institucional 16 de sep de 2022• Política de permanencia y Graduación 24 mar de 2023 | I22: • Impacto del programa de permanencia y graduación • % Participación en actividades bienestar | J22: • O-PL-007 • DS-BI-002 Programa de permanencia y graduación estudiantil • Portafolio Bienestar Universitario • S-BI-002 Programa de permanencia y graduación estudiantil • PR-GC-004 "Acciones Correctivas"
A23: =COUNTA(C$3:C23) -> 21 | B23: GH | C23: Gestión Humana | D23: Gestionar y mantener un talento humano competente para la prestación de los servicios ofertados por la Institución, identificando necesidades de formación que contribuyan al fortalecimiento de las competencias y desarrollando estrategias que permitan garantizar un clima laboral apto y unas condiciones de trabajo adecuadas. | E23: • Constitución Política de Colombia • Código sustantivo de trabajo • Ley 100 de 1993 • Ley 797 de 2003 • Ley 1010 de 2006 • Decreto 1075 de 2015 • Decreto 1443 de 2014 • Decreto 055 de 2015. ley 2414 de 2021 y ley 1822 de 2017 | F23: • 5.2.1 * 5.2.2 • 7.5.1 • 7.5.2 * 7.4.3 • 6.1 • 7.1 • 7.1.2 • 7.1.3 • 7.1.6 • 7.2 • 7.3 • 7.4 •7.5.1 * 7.5.2 * 9.1.1 •9.1.3 • 10.2 • 10.3 | G23: • Contratación oportuna y de calidad | H23: • Reglamento interno de trabajo • Estatutos Institucionales • Contratos laborales • Acuerdos del consejo superior • Resoluciones de Rectoría • Política de Gestión Humana • Política de Seguridad y Salud en el Trabajo | I23: • Clima Organizacional | J23: • CP-TH-001 "Caracterización Gestión del Talento Humano • CP-ST-001 "Caracterización Gestión de Seguridad y Salud en el Trabajo" • PR-GC-004 "Acciones Correctivas" • Reglamento interno de trabaj • Estatutos Institucionales •Contratos laborales • Acuerdos del consejo superior • Resoluciones de Rectoría • Política de Gestión Humana • Política de Seguridad y Salud en el Trabajo
... A32: =COUNTA(C$3:C32) -> 30 | B32: RT | C32: Recursos Tecnológicos | D32: Administrar una infraestructura tecnológica adecuada a la propuesta de valor Institucional, garantizando la seguridad de la información y el óptimo funcionamiento de los equipos tecnológicos. | E32: • Infraestructura física para las sedes (Bibliotecas y Laboratorios) • Infraestructura tecnológica (Computadores, internet, video beam, impresoras y software) • Recurso humano e insumos de oficina. | F32: • 7.1.2 • 7.1.3 • 8.4 • 8.4.1 • 8.4.2 • 8.4.3 • 8.5.2 • 8.5.3 • 9.1.1 • 9.1.3 • 10.2 • 10.3 | G32: • Oportunidad y cumplimiento | H32: • Política de Renovación y Actualización de Recursos Tecnológicos • Reglamento Uso de Salas de Cómputo • Reglamento Uso del Correo Institucional | I32: • Mantenimiento preventivo Seguimiento a la ejecución de las copias de seguridad. • Incidentes resueltos | J32: •MA-RT-001"ManualdeInfraestructuraTecnológica" •PR-RT-001"Mantenimientopreventivodeequipos" •PR-RT-002"CopiasdeSeguridad" •PR-RT-003"Solicituddesalasdecómputo" •DS-RT-002"Reglamentointernousodelcomputador" •PR-GC-004"AccionesCorrectivas".
A33: =COUNTA(C$3:C33) -> 31 | B33: RF | C33: Recursos Físicos | D33: Administrar y proveer los recursos físicos y de infraestructura necesarios para garantizar una prestación óptima del servicio de educación superior. | E33: • Decreto 1072 de 2015 | F33: • 7.5 • 7.5.1 • 7.5.2 • 7.5.3 • 7.1.2 • 7.1.3 • 7.4 • 8.4 • 8.4.1 • 8.4.2 • 8.4.3 • 9.1 • 9.1.2 • 9.1.3 • 10.3 | G33: • Infraestructura y mobiliario en buen estado Instalaciones aseadas | I33: • Ejecución del programa de mantenimiento | J33: • PR-RF-003 "Mantenimiento de Infraestructura Institucional" • PR-RF-004 "Procedimiento de limpieza Institucional" • PR-GC-004 "Acciones Correctivas"
A34: =COUNTA(C$3:C34) -> 32 | B34: PRO-1 | C34: Prog. Administración de Empresas | D34: Gestionar las diferentes actividades del currículo encaminado a la formación integral de profesionales como gestores de cambio y transformación en los diferentes contextos sociales. | E34: • Ley 30 de 1992 y decretos asociados • Ley 1740 del 2014 • Decreto único 1075 circular # 31 MEN • Decreto 1330 de 2019 del MEN • Acuerdo 02 del CESU • Ley de emprendimiento | F34: 4.4 • 5.1.2 • 6.1 • 7.1.1 • 7.1.2 • 7.1.3 • 7.1.4 • 7.1.5 • 7.1.6 • 7.4 • 7.5.1 • 7.5.2 • 7.5.3 • 8.1 • 8.2.1 • 8.2.2 • 8.2.3 • 8.2.4 • 8.3.1 • 8.3.2 • 8.3.3 • 8.3.4 • 8.3.5 • 8.3.6 • 8.5.1 • 8.5.2 • 8.5.3 • 8.5.4 • 8.5.5 • 8.5.6 • 8.6 • 8.7 • 9.1.1 • 9.1.2 • 9.1.3 • 10.2 • 10.3 | G34: • Información veraz, pertinente y oportuna • Servicio de Educación Superior acorde con los lineamientos del MEN. | H34: • Estatuto General • Estatuto Docente • Reglamento Estudiantil • Reglamento Consultorio Jurídico • Reglamento Alternativas de Grado • Reglamento Prácticas Universitarias Psicología • Reglamento Uso del Correo Institucional • Acuerdos de los Consejos Superior y Académico • Manual de Funciones • Resoluciones de Rectoría • Política de Protección de Datos Personales * Política de Educación Virtual y a Distancia | I34: Tasa técnica ( # de estudiantes / # de docentes tiempo completo) Deserción (# estudiantes desertores / # de estudiantes matriculados) Tasa de Graduación (tiempo de graduación cohorte) Bajo rendimiento (# estudiantes en bajo rendimiento /# de estudiantes matriculados) Evaluación Docente (# docentes con calificación >=4/ # de docentes evaluados) | J34: • PR-GC-004 "Acciones Correctivas"
A35: =COUNTA(C$3:C35) -> 33 | B35: PRO-2 | C35: Prog. Arquitectura | D35: Gestionar las diferentes actividades del currículo encaminado a la formación integral de profesionales como gestores de cambio y transformación en los diferentes contextos sociales. | E35: • Ley 30 de 1992 y decretos asociados • Ley 1740 del 2014 • Decreto único 1075 circular # 31 MEN • Decreto 1330 de 2019 del MEN • Acuerdo 02 del CESU • Ley de emprendimiento | F35: 4.4 • 5.1.2 • 6.1 • 7.1.1 • 7.1.2 • 7.1.3 • 7.1.4 • 7.1.5 • 7.1.6 • 7.4 • 7.5.1 • 7.5.2 • 7.5.3 • 8.1 • 8.2.1 • 8.2.2 • 8.2.3 • 8.2.4 • 8.3.1 • 8.3.2 • 8.3.3 • 8.3.4 • 8.3.5 • 8.3.6 • 8.5.1 • 8.5.2 • 8.5.3 • 8.5.4 • 8.5.5 • 8.5.6 • 8.6 • 8.7 • 9.1.1 • 9.1.2 • 9.1.3 • 10.2 • 10.3 | G35: • Información veraz, pertinente y oportuna • Servicio de Educación Superior acorde con los lineamientos del MEN. | H35: • Estatuto General • Estatuto Docente • Reglamento Estudiantil • Reglamento Consultorio Jurídico • Reglamento Alternativas de Grado • Reglamento Prácticas Universitarias Psicología • Reglamento Uso del Correo Institucional • Acuerdos de los Consejos Superior y Académico • Manual de Funciones • Resoluciones de Rectoría • Política de Protección de Datos Personales * Política de Educación Virtual y a Distancia | I35: Tasa técnica ( # de estudiantes / # de docentes tiempo completo) Deserción (# estudiantes desertores / # de estudiantes matriculados) Tasa de Graduación (tiempo de graduación cohorte) Bajo rendimiento (# estudiantes en bajo rendimiento /# de estudiantes matriculados) Evaluación Docente (# docentes con calificación >=4/ # de docentes evaluados) | J35: • PR-GC-004 "Acciones Correctivas"
A36: =COUNTA(C$3:C36) -> 34 | B36: PRO-3 | C36: Prog. Derecho | D36: Gestionar las diferentes actividades del currículo encaminado a la formación integral de profesionales como gestores de cambio y transformación en los diferentes contextos sociales. | E36: • Ley 30 de 1992 y decretos asociados • Ley 1740 del 2014 • Decreto único 1075 circular # 31 MEN • Decreto 1330 de 2019 del MEN • Acuerdo 02 del CESU • Ley de emprendimiento | F36: 4.4 • 5.1.2 • 6.1 • 7.1.1 • 7.1.2 • 7.1.3 • 7.1.4 • 7.1.5 • 7.1.6 • 7.4 • 7.5.1 • 7.5.2 • 7.5.3 • 8.1 • 8.2.1 • 8.2.2 • 8.2.3 • 8.2.4 • 8.3.1 • 8.3.2 • 8.3.3 • 8.3.4 • 8.3.5 • 8.3.6 • 8.5.1 • 8.5.2 • 8.5.3 • 8.5.4 • 8.5.5 • 8.5.6 • 8.6 • 8.7 • 9.1.1 • 9.1.2 • 9.1.3 • 10.2 • 10.3 | G36: • Información veraz, pertinente y oportuna • Servicio de Educación Superior acorde con los lineamientos del MEN. | H36: • Estatuto General • Estatuto Docente • Reglamento Estudiantil • Reglamento Consultorio Jurídico • Reglamento Alternativas de Grado • Reglamento Prácticas Universitarias Psicología • Reglamento Uso del Correo Institucional • Acuerdos de los Consejos Superior y Académico • Manual de Funciones • Resoluciones de Rectoría • Política de Protección de Datos Personales * Política de Educación Virtual y a Distancia | I36: Tasa técnica ( # de estudiantes / # de docentes tiempo completo) Deserción (# estudiantes desertores / # de estudiantes matriculados) Tasa de Graduación (tiempo de graduación cohorte) Bajo rendimiento (# estudiantes en bajo rendimiento /# de estudiantes matriculados) Evaluación Docente (# docentes con calificación >=4/ # de docentes evaluados) | J36: • PR-GC-004 "Acciones Correctivas"
A37: =COUNTA(C$3:C37) -> 35 | B37: PRO-4 | C37: Prog. Licenciatura Ed. Art. y Cultural | D37: Gestionar las diferentes actividades del currículo encaminado a la formación integral de profesionales como gestores de cambio y transformación en los diferentes contextos sociales. | E37: • Ley 30 de 1992 y decretos asociados • Ley 1740 del 2014 • Decreto único 1075 circular # 31 MEN • Decreto 1330 de 2019 del MEN • Acuerdo 02 del CESU • Ley de emprendimiento | F37: 4.4 • 5.1.2 • 6.1 • 7.1.1 • 7.1.2 • 7.1.3 • 7.1.4 • 7.1.5 • 7.1.6 • 7.4 • 7.5.1 • 7.5.2 • 7.5.3 • 8.1 • 8.2.1 • 8.2.2 • 8.2.3 • 8.2.4 • 8.3.1 • 8.3.2 • 8.3.3 • 8.3.4 • 8.3.5 • 8.3.6 • 8.5.1 • 8.5.2 • 8.5.3 • 8.5.4 • 8.5.5 • 8.5.6 • 8.6 • 8.7 • 9.1.1 • 9.1.2 • 9.1.3 • 10.2 • 10.3 | G37: • Información veraz, pertinente y oportuna • Servicio de Educación Superior acorde con los lineamientos del MEN. | H37: • Estatuto General • Estatuto Docente • Reglamento Estudiantil • Reglamento Consultorio Jurídico • Reglamento Alternativas de Grado • Reglamento Prácticas Universitarias Psicología • Reglamento Uso del Correo Institucional • Acuerdos de los Consejos Superior y Académico • Manual de Funciones • Resoluciones de Rectoría • Política de Protección de Datos Personales * Política de Educación Virtual y a Distancia | I37: Tasa técnica ( # de estudiantes / # de docentes tiempo completo) Deserción (# estudiantes desertores / # de estudiantes matriculados) Tasa de Graduación (tiempo de graduación cohorte) Bajo rendimiento (# estudiantes en bajo rendimiento /# de estudiantes matriculados) Evaluación Docente (# docentes con calificación >=4/ # de docentes evaluados) | J37: • PR-GC-004 "Acciones Correctivas"
A38: =COUNTA(C$3:C38) -> 36 | B38: PRO-5 | C38: Prog. Psicología | D38: Gestionar las diferentes actividades del currículo encaminado a la formación integral de profesionales como gestores de cambio y transformación en los diferentes contextos sociales. | E38: • Ley 30 de 1992 y decretos asociados • Ley 1740 del 2014 • Decreto único 1075 circular # 31 MEN • Decreto 1330 de 2019 del MEN • Acuerdo 02 del CESU • Ley de emprendimiento | F38: 4.4 • 5.1.2 • 6.1 • 7.1.1 • 7.1.2 • 7.1.3 • 7.1.4 • 7.1.5 • 7.1.6 • 7.4 • 7.5.1 • 7.5.2 • 7.5.3 • 8.1 • 8.2.1 • 8.2.2 • 8.2.3 • 8.2.4 • 8.3.1 • 8.3.2 • 8.3.3 • 8.3.4 • 8.3.5 • 8.3.6 • 8.5.1 • 8.5.2 • 8.5.3 • 8.5.4 • 8.5.5 • 8.5.6 • 8.6 • 8.7 • 9.1.1 • 9.1.2 • 9.1.3 • 10.2 • 10.3 | G38: • Información veraz, pertinente y oportuna • Servicio de Educación Superior acorde con los lineamientos del MEN. | H38: • Estatuto General • Estatuto Docente • Reglamento Estudiantil • Reglamento Consultorio Jurídico • Reglamento Alternativas de Grado • Reglamento Prácticas Universitarias Psicología • Reglamento Uso del Correo Institucional • Acuerdos de los Consejos Superior y Académico • Manual de Funciones • Resoluciones de Rectoría • Política de Protección de Datos Personales * Política de Educación Virtual y a Distancia | I38: Tasa técnica ( # de estudiantes / # de docentes tiempo completo) Deserción (# estudiantes desertores / # de estudiantes matriculados) Tasa de Graduación (tiempo de graduación cohorte) Bajo rendimiento (# estudiantes en bajo rendimiento /# de estudiantes matriculados) Evaluación Docente (# docentes con calificación >=4/ # de docentes evaluados) | J38: • PR-GC-004 "Acciones Correctivas"
A39: =COUNTA(C$3:C39) -> 37 | B39: PRO-6 | C39: Prog. Trabajo Social | D39: Gestionar las diferentes actividades del currículo encaminado a la formación integral de profesionales como gestores de cambio y transformación en los diferentes contextos sociales. | E39: • Ley 30 de 1992 y decretos asociados • Ley 1740 del 2014 • Decreto único 1075 circular # 31 MEN • Decreto 1330 de 2019 del MEN • Acuerdo 02 del CESU • Ley de emprendimiento | F39: 4.4 • 5.1.2 • 6.1 • 7.1.1 • 7.1.2 • 7.1.3 • 7.1.4 • 7.1.5 • 7.1.6 • 7.4 • 7.5.1 • 7.5.2 • 7.5.3 • 8.1 • 8.2.1 • 8.2.2 • 8.2.3 • 8.2.4 • 8.3.1 • 8.3.2 • 8.3.3 • 8.3.4 • 8.3.5 • 8.3.6 • 8.5.1 • 8.5.2 • 8.5.3 • 8.5.4 • 8.5.5 • 8.5.6 • 8.6 • 8.7 • 9.1.1 • 9.1.2 • 9.1.3 • 10.2 • 10.3 | G39: • Información veraz, pertinente y oportuna • Servicio de Educación Superior acorde con los lineamientos del MEN. | H39: • Estatuto General • Estatuto Docente • Reglamento Estudiantil • Reglamento Consultorio Jurídico • Reglamento Alternativas de Grado • Reglamento Prácticas Universitarias Psicología • Reglamento Uso del Correo Institucional • Acuerdos de los Consejos Superior y Académico • Manual de Funciones • Resoluciones de Rectoría • Política de Protección de Datos Personales * Política de Educación Virtual y a Distancia | I39: Tasa técnica ( # de estudiantes / # de docentes tiempo completo) Deserción (# estudiantes desertores / # de estudiantes matriculados) Tasa de Graduación (tiempo de graduación cohorte) Bajo rendimiento (# estudiantes en bajo rendimiento /# de estudiantes matriculados) Evaluación Docente (# docentes con calificación >=4/ # de docentes evaluados) | J39: • PR-GC-004 "Acciones Correctivas"
A40: =COUNTA(C$3:C40) -> 38 | B40: PRO-7 | C40: PPN - Prog. Ecología | D40: Gestionar las diferentes actividades del currículo encaminado a la formación integral de profesionales como gestores de cambio y transformación en los diferentes contextos sociales. | E40: • Ley 30 de 1992 y decretos asociados • Ley 1740 del 2014 • Decreto único 1075 circular # 31 MEN • Decreto 1330 de 2019 del MEN • Acuerdo 02 del CESU • Ley de emprendimiento | F40: 4.4 • 5.1.2 • 6.1 • 7.1.1 • 7.1.2 • 7.1.3 • 7.1.4 • 7.1.5 • 7.1.6 • 7.4 • 7.5.1 • 7.5.2 • 7.5.3 • 8.1 • 8.2.1 • 8.2.2 • 8.2.3 • 8.2.4 • 8.3.1 • 8.3.2 • 8.3.3 • 8.3.4 • 8.3.5 • 8.3.6 • 8.5.1 • 8.5.2 • 8.5.3 • 8.5.4 • 8.5.5 • 8.5.6 • 8.6 • 8.7 • 9.1.1 • 9.1.2 • 9.1.3 • 10.2 • 10.3 | G40: • Información veraz, pertinente y oportuna • Servicio de Educación Superior acorde con los lineamientos del MEN. | H40: • Estatuto General • Estatuto Docente • Reglamento Estudiantil • Reglamento Consultorio Jurídico • Reglamento Alternativas de Grado • Reglamento Prácticas Universitarias Psicología • Reglamento Uso del Correo Institucional • Acuerdos de los Consejos Superior y Académico • Manual de Funciones • Resoluciones de Rectoría • Política de Protección de Datos Personales * Política de Educación Virtual y a Distancia | I40: • Tasa técnica (Docentes por estudiante) • Deserción (x Periodo - x Cohorte) • Tasa de Graduación (Graduados por Cohorte) • Estudiantes en Investigación (Semilleros) • # de actualizaciones del PEP • Nivel de cualificación • Cumplimiento de matrículas académicas asociada al calendario académico • Cumplimiento de fechas del Calendario ICFES • Cumplimiento con el Registro de Notas • Entrega oportuna de informes • Cumplimiento de compromisos docentes • Resultados del período T-1 (Evaluación Docente) | J40: • PR-GC-004 "Acciones Correctivas"
A41: =COUNTA(C$3:C41) -> 39 | B41: PRO-8 | C41: PPN - Prog. Ingeniería de Sistemas | D41: Gestionar las diferentes actividades del currículo encaminado a la formación integral de profesionales como gestores de cambio y transformación en los diferentes contextos sociales. | E41: • Ley 30 de 1992 y decretos asociados • Ley 1740 del 2014 • Decreto único 1075 circular # 31 MEN • Decreto 1330 de 2019 del MEN • Acuerdo 02 del CESU • Ley de emprendimiento | F41: 4.4 • 5.1.2 • 6.1 • 7.1.1 • 7.1.2 • 7.1.3 • 7.1.4 • 7.1.5 • 7.1.6 • 7.4 • 7.5.1 • 7.5.2 • 7.5.3 • 8.1 • 8.2.1 • 8.2.2 • 8.2.3 • 8.2.4 • 8.3.1 • 8.3.2 • 8.3.3 • 8.3.4 • 8.3.5 • 8.3.6 • 8.5.1 • 8.5.2 • 8.5.3 • 8.5.4 • 8.5.5 • 8.5.6 • 8.6 • 8.7 • 9.1.1 • 9.1.2 • 9.1.3 • 10.2 • 10.3 | G41: • Información veraz, pertinente y oportuna • Servicio de Educación Superior acorde con los lineamientos del MEN. | H41: • Estatuto General • Estatuto Docente • Reglamento Estudiantil • Reglamento Consultorio Jurídico • Reglamento Alternativas de Grado • Reglamento Prácticas Universitarias Psicología • Reglamento Uso del Correo Institucional • Acuerdos de los Consejos Superior y Académico • Manual de Funciones • Resoluciones de Rectoría • Política de Protección de Datos Personales * Política de Educación Virtual y a Distancia | I41: • Tasa técnica (Docentes por estudiante) • Deserción (x Periodo - x Cohorte) • Tasa de Graduación (Graduados por Cohorte) • Estudiantes en Investigación (Semilleros) • # de actualizaciones del PEP • Nivel de cualificación • Cumplimiento de matrículas académicas asociada al calendario académico • Cumplimiento de fechas del Calendario ICFES • Cumplimiento con el Registro de Notas • Entrega oportuna de informes • Cumplimiento de compromisos docentes • Resultados del período T-1 (Evaluación Docente) | J41: • PR-GC-004 "Acciones Correctivas"
A42: =COUNTA(C$3:C42) -> 40 | B42: PRO-9 | C42: PPN - Prog. Ingeneiría Industrial | D42: Gestionar las diferentes actividades del currículo encaminado a la formación integral de profesionales como gestores de cambio y transformación en los diferentes contextos sociales. | E42: • Ley 30 de 1992 y decretos asociados • Ley 1740 del 2014 • Decreto único 1075 circular # 31 MEN • Decreto 1330 de 2019 del MEN • Acuerdo 02 del CESU • Ley de emprendimiento | F42: 4.4 • 5.1.2 • 6.1 • 7.1.1 • 7.1.2 • 7.1.3 • 7.1.4 • 7.1.5 • 7.1.6 • 7.4 • 7.5.1 • 7.5.2 • 7.5.3 • 8.1 • 8.2.1 • 8.2.2 • 8.2.3 • 8.2.4 • 8.3.1 • 8.3.2 • 8.3.3 • 8.3.4 • 8.3.5 • 8.3.6 • 8.5.1 • 8.5.2 • 8.5.3 • 8.5.4 • 8.5.5 • 8.5.6 • 8.6 • 8.7 • 9.1.1 • 9.1.2 • 9.1.3 • 10.2 • 10.3 | G42: • Información veraz, pertinente y oportuna • Servicio de Educación Superior acorde con los lineamientos del MEN. | H42: • Estatuto General • Estatuto Docente • Reglamento Estudiantil • Reglamento Consultorio Jurídico • Reglamento Alternativas de Grado • Reglamento Prácticas Universitarias Psicología • Reglamento Uso del Correo Institucional • Acuerdos de los Consejos Superior y Académico • Manual de Funciones • Resoluciones de Rectoría • Política de Protección de Datos Personales * Política de Educación Virtual y a Distancia | I42: • Tasa técnica (Docentes por estudiante) • Deserción (x Periodo - x Cohorte) • Tasa de Graduación (Graduados por Cohorte) • Estudiantes en Investigación (Semilleros) • # de actualizaciones del PEP • Nivel de cualificación • Cumplimiento de matrículas académicas asociada al calendario académico • Cumplimiento de fechas del Calendario ICFES • Cumplimiento con el Registro de Notas • Entrega oportuna de informes • Cumplimiento de compromisos docentes • Resultados del período T-1 (Evaluación Docente) | J42: • PR-GC-004 "Acciones Correctivas"
A43: =COUNTA(C$3:C43) -> 41 | B43: PRO-10 | C43: PPN - Prog. Licenciatura Ed. Art. y Cultural | D43: Gestionar las diferentes actividades del currículo encaminado a la formación integral de profesionales como gestores de cambio y transformación en los diferentes contextos sociales. | E43: • Ley 30 de 1992 y decretos asociados • Ley 1740 del 2014 • Decreto único 1075 circular # 31 MEN • Decreto 1330 de 2019 del MEN • Acuerdo 02 del CESU • Ley de emprendimiento | F43: 4.4 • 5.1.2 • 6.1 • 7.1.1 • 7.1.2 • 7.1.3 • 7.1.4 • 7.1.5 • 7.1.6 • 7.4 • 7.5.1 • 7.5.2 • 7.5.3 • 8.1 • 8.2.1 • 8.2.2 • 8.2.3 • 8.2.4 • 8.3.1 • 8.3.2 • 8.3.3 • 8.3.4 • 8.3.5 • 8.3.6 • 8.5.1 • 8.5.2 • 8.5.3 • 8.5.4 • 8.5.5 • 8.5.6 • 8.6 • 8.7 • 9.1.1 • 9.1.2 • 9.1.3 • 10.2 • 10.3 | G43: • Información veraz, pertinente y oportuna • Servicio de Educación Superior acorde con los lineamientos del MEN. | H43: • Estatuto General • Estatuto Docente • Reglamento Estudiantil • Reglamento Consultorio Jurídico • Reglamento Alternativas de Grado • Reglamento Prácticas Universitarias Psicología • Reglamento Uso del Correo Institucional • Acuerdos de los Consejos Superior y Académico • Manual de Funciones • Resoluciones de Rectoría • Política de Protección de Datos Personales * Política de Educación Virtual y a Distancia | I43: • Tasa técnica (Docentes por estudiante) • Deserción (x Periodo - x Cohorte) • Tasa de Graduación (Graduados por Cohorte) • Estudiantes en Investigación (Semilleros) • # de actualizaciones del PEP • Nivel de cualificación • Cumplimiento de matrículas académicas asociada al calendario académico • Cumplimiento de fechas del Calendario ICFES • Cumplimiento con el Registro de Notas • Entrega oportuna de informes • Cumplimiento de compromisos docentes • Resultados del período T-1 (Evaluación Docente) | J43: • PR-GC-004 "Acciones Correctivas"
A44: =COUNTA(C$3:C44) -> 42 | B44: PRO-11 | C44: PPN - Prog. Psicología | D44: Gestionar las diferentes actividades del currículo encaminado a la formación integral de profesionales como gestores de cambio y transformación en los diferentes contextos sociales. | E44: • Ley 30 de 1992 y decretos asociados • Ley 1740 del 2014 • Decreto único 1075 circular # 31 MEN • Decreto 1330 de 2019 del MEN • Acuerdo 02 del CESU • Ley de emprendimiento | F44: 4.4 • 5.1.2 • 6.1 • 7.1.1 • 7.1.2 • 7.1.3 • 7.1.4 • 7.1.5 • 7.1.6 • 7.4 • 7.5.1 • 7.5.2 • 7.5.3 • 8.1 • 8.2.1 • 8.2.2 • 8.2.3 • 8.2.4 • 8.3.1 • 8.3.2 • 8.3.3 • 8.3.4 • 8.3.5 • 8.3.6 • 8.5.1 • 8.5.2 • 8.5.3 • 8.5.4 • 8.5.5 • 8.5.6 • 8.6 • 8.7 • 9.1.1 • 9.1.2 • 9.1.3 • 10.2 • 10.3 | G44: • Información veraz, pertinente y oportuna • Servicio de Educación Superior acorde con los lineamientos del MEN. | H44: • Estatuto General • Estatuto Docente • Reglamento Estudiantil • Reglamento Consultorio Jurídico • Reglamento Alternativas de Grado • Reglamento Prácticas Universitarias Psicología • Reglamento Uso del Correo Institucional • Acuerdos de los Consejos Superior y Académico • Manual de Funciones • Resoluciones de Rectoría • Política de Protección de Datos Personales * Política de Educación Virtual y a Distancia | I44: • Tasa técnica (Docentes por estudiante) • Deserción (x Periodo - x Cohorte) • Tasa de Graduación (Graduados por Cohorte) • Estudiantes en Investigación (Semilleros) • # de actualizaciones del PEP • Nivel de cualificación • Cumplimiento de matrículas académicas asociada al calendario académico • Cumplimiento de fechas del Calendario ICFES • Cumplimiento con el Registro de Notas • Entrega oportuna de informes • Cumplimiento de compromisos docentes • Resultados del período T-1 (Evaluación Docente) | J44: • PR-GC-004 "Acciones Correctivas"
