Workbook

Sheet INSTRUCCIONES
B4: INSTRUCCIONES PARA EL CORRECTO DILIGENCIAMIENTO DEL FO-GC-003 PLAN DE MEJORAMIENTO INSTITUCIONAL
B6: 1 | C6: PROCESO | E6: Escoja de la lista desplegable el proceso en el cual se identificó el hallazgo
B7: 2 | C7: PROGRAMA ACADÉMICO | E7: Escoja de la lista desplegable el programa académico en el cual se identificó el hallazgo
B8: 3 | C8: FUENTE | E8: Escoja de la lista desplegable la fuente del hallazgo, es decir en qué tipo de ejercicio se identificó el hallazgo o la ausencia de cumplimiento de los requisitos normativos, se va a encontrar: PQRs: Cuando se identifique una PQRs que obligue a realizar cambios en el proceso. AUDITORÍA INTERNA: cuando el hallazgo provenga de un ejercicio de Auditoría Interna. AUDITORÍA EXTERNA: cuando el hallazgo provenga de un ejercicio de Auditoría Externa. AUDITORÍA DE CONTROL INTERNO: cuando el hallazgo provenga de un ejercicio de Auditoría de control Interno. Nota: Si la fuente de hallazgo se da en Evaluación Docente, debe diligenciar la casilla denominada CRITERIO SOBRE EL CUAL VA A REALIZAN EL PLAN DE MEJORAMIENTO, al igual que indicar el nombre del docente.
B9: 4 | C9: FECHA DE IDENTIFICACIÓN DEL HALLAZGO | E9: Escriba la fecha en la cual se hizo la identificación del hallazgo en formato (DD/MM/AAAA)
B10: 5 | C10: TIPO DE HALLAZGO | E10: Escoja de la lista desplegable el tipo de hallazgo, se va a encontrar: NO CONFORMIDAD: Cuando el hallazgo responda a una NC con alguno de los requisitos de la NTC ISO 9001:2015 OPORTUNIDAD DE MEJORA: Cuando se identifica una oportunidad de hacer las cosas mejor en el proceso. SALIDA NO CONFORME: Cuando un producto o servicio ha sido liberado (con intención o sin ella) y ha llegado a manos de las partes interesadas (indistintamente de a que grupo pertenezcam).
B11: 6 | C11: DESCRIPCIÓN | D11: REQUISITO DE LA NORMA - FACTOR Y/O CARACTERÍSTICA | E11: En caso de que el hallazgo sea NO CONFORMIDAD escriba aquí el requisito de la Norma ISO 9001:2015 que está incumpliendo, esto lo encuentra en su Informe de auditoría. En caso de que el Hallazgo sea OPORTUNIDAD DE MEJORA escriba aquí XXXXX En caso de que el hallazgo sea SALIDA NO CONFORME escriba aquí 8.7 CONTROL DE LAS SALIDAS NO CONFORMES.
D12: DESCRIPCIÓN DEL HALLAZGO | E12: Escriba aquí la descripción de la No conformidad que aparece en su informe de Auditoría o con sus palabras describa el hallazgo, oportunidad de mejora, salida no conforme o incumplimiento de factores de autoevaluación. | G12: PROBLEMA | H12: En esta casilla usted encontrará la información diligenciada en la DESCRIPCIÓN DEL HALLAZGO de la pestaña FO-GC-003 PLAN DE MEJORA; el problema es la base sobre la cual se formulará la primera pregunta que usted responderá en función de Por qué se presentó el problema.
B13: 7 | C13: TIPO DE ACCIÓN A TOMAR | E13: Selecciones si la acción a tomar es de tipo: CORRECTIVO: Cuando se implementa para eliminar la causa de una No Conformidad y evitar que vuelva a ocurrir y cuando después de una revisión, auditoría, medición no se han alcanzado los resultados esperados o no se ha dado el cumplimiento satisfactorio de los requisitos (factores, condiciones o características). DE MEJORA: Cuando posterior a los resultados satisfactorios en los procesos de medición de los procesos se identifican oportunidades de mejorar en el proceso. Nota: Si su respuesta en este punto fue ACCIÓN INMEDIATA CORRECCIÓN, Describa brevemente cúal fue la acción tomada en la casilla siguiente
B14: 8 | C14: ANÁLISIS DE CAUSAS | E14: PARA EL ANÁLISIS DE CAUSA DIRÍJASE A LA PESTAÑA ANÁLISIS 5PQs Y SIGA LOS SIGUIENTES PASOS:
B15: 9 | C15: EL HALLAZGO SE HABÍA PRESENTADO ANTES? | E15: Indique aquí con una X si este hallazgo se había presentado anteriormente o si es primera vez que surge
B16: 10 | C16: SE PUEDE VOLVER A PRESENTAR? | E16: Indique si el hallazgo encontrado actualmente se puede volver a presentar a futuro
B17: 11 | C17: ES NECESARIO HACER CAMBIOS A | E17: Marque con una X si es necesario hacer cambio a alguna de las siguientes opciones: *Matriz de Riesgos y Oportunidades *Sistema de Gestión de Calidad (SGC) *Ninguna de las anteriores | G17: PRIMER POR QUÉ | H17: Escriba en esta casilla la respuesta al primer por qué, en este caso será: Por qué se presentó el problema
B18: 12 | C18: DESCRIPCIÓN DE LA ACCION A TOMAR | D18: META/OBJETIVO | E18: Escriba aquí, qué es lo que pretende lograr con la implementación de la acción. (Esta meta u objetivo debe agregar valor a la calidad del proceso, ser concreta y de ser necesario incluir una cifra en su formulación) Ej: Reducir la deserción en un punto teniendo en cuenta la linea base a 2022. | G18: 2do POR QUÉ: | H18: El formato está diseñado para que de forma automática se formule la pregunta con la cual usted responderá el SEGUNDO por qué, escriba entonces la respuesta que corresponde al segundo por qué.
D19: DETALLE DE ACTIVIDADES | E19: Escriba aquí en detalle la o las actividades que debe ejecutar para el logro de la meta formulada en la casilla anterior. | G19: 3cer POR QUÉ: | H19: El formato está diseñado para que de forma automática se formule la pregunta con la cual usted responderá el TERCER por qué, escriba entonces la respuesta que corresponde al tercer por qué.
D20: ENTREGABLE O RESULTADO | E20: Escriba aquí la evidencia que se presentará como resultado de la implementación de la acción. Ejemplo: Informe de Auditorías - Resolución Rectoral con actualización de política. | G20: 4to POR QUÉ: | H20: El formato está diseñado para que de forma automática se formule la pregunta con la cual usted responderá el CUARTO por qué, escriba entonces la respuesta que corresponde al cuarto por qué.
B21: 13 | C21: RECURSOS | E21: Escriba a quí el tipo de recurso que va a requerir en la implementación de la actividad, puede ser: HUMANOS - MATERIALES - TÉCNICOS Y FINANCIEROS. | G21: 5to POR QUÉ: | H21: El formato está diseñado para que de forma automática se formule la pregunta con la cual usted responderá el QUINTO por qué, escriba entonces la respuesta que corresponde al quinto por qué.
B22: 14 | C22: RESPONSABLE | E22: Escriba aquí el responsable (Nombre y Cargo) de quien es responsable de la ejecución de las acciones formuladas | G22: CAUSA RAÍZ | H22: La Causa Raíz se calcula de forma automática y corresponderá al ULTIMO por qué respondido, NO ESTÁ EN LA OBLIGACIÓN de dar respuesta a los cinco por qué, si considera que ha llegado a la causa raíz el sistema le mostrará la causa raíz en esta casilla. El resultado se mostrará directamente en su formato de plan de mejoramiento por lo que no necesita diligenciar nada más. Retorne a la pestaña de FO-GC-00x PLAN DE MEJORA y continúe el diigenciamiento
B23: 15 | C23: FECHA MÁXIMA DE IMPLEMENTACIÓN | E23: Escriba aquí cuál es la fecha en la que se pretende alcanzar el objetivo en formato (DD/MM/AAAA)
B24: 16 | C24: RECUPERACIÓN DE EVIDENCIA | E24: Aquí encontrará un enlace lo direcciona a un DRIVE en donde deberá identificar la carpeta que corresponde a su proceso y en la que deben reposar todas las evidencias de implementación de su plan de mejoramiento y sobre la cual se realizará el posterior seguimiento. TENGA POR FAVOR CUIDADO EN LA SELECCIÓN DE SU CARPETA.
B25: 17 | C25: SEGUIMIENTO PROGRAMADO | D25: FECHA SEGUIMIENTO (DD/MM/AAAA) | E25: Escriba aquí cuál es la fecha en la que se realiza el seguimeinto (DD/MM/AAAA)
D26: CUMPLIÓ - CIERRE DEL HALLAZGO | E26: Determine si para la fecha del seguimiento se han desarrollado las actividades propuestas. De ser así dele cierre al PLAN DE MEJORAMIENTO
D27: NO CUMPLIÓ | E27: Si las actividades propuestas no se han desarrollado deberá marcar con una "X".
D28: REPROGRAMACIÓN DE SEGUIMIENTO | E28: Si el PLAN DE MEJORAMIENTO no se ha cerrado, deberá reprogramar y dar fecha (DD/MM/AAAA), para proximo seguimiento

Sheet FO-GC-003
G7: 1. PROCESO | V7: 2. PROGRAMA ACADÉMICO
B9: PLAN DE MEJORAMIENTO INSTITUCIONAL
B10: HALLAZGO | J10: DEFINICION DE LAS ACCIONES A TOMAR | R10: PLAN DE ACCIÓN | AC10: SEGUIMIENTO
B11: N° | C11: 3.FUENTE | D11: CRITERIO SOBRE EL CUAL VA A REALIZAN EL PLAN DE MEJORAMIENTO (Diligencie sólo si la FUENTE es EVALUACIÓN DOCENTE) | E11: NOMBRE DEL DOCENTE (Diligencie sólo si la FUENTE es EVALUACIÓN DOCENTE) | F11: 4.FECHA DE IDENTIFICACIÓN DEL HALLAZGO (DD/MM/AAAA) | G11: 5.TIPO DE HALLAZGO | H11: 6.DESCRIPCION | J11: 7. TIPO DE ACCIÓN A TOMAR (Reacción frente al hallazgo) | K11: Si su respuesta en el punto 7 fue ACCIÓN INMEDIATA CORRECCIÓN, Describa brevemente cúal fue la acción tomada | L11: 8.ANÁLISIS DE CAUSAS (IDENTIFICACIÓN CAUSA RAÍZ) | M11: 9. EL HALLAZGO SE HABÍA PRESENTADO ANTES?(Marque con una X) | P11: 10. SE PUEDE VOLVER A PRESENTAR?(Marque con una X) | R11: 11. ES NECESARIO HACER CAMBIOS A: (Marque con una X) | U11: 12.DESCRIPCIÓN DE LA ACCION A TOMAR (Tenga en cuenta que incluir cuando aplique las acciones de ajuste a matriz de riesgos ocambios al SGC cuando aplique) | X11: 13.RECURSOS | Y11: 14.RESPONSABLE | AA11: 15.FECHA MÁXIMA DE IMPLEMENTACIÓN | AB11: 16. RECUPERACIÓN DE EVIDENCIA | AC11: 17. SEGUIMIENTO PROGRAMADO
H12: REQUISITO DE LA NORMA - CRITERIO DE EVALUACIÓN | I12: DESCRIPCIÓN DEL HALLAZGO | M12: SI | N12: NO | O12: NO SÉ | P12: SI | Q12: NO | R12: MATRIZ DE RIESGOS Y OPORTUNIDADES DEL PROCESO | S12: AL SISTEMA DE GESTIÓN DE CALIDAD | T12: NINGUNO | U12: META | V12: DETALLE DE ACTIVIDADES | W12: ENTREGABLE O RESULTADO | Y12: NOMBRE | Z12: CARGO | AA12: (DD/MM/AAAA) | AC12: FECHA SEGUIMIENTO (DD/MM/AAAA) | AD12: CUMPLIÓ - CIERRE DEL HALLAZGO | AE12: NO CUMPLIÓ | AF12: REPROGRAMACIÓN DE SEGUIMIENTO
B13: 1 | L13: =IF('ANÁLISIS 5PQs'!AA14<>"",'ANÁLISIS 5PQs'!AA14,"") | AB13: https://fupedu-my.sharepoint.com/:f:/g/personal/calidad_fup_edu_co/ErIPOjWRnmJDpNIfwYwCIckBBEZ8c-UUMbURkJEeSKieOw?e=dq0eCs
B17: 2 | L17: =IF('ANÁLISIS 5PQs'!AA21<>"",'ANÁLISIS 5PQs'!AA21,"")
B21: 3 | L21: =IF('ANÁLISIS 5PQs'!AA28<>"",'ANÁLISIS 5PQs'!AA28,"")
B25: 4 | L25: =IF('ANÁLISIS 5PQs'!AA35<>"",'ANÁLISIS 5PQs'!AA35,"")
B29: 5 | L29: =IF('ANÁLISIS 5PQs'!AA42<>"",'ANÁLISIS 5PQs'!AA42,"")
B33: 6 | L33: =IF('ANÁLISIS 5PQs'!AA49<>"",'ANÁLISIS 5PQs'!AA49,"")
B37: 7 | L37: =IF('ANÁLISIS 5PQs'!AA56<>"",'ANÁLISIS 5PQs'!AA56,"")
B41: 8 | L41: =IF('ANÁLISIS 5PQs'!AA63<>"",'ANÁLISIS 5PQs'!AA63,"")
B45: 9 | L45: =IF('ANÁLISIS 5PQs'!AA70<>"",'ANÁLISIS 5PQs'!AA70,"")
B49: 10 | L49: =IF('ANÁLISIS 5PQs'!AA77<>"",'ANÁLISIS 5PQs'!AA77,"")
B53: 11 | L53: =IF('ANÁLISIS 5PQs'!AA84<>"",'ANÁLISIS 5PQs'!AA84,"")
B57: 12 | L57: =IF('ANÁLISIS 5PQs'!AA91<>"",'ANÁLISIS 5PQs'!AA91,"")
B61: 13 | L61: =IF('ANÁLISIS 5PQs'!AA98<>"",'ANÁLISIS 5PQs'!AA98,"")
B65: 14 | L65: =IF('ANÁLISIS 5PQs'!AA105<>"",'ANÁLISIS 5PQs'!AA105,"")
B69: 15 | L69: =IF('ANÁLISIS 5PQs'!AA109<>"",'ANÁLISIS 5PQs'!AA109,"")

Sheet ANÁLISIS 5PQs
F5: ANÁLISIS DE CAUSAS - 5 POR QUÉS
G7: =IF('FO-GC-003'!H7<>"",'FO-GC-003'!H7,"")
K9: =IF('FO-GC-003'!X7<>"",'FO-GC-003'!X7,"")
K11: 2do POR QUÉ: | O11: 3cer POR QUÉ: | S11: 4to POR QUÉ: | W11: 5to POR QUÉ:
B12: PROBLEMA | G12: PRIMER POR QUÉ | K12: =G14 -> 0 | O12: =K14 -> 0 | S12: =O14 -> 0 | W12: =S14 -> 0 | AA12: CAUSA RAÍZ
A14: 1 | B14: =IF('FO-GC-003'!I13<>"",'FO-GC-003'!I13,"") | F14: PORQUE | I14: =IF(AND(I15<>"",J15<>""),IF(AND(G14<>"",K14<>""),"","x"),IF(AND(G14="",K14="",I16="x",I17="x"),"x","")) | M14: =IF(AND(M15<>"",N15<>""),IF(AND(K14<>"",O14<>""),"","x"),IF(AND(K14="",O14="",M16="x",M17="x"),"x","")) -> #REF! | Q14: =IF(AND(Q15<>"",R15<>""),IF(AND(O14<>"",S14<>""),"","x"),IF(AND(O14="",S14="",Q16="x",Q17="x"),"x","")) -> #REF! | U14: =IF(AND(U15<>"",V15<>""),IF(AND(S14<>"",W14<>""),"","x"),IF(AND(S14="",W14="",U16="x",U17="x"),"x","")) -> #REF! | Z14: =IF(LOOKUP(2,1/(G14:W14<>""),G14:W14)="x","",LOOKUP(2,1/(G14:W14<>""),G14:W14)) -> #N/A | AA14: =IF(ISNA($Z14),"",$Z14)
H15: =IF(AND(G14<>"",K14<>""),"x","") | I15: =IF(K14<>"","x",IF(I16="x","x","")) | J15: =IF(K14<>"","x","") | L15: =IF(AND(K14<>"",O14<>""),"x","") | M15: =IF(O14<>"","x",IF(M16="x","x","")) -> #REF! | N15: =IF(O14<>"","x","") | P15: =IF(AND(O14<>"",S14<>""),"x","") | Q15: =IF(S14<>"","x",IF(Q16="x","x","")) -> #REF! | R15: =IF(S14<>"","x","") | T15: =IF(AND(S14<>"",W14<>""),"x","") | U15: =IF(W14<>"","x",IF(U16="x","x","")) -> #REF! | V15: =IF(W14<>"","x","")
I16: =IF(I17="x","x","") | M16: =IF(M17="x","x","") -> #REF! | Q16: =IF(Q17="x","x","") -> #REF! | U16: =IF(U17="x","x","") -> #REF!
I17: =IF(AND(I21<>"",I22<>""),"x","") | M17: =IF(AND(M21<>"",M22<>""),"x","") -> #REF! | Q17: =IF(AND(Q21<>"",Q22<>""),"x","") -> #REF! | U17: =IF(AND(U21<>"",U22<>""),"x","") -> #REF!
K18: 2do POR QUÉ: | O18: 3cer POR QUÉ: | S18: 4to POR QUÉ: | W18: 5to POR QUÉ:
B19: PROBLEMA | G19: PRIMER POR QUÉ | K19: =G21 -> 0 | O19: =K21 -> 0 | S19: =O21 -> 0 | W19: =S21 -> 0 | AA19: CAUSA RAÍZ
A21: 2 | B21: =IF('FO-GC-003'!I17<>"",'FO-GC-003'!I17,"") | F21: PORQUE | I21: =IF(AND(I22<>"",J22<>""),IF(AND(G21<>"",K21<>""),"","x"),IF(AND(G21="",K21="",I23="x",I27="x"),"x","")) | M21: =IF(AND(M22<>"",N22<>""),IF(AND(K21<>"",O21<>""),"","x"),IF(AND(K21="",O21="",M23="x",M27="x"),"x","")) -> #REF! | Q21: =IF(AND(Q22<>"",R22<>""),IF(AND(O21<>"",S21<>""),"","x"),IF(AND(O21="",S21="",Q23="x",Q27="x"),"x","")) -> #REF! | U21: =IF(AND(U22<>"",V22<>""),IF(AND(S21<>"",W21<>""),"","x"),IF(AND(S21="",W21="",U23="x",U27="x"),"x","")) -> #REF! | Z21: =IF(LOOKUP(2,1/(G21:W21<>""),G21:W21)="x","",LOOKUP(2,1/(G21:W21<>""),G21:W21)) -> #N/A | AA21: =IF(ISNA($Z21),"",$Z21)
H22: =IF(AND(G21<>"",K21<>""),"x","") | I22: =IF(K21<>"","x",IF(I23="x","x","")) | J22: =IF(K21<>"","x","") | L22: =IF(AND(K21<>"",O21<>""),"x","") | M22: =IF(O21<>"","x",IF(M23="x","x","")) -> #REF! | N22: =IF(O21<>"","x","") | P22: =IF(AND(O21<>"",S21<>""),"x","") | Q22: =IF(S21<>"","x",IF(Q23="x","x","")) -> #REF! | R22: =IF(S21<>"","x","") | T22: =IF(AND(S21<>"",W21<>""),"x","") | U22: =IF(W21<>"","x",IF(U23="x","x","")) -> #REF! | V22: =IF(W21<>"","x","")
I23: =IF(I27="x","x","") | M23: =IF(M27="x","x","") -> #REF! | Q23: =IF(Q27="x","x","") -> #REF! | U23: =IF(U27="x","x","") -> #REF!
K25: 2do POR QUÉ: | O25: 3cer POR QUÉ: | S25: 4to POR QUÉ: | W25: 5to POR QUÉ:
B26: PROBLEMA | G26: PRIMER POR QUÉ | K26: =G28 -> 0 | O26: =K28 -> 0 | S26: =O28 -> 0 | W26: =S28 -> 0 | AA26: CAUSA RAÍZ
I27: =IF(AND(I28<>"",I29<>""),"x","") | M27: =IF(AND(M28<>"",M29<>""),"x","") -> #REF! | Q27: =IF(AND(Q28<>"",Q29<>""),"x","") -> #REF! | U27: =IF(AND(U28<>"",U29<>""),"x","") -> #REF!
A28: 3 | B28: =IF('FO-GC-003'!I21<>"",'FO-GC-003'!I21,"") | F28: PORQUE | I28: =IF(AND(I29<>"",J29<>""),IF(AND(G28<>"",K28<>""),"","x"),IF(AND(G28="",K28="",I30="x",I34="x"),"x","")) | M28: =IF(AND(M29<>"",N29<>""),IF(AND(K28<>"",O28<>""),"","x"),IF(AND(K28="",O28="",M30="x",M34="x"),"x","")) -> #REF! | Q28: =IF(AND(Q29<>"",R29<>""),IF(AND(O28<>"",S28<>""),"","x"),IF(AND(O28="",S28="",Q30="x",Q34="x"),"x","")) -> #REF! | U28: =IF(AND(U29<>"",V29<>""),IF(AND(S28<>"",W28<>""),"","x"),IF(AND(S28="",W28="",U30="x",U34="x"),"x","")) -> #REF! | Z28: =IF(LOOKUP(2,1/(G28:W28<>""),G28:W28)="x","",LOOKUP(2,1/(G28:W28<>""),G28:W28)) -> #N/A | AA28: =IF(ISNA($Z28),"",$Z28)
H29: =IF(AND(G28<>"",K28<>""),"x","") | I29: =IF(K28<>"","x",IF(I30="x","x","")) | J29: =IF(K28<>"","x","") | L29: =IF(AND(K28<>"",O28<>""),"x","") | M29: =IF(O28<>"","x",IF(M30="x","x","")) -> #REF! | N29: =IF(O28<>"","x","") | P29: =IF(AND(O28<>"",S28<>""),"x","") | Q29: =IF(S28<>"","x",IF(Q30="x","x","")) -> #REF! | R29: =IF(S28<>"","x","") | T29: =IF(AND(S28<>"",W28<>""),"x","") | U29: =IF(W28<>"","x",IF(U30="x","x","")) -> #REF! | V29: =IF(W28<>"","x","")
I30: =IF(I34="x","x","") | M30: =IF(M34="x","x","") -> #REF! | Q30: =IF(Q34="x","x","") -> #REF! | U30: =IF(U34="x","x","") -> #REF!
K32: 2do POR QUÉ: | O32: 3cer POR QUÉ: | S32: 4to POR QUÉ: | W32: 5to POR QUÉ:
B33: PROBLEMA | G33: PRIMER POR QUÉ | K33: =G35 -> 0 | O33: =K35 -> 0 | S33: =O35 -> 0 | W33: =S35 -> 0 | AA33: CAUSA RAÍZ
I34: =IF(AND(I35<>"",I36<>""),"x","") | M34: =IF(AND(M35<>"",M36<>""),"x","") -> #REF! | Q34: =IF(AND(Q35<>"",Q36<>""),"x","") -> #REF! | U34: =IF(AND(U35<>"",U36<>""),"x","") -> #REF!
A35: 4 | B35: =IF('FO-GC-003'!I25<>"",'FO-GC-003'!I25,"") | F35: PORQUE | I35: =IF(AND(I36<>"",J36<>""),IF(AND(G35<>"",K35<>""),"","x"),IF(AND(G35="",K35="",I37="x",I41="x"),"x","")) | M35: =IF(AND(M36<>"",N36<>""),IF(AND(K35<>"",O35<>""),"","x"),IF(AND(K35="",O35="",M37="x",M41="x"),"x","")) -> #REF! | Q35: =IF(AND(Q36<>"",R36<>""),IF(AND(O35<>"",S35<>""),"","x"),IF(AND(O35="",S35="",Q37="x",Q41="x"),"x","")) -> #REF! | U35: =IF(AND(U36<>"",V36<>""),IF(AND(S35<>"",W35<>""),"","x"),IF(AND(S35="",W35="",U37="x",U41="x"),"x","")) -> #REF! | Z35: =IF(LOOKUP(2,1/(G35:W35<>""),G35:W35)="x","",LOOKUP(2,1/(G35:W35<>""),G35:W35)) -> #N/A | AA35: =IF(ISNA($Z35),"",$Z35)
H36: =IF(AND(G35<>"",K35<>""),"x","") | I36: =IF(K35<>"","x",IF(I37="x","x","")) | J36: =IF(K35<>"","x","") | L36: =IF(AND(K35<>"",O35<>""),"x","") | M36: =IF(O35<>"","x",IF(M37="x","x","")) -> #REF! | N36: =IF(O35<>"","x","") | P36: =IF(AND(O35<>"",S35<>""),"x","") | Q36: =IF(S35<>"","x",IF(Q37="x","x","")) -> #REF! | R36: =IF(S35<>"","x","") | T36: =IF(AND(S35<>"",W35<>""),"x","") | U36: =IF(W35<>"","x",IF(U37="x","x","")) -> #REF! | V36: =IF(W35<>"","x","")
I37: =IF(I41="x","x","") | M37: =IF(M41="x","x","") -> #REF! | Q37: =IF(Q41="x","x","") -> #REF! | U37: =IF(U41="x","x","") -> #REF!
K39: 2do POR QUÉ: | O39: 3cer POR QUÉ: | S39: 4to POR QUÉ: | W39: 5to POR QUÉ:
B40: PROBLEMA | G40: PRIMER POR QUÉ | K40: =G42 -> 0 | O40: =K42 -> 0 | S40: =O42 -> 0 | W40: =S42 -> 0 | AA40: CAUSA RAÍZ
I41: =IF(AND(I42<>"",I43<>""),"x","") | M41: =IF(AND(M42<>"",M43<>""),"x","") -> #REF! | Q41: =IF(AND(Q42<>"",Q43<>""),"x","") -> #REF! | U41: =IF(AND(U42<>"",U43<>""),"x","") -> #REF!
A42: 5 | B42: =IF('FO-GC-003'!I29<>"",'FO-GC-003'!I29,"") | F42: PORQUE | I42: =IF(AND(I43<>"",J43<>""),IF(AND(G42<>"",K42<>""),"","x"),IF(AND(G42="",K42="",I44="x",I48="x"),"x","")) | M42: =IF(AND(M43<>"",N43<>""),IF(AND(K42<>"",O42<>""),"","x"),IF(AND(K42="",O42="",M44="x",M48="x"),"x","")) -> #REF! | Q42: =IF(AND(Q43<>"",R43<>""),IF(AND(O42<>"",S42<>""),"","x"),IF(AND(O42="",S42="",Q44="x",Q48="x"),"x","")) -> #REF! | U42: =IF(AND(U43<>"",V43<>""),IF(AND(S42<>"",W42<>""),"","x"),IF(AND(S42="",W42="",U44="x",U48="x"),"x","")) -> #REF! | Z42: =IF(LOOKUP(2,1/(G42:W42<>""),G42:W42)="x","",LOOKUP(2,1/(G42:W42<>""),G42:W42)) -> #N/A | AA42: =IF(ISNA($Z42),"",$Z42)
H43: =IF(AND(G42<>"",K42<>""),"x","") | I43: =IF(K42<>"","x",IF(I44="x","x","")) | J43: =IF(K42<>"","x","") | L43: =IF(AND(K42<>"",O42<>""),"x","") | M43: =IF(O42<>"","x",IF(M44="x","x","")) -> #REF! | N43: =IF(O42<>"","x","") | P43: =IF(AND(O42<>"",S42<>""),"x","") | Q43: =IF(S42<>"","x",IF(Q44="x","x","")) -> #REF! | R43: =IF(S42<>"","x","") | T43: =IF(AND(S42<>"",W42<>""),"x","") | U43: =IF(W42<>"","x",IF(U44="x","x","")) -> #REF! | V43: =IF(W42<>"","x","")
I44: =IF(I48="x","x","") | M44: =IF(M48="x","x","") -> #REF! | Q44: =IF(Q48="x","x","") -> #REF! | U44: =IF(U48="x","x","") -> #REF!
K46: 2do POR QUÉ: | O46: 3cer POR QUÉ: | S46: 4to POR QUÉ: | W46: 5to POR QUÉ:
B47: PROBLEMA | G47: PRIMER POR QUÉ | K47: =G49 -> 0 | O47: =K49 -> 0 | S47: =O49 -> 0 | W47: =S49 -> 0 | AA47: CAUSA RAÍZ
I48: =IF(AND(I49<>"",I50<>""),"x","") | M48: =IF(AND(M49<>"",M50<>""),"x","") -> #REF! | Q48: =IF(AND(Q49<>"",Q50<>""),"x","") -> #REF! | U48: =IF(AND(U49<>"",U50<>""),"x","") -> #REF!
A49: 6 | B49: =IF('FO-GC-003'!I33<>"",'FO-GC-003'!I33,"") | F49: PORQUE | I49: =IF(AND(I50<>"",J50<>""),IF(AND(G49<>"",K49<>""),"","x"),IF(AND(G49="",K49="",I51="x",I55="x"),"x","")) | M49: =IF(AND(M50<>"",N50<>""),IF(AND(K49<>"",O49<>""),"","x"),IF(AND(K49="",O49="",M51="x",M55="x"),"x","")) -> #REF! | Q49: =IF(AND(Q50<>"",R50<>""),IF(AND(O49<>"",S49<>""),"","x"),IF(AND(O49="",S49="",Q51="x",Q55="x"),"x","")) -> #REF! | U49: =IF(AND(U50<>"",V50<>""),IF(AND(S49<>"",W49<>""),"","x"),IF(AND(S49="",W49="",U51="x",U55="x"),"x","")) -> #REF! | Z49: =IF(LOOKUP(2,1/(G49:W49<>""),G49:W49)="x","",LOOKUP(2,1/(G49:W49<>""),G49:W49)) -> #N/A | AA49: =IF(ISNA($Z49),"",$Z49)
H50: =IF(AND(G49<>"",K49<>""),"x","") | I50: =IF(K49<>"","x",IF(I51="x","x","")) | J50: =IF(K49<>"","x","") | L50: =IF(AND(K49<>"",O49<>""),"x","") | M50: =IF(O49<>"","x",IF(M51="x","x","")) -> #REF! | N50: =IF(O49<>"","x","") | P50: =IF(AND(O49<>"",S49<>""),"x","") | Q50: =IF(S49<>"","x",IF(Q51="x","x","")) -> #REF! | R50: =IF(S49<>"","x","") | T50: =IF(AND(S49<>"",W49<>""),"x","") | U50: =IF(W49<>"","x",IF(U51="x","x","")) -> #REF! | V50: =IF(W49<>"","x","")
I51: =IF(I55="x","x","") | M51: =IF(M55="x","x","") -> #REF! | Q51: =IF(Q55="x","x","") -> #REF! | U51: =IF(U55="x","x","") -> #REF!
K53: 2do POR QUÉ: | O53: 3cer POR QUÉ: | S53: 4to POR QUÉ: | W53: 5to POR QUÉ:
B54: PROBLEMA | G54: PRIMER POR QUÉ | K54: =G56 -> 0 | O54: =K56 -> 0 | S54: =O56 -> 0 | W54: =S56 -> 0 | AA54: CAUSA RAÍZ
...

Sheet DATOS
B6: FUENTE | C6: TIPO DE HALLAZGO | D6: TIPO DE ACCIÓN A TOMAR | F6: Seleccionar | G6: Seleccionar | H6: PROCESO
B7: Seleccionar | C7: Seleccionar | D7: Seleccionar | F7: 1.DO - | G7: Docencia | H7: =CONCATENATE(F7," ",G7) -> 1.DO - Docencia
B8: PQRs | C8: NO CONFORMIDAD | D8: ACCIÓN INMEDIATA CORRECCIÓN | F8: 1.1. RA - | G8: Registro Académico | H8: =CONCATENATE(F8," ",G8) -> 1.1. RA - Registro Académico
B9: HALLAZGO AUDITORÍA INTERNA | C9: OPORTUNIDAD DE MEJORA | D9: ACCIÓN CORRECTIVA | F9: 1.2. CU - | G9: Gestión Curricular | H9: =CONCATENATE(F9," ",G9) -> 1.2. CU - Gestión Curricular
B10: HALLAZGO AUDITORIA EXTERNA | C10: SALIDA NO CONFORME | D10: ACCIÓN DE MEJORA | F10: 2. IN - | G10: Investigación, Desarrollo e Innovación | H10: =CONCATENATE(F10," ",G10) -> 2. IN - Investigación, Desarrollo e Innovación
B11: HALLAZGO AUDITORÍA CONTROL INTERNO | F11: 3. EP - | G11: Extensión y Proyección Social | H11: =CONCATENATE(F11," ",G11) -> 3. EP - Extensión y Proyección Social
B12: SALIDA NO CONFORME | F12: 3.1. EM - | G12: Emprendimiento | H12: =CONCATENATE(F12," ",G12) -> 3.1. EM - Emprendimiento
B13: REVISIÓN POR LA DIRECCIÓN | F13: 3.2. GE - | G13: Gestión de Egresados | H13: =CONCATENATE(F13," ",G13) -> 3.2. GE - Gestión de Egresados
B14: ANÁLISIS DE DATOS INTERNO EN EL PROCESO | F14: 3.3. EC - | G14: Educación Continuada | H14: =CONCATENATE(F14," ",G14) -> 3.3. EC - Educación Continuada
B15: EVALUACIÓN SEMESTRAL DE PROFESORES | F15: 3.4. PE - | G15: Gestión de Proyectos de Extensión | H15: =CONCATENATE(F15," ",G15) -> 3.4. PE - Gestión de Proyectos de Extensión
F16: 3.5. EF - | G16: Escuela de Formación para el TDH | H16: =CONCATENATE(F16," ",G16) -> 3.5. EF - Escuela de Formación para el TDH
D17: CRITERIOS DE EVALUACIÓN | F17: 4 . DE - | G17: Direccionamiento Estratégico | H17: =CONCATENATE(F17," ",G17) -> 4 . DE - Direccionamiento Estratégico
D18: 1 El Profesor respecto a la metodología: | F18: 4.1. PL - | G18: Planeación Institucional | H18: =CONCATENATE(F18," ",G18) -> 4.1. PL - Planeación Institucional
D19: 1.1 ¿El tiempo asignado para la evaluación es adecuado? | F19: 4.2. SI - | G19: Gestión de Sistemas de Información | H19: =CONCATENATE(F19," ",G19) -> 4.2. SI - Gestión de Sistemas de Información
D20: 1.2 ¿Entrega plan de la asignatura al inicio del curso? (Contenido programático) | F20: 4.3. PF - | G20: Gestión de Proyectos Institucionales | H20: =CONCATENATE(F20," ",G20) -> 4.3. PF - Gestión de Proyectos Institucionales
B21: PROGRAMAS ACADÉMICOS | D21: 1.3 ¿Es claro en el planteamiento de las evaluaciones? | F21: 4.4. GC - | G21: Gestión de Calidad | H21: =CONCATENATE(F21," ",G21) -> 4.4. GC - Gestión de Calidad
B22: PPN-Arquitectura | D22: 1.4 ¿La bibliografía o fuentes de información suministrada es coherente con la temática del curso? | F22: 5. AC - | G22: Aseguramiento de la Calidad | H22: =CONCATENATE(F22," ",G22) -> 5. AC - Aseguramiento de la Calidad
B23: PPN-Ingeniería de Sistemas | D23: 1.5 ¿La retroalimentación de las evaluaciones y trabajos permite evidenciar los errores del estudiante y mejorar resultados de aprendizaje? | F23: 5.1. AU - | G23: Autoevaluación Institucional | H23: =CONCATENATE(F23," ",G23) -> 5.1. AU - Autoevaluación Institucional
B24: PPN-Ingeniería Industrial | D24: 1.6 ¿Promueve la investigación? | F24: 5.2. RC - | G24: Registro Calificado | H24: =CONCATENATE(F24," ",G24) -> 5.2. RC - Registro Calificado
B25: PPN-Ingeniería Agroecológica | D25: 1.7 ¿Realiza diferentes evaluaciones por cada nota sumativa? | F25: 6. VN - | G25: Visibilidad Nacional e Internacional | H25: =CONCATENATE(F25," ",G25) -> 6. VN - Visibilidad Nacional e Internacional
B26: PPN-Comunicación Social | D26: 1.8 ¿Socializa las fechas de parciales según calendario académico? | F26: 6.1. VN - | G26: Relaciones Interinstitucionales - ORI | H26: =CONCATENATE(F26," ",G26) -> 6.1. VN - Relaciones Interinstitucionales - ORI
B27: PPN-Derecho | D27: 2 El Profesor respecto a las relaciones interpersonales: | F27: 6.2. MA - | G27: Mercadeo - Admisiones | H27: =CONCATENATE(F27," ",G27) -> 6.2. MA - Mercadeo - Admisiones
B28: PPN-Psicología | D28: 2.1 ¿El ambiente de trabajo promovido por el docente aportó al aprendizaje? | F28: 6.3. CO - | G28: Comunicaciones Institucional | H28: =CONCATENATE(F28," ",G28) -> 6.3. CO - Comunicaciones Institucional
B29: PPN-Trabajo Social | D29: 2.2 ¿Respeta a los estudiantes? | F29: 7. BI - | G29: Bienestar Institucional | H29: =CONCATENATE(F29," ",G29) -> 7. BI - Bienestar Institucional
B30: PPN-Administración de Empresas | D30: 2.3 ¿Respeta los acuerdos establecidos? | F30: 8. GH - | G30: Gestión Humana | H30: =CONCATENATE(F30," ",G30) -> 8. GH - Gestión Humana
B31: PPN-Contaduría Pública | D31: 2.4 ¿Tiene buenas relaciones interpersonales dentro y fuera de la clase? | F31: 8.1. TH - | G31: Gestión del Talento Humano | H31: =CONCATENATE(F31," ",G31) -> 8.1. TH - Gestión del Talento Humano
B32: PPN-Administracción de Empresas Agropecuarias | D32: 2.5 ¿Tiene disposición para atender consultas? | F32: 8.2. ST - | G32: Gestión de Seguridad y Salud en el Trabajo | H32: =CONCATENATE(F32," ",G32) -> 8.2. ST - Gestión de Seguridad y Salud en el Trabajo
... B40: STQ-Psicología | D40: 4.2 ¿Es objetivo en sus evaluaciones? | F40: 11. GR - | G40: Gestión de Recursos | H40: =CONCATENATE(F40," ",G40) -> 11. GR - Gestión de Recursos
D41: 4.3 ¿Fomenta la participación y la creatividad? | F41: 11.1. RE - | G41: Recursos Educativos | H41: =CONCATENATE(F41," ",G41) -> 11.1. RE - Recursos Educativos
D42: 4.4 ¿Hace uso de tecnologías de la información y otros recursos para apoyar el proceso de aprendizaje? | F42: 11.2. RT - | G42: Recursos Tecnológicos | H42: =CONCATENATE(F42," ",G42) -> 11.2. RT - Recursos Tecnológicos
D43: 4.5 ¿La explicación es clara y comprensible? | F43: 11.3. RF - | G43: Recursos Físicos | H43: =CONCATENATE(F43," ",G43) -> 11.3. RF - Recursos Físicos
D44: 4.6 ¿Muestra interés por la formación integral del estudiante?
D45: 4.7 ¿Relaciona la temática con temas de actualidad y contexto?
D46: 4.8 ¿Utiliza diferentes formas de evaluación?
